Workbook

Sheet README
B1: Mitigation (Net Zero) Investment Needs Model v1.1
B4: What it does
B5: Estimates, for every economy with IMF WEO GDP (195 economies) and seven mitigation sectors, the 2030 total and incremental investment need and its incremental cost under three lenses: (a) market cost of capital, (b) the World Bank rate (6%), and (c) the World Bank rate with local co-benefits. All cells recalculate from the Inputs sheet.
B7: Method (equation numbers follow the SISEPUEDE method note)
B8: 1. Totals. Group pools for 2030 (advanced economies, China, other EMDCs) come from IHLEG (2024) and IEA-IFC (2023); clean energy is split into sectors with the IEA-IFC shares; AFOLU uses IHLEG and UNEP (Inputs, Sector_Params).
B9: 2. Allocation (eq. 1/3, Tier 3 of the note). Each group-sector pool is shared across its countries in proportion to w = [beta x physical-driver share + (1 - beta) x PPP GDP share] x price level^phi. Drivers come from IMF CPAT 2024: electricity demand (power, grids), road fuel (transport), building and industrial energy use, fossil supply (fuels), non-CO2 GHG plus net LULUCF source (AFOLU). Countries without CPAT data use GDP only.
B10: 3. Incremental investment (eq. 2): dI = I x incremental share (AE/China 0.38 from McKinsey 2022; EMDC 0.24 from CCDR vs IHLEG).
B11: 4. Capital charge (eq. 4): A = dI x CRF(r, n), CRF = r / (1 - (1 + r)^-n), asset life n by sector.
B12: 5. Cost of capital (eq. 5). Lens (a) uses a country WACC: the average of observed RE WACC (IRENA 2021, converted to nominal; Steffen et al. 2025) where available; else a Damodaran-based WACC, D/V(rf + default spread)(1 - tax) + E/V(rf + beta x ERP + lambda x CRP), shifted to the observed level; else the IHLEG group rate (AE 5.5%, China 6%, EMDC 10.5%). The high case adds the group gap to 7% / 8% / 15%. Lens (b)/(c) use 6% (or IBRD ~5.2% by switch).
B13: 6. Savings, co-benefits and abatement (eq. 6-7), v1.1. Power generation and transport use engineering parameters: renewable output per dollar displaces the country's fossil generation mix (Ember) at CPAT 2024 fuel supply costs and air-pollution costs, with heat rates and IPCC 2006 CO2 factors; EVs replace gasoline cars (fuel, power and maintenance per vehicle over the purchase premium). Grids carry no benefits of their own (switch p_grid_credit). Low-emission fuels and AFOLU are costed per tonne (USD 100/t and 50/t). Buildings and industry keep the calibrated b = 0.133 and c = 0.129 (SISEPUEDE LAC) scaled by CPAT country indices relative to the investment-weighted world average.
B14: 7. Incremental cost: (a) = CRF(WACC) x dI - savings; (b) = CRF(6%) x dI - savings; (c) = (b) - local co-benefits. Memo lines add avoided emissions (a x dI) at the World Bank shadow price of carbon. Positive = net cost.
B15: 8. PIMA. PIMA-adjusted investment = I x [(1 - public share) + public share / (1 - efficiency gap)]. The gap is mapped from the PEFA PI-11 score where available, otherwise the IMF (2015) income-group gap; the reform switch closes two-thirds of it.
... B32: - Build: python InvestmentNeeds/build/build_investment_model.py (reads only repo files).

Sheet Results_Summary
A1: Mitigation (net zero) investment needs and incremental cost, 2030
A2: USD bn a year, 2023 prices. Flows are annual over the asset life of one year's 2030 investment (as in the method note, Tables 6-7). Incremental cost > 0 is a net cost; < 0 a net saving.
A4: Item | B4: AE | C4: China | D4: EMDC | E4: World
A5: Total investment need, I | B5: =SUMIFS(Calc!$J$5:$J$1369,Calc!$B$5:$B$1369,"AE") -> 2385.9844 | C5: =SUMIFS(Calc!$J$5:$J$1369,Calc!$B$5:$B$1369,"China") -> 863.01562 | D5: =SUMIFS(Calc!$J$5:$J$1369,Calc!$B$5:$B$1369,"EMDC") -> 1950 | E5: =SUM(B5:D5) -> 5199
A6: Incremental investment need, dI | B6: =SUMIFS(Calc!$L$5:$L$1369,Calc!$B$5:$B$1369,"AE") -> 906.67406 | C6: =SUMIFS(Calc!$L$5:$L$1369,Calc!$B$5:$B$1369,"China") -> 327.94594 | D6: =SUMIFS(Calc!$L$5:$L$1369,Calc!$B$5:$B$1369,"EMDC") -> 468 | E6: =SUM(B6:D6) -> 1702.62
A7: Savings on dI (fuel and operating) | B7: =SUMIFS(Calc!$W$5:$W$1369,Calc!$B$5:$B$1369,"AE") -> 59.028123 | C7: =SUMIFS(Calc!$W$5:$W$1369,Calc!$B$5:$B$1369,"China") -> 17.58997 | D7: =SUMIFS(Calc!$W$5:$W$1369,Calc!$B$5:$B$1369,"EMDC") -> 24.509441 | E7: =SUM(B7:D7) -> 101.12753
A8: Local co-benefits on dI | B8: =SUMIFS(Calc!$X$5:$X$1369,Calc!$B$5:$B$1369,"AE") -> 17.36481 | C8: =SUMIFS(Calc!$X$5:$X$1369,Calc!$B$5:$B$1369,"China") -> 36.459082 | D8: =SUMIFS(Calc!$X$5:$X$1369,Calc!$B$5:$B$1369,"EMDC") -> 26.573732 | E8: =SUM(B8:D8) -> 80.397624
A9: Capital charge on dI, lens (a) market | B9: =SUMIFS(Calc!$Z$5:$Z$1369,Calc!$B$5:$B$1369,"AE") -> 68.386404 | C9: =SUMIFS(Calc!$Z$5:$Z$1369,Calc!$B$5:$B$1369,"China") -> 21.957883 | D9: =SUMIFS(Calc!$Z$5:$Z$1369,Calc!$B$5:$B$1369,"EMDC") -> 50.45736 | E9: =SUM(B9:D9) -> 140.80165
A10: Capital charge on dI, lens (b) WB rate | B10: =SUMIFS(Calc!$AB$5:$AB$1369,Calc!$B$5:$B$1369,"AE") -> 74.412002 | C10: =SUMIFS(Calc!$AB$5:$AB$1369,Calc!$B$5:$B$1369,"China") -> 26.914979 | D10: =SUMIFS(Calc!$AB$5:$AB$1369,Calc!$B$5:$B$1369,"EMDC") -> 37.673327 | E10: =SUM(B10:D10) -> 139.00031
A11: INCREMENTAL COST (a) market cost of capital | B11: =SUMIFS(Calc!$AC$5:$AC$1369,Calc!$B$5:$B$1369,"AE") -> 9.3582809 | C11: =SUMIFS(Calc!$AC$5:$AC$1369,Calc!$B$5:$B$1369,"China") -> 4.3679123 | D11: =SUMIFS(Calc!$AC$5:$AC$1369,Calc!$B$5:$B$1369,"EMDC") -> 25.947919 | E11: =SUM(B11:D11) -> 39.674113
A12: INCREMENTAL COST (a) market, high case | B12: =SUMIFS(Calc!$AD$5:$AD$1369,Calc!$B$5:$B$1369,"AE") -> 19.454822 | C12: =SUMIFS(Calc!$AD$5:$AD$1369,Calc!$B$5:$B$1369,"China") -> 9.0549635 | D12: =SUMIFS(Calc!$AD$5:$AD$1369,Calc!$B$5:$B$1369,"EMDC") -> 44.366442 | E12: =SUM(B12:D12) -> 72.876228
A13: INCREMENTAL COST (b) World Bank rate | B13: =SUMIFS(Calc!$AE$5:$AE$1369,Calc!$B$5:$B$1369,"AE") -> 15.383879 | C13: =SUMIFS(Calc!$AE$5:$AE$1369,Calc!$B$5:$B$1369,"China") -> 9.3250089 | D13: =SUMIFS(Calc!$AE$5:$AE$1369,Calc!$B$5:$B$1369,"EMDC") -> 13.163886 | E13: =SUM(B13:D13) -> 37.872774
A14: INCREMENTAL COST (c) WB rate + local co-benefits | B14: =SUMIFS(Calc!$AF$5:$AF$1369,Calc!$B$5:$B$1369,"AE") -> -1.9809314 | C14: =SUMIFS(Calc!$AF$5:$AF$1369,Calc!$B$5:$B$1369,"China") -> -27.134073 | D14: =SUMIFS(Calc!$AF$5:$AF$1369,Calc!$B$5:$B$1369,"EMDC") -> -13.409846 | E14: =SUM(B14:D14) -> -42.52485
A15: memo: (c) + avoided carbon at SPC low | B15: =SUMIFS(Calc!$AG$5:$AG$1369,Calc!$B$5:$B$1369,"AE") -> -21.672504 | C15: =SUMIFS(Calc!$AG$5:$AG$1369,Calc!$B$5:$B$1369,"China") -> -37.199122 | D15: =SUMIFS(Calc!$AG$5:$AG$1369,Calc!$B$5:$B$1369,"EMDC") -> -29.707535 | E15: =SUM(B15:D15) -> -88.579161
A16: memo: (c) + avoided carbon at SPC high | B16: =SUMIFS(Calc!$AH$5:$AH$1369,Calc!$B$5:$B$1369,"AE") -> -41.364077 | C16: =SUMIFS(Calc!$AH$5:$AH$1369,Calc!$B$5:$B$1369,"China") -> -47.264171 | D16: =SUMIFS(Calc!$AH$5:$AH$1369,Calc!$B$5:$B$1369,"EMDC") -> -46.005224 | E16: =SUM(B16:D16) -> -134.63347
A17: Abatement from dI (MtCO2e/yr) | B17: =SUMIFS(Calc!$Y$5:$Y$1369,Calc!$B$5:$B$1369,"AE") -> 393.83146 | C17: =SUMIFS(Calc!$Y$5:$Y$1369,Calc!$B$5:$B$1369,"China") -> 201.30098 | D17: =SUMIFS(Calc!$Y$5:$Y$1369,Calc!$B$5:$B$1369,"EMDC") -> 325.95378 | E17: =SUM(B17:D17) -> 921.08623
A18: Cost-of-capital penalty on I, (a) less (b) | B18: =SUMIFS(Calc!$AM$5:$AM$1369,Calc!$B$5:$B$1369,"AE") -> -15.856837 | C18: =SUMIFS(Calc!$AM$5:$AM$1369,Calc!$B$5:$B$1369,"China") -> -13.044991 | D18: =SUMIFS(Calc!$AM$5:$AM$1369,Calc!$B$5:$B$1369,"EMDC") -> 53.266804 | E18: =SUM(B18:D18) -> 24.364976
A19: PIMA-adjusted total investment | B19: =SUMIFS(Calc!$AN$5:$AN$1369,Calc!$B$5:$B$1369,"AE") -> 2492.9423 | C19: =SUMIFS(Calc!$AN$5:$AN$1369,Calc!$B$5:$B$1369,"China") -> 1022.6144 | D19: =SUMIFS(Calc!$AN$5:$AN$1369,Calc!$B$5:$B$1369,"EMDC") -> 2261.7339 | E19: =SUM(B19:D19) -> 5777.2906
A20: PIMA-adjusted incremental investment | B20: =SUMIFS(Calc!$AO$5:$AO$1369,Calc!$B$5:$B$1369,"AE") -> 947.31807 | C20: =SUMIFS(Calc!$AO$5:$AO$1369,Calc!$B$5:$B$1369,"China") -> 388.59347 | D20: =SUMIFS(Calc!$AO$5:$AO$1369,Calc!$B$5:$B$1369,"EMDC") -> 542.81614 | E20: =SUM(B20:D20) -> 1878.7277
A21: GDP 2030 (USD bn, 2024 prices) | B21: =SUMIFS(Country_Data!$BV$5:$BV$199,Country_Data!$E$5:$E$199,"AE") -> 72737.664 | C21: =SUMIFS(Country_Data!$BV$5:$BV$199,Country_Data!$E$5:$E$199,"China") -> 24676.851 | D21: =SUMIFS(Country_Data!$BV$5:$BV$199,Country_Data!$E$5:$E$199,"EMDC") -> 33458.578 | E21: =SUM(B21:D21) -> 130873.09
A22: I, % of GDP | B22: =B5/B21 -> 0.032802598 | C22: =C5/C21 -> 0.034972681 | D22: =D5/D21 -> 0.058281018 | E22: =E5/E21 -> 0.039725507
A23: dI, % of GDP | B23: =B6/B21 -> 0.012464987 | C23: =C6/C21 -> 0.013289619 | D23: =D6/D21 -> 0.013987444 | E23: =E6/E21 -> 0.013009702
A24: Incremental cost (a), % of GDP | B24: =B11/B21 -> 0.00012865798 | C24: =C11/C21 -> 0.00017700445 | D24: =D11/D21 -> 0.00077552367 | E24: =E11/E21 -> 0.0003031495
A25: Incremental cost (b), % of GDP | B25: =B13/B21 -> 0.00021149812 | C25: =C13/C21 -> 0.00037788489 | D25: =D13/D21 -> 0.00039343831 | E25: =E13/E21 -> 0.00028938549
A26: Incremental cost (c), % of GDP | B26: =B14/B21 -> -2.7233916e-05 | C26: =C14/C21 -> -0.001099576 | D26: =D14/D21 -> -0.00040078946 | E26: =E14/E21 -> -0.00032493195
A27: Financial benefit-cost ratio on dI, lens (a) | B27: =B7/B9 -> 0.86315583 | C27: =C7/C9 -> 0.80107771 | D27: =D7/D9 -> 0.4857456 | E27: =E7/E9 -> 0.71822693
A28: Financial benefit-cost ratio on dI, lens (b) | B28: =B7/B10 -> 0.79326078 | C28: =C7/C10 -> 0.65353832 | D28: =D7/D10 -> 0.65057808 | E28: =E7/E10 -> 0.7275346
A29: Economic benefit-cost ratio on dI, lens (c) | B29: =(B7+B8)/B10 -> 1.0266211 | C29: =(C7+C8)/C10 -> 2.0081402 | D29: =(D7+D8)/D10 -> 1.3559507 | E29: =(E7+E8)/E10 -> 1.3059335
A30: Countries in group | B30: =COUNTIF(Country_Data!$E$5:$E$199,"AE") -> 41 | C30: =COUNTIF(Country_Data!$E$5:$E$199,"China") -> 1 | D30: =COUNTIF(Country_Data!$E$5:$E$199,"EMDC") -> 153 | E30: =SUM(B30:D30) -> 195
A32: Total-investment lens (method note Tables 6-7 framing: b and c applied to total I)
A33: Item | B33: AE | C33: China | D33: EMDC | E33: World
A34: Capital charge on I, (a) | B34: =SUMIFS(Calc!$AI$5:$AI$1369,Calc!$B$5:$B$1369,"AE") -> 179.96422 | C34: =SUMIFS(Calc!$AI$5:$AI$1369,Calc!$B$5:$B$1369,"China") -> 57.783902 | D34: =SUMIFS(Calc!$AI$5:$AI$1369,Calc!$B$5:$B$1369,"EMDC") -> 210.239 | E34: =SUM(B34:D34) -> 447.98712
A35: Capital charge on I, (b) | B35: =SUMIFS(Calc!$AJ$5:$AJ$1369,Calc!$B$5:$B$1369,"AE") -> 195.82106 | C35: =SUMIFS(Calc!$AJ$5:$AJ$1369,Calc!$B$5:$B$1369,"China") -> 70.828893 | D35: =SUMIFS(Calc!$AJ$5:$AJ$1369,Calc!$B$5:$B$1369,"EMDC") -> 156.9722 | E35: =SUM(B35:D35) -> 423.62214
A36: Financial savings on I | B36: =SUMIFS(Calc!$AK$5:$AK$1369,Calc!$B$5:$B$1369,"AE") -> 155.33717 | C36: =SUMIFS(Calc!$AK$5:$AK$1369,Calc!$B$5:$B$1369,"China") -> 46.289396 | D36: =SUMIFS(Calc!$AK$5:$AK$1369,Calc!$B$5:$B$1369,"EMDC") -> 102.12267 | E36: =SUM(B36:D36) -> 303.74923
A37: Co-benefits on I | B37: =SUMIFS(Calc!$AL$5:$AL$1369,Calc!$B$5:$B$1369,"AE") -> 45.696869 | C37: =SUMIFS(Calc!$AL$5:$AL$1369,Calc!$B$5:$B$1369,"China") -> 95.944952 | D37: =SUMIFS(Calc!$AL$5:$AL$1369,Calc!$B$5:$B$1369,"EMDC") -> 110.72388 | E37: =SUM(B37:D37) -> 252.3657
A38: Net financial benefit, (a) | B38: =B36-B34 -> -24.627055 | C38: =C36-C34 -> -11.494506 | D38: =D36-D34 -> -108.11633 | E38: =E36-E34 -> -144.23789
A39: Net financial benefit, (b) | B39: =B36-B35 -> -40.483892 | C39: =C36-C35 -> -24.539497 | D39: =D36-D35 -> -54.849527 | E39: =E36-E35 -> -119.87292
A40: Net benefit with co-benefits, (c) | B40: =B36-B35+B37 -> 5.2129774 | C40: =C36-C35+C37 -> 71.405454 | D40: =D36-D35+D37 -> 55.874357 | E40: =E36-E35+E37 -> 132.49279
A42: Investment by sector and group (USD bn/yr)
A43: Sector | B43: I: AE | C43: I: China | D43: I: EMDC | E43: I: World | F43: dI: World | G43: Incr. cost (a) | H43: Incr. cost (b) | I43: Incr. cost (c)
...

Sheet Results_Country
A1: Results by country: mitigation investment needs and incremental cost, 2030 (USD bn/yr, 2023 prices)
A2: Incremental cost = annual capital charge on incremental investment less fuel and operating savings (less local co-benefits in lens c), over the asset life of one year's investment. Positive = net cost. Sorted by 2024 GDP.
A4: ISO3 | B4: Country | C4: Group | D4: WB income | E4: GDP 2030 (USD bn) | F4: Total investment I | G4: I, % GDP | H4: Incremental investment dI | I4: dI, % GDP | J4: Market WACC (a) | K4: WACC source | L4: Savings on dI | M4: Local co-benefits on dI | N4: Incr. cost (a) market | O4: Incr. cost (a) market high | P4: Incr. cost (b) WB rate | Q4: Incr. cost (c) WB + local co-ben. | R4: (a) % GDP | S4: (b) % GDP | T4: (c) % GDP | U4: memo: (c) + carbon, SPC low | V4: memo: (c) + carbon, SPC high | W4: Abatement (MtCO2e/yr) | X4: Incr. cost per t (a) USD/t | Y4: Incr. cost per t (b) USD/t | Z4: Incr. cost per t (c) USD/t | AA4: CoC penalty on I (a-b) | AB4: PIMA-adjusted I | AC4: PIM efficiency gap | AD4: PEFA PI-11 (1-4) | AE4: Capex execution (%) | AF4: Official-private spread (pp) | AG4: Gross debt (% GDP)
A5: =Country_Data!A5 -> USA | B5: =Country_Data!B5 -> United States | C5: =Country_Data!E5 -> AE | D5: =Country_Data!D5 -> High income | E5: =Country_Data!BV5 -> 33560.153 | F5: =SUMIFS(Calc!$J$5:$J$1369,Calc!$A$5:$A$1369,A5) -> 1069.0936 | G5: =IFERROR(F5/E5,"") -> 0.031856041 | H5: =SUMIFS(Calc!$L$5:$L$1369,Calc!$A$5:$A$1369,A5) -> 406.25558 | I5: =IFERROR(H5/E5,"") -> 0.012105296 | J5: =Country_Data!DW5 -> 0.05705 | K5: =Country_Data!DV5 -> Observed (IRENA/Steffen) | L5: =SUMIFS(Calc!$W$5:$W$1369,Calc!$A$5:$A$1369,A5) -> 18.307599 | M5: =SUMIFS(Calc!$X$5:$X$1369,Calc!$A$5:$A$1369,A5) -> 7.1875018 | N5: =SUMIFS(Calc!$AC$5:$AC$1369,Calc!$A$5:$A$1369,A5) -> 14.325479 | O5: =SUMIFS(Calc!$AD$5:$AD$1369,Calc!$A$5:$A$1369,A5) -> 18.967904 | P5: =SUMIFS(Calc!$AE$5:$AE$1369,Calc!$A$5:$A$1369,A5) -> 15.217629 | Q5: =SUMIFS(Calc!$AF$5:$AF$1369,Calc!$A$5:$A$1369,A5) -> 8.0301275 | R5: =IFERROR(N5/E5,"") -> 0.00042685977 | S5: =IFERROR(P5/E5,"") -> 0.00045344338 | T5: =IFERROR(Q5/E5,"") -> 0.00023927565 | U5: =SUMIFS(Calc!$AG$5:$AG$1369,Calc!$A$5:$A$1369,A5) -> -1.4683876 | V5: =SUMIFS(Calc!$AH$5:$AH$1369,Calc!$A$5:$A$1369,A5) -> -10.966903 | W5: =SUMIFS(Calc!$Y$5:$Y$1369,Calc!$A$5:$A$1369,A5) -> 189.9703 | X5: =IFERROR(N5/W5*1000,"") -> 75.409047 | Y5: =IFERROR(P5/W5*1000,"") -> 80.105306 | Z5: =IFERROR(Q5/W5*1000,"") -> 42.270436 | AA5: =SUMIFS(Calc!$AM$5:$AM$1369,Calc!$A$5:$A$1369,A5) -> -2.3477628 | AB5: =SUMIFS(Calc!$AN$5:$AN$1369,Calc!$A$5:$A$1369,A5) -> 1117.0185 | AC5: =Country_Data!DY5 -> 0.13 | AD5: =IF(Country_Data!BD5="","",Country_Data!BD5) | AE5: =IF(Country_Data!BC5="","",Country_Data!BC5) | AF5: =IF(Country_Data!BL5="","",Country_Data!BL5) | AG5: =IF(Country_Data!BA5="","",Country_Data!BA5) -> 122.27
A6: =Country_Data!A6 -> CHN | B6: =Country_Data!B6 -> China | C6: =Country_Data!E6 -> China | D6: =Country_Data!D6 -> Upper middle income | E6: =Country_Data!BV6 -> 24676.851 | F6: =SUMIFS(Calc!$J$5:$J$1369,Calc!$A$5:$A$1369,A6) -> 863.01562 | G6: =IFERROR(F6/E6,"") -> 0.034972681 | H6: =SUMIFS(Calc!$L$5:$L$1369,Calc!$A$5:$A$1369,A6) -> 327.94594 | I6: =IFERROR(H6/E6,"") -> 0.013289619 | J6: =Country_Data!DW6 -> 0.0389 | K6: =Country_Data!DV6 -> Observed (IRENA/Steffen) | L6: =SUMIFS(Calc!$W$5:$W$1369,Calc!$A$5:$A$1369,A6) -> 17.58997 | M6: =SUMIFS(Calc!$X$5:$X$1369,Calc!$A$5:$A$1369,A6) -> 36.459082 | N6: =SUMIFS(Calc!$AC$5:$AC$1369,Calc!$A$5:$A$1369,A6) -> 4.3679123 | O6: =SUMIFS(Calc!$AD$5:$AD$1369,Calc!$A$5:$A$1369,A6) -> 9.0549635 | P6: =SUMIFS(Calc!$AE$5:$AE$1369,Calc!$A$5:$A$1369,A6) -> 9.3250089 | Q6: =SUMIFS(Calc!$AF$5:$AF$1369,Calc!$A$5:$A$1369,A6) -> -27.134073 | R6: =IFERROR(N6/E6,"") -> 0.00017700445 | S6: =IFERROR(P6/E6,"") -> 0.00037788489 | T6: =IFERROR(Q6/E6,"") -> -0.001099576 | U6: =SUMIFS(Calc!$AG$5:$AG$1369,Calc!$A$5:$A$1369,A6) -> -37.199122 | V6: =SUMIFS(Calc!$AH$5:$AH$1369,Calc!$A$5:$A$1369,A6) -> -47.264171 | W6: =SUMIFS(Calc!$Y$5:$Y$1369,Calc!$A$5:$A$1369,A6) -> 201.30098 | X6: =IFERROR(N6/W6*1000,"") -> 21.698415 | Y6: =IFERROR(P6/W6*1000,"") -> 46.323712 | Z6: =IFERROR(Q6/W6*1000,"") -> -134.79354 | AA6: =SUMIFS(Calc!$AM$5:$AM$1369,Calc!$A$5:$A$1369,A6) -> -13.044991 | AB6: =SUMIFS(Calc!$AN$5:$AN$1369,Calc!$A$5:$A$1369,A6) -> 1022.6144 | AC6: =Country_Data!DY6 -> 0.27 | AD6: =IF(Country_Data!BD6="","",Country_Data!BD6) | AE6: =IF(Country_Data!BC6="","",Country_Data!BC6) | AF6: =IF(Country_Data!BL6="","",Country_Data!BL6) -> 0.656 | AG6: =IF(Country_Data!BA6="","",Country_Data!BA6) -> 90.421
A7: =Country_Data!A7 -> DEU | B7: =Country_Data!B7 -> Germany | C7: =Country_Data!E7 -> AE | D7: =Country_Data!D7 -> High income | E7: =Country_Data!BV7 -> 4884.0892 | F7: =SUMIFS(Calc!$J$5:$J$1369,Calc!$A$5:$A$1369,A7) -> 152.2747 | G7: =IFERROR(F7/E7,"") -> 0.031177707 | H7: =SUMIFS(Calc!$L$5:$L$1369,Calc!$A$5:$A$1369,A7) -> 57.864388 | I7: =IFERROR(H7/E7,"") -> 0.011847529 | J7: =Country_Data!DW7 -> 0.0232 | K7: =Country_Data!DV7 -> Observed (IRENA/Steffen) | L7: =SUMIFS(Calc!$W$5:$W$1369,Calc!$A$5:$A$1369,A7) -> 4.3058879 | M7: =SUMIFS(Calc!$X$5:$X$1369,Calc!$A$5:$A$1369,A7) -> 1.4337864 | N7: =SUMIFS(Calc!$AC$5:$AC$1369,Calc!$A$5:$A$1369,A7) -> -1.0147741 | O7: =SUMIFS(Calc!$AD$5:$AD$1369,Calc!$A$5:$A$1369,A7) -> -0.45142451 | P7: =SUMIFS(Calc!$AE$5:$AE$1369,Calc!$A$5:$A$1369,A7) -> 0.45012401 | Q7: =SUMIFS(Calc!$AF$5:$AF$1369,Calc!$A$5:$A$1369,A7) -> -0.98366234 | R7: =IFERROR(N7/E7,"") -> -0.00020777141 | S7: =IFERROR(P7/E7,"") -> 9.2161301e-05 | T7: =IFERROR(Q7/E7,"") -> -0.00020140139 | U7: =SUMIFS(Calc!$AG$5:$AG$1369,Calc!$A$5:$A$1369,A7) -> -2.2521772 | V7: =SUMIFS(Calc!$AH$5:$AH$1369,Calc!$A$5:$A$1369,A7) -> -3.520692 | W7: =SUMIFS(Calc!$Y$5:$Y$1369,Calc!$A$5:$A$1369,A7) -> 25.370297 | X7: =IFERROR(N7/W7*1000,"") -> -39.998512 | Y7: =IFERROR(P7/W7*1000,"") -> 17.742166 | Z7: =IFERROR(Q7/W7*1000,"") -> -38.772204 | AA7: =SUMIFS(Calc!$AM$5:$AM$1369,Calc!$A$5:$A$1369,A7) -> -3.8549951 | AB7: =SUMIFS(Calc!$AN$5:$AN$1369,Calc!$A$5:$A$1369,A7) -> 159.10081 | AC7: =Country_Data!DY7 -> 0.13 | AD7: =IF(Country_Data!BD7="","",Country_Data!BD7) | AE7: =IF(Country_Data!BC7="","",Country_Data!BC7) | AF7: =IF(Country_Data!BL7="","",Country_Data!BL7) | AG7: =IF(Country_Data!BA7="","",Country_Data!BA7) -> 62.227
A8: =Country_Data!A8 -> JPN | B8: =Country_Data!B8 -> Japan | C8: =Country_Data!E8 -> AE | D8: =Country_Data!D8 -> High income | E8: =Country_Data!BV8 -> 4394.6303 | F8: =SUMIFS(Calc!$J$5:$J$1369,Calc!$A$5:$A$1369,A8) -> 190.59034 | G8: =IFERROR(F8/E8,"") -> 0.043368914 | H8: =SUMIFS(Calc!$L$5:$L$1369,Calc!$A$5:$A$1369,A8) -> 72.424331 | I8: =IFERROR(H8/E8,"") -> 0.016480187 | J8: =Country_Data!DW8 -> 0.055 | K8: =Country_Data!DV8 -> Group default (IHLEG) | L8: =SUMIFS(Calc!$W$5:$W$1369,Calc!$A$5:$A$1369,A8) -> 7.1954829 | M8: =SUMIFS(Calc!$X$5:$X$1369,Calc!$A$5:$A$1369,A8) -> 2.2674151 | N8: =SUMIFS(Calc!$AC$5:$AC$1369,Calc!$A$5:$A$1369,A8) -> -1.6293628 | O8: =SUMIFS(Calc!$AD$5:$AD$1369,Calc!$A$5:$A$1369,A8) -> -0.8016585 | P8: =SUMIFS(Calc!$AE$5:$AE$1369,Calc!$A$5:$A$1369,A8) -> -1.3588844 | Q8: =SUMIFS(Calc!$AF$5:$AF$1369,Calc!$A$5:$A$1369,A8) -> -3.6262995 | R8: =IFERROR(N8/E8,"") -> -0.00037076219 | S8: =IFERROR(P8/E8,"") -> -0.00030921472 | T8: =IFERROR(Q8/E8,"") -> -0.00082516599 | U8: =SUMIFS(Calc!$AG$5:$AG$1369,Calc!$A$5:$A$1369,A8) -> -5.6819736 | V8: =SUMIFS(Calc!$AH$5:$AH$1369,Calc!$A$5:$A$1369,A8) -> -7.7376478 | W8: =SUMIFS(Calc!$Y$5:$Y$1369,Calc!$A$5:$A$1369,A8) -> 41.113483 | X8: =IFERROR(N8/W8*1000,"") -> -39.630862 | Y8: =IFERROR(P8/W8*1000,"") -> -33.052038 | Z8: =IFERROR(Q8/W8*1000,"") -> -88.202196 | AA8: =SUMIFS(Calc!$AM$5:$AM$1369,Calc!$A$5:$A$1369,A8) -> -0.71178515 | AB8: =SUMIFS(Calc!$AN$5:$AN$1369,Calc!$A$5:$A$1369,A8) -> 199.13405 | AC8: =Country_Data!DY8 -> 0.13 | AD8: =IF(Country_Data!BD8="","",Country_Data!BD8) | AE8: =IF(Country_Data!BC8="","",Country_Data!BC8) | AF8: =IF(Country_Data!BL8="","",Country_Data!BL8) | AG8: =IF(Country_Data!BA8="","",Country_Data!BA8) -> 214.487
A9: =Country_Data!A9 -> IND | B9: =Country_Data!B9 -> India | C9: =Country_Data!E9 -> EMDC | D9: =Country_Data!D9 -> Lower middle income | E9: =Country_Data!BV9 -> 5539.4443 | F9: =SUMIFS(Calc!$J$5:$J$1369,Calc!$A$5:$A$1369,A9) -> 291.81555 | G9: =IFERROR(F9/E9,"") -> 0.052679572 | H9: =SUMIFS(Calc!$L$5:$L$1369,Calc!$A$5:$A$1369,A9) -> 70.035732 | I9: =IFERROR(H9/E9,"") -> 0.012643097 | J9: =Country_Data!DW9 -> 0.095 | K9: =Country_Data!DV9 -> Observed (IRENA/Steffen) | L9: =SUMIFS(Calc!$W$5:$W$1369,Calc!$A$5:$A$1369,A9) -> 2.462509 | M9: =SUMIFS(Calc!$X$5:$X$1369,Calc!$A$5:$A$1369,A9) -> 3.8924392 | N9: =SUMIFS(Calc!$AC$5:$AC$1369,Calc!$A$5:$A$1369,A9) -> 5.1234387 | O9: =SUMIFS(Calc!$AD$5:$AD$1369,Calc!$A$5:$A$1369,A9) -> 7.9047084 | P9: =SUMIFS(Calc!$AE$5:$AE$1369,Calc!$A$5:$A$1369,A9) -> 3.1546627 | Q9: =SUMIFS(Calc!$AF$5:$AF$1369,Calc!$A$5:$A$1369,A9) -> -0.73777652 | R9: =IFERROR(N9/E9,"") -> 0.00092490121 | S9: =IFERROR(P9/E9,"") -> 0.00056949082 | T9: =IFERROR(Q9/E9,"") -> -0.00013318602 | U9: =SUMIFS(Calc!$AG$5:$AG$1369,Calc!$A$5:$A$1369,A9) -> -3.6543384 | V9: =SUMIFS(Calc!$AH$5:$AH$1369,Calc!$A$5:$A$1369,A9) -> -6.5709003 | W9: =SUMIFS(Calc!$Y$5:$Y$1369,Calc!$A$5:$A$1369,A9) -> 58.331238 | X9: =IFERROR(N9/W9*1000,"") -> 87.833533 | Y9: =IFERROR(P9/W9*1000,"") -> 54.081874 | Z9: =IFERROR(Q9/W9*1000,"") -> -12.648052 | AA9: =SUMIFS(Calc!$AM$5:$AM$1369,Calc!$A$5:$A$1369,A9) -> 8.2032335 | AB9: =SUMIFS(Calc!$AN$5:$AN$1369,Calc!$A$5:$A$1369,A9) -> 334.98826 | AC9: =Country_Data!DY9 -> 0.27 | AD9: =IF(Country_Data!BD9="","",Country_Data!BD9) | AE9: =IF(Country_Data!BC9="","",Country_Data!BC9) -> 106.972 | AF9: =IF(Country_Data!BL9="","",Country_Data!BL9) -> 0.904 | AG9: =IF(Country_Data!BA9="","",Country_Data!BA9) -> 84.782
A10: =Country_Data!A10 -> GBR | B10: =Country_Data!B10 -> United Kingdom | C10: =Country_Data!E10 -> AE | D10: =Country_Data!D10 -> High income | E10: =Country_Data!BV10 -> 3895.8501 | F10: =SUMIFS(Calc!$J$5:$J$1369,Calc!$A$5:$A$1369,A10) -> 104.58983 | G10: =IFERROR(F10/E10,"") -> 0.026846471 | H10: =SUMIFS(Calc!$L$5:$L$1369,Calc!$A$5:$A$1369,A10) -> 39.744135 | I10: =IFERROR(H10/E10,"") -> 0.010201659 | J10: =Country_Data!DW10 -> 0.03587 | K10: =Country_Data!DV10 -> Observed (IRENA/Steffen) | L10: =SUMIFS(Calc!$W$5:$W$1369,Calc!$A$5:$A$1369,A10) -> 4.9009147 | M10: =SUMIFS(Calc!$X$5:$X$1369,Calc!$A$5:$A$1369,A10) -> 0.62999901 | N10: =SUMIFS(Calc!$AC$5:$AC$1369,Calc!$A$5:$A$1369,A10) -> -2.3067663 | O10: =SUMIFS(Calc!$AD$5:$AD$1369,Calc!$A$5:$A$1369,A10) -> -1.8926891 | P10: =SUMIFS(Calc!$AE$5:$AE$1369,Calc!$A$5:$A$1369,A10) -> -1.6261561 | Q10: =SUMIFS(Calc!$AF$5:$AF$1369,Calc!$A$5:$A$1369,A10) -> -2.2561552 | R10: =IFERROR(N10/E10,"") -> -0.0005921086 | S10: =IFERROR(P10/E10,"") -> -0.00041740727 | T10: =IFERROR(Q10/E10,"") -> -0.00057911755 | U10: =SUMIFS(Calc!$AG$5:$AG$1369,Calc!$A$5:$A$1369,A10) -> -2.964141 | V10: =SUMIFS(Calc!$AH$5:$AH$1369,Calc!$A$5:$A$1369,A10) -> -3.6721269 | W10: =SUMIFS(Calc!$Y$5:$Y$1369,Calc!$A$5:$A$1369,A10) -> 14.159717 | X10: =IFERROR(N10/W10*1000,"") -> -162.91048 | Y10: =IFERROR(P10/W10*1000,"") -> -114.84383 | Z10: =IFERROR(Q10/W10*1000,"") -> -159.33617 | AA10: =SUMIFS(Calc!$AM$5:$AM$1369,Calc!$A$5:$A$1369,A10) -> -1.7910795 | AB10: =SUMIFS(Calc!$AN$5:$AN$1369,Calc!$A$5:$A$1369,A10) -> 109.27834 | AC10: =Country_Data!DY10 -> 0.13 | AD10: =IF(Country_Data!BD10="","",Country_Data!BD10) | AE10: =IF(Country_Data!BC10="","",Country_Data!BC10) | AF10: =IF(Country_Data!BL10="","",Country_Data!BL10) | AG10: =IF(Country_Data!BA10="","",Country_Data!BA10) -> 99.901
A11: =Country_Data!A11 -> FRA | B11: =Country_Data!B11 -> France | C11: =Country_Data!E11 -> AE | D11: =Country_Data!D11 -> High income | E11: =Country_Data!BV11 -> 3329.6125 | F11: =SUMIFS(Calc!$J$5:$J$1369,Calc!$A$5:$A$1369,A11) -> 106.42816 | G11: =IFERROR(F11/E11,"") -> 0.031964127 | H11: =SUMIFS(Calc!$L$5:$L$1369,Calc!$A$5:$A$1369,A11) -> 40.4427 | I11: =IFERROR(H11/E11,"") -> 0.012146368 | J11: =Country_Data!DW11 -> 0.03297 | K11: =Country_Data!DV11 -> Observed (IRENA/Steffen) | L11: =SUMIFS(Calc!$W$5:$W$1369,Calc!$A$5:$A$1369,A11) -> 2.1907408 | M11: =SUMIFS(Calc!$X$5:$X$1369,Calc!$A$5:$A$1369,A11) -> 0.36940981 | N11: =SUMIFS(Calc!$AC$5:$AC$1369,Calc!$A$5:$A$1369,A11) -> 0.3466431 | O11: =SUMIFS(Calc!$AD$5:$AD$1369,Calc!$A$5:$A$1369,A11) -> 0.76313705 | P11: =SUMIFS(Calc!$AE$5:$AE$1369,Calc!$A$5:$A$1369,A11) -> 1.1195525 | Q11: =SUMIFS(Calc!$AF$5:$AF$1369,Calc!$A$5:$A$1369,A11) -> 0.75014268 | R11: =IFERROR(N11/E11,"") -> 0.00010410914 | S11: =IFERROR(P11/E11,"") -> 0.00033624108 | T11: =IFERROR(Q11/E11,"") -> 0.00022529429 | U11: =SUMIFS(Calc!$AG$5:$AG$1369,Calc!$A$5:$A$1369,A11) -> 0.26352499 | V11: =SUMIFS(Calc!$AH$5:$AH$1369,Calc!$A$5:$A$1369,A11) -> -0.22309271 | W11: =SUMIFS(Calc!$Y$5:$Y$1369,Calc!$A$5:$A$1369,A11) -> 9.732354 | X11: =IFERROR(N11/W11*1000,"") -> 35.617601 | Y11: =IFERROR(P11/W11*1000,"") -> 115.03409 | Z11: =IFERROR(Q11/W11*1000,"") -> 77.077209 | AA11: =SUMIFS(Calc!$AM$5:$AM$1369,Calc!$A$5:$A$1369,A11) -> -2.0339721 | AB11: =SUMIFS(Calc!$AN$5:$AN$1369,Calc!$A$5:$A$1369,A11) -> 111.19908 | AC11: =Country_Data!DY11 -> 0.13 | AD11: =IF(Country_Data!BD11="","",Country_Data!BD11) | AE11: =IF(Country_Data!BC11="","",Country_Data!BC11) | AF11: =IF(Country_Data!BL11="","",Country_Data!BL11) | AG11: =IF(Country_Data!BA11="","",Country_Data!BA11) -> 113.171
A12: =Country_Data!A12 -> ITA | B12: =Country_Data!B12 -> Italy | C12: =Country_Data!E12 -> AE | D12: =Country_Data!D12 -> High income | E12: =Country_Data!BV12 -> 2458.6433 | F12: =SUMIFS(Calc!$J$5:$J$1369,Calc!$A$5:$A$1369,A12) -> 81.737972 | G12: =IFERROR(F12/E12,"") -> 0.033245152 | H12: =SUMIFS(Calc!$L$5:$L$1369,Calc!$A$5:$A$1369,A12) -> 31.060429 | I12: =IFERROR(H12/E12,"") -> 0.012633158 | J12: =Country_Data!DW12 -> 0.0438 | K12: =Country_Data!DV12 -> Observed (IRENA/Steffen) | L12: =SUMIFS(Calc!$W$5:$W$1369,Calc!$A$5:$A$1369,A12) -> 3.2611012 | M12: =SUMIFS(Calc!$X$5:$X$1369,Calc!$A$5:$A$1369,A12) -> 0.73380338 | N12: =SUMIFS(Calc!$AC$5:$AC$1369,Calc!$A$5:$A$1369,A12) -> -1.0757859 | O12: =SUMIFS(Calc!$AD$5:$AD$1369,Calc!$A$5:$A$1369,A12) -> -0.73928262 | P12: =SUMIFS(Calc!$AE$5:$AE$1369,Calc!$A$5:$A$1369,A12) -> -0.71140553 | Q12: =SUMIFS(Calc!$AF$5:$AF$1369,Calc!$A$5:$A$1369,A12) -> -1.4452089 | R12: =IFERROR(N12/E12,"") -> -0.00043755267 | S12: =IFERROR(P12/E12,"") -> -0.00028934881 | T12: =IFERROR(Q12/E12,"") -> -0.00058780747 | U12: =SUMIFS(Calc!$AG$5:$AG$1369,Calc!$A$5:$A$1369,A12) -> -2.0647334 | V12: =SUMIFS(Calc!$AH$5:$AH$1369,Calc!$A$5:$A$1369,A12) -> -2.6842578 | W12: =SUMIFS(Calc!$Y$5:$Y$1369,Calc!$A$5:$A$1369,A12) -> 12.390489 | X12: =IFERROR(N12/W12*1000,"") -> -86.823526 | Y12: =IFERROR(P12/W12*1000,"") -> -57.415452 | Z12: =IFERROR(Q12/W12*1000,"") -> -116.63857 | AA12: =SUMIFS(Calc!$AM$5:$AM$1369,Calc!$A$5:$A$1369,A12) -> -0.95889583 | AB12: =SUMIFS(Calc!$AN$5:$AN$1369,Calc!$A$5:$A$1369,A12) -> 85.402088 | AC12: =Country_Data!DY12 -> 0.13 | AD12: =IF(Country_Data!BD12="","",Country_Data!BD12) | AE12: =IF(Country_Data!BC12="","",Country_Data!BC12) | AF12: =IF(Country_Data!BL12="","",Country_Data!BL12) | AG12: =IF(Country_Data!BA12="","",Country_Data!BA12) -> 134.735
A13: =Country_Data!A13 -> CAN | B13: =Country_Data!B13 -> Canada | C13: =Country_Data!E13 -> AE | D13: =Country_Data!D13 -> High income | E13: =Country_Data!BV13 -> 2488.1419 | F13: =SUMIFS(Calc!$J$5:$J$1369,Calc!$A$5:$A$1369,A13) -> 108.78607 | G13: =IFERROR(F13/E13,"") -> 0.043721809 | H13: =SUMIFS(Calc!$L$5:$L$1369,Calc!$A$5:$A$1369,A13) -> 41.338705 | I13: =IFERROR(H13/E13,"") -> 0.016614287 | J13: =Country_Data!DW13 -> 0.055 | K13: =Country_Data!DV13 -> Group default (IHLEG) | L13: =SUMIFS(Calc!$W$5:$W$1369,Calc!$A$5:$A$1369,A13) -> 2.1379202 | M13: =SUMIFS(Calc!$X$5:$X$1369,Calc!$A$5:$A$1369,A13) -> 0.39020643 | N13: =SUMIFS(Calc!$AC$5:$AC$1369,Calc!$A$5:$A$1369,A13) -> 1.0876127 | O13: =SUMIFS(Calc!$AD$5:$AD$1369,Calc!$A$5:$A$1369,A13) -> 1.5575851 | P13: =SUMIFS(Calc!$AE$5:$AE$1369,Calc!$A$5:$A$1369,A13) -> 1.2412154 | Q13: =SUMIFS(Calc!$AF$5:$AF$1369,Calc!$A$5:$A$1369,A13) -> 0.85100898 | R13: =IFERROR(N13/E13,"") -> 0.00043711842 | S13: =IFERROR(P13/E13,"") -> 0.00049885233 | T13: =IFERROR(Q13/E13,"") -> 0.0003420259 | U13: =SUMIFS(Calc!$AG$5:$AG$1369,Calc!$A$5:$A$1369,A13) -> 0.19572601 | V13: =SUMIFS(Calc!$AH$5:$AH$1369,Calc!$A$5:$A$1369,A13) -> -0.45955695 | W13: =SUMIFS(Calc!$Y$5:$Y$1369,Calc!$A$5:$A$1369,A13) -> 13.105659 | X13: =IFERROR(N13/W13*1000,"") -> 82.988016 | Y13: =IFERROR(P13/W13*1000,"") -> 94.708353 | Z13: =IFERROR(Q13/W13*1000,"") -> 64.934465 | AA13: =SUMIFS(Calc!$AM$5:$AM$1369,Calc!$A$5:$A$1369,A13) -> -0.40421773 | AB13: =SUMIFS(Calc!$AN$5:$AN$1369,Calc!$A$5:$A$1369,A13) -> 113.66268 | AC13: =Country_Data!DY13 -> 0.13 | AD13: =IF(Country_Data!BD13="","",Country_Data!BD13) | AE13: =IF(Country_Data!BC13="","",Country_Data!BC13) | AF13: =IF(Country_Data!BL13="","",Country_Data!BL13) | AG13: =IF(Country_Data!BA13="","",Country_Data!BA13) -> 110.019
A14: =Country_Data!A14 -> RUS | B14: =Country_Data!B14 -> Russian Federation | C14: =Country_Data!E14 -> EMDC | D14: =Country_Data!D14 -> High income | E14: =Country_Data!BV14 -> 2330.355 | F14: =SUMIFS(Calc!$J$5:$J$1369,Calc!$A$5:$A$1369,A14) -> 177.39905 | G14: =IFERROR(F14/E14,"") -> 0.076125334 | H14: =SUMIFS(Calc!$L$5:$L$1369,Calc!$A$5:$A$1369,A14) -> 42.575773 | I14: =IFERROR(H14/E14,"") -> 0.01827008 | J14: =Country_Data!DW14 -> 0.105 | K14: =Country_Data!DV14 -> Group default (IHLEG) | L14: =SUMIFS(Calc!$W$5:$W$1369,Calc!$A$5:$A$1369,A14) -> 1.3273054 | M14: =SUMIFS(Calc!$X$5:$X$1369,Calc!$A$5:$A$1369,A14) -> 3.8170708 | N14: =SUMIFS(Calc!$AC$5:$AC$1369,Calc!$A$5:$A$1369,A14) -> 3.6517176 | O14: =SUMIFS(Calc!$AD$5:$AD$1369,Calc!$A$5:$A$1369,A14) -> 5.366839 | P14: =SUMIFS(Calc!$AE$5:$AE$1369,Calc!$A$5:$A$1369,A14) -> 2.095114 | Q14: =SUMIFS(Calc!$AF$5:$AF$1369,Calc!$A$5:$A$1369,A14) -> -1.7219568 | R14: =IFERROR(N14/E14,"") -> 0.001567022 | S14: =IFERROR(P14/E14,"") -> 0.00089905359 | T14: =IFERROR(Q14/E14,"") -> -0.00073892465 | U14: =SUMIFS(Calc!$AG$5:$AG$1369,Calc!$A$5:$A$1369,A14) -> -2.9996619 | V14: =SUMIFS(Calc!$AH$5:$AH$1369,Calc!$A$5:$A$1369,A14) -> -4.2773671 | W14: =SUMIFS(Calc!$Y$5:$Y$1369,Calc!$A$5:$A$1369,A14) -> 25.554103 | X14: =IFERROR(N14/W14*1000,"") -> 142.90142 | Y14: =IFERROR(P14/W14*1000,"") -> 81.987382 | Z14: =IFERROR(Q14/W14*1000,"") -> -67.384746 | AA14: =SUMIFS(Calc!$AM$5:$AM$1369,Calc!$A$5:$A$1369,A14) -> 6.485848 | AB14: =SUMIFS(Calc!$AN$5:$AN$1369,Calc!$A$5:$A$1369,A14) -> 203.64439 | AC14: =Country_Data!DY14 -> 0.27 | AD14: =IF(Country_Data!BD14="","",Country_Data!BD14) | AE14: =IF(Country_Data!BC14="","",Country_Data!BC14) | AF14: =IF(Country_Data!BL14="","",Country_Data!BL14) | AG14: =IF(Country_Data!BA14="","",Country_Data!BA14) -> 14.758
A15: =Country_Data!A15 -> BRA | B15: =Country_Data!B15 -> Brazil | C15: =Country_Data!E15 -> EMDC | D15: =Country_Data!D15 -> Upper middle income | E15: =Country_Data!BV15 -> 2457.7421 | F15: =SUMIFS(Calc!$J$5:$J$1369,Calc!$A$5:$A$1369,A15) -> 139.4253 | G15: =IFERROR(F15/E15,"") -> 0.05672902 | H15: =SUMIFS(Calc!$L$5:$L$1369,Calc!$A$5:$A$1369,A15) -> 33.462072 | I15: =IFERROR(H15/E15,"") -> 0.013614965 | J15: =Country_Data!DW15 -> 0.097755 | K15: =Country_Data!DV15 -> Observed (IRENA/Steffen) | L15: =SUMIFS(Calc!$W$5:$W$1369,Calc!$A$5:$A$1369,A15) -> 1.3933363 | M15: =SUMIFS(Calc!$X$5:$X$1369,Calc!$A$5:$A$1369,A15) -> 1.4264195 | N15: =SUMIFS(Calc!$AC$5:$AC$1369,Calc!$A$5:$A$1369,A15) -> 2.3092408 | O15: =SUMIFS(Calc!$AD$5:$AD$1369,Calc!$A$5:$A$1369,A15) -> 3.6459412 | P15: =SUMIFS(Calc!$AE$5:$AE$1369,Calc!$A$5:$A$1369,A15) -> 1.2890906 | Q15: =SUMIFS(Calc!$AF$5:$AF$1369,Calc!$A$5:$A$1369,A15) -> -0.13732882 | R15: =IFERROR(N15/E15,"") -> 0.00093957818 | S15: =IFERROR(P15/E15,"") -> 0.00052450201 | T15: =IFERROR(Q15/E15,"") -> -5.5876009e-05 | U15: =SUMIFS(Calc!$AG$5:$AG$1369,Calc!$A$5:$A$1369,A15) -> -1.0301501 | V15: =SUMIFS(Calc!$AH$5:$AH$1369,Calc!$A$5:$A$1369,A15) -> -1.9229714 | W15: =SUMIFS(Calc!$Y$5:$Y$1369,Calc!$A$5:$A$1369,A15) -> 17.856426 | X15: =IFERROR(N15/W15*1000,"") -> 129.32268 | Y15: =IFERROR(P15/W15*1000,"") -> 72.191974 | Z15: =IFERROR(Q15/W15*1000,"") -> -7.6907225 | AA15: =SUMIFS(Calc!$AM$5:$AM$1369,Calc!$A$5:$A$1369,A15) -> 4.2506257 | AB15: =SUMIFS(Calc!$AN$5:$AN$1369,Calc!$A$5:$A$1369,A15) -> 160.0526 | AC15: =Country_Data!DY15 -> 0.27 | AD15: =IF(Country_Data!BD15="","",Country_Data!BD15) | AE15: =IF(Country_Data!BC15="","",Country_Data!BC15) -> 87.319 | AF15: =IF(Country_Data!BL15="","",Country_Data!BL15) -> 1.341 | AG15: =IF(Country_Data!BA15="","",Country_Data!BA15) -> 87.028
A16: =Country_Data!A16 -> KOR | B16: =Country_Data!B16 -> Korea, Rep. | C16: =Country_Data!E16 -> AE | D16: =Country_Data!D16 -> High income | E16: =Country_Data!BV16 -> 2077.3209 | F16: =SUMIFS(Calc!$J$5:$J$1369,Calc!$A$5:$A$1369,A16) -> 96.990799 | G16: =IFERROR(F16/E16,"") -> 0.046690329 | H16: =SUMIFS(Calc!$L$5:$L$1369,Calc!$A$5:$A$1369,A16) -> 36.856503 | I16: =IFERROR(H16/E16,"") -> 0.017742325 | J16: =Country_Data!DW16 -> 0.055 | K16: =Country_Data!DV16 -> Group default (IHLEG) | L16: =SUMIFS(Calc!$W$5:$W$1369,Calc!$A$5:$A$1369,A16) -> 2.627822 | M16: =SUMIFS(Calc!$X$5:$X$1369,Calc!$A$5:$A$1369,A16) -> 0.89458407 | N16: =SUMIFS(Calc!$AC$5:$AC$1369,Calc!$A$5:$A$1369,A16) -> 0.20323947 | O16: =SUMIFS(Calc!$AD$5:$AD$1369,Calc!$A$5:$A$1369,A16) -> 0.62452295 | P16: =SUMIFS(Calc!$AE$5:$AE$1369,Calc!$A$5:$A$1369,A16) -> 0.34090632 | Q16: =SUMIFS(Calc!$AF$5:$AF$1369,Calc!$A$5:$A$1369,A16) -> -0.55367775 | R16: =IFERROR(N16/E16,"") -> 9.7837297e-05 | S16: =IFERROR(P16/E16,"") -> 0.00016410864 | T16: =IFERROR(Q16/E16,"") -> -0.00026653452 | U16: =SUMIFS(Calc!$AG$5:$AG$1369,Calc!$A$5:$A$1369,A16) -> -1.5445228 | V16: =SUMIFS(Calc!$AH$5:$AH$1369,Calc!$A$5:$A$1369,A16) -> -2.5353678 | W16: =SUMIFS(Calc!$Y$5:$Y$1369,Calc!$A$5:$A$1369,A16) -> 19.8169 | X16: =IFERROR(N16/W16*1000,"") -> 10.255866 | Y16: =IFERROR(P16/W16*1000,"") -> 17.202808 | Z16: =IFERROR(Q16/W16*1000,"") -> -27.939675 | AA16: =SUMIFS(Calc!$AM$5:$AM$1369,Calc!$A$5:$A$1369,A16) -> -0.36228121 | AB16: =SUMIFS(Calc!$AN$5:$AN$1369,Calc!$A$5:$A$1369,A16) -> 101.33866 | AC16: =Country_Data!DY16 -> 0.13 | AD16: =IF(Country_Data!BD16="","",Country_Data!BD16) | AE16: =IF(Country_Data!BC16="","",Country_Data!BC16) | AF16: =IF(Country_Data!BL16="","",Country_Data!BL16) | AG16: =IF(Country_Data!BA16="","",Country_Data!BA16) -> 49.701
... A199: =Country_Data!A199 -> TUV | B199: =Country_Data!B199 -> Tuvalu | C199: =Country_Data!E199 -> EMDC | D199: =Country_Data!D199 -> Upper middle income | E199: =Country_Data!BV199 -> 0.064843686 | F199: =SUMIFS(Calc!$J$5:$J$1369,Calc!$A$5:$A$1369,A199) -> 0.0023782306 | G199: =IFERROR(F199/E199,"") -> 0.036676363 | H199: =SUMIFS(Calc!$L$5:$L$1369,Calc!$A$5:$A$1369,A199) -> 0.00057077534 | I199: =IFERROR(H199/E199,"") -> 0.0088023272 | J199: =Country_Data!DW199 -> 0.105 | K199: =Country_Data!DV199 -> Group default (IHLEG) | L199: =SUMIFS(Calc!$W$5:$W$1369,Calc!$A$5:$A$1369,A199) -> 4.2387135e-05 | M199: =SUMIFS(Calc!$X$5:$X$1369,Calc!$A$5:$A$1369,A199) -> 5.4287106e-05 | N199: =SUMIFS(Calc!$AC$5:$AC$1369,Calc!$A$5:$A$1369,A199) -> 2.4449162e-05 | O199: =SUMIFS(Calc!$AD$5:$AD$1369,Calc!$A$5:$A$1369,A199) -> 4.7457831e-05 | P199: =SUMIFS(Calc!$AE$5:$AE$1369,Calc!$A$5:$A$1369,A199) -> 3.555517e-06 | Q199: =SUMIFS(Calc!$AF$5:$AF$1369,Calc!$A$5:$A$1369,A199) -> -5.0731589e-05 | R199: =IFERROR(N199/E199,"") -> 0.00037704769 | S199: =IFERROR(P199/E199,"") -> 5.4832124e-05 | T199: =IFERROR(Q199/E199,"") -> -0.00078236745 | U199: =SUMIFS(Calc!$AG$5:$AG$1369,Calc!$A$5:$A$1369,A199) -> -6.5366522e-05 | V199: =SUMIFS(Calc!$AH$5:$AH$1369,Calc!$A$5:$A$1369,A199) -> -8.0001454e-05 | W199: =SUMIFS(Calc!$Y$5:$Y$1369,Calc!$A$5:$A$1369,A199) -> 0.00029269865 | X199: =IFERROR(N199/W199*1000,"") -> 83.530149 | Y199: =IFERROR(P199/W199*1000,"") -> 12.147364 | Z199: =IFERROR(Q199/W199*1000,"") -> -173.32362 | AA199: =SUMIFS(Calc!$AM$5:$AM$1369,Calc!$A$5:$A$1369,A199) -> 8.7056853e-05 | AB199: =SUMIFS(Calc!$AN$5:$AN$1369,Calc!$A$5:$A$1369,A199) -> 0.0030124254 | AC199: =Country_Data!DY199 -> 0.4 | AD199: =IF(Country_Data!BD199="","",Country_Data!BD199) -> 1 | AE199: =IF(Country_Data!BC199="","",Country_Data!BC199) -> 170.025 | AF199: =IF(Country_Data!BL199="","",Country_Data!BL199) | AG199: =IF(Country_Data!BA199="","",Country_Data!BA199) -> 6.957

Sheet Sensitivity
A1: Sensitivity: incremental cost, 2030 (USD bn a year), one input changed at a time
A2: STATIC VALUES written by build/run_sensitivity.py from the inputs as they stood when it ran. Re-run the script after changing inputs. Positive = net cost; negative = net saving.
A4: Case | B4: Inputs changed | C4: World (a) market | D4: World (b) WB 6% | E4: World (c) WB + co-ben. | F4: EMDC (a) | G4: EMDC (b) | H4: EMDC (c) | I4: World dI | J4: Abatement (Mt/yr) | K4: World (b) USD/t
A5: Base case (v1.1 defaults) | B5: - | C5: 39.674113 | D5: 37.872774 | E5: -42.52485 | F5: 25.947919 | G5: 13.163886 | H5: -13.409846 | I5: 1702.62 | J5: 921.08623 | K5: 41.117512
A6: v1.0 calibrated benefits for power and transport | B6: p_eng=0 | C6: -7.0604189 | D6: -8.8617573 | E6: -166.39864 | F6: 20.135048 | G6: 7.3510146 | H6: -38.928999 | I6: 1702.62 | J6: 641.50086 | K6: -13.8141
A7: Grids credited with generation benefits | B7: p_grid_credit=1 | C7: 18.469397 | D7: 16.668059 | E7: -79.369886 | F7: 20.492838 | G7: 7.7088053 | H7: -22.079149 | I7: 1702.62 | J7: 1250.1296 | K7: 13.333065
A8: EV premium USD 2,500 | B8: p_ev_prem=2500 | C8: 9.4695796 | D8: 7.6682412 | E8: -77.943356 | F8: 17.55033 | G8: 4.7662969 | H8: -23.086418 | I8: 1702.62 | J8: 998.85261 | K8: 7.6770497
A9: EV premium USD 10,000 | B9: p_ev_prem=10000 | C9: 54.776379 | D9: 52.975041 | E9: -24.815597 | F9: 30.146714 | G9: 17.362681 | H9: -8.5715593 | I9: 1702.62 | J9: 882.20303 | K9: 60.048581
A10: Renewable capex -25% | B10: p_capex_pv=570, p_capex_wind=870 | C10: 26.96732 | D10: 25.165982 | E10: -62.556289 | F10: 22.742376 | G10: 9.9583435 | H10: -18.133958 | I10: 1702.62 | J10: 1080.1468 | K10: 23.298667
A11: Renewable capex +25% | B11: p_capex_pv=950, p_capex_wind=1450 | C11: 47.298188 | D11: 45.49685 | E11: -30.505986 | F11: 27.871245 | G11: 15.087212 | H11: -10.575378 | I11: 1702.62 | J11: 825.64987 | K11: 55.10429
A12: Calibrated savings b -50% (buildings, industry) | B12: p_b=0.0665 | C12: 60.218143 | D12: 58.416805 | E12: -21.980819 | F12: 30.189684 | G12: 17.405651 | H12: -9.1680807 | I12: 1702.62 | J12: 921.08623 | K12: 63.421647
A13: Calibrated savings b +50% (buildings, industry) | B13: p_b=0.1995 | C13: 19.130082 | D13: 17.328743 | E13: -63.068881 | F13: 21.706155 | G13: 8.9221215 | H13: -17.65161 | I13: 1702.62 | J13: 921.08623 | K13: 18.813378
A14: Co-benefits c -50% (buildings, industry, AFOLU) | B14: p_c=0.0645 | C14: 39.674113 | D14: 37.872774 | E14: -15.919995 | F14: 25.947919 | G14: 13.163886 | H14: -3.0403253 | I14: 1702.62 | J14: 921.08623 | K14: 41.117512
A15: EMDC default WACC 15% | B15: p_r_emdc=0.15 | C15: 44.31363 | D15: 37.872774 | E15: -42.52485 | F15: 30.587436 | G15: 13.163886 | H15: -13.409846 | I15: 1702.62 | J15: 921.08623 | K15: 41.117512
A16: Rates compared in real terms | B16: p_basis=1 | C16: 14.478466 | D16: 37.872774 | E16: -42.52485 | F16: 17.808683 | G16: 13.163886 | H16: -13.409846 | I16: 1702.62 | J16: 921.08623 | K16: 41.117512
... A19: Incremental shares halved | B19: p_inc_ae=0.19, p_inc_chn=0.19, p_inc_emdc=0.12 | C19: 19.837056 | D19: 18.936387 | E19: -21.262425 | F19: 12.97396 | G19: 6.5819432 | H19: -6.7049228 | I19: 851.31 | J19: 460.54311 | K19: 41.117512

Sheet Inputs
A1: Inputs and scenario levers
A2: Blue = hard-coded input. Yellow fill = key assumption to review. † = not verified against the primary source, or an author's assumption. All money in USD billion, 2023 prices (IHLEG basis), unless stated.
A4: Key (named cell) | B4: Parameter | C4: Value | D4: Unit | E4: Source / note | F4: Fit
A5: Investment pools, 2030 (mitigation only)
A6: p_ce_world | B6: Clean energy investment need, world, 2030 | C6: 4800 | D6: USD bn/yr | E6: IHLEG 3 (Bhattacharya et al. 2024), clean energy from IEA; method note Table 4 | F6: G
A7: p_ce_emdc | B7: Clean energy, EMDCs other than China | C7: 1600 | D7: USD bn/yr | E7: IHLEG 3 (2024): EMDCs ex-China clean energy USD 1.6 tn; method note Table 4 | F7: G
A8: p_ce_chn | B8: Clean energy, China | C8: 850 | D8: USD bn/yr | E8: Derived: IEA-IFC (2023) EMDE 2.2-2.8 tn less EMDE ex-China 1.4-1.9 tn (midpoints 2.5 - 1.65). † | F8: M
A9: p_ce_ae | B9: Clean energy, advanced economies (residual) | C9: =p_ce_world-p_ce_emdc-p_ce_chn -> 2350 | D9: USD bn/yr | E9: Residual of the three lines above | F9: M
A10: p_nat_emdc | B10: Nature and agriculture (AFOLU), EMDCs ex-China | C10: 350 | D10: USD bn/yr | E10: IHLEG 3 (2024): nature and agriculture USD 0.3-0.4 tn, midpoint. Includes some non-mitigation nature spending. † | F10: M
A11: p_nbs_world | B11: Nature-based solutions, world, 2030 | C11: 399 | D11: USD bn/yr | E11: UNEP State of Finance for Nature (2021): NbS flows USD 133 bn/yr must triple by 2030 (133 x 3) | F11: M
A12: p_nat_ae | B12: AFOLU, advanced economies | C12: =MAX(0,p_nbs_world-p_nat_emdc)*p_ce_ae/(p_ce_ae+p_ce_chn) -> 35.984375 | D12: USD bn/yr | E12: World NbS less EMDC, split AE/China pro rata to clean energy. † | F12: P
A13: p_nat_chn | B13: AFOLU, China | C13: =MAX(0,p_nbs_world-p_nat_emdc)*p_ce_chn/(p_ce_ae+p_ce_chn) -> 13.015625 | D13: USD bn/yr | E13: As above. † | F13: P
A14: Sector split of clean energy (applied to every group; edit per group on Sector_Params)
A15: p_sh_gen | B15: Low-emission power generation | C15: 0.35 | D15: share | E15: IEA-IFC (2023), EMDEs early 2030s: 'just over a third' to low-emission generation | F15: M
A16: p_sh_grid | B16: Grids and storage | C16: 0.24 | D16: share | E16: IEA-IFC (2023): 'just under a quarter' | F16: M
A17: p_sh_end | B17: Efficiency and end use | C17: 0.33 | D17: share | E17: IEA-IFC (2023): 'another third' | F17: M
A18: p_sh_fuel | B18: Low-emission fuels and fuel supply | C18: 0.08 | D18: share | E18: IEA-IFC (2023): 'around 8%' | F18: M
A19: p_spl_trn | B19: of end use: transport | C19: 0.45 | D19: share of end use | E19: Author's assumption: EVs and charging are the largest end-use item. † | F19: P
A20: p_spl_bld | B20: of end use: buildings | C20: 0.35 | D20: share of end use | E20: Author's assumption. † | F20: P
A21: p_spl_ind | B21: of end use: industry | C21: =1-p_spl_trn-p_spl_bld -> 0.2 | D21: share of end use | E21: Residual | F21: P
A22: Total vs incremental
A23: p_inc_ae | B23: Incremental share of total, advanced economies | C23: 0.38 | D23: share | E23: McKinsey (2022): +USD 3.5 tn over today on USD 9.2 tn gross (3.5/9.2). Method note Table 5 | F23: M
A24: p_inc_chn | B24: Incremental share of total, China | C24: 0.38 | D24: share | E24: As AE (McKinsey global ratio). † | F24: M
A25: p_inc_emdc | B25: Incremental share of total, EMDCs | C25: 0.24 | D25: share | E25: CCDR synthesis USD 574 bn/yr incremental vs IHLEG USD 2.4 tn total (about a quarter). Method note Table 5 | F25: M
A26: Cost of capital (lens a: market)
A27: p_r_ae | B27: Market WACC, advanced economies (default) | C27: 0.055 | D27: rate | E27: IEA via IHLEG (2024): solar WACC 5-6% in AEs. Used where no country estimate exists | F27: M
A28: p_r_chn | B28: Market WACC, China (default) | C28: 0.06 | D28: rate | E28: Method note: assumed close to AEs. † | F28: M
A29: p_r_emdc | B29: Market WACC, EMDCs (default) | C29: 0.105 | D29: rate | E29: IEA via IHLEG (2024): 9-12% in EMDCs, midpoint | F29: M
A30: p_rh_ae | B30: High case WACC, advanced economies | C30: 0.07 | D30: rate | E30: Method note lens (a) high case | F30: M
A31: p_rh_chn | B31: High case WACC, China | C31: 0.08 | D31: rate | E31: Method note lens (a) high case | F31: M
A32: p_rh_emdc | B32: High case WACC, EMDCs | C32: 0.15 | D32: rate | E32: Method note lens (a) high case | F32: M
A33: p_use_obs | B33: Use observed country WACC (IRENA / Steffen)? 1=yes | C33: 1 | D33: switch | E33: Dashboard Finance 1 block. Average of the available observations
A34: p_use_dam | B34: Use Damodaran-based WACC where no observation? 1=yes | C34: 1 | D34: switch | E34: Fills coverage gaps from the Damodaran sheet (equation 5)
A35: p_calib | B35: Calibrate Damodaran WACC to observed level? 1=yes | C35: 1 | D35: switch | E35: Shifts the structural estimate by the mean gap to observed WACC over countries with both
A36: p_basis | B36: Rate basis: 0 = nominal (as published), 1 = real | C36: 0 | D36: switch | E36: IHLEG, IEA, Steffen and the 6% WB rate are compared as published in the method note (0). Set 1 to deflate market rates to real terms with the inflation input
A37: p_infl | B37: Inflation for real/nominal conversion (USD) | C37: 0.02 | D37: rate | E37: Assumption: long-run USD inflation. Also converts IRENA real WACC to nominal. † | F37: M
A38: Damodaran WACC build (equation 5) - used only where Damodaran data are present
A39: p_rf | B39: Risk-free rate (US 10-year Treasury) | C39: 0.042 | D39: rate | E39: Placeholder: approximate 2025-26 level. Update to the date of the Damodaran file. † | F39: M
A40: p_erp | B40: Mature-market equity risk premium | C40: 0.042 | D40: rate | E40: Damodaran, July 2026 update (4.20%), as reported by BVWire 22 Jul 2026. Check against ctryprem.xlsx | F40: M
A41: p_dv | B41: Debt share D/V, renewable projects | C41: 0.7 | D41: share | E41: Steffen et al. (2025) database, median 'Leverage (debt share)', all observations | F41: G
...

Sheet Sector_Params
A1: Sector parameters and 2030 investment pools by group (USD bn/yr)
A2: Blue cells are editable. Incremental shares default to the group values on Inputs; overwrite a cell to set a sector-specific share. Technology premium is added to the country market WACC in lens (a) only.
A4: Code | B4: Sector | C4: Share of clean energy | D4: Asset life (yrs) | E4: Tech premium (lens a) | F4: Incr. share AE | G4: Incr. share China | H4: Incr. share EMDC | I4: Savings multiplier (b) | J4: Co-benefit multiplier (c) | K4: Benefit method (v1.1) | L4: Allocation driver | M4: Life source
A5: GEN | B5: Power generation (low-emission) | C5: =p_sh_gen -> 0.35 | D5: 25 | E5: 0 | F5: =p_inc_ae -> 0.38 | G5: =p_inc_chn -> 0.38 | H5: =p_inc_emdc -> 0.24 | I5: 1 | J5: 1 | K5: Engineering: displaced fossil power (Ember mix x heat rates x CPAT fuel cost, air pollution; IPCC CO2 factors) | L5: Electricity demand (TWh) | M5: Method note: 25 yrs (solar 25-30, wind 25)
A6: GRID | B6: Grids and storage | C6: =p_sh_grid -> 0.24 | D6: 40 | E6: 0 | F6: =p_inc_ae -> 0.38 | G6: =p_inc_chn -> 0.38 | H6: =p_inc_emdc -> 0.24 | I6: 1 | J6: 1 | K6: Enabling: no own benefits; p_grid_credit x generation benefits | L6: Electricity demand (TWh) | M6: Method note: grids 40 yrs (storage 15 - blended up)
A7: TRN | B7: Transport (EVs, charging, transit) | C7: =p_sh_end*p_spl_trn -> 0.1485 | D7: 12 | E7: 0 | F7: =p_inc_ae -> 0.38 | G7: =p_inc_chn -> 0.38 | H7: =p_inc_emdc -> 0.24 | I7: 1 | J7: 1 | K7: Engineering: EV vs gasoline car per vehicle (CPAT fuel and power prices, gasoline air pollution) | L7: Road fuel energy (EJ) | M7: Method note: vehicles 12 yrs
A8: BLD | B8: Buildings (efficiency, heat pumps) | C8: =p_sh_end*p_spl_bld -> 0.1155 | D8: 25 | E8: 0 | F8: =p_inc_ae -> 0.38 | G8: =p_inc_chn -> 0.38 | H8: =p_inc_emdc -> 0.24 | I8: 1 | J8: 1 | K8: Calibrated: SISEPUEDE b and c x CPAT country index; a = p_a | L8: Building energy use (EJ) | M8: Method note: 20-30 yrs
A9: IND | B9: Industry (efficiency, electrification, CCS) | C9: =p_sh_end*p_spl_ind -> 0.066 | D9: 25 | E9: 0 | F9: =p_inc_ae -> 0.38 | G9: =p_inc_chn -> 0.38 | H9: =p_inc_emdc -> 0.24 | I9: 1 | J9: 1 | K9: Calibrated: SISEPUEDE b and c x CPAT country index; a = p_a | L9: Industrial energy use (EJ) | M9: Method note: CCS 25 yrs
A10: FUEL | B10: Low-emission fuels and fuel supply | C10: =p_sh_fuel -> 0.08 | D10: 20 | E10: 0 | F10: =p_inc_ae -> 0.38 | G10: =p_inc_chn -> 0.38 | H10: =p_inc_emdc -> 0.24 | I10: 1 | J10: 1 | K10: Cost per tonne: no savings or co-benefits; a = 1000 x CRF(6%) / p_cpt_fuel | L10: Fossil energy supply (EJ) | M10: Assumption †
A11: AFOLU | B11: AFOLU and nature | C11: n.a. | D11: 30 | E11: 0 | F11: =p_inc_ae -> 0.38 | G11: =p_inc_chn -> 0.38 | H11: =p_inc_emdc -> 0.24 | I11: 1 | J11: 1 | K11: Cost per tonne: no savings; c = p_c (ecosystem co-benefits); a = 1000 x CRF(6%) / p_cpt_afolu | L11: Non-CO2 GHG + net LULUCF source (MtCO2e) | M11: Assumption †
B12: Total (energy sectors) | C12: =SUM(C5:C10) -> 1
A14: Investment pools, 2030 (USD bn/yr, total investment)
A15: Code | B15: Sector | C15: AE | D15: China | E15: EMDC | F15: World
A16: GEN | B16: Power generation (low-emission) | C16: =p_ce_ae*C5 -> 822.5 | D16: =p_ce_chn*C5 -> 297.5 | E16: =p_ce_emdc*C5 -> 560 | F16: =SUM(C16:E16) -> 1680
A17: GRID | B17: Grids and storage | C17: =p_ce_ae*C6 -> 564 | D17: =p_ce_chn*C6 -> 204 | E17: =p_ce_emdc*C6 -> 384 | F17: =SUM(C17:E17) -> 1152
A18: TRN | B18: Transport (EVs, charging, transit) | C18: =p_ce_ae*C7 -> 348.975 | D18: =p_ce_chn*C7 -> 126.225 | E18: =p_ce_emdc*C7 -> 237.6 | F18: =SUM(C18:E18) -> 712.8
A19: BLD | B19: Buildings (efficiency, heat pumps) | C19: =p_ce_ae*C8 -> 271.425 | D19: =p_ce_chn*C8 -> 98.175 | E19: =p_ce_emdc*C8 -> 184.8 | F19: =SUM(C19:E19) -> 554.4
A20: IND | B20: Industry (efficiency, electrification, CCS) | C20: =p_ce_ae*C9 -> 155.1 | D20: =p_ce_chn*C9 -> 56.1 | E20: =p_ce_emdc*C9 -> 105.6 | F20: =SUM(C20:E20) -> 316.8
A21: FUEL | B21: Low-emission fuels and fuel supply | C21: =p_ce_ae*C10 -> 188 | D21: =p_ce_chn*C10 -> 68 | E21: =p_ce_emdc*C10 -> 128 | F21: =SUM(C21:E21) -> 384
A22: AFOLU | B22: AFOLU and nature | C22: =p_nat_ae -> 35.984375 | D22: =p_nat_chn -> 13.015625 | E22: =p_nat_emdc -> 350 | F22: =SUM(C22:E22) -> 399
B23: Total | C23: =SUM(C16:C22) -> 2385.9844 | D23: =SUM(D16:D22) -> 863.01562 | E23: =SUM(E16:E22) -> 1950 | F23: =SUM(F16:F22) -> 5199

Sheet Country_Data
A1: Country data (inputs from the dashboard panel, CPAT and WEO) and country parameters (formulas)
A2: Blue = data loaded by the build script; black = formulas. Blank = not available (nothing imputed). Rates as fractions.
A3: iso | B3: name | C3: region | D3: income | E3: group | F3: gdp24 | G3: ppp24 | H3: g25 | I3: g26 | J3: mit.pop.mn | K3: mit.co2.tot.1 | L3: mit.ghg.tot.exc.1 | M3: mit.ghg.tot.inc.1 | N3: mit.con.ecy.ind.1 | O3: mit.con.ecy.res.1 | P3: mit.con.ecy.other.1 | Q3: mit.con.nga.ind.1 | R3: mit.con.nga.res.1 | S3: mit.con.nga.pow.1 | T3: mit.con.nga.other.1 | U3: mit.con.coa.ind.1 | V3: mit.con.coa.res.1 | W3: mit.con.coa.pow.1 | X3: mit.con.coa.other.1 | Y3: mit.con.gso.all.1 | Z3: mit.con.die.all.1 | AA3: mit.con.lpg.all.1 | AB3: mit.con.ker.all.1 | AC3: mit.con.oop.all.1 | AD3: mit.sup.cost.gso.all.1 | AE3: mit.sup.cost.die.all.1 | AF3: mit.sup.cost.lpg.all.1 | AG3: mit.sup.cost.ker.all.1 | AH3: mit.sup.cost.oop.all.1 | AI3: mit.sup.cost.coa.ind.1 | AJ3: mit.sup.cost.coa.res.1 | AK3: mit.sup.cost.coa.pow.1 | AL3: mit.sup.cost.coa.other.1 | AM3: mit.sup.cost.nga.ind.1 | AN3: mit.sup.cost.nga.res.1 | AO3: mit.sup.cost.nga.pow.1 | AP3: mit.sup.cost.nga.other.1 | AQ3: mit.airpol.con.all.all.1 | AR3: mit.con.con.all.all.1 | AS3: mit.roda.con.all.all.1 | AT3: mit.rodd.con.all.all.1 | AU3: mit.ecy.renshare.1 | AV3: mit.sup.cost.ecy.res.1 | AW3: mit.airpol.cost.coa.pow.1 | AX3: mit.airpol.cost.nga.pow.1 | AY3: mit.airpol.cost.oop.1 | AZ3: mit.airpol.cost.gso.all.1 | BA3: gross_debt_pct_gdp | BB3: interest_to_revenue_pct | BC3: capex_execution_rate_pct | BD3: pefa_pi11_pim_score | BE3: pefa_pi122_asset_monitoring | BF3: climate_pfm_diagnostic_on_record | BG3: wacc_solar_real_aftertax_pct | BH3: wacc_steffen_nominal_aftertax_pct | BI3: wacc_steffen_nominal_aftertax_pct__year | BJ3: wacc_n_sources | BK3: wacc_iea_observatory_available | BL3: ids_official_private_rate_spread_pp | BM3: ids_private_creditor_rate_pct | BN3: ids_avg_maturity_years | BO3: mitigation_finance_received_pct_gdp | BP3: ppi_commitments_pct_gdp | BQ3: em_year | BR3: em_Total generation | BS3: em_Coal | BT3: em_Gas | BU3: em_Other fossil | BV3: gdp30 | BW3: ppp_use | BX3: plevel | BY3: has_cpat | BZ3: elec | CA3: d_trn | CB3: d_bld | CC3: d_ind | CD3: d_fuel | CE3: d_afolu | CF3: fuelexp | CG3: co2_pos | CH3: fc_t | CI3: lext | CJ3: cb_t | CK3: idx_b | CL3: idx_c | CM3: b_c | CN3: c_c | CO3: fos_sh | CP3: fos_tot | CQ3: sh_coal | CR3: sh_gas | CS3: sh_oil | CT3: re_kwh | CU3: gen_ok | CV3: fuel_mwh | CW3: co2_mwh | CX3: ap_mwh | CY3: grid_ef | CZ3: b_gen | DA3: c_gen | DB3: a_gen | DC3: trn_ok | DD3: ev_sav | DE3: b_trn | DF3: c_trn | DG3: a_trn | DH3: dam_ds | DI3: dam_crp | DJ3: dam_tax | DK3: w_irena | DL3: w_stef | DM3: w_obs | DN3: w_dam | DO3: ovl | DP3: ovl_obs | DQ3: ovl_dam | DR3: w_damc | DS3: w_grp | DT3: w_grph | DU3: w_sel_n | DV3: w_src | DW3: r_a | DX3: r_ah | DY3: pim_gap | DZ3: pim_src | EA3: pub_sh | EB3: pim_mult | EC3: inv_tot | ED3: fc_wI | EE3: cb_wI | EF3: w_I
A4: ISO3 | B4: Country | C4: WB region | D4: WB income group | E4: IHLEG group (AE / China / EMDC) | F4: GDP 2024 (USD bn), WEO | G4: GDP 2024 (PPP int$ bn), WEO | H4: Real growth 2025 (%), WEO | I4: Real growth 2026 (%), WEO | J4: Population (mn), CPAT 2024 | K4: CO2, energy (Mt), CPAT 2024 | L4: GHG excl. LULUCF (MtCO2e), CPAT 2024 | M4: GHG incl. LULUCF (MtCO2e), CPAT 2024 | N4: Electricity, industry (TWh), CPAT 2024 | O4: Electricity, residential (TWh), CPAT 2024 | P4: Electricity, other (TWh), CPAT 2024 | Q4: Gas, industry (EJ), CPAT 2024 | R4: Gas, residential (EJ), CPAT 2024 | S4: Gas, power (EJ), CPAT 2024 | T4: Gas, other (EJ), CPAT 2024 | U4: Coal, industry (EJ), CPAT 2024 | V4: Coal, residential (EJ), CPAT 2024 | W4: Coal, power (EJ), CPAT 2024 | X4: Coal, other (EJ), CPAT 2024 | Y4: Gasoline (bn litres), CPAT 2024 | Z4: Diesel (bn litres), CPAT 2024 | AA4: LPG (bn litres), CPAT 2024 | AB4: Kerosene (bn litres), CPAT 2024 | AC4: Other oil products (bn litres), CPAT 2024 | AD4: Supply cost gasoline ($/l), CPAT 2024 | AE4: Supply cost diesel ($/l), CPAT 2024 | AF4: Supply cost LPG ($/l), CPAT 2024 | AG4: Supply cost kerosene ($/l), CPAT 2024 | AH4: Supply cost other oil ($/l), CPAT 2024 | AI4: Supply cost coal, industry ($/GJ), CPAT 2024 | AJ4: Supply cost coal, residential ($/GJ), CPAT 2024 | AK4: Supply cost coal, power ($/GJ), CPAT 2024 | AL4: Supply cost coal, other ($/GJ), CPAT 2024 | AM4: Supply cost gas, industry ($/GJ), CPAT 2024 | AN4: Supply cost gas, residential ($/GJ), CPAT 2024 | AO4: Supply cost gas, power ($/GJ), CPAT 2024 | AP4: Supply cost gas, other ($/GJ), CPAT 2024 | AQ4: Local air pollution cost (US$ bn), CPAT 2024 | AR4: Congestion cost (US$ bn), CPAT 2024 | AS4: Road accident cost (US$ bn), CPAT 2024 | AT4: Road damage cost (US$ bn), CPAT 2024 | AU4: Renewable share of electricity (CPAT), CPAT 2024 | AV4: Supply cost electricity, residential ($/kWh), CPAT 2024 | AW4: Air pollution cost coal, power ($/GJ), CPAT 2024 | AX4: Air pollution cost gas, power ($/GJ), CPAT 2024 | AY4: Air pollution cost other oil ($/l), CPAT 2024 | AZ4: Air pollution cost gasoline ($/l), CPAT 2024 | BA4: Gross debt, gen. govt (% GDP) [dashboard: Fiscal] | BB4: Interest-to-revenue (%) [dashboard: Fiscal] | BC4: Capex execution rate (%) [dashboard: PIMA] | BD4: PEFA PI-11 PIM score (1-4) [dashboard: PIMA] | BE4: PEFA PI-12.2 asset monitoring (1-4) [dashboard: PIMA] | BF4: Climate-PFM diagnostic on record (0/1) [dashboard: PIMA] | BG4: WACC solar, real after-tax (%), IRENA 2021 [dashboard: CoC] | BH4: WACC nominal after-tax (%), Steffen et al. [dashboard: CoC] | BI4: Steffen observation year [dashboard: CoC] | BJ4: WACC evidence strength (0-3) [dashboard: CoC] | BK4: IEA CoC Observatory (0/1) [dashboard: CoC] | BL4: Official-private rate spread (pp), IDS [dashboard: CoC] | BM4: Private creditor rate (%), IDS [dashboard: CoC] | BN4: Avg maturity new commitments (yrs), IDS [dashboard: CoC] | BO4: Mitigation finance received (% GDP), OECD [dashboard: Finance] | BP4: PPI commitments (% GDP) [dashboard: Finance] | BQ4: Ember year | BR4: Generation, total (TWh), Ember | BS4: Coal (TWh), Ember | BT4: Gas (TWh), Ember | BU4: Other fossil (TWh), Ember | BV4: GDP 2030 (USD bn, 2024 prices) | BW4: GDP PPP used for weights | BX4: Price level (GDP USD / GDP PPP) | BY4: CPAT data? (1/0) | BZ4: Electricity demand (TWh) | CA4: Road fuel energy (EJ) | CB4: Building energy use (EJ) | CC4: Industrial energy use (EJ) | CD4: Fossil energy supply (EJ) | CE4: Non-CO2 GHG + net LULUCF source (MtCO2e) | CF4: Fossil fuel bill at supply cost (USD bn) | CG4: CO2 used in index (Mt) | CH4: Fuel bill per tCO2 (USD/t) | CI4: Local externality cost (USD bn) | CJ4: Local co-benefit per tCO2 (USD/t) | CK4: Fuel-cost index (world = 1) | CL4: Co-benefit index (world = 1) | CM4: Savings ratio b (per yr) | CN4: Co-benefit ratio c (per yr) | CO4: Fossil share of generation, Ember | CP4: helper: fossil generation (TWh) | CQ4: Coal share of fossil generation | CR4: Gas share of fossil generation | CS4: Oil/other share of fossil generation | CT4: RE output per USD 1,000 (kWh/yr) | CU4: Engineering power data complete? (1/0) | CV4: Fuel cost of displaced fossil power (USD/MWh) | CW4: CO2 of displaced fossil power (t/MWh) | CX4: Air pollution of displaced fossil power (USD/MWh) | CY4: Average grid CO2 (t/MWh) | CZ4: b power: fuel saved per $ less RE O&M | DA4: c power: air pollution avoided per $ | DB4: a power: tCO2/yr per $1,000 | DC4: Engineering transport data complete? (1/0) | DD4: EV saving per vehicle (USD/yr) | DE4: b transport: saving per $ of premium | DF4: c transport: air pollution avoided per $ | DG4: a transport: tCO2/yr per $1,000 | DH4: Damodaran default spread | DI4: Damodaran country risk premium | DJ4: Damodaran corporate tax | DK4: IRENA WACC, nominal | DL4: Steffen WACC, nominal | DM4: Observed WACC (avg of available), nominal | DN4: Damodaran WACC (eq. 5), nominal | DO4: Overlap obs & Damodaran (1/0) | DP4: helper: obs if overlap | DQ4: helper: Damodaran if overlap | DR4: Damodaran WACC, calibrated | DS4: Group default WACC | DT4: Group high-case WACC | DU4: Market WACC selected, nominal | DV4: WACC source | DW4: Lens (a) rate, central | DX4: Lens (a) rate, high | DY4: PIM efficiency gap | DZ4: PIM gap source | EA4: Public share of investment | EB4: PIMA multiplier on investment | EC4: Total investment I (from Results_Country) | ED4: helper: fuel bill per t x I | EE4: helper: co-benefit per t x I | EF4: helper: I where CPAT data
