Workbook
Name p_g_lr_lic: Inputs!$F$8
Name p_g_lr_lmic: Inputs!$F$9
Name p_g_lr_umic: Inputs!$F$10
Name p_g_lr_hic: Inputs!$F$11
Name p_g_conv_year: Inputs!$F$12
Name p_phi: Inputs!$F$13
Name p_pow_T_ae: Inputs!$F$14
Name p_pow_T_chn: Inputs!$F$15
Name p_pow_T_emdc: Inputs!$F$16
Name p_ev_T_ae: Inputs!$F$17
Name p_ev_T_chn: Inputs!$F$18
Name p_ev_T_emdc: Inputs!$F$19
Name p_bld_T_ae: Inputs!$F$20
Name p_bld_T_chn: Inputs!$F$21
Name p_bld_T_emdc: Inputs!$F$22
Name p_ind_a_ae: Inputs!$F$23
Name p_ind_a_chn: Inputs!$F$24
Name p_ind_a_emdc: Inputs!$F$25
Name p_ev0_ae: Inputs!$F$26
Name p_ev0_chn: Inputs!$F$27
Name p_ev0_emdc: Inputs!$F$28
Name p_evb35_ae: Inputs!$F$29
Name p_evb35_chn: Inputs!$F$30
Name p_evb35_emdc: Inputs!$F$31
Name p_sig0_ratio: Inputs!$F$32
Name p_fos_trend_cap: Inputs!$F$33
Name p_ev_ratio: Inputs!$F$34
Name p_hp_ratio: Inputs!$F$35
Name p_ind_elec_sh: Inputs!$F$36
Name p_ind_ratio: Inputs!$F$37
Name p_veh_gj: Inputs!$F$38
Name p_veh_life: Inputs!$F$39
Name p_ev_prem24: Inputs!$F$40
Name p_ev_parity: Inputs!$F$41
Name p_charger: Inputs!$F$42
Name p_ev_maint: Inputs!$F$43
Name p_veh_km: Inputs!$F$44
Name p_k_bld: Inputs!$F$45
Name p_k_ind: Inputs!$F$46
Name p_k_ccs: Inputs!$F$47
Name p_cbam_a_2050: Inputs!$F$48
Name p_capex_sol24: Inputs!$F$49
Name p_capex_wnd24: Inputs!$F$50
Name p_capex_gas: Inputs!$F$51
Name p_lr_sol: Inputs!$F$52
Name p_lr_wnd: Inputs!$F$53
Name p_cf_sol: Inputs!$F$54
Name p_cf_wnd: Inputs!$F$55
Name p_cf_fos: Inputs!$F$56
Name p_sh_sol: Inputs!$F$57
Name p_life_vre: Inputs!$F$58
Name p_life_fos: Inputs!$F$59
Name p_om_vre: Inputs!$F$60
Name p_om_fos: Inputs!$F$61
Name p_grid_ratio: Inputs!$F$62
Name p_st_h: Inputs!$F$63
Name p_capex_st24: Inputs!$F$64
Name p_lr_st: Inputs!$F$65
Name p_hr_coa: Inputs!$F$66
Name p_hr_nga: Inputs!$F$67

Sheet ReadMe
A1: NMIM v0.2 - National Mitigation Investment Model (simplified)
A3: What it is | B3: A simplified national model of net zero mitigation investment for 186 countries, annual 2024-2050, built to CPAT norms. For each country it projects baseline (current trends) and net zero energy use, power capacity, investment by sector, emissions, fuel bills and air pollution, and the incremental cost of the net zero path under three lenses: (a) market WACC, (b) World Bank 6%, (c) 6% with local co-benefits.
A4: How to use | B4: Choose a country on Settings!C4. Mitigation recalculates in live formulas (CPAT layout: K = 2021 ... N = 2024 base year ... AN = 2050). Dashboard summarises it. Inputs holds every parameter (MTInputs column structure; edit column G). Results_All holds every country from the Python engine; Check compares the two.
A5: Method | B5: See NMIM_Method_v0_2.md. Baseline end use follows CPAT's activity equation with CPAT income-group elasticities and prices fixed in real terms; net zero applies sector transformations (EV sales, heat electrification, industrial abatement, fossil-free power by group target year); power capacity is a stock model with lives and learning; clean investment not modelled bottom-up is calibrated to IEA 2024 by group and added to both scenarios; incremental cost sums capital charges on incremental capital in service.
A6: Consistency | B6: Codes and data follow CPAT (IMF CPAT 2024 panel; mit.<indicator>.<fuel>.<sector>.<scenario>). CBAM goods process CO2 comes from the CBAM Policy Tool's Country data. Market WACC is the v1.1 investment-needs workbook's (observed, Damodaran or IHLEG default).
A7: Colours | B7: Title 00B050; section 92D050; inputs EBF1DE (blue text); codes DCE6F1; base year DDD9C4; results to review FFF2CC.
A8: Typology | B8: v0.2 splits every investment line into five types by who pays (P1 pure public, P2 regulated utility, P3 contracted revenue, P4 viability gap, P5 pure private). Shares depend on the country's power market structure (PowerMarket sheet: PSRT, PPI, curated), electricity cost recovery (CPAT), market WACC, explicit fossil subsidies and income group (Mitigation section 1 and 12; Typology sheet). Direct budget need = P1 + the public gap share of P4.
A9: Caveats | B9: Simplified: no price response, no power optimisation, car-equivalent vehicles, assumed transformation dates; several formulas exceed the 100-character norm (to be split). Parameters marked † are assumptions.
A10: Version log | B10: v0.2 | 2026-10-20 | Investment typology (who pays) by country and sector; power market data (PowerMarket); industry and non-CO2 spending split into their parts; results otherwise unchanged from v0.1. v0.1 | 2026-10-20 | First build: 186 countries, 11 end-use rows, power stock model, IEA 2024 calibration of investment levels; three lenses; workbook = Python on key rows (Check).

Sheet Dashboard
A1: NMIM - Dashboard (selected country)
B3: Country | C3: =Settings!C5
B5: USD bn a year unless stated
B6: Item | C6: 2025 | D6: 2030 | E6: 2035 | F6: 2040 | G6: 2045 | H6: 2050
B7: GDP (2024 USD bn) | C7: =Mitigation!O86 | D7: =Mitigation!T86 | E7: =Mitigation!Y86 | F7: =Mitigation!AD86 | G7: =Mitigation!AI86 | H7: =Mitigation!AN86
B8: Investment, baseline | C8: =Mitigation!O220 | D8: =Mitigation!T220 | E8: =Mitigation!Y220 | F8: =Mitigation!AD220 | G8: =Mitigation!AI220 | H8: =Mitigation!AN220
B9: Investment, net zero | C9: =Mitigation!O221 | D9: =Mitigation!T221 | E9: =Mitigation!Y221 | F9: =Mitigation!AD221 | G9: =Mitigation!AI221 | H9: =Mitigation!AN221
B10: Incremental investment | C10: =Mitigation!O222 | D10: =Mitigation!T222 | E10: =Mitigation!Y222 | F10: =Mitigation!AD222 | G10: =Mitigation!AI222 | H10: =Mitigation!AN222
B11: of which power generation | C11: =Mitigation!O212 | D11: =Mitigation!T212 | E11: =Mitigation!Y212 | F11: =Mitigation!AD212 | G11: =Mitigation!AI212 | H11: =Mitigation!AN212
B12: grids and storage | C12: =Mitigation!O213 | D12: =Mitigation!T213 | E12: =Mitigation!Y213 | F12: =Mitigation!AD213 | G12: =Mitigation!AI213 | H12: =Mitigation!AN213
B13: transport | C13: =Mitigation!O214 | D13: =Mitigation!T214 | E13: =Mitigation!Y214 | F13: =Mitigation!AD214 | G13: =Mitigation!AI214 | H13: =Mitigation!AN214
B14: buildings | C14: =Mitigation!O215 | D14: =Mitigation!T215 | E14: =Mitigation!Y215 | F14: =Mitigation!AD215 | G14: =Mitigation!AI215 | H14: =Mitigation!AN215
B15: industry | C15: =Mitigation!O216 | D15: =Mitigation!T216 | E15: =Mitigation!Y216 | F15: =Mitigation!AD216 | G15: =Mitigation!AI216 | H15: =Mitigation!AN216
B16: non-CO2 and land use | C16: =Mitigation!O217 | D16: =Mitigation!T217 | E16: =Mitigation!Y217 | F16: =Mitigation!AD217 | G16: =Mitigation!AI217 | H16: =Mitigation!AN217
B17: Incremental cost (a) market WACC | C17: =Mitigation!O235 | D17: =Mitigation!T235 | E17: =Mitigation!Y235 | F17: =Mitigation!AD235 | G17: =Mitigation!AI235 | H17: =Mitigation!AN235
B18: Incremental cost (b) World Bank 6% | C18: =Mitigation!O236 | D18: =Mitigation!T236 | E18: =Mitigation!Y236 | F18: =Mitigation!AD236 | G18: =Mitigation!AI236 | H18: =Mitigation!AN236
B19: Incremental cost (c) 6% + local co-benefits | C19: =Mitigation!O237 | D19: =Mitigation!T237 | E19: =Mitigation!Y237 | F19: =Mitigation!AD237 | G19: =Mitigation!AI237 | H19: =Mitigation!AN237
B20: GHG, baseline (MtCO2e) | C20: =Mitigation!O200 | D20: =Mitigation!T200 | E20: =Mitigation!Y200 | F20: =Mitigation!AD200 | G20: =Mitigation!AI200 | H20: =Mitigation!AN200
B21: GHG, net zero (MtCO2e) | C21: =Mitigation!O206 | D21: =Mitigation!T206 | E21: =Mitigation!Y206 | F21: =Mitigation!AD206 | G21: =Mitigation!AI206 | H21: =Mitigation!AN206
B22: Net zero investment by type (see Typology) | C22: =Mitigation!O221 | D22: =Mitigation!T221 | E22: =Mitigation!Y221 | F22: =Mitigation!AD221 | G22: =Mitigation!AI221 | H22: =Mitigation!AN221
B23: P1 pure public | C23: =Mitigation!O247 | D23: =Mitigation!T247 | E23: =Mitigation!Y247 | F23: =Mitigation!AD247 | G23: =Mitigation!AI247 | H23: =Mitigation!AN247
B24: P2 regulated utility | C24: =Mitigation!O248 | D24: =Mitigation!T248 | E24: =Mitigation!Y248 | F24: =Mitigation!AD248 | G24: =Mitigation!AI248 | H24: =Mitigation!AN248
B25: P3 contracted revenue | C25: =Mitigation!O249 | D25: =Mitigation!T249 | E25: =Mitigation!Y249 | F25: =Mitigation!AD249 | G25: =Mitigation!AI249 | H25: =Mitigation!AN249
B26: P4 viability gap | C26: =Mitigation!O250 | D26: =Mitigation!T250 | E26: =Mitigation!Y250 | F26: =Mitigation!AD250 | G26: =Mitigation!AI250 | H26: =Mitigation!AN250
B27: P5 pure private | C27: =Mitigation!O251 | D27: =Mitigation!T251 | E27: =Mitigation!Y251 | F27: =Mitigation!AD251 | G27: =Mitigation!AI251 | H27: =Mitigation!AN251
B28: Direct budget need (P1 + gap of P4) | C28: =Mitigation!O257 | D28: =Mitigation!T257 | E28: =Mitigation!Y257 | F28: =Mitigation!AD257 | G28: =Mitigation!AI257 | H28: =Mitigation!AN257

Sheet Settings
A1: NMIM - Settings
B4: Country (ISO3) | C4: IND
B5: Country name | C5: =INDEX(Data!$B:$B,MATCH($C$4,Data!$A:$A,0))
B6: Data row | C6: =MATCH($C$4,Data!$A:$A,0)
B8: Choose a country in C4 (ISO3 code from the Data sheet). Every formula on Mitigation recalculates for it.

Sheet Inputs
A1: NMIM - Inputs (MTInputs column structure)
A2: Parameters; calculations read column F by name (defined names p_<NameOfParameter>)
B7: Parameters | C7: unit | D7: MT values | E7: Dashboard values | F7: Used for calculation | G7: Defaults | H7: NameOfParameter | I7: Source | J7: Fit
B8: Long-run real GDP growth, low income | C8: % a year | F8: =G8 | G8: 4.5 | H8: g_lr_lic | I8: Assumption, SSP2-like convergence. † | J8: P
B9: Long-run real GDP growth, lower middle income | C9: % a year | F9: =G9 | G9: 4 | H9: g_lr_lmic | I9: Assumption. † | J9: P
B10: Long-run real GDP growth, upper middle income | C10: % a year | F10: =G10 | G10: 3 | H10: g_lr_umic | I10: Assumption. † | J10: P
B11: Long-run real GDP growth, high income | C11: % a year | F11: =G11 | G11: 1.5 | H11: g_lr_hic | I11: Assumption. † | J11: P
B12: Year growth reaches its long-run rate | C12: year | F12: =G12 | G12: 2040 | H12: g_conv_year | I12: Assumption | J12: M
B13: Pass-through of local price level to capital cost | C13: elasticity | F13: =G13 | G13: 0.5 | H13: phi | I13: As v1.1 workbook. † | J13: P
B14: Fossil-free power, advanced economies | C14: year | F14: =G14 | G14: 2035 | H14: pow_T_ae | I14: IEA Net Zero by 2050 (2021): AE power net zero 2035 | J14: M
B15: Fossil-free power, China | C15: year | F15: =G15 | G15: 2040 | H15: pow_T_chn | I15: IEA NZE: global power net zero 2040 | J15: M
B16: Fossil-free power, other EMDCs | C16: year | F16: =G16 | G16: 2045 | H16: pow_T_emdc | I16: Assumption: five years after the global NZE date. † | J16: P
B17: 100% EV car sales, advanced economies | C17: year | F17: =G17 | G17: 2035 | H17: ev_T_ae | I17: IEA NZE: no new ICE car sales from 2035 | J17: M
B18: 100% EV car sales, China | C18: year | F18: =G18 | G18: 2035 | H18: ev_T_chn | I18: IEA NZE | J18: M
B19: 100% EV car sales, other EMDCs | C19: year | F19: =G19 | G19: 2040 | H19: ev_T_emdc | I19: Assumption: five years later. † | J19: P
... B130: Public share of P4 capital (the viability gap) | C130: share | F130: =G130 | G130: 0.3 | H130: ty_p4_gap | I130: Assumption. † | J130: P

Sheet MODULES->

Sheet Mitigation
B1: Fuel | C1: Sector | D1: Description | E1: Unit | F1: Source | G1: Input Code | H1: Output Code | I1: Note | J1: Helper | K1: 2021 | L1: 2022 | M1: 2023 | N1: 2024 | O1: 2025 | P1: 2026 | Q1: 2027 | R1: 2028 | S1: 2029 | T1: 2030 | U1: 2031 | V1: 2032 | W1: 2033 | X1: 2034 | Y1: 2035 | Z1: 2036 | AA1: 2037 | AB1: 2038 | AC1: 2039 | AD1: 2040 | AE1: 2041 | AF1: 2042 | AG1: 2043 | AH1: 2044 | AI1: 2045 | AJ1: 2046 | AK1: 2047 | AL1: 2048 | AM1: 2049 | AN1: 2050
A2: NMIM v0.2 - National Mitigation Investment Model (selected country: see Settings)
A3: 1. Country scalars (column J)
D4: Data row of the selected country | H4: mit.sc.row | J4: =Settings!$C$6
D5: IHLEG group (1 AE, 2 China, 3 EMDC) | E5: code | F5: Data / Inputs | G5: grp | H5: mit.sc.grp | J5: =INDEX(Data!$CR:$CR,$J$4)
D6: CPAT income group (1 LIC, 2 LMIC, 3 UMIC, 4 HIC) | E6: code | F6: Data / Inputs | G6: inc | H6: mit.sc.inc | J6: =INDEX(Data!$CS:$CS,$J$4)
D7: GDP 2024 | E7: USD bn | F7: Data / Inputs | G7: gdp24 | H7: mit.sc.gdp24 | J7: =INDEX(Data!$CG:$CG,$J$4)
D8: Real GDP growth 2025 (WEO) | E8: % | F8: Data / Inputs | G8: g25 | H8: mit.sc.g25 | J8: =INDEX(Data!$CE:$CE,$J$4)
D9: Real GDP growth 2026 (WEO) | E9: % | F9: Data / Inputs | G9: g26 | H9: mit.sc.g26 | J9: =INDEX(Data!$CF:$CF,$J$4)
D10: Long-run real GDP growth | E10: % | F10: Data / Inputs | G10: CHOOSE(inc,{g_lr_lic},{g_lr_lmic},{g_lr_umic},{g_lr_hic}) | H10: mit.sc.glr | J10: =CHOOSE($J$6,p_g_lr_lic,p_g_lr_lmic,p_g_lr_umic,p_g_lr_hic)
D11: Local price factor on capital (price level^phi) | E11: x | F11: Data / Inputs | G11: plevel^{phi} | H11: mit.sc.pf | J11: =INDEX(Data!$DE:$DE,$J$4)^p_phi
D12: Market WACC (v1.1: observed, Damodaran or IHLEG default) | E12: rate | F12: Data / Inputs | G12: wacc | H12: mit.sc.wacc | J12: =INDEX(Data!$DS:$DS,$J$4)
D13: Fossil-free power year | E13: year | F13: Data / Inputs | G13: CHOOSE(grp,{pow_T_ae},{pow_T_chn},{pow_T_emdc}) | H13: mit.sc.pow_T | J13: =CHOOSE($J$5,p_pow_T_ae,p_pow_T_chn,p_pow_T_emdc)
D14: 100% EV sales year | E14: year | F14: Data / Inputs | G14: CHOOSE(grp,{ev_T_ae},{ev_T_chn},{ev_T_emdc}) | H14: mit.sc.ev_T | J14: =CHOOSE($J$5,p_ev_T_ae,p_ev_T_chn,p_ev_T_emdc)
D15: Fossil heating replaced by | E15: year | F15: Data / Inputs | G15: CHOOSE(grp,{bld_T_ae},{bld_T_chn},{bld_T_emdc}) | H15: mit.sc.bld_T | J15: =CHOOSE($J$5,p_bld_T_ae,p_bld_T_chn,p_bld_T_emdc)
D16: Industrial fossil use abated by 2050 | E16: share | F16: Data / Inputs | G16: CHOOSE(grp,{ind_a_ae},{ind_a_chn},{ind_a_emdc}) | H16: mit.sc.ind_a | J16: =CHOOSE($J$5,p_ind_a_ae,p_ind_a_chn,p_ind_a_emdc)
D17: EV sales share 2024 | E17: share | F17: Data / Inputs | G17: CHOOSE(grp,{ev0_ae},{ev0_chn},{ev0_emdc}) | H17: mit.sc.ev0 | J17: =CHOOSE($J$5,p_ev0_ae,p_ev0_chn,p_ev0_emdc)
D18: Baseline EV sales share 2035 | E18: share | F18: Data / Inputs | G18: CHOOSE(grp,{evb35_ae},{evb35_chn},{evb35_emdc}) | H18: mit.sc.evb35 | J18: =CHOOSE($J$5,p_evb35_ae,p_evb35_chn,p_evb35_emdc)
D19: EV stock share 2024 | E19: share | F19: Data / Inputs | G19: ev0*{sig0_ratio} | H19: mit.sc.sig0 | J19: =$J$17*p_sig0_ratio
D20: Generation / end-use electricity, 2024 | E20: ratio | F20: Data / Inputs | G20: MIN(1.4,MAX(0.9,gen_tot/MAX(0.001,dem_twh24))) | H20: mit.sc.gcr | J20: =MIN(1.4,MAX(0.9,INDEX(Data!$CN:$CN,$J$4)/MAX(0.001,INDEX(Data!$CB:$CB,$J$4))))
D21: Fossil share of generation 2024 | E21: share | F21: Data / Inputs | G21: MIN(1,gen_fos/MAX(0.001,gen_tot)) | H21: mit.sc.f0 | J21: =MIN(1,INDEX(Data!$CJ:$CJ,$J$4)/MAX(0.001,INDEX(Data!$CN:$CN,$J$4)))
D22: Baseline fall in fossil share | E22: share/yr | F22: Data / Inputs | G22: MIN({fos_trend_cap},MAX(0,fos_trend))/100 | H22: mit.sc.ftrend | J22: =MIN(p_fos_trend_cap,MAX(0,INDEX(Data!$CD:$CD,$J$4)))/100
D23: Clean firm generation (hydro, nuclear, bio, other) | E23: TWh | F23: Data / Inputs | G23: gen_cfirm | H23: mit.sc.cfirm | J23: =INDEX(Data!$CH:$CH,$J$4)
D24: Coal share of fossil generation | E24: share | F24: Data / Inputs | G24: IF(gen_fos>0,gen_coa/gen_fos,0) | H24: mit.sc.sh_coa | J24: =IF(INDEX(Data!$CJ:$CJ,$J$4)>0,INDEX(Data!$CI:$CI,$J$4)/INDEX(Data!$CJ:$CJ,$J$4),0)
D25: Gas share of fossil generation | E25: share | F25: Data / Inputs | G25: IF(gen_fos>0,gen_nga/gen_fos,0) | H25: mit.sc.sh_nga | J25: =IF(INDEX(Data!$CJ:$CJ,$J$4)>0,INDEX(Data!$CK:$CK,$J$4)/INDEX(Data!$CJ:$CJ,$J$4),0)
D26: Oil share of fossil generation | E26: share | F26: Data / Inputs | G26: IF(gen_fos>0,gen_oil/gen_fos,1) | H26: mit.sc.sh_oil | J26: =IF(INDEX(Data!$CJ:$CJ,$J$4)>0,INDEX(Data!$CL:$CL,$J$4)/INDEX(Data!$CJ:$CJ,$J$4),1)
D27: Coal heat rate, calibrated to CPAT power fuel use | E27: GJ/MWh | F27: Data / Inputs | G27: IF(gen_coa>0.1,MIN(14,MAX(7,con_coa_pow/gen_coa)),{hr_coa}) | H27: mit.sc.hr_coa | J27: =IF(INDEX(Data!$CI:$CI,$J$4)>0.1,MIN(14,MAX(7,INDEX(Data!$AK:$AK,$J$4)/INDEX(Data!$CI:$CI,$J$4))),p_hr_coa)
D28: Gas heat rate, calibrated to CPAT power fuel use | E28: GJ/MWh | F28: Data / Inputs | G28: IF(gen_nga>0.1,MIN(12,MAX(5.5,con_nga_pow/gen_nga)),{hr_nga} | H28: mit.sc.hr_nga | J28: =IF(INDEX(Data!$CK:$CK,$J$4)>0.1,MIN(12,MAX(5.5,INDEX(Data!$BR:$BR,$J$4)/INDEX(Data!$CK:$CK,$J$4))),p_hr_nga)
D29: Solar capacity factor | E29: share | F29: Data / Inputs | G29: IF(cap_sol>0.05,MIN(0.3,MAX(0.1,gen_sol/(cap_sol*8.76))),{cf | H29: mit.sc.cf_sol | J29: =IF(INDEX(Data!$AB:$AB,$J$4)>0.05,MIN(0.3,MAX(0.1,INDEX(Data!$CM:$CM,$J$4)/(INDEX(Data!$AB:$AB,$J$4)*8.76))),p_cf_sol)
D30: Wind capacity factor | E30: share | F30: Data / Inputs | G30: IF(cap_wnd>0.05,MIN(0.5,MAX(0.15,gen_wnd/(cap_wnd*8.76))),{c | H30: mit.sc.cf_wnd | J30: =IF(INDEX(Data!$AC:$AC,$J$4)>0.05,MIN(0.5,MAX(0.15,INDEX(Data!$CO:$CO,$J$4)/(INDEX(Data!$AC:$AC,$J$4)*8.76))),p_cf_wnd)
D31: Fossil capacity factor | E31: share | F31: Data / Inputs | G31: IF(cap_fos>0.05,MIN(0.8,MAX(0.2,gen_fos/(cap_fos*8.76))),{cf | H31: mit.sc.cf_fos | J31: =IF(INDEX(Data!$AA:$AA,$J$4)>0.05,MIN(0.8,MAX(0.2,INDEX(Data!$CJ:$CJ,$J$4)/(INDEX(Data!$AA:$AA,$J$4)*8.76))),p_cf_fos)
D32: Non-CO2 and other process GHG 2024 | E32: MtCO2e | F32: Data / Inputs | G32: MAX(0,ghg_exc-co2_24-cbam_proc24) | H32: mit.sc.nc24 | J32: =MAX(0,INDEX(Data!$CP:$CP,$J$4)-INDEX(Data!$AF:$AF,$J$4)-INDEX(Data!$AE:$AE,$J$4))
D33: Net land-use source 2024 | E33: MtCO2e | F33: Data / Inputs | G33: MAX(0,ghg_inc-ghg_exc) | H33: mit.sc.lu24 | J33: =MAX(0,INDEX(Data!$CQ:$CQ,$J$4)-INDEX(Data!$CP:$CP,$J$4))
D34: CBAM-goods process CO2 2024 | E34: MtCO2 | F34: Data / Inputs | G34: cbam_proc24 | H34: mit.sc.cbam24 | J34: =INDEX(Data!$AE:$AE,$J$4)
D35: CBAM-goods output growth to 2030 | E35: % | F35: Data / Inputs | G35: cbam_g | H35: mit.sc.cbam_g | J35: =INDEX(Data!$AD:$AD,$J$4)
D36: CRF at market WACC, grids | E36: x | F36: Data / Inputs | G36: wacc/(1-(1+wacc)^-{life_grid}) | H36: mit.sc.crf_a_grid | J36: =$J$12/(1-(1+$J$12)^-p_life_grid)
D37: CRF at market WACC, generation | E37: x | F37: Data / Inputs | G37: wacc/(1-(1+wacc)^-{life_vre}) | H37: mit.sc.crf_a_vre | J37: =$J$12/(1-(1+$J$12)^-p_life_vre)
D38: CRF at market WACC, vehicles | E38: x | F38: Data / Inputs | G38: wacc/(1-(1+wacc)^-{veh_life}) | H38: mit.sc.crf_a_veh | J38: =$J$12/(1-(1+$J$12)^-p_veh_life)
D39: CRF at market WACC, buildings | E39: x | F39: Data / Inputs | G39: wacc/(1-(1+wacc)^-{life_bld}) | H39: mit.sc.crf_a_bld | J39: =$J$12/(1-(1+$J$12)^-p_life_bld)
D40: CRF at market WACC, industry | E40: x | F40: Data / Inputs | G40: wacc/(1-(1+wacc)^-{life_ind}) | H40: mit.sc.crf_a_ind | J40: =$J$12/(1-(1+$J$12)^-p_life_ind)
...

Sheet Results_All
A1: Results for all countries (Python engine, values), USD bn and MtCO2e
A2: Incremental cost is the annual cost in that year of all incremental capital in service (capital charge) plus the change in O&M, less fuel savings (less air pollution avoided in lens c). Positive = net cost. PV = present value 2025-2050 at the lens rate.
A4: ISO3 | B4: Country | C4: Group | D4: Market WACC | E4: GDP 2030 | F4: Investment 2030, baseline | G4: Investment 2030, net zero | H4: Incremental investment 2030 | I4: Incr. cost 2030 (a) market | J4: Incr. cost 2030 (b) 6% | K4: Incr. cost 2030 (c) 6% + co-ben. | L4: GHG 2030 baseline | M4: GHG 2030 net zero | N4: GHG 2050 net zero | O4: Cumulative investment 2025-50, net zero | P4: Cumulative incremental 2025-50 | Q4: PV incr. cost (a) | R4: PV incr. cost (b) | S4: PV incr. cost (c) | T4: Cumulative abatement 2025-50 | U4: Energy CO2 2024, model | V4: Energy CO2 2024, CPAT | W4: Power market (1 VIU, 2 single buyer, 3 wholesale) | X4: Electricity cost recovery | Y4: 2030 net zero: P1 pure public | Z4: P2 regulated utility | AA4: P3 contracted revenue | AB4: P4 viability gap | AC4: P5 pure private | AD4: Direct budget need 2030 (P1 + gap of P4) | AE4: Incremental budget need 2030 | AF4: Private capital 2030
A5: USA | B5: United States | C5: AE | D5: 0.057 | E5: 33367.503 | F5: 487.1625 | G5: 1060.8972 | H5: 573.7347 | I5: 96.7671 | J5: 102.7929 | K5: 70.8357 | L5: 6790.3026 | M5: 5077.4784 | N5: 982.2613 | O5: 25662.977 | P5: 12880.514 | Q5: 1746.394 | R5: 1821.3497 | S5: 1086.8989 | T5: 86412.44 | U5: 4997.031 | V5: 5445.106 | W5: 3 | X5: 1.0027 | Y5: 87.2785 | Z5: 206.5294 | AA5: 239.2082 | AB5: 49.7901 | AC5: 478.091 | AD5: 102.2155 | AE5: 56.3425 | AF5: 752.1523
A6: CHN | B6: China | C6: China | D6: 0.0389 | E6: 24439.123 | F6: 704.6814 | G6: 1526.2789 | H6: 821.5975 | I6: 152.4876 | J6: 206.8429 | K6: -104.7182 | L6: 16649.529 | M6: 13657.93 | N6: 1962.2461 | O6: 47666.074 | P6: 26520.332 | Q6: 5220.0989 | R6: 5417.0399 | S6: -2977.9423 | T6: 184240.95 | U6: 10506.051 | V6: 13206.767 | W6: 2 | X6: 0.9676 | Y6: 69.702 | Z6: 619.6184 | AA6: 345.7207 | AB6: 166.7166 | AC6: 324.5212 | AD6: 119.717 | AE6: 81.7963 | AF6: 786.9435
A7: IND | B7: India | C7: EMDC | D7: 0.095 | E7: 5447.8957 | F7: 80.3898 | G7: 225.4337 | H7: 145.0439 | I7: 51.3651 | J7: 35.0491 | K7: 1.8928 | L7: 4680.0616 | M7: 3882.6482 | N7: 1010.2699 | O7: 8363.0255 | P7: 5824.1169 | Q7: 680.4675 | R7: 557.3367 | S7: -555.4278 | T7: 57586.006 | U7: 2415.9374 | V7: 2845.008 | W7: 3 | X7: 0.7965 | Y7: 30.7108 | Z7: 34.6382 | AA7: 44.6073 | AB7: 63.1711 | AC7: 52.3064 | AD7: 49.6621 | AE7: 34.7643 | AF7: 141.1334
A8: DEU | B8: Germany | C8: AE | D8: 0.0232 | E8: 4908.6727 | F8: 74.6443 | G8: 157.6997 | H8: 83.0553 | I8: -5.7167 | J8: 5.1837 | K8: 0.8202 | L8: 688.0652 | M8: 545.8375 | N8: 86.3555 | O8: 3845.6213 | P8: 1827.4695 | Q8: -261.7686 | R8: 95.8305 | S8: -18.5959 | T8: 7355.6659 | U8: 594.9479 | V8: 658.368 | W8: 3 | X8: 1.1808 | Y8: 11.6467 | Z8: 38.9085 | AA8: 38.3148 | AB8: 5.9538 | AC8: 62.8759 | AD8: 13.4328 | AE8: 6.9739 | AF8: 105.3584
A9: JPN | B9: Japan | C9: AE | D9: 0.055 | E9: 4419.0183 | F9: 66.823 | G9: 182.8694 | H9: 116.0463 | I9: -2.4332 | J9: -0.2849 | K9: -12.7031 | L9: 1228.4346 | M9: 925.189 | N9: 120.7745 | O9: 4378.3625 | P9: 2474.1672 | Q9: 28.367 | R9: 74.3744 | S9: -197.8789 | T9: 14756.347 | U9: 1121.5329 | V9: 1205.177 | W9: 3 | X9: 1.0476 | Y9: 9.4726 | Z9: 47.3024 | AA9: 47.3628 | AB9: 9.8093 | AC9: 68.9223 | AD9: 12.4154 | AE9: 6.5199 | AF9: 123.1516
A10: GBR | B10: United Kingdom | C10: AE | D10: 0.0359 | E10: 3915.292 | F10: 50.4006 | G10: 102.786 | H10: 52.3854 | I10: -4.7805 | J10: -0.0883 | K10: -2.4179 | L10: 424.7509 | M10: 337.5557 | N10: 63.5164 | O10: 2549.8621 | P10: 1184.014 | Q10: -177.4841 | R10: -17.7496 | S10: -72.1397 | T10: 4524.0143 | U10: 343.3351 | V10: 370.094 | W10: 3 | X10: 1.095 | Y10: 9.6201 | Z10: 21.1711 | AA10: 24.0527 | AB10: 4.2896 | AC10: 43.6525 | AD10: 10.907 | AE10: 5.6119 | AF10: 70.7079
A11: FRA | B11: France | C11: AE | D11: 0.033 | E11: 3344.7754 | F11: 39.8224 | G11: 74.9377 | H11: 35.1154 | I11: -0.7779 | J11: 2.7653 | K11: 0.9473 | L11: 391.7834 | M11: 310.0166 | N11: 72.1852 | O11: 2036.4025 | P11: 914.7157 | Q11: -80.9002 | R11: 29.2257 | S11: -15.0187 | T11: 4218.4369 | U11: 279.3269 | V11: 322.969 | W11: 3 | X11: 1.1236 | Y11: 7.1726 | Z11: 11.6028 | AA11: 17.9253 | AB11: 3.1661 | AC11: 35.0709 | AD11: 8.1224 | AE11: 3.7189 | AF11: 55.2125
A12: CAN | B12: Canada | C12: AE | D12: 0.055 | E12: 2488.1419 | F12: 34.5276 | G12: 104.5845 | H12: 70.0569 | I12: 14.1255 | J12: 15.4926 | K12: 14.4429 | L12: 690.5561 | M12: 531.3236 | N12: 107.9266 | O12: 2682.114 | P12: 1763.9372 | Q12: 302.1613 | R12: 313.9716 | S12: 288.5377 | T12: 8558.7018 | U12: 539.5996 | V12: 554.217 | W12: 2 | X12: 1.1083 | Y12: 7.5397 | Z12: 28.3058 | AA12: 20.0174 | AB12: 7.6102 | AC12: 41.1113 | AD12: 9.8228 | AE12: 6.3928 | AF12: 66.4559
A13: BRA | B13: Brazil | C13: EMDC | D13: 0.0978 | E13: 2476.5515 | F13: 21.9829 | G13: 83.6647 | H13: 61.6818 | I13: 36.68 | J13: 32.3176 | K13: 29.41 | L13: 1785.1893 | M13: 1043.0369 | N13: 442.9016 | O13: 2579.987 | P13: 1900.8246 | Q13: 271.9456 | R13: 286.2362 | S13: 189.706 | T13: 24611.556 | U13: 411.7179 | V13: 505.632 | W13: 3 | X13: 1.0181 | Y13: 17.459 | Z13: 10.836 | AA13: 11.9482 | AB13: 23.4524 | AC13: 19.9692 | AD13: 24.4947 | AE13: 22.2945 | AF13: 48.334
A14: ITA | B14: Italy | C14: AE | D14: 0.0438 | E14: 2475.7888 | F14: 33.0825 | G14: 75.2501 | H14: 42.1676 | I14: -4.3887 | J14: -1.9035 | K14: -5.161 | L14: 419.3619 | M14: 328.2704 | N14: 63.4136 | O14: 1852.1536 | P14: 921.2433 | Q14: -131.039 | R14: -47.513 | S14: -125.8911 | T14: 4561.9678 | U14: 315.8296 | V14: 363.035 | W14: 3 | X14: 1.2138 | Y14: 6.3305 | Z14: 16.0338 | AA14: 17.7496 | AB14: 3.231 | AC14: 31.9052 | AD14: 7.2998 | AE14: 4.0282 | AF14: 51.9165
A15: RUS | B15: Russian Federation | C15: EMDC | D15: 0.105 | E15: 2361.9368 | F15: 20.5356 | G15: 138.5391 | H15: 118.0034 | I15: 60.0054 | J15: 38.6279 | K15: 17.4818 | L15: 2477.3478 | M15: 2079.0048 | N15: 447.818 | O15: 5217.1106 | P15: 4525.7167 | Q15: 815.6703 | R15: 894.9837 | S15: 135.465 | T15: 30837.071 | U15: 1740.9558 | V15: 1982.113 | W15: 3 | X15: 0.4543 | Y15: 25.7277 | Z15: 12.075 | AA15: 20.229 | AB15: 46.0382 | AC15: 34.4692 | AD15: 39.5391 | AE15: 33.8771 | AF15: 86.925
A16: KOR | B16: Korea, Rep. | C16: AE | D16: 0.055 | E16: 2072.0525 | F16: 34.5022 | G16: 104.6285 | H16: 70.1263 | I16: 2.8344 | J16: 4.0867 | K16: -2.2581 | L16: 818.0975 | M16: 598.6343 | N16: 84.6938 | O16: 2537.3706 | P16: 1617.4028 | Q16: 96.2606 | R16: 119.2885 | S16: -25.8957 | T16: 11124.191 | U16: 634.328 | V16: 732.861 | W16: 2 | X16: 1.0217 | Y16: 5.0886 | Z16: 40.0242 | AA16: 24.6505 | AB16: 7.201 | AC16: 27.6642 | AD16: 7.2489 | AE16: 4.3831 | AF16: 57.3554
... A190: NRU | B190: Naoero | C190: EMDC | D190: 0.105 | E190: 0.192 | F190: 0.0032 | G190: 0.0149 | H190: 0.0117 | I190: 0.0061 | J190: 0.0039 | K190: 0.0039 | L190: 0.1354 | M190: 0.1303 | N190: 0.0289 | O190: 0.537 | P190: 0.4462 | Q190: 0.0661 | R190: 0.0512 | S190: 0.0512 | T190: 1.2898 | U190: 0.1323 | V190: 0.101 | W190: 1 | X190: 1 | Y190: 0.0002 | Z190: 0.0064 | AA190: 0.0013 | AB190: 0.0027 | AC190: 0.0042 | AD190: 0.001 | AE190: 0.0008 | AF190: 0.0074

Sheet Typology
A1: Typology - who pays for net zero investment (selected country)
B2: =Settings!C5
B3: P1 pure public (taxes repay it) | P2 regulated utility (tariffs on a regulated asset base) | P3 contracted revenue (PPA, CfD, concession) | P4 viability gap (market revenue + public top-up) | P5 pure private (own savings or sales)
A5: Country context
B6: Power market structure (1 VIU, 2 single buyer, 3 wholesale) | C6: =INDEX(PowerMarket!$B$4:$B$189,MATCH(Settings!$C$4,PowerMarket!$A$4:$A$189,0))
B7: Source | C7: =INDEX(PowerMarket!$C$4:$C$189,MATCH(Settings!$C$4,PowerMarket!$A$4:$A$189,0))&""
B8: Note | C8: =INDEX(PowerMarket!$D$4:$D$189,MATCH(Settings!$C$4,PowerMarket!$A$4:$A$189,0))&""
B9: Independent regulator / unbundled / privatised (0/1, PSRT) | C9: =INDEX(PowerMarket!$E$4:$E$189,MATCH(Settings!$C$4,PowerMarket!$A$4:$A$189,0))&" / "&INDEX(PowerMarket!$F$4:$F$189,MATCH(Settings!$C$4,PowerMarket!$A$4:$A$189,0))&" / "&INDEX(PowerMarket!$G$4:$G$189,MATCH(Settings!$C$4,PowerMarket!$A$4:$A$189,0))
B10: Electricity cost recovery (retail price / supply cost) | C10: =INDEX(PowerMarket!$I$4:$I$189,MATCH(Settings!$C$4,PowerMarket!$A$4:$A$189,0))
B11: Private electricity investment, PPI, USD bn a year 2015-24 | C11: =INDEX(PowerMarket!$L$4:$L$189,MATCH(Settings!$C$4,PowerMarket!$A$4:$A$189,0))
B12: RISE renewable energy score (0-100) | C12: =INDEX(PowerMarket!$S$4:$S$189,MATCH(Settings!$C$4,PowerMarket!$A$4:$A$189,0))
B13: Utility pressure index (tariff under-recovery) | C13: =Mitigation!$J$47
B14: Capital-cost pressure index (WACC above 6%) | C14: =Mitigation!$J$48
B15: Subsidy pressure index (explicit fossil subsidies) | C15: =Mitigation!$J$49
B16: Top-up share of market end-use investment | C16: =Mitigation!$J$50
A18: Type shares by sector (Mitigation section 1)
B19: Sector | C19: P1 | D19: P2 | E19: P3 | F19: P4 | G19: P5 | H19: Sum
B20: Power generation | C20: =Mitigation!$J$54 | D20: =Mitigation!$J$55 | E20: =Mitigation!$J$56 | F20: =Mitigation!$J$57 | G20: =Mitigation!$J$58 | H20: =SUM(C20:G20)
B21: Grids and storage | C21: =Mitigation!$J$60 | D21: =Mitigation!$J$61 | E21: =Mitigation!$J$62 | F21: =Mitigation!$J$63 | G21: =Mitigation!$J$64 | H21: =SUM(C21:G21)
B22: Transport (EV premium, chargers) | C22: =Mitigation!$J$65 | D22: =Mitigation!$J$66 | E22: =Mitigation!$J$67 | F22: =Mitigation!$J$68 | G22: =Mitigation!$J$69 | H22: =SUM(C22:G22)
B23: Buildings | C23: =Mitigation!$J$70 | D23: =Mitigation!$J$71 | E23: =Mitigation!$J$72 | F23: =Mitigation!$J$73 | G23: =Mitigation!$J$74 | H23: =SUM(C23:G23)
B24: Industry: fuel switch | C24: 0 | D24: 0 | E24: 0 | F24: =Mitigation!$J$75 | G24: =1-Mitigation!$J$75 | H24: =SUM(C24:G24)
B25: Industry: CCS on CBAM goods | C25: 0 | D25: 0 | E25: 0 | F25: 1 | G25: 0 | H25: =SUM(C25:G25)
B26: Non-CO2 | C26: =Mitigation!$J$76 | D26: 0 | E26: 0 | F26: =1-Mitigation!$J$76-Mitigation!$J$77 | G26: =Mitigation!$J$77 | H26: =SUM(C26:G26)
B27: Land use | C27: =Mitigation!$J$78 | D27: 0 | E27: 0 | F27: =1-Mitigation!$J$78 | G27: 0 | H27: =SUM(C27:G27)
B28: Other energy CO2 (aviation, shipping) | C28: 0 | D28: 0 | E28: 0 | F28: 1 | G28: 0 | H28: =SUM(C28:G28)
B29: Unmodelled clean investment | C29: =Mitigation!$J$79 | D29: =Mitigation!$J$80 | E29: =Mitigation!$J$81 | F29: =Mitigation!$J$82 | G29: =Mitigation!$J$83 | H29: =SUM(C29:G29)
A31: Investment by type, USD bn a year (Mitigation section 12)
B32: Item | C32: 2025 | D32: 2030 | E32: 2035 | F32: 2040 | G32: 2045 | H32: 2050
B33: Net zero: P1 pure public | C33: =Mitigation!O247 | D33: =Mitigation!T247 | E33: =Mitigation!Y247 | F33: =Mitigation!AD247 | G33: =Mitigation!AI247 | H33: =Mitigation!AN247
B34: Net zero: P2 regulated utility | C34: =Mitigation!O248 | D34: =Mitigation!T248 | E34: =Mitigation!Y248 | F34: =Mitigation!AD248 | G34: =Mitigation!AI248 | H34: =Mitigation!AN248
B35: Net zero: P3 contracted revenue | C35: =Mitigation!O249 | D35: =Mitigation!T249 | E35: =Mitigation!Y249 | F35: =Mitigation!AD249 | G35: =Mitigation!AI249 | H35: =Mitigation!AN249
B36: Net zero: P4 viability gap | C36: =Mitigation!O250 | D36: =Mitigation!T250 | E36: =Mitigation!Y250 | F36: =Mitigation!AD250 | G36: =Mitigation!AI250 | H36: =Mitigation!AN250
B37: Net zero: P5 pure private | C37: =Mitigation!O251 | D37: =Mitigation!T251 | E37: =Mitigation!Y251 | F37: =Mitigation!AD251 | G37: =Mitigation!AI251 | H37: =Mitigation!AN251
B38: Net zero: total | C38: =Mitigation!O221 | D38: =Mitigation!T221 | E38: =Mitigation!Y221 | F38: =Mitigation!AD221 | G38: =Mitigation!AI221 | H38: =Mitigation!AN221
B39: Incremental: P1 pure public | C39: =Mitigation!O252 | D39: =Mitigation!T252 | E39: =Mitigation!Y252 | F39: =Mitigation!AD252 | G39: =Mitigation!AI252 | H39: =Mitigation!AN252
B40: Incremental: P2 regulated utility | C40: =Mitigation!O253 | D40: =Mitigation!T253 | E40: =Mitigation!Y253 | F40: =Mitigation!AD253 | G40: =Mitigation!AI253 | H40: =Mitigation!AN253
B41: Incremental: P3 contracted revenue | C41: =Mitigation!O254 | D41: =Mitigation!T254 | E41: =Mitigation!Y254 | F41: =Mitigation!AD254 | G41: =Mitigation!AI254 | H41: =Mitigation!AN254
B42: Incremental: P4 viability gap | C42: =Mitigation!O255 | D42: =Mitigation!T255 | E42: =Mitigation!Y255 | F42: =Mitigation!AD255 | G42: =Mitigation!AI255 | H42: =Mitigation!AN255
B43: Incremental: P5 pure private | C43: =Mitigation!O256 | D43: =Mitigation!T256 | E43: =Mitigation!Y256 | F43: =Mitigation!AD256 | G43: =Mitigation!AI256 | H43: =Mitigation!AN256
...

Sheet Check
A1: Check: workbook (live formulas) vs Python engine, selected country
A2: Differences should be 0 to rounding. Max abs difference in B3.
A3: Max abs diff | B3: =MAX(MAX(L6:P27),-MIN(L6:P27))
A5: Code | B5: WB 2024 | C5: WB 2025 | D5: WB 2030 | E5: WB 2040 | F5: WB 2050 | G5: Py 2024 | H5: Py 2025 | I5: Py 2030 | J5: Py 2040 | K5: Py 2050 | L5: Diff 2024 | M5: Diff 2025 | N5: Diff 2030 | O5: Diff 2040 | P5: Diff 2050
A6: mit.gdp.lvl | B6: =Mitigation!N86 | C6: =Mitigation!O86 | D6: =Mitigation!T86 | E6: =Mitigation!AD86 | F6: =Mitigation!AN86 | G6: =INDEX(PyKey!D$3:D$4094,MATCH(Settings!$C$4&"|mit.gdp.lvl",PyKey!$A$3:$A$4094,0)) | H6: =INDEX(PyKey!E$3:E$4094,MATCH(Settings!$C$4&"|mit.gdp.lvl",PyKey!$A$3:$A$4094,0)) | I6: =INDEX(PyKey!F$3:F$4094,MATCH(Settings!$C$4&"|mit.gdp.lvl",PyKey!$A$3:$A$4094,0)) | J6: =INDEX(PyKey!G$3:G$4094,MATCH(Settings!$C$4&"|mit.gdp.lvl",PyKey!$A$3:$A$4094,0)) | K6: =INDEX(PyKey!H$3:H$4094,MATCH(Settings!$C$4&"|mit.gdp.lvl",PyKey!$A$3:$A$4094,0)) | L6: =B6-G6 | M6: =C6-H6 | N6: =D6-I6 | O6: =E6-J6 | P6: =F6-K6
A7: mit.act.ecy.res | B7: =Mitigation!N94 | C7: =Mitigation!O94 | D7: =Mitigation!T94 | E7: =Mitigation!AD94 | F7: =Mitigation!AN94 | G7: =INDEX(PyKey!D$3:D$4094,MATCH(Settings!$C$4&"|mit.act.ecy.res",PyKey!$A$3:$A$4094,0)) | H7: =INDEX(PyKey!E$3:E$4094,MATCH(Settings!$C$4&"|mit.act.ecy.res",PyKey!$A$3:$A$4094,0)) | I7: =INDEX(PyKey!F$3:F$4094,MATCH(Settings!$C$4&"|mit.act.ecy.res",PyKey!$A$3:$A$4094,0)) | J7: =INDEX(PyKey!G$3:G$4094,MATCH(Settings!$C$4&"|mit.act.ecy.res",PyKey!$A$3:$A$4094,0)) | K7: =INDEX(PyKey!H$3:H$4094,MATCH(Settings!$C$4&"|mit.act.ecy.res",PyKey!$A$3:$A$4094,0)) | L7: =B7-G7 | M7: =C7-H7 | N7: =D7-I7 | O7: =E7-J7 | P7: =F7-K7
A8: mit.gen.tot.2 | B8: =Mitigation!N171 | C8: =Mitigation!O171 | D8: =Mitigation!T171 | E8: =Mitigation!AD171 | F8: =Mitigation!AN171 | G8: =INDEX(PyKey!D$3:D$4094,MATCH(Settings!$C$4&"|mit.gen.tot.2",PyKey!$A$3:$A$4094,0)) | H8: =INDEX(PyKey!E$3:E$4094,MATCH(Settings!$C$4&"|mit.gen.tot.2",PyKey!$A$3:$A$4094,0)) | I8: =INDEX(PyKey!F$3:F$4094,MATCH(Settings!$C$4&"|mit.gen.tot.2",PyKey!$A$3:$A$4094,0)) | J8: =INDEX(PyKey!G$3:G$4094,MATCH(Settings!$C$4&"|mit.gen.tot.2",PyKey!$A$3:$A$4094,0)) | K8: =INDEX(PyKey!H$3:H$4094,MATCH(Settings!$C$4&"|mit.gen.tot.2",PyKey!$A$3:$A$4094,0)) | L8: =B8-G8 | M8: =C8-H8 | N8: =D8-I8 | O8: =E8-J8 | P8: =F8-K8
A9: mit.gen.fos.1 | B9: =Mitigation!N152 | C9: =Mitigation!O152 | D9: =Mitigation!T152 | E9: =Mitigation!AD152 | F9: =Mitigation!AN152 | G9: =INDEX(PyKey!D$3:D$4094,MATCH(Settings!$C$4&"|mit.gen.fos.1",PyKey!$A$3:$A$4094,0)) | H9: =INDEX(PyKey!E$3:E$4094,MATCH(Settings!$C$4&"|mit.gen.fos.1",PyKey!$A$3:$A$4094,0)) | I9: =INDEX(PyKey!F$3:F$4094,MATCH(Settings!$C$4&"|mit.gen.fos.1",PyKey!$A$3:$A$4094,0)) | J9: =INDEX(PyKey!G$3:G$4094,MATCH(Settings!$C$4&"|mit.gen.fos.1",PyKey!$A$3:$A$4094,0)) | K9: =INDEX(PyKey!H$3:H$4094,MATCH(Settings!$C$4&"|mit.gen.fos.1",PyKey!$A$3:$A$4094,0)) | L9: =B9-G9 | M9: =C9-H9 | N9: =D9-I9 | O9: =E9-J9 | P9: =F9-K9
A10: mit.inv.gen.2 | B10: =Mitigation!N184 | C10: =Mitigation!O184 | D10: =Mitigation!T184 | E10: =Mitigation!AD184 | F10: =Mitigation!AN184 | G10: =INDEX(PyKey!D$3:D$4094,MATCH(Settings!$C$4&"|mit.inv.gen.2",PyKey!$A$3:$A$4094,0)) | H10: =INDEX(PyKey!E$3:E$4094,MATCH(Settings!$C$4&"|mit.inv.gen.2",PyKey!$A$3:$A$4094,0)) | I10: =INDEX(PyKey!F$3:F$4094,MATCH(Settings!$C$4&"|mit.inv.gen.2",PyKey!$A$3:$A$4094,0)) | J10: =INDEX(PyKey!G$3:G$4094,MATCH(Settings!$C$4&"|mit.inv.gen.2",PyKey!$A$3:$A$4094,0)) | K10: =INDEX(PyKey!H$3:H$4094,MATCH(Settings!$C$4&"|mit.inv.gen.2",PyKey!$A$3:$A$4094,0)) | L10: =B10-G10 | M10: =C10-H10 | N10: =D10-I10 | O10: =E10-J10 | P10: =F10-K10
A11: mit.inv.grid.2 | B11: =Mitigation!N186 | C11: =Mitigation!O186 | D11: =Mitigation!T186 | E11: =Mitigation!AD186 | F11: =Mitigation!AN186 | G11: =INDEX(PyKey!D$3:D$4094,MATCH(Settings!$C$4&"|mit.inv.grid.2",PyKey!$A$3:$A$4094,0)) | H11: =INDEX(PyKey!E$3:E$4094,MATCH(Settings!$C$4&"|mit.inv.grid.2",PyKey!$A$3:$A$4094,0)) | I11: =INDEX(PyKey!F$3:F$4094,MATCH(Settings!$C$4&"|mit.inv.grid.2",PyKey!$A$3:$A$4094,0)) | J11: =INDEX(PyKey!G$3:G$4094,MATCH(Settings!$C$4&"|mit.inv.grid.2",PyKey!$A$3:$A$4094,0)) | K11: =INDEX(PyKey!H$3:H$4094,MATCH(Settings!$C$4&"|mit.inv.grid.2",PyKey!$A$3:$A$4094,0)) | L11: =B11-G11 | M11: =C11-H11 | N11: =D11-I11 | O11: =E11-J11 | P11: =F11-K11
A12: mit.inv.trn.2 | B12: =Mitigation!N115 | C12: =Mitigation!O115 | D12: =Mitigation!T115 | E12: =Mitigation!AD115 | F12: =Mitigation!AN115 | G12: =INDEX(PyKey!D$3:D$4094,MATCH(Settings!$C$4&"|mit.inv.trn.2",PyKey!$A$3:$A$4094,0)) | H12: =INDEX(PyKey!E$3:E$4094,MATCH(Settings!$C$4&"|mit.inv.trn.2",PyKey!$A$3:$A$4094,0)) | I12: =INDEX(PyKey!F$3:F$4094,MATCH(Settings!$C$4&"|mit.inv.trn.2",PyKey!$A$3:$A$4094,0)) | J12: =INDEX(PyKey!G$3:G$4094,MATCH(Settings!$C$4&"|mit.inv.trn.2",PyKey!$A$3:$A$4094,0)) | K12: =INDEX(PyKey!H$3:H$4094,MATCH(Settings!$C$4&"|mit.inv.trn.2",PyKey!$A$3:$A$4094,0)) | L12: =B12-G12 | M12: =C12-H12 | N12: =D12-I12 | O12: =E12-J12 | P12: =F12-K12
A13: mit.inv.bld.2 | B13: =Mitigation!N129 | C13: =Mitigation!O129 | D13: =Mitigation!T129 | E13: =Mitigation!AD129 | F13: =Mitigation!AN129 | G13: =INDEX(PyKey!D$3:D$4094,MATCH(Settings!$C$4&"|mit.inv.bld.2",PyKey!$A$3:$A$4094,0)) | H13: =INDEX(PyKey!E$3:E$4094,MATCH(Settings!$C$4&"|mit.inv.bld.2",PyKey!$A$3:$A$4094,0)) | I13: =INDEX(PyKey!F$3:F$4094,MATCH(Settings!$C$4&"|mit.inv.bld.2",PyKey!$A$3:$A$4094,0)) | J13: =INDEX(PyKey!G$3:G$4094,MATCH(Settings!$C$4&"|mit.inv.bld.2",PyKey!$A$3:$A$4094,0)) | K13: =INDEX(PyKey!H$3:H$4094,MATCH(Settings!$C$4&"|mit.inv.bld.2",PyKey!$A$3:$A$4094,0)) | L13: =B13-G13 | M13: =C13-H13 | N13: =D13-I13 | O13: =E13-J13 | P13: =F13-K13
A14: mit.inv.ind.2 | B14: =Mitigation!N144 | C14: =Mitigation!O144 | D14: =Mitigation!T144 | E14: =Mitigation!AD144 | F14: =Mitigation!AN144 | G14: =INDEX(PyKey!D$3:D$4094,MATCH(Settings!$C$4&"|mit.inv.ind.2",PyKey!$A$3:$A$4094,0)) | H14: =INDEX(PyKey!E$3:E$4094,MATCH(Settings!$C$4&"|mit.inv.ind.2",PyKey!$A$3:$A$4094,0)) | I14: =INDEX(PyKey!F$3:F$4094,MATCH(Settings!$C$4&"|mit.inv.ind.2",PyKey!$A$3:$A$4094,0)) | J14: =INDEX(PyKey!G$3:G$4094,MATCH(Settings!$C$4&"|mit.inv.ind.2",PyKey!$A$3:$A$4094,0)) | K14: =INDEX(PyKey!H$3:H$4094,MATCH(Settings!$C$4&"|mit.inv.ind.2",PyKey!$A$3:$A$4094,0)) | L14: =B14-G14 | M14: =C14-H14 | N14: =D14-I14 | O14: =E14-J14 | P14: =F14-K14
A15: mit.inv.tot.1 | B15: =Mitigation!N220 | C15: =Mitigation!O220 | D15: =Mitigation!T220 | E15: =Mitigation!AD220 | F15: =Mitigation!AN220 | G15: =INDEX(PyKey!D$3:D$4094,MATCH(Settings!$C$4&"|mit.inv.tot.1",PyKey!$A$3:$A$4094,0)) | H15: =INDEX(PyKey!E$3:E$4094,MATCH(Settings!$C$4&"|mit.inv.tot.1",PyKey!$A$3:$A$4094,0)) | I15: =INDEX(PyKey!F$3:F$4094,MATCH(Settings!$C$4&"|mit.inv.tot.1",PyKey!$A$3:$A$4094,0)) | J15: =INDEX(PyKey!G$3:G$4094,MATCH(Settings!$C$4&"|mit.inv.tot.1",PyKey!$A$3:$A$4094,0)) | K15: =INDEX(PyKey!H$3:H$4094,MATCH(Settings!$C$4&"|mit.inv.tot.1",PyKey!$A$3:$A$4094,0)) | L15: =B15-G15 | M15: =C15-H15 | N15: =D15-I15 | O15: =E15-J15 | P15: =F15-K15
A16: mit.inv.tot.2 | B16: =Mitigation!N221 | C16: =Mitigation!O221 | D16: =Mitigation!T221 | E16: =Mitigation!AD221 | F16: =Mitigation!AN221 | G16: =INDEX(PyKey!D$3:D$4094,MATCH(Settings!$C$4&"|mit.inv.tot.2",PyKey!$A$3:$A$4094,0)) | H16: =INDEX(PyKey!E$3:E$4094,MATCH(Settings!$C$4&"|mit.inv.tot.2",PyKey!$A$3:$A$4094,0)) | I16: =INDEX(PyKey!F$3:F$4094,MATCH(Settings!$C$4&"|mit.inv.tot.2",PyKey!$A$3:$A$4094,0)) | J16: =INDEX(PyKey!G$3:G$4094,MATCH(Settings!$C$4&"|mit.inv.tot.2",PyKey!$A$3:$A$4094,0)) | K16: =INDEX(PyKey!H$3:H$4094,MATCH(Settings!$C$4&"|mit.inv.tot.2",PyKey!$A$3:$A$4094,0)) | L16: =B16-G16 | M16: =C16-H16 | N16: =D16-I16 | O16: =E16-J16 | P16: =F16-K16
A17: mit.ghg.tot.1 | B17: =Mitigation!N200 | C17: =Mitigation!O200 | D17: =Mitigation!T200 | E17: =Mitigation!AD200 | F17: =Mitigation!AN200 | G17: =INDEX(PyKey!D$3:D$4094,MATCH(Settings!$C$4&"|mit.ghg.tot.1",PyKey!$A$3:$A$4094,0)) | H17: =INDEX(PyKey!E$3:E$4094,MATCH(Settings!$C$4&"|mit.ghg.tot.1",PyKey!$A$3:$A$4094,0)) | I17: =INDEX(PyKey!F$3:F$4094,MATCH(Settings!$C$4&"|mit.ghg.tot.1",PyKey!$A$3:$A$4094,0)) | J17: =INDEX(PyKey!G$3:G$4094,MATCH(Settings!$C$4&"|mit.ghg.tot.1",PyKey!$A$3:$A$4094,0)) | K17: =INDEX(PyKey!H$3:H$4094,MATCH(Settings!$C$4&"|mit.ghg.tot.1",PyKey!$A$3:$A$4094,0)) | L17: =B17-G17 | M17: =C17-H17 | N17: =D17-I17 | O17: =E17-J17 | P17: =F17-K17
A18: mit.ghg.tot.2 | B18: =Mitigation!N206 | C18: =Mitigation!O206 | D18: =Mitigation!T206 | E18: =Mitigation!AD206 | F18: =Mitigation!AN206 | G18: =INDEX(PyKey!D$3:D$4094,MATCH(Settings!$C$4&"|mit.ghg.tot.2",PyKey!$A$3:$A$4094,0)) | H18: =INDEX(PyKey!E$3:E$4094,MATCH(Settings!$C$4&"|mit.ghg.tot.2",PyKey!$A$3:$A$4094,0)) | I18: =INDEX(PyKey!F$3:F$4094,MATCH(Settings!$C$4&"|mit.ghg.tot.2",PyKey!$A$3:$A$4094,0)) | J18: =INDEX(PyKey!G$3:G$4094,MATCH(Settings!$C$4&"|mit.ghg.tot.2",PyKey!$A$3:$A$4094,0)) | K18: =INDEX(PyKey!H$3:H$4094,MATCH(Settings!$C$4&"|mit.ghg.tot.2",PyKey!$A$3:$A$4094,0)) | L18: =B18-G18 | M18: =C18-H18 | N18: =D18-I18 | O18: =E18-J18 | P18: =F18-K18
A19: mit.ic.a | B19: =Mitigation!N235 | C19: =Mitigation!O235 | D19: =Mitigation!T235 | E19: =Mitigation!AD235 | F19: =Mitigation!AN235 | G19: =INDEX(PyKey!D$3:D$4094,MATCH(Settings!$C$4&"|mit.ic.a",PyKey!$A$3:$A$4094,0)) | H19: =INDEX(PyKey!E$3:E$4094,MATCH(Settings!$C$4&"|mit.ic.a",PyKey!$A$3:$A$4094,0)) | I19: =INDEX(PyKey!F$3:F$4094,MATCH(Settings!$C$4&"|mit.ic.a",PyKey!$A$3:$A$4094,0)) | J19: =INDEX(PyKey!G$3:G$4094,MATCH(Settings!$C$4&"|mit.ic.a",PyKey!$A$3:$A$4094,0)) | K19: =INDEX(PyKey!H$3:H$4094,MATCH(Settings!$C$4&"|mit.ic.a",PyKey!$A$3:$A$4094,0)) | L19: =B19-G19 | M19: =C19-H19 | N19: =D19-I19 | O19: =E19-J19 | P19: =F19-K19
A20: mit.ic.b | B20: =Mitigation!N236 | C20: =Mitigation!O236 | D20: =Mitigation!T236 | E20: =Mitigation!AD236 | F20: =Mitigation!AN236 | G20: =INDEX(PyKey!D$3:D$4094,MATCH(Settings!$C$4&"|mit.ic.b",PyKey!$A$3:$A$4094,0)) | H20: =INDEX(PyKey!E$3:E$4094,MATCH(Settings!$C$4&"|mit.ic.b",PyKey!$A$3:$A$4094,0)) | I20: =INDEX(PyKey!F$3:F$4094,MATCH(Settings!$C$4&"|mit.ic.b",PyKey!$A$3:$A$4094,0)) | J20: =INDEX(PyKey!G$3:G$4094,MATCH(Settings!$C$4&"|mit.ic.b",PyKey!$A$3:$A$4094,0)) | K20: =INDEX(PyKey!H$3:H$4094,MATCH(Settings!$C$4&"|mit.ic.b",PyKey!$A$3:$A$4094,0)) | L20: =B20-G20 | M20: =C20-H20 | N20: =D20-I20 | O20: =E20-J20 | P20: =F20-K20
A21: mit.ic.c | B21: =Mitigation!N237 | C21: =Mitigation!O237 | D21: =Mitigation!T237 | E21: =Mitigation!AD237 | F21: =Mitigation!AN237 | G21: =INDEX(PyKey!D$3:D$4094,MATCH(Settings!$C$4&"|mit.ic.c",PyKey!$A$3:$A$4094,0)) | H21: =INDEX(PyKey!E$3:E$4094,MATCH(Settings!$C$4&"|mit.ic.c",PyKey!$A$3:$A$4094,0)) | I21: =INDEX(PyKey!F$3:F$4094,MATCH(Settings!$C$4&"|mit.ic.c",PyKey!$A$3:$A$4094,0)) | J21: =INDEX(PyKey!G$3:G$4094,MATCH(Settings!$C$4&"|mit.ic.c",PyKey!$A$3:$A$4094,0)) | K21: =INDEX(PyKey!H$3:H$4094,MATCH(Settings!$C$4&"|mit.ic.c",PyKey!$A$3:$A$4094,0)) | L21: =B21-G21 | M21: =C21-H21 | N21: =D21-I21 | O21: =E21-J21 | P21: =F21-K21
A22: mit.typ.p1.2 | B22: =Mitigation!N247 | C22: =Mitigation!O247 | D22: =Mitigation!T247 | E22: =Mitigation!AD247 | F22: =Mitigation!AN247 | G22: =INDEX(PyKey!D$3:D$4094,MATCH(Settings!$C$4&"|mit.typ.p1.2",PyKey!$A$3:$A$4094,0)) | H22: =INDEX(PyKey!E$3:E$4094,MATCH(Settings!$C$4&"|mit.typ.p1.2",PyKey!$A$3:$A$4094,0)) | I22: =INDEX(PyKey!F$3:F$4094,MATCH(Settings!$C$4&"|mit.typ.p1.2",PyKey!$A$3:$A$4094,0)) | J22: =INDEX(PyKey!G$3:G$4094,MATCH(Settings!$C$4&"|mit.typ.p1.2",PyKey!$A$3:$A$4094,0)) | K22: =INDEX(PyKey!H$3:H$4094,MATCH(Settings!$C$4&"|mit.typ.p1.2",PyKey!$A$3:$A$4094,0)) | L22: =B22-G22 | M22: =C22-H22 | N22: =D22-I22 | O22: =E22-J22 | P22: =F22-K22
A23: mit.typ.p2.2 | B23: =Mitigation!N248 | C23: =Mitigation!O248 | D23: =Mitigation!T248 | E23: =Mitigation!AD248 | F23: =Mitigation!AN248 | G23: =INDEX(PyKey!D$3:D$4094,MATCH(Settings!$C$4&"|mit.typ.p2.2",PyKey!$A$3:$A$4094,0)) | H23: =INDEX(PyKey!E$3:E$4094,MATCH(Settings!$C$4&"|mit.typ.p2.2",PyKey!$A$3:$A$4094,0)) | I23: =INDEX(PyKey!F$3:F$4094,MATCH(Settings!$C$4&"|mit.typ.p2.2",PyKey!$A$3:$A$4094,0)) | J23: =INDEX(PyKey!G$3:G$4094,MATCH(Settings!$C$4&"|mit.typ.p2.2",PyKey!$A$3:$A$4094,0)) | K23: =INDEX(PyKey!H$3:H$4094,MATCH(Settings!$C$4&"|mit.typ.p2.2",PyKey!$A$3:$A$4094,0)) | L23: =B23-G23 | M23: =C23-H23 | N23: =D23-I23 | O23: =E23-J23 | P23: =F23-K23
A24: mit.typ.p3.2 | B24: =Mitigation!N249 | C24: =Mitigation!O249 | D24: =Mitigation!T249 | E24: =Mitigation!AD249 | F24: =Mitigation!AN249 | G24: =INDEX(PyKey!D$3:D$4094,MATCH(Settings!$C$4&"|mit.typ.p3.2",PyKey!$A$3:$A$4094,0)) | H24: =INDEX(PyKey!E$3:E$4094,MATCH(Settings!$C$4&"|mit.typ.p3.2",PyKey!$A$3:$A$4094,0)) | I24: =INDEX(PyKey!F$3:F$4094,MATCH(Settings!$C$4&"|mit.typ.p3.2",PyKey!$A$3:$A$4094,0)) | J24: =INDEX(PyKey!G$3:G$4094,MATCH(Settings!$C$4&"|mit.typ.p3.2",PyKey!$A$3:$A$4094,0)) | K24: =INDEX(PyKey!H$3:H$4094,MATCH(Settings!$C$4&"|mit.typ.p3.2",PyKey!$A$3:$A$4094,0)) | L24: =B24-G24 | M24: =C24-H24 | N24: =D24-I24 | O24: =E24-J24 | P24: =F24-K24
A25: mit.typ.p4.2 | B25: =Mitigation!N250 | C25: =Mitigation!O250 | D25: =Mitigation!T250 | E25: =Mitigation!AD250 | F25: =Mitigation!AN250 | G25: =INDEX(PyKey!D$3:D$4094,MATCH(Settings!$C$4&"|mit.typ.p4.2",PyKey!$A$3:$A$4094,0)) | H25: =INDEX(PyKey!E$3:E$4094,MATCH(Settings!$C$4&"|mit.typ.p4.2",PyKey!$A$3:$A$4094,0)) | I25: =INDEX(PyKey!F$3:F$4094,MATCH(Settings!$C$4&"|mit.typ.p4.2",PyKey!$A$3:$A$4094,0)) | J25: =INDEX(PyKey!G$3:G$4094,MATCH(Settings!$C$4&"|mit.typ.p4.2",PyKey!$A$3:$A$4094,0)) | K25: =INDEX(PyKey!H$3:H$4094,MATCH(Settings!$C$4&"|mit.typ.p4.2",PyKey!$A$3:$A$4094,0)) | L25: =B25-G25 | M25: =C25-H25 | N25: =D25-I25 | O25: =E25-J25 | P25: =F25-K25
A26: mit.typ.p5.2 | B26: =Mitigation!N251 | C26: =Mitigation!O251 | D26: =Mitigation!T251 | E26: =Mitigation!AD251 | F26: =Mitigation!AN251 | G26: =INDEX(PyKey!D$3:D$4094,MATCH(Settings!$C$4&"|mit.typ.p5.2",PyKey!$A$3:$A$4094,0)) | H26: =INDEX(PyKey!E$3:E$4094,MATCH(Settings!$C$4&"|mit.typ.p5.2",PyKey!$A$3:$A$4094,0)) | I26: =INDEX(PyKey!F$3:F$4094,MATCH(Settings!$C$4&"|mit.typ.p5.2",PyKey!$A$3:$A$4094,0)) | J26: =INDEX(PyKey!G$3:G$4094,MATCH(Settings!$C$4&"|mit.typ.p5.2",PyKey!$A$3:$A$4094,0)) | K26: =INDEX(PyKey!H$3:H$4094,MATCH(Settings!$C$4&"|mit.typ.p5.2",PyKey!$A$3:$A$4094,0)) | L26: =B26-G26 | M26: =C26-H26 | N26: =D26-I26 | O26: =E26-J26 | P26: =F26-K26
A27: mit.typ.bud.2 | B27: =Mitigation!N257 | C27: =Mitigation!O257 | D27: =Mitigation!T257 | E27: =Mitigation!AD257 | F27: =Mitigation!AN257 | G27: =INDEX(PyKey!D$3:D$4094,MATCH(Settings!$C$4&"|mit.typ.bud.2",PyKey!$A$3:$A$4094,0)) | H27: =INDEX(PyKey!E$3:E$4094,MATCH(Settings!$C$4&"|mit.typ.bud.2",PyKey!$A$3:$A$4094,0)) | I27: =INDEX(PyKey!F$3:F$4094,MATCH(Settings!$C$4&"|mit.typ.bud.2",PyKey!$A$3:$A$4094,0)) | J27: =INDEX(PyKey!G$3:G$4094,MATCH(Settings!$C$4&"|mit.typ.bud.2",PyKey!$A$3:$A$4094,0)) | K27: =INDEX(PyKey!H$3:H$4094,MATCH(Settings!$C$4&"|mit.typ.bud.2",PyKey!$A$3:$A$4094,0)) | L27: =B27-G27 | M27: =C27-H27 | N27: =D27-I27 | O27: =E27-J27 | P27: =F27-K27

Sheet DATA->

Sheet Data
A1: Data: one row per country (CPAT 2024 panel, Ember, WEO, CBAM tool, v1.1 WACC). Built by extract_data_v0_2.py.
A3: countrycode | B3: name | C3: aei_coa_ind | D3: aei_coa_res | E3: aei_die_rod | F3: aei_ecy_ind | G3: aei_ecy_res | H3: aei_gso_rod | I3: aei_ker_res | J3: aei_lpg_res | K3: aei_nga_ind | L3: aei_nga_res | M3: aei_oil_ind | N3: ap_coa_ind | O3: ap_coa_pow | P3: ap_coa_res | Q3: ap_die_rod | R3: ap_gso_rod | S3: ap_ker_res | T3: ap_lpg_res | U3: ap_nga_ind | V3: ap_nga_pow | W3: ap_nga_res | X3: ap_oil_ind | Y3: ap_oil_pow | Z3: cal24 | AA3: cap_fos | AB3: cap_sol | AC3: cap_wnd | AD3: cbam_g | AE3: cbam_proc24 | AF3: co2_24 | AG3: con_coa_ind | AH3: con_coa_ind_2021 | AI3: con_coa_ind_2022 | AJ3: con_coa_ind_2023 | AK3: con_coa_pow | AL3: con_coa_res | AM3: con_coa_res_2021 | AN3: con_coa_res_2022 | AO3: con_coa_res_2023 | AP3: con_die_rod | AQ3: con_die_rod_2021 | AR3: con_die_rod_2022 | AS3: con_die_rod_2023 | AT3: con_ecy_ind | AU3: con_ecy_ind_2021 | AV3: con_ecy_ind_2022 | AW3: con_ecy_ind_2023 | AX3: con_ecy_res | AY3: con_ecy_res_2021 | AZ3: con_ecy_res_2022 | BA3: con_ecy_res_2023 | BB3: con_gso_rod | BC3: con_gso_rod_2021 | BD3: con_gso_rod_2022 | BE3: con_gso_rod_2023 | BF3: con_ker_res | BG3: con_ker_res_2021 | BH3: con_ker_res_2022 | BI3: con_ker_res_2023 | BJ3: con_lpg_res | BK3: con_lpg_res_2021 | BL3: con_lpg_res_2022 | BM3: con_lpg_res_2023 | BN3: con_nga_ind | BO3: con_nga_ind_2021 | BP3: con_nga_ind_2022 | BQ3: con_nga_ind_2023 | BR3: con_nga_pow | BS3: con_nga_res | BT3: con_nga_res_2021 | BU3: con_nga_res_2022 | BV3: con_nga_res_2023 | BW3: con_oil_ind | BX3: con_oil_ind_2021 | BY3: con_oil_ind_2022 | BZ3: con_oil_ind_2023 | CA3: cr_ecy | CB3: dem_twh24 | CC3: ffs_exp | CD3: fos_trend | CE3: g25 | CF3: g26 | CG3: gdp24 | CH3: gen_cfirm | CI3: gen_coa | CJ3: gen_fos | CK3: gen_nga | CL3: gen_oil | CM3: gen_sol | CN3: gen_tot | CO3: gen_wnd | CP3: ghg_exc | CQ3: ghg_inc | CR3: grp | CS3: inc | CT3: inc_coa_ind | CU3: inc_coa_res | CV3: inc_die_rod | CW3: inc_ecy_ind | CX3: inc_ecy_res | CY3: inc_gso_rod | CZ3: inc_ker_res | DA3: inc_lpg_res | DB3: inc_nga_ind | DC3: inc_nga_res | DD3: inc_oil_ind | DE3: plevel | DF3: pms | DG3: sp_coa_ind | DH3: sp_coa_pow | DI3: sp_coa_res | DJ3: sp_die_rod | DK3: sp_gso_rod | DL3: sp_ker_res | DM3: sp_lpg_res | DN3: sp_nga_ind | DO3: sp_nga_pow | DP3: sp_nga_res | DQ3: sp_oil_ind | DR3: sp_oil_pow | DS3: wacc
A4: ABW | B4: Aruba | C4: 0.005 | D4: 0.005 | E4: 0.01 | F4: 0.005 | G4: 0.005 | H4: 0.01 | I4: 0.005 | J4: 0.005 | K4: 0.01 | L4: 0.01 | M4: 0.005 | N4: 0 | O4: 0 | P4: 0 | Q4: 0 | R4: 0 | S4: 0 | T4: 0 | U4: 0 | V4: 0 | W4: 0 | X4: 0 | Y4: 0 | Z4: 0.016364296 | AA4: 0.24 | AB4: 0.01 | AC4: 0.03 | AD4: 0 | AE4: 0 | AF4: 0.429 | AG4: 0 | AH4: 0 | AI4: 0 | AJ4: 0 | AK4: 0 | AL4: 0 | AM4: 0 | AN4: 0 | AO4: 0 | AP4: 0.6726517 | AQ4: 0.64640713 | AR4: 0.64640713 | AS4: 0.64640713 | AT4: 1.7736358 | AU4: 1.5855804 | AV4: 1.7436998 | AW4: 1.8023056 | AX4: 1.3329033 | AY4: 1.231542 | AZ4: 1.3104061 | BA4: 1.3544489 | BB4: 3.185888 | BC4: 2.9833029 | BD4: 3.155658 | BE4: 3.0682705 | BF4: 0 | BG4: 0 | BH4: 0 | BI4: 0 | BJ4: 0.3839034 | BK4: 0.37032924 | BL4: 0.37032924 | BM4: 0.37032924 | BN4: 0 | BO4: 0 | BP4: 0 | BQ4: 0 | BR4: 0 | BS4: 0 | BT4: 0 | BU4: 0 | BV4: 0 | BW4: 11.162686 | BX4: 11.588358 | BY4: 11.50107 | BZ4: 11.282727 | CA4: 1.3702695 | CB4: 0.86292754 | CC4: 0 | CD4: 0 | CE4: 5.608 | CF4: 2.25 | CG4: 4.285 | CH4: 0 | CI4: 0 | CJ4: 0.83 | CK4: 0 | CL4: 0.83 | CM4: 0.03 | CN4: 1 | CO4: 0.14 | CP4: 0.47 | CQ4: 0.47 | CR4: 3 | CS4: 4 | CT4: 0.5 | CU4: 0.3 | CV4: 0.6 | CW4: 0.8 | CX4: 0.8 | CY4: 0.7 | CZ4: 0.5 | DA4: 0.5 | DB4: 1 | DC4: 0.3 | DD4: 0.8 | DE4: 0.76805879 | DF4: 1 | DG4: 7.124 | DH4: 5.575 | DI4: 12.375895 | DJ4: 17.653885 | DK4: 21.924613 | DL4: 15.046824 | DM4: 20.972208 | DN4: 8.176 | DO4: 6.853 | DP4: 16.35977 | DQ4: 13.497473 | DR4: 13.497473 | DS4: 0.105
A5: AFG | B5: Afghanistan | C5: 0.005 | D5: 0.005 | E5: 0.01 | F5: 0.005 | G5: 0.005 | H5: 0.01 | I5: 0.005 | J5: 0.005 | K5: 0.01 | L5: 0.01 | M5: 0.005 | N5: 0.725007 | O5: 0.004124 | P5: 1.988039 | Q5: 0.60171298 | R5: 0.16906045 | S5: 0.26149155 | T5: 0.087122852 | U5: 0.043622 | V5: 0.002521 | W5: 0.010402 | X5: 0.86813036 | Y5: 0.86813036 | Z5: 0.068042629 | AA5: 0.28 | AB5: 0.06 | AC5: 0 | AD5: 0 | AE5: 0 | AF5: 5.893 | AG5: 37.262738 | AH5: 34.328411 | AI5: 34.671695 | AJ5: 34.671695 | AK5: 1.3876284 | AL5: 0 | AM5: 0 | AN5: 0 | AO5: 0 | AP5: 23.103497 | AQ5: 22.030559 | AR5: 22.250865 | AS5: 22.250865 | AT5: 8.0369065 | AU5: 8.3715066 | AV5: 8.0795415 | AW5: 8.0522437 | AX5: 11.885731 | AY5: 12.328619 | AZ5: 11.948784 | BA5: 11.908413 | BB5: 42.414237 | BC5: 43.222909 | BD5: 39.192842 | BE5: 41.36386 | BF5: 2.6071822 | BG5: 2.5860416 | BH5: 2.611902 | BI5: 2.611902 | BJ5: 28.421359 | BK5: 27.42355 | BL5: 27.697785 | BM5: 27.697785 | BN5: 2.87982 | BO5: 2.8664897 | BP5: 2.8951546 | BQ5: 2.8951546 | BR5: 0 | BS5: 0 | BT5: 0 | BU5: 0 | BV5: 0 | BW5: 1.5519122 | BX5: 3.2424263 | BY5: 1.5152981 | BZ5: 1.5153562 | CA5: 0.30216437 | CB5: 5.534066 | CC5: 1.383 | CD5: -0.28905406 | CE5: 3.004 | CF5: 3 | CG5: 17.817 | CH5: 0.75 | CI5: 0.03 | CJ5: 0.13 | CK5: 0 | CL5: 0.1 | CM5: 0.11 | CN5: 0.99 | CO5: 0 | CP5: 29.715 | CQ5: 29.862 | CR5: 3 | CS5: 1 | CT5: 0.5 | CU5: 0.3 | CV5: 0.6 | CW5: 0.8 | CX5: 0.8 | CY5: 0.7 | CZ5: 0.5 | DA5: 0.5 | DB5: 1 | DC5: 0.3 | DD5: 0.8 | DE5: 0.18682367 | DF5: 2 | DG5: 7.124 | DH5: 4.833 | DI5: 12.5961 | DJ5: 20.300446 | DK5: 22.648152 | DL5: 18.999265 | DM5: 21.687694 | DN5: 6.449 | DO5: 5.125 | DP5: 15.829 | DQ5: 14.11517 | DR5: 14.11517 | DS5: 0.105
A6: AGO | B6: Angola | C6: 0.005 | D6: 0.005 | E6: 0.01 | F6: 0.005 | G6: 0.005 | H6: 0.01 | I6: 0.005 | J6: 0.005 | K6: 0.01 | L6: 0.01 | M6: 0.005 | N6: 0.282221 | O6: 0.199568 | P6: 7.193399 | Q6: 2.8222674 | R6: 0.64461446 | S6: 0.58446845 | T6: 0.20706224 | U6: 0.012474 | V6: 0.011921 | W6: 0.017842 | X6: 0.57020957 | Y6: 0.57020957 | Z6: 0.45664979 | AA6: 2.36 | AB6: 0.36 | AC6: 0 | AD6: 0 | AE6: 0 | AF6: 19.873 | AG6: 0 | AH6: 0 | AI6: 0 | AJ6: 0 | AK6: 0 | AL6: 0 | AM6: 0 | AN6: 0 | AO6: 0 | AP6: 52.323103 | AQ6: 55.365613 | AR6: 50.933371 | AS6: 51.442704 | AT6: 18.011454 | AU6: 16.010001 | AV6: 16.164924 | AW6: 14.516393 | AX6: 35.336891 | AY6: 31.410215 | AZ6: 31.714162 | BA6: 28.479888 | BB6: 41.411322 | BC6: 34.262694 | BD6: 49.721231 | BE6: 39.983814 | BF6: 0 | BG6: 0 | BH6: 0 | BI6: 0 | BJ6: 81.853958 | BK6: 80.336927 | BL6: 73.905631 | BM6: 74.644687 | BN6: 25.887409 | BO6: 27.197357 | BP6: 25.020098 | BQ6: 25.270299 | BR6: 37.694277 | BS6: 0 | BT6: 0 | BU6: 0 | BV6: 0 | BW6: 41.162827 | BX6: 82.166654 | BY6: 60.161164 | BZ6: 39.401542 | CA6: 0.08399682 | CB6: 14.818985 | CC6: 3.212 | CD6: -0.57639221 | CE6: 3.13 | CF6: 2.294 | CG6: 119.574 | CH6: 11.05 | CI6: 0 | CJ6: 4.1 | CK6: 1.4 | CL6: 2.7 | CM6: 0.44 | CN6: 15.59 | CO6: 0 | CP6: 70.933 | CQ6: 113.459 | CR6: 3 | CS6: 2 | CT6: 0.5 | CU6: 0.3 | CV6: 0.6 | CW6: 0.8 | CX6: 0.8 | CY6: 0.7 | CZ6: 0.5 | DA6: 0.5 | DB6: 1 | DC6: 0.3 | DD6: 0.8 | DE6: 0.31475622 | DF6: 2 | DG6: 7.124 | DH6: 5.575 | DI6: 13.90002 | DJ6: 20.889101 | DK6: 23.371435 | DL6: 15.656115 | DM6: 22.525485 | DN6: 6.696 | DO6: 6.034 | DP6: 12.16038 | DQ6: 13.494746 | DR6: 13.494746 | DS6: 0.105
A7: ALB | B7: Albania | C7: 0.005 | D7: 0.005 | E7: 0.01 | F7: 0.005 | G7: 0.005 | H7: 0.01 | I7: 0.005 | J7: 0.005 | K7: 0.01 | L7: 0.01 | M7: 0.005 | N7: 0.854677 | O7: 0.895432 | P7: 66.69538 | Q7: 12.628385 | R7: 1.3628068 | S7: 4.1329228 | T7: 4.7884985 | U7: 0.552136 | V7: 0.090351 | W7: 0.198232 | X7: 8.9926945 | Y7: 8.9926945 | Z7: 0.10343304 | AA7: 0 | AB7: 0 | AC7: 0 | AD7: 3.2 | AE7: 0 | AF7: 4.479 | AG7: 9.9748785 | AH7: 9.3703515 | AI7: 9.7264248 | AJ7: 9.3568207 | AK7: 0 | AL7: 0.14880412 | AM7: 0.13665297 | AN7: 0.14184578 | AO7: 0.13645564 | AP7: 20.596581 | AQ7: 20.443194 | AR7: 21.220036 | AS7: 20.413674 | AT7: 12.745462 | AU7: 11.379739 | AV7: 12.274368 | AW7: 12.929552 | AX7: 14.030846 | AY7: 12.616742 | AZ7: 13.51241 | BA7: 14.233809 | BB7: 3.1098948 | BC7: 3.0867562 | BD7: 3.1704411 | BE7: 3.082299 | BF7: 0 | BG7: 0 | BH7: 0 | BI7: 0 | BJ7: 5.425202 | BK7: 5.1191744 | BL7: 5.313703 | BM7: 5.1117823 | BN7: 1.6153267 | BO7: 1.5822001 | BP7: 1.6423237 | BQ7: 1.5799154 | BR7: 0 | BS7: 0.27693795 | BT7: 0.27125859 | BU7: 0.28156641 | BV7: 0.27086689 | BW7: 12.710964 | BX7: 12.276594 | BY7: 12.737206 | BZ7: 12.258867 | CA7: 1.0202288 | CB7: 7.4378632 | CC7: 0 | CD7: 0 | CE7: 3.705 | CF7: 3.409 | CG7: 27.084 | CH7: 6.707 | CI7: 0 | CJ7: 0 | CK7: 0 | CL7: 0 | CM7: 0.404 | CN7: 7.111 | CO7: 0 | CP7: 8.074 | CQ7: 7.828 | CR7: 3 | CS7: 3 | CT7: 0.5 | CU7: 0.3 | CV7: 0.6 | CW7: 0.8 | CX7: 0.8 | CY7: 0.7 | CZ7: 0.5 | DA7: 0.5 | DB7: 1 | DC7: 0.3 | DD7: 0.8 | DE7: 0.45608245 | DF7: 3 | DG7: 5.333 | DH7: 3.252 | DI7: 9.9468 | DJ7: 21.594018 | DK7: 23.934779 | DL7: 15.656115 | DM7: 22.265009 | DN7: 6.853 | DO7: 6.191 | DP7: 12.9876 | DQ7: 13.494746 | DR7: 13.494746 | DS7: 0.105
A8: ARE | B8: United Arab Emirates | C8: 0.005 | D8: 0.005 | E8: 0.01 | F8: 0.005 | G8: 0.005 | H8: 0.01 | I8: 0.005 | J8: 0.005 | K8: 0.01 | L8: 0.01 | M8: 0.005 | N8: 4.186571 | O8: 1.405832 | P8: 10.854225 | Q8: 6.4463004 | R8: 1.4539713 | S8: 1.9410933 | T8: 2.636533 | U8: 0.238403 | V8: 0.22187 | W8: 0.020982 | X8: 5.6690649 | Y8: 5.6690649 | Z8: 2.1093139 | AA8: 41.7 | AB8: 6.5 | AC8: 0.11 | AD8: 3 | AE8: 4.2625469 | AF8: 230.363 | AG8: 96.938444 | AH8: 86.409858 | AI8: 87.273957 | AJ8: 89.698233 | AK8: 5.3875039 | AL8: 0 | AM8: 0 | AN8: 0 | AO8: 0 | AP8: 143.66293 | AQ8: 131.30045 | AR8: 132.61345 | AS8: 136.29716 | AT8: 393.28241 | AU8: 330.53553 | AV8: 357.79146 | AW8: 382.69435 | AX8: 180.25171 | AY8: 154.58869 | AZ8: 163.98527 | BA8: 175.39892 | BB8: 366.23614 | BC8: 322.84879 | BD8: 349.82194 | BE8: 347.1227 | BF8: 0 | BG8: 0 | BH8: 0 | BI8: 0 | BJ8: 9.93201 | BK8: 9.1724673 | BL8: 9.2641919 | BM8: 9.5215306 | BN8: 1201.582 | BO8: 1057.5446 | BP8: 1068.1201 | BQ8: 1097.7901 | BR8: 1240.1624 | BS8: 0 | BT8: 0 | BU8: 0 | BV8: 0 | BW8: 104.19137 | BX8: 105.49164 | BY8: 97.992603 | BZ8: 100.71815 | CA8: 0.7796992 | CB8: 159.31503 | CC8: 2.028 | CD8: 6.820554 | CE8: 5.804 | CF8: 3.143 | CG8: 552.325 | CH8: 40.84 | CI8: 0 | CJ8: 121.01 | CK8: 121.01 | CL8: 0 | CM8: 15.21 | CN8: 177.26 | CO8: 0.2 | CP8: 313.523 | CQ8: 313.523 | CR8: 3 | CS8: 4 | CT8: 0.5 | CU8: 0.3 | CV8: 0.6 | CW8: 0.8 | CX8: 0.8 | CY8: 0.7 | CZ8: 0.5 | DA8: 0.5 | DB8: 1 | DC8: 0.3 | DD8: 0.8 | DE8: 0.63361676 | DF8: 2 | DG8: 7.124 | DH8: 5.575 | DI8: 12.80265 | DJ8: 20.150722 | DK8: 21.618691 | DL8: 17.272059 | DM8: 20.40463 | DN8: 6.831 | DO8: 5.975 | DP8: 12.5643 | DQ8: 14.11517 | DR8: 14.11517 | DS8: 0.0535
A9: ARG | B9: Argentina | C9: 0.005 | D9: 0.005 | E9: 0.01 | F9: 0.005 | G9: 0.005 | H9: 0.01 | I9: 0.005 | J9: 0.005 | K9: 0.01 | L9: 0.01 | M9: 0.005 | N9: 3.013924 | O9: 1.427653 | P9: 49.865627 | Q9: 16.495317 | R9: 2.5698504 | S9: 1.939133 | T9: 1.6714709 | U9: 0.096787 | V9: 0.090456 | W9: 0.07618 | X9: 7.3222096 | Y9: 7.3222096 | Z9: 2.433579 | AA9: 28.04 | AB9: 2.59 | AC9: 4.5 | AD9: 3.6 | AE9: 0.20358314 | AF9: 169.164 | AG9: 21.679507 | AH9: 20.019167 | AI9: 20.739857 | AJ9: 20.470239 | AK9: 66.214919 | AL9: 0 | AM9: 0 | AN9: 0 | AO9: 0 | AP9: 284.36721 | AQ9: 296.81962 | AR9: 307.50512 | AS9: 303.50756 | AT9: 282.98121 | AU9: 292.07607 | AV9: 346.24293 | AW9: 280.94466 | AX9: 162.24679 | AY9: 172.65843 | AZ9: 198.53345 | BA9: 161.06134 | BB9: 224.38993 | BC9: 233.17949 | BD9: 275.96728 | BE9: 254.842 | BF9: 8.6041301 | BG9: 9.5794964 | BH9: 9.9243583 | BI9: 9.7953417 | BJ9: 51.22736 | BK9: 56.513731 | BL9: 58.548225 | BM9: 57.787099 | BN9: 477.05652 | BO9: 474.62498 | BP9: 491.71148 | BQ9: 485.31923 | BR9: 548.04669 | BS9: 419.69659 | BT9: 424.62073 | BU9: 439.90708 | BV9: 434.18828 | BW9: 250.88375 | BX9: 355.80849 | BY9: 260.51761 | BZ9: 258.29935 | CA9: 0.80858843 | CB9: 123.67444 | CC9: 2.164 | CD9: 2.4839869 | CE9: 4.367 | CF9: 3.5 | CG9: 637.234 | CH9: 39.96 | CI9: 1.34 | CJ9: 89.41 | CK9: 82.15 | CL9: 5.92 | CM9: 5.14 | CN9: 153.13 | CO9: 18.62 | CP9: 370.869 | CQ9: 404.174 | CR9: 3 | CS9: 4 | CT9: 0.5 | CU9: 0.3 | CV9: 0.6 | CW9: 0.8 | CX9: 0.8 | CY9: 0.7 | CZ9: 0.5 | DA9: 0.5 | DB9: 1 | DC9: 0.3 | DD9: 0.8 | DE9: 0.45758351 | DF9: 3 | DG9: 7.084 | DH9: 5.538 | DI9: 14.66641 | DJ9: 18.677931 | DK9: 26.158616 | DL9: 18.206657 | DM9: 23.87845 | DN9: 8.851 | DO9: 8.117 | DP9: 16.04097 | DQ9: 13.494746 | DR9: 13.494746 | DS9: 0.12688
