Workbook
Name ELAST: _xlfn.LAMBDA(_xlpm.kind,_xlpm.fuel,_xlpm.group,INDEX(Data_Elast!$D:$G, MATCH(_xlpm.kind&"_"&_xlpm.fuel, Data_Elast!$A:$A, 0), MATCH(_xlpm.group, Data_Elast!$D$1:$G$1, 0)))
Name OUTCODE: _xlfn.LAMBDA(_xlpm.country,_xlpm.vname,_xlpm.sector,_xlpm.fuel,_xlpm.scen,_xlpm.country&".mit."&_xlpm.vname&"."&_xlpm.sector&"."&_xlpm.fuel&".e."&_xlpm.scen)
Name POSTTAX: _xlfn.LAMBDA(_xlpm.ptp,_xlpm.nce,_xlpm.tcf,_xlpm.ptp+_xlpm.nce*_xlpm.tcf)
Name SHADOW: _xlfn.LAMBDA(_xlpm.atp,_xlpm.sigma,_xlpm.ssc,_xlpm.atp+_xlpm.sigma*_xlpm.ssc)

Sheet Settings
A1: CPAT industry kernel - Egypt prototype v0.2 (LAMBDA build)
A3: Country code | B3: egy | C3: First component of every code; CPAT convention (egy.mit.<var>.<sector>.<fuel>.<type>.<scenario>)
A4: Price group for industry sectors | B4: ind | C4: C2 retail-price group the four sectors read (pow / res / ind / tra)
A5: Elasticity column | B5: Industries | C5: Column of the master elasticity table (Transport / Residential / Industries / Services)
A6: Base year | B6: 2022 | C6: MTInputs FirstYearCalculations; energy in the base year is read from Data_Energy, later years from the kernel
A7: Additional policy-induced efficiency (alpha+) | B7: =INDEX(MTInputs!$F$8:$F$415,MATCH("AdditionalEfficiencyIndustrial",MTInputs!$H$8:$H$415,0)) -> 0 | C7: Read from the MTInputs column by NameOfParameter; this is the only MTInputs dependency of the kernel rows
A8: Carbon price start year (info) | B8: =INDEX(MTInputs!$F$8:$F$415,MATCH("CPIntro",MTInputs!$H$8:$H$415,0)) -> 2026 | C8: For reference: the policy scenario new-policy wedge (nce) starts here
A9: Carbon price target (info) | B9: =INDEX(MTInputs!$F$8:$F$415,MATCH("CPLevelTarget",MTInputs!$H$8:$H$415,0)) -> 50 | C9: $/tCO2
A12: Kernel (every energy cell, year t >= 2023):
A13: F(t) = F(t-1) * (1+g)^(eY*delta) * (1+psi) * (p(t)/p(t-1))^eU * [ (s(t)/s(t-1))^eF / (1 + a + a+) ]^(1+eU)
A14: p = post-tax price (atp), s = shadow price (shp) = atp + sigma*ssc, g = post-policy GDP growth, delta = income-elasticity discount, psi = exogenous shock
A16: Sheets
A17: Mitigation_Industry | C17: Kernel sheet in the CPAT Mitigation layout (columns A-AI, years K-AI): 4 CBAM sectors x 2 scenarios. All formulas; codes built from components.
A18: MTInputs | C18: The 415-row CPAT parameter column, copied unchanged (columns A-I of the MTInputs sheet).
A19: Data_Energy | C19: Base-year energy matrix, fuel x sector, ktoe (Mitigation B4 rows 583-602).
A20: Data_Prices | C20: Pre-tax price before new policies (pbc), new-policy wedge (nce), shadow price (shp), sector coverage (tcf), share of shadow price on efficiency (ssc); both scenarios.
A21: Data_Macro | C21: GDP growth, income-elasticity discount factor, exogenous shock; both scenarios.
A22: Data_Elast | C22: Master elasticity table (income, usage, efficiency, AEEI) by fuel group x sector group, plus the fuel-group map.
A23: Check | C23: Kernel output against the values stored in CPAT_1_0pre_456 for the same rows; max absolute and relative differences.

Sheet Mitigation_Industry
B1: Fuel | C1: Sector | D1: Description | E1: Unit | F1: Source | G1: Input Code | H1: Output Code | I1: Note | J1: Helper | K1: 2021 | L1: 2022 | M1: 2023 | N1: 2024 | O1: 2025 | P1: 2026 | Q1: 2027 | R1: 2028 | S1: 2029 | T1: 2030 | U1: 2031 | V1: 2032 | W1: 2033 | X1: 2034 | Y1: 2035 | Z1: 2036 | AA1: 2037 | AB1: 2038 | AC1: 2039 | AD1: 2040 | AE1: 2041 | AF1: 2042 | AG1: 2043 | AH1: 2044 | AI1: 2045
A3: 7 | B3: Industrial sector - Baseline (CBAM sectors: iron and steel, cement, non-ferrous metals, mining & chemicals)
B5: Iron and steel | C5: irn | D5: Fuel Type | E5: Unit | F5: Variable Code | G5: Input Code (data-table key) | H5: Output Code | I5: Scenario | J5: 1 | K5: 2021 | L5: 2022 | M5: 2023 | N5: 2024 | O5: 2025 | P5: 2026 | Q5: 2027 | R5: 2028 | S5: 2029 | T5: 2030 | U5: 2031 | V5: 2032 | W5: 2033 | X5: 2034 | Y5: 2035 | Z5: 2036 | AA5: 2037 | AB5: 2038 | AC5: 2039 | AD5: 2040 | AE5: 2041 | AF5: 2042 | AG5: 2043 | AH5: 2044 | AI5: 2045
B6: Pre-tax price: price before any new policy (supply cost + VAT + existing excise, subsidies and carbon prices)
B7: coa | C7: =$C$5 -> irn | D7: Coal | E7: $/GJ | F7: ptp | G7: =Settings!$B$3&".mit.pbc."&Settings!$B$4&"."&$B7&".a."&$J$5 -> egy.mit.pbc.ind.coa.a.1 | H7: =OUTCODE(Settings!$B$3,"ptp",$C$5,$B7,$J$5) -> egy.mit.ptp.irn.coa.e.1 | K7: =INDEX(Data_Prices!K:K,MATCH($G7,Data_Prices!$A:$A,0)) -> 11.182902 | L7: =INDEX(Data_Prices!L:L,MATCH($G7,Data_Prices!$A:$A,0)) -> 10.523361 | M7: =INDEX(Data_Prices!M:M,MATCH($G7,Data_Prices!$A:$A,0)) -> 10.299561 | N7: =INDEX(Data_Prices!N:N,MATCH($G7,Data_Prices!$A:$A,0)) -> 9.5775284 | O7: =INDEX(Data_Prices!O:O,MATCH($G7,Data_Prices!$A:$A,0)) -> 8.4854783 | P7: =INDEX(Data_Prices!P:P,MATCH($G7,Data_Prices!$A:$A,0)) -> 9.0871922 | Q7: =INDEX(Data_Prices!Q:Q,MATCH($G7,Data_Prices!$A:$A,0)) -> 9.2229237 | R7: =INDEX(Data_Prices!R:R,MATCH($G7,Data_Prices!$A:$A,0)) -> 9.158565 | S7: =INDEX(Data_Prices!S:S,MATCH($G7,Data_Prices!$A:$A,0)) -> 9.0895479 | T7: =INDEX(Data_Prices!T:T,MATCH($G7,Data_Prices!$A:$A,0)) -> 9.0156817 | U7: =INDEX(Data_Prices!U:U,MATCH($G7,Data_Prices!$A:$A,0)) -> 8.9443978 | V7: =INDEX(Data_Prices!V:V,MATCH($G7,Data_Prices!$A:$A,0)) -> 8.9443978 | W7: =INDEX(Data_Prices!W:W,MATCH($G7,Data_Prices!$A:$A,0)) -> 8.9443978 | X7: =INDEX(Data_Prices!X:X,MATCH($G7,Data_Prices!$A:$A,0)) -> 8.9443978 | Y7: =INDEX(Data_Prices!Y:Y,MATCH($G7,Data_Prices!$A:$A,0)) -> 8.9443978 | Z7: =INDEX(Data_Prices!Z:Z,MATCH($G7,Data_Prices!$A:$A,0)) -> 8.9443978 | AA7: =INDEX(Data_Prices!AA:AA,MATCH($G7,Data_Prices!$A:$A,0)) -> 8.9443978 | AB7: =INDEX(Data_Prices!AB:AB,MATCH($G7,Data_Prices!$A:$A,0)) -> 8.9443978 | AC7: =INDEX(Data_Prices!AC:AC,MATCH($G7,Data_Prices!$A:$A,0)) -> 8.9443978 | AD7: =INDEX(Data_Prices!AD:AD,MATCH($G7,Data_Prices!$A:$A,0)) -> 8.9443978 | AE7: =INDEX(Data_Prices!AE:AE,MATCH($G7,Data_Prices!$A:$A,0)) -> 8.9443978
B8: nga | C8: =$C$5 -> irn | D8: Natural gas | E8: $/GJ | F8: ptp | G8: =Settings!$B$3&".mit.pbc."&Settings!$B$4&"."&$B8&".a."&$J$5 -> egy.mit.pbc.ind.nga.a.1 | H8: =OUTCODE(Settings!$B$3,"ptp",$C$5,$B8,$J$5) -> egy.mit.ptp.irn.nga.e.1 | K8: =INDEX(Data_Prices!K:K,MATCH($G8,Data_Prices!$A:$A,0)) -> 6.0634636 | L8: =INDEX(Data_Prices!L:L,MATCH($G8,Data_Prices!$A:$A,0)) -> 5.4510151 | M8: =INDEX(Data_Prices!M:M,MATCH($G8,Data_Prices!$A:$A,0)) -> 5.1193563 | N8: =INDEX(Data_Prices!N:N,MATCH($G8,Data_Prices!$A:$A,0)) -> 5.0821846 | O8: =INDEX(Data_Prices!O:O,MATCH($G8,Data_Prices!$A:$A,0)) -> 5.0821846 | P8: =INDEX(Data_Prices!P:P,MATCH($G8,Data_Prices!$A:$A,0)) -> 5.0821846 | Q8: =INDEX(Data_Prices!Q:Q,MATCH($G8,Data_Prices!$A:$A,0)) -> 5.0821846 | R8: =INDEX(Data_Prices!R:R,MATCH($G8,Data_Prices!$A:$A,0)) -> 5.0821846 | S8: =INDEX(Data_Prices!S:S,MATCH($G8,Data_Prices!$A:$A,0)) -> 5.0821846 | T8: =INDEX(Data_Prices!T:T,MATCH($G8,Data_Prices!$A:$A,0)) -> 5.0821846 | U8: =INDEX(Data_Prices!U:U,MATCH($G8,Data_Prices!$A:$A,0)) -> 5.0821846 | V8: =INDEX(Data_Prices!V:V,MATCH($G8,Data_Prices!$A:$A,0)) -> 5.0821846 | W8: =INDEX(Data_Prices!W:W,MATCH($G8,Data_Prices!$A:$A,0)) -> 5.0821846 | X8: =INDEX(Data_Prices!X:X,MATCH($G8,Data_Prices!$A:$A,0)) -> 5.0821846 | Y8: =INDEX(Data_Prices!Y:Y,MATCH($G8,Data_Prices!$A:$A,0)) -> 5.0821846 | Z8: =INDEX(Data_Prices!Z:Z,MATCH($G8,Data_Prices!$A:$A,0)) -> 5.0821846 | AA8: =INDEX(Data_Prices!AA:AA,MATCH($G8,Data_Prices!$A:$A,0)) -> 5.0821846 | AB8: =INDEX(Data_Prices!AB:AB,MATCH($G8,Data_Prices!$A:$A,0)) -> 5.0821846 | AC8: =INDEX(Data_Prices!AC:AC,MATCH($G8,Data_Prices!$A:$A,0)) -> 5.0821846 | AD8: =INDEX(Data_Prices!AD:AD,MATCH($G8,Data_Prices!$A:$A,0)) -> 5.0821846 | AE8: =INDEX(Data_Prices!AE:AE,MATCH($G8,Data_Prices!$A:$A,0)) -> 5.0821846
B9: gso | C9: =$C$5 -> irn | D9: Gasoline | E9: $/liter | F9: ptp | G9: =Settings!$B$3&".mit.pbc."&Settings!$B$4&"."&$B9&".a."&$J$5 -> egy.mit.pbc.ind.gso.a.1 | H9: =OUTCODE(Settings!$B$3,"ptp",$C$5,$B9,$J$5) -> egy.mit.ptp.irn.gso.e.1 | K9: =INDEX(Data_Prices!K:K,MATCH($G9,Data_Prices!$A:$A,0)) -> 0.67114653 | L9: =INDEX(Data_Prices!L:L,MATCH($G9,Data_Prices!$A:$A,0)) -> 0.61197798 | M9: =INDEX(Data_Prices!M:M,MATCH($G9,Data_Prices!$A:$A,0)) -> 0.61180975 | N9: =INDEX(Data_Prices!N:N,MATCH($G9,Data_Prices!$A:$A,0)) -> 0.6035831 | O9: =INDEX(Data_Prices!O:O,MATCH($G9,Data_Prices!$A:$A,0)) -> 0.6035831 | P9: =INDEX(Data_Prices!P:P,MATCH($G9,Data_Prices!$A:$A,0)) -> 0.6035831 | Q9: =INDEX(Data_Prices!Q:Q,MATCH($G9,Data_Prices!$A:$A,0)) -> 0.6035831 | R9: =INDEX(Data_Prices!R:R,MATCH($G9,Data_Prices!$A:$A,0)) -> 0.6035831 | S9: =INDEX(Data_Prices!S:S,MATCH($G9,Data_Prices!$A:$A,0)) -> 0.6035831 | T9: =INDEX(Data_Prices!T:T,MATCH($G9,Data_Prices!$A:$A,0)) -> 0.6035831 | U9: =INDEX(Data_Prices!U:U,MATCH($G9,Data_Prices!$A:$A,0)) -> 0.6035831 | V9: =INDEX(Data_Prices!V:V,MATCH($G9,Data_Prices!$A:$A,0)) -> 0.6035831 | W9: =INDEX(Data_Prices!W:W,MATCH($G9,Data_Prices!$A:$A,0)) -> 0.6035831 | X9: =INDEX(Data_Prices!X:X,MATCH($G9,Data_Prices!$A:$A,0)) -> 0.6035831 | Y9: =INDEX(Data_Prices!Y:Y,MATCH($G9,Data_Prices!$A:$A,0)) -> 0.6035831 | Z9: =INDEX(Data_Prices!Z:Z,MATCH($G9,Data_Prices!$A:$A,0)) -> 0.6035831 | AA9: =INDEX(Data_Prices!AA:AA,MATCH($G9,Data_Prices!$A:$A,0)) -> 0.6035831 | AB9: =INDEX(Data_Prices!AB:AB,MATCH($G9,Data_Prices!$A:$A,0)) -> 0.6035831 | AC9: =INDEX(Data_Prices!AC:AC,MATCH($G9,Data_Prices!$A:$A,0)) -> 0.6035831 | AD9: =INDEX(Data_Prices!AD:AD,MATCH($G9,Data_Prices!$A:$A,0)) -> 0.6035831 | AE9: =INDEX(Data_Prices!AE:AE,MATCH($G9,Data_Prices!$A:$A,0)) -> 0.6035831
B10: die | C10: =$C$5 -> irn | D10: Diesel | E10: $/liter | F10: ptp | G10: =Settings!$B$3&".mit.pbc."&Settings!$B$4&"."&$B10&".a."&$J$5 -> egy.mit.pbc.ind.die.a.1 | H10: =OUTCODE(Settings!$B$3,"ptp",$C$5,$B10,$J$5) -> egy.mit.ptp.irn.die.e.1 | K10: =INDEX(Data_Prices!K:K,MATCH($G10,Data_Prices!$A:$A,0)) -> 0.55971121 | L10: =INDEX(Data_Prices!L:L,MATCH($G10,Data_Prices!$A:$A,0)) -> 0.49458873 | M10: =INDEX(Data_Prices!M:M,MATCH($G10,Data_Prices!$A:$A,0)) -> 0.50778655 | N10: =INDEX(Data_Prices!N:N,MATCH($G10,Data_Prices!$A:$A,0)) -> 0.47043643 | O10: =INDEX(Data_Prices!O:O,MATCH($G10,Data_Prices!$A:$A,0)) -> 0.47043643 | P10: =INDEX(Data_Prices!P:P,MATCH($G10,Data_Prices!$A:$A,0)) -> 0.47043643 | Q10: =INDEX(Data_Prices!Q:Q,MATCH($G10,Data_Prices!$A:$A,0)) -> 0.47043643 | R10: =INDEX(Data_Prices!R:R,MATCH($G10,Data_Prices!$A:$A,0)) -> 0.47043643 | S10: =INDEX(Data_Prices!S:S,MATCH($G10,Data_Prices!$A:$A,0)) -> 0.47043643 | T10: =INDEX(Data_Prices!T:T,MATCH($G10,Data_Prices!$A:$A,0)) -> 0.47043643 | U10: =INDEX(Data_Prices!U:U,MATCH($G10,Data_Prices!$A:$A,0)) -> 0.47043643 | V10: =INDEX(Data_Prices!V:V,MATCH($G10,Data_Prices!$A:$A,0)) -> 0.47043643 | W10: =INDEX(Data_Prices!W:W,MATCH($G10,Data_Prices!$A:$A,0)) -> 0.47043643 | X10: =INDEX(Data_Prices!X:X,MATCH($G10,Data_Prices!$A:$A,0)) -> 0.47043643 | Y10: =INDEX(Data_Prices!Y:Y,MATCH($G10,Data_Prices!$A:$A,0)) -> 0.47043643 | Z10: =INDEX(Data_Prices!Z:Z,MATCH($G10,Data_Prices!$A:$A,0)) -> 0.47043643 | AA10: =INDEX(Data_Prices!AA:AA,MATCH($G10,Data_Prices!$A:$A,0)) -> 0.47043643 | AB10: =INDEX(Data_Prices!AB:AB,MATCH($G10,Data_Prices!$A:$A,0)) -> 0.47043643 | AC10: =INDEX(Data_Prices!AC:AC,MATCH($G10,Data_Prices!$A:$A,0)) -> 0.47043643 | AD10: =INDEX(Data_Prices!AD:AD,MATCH($G10,Data_Prices!$A:$A,0)) -> 0.47043643 | AE10: =INDEX(Data_Prices!AE:AE,MATCH($G10,Data_Prices!$A:$A,0)) -> 0.47043643
B11: lpg | C11: =$C$5 -> irn | D11: LPG | E11: $/liter | F11: ptp | G11: =Settings!$B$3&".mit.pbc."&Settings!$B$4&"."&$B11&".a."&$J$5 -> egy.mit.pbc.ind.lpg.a.1 | H11: =OUTCODE(Settings!$B$3,"ptp",$C$5,$B11,$J$5) -> egy.mit.ptp.irn.lpg.e.1 | K11: =INDEX(Data_Prices!K:K,MATCH($G11,Data_Prices!$A:$A,0)) -> 0.20036669 | L11: =INDEX(Data_Prices!L:L,MATCH($G11,Data_Prices!$A:$A,0)) -> 0.15734474 | M11: =INDEX(Data_Prices!M:M,MATCH($G11,Data_Prices!$A:$A,0)) -> 0.16448404 | N11: =INDEX(Data_Prices!N:N,MATCH($G11,Data_Prices!$A:$A,0)) -> 0.15070908 | O11: =INDEX(Data_Prices!O:O,MATCH($G11,Data_Prices!$A:$A,0)) -> 0.15070908 | P11: =INDEX(Data_Prices!P:P,MATCH($G11,Data_Prices!$A:$A,0)) -> 0.15070908 | Q11: =INDEX(Data_Prices!Q:Q,MATCH($G11,Data_Prices!$A:$A,0)) -> 0.15070908 | R11: =INDEX(Data_Prices!R:R,MATCH($G11,Data_Prices!$A:$A,0)) -> 0.15070908 | S11: =INDEX(Data_Prices!S:S,MATCH($G11,Data_Prices!$A:$A,0)) -> 0.15070908 | T11: =INDEX(Data_Prices!T:T,MATCH($G11,Data_Prices!$A:$A,0)) -> 0.15070908 | U11: =INDEX(Data_Prices!U:U,MATCH($G11,Data_Prices!$A:$A,0)) -> 0.15070908 | V11: =INDEX(Data_Prices!V:V,MATCH($G11,Data_Prices!$A:$A,0)) -> 0.15070908 | W11: =INDEX(Data_Prices!W:W,MATCH($G11,Data_Prices!$A:$A,0)) -> 0.15070908 | X11: =INDEX(Data_Prices!X:X,MATCH($G11,Data_Prices!$A:$A,0)) -> 0.15070908 | Y11: =INDEX(Data_Prices!Y:Y,MATCH($G11,Data_Prices!$A:$A,0)) -> 0.15070908 | Z11: =INDEX(Data_Prices!Z:Z,MATCH($G11,Data_Prices!$A:$A,0)) -> 0.15070908 | AA11: =INDEX(Data_Prices!AA:AA,MATCH($G11,Data_Prices!$A:$A,0)) -> 0.15070908 | AB11: =INDEX(Data_Prices!AB:AB,MATCH($G11,Data_Prices!$A:$A,0)) -> 0.15070908 | AC11: =INDEX(Data_Prices!AC:AC,MATCH($G11,Data_Prices!$A:$A,0)) -> 0.15070908 | AD11: =INDEX(Data_Prices!AD:AD,MATCH($G11,Data_Prices!$A:$A,0)) -> 0.15070908 | AE11: =INDEX(Data_Prices!AE:AE,MATCH($G11,Data_Prices!$A:$A,0)) -> 0.15070908
B12: ker | C12: =$C$5 -> irn | D12: Kerosene | E12: $/liter | F12: ptp | G12: =Settings!$B$3&".mit.pbc."&Settings!$B$4&"."&$B12&".a."&$J$5 -> egy.mit.pbc.ind.ker.a.1 | H12: =OUTCODE(Settings!$B$3,"ptp",$C$5,$B12,$J$5) -> egy.mit.ptp.irn.ker.e.1 | K12: =INDEX(Data_Prices!K:K,MATCH($G12,Data_Prices!$A:$A,0)) -> 0.48429424 | L12: =INDEX(Data_Prices!L:L,MATCH($G12,Data_Prices!$A:$A,0)) -> 0.45642817 | M12: =INDEX(Data_Prices!M:M,MATCH($G12,Data_Prices!$A:$A,0)) -> 0.4316892 | N12: =INDEX(Data_Prices!N:N,MATCH($G12,Data_Prices!$A:$A,0)) -> 0.42507558 | O12: =INDEX(Data_Prices!O:O,MATCH($G12,Data_Prices!$A:$A,0)) -> 0.42507558 | P12: =INDEX(Data_Prices!P:P,MATCH($G12,Data_Prices!$A:$A,0)) -> 0.42507558 | Q12: =INDEX(Data_Prices!Q:Q,MATCH($G12,Data_Prices!$A:$A,0)) -> 0.42507558 | R12: =INDEX(Data_Prices!R:R,MATCH($G12,Data_Prices!$A:$A,0)) -> 0.42507558 | S12: =INDEX(Data_Prices!S:S,MATCH($G12,Data_Prices!$A:$A,0)) -> 0.42507558 | T12: =INDEX(Data_Prices!T:T,MATCH($G12,Data_Prices!$A:$A,0)) -> 0.42507558 | U12: =INDEX(Data_Prices!U:U,MATCH($G12,Data_Prices!$A:$A,0)) -> 0.42507558 | V12: =INDEX(Data_Prices!V:V,MATCH($G12,Data_Prices!$A:$A,0)) -> 0.42507558 | W12: =INDEX(Data_Prices!W:W,MATCH($G12,Data_Prices!$A:$A,0)) -> 0.42507558 | X12: =INDEX(Data_Prices!X:X,MATCH($G12,Data_Prices!$A:$A,0)) -> 0.42507558 | Y12: =INDEX(Data_Prices!Y:Y,MATCH($G12,Data_Prices!$A:$A,0)) -> 0.42507558 | Z12: =INDEX(Data_Prices!Z:Z,MATCH($G12,Data_Prices!$A:$A,0)) -> 0.42507558 | AA12: =INDEX(Data_Prices!AA:AA,MATCH($G12,Data_Prices!$A:$A,0)) -> 0.42507558 | AB12: =INDEX(Data_Prices!AB:AB,MATCH($G12,Data_Prices!$A:$A,0)) -> 0.42507558 | AC12: =INDEX(Data_Prices!AC:AC,MATCH($G12,Data_Prices!$A:$A,0)) -> 0.42507558 | AD12: =INDEX(Data_Prices!AD:AD,MATCH($G12,Data_Prices!$A:$A,0)) -> 0.42507558 | AE12: =INDEX(Data_Prices!AE:AE,MATCH($G12,Data_Prices!$A:$A,0)) -> 0.42507558
B13: oop | C13: =$C$5 -> irn | D13: Other oil products | E13: $/bbl | F13: ptp | G13: =Settings!$B$3&".mit.pbc."&Settings!$B$4&"."&$B13&".a."&$J$5 -> egy.mit.pbc.ind.oop.a.1 | H13: =OUTCODE(Settings!$B$3,"ptp",$C$5,$B13,$J$5) -> egy.mit.ptp.irn.oop.e.1 | K13: =INDEX(Data_Prices!K:K,MATCH($G13,Data_Prices!$A:$A,0)) -> 41.500338 | L13: =INDEX(Data_Prices!L:L,MATCH($G13,Data_Prices!$A:$A,0)) -> 34.41537 | M13: =INDEX(Data_Prices!M:M,MATCH($G13,Data_Prices!$A:$A,0)) -> 37.368961 | N13: =INDEX(Data_Prices!N:N,MATCH($G13,Data_Prices!$A:$A,0)) -> 28.982761 | O13: =INDEX(Data_Prices!O:O,MATCH($G13,Data_Prices!$A:$A,0)) -> 15 | P13: =INDEX(Data_Prices!P:P,MATCH($G13,Data_Prices!$A:$A,0)) -> 24.25863 | Q13: =INDEX(Data_Prices!Q:Q,MATCH($G13,Data_Prices!$A:$A,0)) -> 15 | R13: =INDEX(Data_Prices!R:R,MATCH($G13,Data_Prices!$A:$A,0)) -> 15 | S13: =INDEX(Data_Prices!S:S,MATCH($G13,Data_Prices!$A:$A,0)) -> 15 | T13: =INDEX(Data_Prices!T:T,MATCH($G13,Data_Prices!$A:$A,0)) -> 15 | U13: =INDEX(Data_Prices!U:U,MATCH($G13,Data_Prices!$A:$A,0)) -> 15 | V13: =INDEX(Data_Prices!V:V,MATCH($G13,Data_Prices!$A:$A,0)) -> 15 | W13: =INDEX(Data_Prices!W:W,MATCH($G13,Data_Prices!$A:$A,0)) -> 15 | X13: =INDEX(Data_Prices!X:X,MATCH($G13,Data_Prices!$A:$A,0)) -> 15 | Y13: =INDEX(Data_Prices!Y:Y,MATCH($G13,Data_Prices!$A:$A,0)) -> 15 | Z13: =INDEX(Data_Prices!Z:Z,MATCH($G13,Data_Prices!$A:$A,0)) -> 15 | AA13: =INDEX(Data_Prices!AA:AA,MATCH($G13,Data_Prices!$A:$A,0)) -> 15 | AB13: =INDEX(Data_Prices!AB:AB,MATCH($G13,Data_Prices!$A:$A,0)) -> 15 | AC13: =INDEX(Data_Prices!AC:AC,MATCH($G13,Data_Prices!$A:$A,0)) -> 15 | AD13: =INDEX(Data_Prices!AD:AD,MATCH($G13,Data_Prices!$A:$A,0)) -> 15 | AE13: =INDEX(Data_Prices!AE:AE,MATCH($G13,Data_Prices!$A:$A,0)) -> 15
B14: bio | C14: =$C$5 -> irn | D14: Biomass | E14: $/GJ | F14: ptp | G14: =Settings!$B$3&".mit.pbc."&Settings!$B$4&"."&$B14&".a."&$J$5 -> egy.mit.pbc.ind.bio.a.1 | H14: =OUTCODE(Settings!$B$3,"ptp",$C$5,$B14,$J$5) -> egy.mit.ptp.irn.bio.e.1 | K14: =INDEX(Data_Prices!K:K,MATCH($G14,Data_Prices!$A:$A,0)) -> 15.334551 | L14: =INDEX(Data_Prices!L:L,MATCH($G14,Data_Prices!$A:$A,0)) -> 14.199528 | M14: =INDEX(Data_Prices!M:M,MATCH($G14,Data_Prices!$A:$A,0)) -> 13.840442 | N14: =INDEX(Data_Prices!N:N,MATCH($G14,Data_Prices!$A:$A,0)) -> 13.567727 | O14: =INDEX(Data_Prices!O:O,MATCH($G14,Data_Prices!$A:$A,0)) -> 13.567727 | P14: =INDEX(Data_Prices!P:P,MATCH($G14,Data_Prices!$A:$A,0)) -> 13.567727 | Q14: =INDEX(Data_Prices!Q:Q,MATCH($G14,Data_Prices!$A:$A,0)) -> 13.567727 | R14: =INDEX(Data_Prices!R:R,MATCH($G14,Data_Prices!$A:$A,0)) -> 13.567727 | S14: =INDEX(Data_Prices!S:S,MATCH($G14,Data_Prices!$A:$A,0)) -> 13.567727 | T14: =INDEX(Data_Prices!T:T,MATCH($G14,Data_Prices!$A:$A,0)) -> 13.567727 | U14: =INDEX(Data_Prices!U:U,MATCH($G14,Data_Prices!$A:$A,0)) -> 13.567727 | V14: =INDEX(Data_Prices!V:V,MATCH($G14,Data_Prices!$A:$A,0)) -> 13.567727 | W14: =INDEX(Data_Prices!W:W,MATCH($G14,Data_Prices!$A:$A,0)) -> 13.567727 | X14: =INDEX(Data_Prices!X:X,MATCH($G14,Data_Prices!$A:$A,0)) -> 13.567727 | Y14: =INDEX(Data_Prices!Y:Y,MATCH($G14,Data_Prices!$A:$A,0)) -> 13.567727 | Z14: =INDEX(Data_Prices!Z:Z,MATCH($G14,Data_Prices!$A:$A,0)) -> 13.567727 | AA14: =INDEX(Data_Prices!AA:AA,MATCH($G14,Data_Prices!$A:$A,0)) -> 13.567727 | AB14: =INDEX(Data_Prices!AB:AB,MATCH($G14,Data_Prices!$A:$A,0)) -> 13.567727 | AC14: =INDEX(Data_Prices!AC:AC,MATCH($G14,Data_Prices!$A:$A,0)) -> 13.567727 | AD14: =INDEX(Data_Prices!AD:AD,MATCH($G14,Data_Prices!$A:$A,0)) -> 13.567727 | AE14: =INDEX(Data_Prices!AE:AE,MATCH($G14,Data_Prices!$A:$A,0)) -> 13.567727
B15: ren | C15: =$C$5 -> irn | D15: Self-generated renewables | E15: $/kwh | F15: ptp | G15: =Settings!$B$3&".mit.pbc."&Settings!$B$4&"."&$B15&".a."&$J$5 -> egy.mit.pbc.ind.ren.a.1 | H15: =OUTCODE(Settings!$B$3,"ptp",$C$5,$B15,$J$5) -> egy.mit.ptp.irn.ren.e.1 | K15: =INDEX(Data_Prices!K:K,MATCH($G15,Data_Prices!$A:$A,0)) -> 0 | L15: =INDEX(Data_Prices!L:L,MATCH($G15,Data_Prices!$A:$A,0)) -> 0.14404499 | M15: =INDEX(Data_Prices!M:M,MATCH($G15,Data_Prices!$A:$A,0)) -> 0.14102041 | N15: =INDEX(Data_Prices!N:N,MATCH($G15,Data_Prices!$A:$A,0)) -> 0.13511636 | O15: =INDEX(Data_Prices!O:O,MATCH($G15,Data_Prices!$A:$A,0)) -> 0.13098826 | P15: =INDEX(Data_Prices!P:P,MATCH($G15,Data_Prices!$A:$A,0)) -> 0.12790842 | Q15: =INDEX(Data_Prices!Q:Q,MATCH($G15,Data_Prices!$A:$A,0)) -> 0.12481431 | R15: =INDEX(Data_Prices!R:R,MATCH($G15,Data_Prices!$A:$A,0)) -> 0.12146026 | S15: =INDEX(Data_Prices!S:S,MATCH($G15,Data_Prices!$A:$A,0)) -> 0.11795074 | T15: =INDEX(Data_Prices!T:T,MATCH($G15,Data_Prices!$A:$A,0)) -> 0.11419916 | U15: =INDEX(Data_Prices!U:U,MATCH($G15,Data_Prices!$A:$A,0)) -> 0.1136651 | V15: =INDEX(Data_Prices!V:V,MATCH($G15,Data_Prices!$A:$A,0)) -> 0.11301693 | W15: =INDEX(Data_Prices!W:W,MATCH($G15,Data_Prices!$A:$A,0)) -> 0.11231407 | X15: =INDEX(Data_Prices!X:X,MATCH($G15,Data_Prices!$A:$A,0)) -> 0.11142204 | Y15: =INDEX(Data_Prices!Y:Y,MATCH($G15,Data_Prices!$A:$A,0)) -> 0.11043412 | Z15: =INDEX(Data_Prices!Z:Z,MATCH($G15,Data_Prices!$A:$A,0)) -> 0.10948397 | AA15: =INDEX(Data_Prices!AA:AA,MATCH($G15,Data_Prices!$A:$A,0)) -> 0.10839192 | AB15: =INDEX(Data_Prices!AB:AB,MATCH($G15,Data_Prices!$A:$A,0)) -> 0.10735443 | AC15: =INDEX(Data_Prices!AC:AC,MATCH($G15,Data_Prices!$A:$A,0)) -> 0.10516868 | AD15: =INDEX(Data_Prices!AD:AD,MATCH($G15,Data_Prices!$A:$A,0)) -> 0.10305798 | AE15: =INDEX(Data_Prices!AE:AE,MATCH($G15,Data_Prices!$A:$A,0)) -> 0.10093184
B16: Post-tax price: pre-tax + new-policy wedge x sector coverage factor (= CPAT atp row)
B17: coa | C17: =$C$5 -> irn | D17: Coal | E17: $/GJ | F17: atp | G17: =Settings!$B$3&".mit.nce."&Settings!$B$4&"."&$B17&".a."&$J$5 -> egy.mit.nce.ind.coa.a.1 | H17: =OUTCODE(Settings!$B$3,"atp",$C$5,$B17,$J$5) -> egy.mit.atp.irn.coa.e.1 | K17: =POSTTAX(K7,INDEX(Data_Prices!K:K,MATCH($G17,Data_Prices!$A:$A,0)),K$37) -> 11.182902 | L17: =POSTTAX(L7,INDEX(Data_Prices!L:L,MATCH($G17,Data_Prices!$A:$A,0)),L$37) -> 10.523361 | M17: =POSTTAX(M7,INDEX(Data_Prices!M:M,MATCH($G17,Data_Prices!$A:$A,0)),M$37) -> 10.299561 | N17: =POSTTAX(N7,INDEX(Data_Prices!N:N,MATCH($G17,Data_Prices!$A:$A,0)),N$37) -> 9.5775284 | O17: =POSTTAX(O7,INDEX(Data_Prices!O:O,MATCH($G17,Data_Prices!$A:$A,0)),O$37) -> 8.4854783 | P17: =POSTTAX(P7,INDEX(Data_Prices!P:P,MATCH($G17,Data_Prices!$A:$A,0)),P$37) -> 9.0871922 | Q17: =POSTTAX(Q7,INDEX(Data_Prices!Q:Q,MATCH($G17,Data_Prices!$A:$A,0)),Q$37) -> 9.2229237 | R17: =POSTTAX(R7,INDEX(Data_Prices!R:R,MATCH($G17,Data_Prices!$A:$A,0)),R$37) -> 9.158565 | S17: =POSTTAX(S7,INDEX(Data_Prices!S:S,MATCH($G17,Data_Prices!$A:$A,0)),S$37) -> 9.0895479 | T17: =POSTTAX(T7,INDEX(Data_Prices!T:T,MATCH($G17,Data_Prices!$A:$A,0)),T$37) -> 9.0156817 | U17: =POSTTAX(U7,INDEX(Data_Prices!U:U,MATCH($G17,Data_Prices!$A:$A,0)),U$37) -> 8.9443978 | V17: =POSTTAX(V7,INDEX(Data_Prices!V:V,MATCH($G17,Data_Prices!$A:$A,0)),V$37) -> 8.9443978 | W17: =POSTTAX(W7,INDEX(Data_Prices!W:W,MATCH($G17,Data_Prices!$A:$A,0)),W$37) -> 8.9443978 | X17: =POSTTAX(X7,INDEX(Data_Prices!X:X,MATCH($G17,Data_Prices!$A:$A,0)),X$37) -> 8.9443978 | Y17: =POSTTAX(Y7,INDEX(Data_Prices!Y:Y,MATCH($G17,Data_Prices!$A:$A,0)),Y$37) -> 8.9443978 | Z17: =POSTTAX(Z7,INDEX(Data_Prices!Z:Z,MATCH($G17,Data_Prices!$A:$A,0)),Z$37) -> 8.9443978 | AA17: =POSTTAX(AA7,INDEX(Data_Prices!AA:AA,MATCH($G17,Data_Prices!$A:$A,0)),AA$37) -> 8.9443978 | AB17: =POSTTAX(AB7,INDEX(Data_Prices!AB:AB,MATCH($G17,Data_Prices!$A:$A,0)),AB$37) -> 8.9443978 | AC17: =POSTTAX(AC7,INDEX(Data_Prices!AC:AC,MATCH($G17,Data_Prices!$A:$A,0)),AC$37) -> 8.9443978 | AD17: =POSTTAX(AD7,INDEX(Data_Prices!AD:AD,MATCH($G17,Data_Prices!$A:$A,0)),AD$37) -> 8.9443978 | AE17: =POSTTAX(AE7,INDEX(Data_Prices!AE:AE,MATCH($G17,Data_Prices!$A:$A,0)),AE$37) -> 8.9443978
B18: nga | C18: =$C$5 -> irn | D18: Natural gas | E18: $/GJ | F18: atp | G18: =Settings!$B$3&".mit.nce."&Settings!$B$4&"."&$B18&".a."&$J$5 -> egy.mit.nce.ind.nga.a.1 | H18: =OUTCODE(Settings!$B$3,"atp",$C$5,$B18,$J$5) -> egy.mit.atp.irn.nga.e.1 | K18: =POSTTAX(K8,INDEX(Data_Prices!K:K,MATCH($G18,Data_Prices!$A:$A,0)),K$37) -> 6.0634636 | L18: =POSTTAX(L8,INDEX(Data_Prices!L:L,MATCH($G18,Data_Prices!$A:$A,0)),L$37) -> 5.4510151 | M18: =POSTTAX(M8,INDEX(Data_Prices!M:M,MATCH($G18,Data_Prices!$A:$A,0)),M$37) -> 5.1193563 | N18: =POSTTAX(N8,INDEX(Data_Prices!N:N,MATCH($G18,Data_Prices!$A:$A,0)),N$37) -> 5.0821846 | O18: =POSTTAX(O8,INDEX(Data_Prices!O:O,MATCH($G18,Data_Prices!$A:$A,0)),O$37) -> 5.0821846 | P18: =POSTTAX(P8,INDEX(Data_Prices!P:P,MATCH($G18,Data_Prices!$A:$A,0)),P$37) -> 5.0821846 | Q18: =POSTTAX(Q8,INDEX(Data_Prices!Q:Q,MATCH($G18,Data_Prices!$A:$A,0)),Q$37) -> 5.0821846 | R18: =POSTTAX(R8,INDEX(Data_Prices!R:R,MATCH($G18,Data_Prices!$A:$A,0)),R$37) -> 5.0821846 | S18: =POSTTAX(S8,INDEX(Data_Prices!S:S,MATCH($G18,Data_Prices!$A:$A,0)),S$37) -> 5.0821846 | T18: =POSTTAX(T8,INDEX(Data_Prices!T:T,MATCH($G18,Data_Prices!$A:$A,0)),T$37) -> 5.0821846 | U18: =POSTTAX(U8,INDEX(Data_Prices!U:U,MATCH($G18,Data_Prices!$A:$A,0)),U$37) -> 5.0821846 | V18: =POSTTAX(V8,INDEX(Data_Prices!V:V,MATCH($G18,Data_Prices!$A:$A,0)),V$37) -> 5.0821846 | W18: =POSTTAX(W8,INDEX(Data_Prices!W:W,MATCH($G18,Data_Prices!$A:$A,0)),W$37) -> 5.0821846 | X18: =POSTTAX(X8,INDEX(Data_Prices!X:X,MATCH($G18,Data_Prices!$A:$A,0)),X$37) -> 5.0821846 | Y18: =POSTTAX(Y8,INDEX(Data_Prices!Y:Y,MATCH($G18,Data_Prices!$A:$A,0)),Y$37) -> 5.0821846 | Z18: =POSTTAX(Z8,INDEX(Data_Prices!Z:Z,MATCH($G18,Data_Prices!$A:$A,0)),Z$37) -> 5.0821846 | AA18: =POSTTAX(AA8,INDEX(Data_Prices!AA:AA,MATCH($G18,Data_Prices!$A:$A,0)),AA$37) -> 5.0821846 | AB18: =POSTTAX(AB8,INDEX(Data_Prices!AB:AB,MATCH($G18,Data_Prices!$A:$A,0)),AB$37) -> 5.0821846 | AC18: =POSTTAX(AC8,INDEX(Data_Prices!AC:AC,MATCH($G18,Data_Prices!$A:$A,0)),AC$37) -> 5.0821846 | AD18: =POSTTAX(AD8,INDEX(Data_Prices!AD:AD,MATCH($G18,Data_Prices!$A:$A,0)),AD$37) -> 5.0821846 | AE18: =POSTTAX(AE8,INDEX(Data_Prices!AE:AE,MATCH($G18,Data_Prices!$A:$A,0)),AE$37) -> 5.0821846
B19: gso | C19: =$C$5 -> irn | D19: Gasoline | E19: $/liter | F19: atp | G19: =Settings!$B$3&".mit.nce."&Settings!$B$4&"."&$B19&".a."&$J$5 -> egy.mit.nce.ind.gso.a.1 | H19: =OUTCODE(Settings!$B$3,"atp",$C$5,$B19,$J$5) -> egy.mit.atp.irn.gso.e.1 | K19: =POSTTAX(K9,INDEX(Data_Prices!K:K,MATCH($G19,Data_Prices!$A:$A,0)),K$37) -> 0.67114653 | L19: =POSTTAX(L9,INDEX(Data_Prices!L:L,MATCH($G19,Data_Prices!$A:$A,0)),L$37) -> 0.61197798 | M19: =POSTTAX(M9,INDEX(Data_Prices!M:M,MATCH($G19,Data_Prices!$A:$A,0)),M$37) -> 0.61180975 | N19: =POSTTAX(N9,INDEX(Data_Prices!N:N,MATCH($G19,Data_Prices!$A:$A,0)),N$37) -> 0.6035831 | O19: =POSTTAX(O9,INDEX(Data_Prices!O:O,MATCH($G19,Data_Prices!$A:$A,0)),O$37) -> 0.6035831 | P19: =POSTTAX(P9,INDEX(Data_Prices!P:P,MATCH($G19,Data_Prices!$A:$A,0)),P$37) -> 0.6035831 | Q19: =POSTTAX(Q9,INDEX(Data_Prices!Q:Q,MATCH($G19,Data_Prices!$A:$A,0)),Q$37) -> 0.6035831 | R19: =POSTTAX(R9,INDEX(Data_Prices!R:R,MATCH($G19,Data_Prices!$A:$A,0)),R$37) -> 0.6035831 | S19: =POSTTAX(S9,INDEX(Data_Prices!S:S,MATCH($G19,Data_Prices!$A:$A,0)),S$37) -> 0.6035831 | T19: =POSTTAX(T9,INDEX(Data_Prices!T:T,MATCH($G19,Data_Prices!$A:$A,0)),T$37) -> 0.6035831 | U19: =POSTTAX(U9,INDEX(Data_Prices!U:U,MATCH($G19,Data_Prices!$A:$A,0)),U$37) -> 0.6035831 | V19: =POSTTAX(V9,INDEX(Data_Prices!V:V,MATCH($G19,Data_Prices!$A:$A,0)),V$37) -> 0.6035831 | W19: =POSTTAX(W9,INDEX(Data_Prices!W:W,MATCH($G19,Data_Prices!$A:$A,0)),W$37) -> 0.6035831 | X19: =POSTTAX(X9,INDEX(Data_Prices!X:X,MATCH($G19,Data_Prices!$A:$A,0)),X$37) -> 0.6035831 | Y19: =POSTTAX(Y9,INDEX(Data_Prices!Y:Y,MATCH($G19,Data_Prices!$A:$A,0)),Y$37) -> 0.6035831 | Z19: =POSTTAX(Z9,INDEX(Data_Prices!Z:Z,MATCH($G19,Data_Prices!$A:$A,0)),Z$37) -> 0.6035831 | AA19: =POSTTAX(AA9,INDEX(Data_Prices!AA:AA,MATCH($G19,Data_Prices!$A:$A,0)),AA$37) -> 0.6035831 | AB19: =POSTTAX(AB9,INDEX(Data_Prices!AB:AB,MATCH($G19,Data_Prices!$A:$A,0)),AB$37) -> 0.6035831 | AC19: =POSTTAX(AC9,INDEX(Data_Prices!AC:AC,MATCH($G19,Data_Prices!$A:$A,0)),AC$37) -> 0.6035831 | AD19: =POSTTAX(AD9,INDEX(Data_Prices!AD:AD,MATCH($G19,Data_Prices!$A:$A,0)),AD$37) -> 0.6035831 | AE19: =POSTTAX(AE9,INDEX(Data_Prices!AE:AE,MATCH($G19,Data_Prices!$A:$A,0)),AE$37) -> 0.6035831
B20: die | C20: =$C$5 -> irn | D20: Diesel | E20: $/liter | F20: atp | G20: =Settings!$B$3&".mit.nce."&Settings!$B$4&"."&$B20&".a."&$J$5 -> egy.mit.nce.ind.die.a.1 | H20: =OUTCODE(Settings!$B$3,"atp",$C$5,$B20,$J$5) -> egy.mit.atp.irn.die.e.1 | K20: =POSTTAX(K10,INDEX(Data_Prices!K:K,MATCH($G20,Data_Prices!$A:$A,0)),K$37) -> 0.55971121 | L20: =POSTTAX(L10,INDEX(Data_Prices!L:L,MATCH($G20,Data_Prices!$A:$A,0)),L$37) -> 0.49458873 | M20: =POSTTAX(M10,INDEX(Data_Prices!M:M,MATCH($G20,Data_Prices!$A:$A,0)),M$37) -> 0.50778655 | N20: =POSTTAX(N10,INDEX(Data_Prices!N:N,MATCH($G20,Data_Prices!$A:$A,0)),N$37) -> 0.47043643 | O20: =POSTTAX(O10,INDEX(Data_Prices!O:O,MATCH($G20,Data_Prices!$A:$A,0)),O$37) -> 0.47043643 | P20: =POSTTAX(P10,INDEX(Data_Prices!P:P,MATCH($G20,Data_Prices!$A:$A,0)),P$37) -> 0.47043643 | Q20: =POSTTAX(Q10,INDEX(Data_Prices!Q:Q,MATCH($G20,Data_Prices!$A:$A,0)),Q$37) -> 0.47043643 | R20: =POSTTAX(R10,INDEX(Data_Prices!R:R,MATCH($G20,Data_Prices!$A:$A,0)),R$37) -> 0.47043643 | S20: =POSTTAX(S10,INDEX(Data_Prices!S:S,MATCH($G20,Data_Prices!$A:$A,0)),S$37) -> 0.47043643 | T20: =POSTTAX(T10,INDEX(Data_Prices!T:T,MATCH($G20,Data_Prices!$A:$A,0)),T$37) -> 0.47043643 | U20: =POSTTAX(U10,INDEX(Data_Prices!U:U,MATCH($G20,Data_Prices!$A:$A,0)),U$37) -> 0.47043643 | V20: =POSTTAX(V10,INDEX(Data_Prices!V:V,MATCH($G20,Data_Prices!$A:$A,0)),V$37) -> 0.47043643 | W20: =POSTTAX(W10,INDEX(Data_Prices!W:W,MATCH($G20,Data_Prices!$A:$A,0)),W$37) -> 0.47043643 | X20: =POSTTAX(X10,INDEX(Data_Prices!X:X,MATCH($G20,Data_Prices!$A:$A,0)),X$37) -> 0.47043643 | Y20: =POSTTAX(Y10,INDEX(Data_Prices!Y:Y,MATCH($G20,Data_Prices!$A:$A,0)),Y$37) -> 0.47043643 | Z20: =POSTTAX(Z10,INDEX(Data_Prices!Z:Z,MATCH($G20,Data_Prices!$A:$A,0)),Z$37) -> 0.47043643 | AA20: =POSTTAX(AA10,INDEX(Data_Prices!AA:AA,MATCH($G20,Data_Prices!$A:$A,0)),AA$37) -> 0.47043643 | AB20: =POSTTAX(AB10,INDEX(Data_Prices!AB:AB,MATCH($G20,Data_Prices!$A:$A,0)),AB$37) -> 0.47043643 | AC20: =POSTTAX(AC10,INDEX(Data_Prices!AC:AC,MATCH($G20,Data_Prices!$A:$A,0)),AC$37) -> 0.47043643 | AD20: =POSTTAX(AD10,INDEX(Data_Prices!AD:AD,MATCH($G20,Data_Prices!$A:$A,0)),AD$37) -> 0.47043643 | AE20: =POSTTAX(AE10,INDEX(Data_Prices!AE:AE,MATCH($G20,Data_Prices!$A:$A,0)),AE$37) -> 0.47043643
B21: lpg | C21: =$C$5 -> irn | D21: LPG | E21: $/liter | F21: atp | G21: =Settings!$B$3&".mit.nce."&Settings!$B$4&"."&$B21&".a."&$J$5 -> egy.mit.nce.ind.lpg.a.1 | H21: =OUTCODE(Settings!$B$3,"atp",$C$5,$B21,$J$5) -> egy.mit.atp.irn.lpg.e.1 | K21: =POSTTAX(K11,INDEX(Data_Prices!K:K,MATCH($G21,Data_Prices!$A:$A,0)),K$37) -> 0.20036669 | L21: =POSTTAX(L11,INDEX(Data_Prices!L:L,MATCH($G21,Data_Prices!$A:$A,0)),L$37) -> 0.15734474 | M21: =POSTTAX(M11,INDEX(Data_Prices!M:M,MATCH($G21,Data_Prices!$A:$A,0)),M$37) -> 0.16448404 | N21: =POSTTAX(N11,INDEX(Data_Prices!N:N,MATCH($G21,Data_Prices!$A:$A,0)),N$37) -> 0.15070908 | O21: =POSTTAX(O11,INDEX(Data_Prices!O:O,MATCH($G21,Data_Prices!$A:$A,0)),O$37) -> 0.15070908 | P21: =POSTTAX(P11,INDEX(Data_Prices!P:P,MATCH($G21,Data_Prices!$A:$A,0)),P$37) -> 0.15070908 | Q21: =POSTTAX(Q11,INDEX(Data_Prices!Q:Q,MATCH($G21,Data_Prices!$A:$A,0)),Q$37) -> 0.15070908 | R21: =POSTTAX(R11,INDEX(Data_Prices!R:R,MATCH($G21,Data_Prices!$A:$A,0)),R$37) -> 0.15070908 | S21: =POSTTAX(S11,INDEX(Data_Prices!S:S,MATCH($G21,Data_Prices!$A:$A,0)),S$37) -> 0.15070908 | T21: =POSTTAX(T11,INDEX(Data_Prices!T:T,MATCH($G21,Data_Prices!$A:$A,0)),T$37) -> 0.15070908 | U21: =POSTTAX(U11,INDEX(Data_Prices!U:U,MATCH($G21,Data_Prices!$A:$A,0)),U$37) -> 0.15070908 | V21: =POSTTAX(V11,INDEX(Data_Prices!V:V,MATCH($G21,Data_Prices!$A:$A,0)),V$37) -> 0.15070908 | W21: =POSTTAX(W11,INDEX(Data_Prices!W:W,MATCH($G21,Data_Prices!$A:$A,0)),W$37) -> 0.15070908 | X21: =POSTTAX(X11,INDEX(Data_Prices!X:X,MATCH($G21,Data_Prices!$A:$A,0)),X$37) -> 0.15070908 | Y21: =POSTTAX(Y11,INDEX(Data_Prices!Y:Y,MATCH($G21,Data_Prices!$A:$A,0)),Y$37) -> 0.15070908 | Z21: =POSTTAX(Z11,INDEX(Data_Prices!Z:Z,MATCH($G21,Data_Prices!$A:$A,0)),Z$37) -> 0.15070908 | AA21: =POSTTAX(AA11,INDEX(Data_Prices!AA:AA,MATCH($G21,Data_Prices!$A:$A,0)),AA$37) -> 0.15070908 | AB21: =POSTTAX(AB11,INDEX(Data_Prices!AB:AB,MATCH($G21,Data_Prices!$A:$A,0)),AB$37) -> 0.15070908 | AC21: =POSTTAX(AC11,INDEX(Data_Prices!AC:AC,MATCH($G21,Data_Prices!$A:$A,0)),AC$37) -> 0.15070908 | AD21: =POSTTAX(AD11,INDEX(Data_Prices!AD:AD,MATCH($G21,Data_Prices!$A:$A,0)),AD$37) -> 0.15070908 | AE21: =POSTTAX(AE11,INDEX(Data_Prices!AE:AE,MATCH($G21,Data_Prices!$A:$A,0)),AE$37) -> 0.15070908
B22: ker | C22: =$C$5 -> irn | D22: Kerosene | E22: $/liter | F22: atp | G22: =Settings!$B$3&".mit.nce."&Settings!$B$4&"."&$B22&".a."&$J$5 -> egy.mit.nce.ind.ker.a.1 | H22: =OUTCODE(Settings!$B$3,"atp",$C$5,$B22,$J$5) -> egy.mit.atp.irn.ker.e.1 | K22: =POSTTAX(K12,INDEX(Data_Prices!K:K,MATCH($G22,Data_Prices!$A:$A,0)),K$37) -> 0.48429424 | L22: =POSTTAX(L12,INDEX(Data_Prices!L:L,MATCH($G22,Data_Prices!$A:$A,0)),L$37) -> 0.45642817 | M22: =POSTTAX(M12,INDEX(Data_Prices!M:M,MATCH($G22,Data_Prices!$A:$A,0)),M$37) -> 0.4316892 | N22: =POSTTAX(N12,INDEX(Data_Prices!N:N,MATCH($G22,Data_Prices!$A:$A,0)),N$37) -> 0.42507558 | O22: =POSTTAX(O12,INDEX(Data_Prices!O:O,MATCH($G22,Data_Prices!$A:$A,0)),O$37) -> 0.42507558 | P22: =POSTTAX(P12,INDEX(Data_Prices!P:P,MATCH($G22,Data_Prices!$A:$A,0)),P$37) -> 0.42507558 | Q22: =POSTTAX(Q12,INDEX(Data_Prices!Q:Q,MATCH($G22,Data_Prices!$A:$A,0)),Q$37) -> 0.42507558 | R22: =POSTTAX(R12,INDEX(Data_Prices!R:R,MATCH($G22,Data_Prices!$A:$A,0)),R$37) -> 0.42507558 | S22: =POSTTAX(S12,INDEX(Data_Prices!S:S,MATCH($G22,Data_Prices!$A:$A,0)),S$37) -> 0.42507558 | T22: =POSTTAX(T12,INDEX(Data_Prices!T:T,MATCH($G22,Data_Prices!$A:$A,0)),T$37) -> 0.42507558 | U22: =POSTTAX(U12,INDEX(Data_Prices!U:U,MATCH($G22,Data_Prices!$A:$A,0)),U$37) -> 0.42507558 | V22: =POSTTAX(V12,INDEX(Data_Prices!V:V,MATCH($G22,Data_Prices!$A:$A,0)),V$37) -> 0.42507558 | W22: =POSTTAX(W12,INDEX(Data_Prices!W:W,MATCH($G22,Data_Prices!$A:$A,0)),W$37) -> 0.42507558 | X22: =POSTTAX(X12,INDEX(Data_Prices!X:X,MATCH($G22,Data_Prices!$A:$A,0)),X$37) -> 0.42507558 | Y22: =POSTTAX(Y12,INDEX(Data_Prices!Y:Y,MATCH($G22,Data_Prices!$A:$A,0)),Y$37) -> 0.42507558 | Z22: =POSTTAX(Z12,INDEX(Data_Prices!Z:Z,MATCH($G22,Data_Prices!$A:$A,0)),Z$37) -> 0.42507558 | AA22: =POSTTAX(AA12,INDEX(Data_Prices!AA:AA,MATCH($G22,Data_Prices!$A:$A,0)),AA$37) -> 0.42507558 | AB22: =POSTTAX(AB12,INDEX(Data_Prices!AB:AB,MATCH($G22,Data_Prices!$A:$A,0)),AB$37) -> 0.42507558 | AC22: =POSTTAX(AC12,INDEX(Data_Prices!AC:AC,MATCH($G22,Data_Prices!$A:$A,0)),AC$37) -> 0.42507558 | AD22: =POSTTAX(AD12,INDEX(Data_Prices!AD:AD,MATCH($G22,Data_Prices!$A:$A,0)),AD$37) -> 0.42507558 | AE22: =POSTTAX(AE12,INDEX(Data_Prices!AE:AE,MATCH($G22,Data_Prices!$A:$A,0)),AE$37) -> 0.42507558
B23: oop | C23: =$C$5 -> irn | D23: Other oil products | E23: $/bbl | F23: atp | G23: =Settings!$B$3&".mit.nce."&Settings!$B$4&"."&$B23&".a."&$J$5 -> egy.mit.nce.ind.oop.a.1 | H23: =OUTCODE(Settings!$B$3,"atp",$C$5,$B23,$J$5) -> egy.mit.atp.irn.oop.e.1 | K23: =POSTTAX(K13,INDEX(Data_Prices!K:K,MATCH($G23,Data_Prices!$A:$A,0)),K$37) -> 41.500338 | L23: =POSTTAX(L13,INDEX(Data_Prices!L:L,MATCH($G23,Data_Prices!$A:$A,0)),L$37) -> 34.41537 | M23: =POSTTAX(M13,INDEX(Data_Prices!M:M,MATCH($G23,Data_Prices!$A:$A,0)),M$37) -> 37.368961 | N23: =POSTTAX(N13,INDEX(Data_Prices!N:N,MATCH($G23,Data_Prices!$A:$A,0)),N$37) -> 28.982761 | O23: =POSTTAX(O13,INDEX(Data_Prices!O:O,MATCH($G23,Data_Prices!$A:$A,0)),O$37) -> 15 | P23: =POSTTAX(P13,INDEX(Data_Prices!P:P,MATCH($G23,Data_Prices!$A:$A,0)),P$37) -> 24.25863 | Q23: =POSTTAX(Q13,INDEX(Data_Prices!Q:Q,MATCH($G23,Data_Prices!$A:$A,0)),Q$37) -> 15 | R23: =POSTTAX(R13,INDEX(Data_Prices!R:R,MATCH($G23,Data_Prices!$A:$A,0)),R$37) -> 15 | S23: =POSTTAX(S13,INDEX(Data_Prices!S:S,MATCH($G23,Data_Prices!$A:$A,0)),S$37) -> 15 | T23: =POSTTAX(T13,INDEX(Data_Prices!T:T,MATCH($G23,Data_Prices!$A:$A,0)),T$37) -> 15 | U23: =POSTTAX(U13,INDEX(Data_Prices!U:U,MATCH($G23,Data_Prices!$A:$A,0)),U$37) -> 15 | V23: =POSTTAX(V13,INDEX(Data_Prices!V:V,MATCH($G23,Data_Prices!$A:$A,0)),V$37) -> 15 | W23: =POSTTAX(W13,INDEX(Data_Prices!W:W,MATCH($G23,Data_Prices!$A:$A,0)),W$37) -> 15 | X23: =POSTTAX(X13,INDEX(Data_Prices!X:X,MATCH($G23,Data_Prices!$A:$A,0)),X$37) -> 15 | Y23: =POSTTAX(Y13,INDEX(Data_Prices!Y:Y,MATCH($G23,Data_Prices!$A:$A,0)),Y$37) -> 15 | Z23: =POSTTAX(Z13,INDEX(Data_Prices!Z:Z,MATCH($G23,Data_Prices!$A:$A,0)),Z$37) -> 15 | AA23: =POSTTAX(AA13,INDEX(Data_Prices!AA:AA,MATCH($G23,Data_Prices!$A:$A,0)),AA$37) -> 15 | AB23: =POSTTAX(AB13,INDEX(Data_Prices!AB:AB,MATCH($G23,Data_Prices!$A:$A,0)),AB$37) -> 15 | AC23: =POSTTAX(AC13,INDEX(Data_Prices!AC:AC,MATCH($G23,Data_Prices!$A:$A,0)),AC$37) -> 15 | AD23: =POSTTAX(AD13,INDEX(Data_Prices!AD:AD,MATCH($G23,Data_Prices!$A:$A,0)),AD$37) -> 15 | AE23: =POSTTAX(AE13,INDEX(Data_Prices!AE:AE,MATCH($G23,Data_Prices!$A:$A,0)),AE$37) -> 15
B24: bio | C24: =$C$5 -> irn | D24: Biomass | E24: $/GJ | F24: atp | G24: =Settings!$B$3&".mit.nce."&Settings!$B$4&"."&$B24&".a."&$J$5 -> egy.mit.nce.ind.bio.a.1 | H24: =OUTCODE(Settings!$B$3,"atp",$C$5,$B24,$J$5) -> egy.mit.atp.irn.bio.e.1 | K24: =POSTTAX(K14,INDEX(Data_Prices!K:K,MATCH($G24,Data_Prices!$A:$A,0)),K$37) -> 15.334551 | L24: =POSTTAX(L14,INDEX(Data_Prices!L:L,MATCH($G24,Data_Prices!$A:$A,0)),L$37) -> 14.199528 | M24: =POSTTAX(M14,INDEX(Data_Prices!M:M,MATCH($G24,Data_Prices!$A:$A,0)),M$37) -> 13.840442 | N24: =POSTTAX(N14,INDEX(Data_Prices!N:N,MATCH($G24,Data_Prices!$A:$A,0)),N$37) -> 13.567727 | O24: =POSTTAX(O14,INDEX(Data_Prices!O:O,MATCH($G24,Data_Prices!$A:$A,0)),O$37) -> 13.567727 | P24: =POSTTAX(P14,INDEX(Data_Prices!P:P,MATCH($G24,Data_Prices!$A:$A,0)),P$37) -> 13.567727 | Q24: =POSTTAX(Q14,INDEX(Data_Prices!Q:Q,MATCH($G24,Data_Prices!$A:$A,0)),Q$37) -> 13.567727 | R24: =POSTTAX(R14,INDEX(Data_Prices!R:R,MATCH($G24,Data_Prices!$A:$A,0)),R$37) -> 13.567727 | S24: =POSTTAX(S14,INDEX(Data_Prices!S:S,MATCH($G24,Data_Prices!$A:$A,0)),S$37) -> 13.567727 | T24: =POSTTAX(T14,INDEX(Data_Prices!T:T,MATCH($G24,Data_Prices!$A:$A,0)),T$37) -> 13.567727 | U24: =POSTTAX(U14,INDEX(Data_Prices!U:U,MATCH($G24,Data_Prices!$A:$A,0)),U$37) -> 13.567727 | V24: =POSTTAX(V14,INDEX(Data_Prices!V:V,MATCH($G24,Data_Prices!$A:$A,0)),V$37) -> 13.567727 | W24: =POSTTAX(W14,INDEX(Data_Prices!W:W,MATCH($G24,Data_Prices!$A:$A,0)),W$37) -> 13.567727 | X24: =POSTTAX(X14,INDEX(Data_Prices!X:X,MATCH($G24,Data_Prices!$A:$A,0)),X$37) -> 13.567727 | Y24: =POSTTAX(Y14,INDEX(Data_Prices!Y:Y,MATCH($G24,Data_Prices!$A:$A,0)),Y$37) -> 13.567727 | Z24: =POSTTAX(Z14,INDEX(Data_Prices!Z:Z,MATCH($G24,Data_Prices!$A:$A,0)),Z$37) -> 13.567727 | AA24: =POSTTAX(AA14,INDEX(Data_Prices!AA:AA,MATCH($G24,Data_Prices!$A:$A,0)),AA$37) -> 13.567727 | AB24: =POSTTAX(AB14,INDEX(Data_Prices!AB:AB,MATCH($G24,Data_Prices!$A:$A,0)),AB$37) -> 13.567727 | AC24: =POSTTAX(AC14,INDEX(Data_Prices!AC:AC,MATCH($G24,Data_Prices!$A:$A,0)),AC$37) -> 13.567727 | AD24: =POSTTAX(AD14,INDEX(Data_Prices!AD:AD,MATCH($G24,Data_Prices!$A:$A,0)),AD$37) -> 13.567727 | AE24: =POSTTAX(AE14,INDEX(Data_Prices!AE:AE,MATCH($G24,Data_Prices!$A:$A,0)),AE$37) -> 13.567727
B25: ren | C25: =$C$5 -> irn | D25: Self-generated renewables | E25: $/kwh | F25: atp | G25: =Settings!$B$3&".mit.nce."&Settings!$B$4&"."&$B25&".a."&$J$5 -> egy.mit.nce.ind.ren.a.1 | H25: =OUTCODE(Settings!$B$3,"atp",$C$5,$B25,$J$5) -> egy.mit.atp.irn.ren.e.1 | K25: =POSTTAX(K15,INDEX(Data_Prices!K:K,MATCH($G25,Data_Prices!$A:$A,0)),K$37) -> 0 | L25: =POSTTAX(L15,INDEX(Data_Prices!L:L,MATCH($G25,Data_Prices!$A:$A,0)),L$37) -> 0.14404499 | M25: =POSTTAX(M15,INDEX(Data_Prices!M:M,MATCH($G25,Data_Prices!$A:$A,0)),M$37) -> 0.14102041 | N25: =POSTTAX(N15,INDEX(Data_Prices!N:N,MATCH($G25,Data_Prices!$A:$A,0)),N$37) -> 0.13511636 | O25: =POSTTAX(O15,INDEX(Data_Prices!O:O,MATCH($G25,Data_Prices!$A:$A,0)),O$37) -> 0.13098826 | P25: =POSTTAX(P15,INDEX(Data_Prices!P:P,MATCH($G25,Data_Prices!$A:$A,0)),P$37) -> 0.12790842 | Q25: =POSTTAX(Q15,INDEX(Data_Prices!Q:Q,MATCH($G25,Data_Prices!$A:$A,0)),Q$37) -> 0.12481431 | R25: =POSTTAX(R15,INDEX(Data_Prices!R:R,MATCH($G25,Data_Prices!$A:$A,0)),R$37) -> 0.12146026 | S25: =POSTTAX(S15,INDEX(Data_Prices!S:S,MATCH($G25,Data_Prices!$A:$A,0)),S$37) -> 0.11795074 | T25: =POSTTAX(T15,INDEX(Data_Prices!T:T,MATCH($G25,Data_Prices!$A:$A,0)),T$37) -> 0.11419916 | U25: =POSTTAX(U15,INDEX(Data_Prices!U:U,MATCH($G25,Data_Prices!$A:$A,0)),U$37) -> 0.1136651 | V25: =POSTTAX(V15,INDEX(Data_Prices!V:V,MATCH($G25,Data_Prices!$A:$A,0)),V$37) -> 0.11301693 | W25: =POSTTAX(W15,INDEX(Data_Prices!W:W,MATCH($G25,Data_Prices!$A:$A,0)),W$37) -> 0.11231407 | X25: =POSTTAX(X15,INDEX(Data_Prices!X:X,MATCH($G25,Data_Prices!$A:$A,0)),X$37) -> 0.11142204 | Y25: =POSTTAX(Y15,INDEX(Data_Prices!Y:Y,MATCH($G25,Data_Prices!$A:$A,0)),Y$37) -> 0.11043412 | Z25: =POSTTAX(Z15,INDEX(Data_Prices!Z:Z,MATCH($G25,Data_Prices!$A:$A,0)),Z$37) -> 0.10948397 | AA25: =POSTTAX(AA15,INDEX(Data_Prices!AA:AA,MATCH($G25,Data_Prices!$A:$A,0)),AA$37) -> 0.10839192 | AB25: =POSTTAX(AB15,INDEX(Data_Prices!AB:AB,MATCH($G25,Data_Prices!$A:$A,0)),AB$37) -> 0.10735443 | AC25: =POSTTAX(AC15,INDEX(Data_Prices!AC:AC,MATCH($G25,Data_Prices!$A:$A,0)),AC$37) -> 0.10516868 | AD25: =POSTTAX(AD15,INDEX(Data_Prices!AD:AD,MATCH($G25,Data_Prices!$A:$A,0)),AD$37) -> 0.10305798 | AE25: =POSTTAX(AE15,INDEX(Data_Prices!AE:AE,MATCH($G25,Data_Prices!$A:$A,0)),AE$37) -> 0.10093184
B26: Shadow price: post-tax + shadow price of non-price policies x share acting on efficiency
B27: coa | C27: =$C$5 -> irn | D27: Coal | E27: $/GJ | F27: shp | G27: =Settings!$B$3&".mit.shp."&$B27&"."&Settings!$B$4&"."&$J$5 -> egy.mit.shp.coa.ind.1 | H27: =OUTCODE(Settings!$B$3,"shp",$C$5,$B27,$J$5) -> egy.mit.shp.irn.coa.e.1 | K27: =SHADOW(K17,INDEX(Data_Prices!K:K,MATCH($G27,Data_Prices!$A:$A,0)),K$38) -> 11.182902 | L27: =SHADOW(L17,INDEX(Data_Prices!L:L,MATCH($G27,Data_Prices!$A:$A,0)),L$38) -> 10.523361 | M27: =SHADOW(M17,INDEX(Data_Prices!M:M,MATCH($G27,Data_Prices!$A:$A,0)),M$38) -> 10.299561 | N27: =SHADOW(N17,INDEX(Data_Prices!N:N,MATCH($G27,Data_Prices!$A:$A,0)),N$38) -> 9.5775284 | O27: =SHADOW(O17,INDEX(Data_Prices!O:O,MATCH($G27,Data_Prices!$A:$A,0)),O$38) -> 8.4854783 | P27: =SHADOW(P17,INDEX(Data_Prices!P:P,MATCH($G27,Data_Prices!$A:$A,0)),P$38) -> 9.0871922 | Q27: =SHADOW(Q17,INDEX(Data_Prices!Q:Q,MATCH($G27,Data_Prices!$A:$A,0)),Q$38) -> 9.2229237 | R27: =SHADOW(R17,INDEX(Data_Prices!R:R,MATCH($G27,Data_Prices!$A:$A,0)),R$38) -> 9.158565 | S27: =SHADOW(S17,INDEX(Data_Prices!S:S,MATCH($G27,Data_Prices!$A:$A,0)),S$38) -> 9.0895479 | T27: =SHADOW(T17,INDEX(Data_Prices!T:T,MATCH($G27,Data_Prices!$A:$A,0)),T$38) -> 9.0156817 | U27: =SHADOW(U17,INDEX(Data_Prices!U:U,MATCH($G27,Data_Prices!$A:$A,0)),U$38) -> 8.9443978 | V27: =SHADOW(V17,INDEX(Data_Prices!V:V,MATCH($G27,Data_Prices!$A:$A,0)),V$38) -> 8.9443978 | W27: =SHADOW(W17,INDEX(Data_Prices!W:W,MATCH($G27,Data_Prices!$A:$A,0)),W$38) -> 8.9443978 | X27: =SHADOW(X17,INDEX(Data_Prices!X:X,MATCH($G27,Data_Prices!$A:$A,0)),X$38) -> 8.9443978 | Y27: =SHADOW(Y17,INDEX(Data_Prices!Y:Y,MATCH($G27,Data_Prices!$A:$A,0)),Y$38) -> 8.9443978 | Z27: =SHADOW(Z17,INDEX(Data_Prices!Z:Z,MATCH($G27,Data_Prices!$A:$A,0)),Z$38) -> 8.9443978 | AA27: =SHADOW(AA17,INDEX(Data_Prices!AA:AA,MATCH($G27,Data_Prices!$A:$A,0)),AA$38) -> 8.9443978 | AB27: =SHADOW(AB17,INDEX(Data_Prices!AB:AB,MATCH($G27,Data_Prices!$A:$A,0)),AB$38) -> 8.9443978 | AC27: =SHADOW(AC17,INDEX(Data_Prices!AC:AC,MATCH($G27,Data_Prices!$A:$A,0)),AC$38) -> 8.9443978 | AD27: =SHADOW(AD17,INDEX(Data_Prices!AD:AD,MATCH($G27,Data_Prices!$A:$A,0)),AD$38) -> 8.9443978 | AE27: =SHADOW(AE17,INDEX(Data_Prices!AE:AE,MATCH($G27,Data_Prices!$A:$A,0)),AE$38) -> 8.9443978
B28: nga | C28: =$C$5 -> irn | D28: Natural gas | E28: $/GJ | F28: shp | G28: =Settings!$B$3&".mit.shp."&$B28&"."&Settings!$B$4&"."&$J$5 -> egy.mit.shp.nga.ind.1 | H28: =OUTCODE(Settings!$B$3,"shp",$C$5,$B28,$J$5) -> egy.mit.shp.irn.nga.e.1 | K28: =SHADOW(K18,INDEX(Data_Prices!K:K,MATCH($G28,Data_Prices!$A:$A,0)),K$38) -> 6.0634636 | L28: =SHADOW(L18,INDEX(Data_Prices!L:L,MATCH($G28,Data_Prices!$A:$A,0)),L$38) -> 5.4510151 | M28: =SHADOW(M18,INDEX(Data_Prices!M:M,MATCH($G28,Data_Prices!$A:$A,0)),M$38) -> 5.1193563 | N28: =SHADOW(N18,INDEX(Data_Prices!N:N,MATCH($G28,Data_Prices!$A:$A,0)),N$38) -> 5.0821846 | O28: =SHADOW(O18,INDEX(Data_Prices!O:O,MATCH($G28,Data_Prices!$A:$A,0)),O$38) -> 5.0821846 | P28: =SHADOW(P18,INDEX(Data_Prices!P:P,MATCH($G28,Data_Prices!$A:$A,0)),P$38) -> 5.0821846 | Q28: =SHADOW(Q18,INDEX(Data_Prices!Q:Q,MATCH($G28,Data_Prices!$A:$A,0)),Q$38) -> 5.0821846 | R28: =SHADOW(R18,INDEX(Data_Prices!R:R,MATCH($G28,Data_Prices!$A:$A,0)),R$38) -> 5.0821846 | S28: =SHADOW(S18,INDEX(Data_Prices!S:S,MATCH($G28,Data_Prices!$A:$A,0)),S$38) -> 5.0821846 | T28: =SHADOW(T18,INDEX(Data_Prices!T:T,MATCH($G28,Data_Prices!$A:$A,0)),T$38) -> 5.0821846 | U28: =SHADOW(U18,INDEX(Data_Prices!U:U,MATCH($G28,Data_Prices!$A:$A,0)),U$38) -> 5.0821846 | V28: =SHADOW(V18,INDEX(Data_Prices!V:V,MATCH($G28,Data_Prices!$A:$A,0)),V$38) -> 5.0821846 | W28: =SHADOW(W18,INDEX(Data_Prices!W:W,MATCH($G28,Data_Prices!$A:$A,0)),W$38) -> 5.0821846 | X28: =SHADOW(X18,INDEX(Data_Prices!X:X,MATCH($G28,Data_Prices!$A:$A,0)),X$38) -> 5.0821846 | Y28: =SHADOW(Y18,INDEX(Data_Prices!Y:Y,MATCH($G28,Data_Prices!$A:$A,0)),Y$38) -> 5.0821846 | Z28: =SHADOW(Z18,INDEX(Data_Prices!Z:Z,MATCH($G28,Data_Prices!$A:$A,0)),Z$38) -> 5.0821846 | AA28: =SHADOW(AA18,INDEX(Data_Prices!AA:AA,MATCH($G28,Data_Prices!$A:$A,0)),AA$38) -> 5.0821846 | AB28: =SHADOW(AB18,INDEX(Data_Prices!AB:AB,MATCH($G28,Data_Prices!$A:$A,0)),AB$38) -> 5.0821846 | AC28: =SHADOW(AC18,INDEX(Data_Prices!AC:AC,MATCH($G28,Data_Prices!$A:$A,0)),AC$38) -> 5.0821846 | AD28: =SHADOW(AD18,INDEX(Data_Prices!AD:AD,MATCH($G28,Data_Prices!$A:$A,0)),AD$38) -> 5.0821846 | AE28: =SHADOW(AE18,INDEX(Data_Prices!AE:AE,MATCH($G28,Data_Prices!$A:$A,0)),AE$38) -> 5.0821846
B29: gso | C29: =$C$5 -> irn | D29: Gasoline | E29: $/liter | F29: shp | G29: =Settings!$B$3&".mit.shp."&$B29&"."&Settings!$B$4&"."&$J$5 -> egy.mit.shp.gso.ind.1 | H29: =OUTCODE(Settings!$B$3,"shp",$C$5,$B29,$J$5) -> egy.mit.shp.irn.gso.e.1 | K29: =SHADOW(K19,INDEX(Data_Prices!K:K,MATCH($G29,Data_Prices!$A:$A,0)),K$38) -> 0.67114653 | L29: =SHADOW(L19,INDEX(Data_Prices!L:L,MATCH($G29,Data_Prices!$A:$A,0)),L$38) -> 0.61197798 | M29: =SHADOW(M19,INDEX(Data_Prices!M:M,MATCH($G29,Data_Prices!$A:$A,0)),M$38) -> 0.61180975 | N29: =SHADOW(N19,INDEX(Data_Prices!N:N,MATCH($G29,Data_Prices!$A:$A,0)),N$38) -> 0.6035831 | O29: =SHADOW(O19,INDEX(Data_Prices!O:O,MATCH($G29,Data_Prices!$A:$A,0)),O$38) -> 0.6035831 | P29: =SHADOW(P19,INDEX(Data_Prices!P:P,MATCH($G29,Data_Prices!$A:$A,0)),P$38) -> 0.6035831 | Q29: =SHADOW(Q19,INDEX(Data_Prices!Q:Q,MATCH($G29,Data_Prices!$A:$A,0)),Q$38) -> 0.6035831 | R29: =SHADOW(R19,INDEX(Data_Prices!R:R,MATCH($G29,Data_Prices!$A:$A,0)),R$38) -> 0.6035831 | S29: =SHADOW(S19,INDEX(Data_Prices!S:S,MATCH($G29,Data_Prices!$A:$A,0)),S$38) -> 0.6035831 | T29: =SHADOW(T19,INDEX(Data_Prices!T:T,MATCH($G29,Data_Prices!$A:$A,0)),T$38) -> 0.6035831 | U29: =SHADOW(U19,INDEX(Data_Prices!U:U,MATCH($G29,Data_Prices!$A:$A,0)),U$38) -> 0.6035831 | V29: =SHADOW(V19,INDEX(Data_Prices!V:V,MATCH($G29,Data_Prices!$A:$A,0)),V$38) -> 0.6035831 | W29: =SHADOW(W19,INDEX(Data_Prices!W:W,MATCH($G29,Data_Prices!$A:$A,0)),W$38) -> 0.6035831 | X29: =SHADOW(X19,INDEX(Data_Prices!X:X,MATCH($G29,Data_Prices!$A:$A,0)),X$38) -> 0.6035831 | Y29: =SHADOW(Y19,INDEX(Data_Prices!Y:Y,MATCH($G29,Data_Prices!$A:$A,0)),Y$38) -> 0.6035831 | Z29: =SHADOW(Z19,INDEX(Data_Prices!Z:Z,MATCH($G29,Data_Prices!$A:$A,0)),Z$38) -> 0.6035831 | AA29: =SHADOW(AA19,INDEX(Data_Prices!AA:AA,MATCH($G29,Data_Prices!$A:$A,0)),AA$38) -> 0.6035831 | AB29: =SHADOW(AB19,INDEX(Data_Prices!AB:AB,MATCH($G29,Data_Prices!$A:$A,0)),AB$38) -> 0.6035831 | AC29: =SHADOW(AC19,INDEX(Data_Prices!AC:AC,MATCH($G29,Data_Prices!$A:$A,0)),AC$38) -> 0.6035831 | AD29: =SHADOW(AD19,INDEX(Data_Prices!AD:AD,MATCH($G29,Data_Prices!$A:$A,0)),AD$38) -> 0.6035831 | AE29: =SHADOW(AE19,INDEX(Data_Prices!AE:AE,MATCH($G29,Data_Prices!$A:$A,0)),AE$38) -> 0.6035831
B30: die | C30: =$C$5 -> irn | D30: Diesel | E30: $/liter | F30: shp | G30: =Settings!$B$3&".mit.shp."&$B30&"."&Settings!$B$4&"."&$J$5 -> egy.mit.shp.die.ind.1 | H30: =OUTCODE(Settings!$B$3,"shp",$C$5,$B30,$J$5) -> egy.mit.shp.irn.die.e.1 | K30: =SHADOW(K20,INDEX(Data_Prices!K:K,MATCH($G30,Data_Prices!$A:$A,0)),K$38) -> 0.55971121 | L30: =SHADOW(L20,INDEX(Data_Prices!L:L,MATCH($G30,Data_Prices!$A:$A,0)),L$38) -> 0.49458873 | M30: =SHADOW(M20,INDEX(Data_Prices!M:M,MATCH($G30,Data_Prices!$A:$A,0)),M$38) -> 0.50778655 | N30: =SHADOW(N20,INDEX(Data_Prices!N:N,MATCH($G30,Data_Prices!$A:$A,0)),N$38) -> 0.47043643 | O30: =SHADOW(O20,INDEX(Data_Prices!O:O,MATCH($G30,Data_Prices!$A:$A,0)),O$38) -> 0.47043643 | P30: =SHADOW(P20,INDEX(Data_Prices!P:P,MATCH($G30,Data_Prices!$A:$A,0)),P$38) -> 0.47043643 | Q30: =SHADOW(Q20,INDEX(Data_Prices!Q:Q,MATCH($G30,Data_Prices!$A:$A,0)),Q$38) -> 0.47043643 | R30: =SHADOW(R20,INDEX(Data_Prices!R:R,MATCH($G30,Data_Prices!$A:$A,0)),R$38) -> 0.47043643 | S30: =SHADOW(S20,INDEX(Data_Prices!S:S,MATCH($G30,Data_Prices!$A:$A,0)),S$38) -> 0.47043643 | T30: =SHADOW(T20,INDEX(Data_Prices!T:T,MATCH($G30,Data_Prices!$A:$A,0)),T$38) -> 0.47043643 | U30: =SHADOW(U20,INDEX(Data_Prices!U:U,MATCH($G30,Data_Prices!$A:$A,0)),U$38) -> 0.47043643 | V30: =SHADOW(V20,INDEX(Data_Prices!V:V,MATCH($G30,Data_Prices!$A:$A,0)),V$38) -> 0.47043643 | W30: =SHADOW(W20,INDEX(Data_Prices!W:W,MATCH($G30,Data_Prices!$A:$A,0)),W$38) -> 0.47043643 | X30: =SHADOW(X20,INDEX(Data_Prices!X:X,MATCH($G30,Data_Prices!$A:$A,0)),X$38) -> 0.47043643 | Y30: =SHADOW(Y20,INDEX(Data_Prices!Y:Y,MATCH($G30,Data_Prices!$A:$A,0)),Y$38) -> 0.47043643 | Z30: =SHADOW(Z20,INDEX(Data_Prices!Z:Z,MATCH($G30,Data_Prices!$A:$A,0)),Z$38) -> 0.47043643 | AA30: =SHADOW(AA20,INDEX(Data_Prices!AA:AA,MATCH($G30,Data_Prices!$A:$A,0)),AA$38) -> 0.47043643 | AB30: =SHADOW(AB20,INDEX(Data_Prices!AB:AB,MATCH($G30,Data_Prices!$A:$A,0)),AB$38) -> 0.47043643 | AC30: =SHADOW(AC20,INDEX(Data_Prices!AC:AC,MATCH($G30,Data_Prices!$A:$A,0)),AC$38) -> 0.47043643 | AD30: =SHADOW(AD20,INDEX(Data_Prices!AD:AD,MATCH($G30,Data_Prices!$A:$A,0)),AD$38) -> 0.47043643 | AE30: =SHADOW(AE20,INDEX(Data_Prices!AE:AE,MATCH($G30,Data_Prices!$A:$A,0)),AE$38) -> 0.47043643
B31: lpg | C31: =$C$5 -> irn | D31: LPG | E31: $/liter | F31: shp | G31: =Settings!$B$3&".mit.shp."&$B31&"."&Settings!$B$4&"."&$J$5 -> egy.mit.shp.lpg.ind.1 | H31: =OUTCODE(Settings!$B$3,"shp",$C$5,$B31,$J$5) -> egy.mit.shp.irn.lpg.e.1 | K31: =SHADOW(K21,INDEX(Data_Prices!K:K,MATCH($G31,Data_Prices!$A:$A,0)),K$38) -> 0.20036669 | L31: =SHADOW(L21,INDEX(Data_Prices!L:L,MATCH($G31,Data_Prices!$A:$A,0)),L$38) -> 0.15734474 | M31: =SHADOW(M21,INDEX(Data_Prices!M:M,MATCH($G31,Data_Prices!$A:$A,0)),M$38) -> 0.16448404 | N31: =SHADOW(N21,INDEX(Data_Prices!N:N,MATCH($G31,Data_Prices!$A:$A,0)),N$38) -> 0.15070908 | O31: =SHADOW(O21,INDEX(Data_Prices!O:O,MATCH($G31,Data_Prices!$A:$A,0)),O$38) -> 0.15070908 | P31: =SHADOW(P21,INDEX(Data_Prices!P:P,MATCH($G31,Data_Prices!$A:$A,0)),P$38) -> 0.15070908 | Q31: =SHADOW(Q21,INDEX(Data_Prices!Q:Q,MATCH($G31,Data_Prices!$A:$A,0)),Q$38) -> 0.15070908 | R31: =SHADOW(R21,INDEX(Data_Prices!R:R,MATCH($G31,Data_Prices!$A:$A,0)),R$38) -> 0.15070908 | S31: =SHADOW(S21,INDEX(Data_Prices!S:S,MATCH($G31,Data_Prices!$A:$A,0)),S$38) -> 0.15070908 | T31: =SHADOW(T21,INDEX(Data_Prices!T:T,MATCH($G31,Data_Prices!$A:$A,0)),T$38) -> 0.15070908 | U31: =SHADOW(U21,INDEX(Data_Prices!U:U,MATCH($G31,Data_Prices!$A:$A,0)),U$38) -> 0.15070908 | V31: =SHADOW(V21,INDEX(Data_Prices!V:V,MATCH($G31,Data_Prices!$A:$A,0)),V$38) -> 0.15070908 | W31: =SHADOW(W21,INDEX(Data_Prices!W:W,MATCH($G31,Data_Prices!$A:$A,0)),W$38) -> 0.15070908 | X31: =SHADOW(X21,INDEX(Data_Prices!X:X,MATCH($G31,Data_Prices!$A:$A,0)),X$38) -> 0.15070908 | Y31: =SHADOW(Y21,INDEX(Data_Prices!Y:Y,MATCH($G31,Data_Prices!$A:$A,0)),Y$38) -> 0.15070908 | Z31: =SHADOW(Z21,INDEX(Data_Prices!Z:Z,MATCH($G31,Data_Prices!$A:$A,0)),Z$38) -> 0.15070908 | AA31: =SHADOW(AA21,INDEX(Data_Prices!AA:AA,MATCH($G31,Data_Prices!$A:$A,0)),AA$38) -> 0.15070908 | AB31: =SHADOW(AB21,INDEX(Data_Prices!AB:AB,MATCH($G31,Data_Prices!$A:$A,0)),AB$38) -> 0.15070908 | AC31: =SHADOW(AC21,INDEX(Data_Prices!AC:AC,MATCH($G31,Data_Prices!$A:$A,0)),AC$38) -> 0.15070908 | AD31: =SHADOW(AD21,INDEX(Data_Prices!AD:AD,MATCH($G31,Data_Prices!$A:$A,0)),AD$38) -> 0.15070908 | AE31: =SHADOW(AE21,INDEX(Data_Prices!AE:AE,MATCH($G31,Data_Prices!$A:$A,0)),AE$38) -> 0.15070908
B32: ker | C32: =$C$5 -> irn | D32: Kerosene | E32: $/liter | F32: shp | G32: =Settings!$B$3&".mit.shp."&$B32&"."&Settings!$B$4&"."&$J$5 -> egy.mit.shp.ker.ind.1 | H32: =OUTCODE(Settings!$B$3,"shp",$C$5,$B32,$J$5) -> egy.mit.shp.irn.ker.e.1 | K32: =SHADOW(K22,INDEX(Data_Prices!K:K,MATCH($G32,Data_Prices!$A:$A,0)),K$38) -> 0.48429424 | L32: =SHADOW(L22,INDEX(Data_Prices!L:L,MATCH($G32,Data_Prices!$A:$A,0)),L$38) -> 0.45642817 | M32: =SHADOW(M22,INDEX(Data_Prices!M:M,MATCH($G32,Data_Prices!$A:$A,0)),M$38) -> 0.4316892 | N32: =SHADOW(N22,INDEX(Data_Prices!N:N,MATCH($G32,Data_Prices!$A:$A,0)),N$38) -> 0.42507558 | O32: =SHADOW(O22,INDEX(Data_Prices!O:O,MATCH($G32,Data_Prices!$A:$A,0)),O$38) -> 0.42507558 | P32: =SHADOW(P22,INDEX(Data_Prices!P:P,MATCH($G32,Data_Prices!$A:$A,0)),P$38) -> 0.42507558 | Q32: =SHADOW(Q22,INDEX(Data_Prices!Q:Q,MATCH($G32,Data_Prices!$A:$A,0)),Q$38) -> 0.42507558 | R32: =SHADOW(R22,INDEX(Data_Prices!R:R,MATCH($G32,Data_Prices!$A:$A,0)),R$38) -> 0.42507558 | S32: =SHADOW(S22,INDEX(Data_Prices!S:S,MATCH($G32,Data_Prices!$A:$A,0)),S$38) -> 0.42507558 | T32: =SHADOW(T22,INDEX(Data_Prices!T:T,MATCH($G32,Data_Prices!$A:$A,0)),T$38) -> 0.42507558 | U32: =SHADOW(U22,INDEX(Data_Prices!U:U,MATCH($G32,Data_Prices!$A:$A,0)),U$38) -> 0.42507558 | V32: =SHADOW(V22,INDEX(Data_Prices!V:V,MATCH($G32,Data_Prices!$A:$A,0)),V$38) -> 0.42507558 | W32: =SHADOW(W22,INDEX(Data_Prices!W:W,MATCH($G32,Data_Prices!$A:$A,0)),W$38) -> 0.42507558 | X32: =SHADOW(X22,INDEX(Data_Prices!X:X,MATCH($G32,Data_Prices!$A:$A,0)),X$38) -> 0.42507558 | Y32: =SHADOW(Y22,INDEX(Data_Prices!Y:Y,MATCH($G32,Data_Prices!$A:$A,0)),Y$38) -> 0.42507558 | Z32: =SHADOW(Z22,INDEX(Data_Prices!Z:Z,MATCH($G32,Data_Prices!$A:$A,0)),Z$38) -> 0.42507558 | AA32: =SHADOW(AA22,INDEX(Data_Prices!AA:AA,MATCH($G32,Data_Prices!$A:$A,0)),AA$38) -> 0.42507558 | AB32: =SHADOW(AB22,INDEX(Data_Prices!AB:AB,MATCH($G32,Data_Prices!$A:$A,0)),AB$38) -> 0.42507558 | AC32: =SHADOW(AC22,INDEX(Data_Prices!AC:AC,MATCH($G32,Data_Prices!$A:$A,0)),AC$38) -> 0.42507558 | AD32: =SHADOW(AD22,INDEX(Data_Prices!AD:AD,MATCH($G32,Data_Prices!$A:$A,0)),AD$38) -> 0.42507558 | AE32: =SHADOW(AE22,INDEX(Data_Prices!AE:AE,MATCH($G32,Data_Prices!$A:$A,0)),AE$38) -> 0.42507558
B33: oop | C33: =$C$5 -> irn | D33: Other oil products | E33: $/bbl | F33: shp | G33: =Settings!$B$3&".mit.shp."&$B33&"."&Settings!$B$4&"."&$J$5 -> egy.mit.shp.oop.ind.1 | H33: =OUTCODE(Settings!$B$3,"shp",$C$5,$B33,$J$5) -> egy.mit.shp.irn.oop.e.1 | K33: =SHADOW(K23,INDEX(Data_Prices!K:K,MATCH($G33,Data_Prices!$A:$A,0)),K$38) -> 41.500338 | L33: =SHADOW(L23,INDEX(Data_Prices!L:L,MATCH($G33,Data_Prices!$A:$A,0)),L$38) -> 34.41537 | M33: =SHADOW(M23,INDEX(Data_Prices!M:M,MATCH($G33,Data_Prices!$A:$A,0)),M$38) -> 37.368961 | N33: =SHADOW(N23,INDEX(Data_Prices!N:N,MATCH($G33,Data_Prices!$A:$A,0)),N$38) -> 28.982761 | O33: =SHADOW(O23,INDEX(Data_Prices!O:O,MATCH($G33,Data_Prices!$A:$A,0)),O$38) -> 15 | P33: =SHADOW(P23,INDEX(Data_Prices!P:P,MATCH($G33,Data_Prices!$A:$A,0)),P$38) -> 24.25863 | Q33: =SHADOW(Q23,INDEX(Data_Prices!Q:Q,MATCH($G33,Data_Prices!$A:$A,0)),Q$38) -> 15 | R33: =SHADOW(R23,INDEX(Data_Prices!R:R,MATCH($G33,Data_Prices!$A:$A,0)),R$38) -> 15 | S33: =SHADOW(S23,INDEX(Data_Prices!S:S,MATCH($G33,Data_Prices!$A:$A,0)),S$38) -> 15 | T33: =SHADOW(T23,INDEX(Data_Prices!T:T,MATCH($G33,Data_Prices!$A:$A,0)),T$38) -> 15 | U33: =SHADOW(U23,INDEX(Data_Prices!U:U,MATCH($G33,Data_Prices!$A:$A,0)),U$38) -> 15 | V33: =SHADOW(V23,INDEX(Data_Prices!V:V,MATCH($G33,Data_Prices!$A:$A,0)),V$38) -> 15 | W33: =SHADOW(W23,INDEX(Data_Prices!W:W,MATCH($G33,Data_Prices!$A:$A,0)),W$38) -> 15 | X33: =SHADOW(X23,INDEX(Data_Prices!X:X,MATCH($G33,Data_Prices!$A:$A,0)),X$38) -> 15 | Y33: =SHADOW(Y23,INDEX(Data_Prices!Y:Y,MATCH($G33,Data_Prices!$A:$A,0)),Y$38) -> 15 | Z33: =SHADOW(Z23,INDEX(Data_Prices!Z:Z,MATCH($G33,Data_Prices!$A:$A,0)),Z$38) -> 15 | AA33: =SHADOW(AA23,INDEX(Data_Prices!AA:AA,MATCH($G33,Data_Prices!$A:$A,0)),AA$38) -> 15 | AB33: =SHADOW(AB23,INDEX(Data_Prices!AB:AB,MATCH($G33,Data_Prices!$A:$A,0)),AB$38) -> 15 | AC33: =SHADOW(AC23,INDEX(Data_Prices!AC:AC,MATCH($G33,Data_Prices!$A:$A,0)),AC$38) -> 15 | AD33: =SHADOW(AD23,INDEX(Data_Prices!AD:AD,MATCH($G33,Data_Prices!$A:$A,0)),AD$38) -> 15 | AE33: =SHADOW(AE23,INDEX(Data_Prices!AE:AE,MATCH($G33,Data_Prices!$A:$A,0)),AE$38) -> 15
B34: bio | C34: =$C$5 -> irn | D34: Biomass | E34: $/GJ | F34: shp | G34: =Settings!$B$3&".mit.shp."&$B34&"."&Settings!$B$4&"."&$J$5 -> egy.mit.shp.bio.ind.1 | H34: =OUTCODE(Settings!$B$3,"shp",$C$5,$B34,$J$5) -> egy.mit.shp.irn.bio.e.1 | K34: =SHADOW(K24,INDEX(Data_Prices!K:K,MATCH($G34,Data_Prices!$A:$A,0)),K$38) -> 15.334551 | L34: =SHADOW(L24,INDEX(Data_Prices!L:L,MATCH($G34,Data_Prices!$A:$A,0)),L$38) -> 14.199528 | M34: =SHADOW(M24,INDEX(Data_Prices!M:M,MATCH($G34,Data_Prices!$A:$A,0)),M$38) -> 13.840442 | N34: =SHADOW(N24,INDEX(Data_Prices!N:N,MATCH($G34,Data_Prices!$A:$A,0)),N$38) -> 13.567727 | O34: =SHADOW(O24,INDEX(Data_Prices!O:O,MATCH($G34,Data_Prices!$A:$A,0)),O$38) -> 13.567727 | P34: =SHADOW(P24,INDEX(Data_Prices!P:P,MATCH($G34,Data_Prices!$A:$A,0)),P$38) -> 13.567727 | Q34: =SHADOW(Q24,INDEX(Data_Prices!Q:Q,MATCH($G34,Data_Prices!$A:$A,0)),Q$38) -> 13.567727 | R34: =SHADOW(R24,INDEX(Data_Prices!R:R,MATCH($G34,Data_Prices!$A:$A,0)),R$38) -> 13.567727 | S34: =SHADOW(S24,INDEX(Data_Prices!S:S,MATCH($G34,Data_Prices!$A:$A,0)),S$38) -> 13.567727 | T34: =SHADOW(T24,INDEX(Data_Prices!T:T,MATCH($G34,Data_Prices!$A:$A,0)),T$38) -> 13.567727 | U34: =SHADOW(U24,INDEX(Data_Prices!U:U,MATCH($G34,Data_Prices!$A:$A,0)),U$38) -> 13.567727 | V34: =SHADOW(V24,INDEX(Data_Prices!V:V,MATCH($G34,Data_Prices!$A:$A,0)),V$38) -> 13.567727 | W34: =SHADOW(W24,INDEX(Data_Prices!W:W,MATCH($G34,Data_Prices!$A:$A,0)),W$38) -> 13.567727 | X34: =SHADOW(X24,INDEX(Data_Prices!X:X,MATCH($G34,Data_Prices!$A:$A,0)),X$38) -> 13.567727 | Y34: =SHADOW(Y24,INDEX(Data_Prices!Y:Y,MATCH($G34,Data_Prices!$A:$A,0)),Y$38) -> 13.567727 | Z34: =SHADOW(Z24,INDEX(Data_Prices!Z:Z,MATCH($G34,Data_Prices!$A:$A,0)),Z$38) -> 13.567727 | AA34: =SHADOW(AA24,INDEX(Data_Prices!AA:AA,MATCH($G34,Data_Prices!$A:$A,0)),AA$38) -> 13.567727 | AB34: =SHADOW(AB24,INDEX(Data_Prices!AB:AB,MATCH($G34,Data_Prices!$A:$A,0)),AB$38) -> 13.567727 | AC34: =SHADOW(AC24,INDEX(Data_Prices!AC:AC,MATCH($G34,Data_Prices!$A:$A,0)),AC$38) -> 13.567727 | AD34: =SHADOW(AD24,INDEX(Data_Prices!AD:AD,MATCH($G34,Data_Prices!$A:$A,0)),AD$38) -> 13.567727 | AE34: =SHADOW(AE24,INDEX(Data_Prices!AE:AE,MATCH($G34,Data_Prices!$A:$A,0)),AE$38) -> 13.567727
