Workbook

Sheet ReadMe
A2: CPAT mitigation module - copy-pasteable prototype v0.1
A4: Purpose | B4: Auditable, copy-pasteable replacement of the CPAT mitigation price -> fuel-use chain. Every block has one formula (same R1C1 text) across all its projection cells; a whole scenario group copies to the next group position and keeps working.
A5: Status | B5: v0.1 prototype. Price -> fuel use only (no emissions, power or revenue yet).
A6: Layout (design 2) | B6: Columns: descriptors A-J (NORMS 1.1), keys K-P, parameter sets Q-AJ, then one column group per scenario (15 columns: label, base year, 2023-2035). Rows: macro rows 4-8, then blocks.
A7: Nesting | B7: Across: scenario (outer) > year (inner). Down: variable block (outer) > subsector > fuel (inner). 16 CPAT energy-use subsectors x 8 fuels = 128 rows per block.
A8: Blocks | B8: Pre-tax price (row 10), Tax (row 140), Post-tax price (row 270), Fuel use (row 400), Totals (row 530).
A9: Pre-tax price | B9: base year: Prices_dom supply cost (mit.sp) / GJ per price unit; then p(t) = p(t-1) x (1 + P1 growth).
A10: Tax | B10: tax(t) = P1 base tax + carbon price(t) x P2 EF x P3 coverage. Base tax = (retail - supply cost) / GJ per unit, so it includes existing excise, subsidies and VAT.
A11: Post-tax price | B11: pre-tax + tax (same row in the blocks above, fixed offsets).
A12: Fuel use | B12: F(t) = F(t-1) x (1/(1+alpha))^(1+eps_U) x (1+g)^eps_Y x (p(t)/p(t-1))^eps_U x (p(t)/p(t-1))^(eps_F(1+eps_U)) - CPAT documentation 3.3.3, without the Covid factor and shadow price.
A13: Parameters | B13: Each row has 4 parameter sets of 5 slots (P5 = buffer). Set 1 holds the lookups; sets 2-4 link to set 1 - overwrite a cell to make a parameter scenario-specific. Formulas pick the set with INDEX(row, (scenario number - 1) x 5 + slot).
A14: Lookups by country | B14: Settings!C4 selects the country. Elasticities (via income group) and prices cover all CPAT countries; base-year energy use, GDP growth and EFs are Egypt only so far (other countries return #N/A until their rows are added).
A15: Add a scenario | B15: (1) Copy columns AZ:BN (a whole group) and paste at the next free group position (column BO). (2) Type the new scenario number in its label cell (row 4). (3) Edit the carbon prices in row 8. (4) Optionally overwrite parameter set N on the left. Up to 4 scenarios fit without inserting parameter columns.
... A19: Checks | B19: Row 558 (sum by fuel - sum by subsector) should be 0. check_v0_1.py tests formula uniformity, the scenario-copy behaviour and an independent recomputation.

Sheet Settings
A2: Settings
B4: Country code | C4: EGY
B5: Country name | C5: =INDEX(Countries!$B$4:$B$1000,MATCH($C$4,Countries!$A$4:$A$1000,0))
B6: Income group (selects elasticities) | C6: =INDEX(Countries!$D$4:$D$1000,MATCH($C$4,Countries!$A$4:$A$1000,0))
B7: Base year | C7: 2022
B9: Scenario number | C9: Scenario name
B10: 1 | C10: Baseline (no carbon price)
B11: 2 | C11: Carbon price $20/tCO2 from 2027
B12: 3 | C12: Spare (copy a group here)
B13: 4 | C13: Spare (copy a group here)
B16: Version log
B17: Version | C17: Date | D17: Description | E17: Max abs regression diff
B18: 0.1 | C18: 2026-10-08 | D18: First build: design 2 price -> fuel-use prototype, Egypt base data, 2 scenarios. | E18: n/a (first version)

Sheet Mitigation
B1: Fuel | C1: Sector | D1: Description | E1: Unit | F1: Source | G1: Input Code | H1: Output Code | I1: Note | J1: Helper (group) | K1: Elasticity sector | L1: Elasticity fuel | M1: AEEI fuel | N1: Price code | O1: EF sector | P1: GJ per price unit | Q1: S1 P1 | R1: S1 P2 | S1: S1 P3 | T1: S1 P4 | U1: S1 P5 | V1: S2 P1 | W1: S2 P2 | X1: S2 P3 | Y1: S2 P4 | Z1: S2 P5 | AA1: S3 P1 | AB1: S3 P2 | AC1: S3 P3 | AD1: S3 P4 | AE1: S3 P5 | AF1: S4 P1 | AG1: S4 P2 | AH1: S4 P3 | AI1: S4 P4 | AJ1: S4 P5 | AK1: Scenario group 1 | AZ1: Scenario group 2
A2: Mitigation module - price to fuel use (copy-pasteable, design 2)
A3: Scenario and macro inputs (one column group per scenario; copy a whole group to add a scenario)
D4: Scenario number | E4: no. | AK4: 1 | AL4: =AK4 | AM4: =AL4 | AN4: =AM4 | AO4: =AN4 | AP4: =AO4 | AQ4: =AP4 | AR4: =AQ4 | AS4: =AR4 | ... AY4: =AX4 | AZ4: 2 | BA4: =AZ4 | BB4: =BA4 | BC4: =BB4 | BD4: =BC4 | BE4: =BD4 | BF4: =BE4 | BG4: =BF4 | BH4: =BG4 | ... BN4: =BM4
D5: Year | E5: year | AK5: base -> | AL5: =Settings!$C$7 | AM5: =AL5+1 | AN5: =AM5+1 | AO5: =AN5+1 | AP5: =AO5+1 | AQ5: =AP5+1 | AR5: =AQ5+1 | AS5: =AR5+1 | AT5: =AS5+1 | ... AY5: =AX5+1 | AZ5: base -> | BA5: =Settings!$C$7 | BB5: =BA5+1 | BC5: =BB5+1 | BD5: =BC5+1 | BE5: =BD5+1 | BF5: =BE5+1 | BG5: =BF5+1 | BH5: =BG5+1 | BI5: =BH5+1 | ... BN5: =BM5+1
D6: Scenario name | AL6: =INDEX(Settings!$C$10:$C$13,AL$4) | BA6: =INDEX(Settings!$C$10:$C$13,BA$4)
D7: Real GDP growth | E7: % | F7: WEO (by country) | H7: mit.gdp.pos.pct | AL7: =INDEX(WEO!$F$4:$AZ$1000,MATCH(Settings!$C$4&"|gdp_growth",WEO!$A$4:$A$1000,0),MATCH(AL$5,WEO!$F$3:$AZ$3,0)) | AM7: =INDEX(WEO!$F$4:$AZ$1000,MATCH(Settings!$C$4&"|gdp_growth",WEO!$A$4:$A$1000,0),MATCH(AM$5,WEO!$F$3:$AZ$3,0)) | AN7: =INDEX(WEO!$F$4:$AZ$1000,MATCH(Settings!$C$4&"|gdp_growth",WEO!$A$4:$A$1000,0),MATCH(AN$5,WEO!$F$3:$AZ$3,0)) | AO7: =INDEX(WEO!$F$4:$AZ$1000,MATCH(Settings!$C$4&"|gdp_growth",WEO!$A$4:$A$1000,0),MATCH(AO$5,WEO!$F$3:$AZ$3,0)) | AP7: =INDEX(WEO!$F$4:$AZ$1000,MATCH(Settings!$C$4&"|gdp_growth",WEO!$A$4:$A$1000,0),MATCH(AP$5,WEO!$F$3:$AZ$3,0)) | AQ7: =INDEX(WEO!$F$4:$AZ$1000,MATCH(Settings!$C$4&"|gdp_growth",WEO!$A$4:$A$1000,0),MATCH(AQ$5,WEO!$F$3:$AZ$3,0)) | AR7: =INDEX(WEO!$F$4:$AZ$1000,MATCH(Settings!$C$4&"|gdp_growth",WEO!$A$4:$A$1000,0),MATCH(AR$5,WEO!$F$3:$AZ$3,0)) | AS7: =INDEX(WEO!$F$4:$AZ$1000,MATCH(Settings!$C$4&"|gdp_growth",WEO!$A$4:$A$1000,0),MATCH(AS$5,WEO!$F$3:$AZ$3,0)) | ... AY7: =INDEX(WEO!$F$4:$AZ$1000,MATCH(Settings!$C$4&"|gdp_growth",WEO!$A$4:$A$1000,0),MATCH(AY$5,WEO!$F$3:$AZ$3,0)) | BA7: =INDEX(WEO!$F$4:$AZ$1000,MATCH(Settings!$C$4&"|gdp_growth",WEO!$A$4:$A$1000,0),MATCH(BA$5,WEO!$F$3:$AZ$3,0)) | BB7: =INDEX(WEO!$F$4:$AZ$1000,MATCH(Settings!$C$4&"|gdp_growth",WEO!$A$4:$A$1000,0),MATCH(BB$5,WEO!$F$3:$AZ$3,0)) | BC7: =INDEX(WEO!$F$4:$AZ$1000,MATCH(Settings!$C$4&"|gdp_growth",WEO!$A$4:$A$1000,0),MATCH(BC$5,WEO!$F$3:$AZ$3,0)) | BD7: =INDEX(WEO!$F$4:$AZ$1000,MATCH(Settings!$C$4&"|gdp_growth",WEO!$A$4:$A$1000,0),MATCH(BD$5,WEO!$F$3:$AZ$3,0)) | BE7: =INDEX(WEO!$F$4:$AZ$1000,MATCH(Settings!$C$4&"|gdp_growth",WEO!$A$4:$A$1000,0),MATCH(BE$5,WEO!$F$3:$AZ$3,0)) | BF7: =INDEX(WEO!$F$4:$AZ$1000,MATCH(Settings!$C$4&"|gdp_growth",WEO!$A$4:$A$1000,0),MATCH(BF$5,WEO!$F$3:$AZ$3,0)) | BG7: =INDEX(WEO!$F$4:$AZ$1000,MATCH(Settings!$C$4&"|gdp_growth",WEO!$A$4:$A$1000,0),MATCH(BG$5,WEO!$F$3:$AZ$3,0)) | BH7: =INDEX(WEO!$F$4:$AZ$1000,MATCH(Settings!$C$4&"|gdp_growth",WEO!$A$4:$A$1000,0),MATCH(BH$5,WEO!$F$3:$AZ$3,0)) | ... BN7: =INDEX(WEO!$F$4:$AZ$1000,MATCH(Settings!$C$4&"|gdp_growth",WEO!$A$4:$A$1000,0),MATCH(BN$5,WEO!$F$3:$AZ$3,0))
D8: Carbon price | E8: $/tCO2 | F8: Scenario input | H8: mit.cp | AL8: 0 | AM8: 0 | AN8: 0 | AO8: 0 | AP8: 0 | AQ8: 0 | AR8: 0 | AS8: 0 | AT8: 0 | AU8: 0 | AV8: 0 | AW8: 0 | AX8: 0 | AY8: 0 | BA8: 0 | BB8: 0 | BC8: 0 | BD8: 0 | BE8: 0 | BF8: 20 | BG8: 20 | BH8: 20 | BI8: 20 | BJ8: 20 | BK8: 20 | BL8: 20 | BM8: 20 | BN8: 20
A10: Pre-tax price (supply cost) | Q10: Annual growth | R10: - | S10: - | T10: - | U10: buffer | V10: Annual growth | W10: - | X10: - | Y10: - | Z10: buffer | AA10: Annual growth | AB10: - | AC10: - | AD10: - | AE10: buffer | AF10: Annual growth | AG10: - | AH10: - | AI10: - | AJ10: buffer
B11: coa | C11: rod | D11: Pre-tax price | Road | Coal | E11: $/GJ | F11: Prices_dom (base year), then growth | G11: mit.sp.coa | H11: mit.pbt.coa.rod | J11: =INDEX(Mapping!$C$5:$C$20,MATCH($C11,Mapping!$A$5:$A$20,0)) | K11: =INDEX(Mapping!$D$5:$D$20,MATCH($C11,Mapping!$A$5:$A$20,0)) | L11: =INDEX(Mapping!$C$24:$C$31,MATCH($B11,Mapping!$A$24:$A$31,0)) | M11: =INDEX(Mapping!$D$24:$D$31,MATCH($B11,Mapping!$A$24:$A$31,0)) | N11: =$B11&"."&IF(INDEX(Mapping!$E$24:$E$31,MATCH($B11,Mapping!$A$24:$A$31,0))="sub",INDEX(Mapping!$F$5:$F$20,MATCH($C11,Mapping!$A$5:$A$20,0)),"all") | O11: =INDEX(Mapping!$E$5:$E$20,MATCH($C11,Mapping!$A$5:$A$20,0)) | P11: =INDEX(Mapping!$G$24:$G$31,MATCH($B11,Mapping!$A$24:$A$31,0)) | Q11: 0 | V11: =Q11 | AA11: =Q11 | AF11: =Q11 | AL11: =INDEX(Prices_dom!$A$6:$CU$2000,MATCH(Settings!$C$4&AL$5,Prices_dom!$A$6:$A$2000,0),MATCH("mit.sp."&$N11,Prices_dom!$A$5:$CU$5,0))/$P11 | AM11: =AL11*(1+INDEX($Q11:$AJ11,1,(AM$4-1)*5+1)) | AN11: =AM11*(1+INDEX($Q11:$AJ11,1,(AN$4-1)*5+1)) | AO11: =AN11*(1+INDEX($Q11:$AJ11,1,(AO$4-1)*5+1)) | AP11: =AO11*(1+INDEX($Q11:$AJ11,1,(AP$4-1)*5+1)) | AQ11: =AP11*(1+INDEX($Q11:$AJ11,1,(AQ$4-1)*5+1)) | AR11: =AQ11*(1+INDEX($Q11:$AJ11,1,(AR$4-1)*5+1)) | AS11: =AR11*(1+INDEX($Q11:$AJ11,1,(AS$4-1)*5+1)) | AT11: =AS11*(1+INDEX($Q11:$AJ11,1,(AT$4-1)*5+1)) | ... AY11: =AX11*(1+INDEX($Q11:$AJ11,1,(AY$4-1)*5+1)) | BA11: =INDEX(Prices_dom!$A$6:$CU$2000,MATCH(Settings!$C$4&BA$5,Prices_dom!$A$6:$A$2000,0),MATCH("mit.sp."&$N11,Prices_dom!$A$5:$CU$5,0))/$P11 | BB11: =BA11*(1+INDEX($Q11:$AJ11,1,(BB$4-1)*5+1)) | BC11: =BB11*(1+INDEX($Q11:$AJ11,1,(BC$4-1)*5+1)) | BD11: =BC11*(1+INDEX($Q11:$AJ11,1,(BD$4-1)*5+1)) | BE11: =BD11*(1+INDEX($Q11:$AJ11,1,(BE$4-1)*5+1)) | BF11: =BE11*(1+INDEX($Q11:$AJ11,1,(BF$4-1)*5+1)) | BG11: =BF11*(1+INDEX($Q11:$AJ11,1,(BG$4-1)*5+1)) | BH11: =BG11*(1+INDEX($Q11:$AJ11,1,(BH$4-1)*5+1)) | BI11: =BH11*(1+INDEX($Q11:$AJ11,1,(BI$4-1)*5+1)) | ... BN11: =BM11*(1+INDEX($Q11:$AJ11,1,(BN$4-1)*5+1))
B12: nga | C12: rod | D12: Pre-tax price | Road | Natural gas | E12: $/GJ | F12: Prices_dom (base year), then growth | G12: mit.sp.nga | H12: mit.pbt.nga.rod | J12: =INDEX(Mapping!$C$5:$C$20,MATCH($C12,Mapping!$A$5:$A$20,0)) | K12: =INDEX(Mapping!$D$5:$D$20,MATCH($C12,Mapping!$A$5:$A$20,0)) | L12: =INDEX(Mapping!$C$24:$C$31,MATCH($B12,Mapping!$A$24:$A$31,0)) | M12: =INDEX(Mapping!$D$24:$D$31,MATCH($B12,Mapping!$A$24:$A$31,0)) | N12: =$B12&"."&IF(INDEX(Mapping!$E$24:$E$31,MATCH($B12,Mapping!$A$24:$A$31,0))="sub",INDEX(Mapping!$F$5:$F$20,MATCH($C12,Mapping!$A$5:$A$20,0)),"all") | O12: =INDEX(Mapping!$E$5:$E$20,MATCH($C12,Mapping!$A$5:$A$20,0)) | P12: =INDEX(Mapping!$G$24:$G$31,MATCH($B12,Mapping!$A$24:$A$31,0)) | Q12: 0 | V12: =Q12 | AA12: =Q12 | AF12: =Q12 | AL12: =INDEX(Prices_dom!$A$6:$CU$2000,MATCH(Settings!$C$4&AL$5,Prices_dom!$A$6:$A$2000,0),MATCH("mit.sp."&$N12,Prices_dom!$A$5:$CU$5,0))/$P12 | AM12: =AL12*(1+INDEX($Q12:$AJ12,1,(AM$4-1)*5+1)) | AN12: =AM12*(1+INDEX($Q12:$AJ12,1,(AN$4-1)*5+1)) | AO12: =AN12*(1+INDEX($Q12:$AJ12,1,(AO$4-1)*5+1)) | AP12: =AO12*(1+INDEX($Q12:$AJ12,1,(AP$4-1)*5+1)) | AQ12: =AP12*(1+INDEX($Q12:$AJ12,1,(AQ$4-1)*5+1)) | AR12: =AQ12*(1+INDEX($Q12:$AJ12,1,(AR$4-1)*5+1)) | AS12: =AR12*(1+INDEX($Q12:$AJ12,1,(AS$4-1)*5+1)) | AT12: =AS12*(1+INDEX($Q12:$AJ12,1,(AT$4-1)*5+1)) | ... AY12: =AX12*(1+INDEX($Q12:$AJ12,1,(AY$4-1)*5+1)) | BA12: =INDEX(Prices_dom!$A$6:$CU$2000,MATCH(Settings!$C$4&BA$5,Prices_dom!$A$6:$A$2000,0),MATCH("mit.sp."&$N12,Prices_dom!$A$5:$CU$5,0))/$P12 | BB12: =BA12*(1+INDEX($Q12:$AJ12,1,(BB$4-1)*5+1)) | BC12: =BB12*(1+INDEX($Q12:$AJ12,1,(BC$4-1)*5+1)) | BD12: =BC12*(1+INDEX($Q12:$AJ12,1,(BD$4-1)*5+1)) | BE12: =BD12*(1+INDEX($Q12:$AJ12,1,(BE$4-1)*5+1)) | BF12: =BE12*(1+INDEX($Q12:$AJ12,1,(BF$4-1)*5+1)) | BG12: =BF12*(1+INDEX($Q12:$AJ12,1,(BG$4-1)*5+1)) | BH12: =BG12*(1+INDEX($Q12:$AJ12,1,(BH$4-1)*5+1)) | BI12: =BH12*(1+INDEX($Q12:$AJ12,1,(BI$4-1)*5+1)) | ... BN12: =BM12*(1+INDEX($Q12:$AJ12,1,(BN$4-1)*5+1))
B13: gso | C13: rod | D13: Pre-tax price | Road | Gasoline | E13: $/GJ | F13: Prices_dom (base year), then growth | G13: mit.sp.gso | H13: mit.pbt.gso.rod | J13: =INDEX(Mapping!$C$5:$C$20,MATCH($C13,Mapping!$A$5:$A$20,0)) | K13: =INDEX(Mapping!$D$5:$D$20,MATCH($C13,Mapping!$A$5:$A$20,0)) | L13: =INDEX(Mapping!$C$24:$C$31,MATCH($B13,Mapping!$A$24:$A$31,0)) | M13: =INDEX(Mapping!$D$24:$D$31,MATCH($B13,Mapping!$A$24:$A$31,0)) | N13: =$B13&"."&IF(INDEX(Mapping!$E$24:$E$31,MATCH($B13,Mapping!$A$24:$A$31,0))="sub",INDEX(Mapping!$F$5:$F$20,MATCH($C13,Mapping!$A$5:$A$20,0)),"all") | O13: =INDEX(Mapping!$E$5:$E$20,MATCH($C13,Mapping!$A$5:$A$20,0)) | P13: =INDEX(Mapping!$G$24:$G$31,MATCH($B13,Mapping!$A$24:$A$31,0)) | Q13: 0 | V13: =Q13 | AA13: =Q13 | AF13: =Q13 | AL13: =INDEX(Prices_dom!$A$6:$CU$2000,MATCH(Settings!$C$4&AL$5,Prices_dom!$A$6:$A$2000,0),MATCH("mit.sp."&$N13,Prices_dom!$A$5:$CU$5,0))/$P13 | AM13: =AL13*(1+INDEX($Q13:$AJ13,1,(AM$4-1)*5+1)) | AN13: =AM13*(1+INDEX($Q13:$AJ13,1,(AN$4-1)*5+1)) | AO13: =AN13*(1+INDEX($Q13:$AJ13,1,(AO$4-1)*5+1)) | AP13: =AO13*(1+INDEX($Q13:$AJ13,1,(AP$4-1)*5+1)) | AQ13: =AP13*(1+INDEX($Q13:$AJ13,1,(AQ$4-1)*5+1)) | AR13: =AQ13*(1+INDEX($Q13:$AJ13,1,(AR$4-1)*5+1)) | AS13: =AR13*(1+INDEX($Q13:$AJ13,1,(AS$4-1)*5+1)) | AT13: =AS13*(1+INDEX($Q13:$AJ13,1,(AT$4-1)*5+1)) | ... AY13: =AX13*(1+INDEX($Q13:$AJ13,1,(AY$4-1)*5+1)) | BA13: =INDEX(Prices_dom!$A$6:$CU$2000,MATCH(Settings!$C$4&BA$5,Prices_dom!$A$6:$A$2000,0),MATCH("mit.sp."&$N13,Prices_dom!$A$5:$CU$5,0))/$P13 | BB13: =BA13*(1+INDEX($Q13:$AJ13,1,(BB$4-1)*5+1)) | BC13: =BB13*(1+INDEX($Q13:$AJ13,1,(BC$4-1)*5+1)) | BD13: =BC13*(1+INDEX($Q13:$AJ13,1,(BD$4-1)*5+1)) | BE13: =BD13*(1+INDEX($Q13:$AJ13,1,(BE$4-1)*5+1)) | BF13: =BE13*(1+INDEX($Q13:$AJ13,1,(BF$4-1)*5+1)) | BG13: =BF13*(1+INDEX($Q13:$AJ13,1,(BG$4-1)*5+1)) | BH13: =BG13*(1+INDEX($Q13:$AJ13,1,(BH$4-1)*5+1)) | BI13: =BH13*(1+INDEX($Q13:$AJ13,1,(BI$4-1)*5+1)) | ... BN13: =BM13*(1+INDEX($Q13:$AJ13,1,(BN$4-1)*5+1))
B14: die | C14: rod | D14: Pre-tax price | Road | Diesel | E14: $/GJ | F14: Prices_dom (base year), then growth | G14: mit.sp.die | H14: mit.pbt.die.rod | J14: =INDEX(Mapping!$C$5:$C$20,MATCH($C14,Mapping!$A$5:$A$20,0)) | K14: =INDEX(Mapping!$D$5:$D$20,MATCH($C14,Mapping!$A$5:$A$20,0)) | L14: =INDEX(Mapping!$C$24:$C$31,MATCH($B14,Mapping!$A$24:$A$31,0)) | M14: =INDEX(Mapping!$D$24:$D$31,MATCH($B14,Mapping!$A$24:$A$31,0)) | N14: =$B14&"."&IF(INDEX(Mapping!$E$24:$E$31,MATCH($B14,Mapping!$A$24:$A$31,0))="sub",INDEX(Mapping!$F$5:$F$20,MATCH($C14,Mapping!$A$5:$A$20,0)),"all") | O14: =INDEX(Mapping!$E$5:$E$20,MATCH($C14,Mapping!$A$5:$A$20,0)) | P14: =INDEX(Mapping!$G$24:$G$31,MATCH($B14,Mapping!$A$24:$A$31,0)) | Q14: 0 | V14: =Q14 | AA14: =Q14 | AF14: =Q14 | AL14: =INDEX(Prices_dom!$A$6:$CU$2000,MATCH(Settings!$C$4&AL$5,Prices_dom!$A$6:$A$2000,0),MATCH("mit.sp."&$N14,Prices_dom!$A$5:$CU$5,0))/$P14 | AM14: =AL14*(1+INDEX($Q14:$AJ14,1,(AM$4-1)*5+1)) | AN14: =AM14*(1+INDEX($Q14:$AJ14,1,(AN$4-1)*5+1)) | AO14: =AN14*(1+INDEX($Q14:$AJ14,1,(AO$4-1)*5+1)) | AP14: =AO14*(1+INDEX($Q14:$AJ14,1,(AP$4-1)*5+1)) | AQ14: =AP14*(1+INDEX($Q14:$AJ14,1,(AQ$4-1)*5+1)) | AR14: =AQ14*(1+INDEX($Q14:$AJ14,1,(AR$4-1)*5+1)) | AS14: =AR14*(1+INDEX($Q14:$AJ14,1,(AS$4-1)*5+1)) | AT14: =AS14*(1+INDEX($Q14:$AJ14,1,(AT$4-1)*5+1)) | ... AY14: =AX14*(1+INDEX($Q14:$AJ14,1,(AY$4-1)*5+1)) | BA14: =INDEX(Prices_dom!$A$6:$CU$2000,MATCH(Settings!$C$4&BA$5,Prices_dom!$A$6:$A$2000,0),MATCH("mit.sp."&$N14,Prices_dom!$A$5:$CU$5,0))/$P14 | BB14: =BA14*(1+INDEX($Q14:$AJ14,1,(BB$4-1)*5+1)) | BC14: =BB14*(1+INDEX($Q14:$AJ14,1,(BC$4-1)*5+1)) | BD14: =BC14*(1+INDEX($Q14:$AJ14,1,(BD$4-1)*5+1)) | BE14: =BD14*(1+INDEX($Q14:$AJ14,1,(BE$4-1)*5+1)) | BF14: =BE14*(1+INDEX($Q14:$AJ14,1,(BF$4-1)*5+1)) | BG14: =BF14*(1+INDEX($Q14:$AJ14,1,(BG$4-1)*5+1)) | BH14: =BG14*(1+INDEX($Q14:$AJ14,1,(BH$4-1)*5+1)) | BI14: =BH14*(1+INDEX($Q14:$AJ14,1,(BI$4-1)*5+1)) | ... BN14: =BM14*(1+INDEX($Q14:$AJ14,1,(BN$4-1)*5+1))
B15: lpg | C15: rod | D15: Pre-tax price | Road | LPG | E15: $/GJ | F15: Prices_dom (base year), then growth | G15: mit.sp.lpg | H15: mit.pbt.lpg.rod | J15: =INDEX(Mapping!$C$5:$C$20,MATCH($C15,Mapping!$A$5:$A$20,0)) | K15: =INDEX(Mapping!$D$5:$D$20,MATCH($C15,Mapping!$A$5:$A$20,0)) | L15: =INDEX(Mapping!$C$24:$C$31,MATCH($B15,Mapping!$A$24:$A$31,0)) | M15: =INDEX(Mapping!$D$24:$D$31,MATCH($B15,Mapping!$A$24:$A$31,0)) | N15: =$B15&"."&IF(INDEX(Mapping!$E$24:$E$31,MATCH($B15,Mapping!$A$24:$A$31,0))="sub",INDEX(Mapping!$F$5:$F$20,MATCH($C15,Mapping!$A$5:$A$20,0)),"all") | O15: =INDEX(Mapping!$E$5:$E$20,MATCH($C15,Mapping!$A$5:$A$20,0)) | P15: =INDEX(Mapping!$G$24:$G$31,MATCH($B15,Mapping!$A$24:$A$31,0)) | Q15: 0 | V15: =Q15 | AA15: =Q15 | AF15: =Q15 | AL15: =INDEX(Prices_dom!$A$6:$CU$2000,MATCH(Settings!$C$4&AL$5,Prices_dom!$A$6:$A$2000,0),MATCH("mit.sp."&$N15,Prices_dom!$A$5:$CU$5,0))/$P15 | AM15: =AL15*(1+INDEX($Q15:$AJ15,1,(AM$4-1)*5+1)) | AN15: =AM15*(1+INDEX($Q15:$AJ15,1,(AN$4-1)*5+1)) | AO15: =AN15*(1+INDEX($Q15:$AJ15,1,(AO$4-1)*5+1)) | AP15: =AO15*(1+INDEX($Q15:$AJ15,1,(AP$4-1)*5+1)) | AQ15: =AP15*(1+INDEX($Q15:$AJ15,1,(AQ$4-1)*5+1)) | AR15: =AQ15*(1+INDEX($Q15:$AJ15,1,(AR$4-1)*5+1)) | AS15: =AR15*(1+INDEX($Q15:$AJ15,1,(AS$4-1)*5+1)) | AT15: =AS15*(1+INDEX($Q15:$AJ15,1,(AT$4-1)*5+1)) | ... AY15: =AX15*(1+INDEX($Q15:$AJ15,1,(AY$4-1)*5+1)) | BA15: =INDEX(Prices_dom!$A$6:$CU$2000,MATCH(Settings!$C$4&BA$5,Prices_dom!$A$6:$A$2000,0),MATCH("mit.sp."&$N15,Prices_dom!$A$5:$CU$5,0))/$P15 | BB15: =BA15*(1+INDEX($Q15:$AJ15,1,(BB$4-1)*5+1)) | BC15: =BB15*(1+INDEX($Q15:$AJ15,1,(BC$4-1)*5+1)) | BD15: =BC15*(1+INDEX($Q15:$AJ15,1,(BD$4-1)*5+1)) | BE15: =BD15*(1+INDEX($Q15:$AJ15,1,(BE$4-1)*5+1)) | BF15: =BE15*(1+INDEX($Q15:$AJ15,1,(BF$4-1)*5+1)) | BG15: =BF15*(1+INDEX($Q15:$AJ15,1,(BG$4-1)*5+1)) | BH15: =BG15*(1+INDEX($Q15:$AJ15,1,(BH$4-1)*5+1)) | BI15: =BH15*(1+INDEX($Q15:$AJ15,1,(BI$4-1)*5+1)) | ... BN15: =BM15*(1+INDEX($Q15:$AJ15,1,(BN$4-1)*5+1))
B16: ker | C16: rod | D16: Pre-tax price | Road | Kerosene | E16: $/GJ | F16: Prices_dom (base year), then growth | G16: mit.sp.ker | H16: mit.pbt.ker.rod | J16: =INDEX(Mapping!$C$5:$C$20,MATCH($C16,Mapping!$A$5:$A$20,0)) | K16: =INDEX(Mapping!$D$5:$D$20,MATCH($C16,Mapping!$A$5:$A$20,0)) | L16: =INDEX(Mapping!$C$24:$C$31,MATCH($B16,Mapping!$A$24:$A$31,0)) | M16: =INDEX(Mapping!$D$24:$D$31,MATCH($B16,Mapping!$A$24:$A$31,0)) | N16: =$B16&"."&IF(INDEX(Mapping!$E$24:$E$31,MATCH($B16,Mapping!$A$24:$A$31,0))="sub",INDEX(Mapping!$F$5:$F$20,MATCH($C16,Mapping!$A$5:$A$20,0)),"all") | O16: =INDEX(Mapping!$E$5:$E$20,MATCH($C16,Mapping!$A$5:$A$20,0)) | P16: =INDEX(Mapping!$G$24:$G$31,MATCH($B16,Mapping!$A$24:$A$31,0)) | Q16: 0 | V16: =Q16 | AA16: =Q16 | AF16: =Q16 | AL16: =INDEX(Prices_dom!$A$6:$CU$2000,MATCH(Settings!$C$4&AL$5,Prices_dom!$A$6:$A$2000,0),MATCH("mit.sp."&$N16,Prices_dom!$A$5:$CU$5,0))/$P16 | AM16: =AL16*(1+INDEX($Q16:$AJ16,1,(AM$4-1)*5+1)) | AN16: =AM16*(1+INDEX($Q16:$AJ16,1,(AN$4-1)*5+1)) | AO16: =AN16*(1+INDEX($Q16:$AJ16,1,(AO$4-1)*5+1)) | AP16: =AO16*(1+INDEX($Q16:$AJ16,1,(AP$4-1)*5+1)) | AQ16: =AP16*(1+INDEX($Q16:$AJ16,1,(AQ$4-1)*5+1)) | AR16: =AQ16*(1+INDEX($Q16:$AJ16,1,(AR$4-1)*5+1)) | AS16: =AR16*(1+INDEX($Q16:$AJ16,1,(AS$4-1)*5+1)) | AT16: =AS16*(1+INDEX($Q16:$AJ16,1,(AT$4-1)*5+1)) | ... AY16: =AX16*(1+INDEX($Q16:$AJ16,1,(AY$4-1)*5+1)) | BA16: =INDEX(Prices_dom!$A$6:$CU$2000,MATCH(Settings!$C$4&BA$5,Prices_dom!$A$6:$A$2000,0),MATCH("mit.sp."&$N16,Prices_dom!$A$5:$CU$5,0))/$P16 | BB16: =BA16*(1+INDEX($Q16:$AJ16,1,(BB$4-1)*5+1)) | BC16: =BB16*(1+INDEX($Q16:$AJ16,1,(BC$4-1)*5+1)) | BD16: =BC16*(1+INDEX($Q16:$AJ16,1,(BD$4-1)*5+1)) | BE16: =BD16*(1+INDEX($Q16:$AJ16,1,(BE$4-1)*5+1)) | BF16: =BE16*(1+INDEX($Q16:$AJ16,1,(BF$4-1)*5+1)) | BG16: =BF16*(1+INDEX($Q16:$AJ16,1,(BG$4-1)*5+1)) | BH16: =BG16*(1+INDEX($Q16:$AJ16,1,(BH$4-1)*5+1)) | BI16: =BH16*(1+INDEX($Q16:$AJ16,1,(BI$4-1)*5+1)) | ... BN16: =BM16*(1+INDEX($Q16:$AJ16,1,(BN$4-1)*5+1))
B17: oop | C17: rod | D17: Pre-tax price | Road | Other oil products | E17: $/GJ | F17: Prices_dom (base year), then growth | G17: mit.sp.oop | H17: mit.pbt.oop.rod | J17: =INDEX(Mapping!$C$5:$C$20,MATCH($C17,Mapping!$A$5:$A$20,0)) | K17: =INDEX(Mapping!$D$5:$D$20,MATCH($C17,Mapping!$A$5:$A$20,0)) | L17: =INDEX(Mapping!$C$24:$C$31,MATCH($B17,Mapping!$A$24:$A$31,0)) | M17: =INDEX(Mapping!$D$24:$D$31,MATCH($B17,Mapping!$A$24:$A$31,0)) | N17: =$B17&"."&IF(INDEX(Mapping!$E$24:$E$31,MATCH($B17,Mapping!$A$24:$A$31,0))="sub",INDEX(Mapping!$F$5:$F$20,MATCH($C17,Mapping!$A$5:$A$20,0)),"all") | O17: =INDEX(Mapping!$E$5:$E$20,MATCH($C17,Mapping!$A$5:$A$20,0)) | P17: =INDEX(Mapping!$G$24:$G$31,MATCH($B17,Mapping!$A$24:$A$31,0)) | Q17: 0 | V17: =Q17 | AA17: =Q17 | AF17: =Q17 | AL17: =INDEX(Prices_dom!$A$6:$CU$2000,MATCH(Settings!$C$4&AL$5,Prices_dom!$A$6:$A$2000,0),MATCH("mit.sp."&$N17,Prices_dom!$A$5:$CU$5,0))/$P17 | AM17: =AL17*(1+INDEX($Q17:$AJ17,1,(AM$4-1)*5+1)) | AN17: =AM17*(1+INDEX($Q17:$AJ17,1,(AN$4-1)*5+1)) | AO17: =AN17*(1+INDEX($Q17:$AJ17,1,(AO$4-1)*5+1)) | AP17: =AO17*(1+INDEX($Q17:$AJ17,1,(AP$4-1)*5+1)) | AQ17: =AP17*(1+INDEX($Q17:$AJ17,1,(AQ$4-1)*5+1)) | AR17: =AQ17*(1+INDEX($Q17:$AJ17,1,(AR$4-1)*5+1)) | AS17: =AR17*(1+INDEX($Q17:$AJ17,1,(AS$4-1)*5+1)) | AT17: =AS17*(1+INDEX($Q17:$AJ17,1,(AT$4-1)*5+1)) | ... AY17: =AX17*(1+INDEX($Q17:$AJ17,1,(AY$4-1)*5+1)) | BA17: =INDEX(Prices_dom!$A$6:$CU$2000,MATCH(Settings!$C$4&BA$5,Prices_dom!$A$6:$A$2000,0),MATCH("mit.sp."&$N17,Prices_dom!$A$5:$CU$5,0))/$P17 | BB17: =BA17*(1+INDEX($Q17:$AJ17,1,(BB$4-1)*5+1)) | BC17: =BB17*(1+INDEX($Q17:$AJ17,1,(BC$4-1)*5+1)) | BD17: =BC17*(1+INDEX($Q17:$AJ17,1,(BD$4-1)*5+1)) | BE17: =BD17*(1+INDEX($Q17:$AJ17,1,(BE$4-1)*5+1)) | BF17: =BE17*(1+INDEX($Q17:$AJ17,1,(BF$4-1)*5+1)) | BG17: =BF17*(1+INDEX($Q17:$AJ17,1,(BG$4-1)*5+1)) | BH17: =BG17*(1+INDEX($Q17:$AJ17,1,(BH$4-1)*5+1)) | BI17: =BH17*(1+INDEX($Q17:$AJ17,1,(BI$4-1)*5+1)) | ... BN17: =BM17*(1+INDEX($Q17:$AJ17,1,(BN$4-1)*5+1))
B18: bio | C18: rod | D18: Pre-tax price | Road | Biomass | E18: $/GJ | F18: Prices_dom (base year), then growth | G18: mit.sp.bio | H18: mit.pbt.bio.rod | J18: =INDEX(Mapping!$C$5:$C$20,MATCH($C18,Mapping!$A$5:$A$20,0)) | K18: =INDEX(Mapping!$D$5:$D$20,MATCH($C18,Mapping!$A$5:$A$20,0)) | L18: =INDEX(Mapping!$C$24:$C$31,MATCH($B18,Mapping!$A$24:$A$31,0)) | M18: =INDEX(Mapping!$D$24:$D$31,MATCH($B18,Mapping!$A$24:$A$31,0)) | N18: =$B18&"."&IF(INDEX(Mapping!$E$24:$E$31,MATCH($B18,Mapping!$A$24:$A$31,0))="sub",INDEX(Mapping!$F$5:$F$20,MATCH($C18,Mapping!$A$5:$A$20,0)),"all") | O18: =INDEX(Mapping!$E$5:$E$20,MATCH($C18,Mapping!$A$5:$A$20,0)) | P18: =INDEX(Mapping!$G$24:$G$31,MATCH($B18,Mapping!$A$24:$A$31,0)) | Q18: 0 | V18: =Q18 | AA18: =Q18 | AF18: =Q18 | AL18: =INDEX(Prices_dom!$A$6:$CU$2000,MATCH(Settings!$C$4&AL$5,Prices_dom!$A$6:$A$2000,0),MATCH("mit.sp."&$N18,Prices_dom!$A$5:$CU$5,0))/$P18 | AM18: =AL18*(1+INDEX($Q18:$AJ18,1,(AM$4-1)*5+1)) | AN18: =AM18*(1+INDEX($Q18:$AJ18,1,(AN$4-1)*5+1)) | AO18: =AN18*(1+INDEX($Q18:$AJ18,1,(AO$4-1)*5+1)) | AP18: =AO18*(1+INDEX($Q18:$AJ18,1,(AP$4-1)*5+1)) | AQ18: =AP18*(1+INDEX($Q18:$AJ18,1,(AQ$4-1)*5+1)) | AR18: =AQ18*(1+INDEX($Q18:$AJ18,1,(AR$4-1)*5+1)) | AS18: =AR18*(1+INDEX($Q18:$AJ18,1,(AS$4-1)*5+1)) | AT18: =AS18*(1+INDEX($Q18:$AJ18,1,(AT$4-1)*5+1)) | ... AY18: =AX18*(1+INDEX($Q18:$AJ18,1,(AY$4-1)*5+1)) | BA18: =INDEX(Prices_dom!$A$6:$CU$2000,MATCH(Settings!$C$4&BA$5,Prices_dom!$A$6:$A$2000,0),MATCH("mit.sp."&$N18,Prices_dom!$A$5:$CU$5,0))/$P18 | BB18: =BA18*(1+INDEX($Q18:$AJ18,1,(BB$4-1)*5+1)) | BC18: =BB18*(1+INDEX($Q18:$AJ18,1,(BC$4-1)*5+1)) | BD18: =BC18*(1+INDEX($Q18:$AJ18,1,(BD$4-1)*5+1)) | BE18: =BD18*(1+INDEX($Q18:$AJ18,1,(BE$4-1)*5+1)) | BF18: =BE18*(1+INDEX($Q18:$AJ18,1,(BF$4-1)*5+1)) | BG18: =BF18*(1+INDEX($Q18:$AJ18,1,(BG$4-1)*5+1)) | BH18: =BG18*(1+INDEX($Q18:$AJ18,1,(BH$4-1)*5+1)) | BI18: =BH18*(1+INDEX($Q18:$AJ18,1,(BI$4-1)*5+1)) | ... BN18: =BM18*(1+INDEX($Q18:$AJ18,1,(BN$4-1)*5+1))
B19: coa | C19: ral | D19: Pre-tax price | Rail | Coal | E19: $/GJ | F19: Prices_dom (base year), then growth | G19: mit.sp.coa | H19: mit.pbt.coa.ral | J19: =INDEX(Mapping!$C$5:$C$20,MATCH($C19,Mapping!$A$5:$A$20,0)) | K19: =INDEX(Mapping!$D$5:$D$20,MATCH($C19,Mapping!$A$5:$A$20,0)) | L19: =INDEX(Mapping!$C$24:$C$31,MATCH($B19,Mapping!$A$24:$A$31,0)) | M19: =INDEX(Mapping!$D$24:$D$31,MATCH($B19,Mapping!$A$24:$A$31,0)) | N19: =$B19&"."&IF(INDEX(Mapping!$E$24:$E$31,MATCH($B19,Mapping!$A$24:$A$31,0))="sub",INDEX(Mapping!$F$5:$F$20,MATCH($C19,Mapping!$A$5:$A$20,0)),"all") | O19: =INDEX(Mapping!$E$5:$E$20,MATCH($C19,Mapping!$A$5:$A$20,0)) | P19: =INDEX(Mapping!$G$24:$G$31,MATCH($B19,Mapping!$A$24:$A$31,0)) | Q19: 0 | V19: =Q19 | AA19: =Q19 | AF19: =Q19 | AL19: =INDEX(Prices_dom!$A$6:$CU$2000,MATCH(Settings!$C$4&AL$5,Prices_dom!$A$6:$A$2000,0),MATCH("mit.sp."&$N19,Prices_dom!$A$5:$CU$5,0))/$P19 | AM19: =AL19*(1+INDEX($Q19:$AJ19,1,(AM$4-1)*5+1)) | AN19: =AM19*(1+INDEX($Q19:$AJ19,1,(AN$4-1)*5+1)) | AO19: =AN19*(1+INDEX($Q19:$AJ19,1,(AO$4-1)*5+1)) | AP19: =AO19*(1+INDEX($Q19:$AJ19,1,(AP$4-1)*5+1)) | AQ19: =AP19*(1+INDEX($Q19:$AJ19,1,(AQ$4-1)*5+1)) | AR19: =AQ19*(1+INDEX($Q19:$AJ19,1,(AR$4-1)*5+1)) | AS19: =AR19*(1+INDEX($Q19:$AJ19,1,(AS$4-1)*5+1)) | AT19: =AS19*(1+INDEX($Q19:$AJ19,1,(AT$4-1)*5+1)) | ... AY19: =AX19*(1+INDEX($Q19:$AJ19,1,(AY$4-1)*5+1)) | BA19: =INDEX(Prices_dom!$A$6:$CU$2000,MATCH(Settings!$C$4&BA$5,Prices_dom!$A$6:$A$2000,0),MATCH("mit.sp."&$N19,Prices_dom!$A$5:$CU$5,0))/$P19 | BB19: =BA19*(1+INDEX($Q19:$AJ19,1,(BB$4-1)*5+1)) | BC19: =BB19*(1+INDEX($Q19:$AJ19,1,(BC$4-1)*5+1)) | BD19: =BC19*(1+INDEX($Q19:$AJ19,1,(BD$4-1)*5+1)) | BE19: =BD19*(1+INDEX($Q19:$AJ19,1,(BE$4-1)*5+1)) | BF19: =BE19*(1+INDEX($Q19:$AJ19,1,(BF$4-1)*5+1)) | BG19: =BF19*(1+INDEX($Q19:$AJ19,1,(BG$4-1)*5+1)) | BH19: =BG19*(1+INDEX($Q19:$AJ19,1,(BH$4-1)*5+1)) | BI19: =BH19*(1+INDEX($Q19:$AJ19,1,(BI$4-1)*5+1)) | ... BN19: =BM19*(1+INDEX($Q19:$AJ19,1,(BN$4-1)*5+1))
B20: nga | C20: ral | D20: Pre-tax price | Rail | Natural gas | E20: $/GJ | F20: Prices_dom (base year), then growth | G20: mit.sp.nga | H20: mit.pbt.nga.ral | J20: =INDEX(Mapping!$C$5:$C$20,MATCH($C20,Mapping!$A$5:$A$20,0)) | K20: =INDEX(Mapping!$D$5:$D$20,MATCH($C20,Mapping!$A$5:$A$20,0)) | L20: =INDEX(Mapping!$C$24:$C$31,MATCH($B20,Mapping!$A$24:$A$31,0)) | M20: =INDEX(Mapping!$D$24:$D$31,MATCH($B20,Mapping!$A$24:$A$31,0)) | N20: =$B20&"."&IF(INDEX(Mapping!$E$24:$E$31,MATCH($B20,Mapping!$A$24:$A$31,0))="sub",INDEX(Mapping!$F$5:$F$20,MATCH($C20,Mapping!$A$5:$A$20,0)),"all") | O20: =INDEX(Mapping!$E$5:$E$20,MATCH($C20,Mapping!$A$5:$A$20,0)) | P20: =INDEX(Mapping!$G$24:$G$31,MATCH($B20,Mapping!$A$24:$A$31,0)) | Q20: 0 | V20: =Q20 | AA20: =Q20 | AF20: =Q20 | AL20: =INDEX(Prices_dom!$A$6:$CU$2000,MATCH(Settings!$C$4&AL$5,Prices_dom!$A$6:$A$2000,0),MATCH("mit.sp."&$N20,Prices_dom!$A$5:$CU$5,0))/$P20 | AM20: =AL20*(1+INDEX($Q20:$AJ20,1,(AM$4-1)*5+1)) | AN20: =AM20*(1+INDEX($Q20:$AJ20,1,(AN$4-1)*5+1)) | AO20: =AN20*(1+INDEX($Q20:$AJ20,1,(AO$4-1)*5+1)) | AP20: =AO20*(1+INDEX($Q20:$AJ20,1,(AP$4-1)*5+1)) | AQ20: =AP20*(1+INDEX($Q20:$AJ20,1,(AQ$4-1)*5+1)) | AR20: =AQ20*(1+INDEX($Q20:$AJ20,1,(AR$4-1)*5+1)) | AS20: =AR20*(1+INDEX($Q20:$AJ20,1,(AS$4-1)*5+1)) | AT20: =AS20*(1+INDEX($Q20:$AJ20,1,(AT$4-1)*5+1)) | ... AY20: =AX20*(1+INDEX($Q20:$AJ20,1,(AY$4-1)*5+1)) | BA20: =INDEX(Prices_dom!$A$6:$CU$2000,MATCH(Settings!$C$4&BA$5,Prices_dom!$A$6:$A$2000,0),MATCH("mit.sp."&$N20,Prices_dom!$A$5:$CU$5,0))/$P20 | BB20: =BA20*(1+INDEX($Q20:$AJ20,1,(BB$4-1)*5+1)) | BC20: =BB20*(1+INDEX($Q20:$AJ20,1,(BC$4-1)*5+1)) | BD20: =BC20*(1+INDEX($Q20:$AJ20,1,(BD$4-1)*5+1)) | BE20: =BD20*(1+INDEX($Q20:$AJ20,1,(BE$4-1)*5+1)) | BF20: =BE20*(1+INDEX($Q20:$AJ20,1,(BF$4-1)*5+1)) | BG20: =BF20*(1+INDEX($Q20:$AJ20,1,(BG$4-1)*5+1)) | BH20: =BG20*(1+INDEX($Q20:$AJ20,1,(BH$4-1)*5+1)) | BI20: =BH20*(1+INDEX($Q20:$AJ20,1,(BI$4-1)*5+1)) | ... BN20: =BM20*(1+INDEX($Q20:$AJ20,1,(BN$4-1)*5+1))
B21: gso | C21: ral | D21: Pre-tax price | Rail | Gasoline | E21: $/GJ | F21: Prices_dom (base year), then growth | G21: mit.sp.gso | H21: mit.pbt.gso.ral | J21: =INDEX(Mapping!$C$5:$C$20,MATCH($C21,Mapping!$A$5:$A$20,0)) | K21: =INDEX(Mapping!$D$5:$D$20,MATCH($C21,Mapping!$A$5:$A$20,0)) | L21: =INDEX(Mapping!$C$24:$C$31,MATCH($B21,Mapping!$A$24:$A$31,0)) | M21: =INDEX(Mapping!$D$24:$D$31,MATCH($B21,Mapping!$A$24:$A$31,0)) | N21: =$B21&"."&IF(INDEX(Mapping!$E$24:$E$31,MATCH($B21,Mapping!$A$24:$A$31,0))="sub",INDEX(Mapping!$F$5:$F$20,MATCH($C21,Mapping!$A$5:$A$20,0)),"all") | O21: =INDEX(Mapping!$E$5:$E$20,MATCH($C21,Mapping!$A$5:$A$20,0)) | P21: =INDEX(Mapping!$G$24:$G$31,MATCH($B21,Mapping!$A$24:$A$31,0)) | Q21: 0 | V21: =Q21 | AA21: =Q21 | AF21: =Q21 | AL21: =INDEX(Prices_dom!$A$6:$CU$2000,MATCH(Settings!$C$4&AL$5,Prices_dom!$A$6:$A$2000,0),MATCH("mit.sp."&$N21,Prices_dom!$A$5:$CU$5,0))/$P21 | AM21: =AL21*(1+INDEX($Q21:$AJ21,1,(AM$4-1)*5+1)) | AN21: =AM21*(1+INDEX($Q21:$AJ21,1,(AN$4-1)*5+1)) | AO21: =AN21*(1+INDEX($Q21:$AJ21,1,(AO$4-1)*5+1)) | AP21: =AO21*(1+INDEX($Q21:$AJ21,1,(AP$4-1)*5+1)) | AQ21: =AP21*(1+INDEX($Q21:$AJ21,1,(AQ$4-1)*5+1)) | AR21: =AQ21*(1+INDEX($Q21:$AJ21,1,(AR$4-1)*5+1)) | AS21: =AR21*(1+INDEX($Q21:$AJ21,1,(AS$4-1)*5+1)) | AT21: =AS21*(1+INDEX($Q21:$AJ21,1,(AT$4-1)*5+1)) | ... AY21: =AX21*(1+INDEX($Q21:$AJ21,1,(AY$4-1)*5+1)) | BA21: =INDEX(Prices_dom!$A$6:$CU$2000,MATCH(Settings!$C$4&BA$5,Prices_dom!$A$6:$A$2000,0),MATCH("mit.sp."&$N21,Prices_dom!$A$5:$CU$5,0))/$P21 | BB21: =BA21*(1+INDEX($Q21:$AJ21,1,(BB$4-1)*5+1)) | BC21: =BB21*(1+INDEX($Q21:$AJ21,1,(BC$4-1)*5+1)) | BD21: =BC21*(1+INDEX($Q21:$AJ21,1,(BD$4-1)*5+1)) | BE21: =BD21*(1+INDEX($Q21:$AJ21,1,(BE$4-1)*5+1)) | BF21: =BE21*(1+INDEX($Q21:$AJ21,1,(BF$4-1)*5+1)) | BG21: =BF21*(1+INDEX($Q21:$AJ21,1,(BG$4-1)*5+1)) | BH21: =BG21*(1+INDEX($Q21:$AJ21,1,(BH$4-1)*5+1)) | BI21: =BH21*(1+INDEX($Q21:$AJ21,1,(BI$4-1)*5+1)) | ... BN21: =BM21*(1+INDEX($Q21:$AJ21,1,(BN$4-1)*5+1))
B22: die | C22: ral | D22: Pre-tax price | Rail | Diesel | E22: $/GJ | F22: Prices_dom (base year), then growth | G22: mit.sp.die | H22: mit.pbt.die.ral | J22: =INDEX(Mapping!$C$5:$C$20,MATCH($C22,Mapping!$A$5:$A$20,0)) | K22: =INDEX(Mapping!$D$5:$D$20,MATCH($C22,Mapping!$A$5:$A$20,0)) | L22: =INDEX(Mapping!$C$24:$C$31,MATCH($B22,Mapping!$A$24:$A$31,0)) | M22: =INDEX(Mapping!$D$24:$D$31,MATCH($B22,Mapping!$A$24:$A$31,0)) | N22: =$B22&"."&IF(INDEX(Mapping!$E$24:$E$31,MATCH($B22,Mapping!$A$24:$A$31,0))="sub",INDEX(Mapping!$F$5:$F$20,MATCH($C22,Mapping!$A$5:$A$20,0)),"all") | O22: =INDEX(Mapping!$E$5:$E$20,MATCH($C22,Mapping!$A$5:$A$20,0)) | P22: =INDEX(Mapping!$G$24:$G$31,MATCH($B22,Mapping!$A$24:$A$31,0)) | Q22: 0 | V22: =Q22 | AA22: =Q22 | AF22: =Q22 | AL22: =INDEX(Prices_dom!$A$6:$CU$2000,MATCH(Settings!$C$4&AL$5,Prices_dom!$A$6:$A$2000,0),MATCH("mit.sp."&$N22,Prices_dom!$A$5:$CU$5,0))/$P22 | AM22: =AL22*(1+INDEX($Q22:$AJ22,1,(AM$4-1)*5+1)) | AN22: =AM22*(1+INDEX($Q22:$AJ22,1,(AN$4-1)*5+1)) | AO22: =AN22*(1+INDEX($Q22:$AJ22,1,(AO$4-1)*5+1)) | AP22: =AO22*(1+INDEX($Q22:$AJ22,1,(AP$4-1)*5+1)) | AQ22: =AP22*(1+INDEX($Q22:$AJ22,1,(AQ$4-1)*5+1)) | AR22: =AQ22*(1+INDEX($Q22:$AJ22,1,(AR$4-1)*5+1)) | AS22: =AR22*(1+INDEX($Q22:$AJ22,1,(AS$4-1)*5+1)) | AT22: =AS22*(1+INDEX($Q22:$AJ22,1,(AT$4-1)*5+1)) | ... AY22: =AX22*(1+INDEX($Q22:$AJ22,1,(AY$4-1)*5+1)) | BA22: =INDEX(Prices_dom!$A$6:$CU$2000,MATCH(Settings!$C$4&BA$5,Prices_dom!$A$6:$A$2000,0),MATCH("mit.sp."&$N22,Prices_dom!$A$5:$CU$5,0))/$P22 | BB22: =BA22*(1+INDEX($Q22:$AJ22,1,(BB$4-1)*5+1)) | BC22: =BB22*(1+INDEX($Q22:$AJ22,1,(BC$4-1)*5+1)) | BD22: =BC22*(1+INDEX($Q22:$AJ22,1,(BD$4-1)*5+1)) | BE22: =BD22*(1+INDEX($Q22:$AJ22,1,(BE$4-1)*5+1)) | BF22: =BE22*(1+INDEX($Q22:$AJ22,1,(BF$4-1)*5+1)) | BG22: =BF22*(1+INDEX($Q22:$AJ22,1,(BG$4-1)*5+1)) | BH22: =BG22*(1+INDEX($Q22:$AJ22,1,(BH$4-1)*5+1)) | BI22: =BH22*(1+INDEX($Q22:$AJ22,1,(BI$4-1)*5+1)) | ... BN22: =BM22*(1+INDEX($Q22:$AJ22,1,(BN$4-1)*5+1))
... B138: bio | C138: oen | D138: Pre-tax price | Other energy use | Biomass | E138: $/GJ | F138: Prices_dom (base year), then growth | G138: mit.sp.bio | H138: mit.pbt.bio.oen | J138: =INDEX(Mapping!$C$5:$C$20,MATCH($C138,Mapping!$A$5:$A$20,0)) | K138: =INDEX(Mapping!$D$5:$D$20,MATCH($C138,Mapping!$A$5:$A$20,0)) | L138: =INDEX(Mapping!$C$24:$C$31,MATCH($B138,Mapping!$A$24:$A$31,0)) | M138: =INDEX(Mapping!$D$24:$D$31,MATCH($B138,Mapping!$A$24:$A$31,0)) | N138: =$B138&"."&IF(INDEX(Mapping!$E$24:$E$31,MATCH($B138,Mapping!$A$24:$A$31,0))="sub",INDEX(Mapping!$F$5:$F$20,MATCH($C138,Mapping!$A$5:$A$20,0)),"all") | O138: =INDEX(Mapping!$E$5:$E$20,MATCH($C138,Mapping!$A$5:$A$20,0)) | P138: =INDEX(Mapping!$G$24:$G$31,MATCH($B138,Mapping!$A$24:$A$31,0)) | Q138: 0 | V138: =Q138 | AA138: =Q138 | AF138: =Q138 | AL138: =INDEX(Prices_dom!$A$6:$CU$2000,MATCH(Settings!$C$4&AL$5,Prices_dom!$A$6:$A$2000,0),MATCH("mit.sp."&$N138,Prices_dom!$A$5:$CU$5,0))/$P138 | AM138: =AL138*(1+INDEX($Q138:$AJ138,1,(AM$4-1)*5+1)) | AN138: =AM138*(1+INDEX($Q138:$AJ138,1,(AN$4-1)*5+1)) | AO138: =AN138*(1+INDEX($Q138:$AJ138,1,(AO$4-1)*5+1)) | AP138: =AO138*(1+INDEX($Q138:$AJ138,1,(AP$4-1)*5+1)) | AQ138: =AP138*(1+INDEX($Q138:$AJ138,1,(AQ$4-1)*5+1)) | AR138: =AQ138*(1+INDEX($Q138:$AJ138,1,(AR$4-1)*5+1)) | AS138: =AR138*(1+INDEX($Q138:$AJ138,1,(AS$4-1)*5+1)) | AT138: =AS138*(1+INDEX($Q138:$AJ138,1,(AT$4-1)*5+1)) | ... AY138: =AX138*(1+INDEX($Q138:$AJ138,1,(AY$4-1)*5+1)) | BA138: =INDEX(Prices_dom!$A$6:$CU$2000,MATCH(Settings!$C$4&BA$5,Prices_dom!$A$6:$A$2000,0),MATCH("mit.sp."&$N138,Prices_dom!$A$5:$CU$5,0))/$P138 | BB138: =BA138*(1+INDEX($Q138:$AJ138,1,(BB$4-1)*5+1)) | BC138: =BB138*(1+INDEX($Q138:$AJ138,1,(BC$4-1)*5+1)) | BD138: =BC138*(1+INDEX($Q138:$AJ138,1,(BD$4-1)*5+1)) | BE138: =BD138*(1+INDEX($Q138:$AJ138,1,(BE$4-1)*5+1)) | BF138: =BE138*(1+INDEX($Q138:$AJ138,1,(BF$4-1)*5+1)) | BG138: =BF138*(1+INDEX($Q138:$AJ138,1,(BG$4-1)*5+1)) | BH138: =BG138*(1+INDEX($Q138:$AJ138,1,(BH$4-1)*5+1)) | BI138: =BH138*(1+INDEX($Q138:$AJ138,1,(BI$4-1)*5+1)) | ... BN138: =BM138*(1+INDEX($Q138:$AJ138,1,(BN$4-1)*5+1))
A140: Tax: base tax + carbon price x EF x coverage | Q140: Base tax ($/GJ) | R140: EF (tCO2/GJ) | S140: Coverage | T140: - | U140: buffer | V140: Base tax ($/GJ) | W140: EF (tCO2/GJ) | X140: Coverage | Y140: - | Z140: buffer | AA140: Base tax ($/GJ) | AB140: EF (tCO2/GJ) | AC140: Coverage | AD140: - | AE140: buffer | AF140: Base tax ($/GJ) | AG140: EF (tCO2/GJ) | AH140: Coverage | AI140: - | AJ140: buffer
B141: coa | C141: rod | D141: Tax | Road | Coal | E141: $/GJ | F141: Prices_dom, EF_GHG, Mapping | G141: mit.rp.coa | H141: mit.tax.coa.rod | J141: =INDEX(Mapping!$C$5:$C$20,MATCH($C141,Mapping!$A$5:$A$20,0)) | K141: =INDEX(Mapping!$D$5:$D$20,MATCH($C141,Mapping!$A$5:$A$20,0)) | L141: =INDEX(Mapping!$C$24:$C$31,MATCH($B141,Mapping!$A$24:$A$31,0)) | M141: =INDEX(Mapping!$D$24:$D$31,MATCH($B141,Mapping!$A$24:$A$31,0)) | N141: =$B141&"."&IF(INDEX(Mapping!$E$24:$E$31,MATCH($B141,Mapping!$A$24:$A$31,0))="sub",INDEX(Mapping!$F$5:$F$20,MATCH($C141,Mapping!$A$5:$A$20,0)),"all") | O141: =INDEX(Mapping!$E$5:$E$20,MATCH($C141,Mapping!$A$5:$A$20,0)) | P141: =INDEX(Mapping!$G$24:$G$31,MATCH($B141,Mapping!$A$24:$A$31,0)) | Q141: =(INDEX(Prices_dom!$A$6:$CU$2000,MATCH(Settings!$C$4&Settings!$C$7,Prices_dom!$A$6:$A$2000,0),MATCH("mit.rp."&$N141,Prices_dom!$A$5:$CU$5,0))-INDEX(Prices_dom!$A$6:$CU$2000,MATCH(Settings!$C$4&Settings!$C$7,Prices_dom!$A$6:$A$2000,0),MATCH("mit.sp."&$N141,Prices_dom!$A$5:$CU$5,0)))/$P141 | R141: =INDEX(EF_GHG!$E$4:$E$1000,MATCH(Settings!$C$4&"|"&$B141&"|"&$O141,EF_GHG!$A$4:$A$1000,0)) | S141: =INDEX(Mapping!$G$5:$G$20,MATCH($C141,Mapping!$A$5:$A$20,0)) | V141: =Q141 | W141: =R141 | X141: =S141 | AA141: =Q141 | AB141: =R141 | AC141: =S141 | AF141: =Q141 | AG141: =R141 | AH141: =S141 | AL141: =INDEX($Q141:$AJ141,1,(AL$4-1)*5+1)+AL$8*INDEX($Q141:$AJ141,1,(AL$4-1)*5+2)*INDEX($Q141:$AJ141,1,(AL$4-1)*5+3) | AM141: =INDEX($Q141:$AJ141,1,(AM$4-1)*5+1)+AM$8*INDEX($Q141:$AJ141,1,(AM$4-1)*5+2)*INDEX($Q141:$AJ141,1,(AM$4-1)*5+3) | AN141: =INDEX($Q141:$AJ141,1,(AN$4-1)*5+1)+AN$8*INDEX($Q141:$AJ141,1,(AN$4-1)*5+2)*INDEX($Q141:$AJ141,1,(AN$4-1)*5+3) | AO141: =INDEX($Q141:$AJ141,1,(AO$4-1)*5+1)+AO$8*INDEX($Q141:$AJ141,1,(AO$4-1)*5+2)*INDEX($Q141:$AJ141,1,(AO$4-1)*5+3) | AP141: =INDEX($Q141:$AJ141,1,(AP$4-1)*5+1)+AP$8*INDEX($Q141:$AJ141,1,(AP$4-1)*5+2)*INDEX($Q141:$AJ141,1,(AP$4-1)*5+3) | AQ141: =INDEX($Q141:$AJ141,1,(AQ$4-1)*5+1)+AQ$8*INDEX($Q141:$AJ141,1,(AQ$4-1)*5+2)*INDEX($Q141:$AJ141,1,(AQ$4-1)*5+3) | AR141: =INDEX($Q141:$AJ141,1,(AR$4-1)*5+1)+AR$8*INDEX($Q141:$AJ141,1,(AR$4-1)*5+2)*INDEX($Q141:$AJ141,1,(AR$4-1)*5+3) | AS141: =INDEX($Q141:$AJ141,1,(AS$4-1)*5+1)+AS$8*INDEX($Q141:$AJ141,1,(AS$4-1)*5+2)*INDEX($Q141:$AJ141,1,(AS$4-1)*5+3) | ... AY141: =INDEX($Q141:$AJ141,1,(AY$4-1)*5+1)+AY$8*INDEX($Q141:$AJ141,1,(AY$4-1)*5+2)*INDEX($Q141:$AJ141,1,(AY$4-1)*5+3) | BA141: =INDEX($Q141:$AJ141,1,(BA$4-1)*5+1)+BA$8*INDEX($Q141:$AJ141,1,(BA$4-1)*5+2)*INDEX($Q141:$AJ141,1,(BA$4-1)*5+3) | BB141: =INDEX($Q141:$AJ141,1,(BB$4-1)*5+1)+BB$8*INDEX($Q141:$AJ141,1,(BB$4-1)*5+2)*INDEX($Q141:$AJ141,1,(BB$4-1)*5+3) | BC141: =INDEX($Q141:$AJ141,1,(BC$4-1)*5+1)+BC$8*INDEX($Q141:$AJ141,1,(BC$4-1)*5+2)*INDEX($Q141:$AJ141,1,(BC$4-1)*5+3) | BD141: =INDEX($Q141:$AJ141,1,(BD$4-1)*5+1)+BD$8*INDEX($Q141:$AJ141,1,(BD$4-1)*5+2)*INDEX($Q141:$AJ141,1,(BD$4-1)*5+3) | BE141: =INDEX($Q141:$AJ141,1,(BE$4-1)*5+1)+BE$8*INDEX($Q141:$AJ141,1,(BE$4-1)*5+2)*INDEX($Q141:$AJ141,1,(BE$4-1)*5+3) | BF141: =INDEX($Q141:$AJ141,1,(BF$4-1)*5+1)+BF$8*INDEX($Q141:$AJ141,1,(BF$4-1)*5+2)*INDEX($Q141:$AJ141,1,(BF$4-1)*5+3) | BG141: =INDEX($Q141:$AJ141,1,(BG$4-1)*5+1)+BG$8*INDEX($Q141:$AJ141,1,(BG$4-1)*5+2)*INDEX($Q141:$AJ141,1,(BG$4-1)*5+3) | BH141: =INDEX($Q141:$AJ141,1,(BH$4-1)*5+1)+BH$8*INDEX($Q141:$AJ141,1,(BH$4-1)*5+2)*INDEX($Q141:$AJ141,1,(BH$4-1)*5+3) | ... BN141: =INDEX($Q141:$AJ141,1,(BN$4-1)*5+1)+BN$8*INDEX($Q141:$AJ141,1,(BN$4-1)*5+2)*INDEX($Q141:$AJ141,1,(BN$4-1)*5+3)
B142: nga | C142: rod | D142: Tax | Road | Natural gas | E142: $/GJ | F142: Prices_dom, EF_GHG, Mapping | G142: mit.rp.nga | H142: mit.tax.nga.rod | J142: =INDEX(Mapping!$C$5:$C$20,MATCH($C142,Mapping!$A$5:$A$20,0)) | K142: =INDEX(Mapping!$D$5:$D$20,MATCH($C142,Mapping!$A$5:$A$20,0)) | L142: =INDEX(Mapping!$C$24:$C$31,MATCH($B142,Mapping!$A$24:$A$31,0)) | M142: =INDEX(Mapping!$D$24:$D$31,MATCH($B142,Mapping!$A$24:$A$31,0)) | N142: =$B142&"."&IF(INDEX(Mapping!$E$24:$E$31,MATCH($B142,Mapping!$A$24:$A$31,0))="sub",INDEX(Mapping!$F$5:$F$20,MATCH($C142,Mapping!$A$5:$A$20,0)),"all") | O142: =INDEX(Mapping!$E$5:$E$20,MATCH($C142,Mapping!$A$5:$A$20,0)) | P142: =INDEX(Mapping!$G$24:$G$31,MATCH($B142,Mapping!$A$24:$A$31,0)) | Q142: =(INDEX(Prices_dom!$A$6:$CU$2000,MATCH(Settings!$C$4&Settings!$C$7,Prices_dom!$A$6:$A$2000,0),MATCH("mit.rp."&$N142,Prices_dom!$A$5:$CU$5,0))-INDEX(Prices_dom!$A$6:$CU$2000,MATCH(Settings!$C$4&Settings!$C$7,Prices_dom!$A$6:$A$2000,0),MATCH("mit.sp."&$N142,Prices_dom!$A$5:$CU$5,0)))/$P142 | R142: =INDEX(EF_GHG!$E$4:$E$1000,MATCH(Settings!$C$4&"|"&$B142&"|"&$O142,EF_GHG!$A$4:$A$1000,0)) | S142: =INDEX(Mapping!$G$5:$G$20,MATCH($C142,Mapping!$A$5:$A$20,0)) | V142: =Q142 | W142: =R142 | X142: =S142 | AA142: =Q142 | AB142: =R142 | AC142: =S142 | AF142: =Q142 | AG142: =R142 | AH142: =S142 | AL142: =INDEX($Q142:$AJ142,1,(AL$4-1)*5+1)+AL$8*INDEX($Q142:$AJ142,1,(AL$4-1)*5+2)*INDEX($Q142:$AJ142,1,(AL$4-1)*5+3) | AM142: =INDEX($Q142:$AJ142,1,(AM$4-1)*5+1)+AM$8*INDEX($Q142:$AJ142,1,(AM$4-1)*5+2)*INDEX($Q142:$AJ142,1,(AM$4-1)*5+3) | AN142: =INDEX($Q142:$AJ142,1,(AN$4-1)*5+1)+AN$8*INDEX($Q142:$AJ142,1,(AN$4-1)*5+2)*INDEX($Q142:$AJ142,1,(AN$4-1)*5+3) | AO142: =INDEX($Q142:$AJ142,1,(AO$4-1)*5+1)+AO$8*INDEX($Q142:$AJ142,1,(AO$4-1)*5+2)*INDEX($Q142:$AJ142,1,(AO$4-1)*5+3) | AP142: =INDEX($Q142:$AJ142,1,(AP$4-1)*5+1)+AP$8*INDEX($Q142:$AJ142,1,(AP$4-1)*5+2)*INDEX($Q142:$AJ142,1,(AP$4-1)*5+3) | AQ142: =INDEX($Q142:$AJ142,1,(AQ$4-1)*5+1)+AQ$8*INDEX($Q142:$AJ142,1,(AQ$4-1)*5+2)*INDEX($Q142:$AJ142,1,(AQ$4-1)*5+3) | AR142: =INDEX($Q142:$AJ142,1,(AR$4-1)*5+1)+AR$8*INDEX($Q142:$AJ142,1,(AR$4-1)*5+2)*INDEX($Q142:$AJ142,1,(AR$4-1)*5+3) | AS142: =INDEX($Q142:$AJ142,1,(AS$4-1)*5+1)+AS$8*INDEX($Q142:$AJ142,1,(AS$4-1)*5+2)*INDEX($Q142:$AJ142,1,(AS$4-1)*5+3) | ... AY142: =INDEX($Q142:$AJ142,1,(AY$4-1)*5+1)+AY$8*INDEX($Q142:$AJ142,1,(AY$4-1)*5+2)*INDEX($Q142:$AJ142,1,(AY$4-1)*5+3) | BA142: =INDEX($Q142:$AJ142,1,(BA$4-1)*5+1)+BA$8*INDEX($Q142:$AJ142,1,(BA$4-1)*5+2)*INDEX($Q142:$AJ142,1,(BA$4-1)*5+3) | BB142: =INDEX($Q142:$AJ142,1,(BB$4-1)*5+1)+BB$8*INDEX($Q142:$AJ142,1,(BB$4-1)*5+2)*INDEX($Q142:$AJ142,1,(BB$4-1)*5+3) | BC142: =INDEX($Q142:$AJ142,1,(BC$4-1)*5+1)+BC$8*INDEX($Q142:$AJ142,1,(BC$4-1)*5+2)*INDEX($Q142:$AJ142,1,(BC$4-1)*5+3) | BD142: =INDEX($Q142:$AJ142,1,(BD$4-1)*5+1)+BD$8*INDEX($Q142:$AJ142,1,(BD$4-1)*5+2)*INDEX($Q142:$AJ142,1,(BD$4-1)*5+3) | BE142: =INDEX($Q142:$AJ142,1,(BE$4-1)*5+1)+BE$8*INDEX($Q142:$AJ142,1,(BE$4-1)*5+2)*INDEX($Q142:$AJ142,1,(BE$4-1)*5+3) | BF142: =INDEX($Q142:$AJ142,1,(BF$4-1)*5+1)+BF$8*INDEX($Q142:$AJ142,1,(BF$4-1)*5+2)*INDEX($Q142:$AJ142,1,(BF$4-1)*5+3) | BG142: =INDEX($Q142:$AJ142,1,(BG$4-1)*5+1)+BG$8*INDEX($Q142:$AJ142,1,(BG$4-1)*5+2)*INDEX($Q142:$AJ142,1,(BG$4-1)*5+3) | BH142: =INDEX($Q142:$AJ142,1,(BH$4-1)*5+1)+BH$8*INDEX($Q142:$AJ142,1,(BH$4-1)*5+2)*INDEX($Q142:$AJ142,1,(BH$4-1)*5+3) | ... BN142: =INDEX($Q142:$AJ142,1,(BN$4-1)*5+1)+BN$8*INDEX($Q142:$AJ142,1,(BN$4-1)*5+2)*INDEX($Q142:$AJ142,1,(BN$4-1)*5+3)
B143: gso | C143: rod | D143: Tax | Road | Gasoline | E143: $/GJ | F143: Prices_dom, EF_GHG, Mapping | G143: mit.rp.gso | H143: mit.tax.gso.rod | J143: =INDEX(Mapping!$C$5:$C$20,MATCH($C143,Mapping!$A$5:$A$20,0)) | K143: =INDEX(Mapping!$D$5:$D$20,MATCH($C143,Mapping!$A$5:$A$20,0)) | L143: =INDEX(Mapping!$C$24:$C$31,MATCH($B143,Mapping!$A$24:$A$31,0)) | M143: =INDEX(Mapping!$D$24:$D$31,MATCH($B143,Mapping!$A$24:$A$31,0)) | N143: =$B143&"."&IF(INDEX(Mapping!$E$24:$E$31,MATCH($B143,Mapping!$A$24:$A$31,0))="sub",INDEX(Mapping!$F$5:$F$20,MATCH($C143,Mapping!$A$5:$A$20,0)),"all") | O143: =INDEX(Mapping!$E$5:$E$20,MATCH($C143,Mapping!$A$5:$A$20,0)) | P143: =INDEX(Mapping!$G$24:$G$31,MATCH($B143,Mapping!$A$24:$A$31,0)) | Q143: =(INDEX(Prices_dom!$A$6:$CU$2000,MATCH(Settings!$C$4&Settings!$C$7,Prices_dom!$A$6:$A$2000,0),MATCH("mit.rp."&$N143,Prices_dom!$A$5:$CU$5,0))-INDEX(Prices_dom!$A$6:$CU$2000,MATCH(Settings!$C$4&Settings!$C$7,Prices_dom!$A$6:$A$2000,0),MATCH("mit.sp."&$N143,Prices_dom!$A$5:$CU$5,0)))/$P143 | R143: =INDEX(EF_GHG!$E$4:$E$1000,MATCH(Settings!$C$4&"|"&$B143&"|"&$O143,EF_GHG!$A$4:$A$1000,0)) | S143: =INDEX(Mapping!$G$5:$G$20,MATCH($C143,Mapping!$A$5:$A$20,0)) | V143: =Q143 | W143: =R143 | X143: =S143 | AA143: =Q143 | AB143: =R143 | AC143: =S143 | AF143: =Q143 | AG143: =R143 | AH143: =S143 | AL143: =INDEX($Q143:$AJ143,1,(AL$4-1)*5+1)+AL$8*INDEX($Q143:$AJ143,1,(AL$4-1)*5+2)*INDEX($Q143:$AJ143,1,(AL$4-1)*5+3) | AM143: =INDEX($Q143:$AJ143,1,(AM$4-1)*5+1)+AM$8*INDEX($Q143:$AJ143,1,(AM$4-1)*5+2)*INDEX($Q143:$AJ143,1,(AM$4-1)*5+3) | AN143: =INDEX($Q143:$AJ143,1,(AN$4-1)*5+1)+AN$8*INDEX($Q143:$AJ143,1,(AN$4-1)*5+2)*INDEX($Q143:$AJ143,1,(AN$4-1)*5+3) | AO143: =INDEX($Q143:$AJ143,1,(AO$4-1)*5+1)+AO$8*INDEX($Q143:$AJ143,1,(AO$4-1)*5+2)*INDEX($Q143:$AJ143,1,(AO$4-1)*5+3) | AP143: =INDEX($Q143:$AJ143,1,(AP$4-1)*5+1)+AP$8*INDEX($Q143:$AJ143,1,(AP$4-1)*5+2)*INDEX($Q143:$AJ143,1,(AP$4-1)*5+3) | AQ143: =INDEX($Q143:$AJ143,1,(AQ$4-1)*5+1)+AQ$8*INDEX($Q143:$AJ143,1,(AQ$4-1)*5+2)*INDEX($Q143:$AJ143,1,(AQ$4-1)*5+3) | AR143: =INDEX($Q143:$AJ143,1,(AR$4-1)*5+1)+AR$8*INDEX($Q143:$AJ143,1,(AR$4-1)*5+2)*INDEX($Q143:$AJ143,1,(AR$4-1)*5+3) | AS143: =INDEX($Q143:$AJ143,1,(AS$4-1)*5+1)+AS$8*INDEX($Q143:$AJ143,1,(AS$4-1)*5+2)*INDEX($Q143:$AJ143,1,(AS$4-1)*5+3) | ... AY143: =INDEX($Q143:$AJ143,1,(AY$4-1)*5+1)+AY$8*INDEX($Q143:$AJ143,1,(AY$4-1)*5+2)*INDEX($Q143:$AJ143,1,(AY$4-1)*5+3) | BA143: =INDEX($Q143:$AJ143,1,(BA$4-1)*5+1)+BA$8*INDEX($Q143:$AJ143,1,(BA$4-1)*5+2)*INDEX($Q143:$AJ143,1,(BA$4-1)*5+3) | BB143: =INDEX($Q143:$AJ143,1,(BB$4-1)*5+1)+BB$8*INDEX($Q143:$AJ143,1,(BB$4-1)*5+2)*INDEX($Q143:$AJ143,1,(BB$4-1)*5+3) | BC143: =INDEX($Q143:$AJ143,1,(BC$4-1)*5+1)+BC$8*INDEX($Q143:$AJ143,1,(BC$4-1)*5+2)*INDEX($Q143:$AJ143,1,(BC$4-1)*5+3) | BD143: =INDEX($Q143:$AJ143,1,(BD$4-1)*5+1)+BD$8*INDEX($Q143:$AJ143,1,(BD$4-1)*5+2)*INDEX($Q143:$AJ143,1,(BD$4-1)*5+3) | BE143: =INDEX($Q143:$AJ143,1,(BE$4-1)*5+1)+BE$8*INDEX($Q143:$AJ143,1,(BE$4-1)*5+2)*INDEX($Q143:$AJ143,1,(BE$4-1)*5+3) | BF143: =INDEX($Q143:$AJ143,1,(BF$4-1)*5+1)+BF$8*INDEX($Q143:$AJ143,1,(BF$4-1)*5+2)*INDEX($Q143:$AJ143,1,(BF$4-1)*5+3) | BG143: =INDEX($Q143:$AJ143,1,(BG$4-1)*5+1)+BG$8*INDEX($Q143:$AJ143,1,(BG$4-1)*5+2)*INDEX($Q143:$AJ143,1,(BG$4-1)*5+3) | BH143: =INDEX($Q143:$AJ143,1,(BH$4-1)*5+1)+BH$8*INDEX($Q143:$AJ143,1,(BH$4-1)*5+2)*INDEX($Q143:$AJ143,1,(BH$4-1)*5+3) | ... BN143: =INDEX($Q143:$AJ143,1,(BN$4-1)*5+1)+BN$8*INDEX($Q143:$AJ143,1,(BN$4-1)*5+2)*INDEX($Q143:$AJ143,1,(BN$4-1)*5+3)
B144: die | C144: rod | D144: Tax | Road | Diesel | E144: $/GJ | F144: Prices_dom, EF_GHG, Mapping | G144: mit.rp.die | H144: mit.tax.die.rod | J144: =INDEX(Mapping!$C$5:$C$20,MATCH($C144,Mapping!$A$5:$A$20,0)) | K144: =INDEX(Mapping!$D$5:$D$20,MATCH($C144,Mapping!$A$5:$A$20,0)) | L144: =INDEX(Mapping!$C$24:$C$31,MATCH($B144,Mapping!$A$24:$A$31,0)) | M144: =INDEX(Mapping!$D$24:$D$31,MATCH($B144,Mapping!$A$24:$A$31,0)) | N144: =$B144&"."&IF(INDEX(Mapping!$E$24:$E$31,MATCH($B144,Mapping!$A$24:$A$31,0))="sub",INDEX(Mapping!$F$5:$F$20,MATCH($C144,Mapping!$A$5:$A$20,0)),"all") | O144: =INDEX(Mapping!$E$5:$E$20,MATCH($C144,Mapping!$A$5:$A$20,0)) | P144: =INDEX(Mapping!$G$24:$G$31,MATCH($B144,Mapping!$A$24:$A$31,0)) | Q144: =(INDEX(Prices_dom!$A$6:$CU$2000,MATCH(Settings!$C$4&Settings!$C$7,Prices_dom!$A$6:$A$2000,0),MATCH("mit.rp."&$N144,Prices_dom!$A$5:$CU$5,0))-INDEX(Prices_dom!$A$6:$CU$2000,MATCH(Settings!$C$4&Settings!$C$7,Prices_dom!$A$6:$A$2000,0),MATCH("mit.sp."&$N144,Prices_dom!$A$5:$CU$5,0)))/$P144 | R144: =INDEX(EF_GHG!$E$4:$E$1000,MATCH(Settings!$C$4&"|"&$B144&"|"&$O144,EF_GHG!$A$4:$A$1000,0)) | S144: =INDEX(Mapping!$G$5:$G$20,MATCH($C144,Mapping!$A$5:$A$20,0)) | V144: =Q144 | W144: =R144 | X144: =S144 | AA144: =Q144 | AB144: =R144 | AC144: =S144 | AF144: =Q144 | AG144: =R144 | AH144: =S144 | AL144: =INDEX($Q144:$AJ144,1,(AL$4-1)*5+1)+AL$8*INDEX($Q144:$AJ144,1,(AL$4-1)*5+2)*INDEX($Q144:$AJ144,1,(AL$4-1)*5+3) | AM144: =INDEX($Q144:$AJ144,1,(AM$4-1)*5+1)+AM$8*INDEX($Q144:$AJ144,1,(AM$4-1)*5+2)*INDEX($Q144:$AJ144,1,(AM$4-1)*5+3) | AN144: =INDEX($Q144:$AJ144,1,(AN$4-1)*5+1)+AN$8*INDEX($Q144:$AJ144,1,(AN$4-1)*5+2)*INDEX($Q144:$AJ144,1,(AN$4-1)*5+3) | AO144: =INDEX($Q144:$AJ144,1,(AO$4-1)*5+1)+AO$8*INDEX($Q144:$AJ144,1,(AO$4-1)*5+2)*INDEX($Q144:$AJ144,1,(AO$4-1)*5+3) | AP144: =INDEX($Q144:$AJ144,1,(AP$4-1)*5+1)+AP$8*INDEX($Q144:$AJ144,1,(AP$4-1)*5+2)*INDEX($Q144:$AJ144,1,(AP$4-1)*5+3) | AQ144: =INDEX($Q144:$AJ144,1,(AQ$4-1)*5+1)+AQ$8*INDEX($Q144:$AJ144,1,(AQ$4-1)*5+2)*INDEX($Q144:$AJ144,1,(AQ$4-1)*5+3) | AR144: =INDEX($Q144:$AJ144,1,(AR$4-1)*5+1)+AR$8*INDEX($Q144:$AJ144,1,(AR$4-1)*5+2)*INDEX($Q144:$AJ144,1,(AR$4-1)*5+3) | AS144: =INDEX($Q144:$AJ144,1,(AS$4-1)*5+1)+AS$8*INDEX($Q144:$AJ144,1,(AS$4-1)*5+2)*INDEX($Q144:$AJ144,1,(AS$4-1)*5+3) | ... AY144: =INDEX($Q144:$AJ144,1,(AY$4-1)*5+1)+AY$8*INDEX($Q144:$AJ144,1,(AY$4-1)*5+2)*INDEX($Q144:$AJ144,1,(AY$4-1)*5+3) | BA144: =INDEX($Q144:$AJ144,1,(BA$4-1)*5+1)+BA$8*INDEX($Q144:$AJ144,1,(BA$4-1)*5+2)*INDEX($Q144:$AJ144,1,(BA$4-1)*5+3) | BB144: =INDEX($Q144:$AJ144,1,(BB$4-1)*5+1)+BB$8*INDEX($Q144:$AJ144,1,(BB$4-1)*5+2)*INDEX($Q144:$AJ144,1,(BB$4-1)*5+3) | BC144: =INDEX($Q144:$AJ144,1,(BC$4-1)*5+1)+BC$8*INDEX($Q144:$AJ144,1,(BC$4-1)*5+2)*INDEX($Q144:$AJ144,1,(BC$4-1)*5+3) | BD144: =INDEX($Q144:$AJ144,1,(BD$4-1)*5+1)+BD$8*INDEX($Q144:$AJ144,1,(BD$4-1)*5+2)*INDEX($Q144:$AJ144,1,(BD$4-1)*5+3) | BE144: =INDEX($Q144:$AJ144,1,(BE$4-1)*5+1)+BE$8*INDEX($Q144:$AJ144,1,(BE$4-1)*5+2)*INDEX($Q144:$AJ144,1,(BE$4-1)*5+3) | BF144: =INDEX($Q144:$AJ144,1,(BF$4-1)*5+1)+BF$8*INDEX($Q144:$AJ144,1,(BF$4-1)*5+2)*INDEX($Q144:$AJ144,1,(BF$4-1)*5+3) | BG144: =INDEX($Q144:$AJ144,1,(BG$4-1)*5+1)+BG$8*INDEX($Q144:$AJ144,1,(BG$4-1)*5+2)*INDEX($Q144:$AJ144,1,(BG$4-1)*5+3) | BH144: =INDEX($Q144:$AJ144,1,(BH$4-1)*5+1)+BH$8*INDEX($Q144:$AJ144,1,(BH$4-1)*5+2)*INDEX($Q144:$AJ144,1,(BH$4-1)*5+3) | ... BN144: =INDEX($Q144:$AJ144,1,(BN$4-1)*5+1)+BN$8*INDEX($Q144:$AJ144,1,(BN$4-1)*5+2)*INDEX($Q144:$AJ144,1,(BN$4-1)*5+3)
B145: lpg | C145: rod | D145: Tax | Road | LPG | E145: $/GJ | F145: Prices_dom, EF_GHG, Mapping | G145: mit.rp.lpg | H145: mit.tax.lpg.rod | J145: =INDEX(Mapping!$C$5:$C$20,MATCH($C145,Mapping!$A$5:$A$20,0)) | K145: =INDEX(Mapping!$D$5:$D$20,MATCH($C145,Mapping!$A$5:$A$20,0)) | L145: =INDEX(Mapping!$C$24:$C$31,MATCH($B145,Mapping!$A$24:$A$31,0)) | M145: =INDEX(Mapping!$D$24:$D$31,MATCH($B145,Mapping!$A$24:$A$31,0)) | N145: =$B145&"."&IF(INDEX(Mapping!$E$24:$E$31,MATCH($B145,Mapping!$A$24:$A$31,0))="sub",INDEX(Mapping!$F$5:$F$20,MATCH($C145,Mapping!$A$5:$A$20,0)),"all") | O145: =INDEX(Mapping!$E$5:$E$20,MATCH($C145,Mapping!$A$5:$A$20,0)) | P145: =INDEX(Mapping!$G$24:$G$31,MATCH($B145,Mapping!$A$24:$A$31,0)) | Q145: =(INDEX(Prices_dom!$A$6:$CU$2000,MATCH(Settings!$C$4&Settings!$C$7,Prices_dom!$A$6:$A$2000,0),MATCH("mit.rp."&$N145,Prices_dom!$A$5:$CU$5,0))-INDEX(Prices_dom!$A$6:$CU$2000,MATCH(Settings!$C$4&Settings!$C$7,Prices_dom!$A$6:$A$2000,0),MATCH("mit.sp."&$N145,Prices_dom!$A$5:$CU$5,0)))/$P145 | R145: =INDEX(EF_GHG!$E$4:$E$1000,MATCH(Settings!$C$4&"|"&$B145&"|"&$O145,EF_GHG!$A$4:$A$1000,0)) | S145: =INDEX(Mapping!$G$5:$G$20,MATCH($C145,Mapping!$A$5:$A$20,0)) | V145: =Q145 | W145: =R145 | X145: =S145 | AA145: =Q145 | AB145: =R145 | AC145: =S145 | AF145: =Q145 | AG145: =R145 | AH145: =S145 | AL145: =INDEX($Q145:$AJ145,1,(AL$4-1)*5+1)+AL$8*INDEX($Q145:$AJ145,1,(AL$4-1)*5+2)*INDEX($Q145:$AJ145,1,(AL$4-1)*5+3) | AM145: =INDEX($Q145:$AJ145,1,(AM$4-1)*5+1)+AM$8*INDEX($Q145:$AJ145,1,(AM$4-1)*5+2)*INDEX($Q145:$AJ145,1,(AM$4-1)*5+3) | AN145: =INDEX($Q145:$AJ145,1,(AN$4-1)*5+1)+AN$8*INDEX($Q145:$AJ145,1,(AN$4-1)*5+2)*INDEX($Q145:$AJ145,1,(AN$4-1)*5+3) | AO145: =INDEX($Q145:$AJ145,1,(AO$4-1)*5+1)+AO$8*INDEX($Q145:$AJ145,1,(AO$4-1)*5+2)*INDEX($Q145:$AJ145,1,(AO$4-1)*5+3) | AP145: =INDEX($Q145:$AJ145,1,(AP$4-1)*5+1)+AP$8*INDEX($Q145:$AJ145,1,(AP$4-1)*5+2)*INDEX($Q145:$AJ145,1,(AP$4-1)*5+3) | AQ145: =INDEX($Q145:$AJ145,1,(AQ$4-1)*5+1)+AQ$8*INDEX($Q145:$AJ145,1,(AQ$4-1)*5+2)*INDEX($Q145:$AJ145,1,(AQ$4-1)*5+3) | AR145: =INDEX($Q145:$AJ145,1,(AR$4-1)*5+1)+AR$8*INDEX($Q145:$AJ145,1,(AR$4-1)*5+2)*INDEX($Q145:$AJ145,1,(AR$4-1)*5+3) | AS145: =INDEX($Q145:$AJ145,1,(AS$4-1)*5+1)+AS$8*INDEX($Q145:$AJ145,1,(AS$4-1)*5+2)*INDEX($Q145:$AJ145,1,(AS$4-1)*5+3) | ... AY145: =INDEX($Q145:$AJ145,1,(AY$4-1)*5+1)+AY$8*INDEX($Q145:$AJ145,1,(AY$4-1)*5+2)*INDEX($Q145:$AJ145,1,(AY$4-1)*5+3) | BA145: =INDEX($Q145:$AJ145,1,(BA$4-1)*5+1)+BA$8*INDEX($Q145:$AJ145,1,(BA$4-1)*5+2)*INDEX($Q145:$AJ145,1,(BA$4-1)*5+3) | BB145: =INDEX($Q145:$AJ145,1,(BB$4-1)*5+1)+BB$8*INDEX($Q145:$AJ145,1,(BB$4-1)*5+2)*INDEX($Q145:$AJ145,1,(BB$4-1)*5+3) | BC145: =INDEX($Q145:$AJ145,1,(BC$4-1)*5+1)+BC$8*INDEX($Q145:$AJ145,1,(BC$4-1)*5+2)*INDEX($Q145:$AJ145,1,(BC$4-1)*5+3) | BD145: =INDEX($Q145:$AJ145,1,(BD$4-1)*5+1)+BD$8*INDEX($Q145:$AJ145,1,(BD$4-1)*5+2)*INDEX($Q145:$AJ145,1,(BD$4-1)*5+3) | BE145: =INDEX($Q145:$AJ145,1,(BE$4-1)*5+1)+BE$8*INDEX($Q145:$AJ145,1,(BE$4-1)*5+2)*INDEX($Q145:$AJ145,1,(BE$4-1)*5+3) | BF145: =INDEX($Q145:$AJ145,1,(BF$4-1)*5+1)+BF$8*INDEX($Q145:$AJ145,1,(BF$4-1)*5+2)*INDEX($Q145:$AJ145,1,(BF$4-1)*5+3) | BG145: =INDEX($Q145:$AJ145,1,(BG$4-1)*5+1)+BG$8*INDEX($Q145:$AJ145,1,(BG$4-1)*5+2)*INDEX($Q145:$AJ145,1,(BG$4-1)*5+3) | BH145: =INDEX($Q145:$AJ145,1,(BH$4-1)*5+1)+BH$8*INDEX($Q145:$AJ145,1,(BH$4-1)*5+2)*INDEX($Q145:$AJ145,1,(BH$4-1)*5+3) | ... BN145: =INDEX($Q145:$AJ145,1,(BN$4-1)*5+1)+BN$8*INDEX($Q145:$AJ145,1,(BN$4-1)*5+2)*INDEX($Q145:$AJ145,1,(BN$4-1)*5+3)
B146: ker | C146: rod | D146: Tax | Road | Kerosene | E146: $/GJ | F146: Prices_dom, EF_GHG, Mapping | G146: mit.rp.ker | H146: mit.tax.ker.rod | J146: =INDEX(Mapping!$C$5:$C$20,MATCH($C146,Mapping!$A$5:$A$20,0)) | K146: =INDEX(Mapping!$D$5:$D$20,MATCH($C146,Mapping!$A$5:$A$20,0)) | L146: =INDEX(Mapping!$C$24:$C$31,MATCH($B146,Mapping!$A$24:$A$31,0)) | M146: =INDEX(Mapping!$D$24:$D$31,MATCH($B146,Mapping!$A$24:$A$31,0)) | N146: =$B146&"."&IF(INDEX(Mapping!$E$24:$E$31,MATCH($B146,Mapping!$A$24:$A$31,0))="sub",INDEX(Mapping!$F$5:$F$20,MATCH($C146,Mapping!$A$5:$A$20,0)),"all") | O146: =INDEX(Mapping!$E$5:$E$20,MATCH($C146,Mapping!$A$5:$A$20,0)) | P146: =INDEX(Mapping!$G$24:$G$31,MATCH($B146,Mapping!$A$24:$A$31,0)) | Q146: =(INDEX(Prices_dom!$A$6:$CU$2000,MATCH(Settings!$C$4&Settings!$C$7,Prices_dom!$A$6:$A$2000,0),MATCH("mit.rp."&$N146,Prices_dom!$A$5:$CU$5,0))-INDEX(Prices_dom!$A$6:$CU$2000,MATCH(Settings!$C$4&Settings!$C$7,Prices_dom!$A$6:$A$2000,0),MATCH("mit.sp."&$N146,Prices_dom!$A$5:$CU$5,0)))/$P146 | R146: =INDEX(EF_GHG!$E$4:$E$1000,MATCH(Settings!$C$4&"|"&$B146&"|"&$O146,EF_GHG!$A$4:$A$1000,0)) | S146: =INDEX(Mapping!$G$5:$G$20,MATCH($C146,Mapping!$A$5:$A$20,0)) | V146: =Q146 | W146: =R146 | X146: =S146 | AA146: =Q146 | AB146: =R146 | AC146: =S146 | AF146: =Q146 | AG146: =R146 | AH146: =S146 | AL146: =INDEX($Q146:$AJ146,1,(AL$4-1)*5+1)+AL$8*INDEX($Q146:$AJ146,1,(AL$4-1)*5+2)*INDEX($Q146:$AJ146,1,(AL$4-1)*5+3) | AM146: =INDEX($Q146:$AJ146,1,(AM$4-1)*5+1)+AM$8*INDEX($Q146:$AJ146,1,(AM$4-1)*5+2)*INDEX($Q146:$AJ146,1,(AM$4-1)*5+3) | AN146: =INDEX($Q146:$AJ146,1,(AN$4-1)*5+1)+AN$8*INDEX($Q146:$AJ146,1,(AN$4-1)*5+2)*INDEX($Q146:$AJ146,1,(AN$4-1)*5+3) | AO146: =INDEX($Q146:$AJ146,1,(AO$4-1)*5+1)+AO$8*INDEX($Q146:$AJ146,1,(AO$4-1)*5+2)*INDEX($Q146:$AJ146,1,(AO$4-1)*5+3) | AP146: =INDEX($Q146:$AJ146,1,(AP$4-1)*5+1)+AP$8*INDEX($Q146:$AJ146,1,(AP$4-1)*5+2)*INDEX($Q146:$AJ146,1,(AP$4-1)*5+3) | AQ146: =INDEX($Q146:$AJ146,1,(AQ$4-1)*5+1)+AQ$8*INDEX($Q146:$AJ146,1,(AQ$4-1)*5+2)*INDEX($Q146:$AJ146,1,(AQ$4-1)*5+3) | AR146: =INDEX($Q146:$AJ146,1,(AR$4-1)*5+1)+AR$8*INDEX($Q146:$AJ146,1,(AR$4-1)*5+2)*INDEX($Q146:$AJ146,1,(AR$4-1)*5+3) | AS146: =INDEX($Q146:$AJ146,1,(AS$4-1)*5+1)+AS$8*INDEX($Q146:$AJ146,1,(AS$4-1)*5+2)*INDEX($Q146:$AJ146,1,(AS$4-1)*5+3) | ... AY146: =INDEX($Q146:$AJ146,1,(AY$4-1)*5+1)+AY$8*INDEX($Q146:$AJ146,1,(AY$4-1)*5+2)*INDEX($Q146:$AJ146,1,(AY$4-1)*5+3) | BA146: =INDEX($Q146:$AJ146,1,(BA$4-1)*5+1)+BA$8*INDEX($Q146:$AJ146,1,(BA$4-1)*5+2)*INDEX($Q146:$AJ146,1,(BA$4-1)*5+3) | BB146: =INDEX($Q146:$AJ146,1,(BB$4-1)*5+1)+BB$8*INDEX($Q146:$AJ146,1,(BB$4-1)*5+2)*INDEX($Q146:$AJ146,1,(BB$4-1)*5+3) | BC146: =INDEX($Q146:$AJ146,1,(BC$4-1)*5+1)+BC$8*INDEX($Q146:$AJ146,1,(BC$4-1)*5+2)*INDEX($Q146:$AJ146,1,(BC$4-1)*5+3) | BD146: =INDEX($Q146:$AJ146,1,(BD$4-1)*5+1)+BD$8*INDEX($Q146:$AJ146,1,(BD$4-1)*5+2)*INDEX($Q146:$AJ146,1,(BD$4-1)*5+3) | BE146: =INDEX($Q146:$AJ146,1,(BE$4-1)*5+1)+BE$8*INDEX($Q146:$AJ146,1,(BE$4-1)*5+2)*INDEX($Q146:$AJ146,1,(BE$4-1)*5+3) | BF146: =INDEX($Q146:$AJ146,1,(BF$4-1)*5+1)+BF$8*INDEX($Q146:$AJ146,1,(BF$4-1)*5+2)*INDEX($Q146:$AJ146,1,(BF$4-1)*5+3) | BG146: =INDEX($Q146:$AJ146,1,(BG$4-1)*5+1)+BG$8*INDEX($Q146:$AJ146,1,(BG$4-1)*5+2)*INDEX($Q146:$AJ146,1,(BG$4-1)*5+3) | BH146: =INDEX($Q146:$AJ146,1,(BH$4-1)*5+1)+BH$8*INDEX($Q146:$AJ146,1,(BH$4-1)*5+2)*INDEX($Q146:$AJ146,1,(BH$4-1)*5+3) | ... BN146: =INDEX($Q146:$AJ146,1,(BN$4-1)*5+1)+BN$8*INDEX($Q146:$AJ146,1,(BN$4-1)*5+2)*INDEX($Q146:$AJ146,1,(BN$4-1)*5+3)
B147: oop | C147: rod | D147: Tax | Road | Other oil products | E147: $/GJ | F147: Prices_dom, EF_GHG, Mapping | G147: mit.rp.oop | H147: mit.tax.oop.rod | J147: =INDEX(Mapping!$C$5:$C$20,MATCH($C147,Mapping!$A$5:$A$20,0)) | K147: =INDEX(Mapping!$D$5:$D$20,MATCH($C147,Mapping!$A$5:$A$20,0)) | L147: =INDEX(Mapping!$C$24:$C$31,MATCH($B147,Mapping!$A$24:$A$31,0)) | M147: =INDEX(Mapping!$D$24:$D$31,MATCH($B147,Mapping!$A$24:$A$31,0)) | N147: =$B147&"."&IF(INDEX(Mapping!$E$24:$E$31,MATCH($B147,Mapping!$A$24:$A$31,0))="sub",INDEX(Mapping!$F$5:$F$20,MATCH($C147,Mapping!$A$5:$A$20,0)),"all") | O147: =INDEX(Mapping!$E$5:$E$20,MATCH($C147,Mapping!$A$5:$A$20,0)) | P147: =INDEX(Mapping!$G$24:$G$31,MATCH($B147,Mapping!$A$24:$A$31,0)) | Q147: =(INDEX(Prices_dom!$A$6:$CU$2000,MATCH(Settings!$C$4&Settings!$C$7,Prices_dom!$A$6:$A$2000,0),MATCH("mit.rp."&$N147,Prices_dom!$A$5:$CU$5,0))-INDEX(Prices_dom!$A$6:$CU$2000,MATCH(Settings!$C$4&Settings!$C$7,Prices_dom!$A$6:$A$2000,0),MATCH("mit.sp."&$N147,Prices_dom!$A$5:$CU$5,0)))/$P147 | R147: =INDEX(EF_GHG!$E$4:$E$1000,MATCH(Settings!$C$4&"|"&$B147&"|"&$O147,EF_GHG!$A$4:$A$1000,0)) | S147: =INDEX(Mapping!$G$5:$G$20,MATCH($C147,Mapping!$A$5:$A$20,0)) | V147: =Q147 | W147: =R147 | X147: =S147 | AA147: =Q147 | AB147: =R147 | AC147: =S147 | AF147: =Q147 | AG147: =R147 | AH147: =S147 | AL147: =INDEX($Q147:$AJ147,1,(AL$4-1)*5+1)+AL$8*INDEX($Q147:$AJ147,1,(AL$4-1)*5+2)*INDEX($Q147:$AJ147,1,(AL$4-1)*5+3) | AM147: =INDEX($Q147:$AJ147,1,(AM$4-1)*5+1)+AM$8*INDEX($Q147:$AJ147,1,(AM$4-1)*5+2)*INDEX($Q147:$AJ147,1,(AM$4-1)*5+3) | AN147: =INDEX($Q147:$AJ147,1,(AN$4-1)*5+1)+AN$8*INDEX($Q147:$AJ147,1,(AN$4-1)*5+2)*INDEX($Q147:$AJ147,1,(AN$4-1)*5+3) | AO147: =INDEX($Q147:$AJ147,1,(AO$4-1)*5+1)+AO$8*INDEX($Q147:$AJ147,1,(AO$4-1)*5+2)*INDEX($Q147:$AJ147,1,(AO$4-1)*5+3) | AP147: =INDEX($Q147:$AJ147,1,(AP$4-1)*5+1)+AP$8*INDEX($Q147:$AJ147,1,(AP$4-1)*5+2)*INDEX($Q147:$AJ147,1,(AP$4-1)*5+3) | AQ147: =INDEX($Q147:$AJ147,1,(AQ$4-1)*5+1)+AQ$8*INDEX($Q147:$AJ147,1,(AQ$4-1)*5+2)*INDEX($Q147:$AJ147,1,(AQ$4-1)*5+3) | AR147: =INDEX($Q147:$AJ147,1,(AR$4-1)*5+1)+AR$8*INDEX($Q147:$AJ147,1,(AR$4-1)*5+2)*INDEX($Q147:$AJ147,1,(AR$4-1)*5+3) | AS147: =INDEX($Q147:$AJ147,1,(AS$4-1)*5+1)+AS$8*INDEX($Q147:$AJ147,1,(AS$4-1)*5+2)*INDEX($Q147:$AJ147,1,(AS$4-1)*5+3) | ... AY147: =INDEX($Q147:$AJ147,1,(AY$4-1)*5+1)+AY$8*INDEX($Q147:$AJ147,1,(AY$4-1)*5+2)*INDEX($Q147:$AJ147,1,(AY$4-1)*5+3) | BA147: =INDEX($Q147:$AJ147,1,(BA$4-1)*5+1)+BA$8*INDEX($Q147:$AJ147,1,(BA$4-1)*5+2)*INDEX($Q147:$AJ147,1,(BA$4-1)*5+3) | BB147: =INDEX($Q147:$AJ147,1,(BB$4-1)*5+1)+BB$8*INDEX($Q147:$AJ147,1,(BB$4-1)*5+2)*INDEX($Q147:$AJ147,1,(BB$4-1)*5+3) | BC147: =INDEX($Q147:$AJ147,1,(BC$4-1)*5+1)+BC$8*INDEX($Q147:$AJ147,1,(BC$4-1)*5+2)*INDEX($Q147:$AJ147,1,(BC$4-1)*5+3) | BD147: =INDEX($Q147:$AJ147,1,(BD$4-1)*5+1)+BD$8*INDEX($Q147:$AJ147,1,(BD$4-1)*5+2)*INDEX($Q147:$AJ147,1,(BD$4-1)*5+3) | BE147: =INDEX($Q147:$AJ147,1,(BE$4-1)*5+1)+BE$8*INDEX($Q147:$AJ147,1,(BE$4-1)*5+2)*INDEX($Q147:$AJ147,1,(BE$4-1)*5+3) | BF147: =INDEX($Q147:$AJ147,1,(BF$4-1)*5+1)+BF$8*INDEX($Q147:$AJ147,1,(BF$4-1)*5+2)*INDEX($Q147:$AJ147,1,(BF$4-1)*5+3) | BG147: =INDEX($Q147:$AJ147,1,(BG$4-1)*5+1)+BG$8*INDEX($Q147:$AJ147,1,(BG$4-1)*5+2)*INDEX($Q147:$AJ147,1,(BG$4-1)*5+3) | BH147: =INDEX($Q147:$AJ147,1,(BH$4-1)*5+1)+BH$8*INDEX($Q147:$AJ147,1,(BH$4-1)*5+2)*INDEX($Q147:$AJ147,1,(BH$4-1)*5+3) | ... BN147: =INDEX($Q147:$AJ147,1,(BN$4-1)*5+1)+BN$8*INDEX($Q147:$AJ147,1,(BN$4-1)*5+2)*INDEX($Q147:$AJ147,1,(BN$4-1)*5+3)
