Workbook
Name ETSPRICE: _xlfn.LAMBDA(_xlpm.apply,_xlpm.year,_xlpm.start_year,_xlpm.carbon_price,IF(AND(LEFT(_xlpm.apply,3)="Yes",_xlpm.year>=_xlpm.start_year),_xlpm.carbon_price,0))
Name ETSCOVER: _xlfn.LAMBDA(_xlpm.apply,_xlpm.year,_xlpm.start_year,_xlpm.covered,IF(AND(LEFT(_xlpm.apply,3)="Yes",_xlpm.year>=_xlpm.start_year),IF(_xlpm.covered,1,0),0))
Name SHADOWSECTOR: _xlfn.LAMBDA(_xlpm.feebate,_xlpm.regulation,_xlpm.feebate+_xlpm.regulation)
Name SHADOWSHARE: _xlfn.LAMBDA(_xlpm.coverage,_xlpm.adjustment,IF(_xlpm.coverage,1,0)*_xlpm.adjustment)
Name RETAILPRICE: _xlfn.LAMBDA(_xlpm.sp,_xlpm.txo,_xlpm.vat_rate,(_xlpm.sp+_xlpm.txo)*(1+_xlpm.vat_rate))
Name VATPAY: _xlfn.LAMBDA(_xlpm.sp,_xlpm.txo,_xlpm.vat_rate,(_xlpm.sp+_xlpm.txo)*_xlpm.vat_rate)
Name TAXPART: _xlfn.LAMBDA(_xlpm.txo,MAX(_xlpm.txo,0))
Name SUBSIDYPART: _xlfn.LAMBDA(_xlpm.txo,MAX(-_xlpm.txo,0))
Name PERUNIT: _xlfn.LAMBDA(_xlpm.value_gj,_xlpm.gj_per_unit,_xlpm.value_gj*_xlpm.gj_per_unit)
Name CARBONTAX: _xlfn.LAMBDA(_xlpm.price,_xlpm.ef,_xlpm.fuel_cov,_xlpm.sector_cov,_xlpm.ets_cov,_xlpm.price*_xlpm.ef*_xlpm.fuel_cov*_xlpm.sector_cov*(1-_xlpm.ets_cov))
Name ETSCOST: _xlfn.LAMBDA(_xlpm.price,_xlpm.ef,_xlpm.ets_cov,_xlpm.price*_xlpm.ef*_xlpm.ets_cov)
Name NEWEXCISE: _xlfn.LAMBDA(_xlpm.increase,_xlpm.gj_per_unit,_xlpm.increase/_xlpm.gj_per_unit)
Name NEWPOLICY: _xlfn.LAMBDA(_xlpm.carbon_tax,_xlpm.ets,_xlpm.excise,_xlpm.carbon_tax+_xlpm.ets+_xlpm.excise)
Name POSTTAX: _xlfn.LAMBDA(_xlpm.pre_policy_p,_xlpm.new_policy,_xlpm.vat_rate,MAX(_xlpm.pre_policy_p+_xlpm.new_policy*(1+_xlpm.vat_rate),0.01))
Name SHADOWEFF: _xlfn.LAMBDA(_xlpm.sector_price,_xlpm.ef,_xlpm.share,_xlpm.sector_price*_xlpm.ef*_xlpm.share)

Sheet ReadMe
A2: CPAT mitigation module - copy-pasteable prototype v0.11
A4: Purpose | B4: Auditable, copy-pasteable replacement of the CPAT mitigation price -> fuel-use chain. Each variable has one formula across all subsectors, fuels and years, and a whole scenario group copies to a new scenario and keeps working.
A5: Status | B5: v0.11 prototype to 2040: policies (carbon tax, new ETS, fuel price reform, feebates with sectoral shadow prices), domestic prices with existing taxes and subsidies, and price -> fuel use for transport, buildings, industry and other energy use. Revenues prepared (section 12). Power, electricity prices and emissions not yet. Differences with legacy: sheet LegacyDiff.
A6: Layout (as legacy CPAT) | B6: Sections: 1. Policies (row 11), 2. Retail energy prices (row 197), 3. Power sector (row 298, placeholder), 5. Transport (row 301), 6. Buildings (row 560), 7. Industrial (row 755), 8. Other energy use (row 1270), 11. Results - energy consumption (row 1337). Numbers follow the legacy Mitigation sheet.
A7: Nesting | B7: Across: scenario (outer) > year (inner). Down: sector section > subsector > variable > fuel. Each subsector: a heading line (its total fuel use), then ctxnew, ets, ntx, nce, atp, shp, ener, each over the 8 fuels with one blank row (64 rows per subsector). Section 2: sp, txo, rpb over the 12 price fuels (coal and gas x power / residential / industry; gasoline, diesel, LPG, kerosene, other oil products, biomass for all sectors).
A8: ASSUMPTIONS: units | B8: All prices, taxes and policy values are in REAL US DOLLARS OF THE RESULTS YEAR (MTInputs ResultsYear, 2026; Settings C8), per GJ. There is no inflation after the conversion: a constant real price is a constant number. Fuel use is in ktoe.
A9: ASSUMPTIONS: two indices | B9: Row 8 infl = US CPI(ResultsYear) / US CPI(year) converts nominal DOMESTIC data (IMF price dataset: supply cost, taxes, retail price, margin, production cost) and nominal policy inputs. Row 9 defl = US GDP deflator(ResultsYear) / deflator(year) converts nominal INTERNATIONAL prices (legacy uses the deflator there). The two differ by up to 1.2% before 2030 (2022: 1.137 vs 1.124), so both are kept. The CPI is held flat after 2031 in the legacy data (WEO horizon); results after 2030 are not compared with legacy.
A10: ASSUMPTIONS: inputs | B10: Domestic price data are nominal USD of their year -> x infl of that year. International prices are nominal -> x defl; only their year-on-year ratios move the supply cost, so their units and level drop out. MTInputs policy values are REAL (ResultsYear USD): carbon price, feebate rates and fuel price reform increases. Only the carbon price has a switch: NomorReal = Nominal makes it nominal, then x infl (legacy row 2249). Margins and production costs are base-year (2022) nominal values -> x infl(2022), held constant in real terms.
A11: ASSUMPTIONS: history | B11: Years up to the last historical price year (Settings C10, 2024) take prices from data (Inputs_prices); later years are projected. Base-year (2022) fuel use is data; fuel use from 2023 on is modelled with these prices (also in 2023-2024).
A12: ASSUMPTIONS: global vs scenario | B12: Global (Settings, from MTInputs scenario 1): ResultsYear, government price controls (pass-through), last historical year, gas market of the country. Per scenario (MTInputs column): international price source and adjustment, carbon price and its nominal/real switch, fuel price reform, feebates, coverage.
A13: ASSUMPTIONS: legacy quirk | B13: Legacy rule kept: with pass-through 0.5 or 0.8 txo jumps in the first projected year. See PriceProjection_Method_v0.3.md.
A14: ASSUMPTIONS: DATA CHANGED (v0.10) | B14: Bright yellow cells with red text in Inputs_prices: (1) other oil products take pass-through and margin from the dataset like the other oil products (legacy hardcodes 1 and 0, which drove their retail price to the 0.01 floor); (2) VAT rate: dataset rate where filled, else the general VAT rate VAT_WEO (Egypt 14%) for residential coal and gas and all-sector oil products; power, industry and biomass 0. New policies pay this VAT.
A15: Price projection | B15: gp = international price (source, gas market, High/Low factor after the last historical year). sp = fixsp + (sp(t-1) - fixsp) x gp(t) / gp(t-1), fixsp = margin + pass-through x production cost (coal, gas). txo = txo_L x pcc + cs, cs = (sp_L - sp + txo_L(1 - pcc)) x (1 - pcc), not below txo_L(1 - pcc) if that is >= 0. rpb = (sp + txo) x (1 + VAT rate). atp = max(rpb + nce x (1 + VAT rate), 0.01): new policies are fully passed through and pay VAT. Pass-through 0 keeps rpb at its last historical value (Egypt gas and oil products); 1 passes supply-cost changes on in full.
... A27: Data | B27: Countries, Elasticities, Prices_dom, Prices_int, PriceAssump, EnergyCons, WEO, EF_GHG; Mapping; Variables; MTInputs. Built by build_v0_11.py; checked by check_v0_11.py.

Sheet LegacyDiff
A2: Differences with legacy CPAT (decisions, assumptions, simplifications, not yet modelled)
A3: Keep this list current with each version. Type: Decision = user decision; Assumption = data assumption (bright yellow in Inputs_prices); Simplification; Not yet; Data; Design; Same.
A4: # | B4: Area | C4: Legacy CPAT | D4: This model | E4: Why | F4: Effect | G4: Type
A5: 1 | B5: Elasticities: food & forestry | C5: Industry elasticities (cpat_coded EC_SECTORS) | D5: Services (buildings) elasticities | E5: User decision v0.11; legacy groups food & forestry with services as Commercial | F5: Food & forestry fuel response | G5: Decision
A6: 2 | B6: Other oil products: pass-through and margin | C6: Hardcoded 1 and 0 | D6: From the IMF dataset like the other oil products (Egypt 0 and 7.95 $/bbl) | E6: User decision v0.10: the legacy rule drove the retail price to the 0.01 floor and fuel use 10x by 2030 | F6: Large: other oil products, total fuel use | G6: Decision
A7: 3 | B7: VAT rate where the dataset is blank | C7: 0 | D7: General VAT rate VAT_WEO (Egypt 14%) for residential coal and gas and all-sector oil products; 0 for power, industry, biomass | E7: User decision v0.10; matches the retail prices in the Egypt dataset | F7: Historical oil-product retail prices +14%; VAT on new policies | G7: Assumption
A8: 4 | B8: Oil-product share in the VAT of transport fuels | C8: VAT rate x oil-product share | D8: Share = 1 | E8: Not yet extracted | F8: None for Egypt today | G8: Simplification
A9: 5 | B9: New ETS price | C9: Endogenous: cap relative to baseline emissions (MTInputs 85-87) | D9: Carbon price inputs (cptraj) once the ETS applies; replaces the carbon tax in ETS-covered sectors | E9: User decision v0.11: ETS as effective as a carbon tax; emissions not yet modelled | F9: ETS scenarios | G9: Simplification
A10: 6 | B10: ETS free allocation | C10: Non-auctioned share can act as a shadow price | D10: Full permit price in the retail price; auction share only for revenue | E10: As effective as a carbon tax (marginal incentive unchanged) | F10: Price level in ETS sectors; revenue | G10: Simplification
A11: 7 | B11: Existing ETS and existing carbon taxes | C11: Included where they exist | D11: Not modelled | E11: None for Egypt | F11: Other countries | G11: Not yet
A12: 8 | B12: Sectoral shadow prices | C12: Feebates + non-auctioned ETS + regulations | D12: Feebates + regulations (placeholder 0) | E12: Regulations not yet; ETS in the price | F12: Regulation scenarios | G12: Not yet
A13: 9 | B13: Policy paths after the target year | C13: Per instrument (carbon price: MTInputs switch) | D13: Linear continuation for fuel price reform and feebates; carbon price keeps the switch; ETS auction share constant | E13: User decision v0.8 (one default) | F13: Post-target years | G13: Decision
A14: 10 | B14: Feebate grouping | C14: Main grouping (buildings = residential rate) | D14: Same: food & forestry and services take the residential rate; other energy use the industry rate | E14: User decision v0.8 | F14: None | G14: Same
A15: 11 | B15: Biomass carbon-tax coverage | C15: No switch | D15: TRUE (EF 0) | E15: User decision v0.8 | F15: None | G15: Decision
A16: 12 | B16: Margins and production costs | C16: cpat_coded applies no inflation conversion | D16: x CPI index of the base year | E16: Consistent real terms (assumption A4) | F16: Coal and gas supply cost level | G16: To check (bucket 5)
... A25: 21 | B25: Formula structure | C25: Different formulas by block and year | D25: One formula per variable block; LAMBDA in the right column (2040) with the history/projection IF inside | E25: Auditability and copy-paste | F25: None (numerically identical) | G25: Design

Sheet Settings
A2: Settings
B4: Country code | C4: EGY
B5: Country name | C5: =INDEX(Countries!$B$4:$B$1000,MATCH($C$4,Countries!$A$4:$A$1000,0))
B6: Income group (selects elasticities) | C6: =INDEX(Countries!$D$4:$D$1000,MATCH($C$4,Countries!$A$4:$A$1000,0))
B7: Base year | C7: 2022
B8: Results in real USD of year (MTInputs ResultsYear, scenario 1) | C8: =INDEX(MTInputs!$J$8:$J$415,MATCH("ResultsYear",MTInputs!$H$8:$H$415,0))
B9: Government energy price controls (MTInputs GovPriceControls, scenario 1) | C9: =INDEX(MTInputs!$J$8:$J$415,MATCH("GovPriceControls",MTInputs!$H$8:$H$415,0))
B10: Last historical price year (IMF price dataset) | C10: 2024
B11: Gas market (PriceAssump, by country name) | C11: =INDEX(PriceAssump!$C$4:$C$400,MATCH($C$5,PriceAssump!$A$4:$A$400,0))
B12: Gas price commodity key (Prices_int) | C12: =IF($C$11="LNG","lng",IF($C$11="Europe","eur",IF($C$11="North Am","nam","glo")))
B15: Version log
B16: Version | C16: Date | D16: Description | E16: Max abs regression diff
B17: 0.1 | C17: 2026-10-08 | D17: First build: design 2 price -> fuel-use prototype, Egypt base data, 2 scenarios. | E17: n/a (first version)
B18: 0.2 | C18: 2026-10-08 | D18: Inputs sheet by fuel|subsector (lookups separated from formulas); 4 hidden parameter columns D:G, global parameters; base year 2022 in column L; named LAMBDAs in 2035. | E18: 0 (vs v0.1)
B19: 0.3 | C19: 2026-10-08 | D19: Variable codes in column A; labels from Variables; code column per scenario with full CPAT codes (auto-numbered). | E19: 0 (vs v0.2)
B20: 0.4 | C20: 2026-10-08 | D20: Row outline: blocks roll up. | E20: 0 (vs v0.3)
B21: 0.5 | C21: 2026-10-08 | D21: White band text; summary lines under bands. | E21: 0 (vs v0.4)
B22: 0.6 | C22: 2026-10-08 | D22: MTInputs sheet per scenario; carbon price from MTInputs. | E22: 0 (vs v0.5)
B23: 0.7 | C23: 2026-10-08 | D23: Legacy CPAT section layout (1 Policies, 3 Power, 5-8 sectors, 11 Results; subsector > variable > fuel); policy wedges: new carbon tax with MTInputs coverage, new excise (fuel price reform), total new policy; feebate shadow price (not yet used). | E23: 0 (common codes vs v0.6)
B24: 0.8 | C24: 2026-10-08 | D24: Shadow price on the efficiency margin of fuel use; shadow prices by sector and share impacting efficiency in section 1; all policy paths continue linearly; biomass carbon-tax coverage TRUE. | E24: 0 (common codes vs v0.7, no feebate)
B25: 0.9 | C25: 2026-10-08 | D25: Domestic price projection (legacy method) in section 2: international prices by source, supply cost, excise and other taxes with pass-through, retail price before new policies; real USD of ResultsYear (CPI and deflator indices); historical prices 2022-2024 from data; per subsector atp = rpb + nce x (1 + VAT). | E25: intended change: all prices and fuel use (see check report)
B26: 0.10 | C26: 2026-10-08 | D26: Other oil products treated like the other oil products (pass-through and margin from data); VAT-rate assumption where data blank (VAT_WEO for residential and oil products); changed data marked bright yellow. | E26: intended change: prices with VAT, other oil products, fuel use
B27: 0.11 | C27: 2026-10-09 | D27: Horizon 2040; food & forestry with services elasticities; new ETS (price = carbon price inputs, replaces the carbon tax where it covers); sectoral shadow prices (feebates + regulations placeholder); section 2: VAT payment, existing taxes and subsidies, subsidy per price unit; LAMBDA in the right column of every calculated row; separate history / projection column blocks; LegacyDiff sheet; 12. Revenues prepared. | E27: 0 to 2035 on unaffected codes (see check report); foo and horizon changes intended

Sheet MTInputs
B1: MTInputs template - row structure copied exactly from legacy CPAT MTInputs
B2: Do not insert/delete rows. Columns D:E are hidden placeholders (MT values, Dashboard values).
B3: Rows must match legacy exactly. Green (EBF1DE) = used by module; grey (F2F2F2) = unused. See NORMS.md section 4. | J3: Scenario columns (Used for calculation): number in row 5, name in row 6. Red = changed from the template value. Copy the last column one to the right to add a scenario.
C5: FALSE | D5: <-- Should normally be "FALSE"! | J5: 1 | K5: =J5+1
D6: 6 | J6: Baseline (no carbon price) | K6: Carbon price $20/tCO2 from 2027
B7: Parameters | C7: unit | D7: MT values | E7: "Dashboard" values | F7: Used for calculation | G7: Defaults | H7: NameOfParameter | J7: Used for calculation | K7: Used for calculation
B8: Country | F8: Egypt | G8: Egypt | H8: Countryname | J8: Egypt | K8: Egypt
B9: Scenario identification
B10: Scenario ID | C10: # | F10: N/A | G10: N/A | H10: MSTScenarioID | J10: =J$5 | K10: =K$5
B11: Scenario status | C11: switch | F11: N/A | G11: N/A | J11: N/A | K11: N/A
B12: Scenario name | C12: name | F12: N/A | G12: N/A | J12: =J$6 | K12: =K$6
B13: Chosen policy | C13: switch | F13: - Carbon tax | G13: - Carbon tax | H13: ScenarioSelected | J13: - Carbon tax | K13: - Carbon tax
B14: Scenario status for macro | C14: # | F14: N/A | G14: N/A | J14: N/A | K14: N/A
B15: Scenario parameters override? | C15: # | F15: N/A | G15: N/A | J15: N/A | K15: N/A
B16: CPAT-side parameters override? | C16: switch | F16: Manual* | G16: Manual* | H16: CPATDefaultsOrUserDefined | J16: Manual* | K16: Manual*
B17: Carbon pricing: main inputs
A18: X | B18: Carbon pricing start year | C18: year | F18: 2026 | G18: 2027 | H18: CPIntro | J18: 2027 | K18: 2027
A19: X | B19: Starting carbon price | C19: nom. USD/tCO2 | F19: 0 | G19: 20 | H19: CPLevelStart | J19: 0 | K19: 20
B20: Target level of carbon price | C20: nom. USD/tCO2 | F20: 50 | G20: 50 | H20: CPLevelTarget | J20: 0 | K20: 20
A21: X | B21: Year to reach target level | C21: year | F21: 2030 | G21: 2035 | H21: CPOutro | J21: 2030 | K21: 2030
B22: Carbon pricing: fuel coverage
B23: Apply tax to coal? | C23: switch | F23: TRUE | G23: TRUE | H23: MCovCoa | J23: TRUE | K23: TRUE
B24: Apply tax to natural gas? | C24: switch | F24: TRUE | G24: TRUE | H24: MCovNga | J24: TRUE | K24: TRUE
B25: Apply tax to gasoline? | C25: switch | F25: TRUE | G25: TRUE | H25: MCovGso | J25: TRUE | K25: TRUE
B26: Apply tax to diesel? | C26: switch | F26: TRUE | G26: TRUE | H26: MCovDie | J26: TRUE | K26: TRUE
B27: Apply tax to LPG? | C27: switch | F27: TRUE | G27: TRUE | H27: MCovLpg | J27: TRUE | K27: TRUE
B28: Apply tax to kerosene? | C28: switch | F28: TRUE | G28: TRUE | H28: MCovKer | J28: TRUE | K28: TRUE
B29: Apply tax to non-road oil products? | C29: switch | F29: TRUE | G29: TRUE | H29: MCovOop | J29: TRUE | K29: TRUE
B30: Carbon pricing: sector coverage
B31: Apply tax to power sector? | C31: switch | F31: TRUE | G31: TRUE | H31: MCovPow | J31: TRUE | K31: TRUE
B32: Apply tax to road transportation? | C32: switch | F32: TRUE | G32: TRUE | H32: MCovRod | J32: TRUE | K32: TRUE
B33: Apply tax to rail transportation? | C33: switch | F33: TRUE | G33: TRUE | H33: MCovRal | J33: TRUE | K33: TRUE
B34: Apply tax to domestic aviation? | C34: switch | F34: TRUE | G34: TRUE | H34: MCovAvi | J34: TRUE | K34: TRUE
B35: Apply tax to domestic shipping? | C35: switch | F35: TRUE | G35: TRUE | H35: MCovNav | J35: TRUE | K35: TRUE
B36: Apply tax to residential sector? | C36: switch | F36: TRUE | G36: TRUE | H36: MCovRes | J36: TRUE | K36: TRUE
B37: Apply tax to food & forestry? | C37: switch | F37: TRUE | G37: TRUE | H37: MCovFoo | J37: TRUE | K37: TRUE
B38: Apply tax to services (private / public)? | C38: switch | F38: TRUE | G38: TRUE | H38: MCovSrv | J38: TRUE | K38: TRUE
B39: Apply tax to mining & chemicals? | C39: switch | F39: TRUE | G39: TRUE | H39: MCovMch | J39: TRUE | K39: TRUE
B40: Apply tax to iron and steel? | C40: switch | F40: TRUE | G40: TRUE | H40: MCovIrn | J40: TRUE | K40: TRUE
B41: Apply tax to non-ferrous metals? | C41: switch | F41: TRUE | G41: TRUE | H41: MCovNfm | J41: TRUE | K41: TRUE
...

Sheet Mitigation
A1: Variable | B1: Fuel | C1: Sector | D1: Param 1 | E1: Param 2 | F1: Param 3 | G1: Param 4 | H1: Description | I1: Unit | J1: Source | K1: Scenario 1: output code | AE1: Scenario 2: output code
A2: Mitigation module - price to fuel use (copy-pasteable, design 2, legacy CPAT sections)
A3: Scenario assumptions (one column group per scenario: code column + years; copy a whole group to add a scenario)
H4: Year | L4: =Settings!$C$7 | M4: =L4+1 | N4: =M4+1 | O4: =N4+1 | P4: =O4+1 | Q4: =P4+1 | R4: =Q4+1 | S4: =R4+1 | T4: =S4+1 | ... AD4: =AC4+1 | AF4: =Settings!$C$7 | AG4: =AF4+1 | AH4: =AG4+1 | AI4: =AH4+1 | AJ4: =AI4+1 | AK4: =AJ4+1 | AL4: =AK4+1 | AM4: =AL4+1 | AN4: =AM4+1 | ... AX4: =AW4+1
H5: Scenario number (MTInputs column) | K5: 1 | L5: =K5 | M5: =L5 | N5: =M5 | O5: =N5 | P5: =O5 | Q5: =P5 | R5: =Q5 | S5: =R5 | ... AD5: =AC5 | AE5: =K5+1 | AF5: =AE5 | AG5: =AF5 | AH5: =AG5 | AI5: =AH5 | AJ5: =AI5 | AK5: =AJ5 | AL5: =AK5 | AM5: =AL5 | ... AX5: =AW5
H6: Scenario name (from MTInputs) | L6: =INDEX(MTInputs!$J$6:$AZ$6,MATCH(L$5,MTInputs!$J$5:$AZ$5,0)) | AF6: =INDEX(MTInputs!$J$6:$AZ$6,MATCH(AF$5,MTInputs!$J$5:$AZ$5,0))
A7: gdp.pos.pct | H7: =INDEX(Variables!$B$5:$B$105,MATCH($A7,Variables!$A$5:$A$105,0))&IF($C7="",""," | "&INDEX(Mapping!$B$5:$B$26,MATCH($C7,Mapping!$A$5:$A$26,0))&" | "&INDEX(Mapping!$B$30:$B$41,MATCH($B7,Mapping!$A$30:$A$41,0))) | I7: =INDEX(Variables!$C$5:$C$105,MATCH($A7,Variables!$A$5:$A$105,0)) | J7: =INDEX(Variables!$E$5:$E$105,MATCH($A7,Variables!$A$5:$A$105,0)) | K7: =LOWER(Settings!$C$4)&".mit."&$A7&IF($C7="","","."&$C7&"."&$B7)&IF(INDEX(Variables!$D$5:$D$105,MATCH($A7,Variables!$A$5:$A$105,0))="","","."&INDEX(Variables!$D$5:$D$105,MATCH($A7,Variables!$A$5:$A$105,0)))&"."&K$5 | L7: =INDEX(WEO!$F$4:$AZ$1000,MATCH(Settings!$C$4&"|gdp_growth",WEO!$A$4:$A$1000,0),MATCH(L$4,WEO!$F$3:$AZ$3,0)) | M7: =INDEX(WEO!$F$4:$AZ$1000,MATCH(Settings!$C$4&"|gdp_growth",WEO!$A$4:$A$1000,0),MATCH(M$4,WEO!$F$3:$AZ$3,0)) | N7: =INDEX(WEO!$F$4:$AZ$1000,MATCH(Settings!$C$4&"|gdp_growth",WEO!$A$4:$A$1000,0),MATCH(N$4,WEO!$F$3:$AZ$3,0)) | O7: =INDEX(WEO!$F$4:$AZ$1000,MATCH(Settings!$C$4&"|gdp_growth",WEO!$A$4:$A$1000,0),MATCH(O$4,WEO!$F$3:$AZ$3,0)) | P7: =INDEX(WEO!$F$4:$AZ$1000,MATCH(Settings!$C$4&"|gdp_growth",WEO!$A$4:$A$1000,0),MATCH(P$4,WEO!$F$3:$AZ$3,0)) | Q7: =INDEX(WEO!$F$4:$AZ$1000,MATCH(Settings!$C$4&"|gdp_growth",WEO!$A$4:$A$1000,0),MATCH(Q$4,WEO!$F$3:$AZ$3,0)) | R7: =INDEX(WEO!$F$4:$AZ$1000,MATCH(Settings!$C$4&"|gdp_growth",WEO!$A$4:$A$1000,0),MATCH(R$4,WEO!$F$3:$AZ$3,0)) | S7: =INDEX(WEO!$F$4:$AZ$1000,MATCH(Settings!$C$4&"|gdp_growth",WEO!$A$4:$A$1000,0),MATCH(S$4,WEO!$F$3:$AZ$3,0)) | ... AD7: =INDEX(WEO!$F$4:$AZ$1000,MATCH(Settings!$C$4&"|gdp_growth",WEO!$A$4:$A$1000,0),MATCH(AD$4,WEO!$F$3:$AZ$3,0)) | AE7: =LOWER(Settings!$C$4)&".mit."&$A7&IF($C7="","","."&$C7&"."&$B7)&IF(INDEX(Variables!$D$5:$D$105,MATCH($A7,Variables!$A$5:$A$105,0))="","","."&INDEX(Variables!$D$5:$D$105,MATCH($A7,Variables!$A$5:$A$105,0)))&"."&AE$5 | AF7: =INDEX(WEO!$F$4:$AZ$1000,MATCH(Settings!$C$4&"|gdp_growth",WEO!$A$4:$A$1000,0),MATCH(AF$4,WEO!$F$3:$AZ$3,0)) | AG7: =INDEX(WEO!$F$4:$AZ$1000,MATCH(Settings!$C$4&"|gdp_growth",WEO!$A$4:$A$1000,0),MATCH(AG$4,WEO!$F$3:$AZ$3,0)) | AH7: =INDEX(WEO!$F$4:$AZ$1000,MATCH(Settings!$C$4&"|gdp_growth",WEO!$A$4:$A$1000,0),MATCH(AH$4,WEO!$F$3:$AZ$3,0)) | AI7: =INDEX(WEO!$F$4:$AZ$1000,MATCH(Settings!$C$4&"|gdp_growth",WEO!$A$4:$A$1000,0),MATCH(AI$4,WEO!$F$3:$AZ$3,0)) | AJ7: =INDEX(WEO!$F$4:$AZ$1000,MATCH(Settings!$C$4&"|gdp_growth",WEO!$A$4:$A$1000,0),MATCH(AJ$4,WEO!$F$3:$AZ$3,0)) | AK7: =INDEX(WEO!$F$4:$AZ$1000,MATCH(Settings!$C$4&"|gdp_growth",WEO!$A$4:$A$1000,0),MATCH(AK$4,WEO!$F$3:$AZ$3,0)) | AL7: =INDEX(WEO!$F$4:$AZ$1000,MATCH(Settings!$C$4&"|gdp_growth",WEO!$A$4:$A$1000,0),MATCH(AL$4,WEO!$F$3:$AZ$3,0)) | AM7: =INDEX(WEO!$F$4:$AZ$1000,MATCH(Settings!$C$4&"|gdp_growth",WEO!$A$4:$A$1000,0),MATCH(AM$4,WEO!$F$3:$AZ$3,0)) | ... AX7: =INDEX(WEO!$F$4:$AZ$1000,MATCH(Settings!$C$4&"|gdp_growth",WEO!$A$4:$A$1000,0),MATCH(AX$4,WEO!$F$3:$AZ$3,0))
A8: infl | H8: =INDEX(Variables!$B$5:$B$105,MATCH($A8,Variables!$A$5:$A$105,0))&IF($C8="",""," | "&INDEX(Mapping!$B$5:$B$26,MATCH($C8,Mapping!$A$5:$A$26,0))&" | "&INDEX(Mapping!$B$30:$B$41,MATCH($B8,Mapping!$A$30:$A$41,0))) | I8: =INDEX(Variables!$C$5:$C$105,MATCH($A8,Variables!$A$5:$A$105,0)) | J8: =INDEX(Variables!$E$5:$E$105,MATCH($A8,Variables!$A$5:$A$105,0)) | K8: =LOWER(Settings!$C$4)&".mit."&$A8&IF($C8="","","."&$C8&"."&$B8)&IF(INDEX(Variables!$D$5:$D$105,MATCH($A8,Variables!$A$5:$A$105,0))="","","."&INDEX(Variables!$D$5:$D$105,MATCH($A8,Variables!$A$5:$A$105,0)))&"."&K$5 | L8: =INDEX(WEO!$F$4:$AZ$1000,MATCH("USA|pcpi",WEO!$A$4:$A$1000,0),MATCH(Settings!$C$8,WEO!$F$3:$AZ$3,0))/INDEX(WEO!$F$4:$AZ$1000,MATCH("USA|pcpi",WEO!$A$4:$A$1000,0),MATCH(L$4,WEO!$F$3:$AZ$3,0)) | M8: =INDEX(WEO!$F$4:$AZ$1000,MATCH("USA|pcpi",WEO!$A$4:$A$1000,0),MATCH(Settings!$C$8,WEO!$F$3:$AZ$3,0))/INDEX(WEO!$F$4:$AZ$1000,MATCH("USA|pcpi",WEO!$A$4:$A$1000,0),MATCH(M$4,WEO!$F$3:$AZ$3,0)) | N8: =INDEX(WEO!$F$4:$AZ$1000,MATCH("USA|pcpi",WEO!$A$4:$A$1000,0),MATCH(Settings!$C$8,WEO!$F$3:$AZ$3,0))/INDEX(WEO!$F$4:$AZ$1000,MATCH("USA|pcpi",WEO!$A$4:$A$1000,0),MATCH(N$4,WEO!$F$3:$AZ$3,0)) | O8: =INDEX(WEO!$F$4:$AZ$1000,MATCH("USA|pcpi",WEO!$A$4:$A$1000,0),MATCH(Settings!$C$8,WEO!$F$3:$AZ$3,0))/INDEX(WEO!$F$4:$AZ$1000,MATCH("USA|pcpi",WEO!$A$4:$A$1000,0),MATCH(O$4,WEO!$F$3:$AZ$3,0)) | P8: =INDEX(WEO!$F$4:$AZ$1000,MATCH("USA|pcpi",WEO!$A$4:$A$1000,0),MATCH(Settings!$C$8,WEO!$F$3:$AZ$3,0))/INDEX(WEO!$F$4:$AZ$1000,MATCH("USA|pcpi",WEO!$A$4:$A$1000,0),MATCH(P$4,WEO!$F$3:$AZ$3,0)) | Q8: =INDEX(WEO!$F$4:$AZ$1000,MATCH("USA|pcpi",WEO!$A$4:$A$1000,0),MATCH(Settings!$C$8,WEO!$F$3:$AZ$3,0))/INDEX(WEO!$F$4:$AZ$1000,MATCH("USA|pcpi",WEO!$A$4:$A$1000,0),MATCH(Q$4,WEO!$F$3:$AZ$3,0)) | R8: =INDEX(WEO!$F$4:$AZ$1000,MATCH("USA|pcpi",WEO!$A$4:$A$1000,0),MATCH(Settings!$C$8,WEO!$F$3:$AZ$3,0))/INDEX(WEO!$F$4:$AZ$1000,MATCH("USA|pcpi",WEO!$A$4:$A$1000,0),MATCH(R$4,WEO!$F$3:$AZ$3,0)) | S8: =INDEX(WEO!$F$4:$AZ$1000,MATCH("USA|pcpi",WEO!$A$4:$A$1000,0),MATCH(Settings!$C$8,WEO!$F$3:$AZ$3,0))/INDEX(WEO!$F$4:$AZ$1000,MATCH("USA|pcpi",WEO!$A$4:$A$1000,0),MATCH(S$4,WEO!$F$3:$AZ$3,0)) | ... AD8: =INDEX(WEO!$F$4:$AZ$1000,MATCH("USA|pcpi",WEO!$A$4:$A$1000,0),MATCH(Settings!$C$8,WEO!$F$3:$AZ$3,0))/INDEX(WEO!$F$4:$AZ$1000,MATCH("USA|pcpi",WEO!$A$4:$A$1000,0),MATCH(AD$4,WEO!$F$3:$AZ$3,0)) | AE8: =LOWER(Settings!$C$4)&".mit."&$A8&IF($C8="","","."&$C8&"."&$B8)&IF(INDEX(Variables!$D$5:$D$105,MATCH($A8,Variables!$A$5:$A$105,0))="","","."&INDEX(Variables!$D$5:$D$105,MATCH($A8,Variables!$A$5:$A$105,0)))&"."&AE$5 | AF8: =INDEX(WEO!$F$4:$AZ$1000,MATCH("USA|pcpi",WEO!$A$4:$A$1000,0),MATCH(Settings!$C$8,WEO!$F$3:$AZ$3,0))/INDEX(WEO!$F$4:$AZ$1000,MATCH("USA|pcpi",WEO!$A$4:$A$1000,0),MATCH(AF$4,WEO!$F$3:$AZ$3,0)) | AG8: =INDEX(WEO!$F$4:$AZ$1000,MATCH("USA|pcpi",WEO!$A$4:$A$1000,0),MATCH(Settings!$C$8,WEO!$F$3:$AZ$3,0))/INDEX(WEO!$F$4:$AZ$1000,MATCH("USA|pcpi",WEO!$A$4:$A$1000,0),MATCH(AG$4,WEO!$F$3:$AZ$3,0)) | AH8: =INDEX(WEO!$F$4:$AZ$1000,MATCH("USA|pcpi",WEO!$A$4:$A$1000,0),MATCH(Settings!$C$8,WEO!$F$3:$AZ$3,0))/INDEX(WEO!$F$4:$AZ$1000,MATCH("USA|pcpi",WEO!$A$4:$A$1000,0),MATCH(AH$4,WEO!$F$3:$AZ$3,0)) | AI8: =INDEX(WEO!$F$4:$AZ$1000,MATCH("USA|pcpi",WEO!$A$4:$A$1000,0),MATCH(Settings!$C$8,WEO!$F$3:$AZ$3,0))/INDEX(WEO!$F$4:$AZ$1000,MATCH("USA|pcpi",WEO!$A$4:$A$1000,0),MATCH(AI$4,WEO!$F$3:$AZ$3,0)) | AJ8: =INDEX(WEO!$F$4:$AZ$1000,MATCH("USA|pcpi",WEO!$A$4:$A$1000,0),MATCH(Settings!$C$8,WEO!$F$3:$AZ$3,0))/INDEX(WEO!$F$4:$AZ$1000,MATCH("USA|pcpi",WEO!$A$4:$A$1000,0),MATCH(AJ$4,WEO!$F$3:$AZ$3,0)) | AK8: =INDEX(WEO!$F$4:$AZ$1000,MATCH("USA|pcpi",WEO!$A$4:$A$1000,0),MATCH(Settings!$C$8,WEO!$F$3:$AZ$3,0))/INDEX(WEO!$F$4:$AZ$1000,MATCH("USA|pcpi",WEO!$A$4:$A$1000,0),MATCH(AK$4,WEO!$F$3:$AZ$3,0)) | AL8: =INDEX(WEO!$F$4:$AZ$1000,MATCH("USA|pcpi",WEO!$A$4:$A$1000,0),MATCH(Settings!$C$8,WEO!$F$3:$AZ$3,0))/INDEX(WEO!$F$4:$AZ$1000,MATCH("USA|pcpi",WEO!$A$4:$A$1000,0),MATCH(AL$4,WEO!$F$3:$AZ$3,0)) | AM8: =INDEX(WEO!$F$4:$AZ$1000,MATCH("USA|pcpi",WEO!$A$4:$A$1000,0),MATCH(Settings!$C$8,WEO!$F$3:$AZ$3,0))/INDEX(WEO!$F$4:$AZ$1000,MATCH("USA|pcpi",WEO!$A$4:$A$1000,0),MATCH(AM$4,WEO!$F$3:$AZ$3,0)) | ... AX8: =INDEX(WEO!$F$4:$AZ$1000,MATCH("USA|pcpi",WEO!$A$4:$A$1000,0),MATCH(Settings!$C$8,WEO!$F$3:$AZ$3,0))/INDEX(WEO!$F$4:$AZ$1000,MATCH("USA|pcpi",WEO!$A$4:$A$1000,0),MATCH(AX$4,WEO!$F$3:$AZ$3,0))
A9: defl | H9: =INDEX(Variables!$B$5:$B$105,MATCH($A9,Variables!$A$5:$A$105,0))&IF($C9="",""," | "&INDEX(Mapping!$B$5:$B$26,MATCH($C9,Mapping!$A$5:$A$26,0))&" | "&INDEX(Mapping!$B$30:$B$41,MATCH($B9,Mapping!$A$30:$A$41,0))) | I9: =INDEX(Variables!$C$5:$C$105,MATCH($A9,Variables!$A$5:$A$105,0)) | J9: =INDEX(Variables!$E$5:$E$105,MATCH($A9,Variables!$A$5:$A$105,0)) | K9: =LOWER(Settings!$C$4)&".mit."&$A9&IF($C9="","","."&$C9&"."&$B9)&IF(INDEX(Variables!$D$5:$D$105,MATCH($A9,Variables!$A$5:$A$105,0))="","","."&INDEX(Variables!$D$5:$D$105,MATCH($A9,Variables!$A$5:$A$105,0)))&"."&K$5 | L9: =INDEX(WEO!$F$4:$AZ$1000,MATCH("USA|ngdp_d",WEO!$A$4:$A$1000,0),MATCH(Settings!$C$8,WEO!$F$3:$AZ$3,0))/INDEX(WEO!$F$4:$AZ$1000,MATCH("USA|ngdp_d",WEO!$A$4:$A$1000,0),MATCH(L$4,WEO!$F$3:$AZ$3,0)) | M9: =INDEX(WEO!$F$4:$AZ$1000,MATCH("USA|ngdp_d",WEO!$A$4:$A$1000,0),MATCH(Settings!$C$8,WEO!$F$3:$AZ$3,0))/INDEX(WEO!$F$4:$AZ$1000,MATCH("USA|ngdp_d",WEO!$A$4:$A$1000,0),MATCH(M$4,WEO!$F$3:$AZ$3,0)) | N9: =INDEX(WEO!$F$4:$AZ$1000,MATCH("USA|ngdp_d",WEO!$A$4:$A$1000,0),MATCH(Settings!$C$8,WEO!$F$3:$AZ$3,0))/INDEX(WEO!$F$4:$AZ$1000,MATCH("USA|ngdp_d",WEO!$A$4:$A$1000,0),MATCH(N$4,WEO!$F$3:$AZ$3,0)) | O9: =INDEX(WEO!$F$4:$AZ$1000,MATCH("USA|ngdp_d",WEO!$A$4:$A$1000,0),MATCH(Settings!$C$8,WEO!$F$3:$AZ$3,0))/INDEX(WEO!$F$4:$AZ$1000,MATCH("USA|ngdp_d",WEO!$A$4:$A$1000,0),MATCH(O$4,WEO!$F$3:$AZ$3,0)) | P9: =INDEX(WEO!$F$4:$AZ$1000,MATCH("USA|ngdp_d",WEO!$A$4:$A$1000,0),MATCH(Settings!$C$8,WEO!$F$3:$AZ$3,0))/INDEX(WEO!$F$4:$AZ$1000,MATCH("USA|ngdp_d",WEO!$A$4:$A$1000,0),MATCH(P$4,WEO!$F$3:$AZ$3,0)) | Q9: =INDEX(WEO!$F$4:$AZ$1000,MATCH("USA|ngdp_d",WEO!$A$4:$A$1000,0),MATCH(Settings!$C$8,WEO!$F$3:$AZ$3,0))/INDEX(WEO!$F$4:$AZ$1000,MATCH("USA|ngdp_d",WEO!$A$4:$A$1000,0),MATCH(Q$4,WEO!$F$3:$AZ$3,0)) | R9: =INDEX(WEO!$F$4:$AZ$1000,MATCH("USA|ngdp_d",WEO!$A$4:$A$1000,0),MATCH(Settings!$C$8,WEO!$F$3:$AZ$3,0))/INDEX(WEO!$F$4:$AZ$1000,MATCH("USA|ngdp_d",WEO!$A$4:$A$1000,0),MATCH(R$4,WEO!$F$3:$AZ$3,0)) | S9: =INDEX(WEO!$F$4:$AZ$1000,MATCH("USA|ngdp_d",WEO!$A$4:$A$1000,0),MATCH(Settings!$C$8,WEO!$F$3:$AZ$3,0))/INDEX(WEO!$F$4:$AZ$1000,MATCH("USA|ngdp_d",WEO!$A$4:$A$1000,0),MATCH(S$4,WEO!$F$3:$AZ$3,0)) | ... AD9: =INDEX(WEO!$F$4:$AZ$1000,MATCH("USA|ngdp_d",WEO!$A$4:$A$1000,0),MATCH(Settings!$C$8,WEO!$F$3:$AZ$3,0))/INDEX(WEO!$F$4:$AZ$1000,MATCH("USA|ngdp_d",WEO!$A$4:$A$1000,0),MATCH(AD$4,WEO!$F$3:$AZ$3,0)) | AE9: =LOWER(Settings!$C$4)&".mit."&$A9&IF($C9="","","."&$C9&"."&$B9)&IF(INDEX(Variables!$D$5:$D$105,MATCH($A9,Variables!$A$5:$A$105,0))="","","."&INDEX(Variables!$D$5:$D$105,MATCH($A9,Variables!$A$5:$A$105,0)))&"."&AE$5 | AF9: =INDEX(WEO!$F$4:$AZ$1000,MATCH("USA|ngdp_d",WEO!$A$4:$A$1000,0),MATCH(Settings!$C$8,WEO!$F$3:$AZ$3,0))/INDEX(WEO!$F$4:$AZ$1000,MATCH("USA|ngdp_d",WEO!$A$4:$A$1000,0),MATCH(AF$4,WEO!$F$3:$AZ$3,0)) | AG9: =INDEX(WEO!$F$4:$AZ$1000,MATCH("USA|ngdp_d",WEO!$A$4:$A$1000,0),MATCH(Settings!$C$8,WEO!$F$3:$AZ$3,0))/INDEX(WEO!$F$4:$AZ$1000,MATCH("USA|ngdp_d",WEO!$A$4:$A$1000,0),MATCH(AG$4,WEO!$F$3:$AZ$3,0)) | AH9: =INDEX(WEO!$F$4:$AZ$1000,MATCH("USA|ngdp_d",WEO!$A$4:$A$1000,0),MATCH(Settings!$C$8,WEO!$F$3:$AZ$3,0))/INDEX(WEO!$F$4:$AZ$1000,MATCH("USA|ngdp_d",WEO!$A$4:$A$1000,0),MATCH(AH$4,WEO!$F$3:$AZ$3,0)) | AI9: =INDEX(WEO!$F$4:$AZ$1000,MATCH("USA|ngdp_d",WEO!$A$4:$A$1000,0),MATCH(Settings!$C$8,WEO!$F$3:$AZ$3,0))/INDEX(WEO!$F$4:$AZ$1000,MATCH("USA|ngdp_d",WEO!$A$4:$A$1000,0),MATCH(AI$4,WEO!$F$3:$AZ$3,0)) | AJ9: =INDEX(WEO!$F$4:$AZ$1000,MATCH("USA|ngdp_d",WEO!$A$4:$A$1000,0),MATCH(Settings!$C$8,WEO!$F$3:$AZ$3,0))/INDEX(WEO!$F$4:$AZ$1000,MATCH("USA|ngdp_d",WEO!$A$4:$A$1000,0),MATCH(AJ$4,WEO!$F$3:$AZ$3,0)) | AK9: =INDEX(WEO!$F$4:$AZ$1000,MATCH("USA|ngdp_d",WEO!$A$4:$A$1000,0),MATCH(Settings!$C$8,WEO!$F$3:$AZ$3,0))/INDEX(WEO!$F$4:$AZ$1000,MATCH("USA|ngdp_d",WEO!$A$4:$A$1000,0),MATCH(AK$4,WEO!$F$3:$AZ$3,0)) | AL9: =INDEX(WEO!$F$4:$AZ$1000,MATCH("USA|ngdp_d",WEO!$A$4:$A$1000,0),MATCH(Settings!$C$8,WEO!$F$3:$AZ$3,0))/INDEX(WEO!$F$4:$AZ$1000,MATCH("USA|ngdp_d",WEO!$A$4:$A$1000,0),MATCH(AL$4,WEO!$F$3:$AZ$3,0)) | AM9: =INDEX(WEO!$F$4:$AZ$1000,MATCH("USA|ngdp_d",WEO!$A$4:$A$1000,0),MATCH(Settings!$C$8,WEO!$F$3:$AZ$3,0))/INDEX(WEO!$F$4:$AZ$1000,MATCH("USA|ngdp_d",WEO!$A$4:$A$1000,0),MATCH(AM$4,WEO!$F$3:$AZ$3,0)) | ... AX9: =INDEX(WEO!$F$4:$AZ$1000,MATCH("USA|ngdp_d",WEO!$A$4:$A$1000,0),MATCH(Settings!$C$8,WEO!$F$3:$AZ$3,0))/INDEX(WEO!$F$4:$AZ$1000,MATCH("USA|ngdp_d",WEO!$A$4:$A$1000,0),MATCH(AX$4,WEO!$F$3:$AZ$3,0))
A11: 1. Policies (scenario inputs from MTInputs by row and scenario number; policy paths) | D11: MTInputs row
A12: cptraj | H12: =INDEX(Variables!$B$5:$B$105,MATCH($A12,Variables!$A$5:$A$105,0))&IF($C12="",""," | "&INDEX(Mapping!$B$5:$B$26,MATCH($C12,Mapping!$A$5:$A$26,0))&" | "&INDEX(Mapping!$B$30:$B$41,MATCH($B12,Mapping!$A$30:$A$41,0))) | I12: =INDEX(Variables!$C$5:$C$105,MATCH($A12,Variables!$A$5:$A$105,0)) | J12: =INDEX(Variables!$E$5:$E$105,MATCH($A12,Variables!$A$5:$A$105,0)) | K12: =LOWER(Settings!$C$4)&".mit."&$A12&IF($C12="","","."&$C12&"."&$B12)&IF(INDEX(Variables!$D$5:$D$105,MATCH($A12,Variables!$A$5:$A$105,0))="","","."&INDEX(Variables!$D$5:$D$105,MATCH($A12,Variables!$A$5:$A$105,0)))&"."&K$5 | L12: =(IF(L$4<L$14,0,L$15+(L$16-L$15)/MAX(L$17-L$14,1)*IF(OR(L$4<=L$17,L$18="Linear*"),L$4-L$14,L$17-L$14)))*IF(LEFT(L$19,7)="Nominal",L$8,1) | M12: =(IF(M$4<M$14,0,M$15+(M$16-M$15)/MAX(M$17-M$14,1)*IF(OR(M$4<=M$17,M$18="Linear*"),M$4-M$14,M$17-M$14)))*IF(LEFT(M$19,7)="Nominal",M$8,1) | N12: =(IF(N$4<N$14,0,N$15+(N$16-N$15)/MAX(N$17-N$14,1)*IF(OR(N$4<=N$17,N$18="Linear*"),N$4-N$14,N$17-N$14)))*IF(LEFT(N$19,7)="Nominal",N$8,1) | O12: =(IF(O$4<O$14,0,O$15+(O$16-O$15)/MAX(O$17-O$14,1)*IF(OR(O$4<=O$17,O$18="Linear*"),O$4-O$14,O$17-O$14)))*IF(LEFT(O$19,7)="Nominal",O$8,1) | P12: =(IF(P$4<P$14,0,P$15+(P$16-P$15)/MAX(P$17-P$14,1)*IF(OR(P$4<=P$17,P$18="Linear*"),P$4-P$14,P$17-P$14)))*IF(LEFT(P$19,7)="Nominal",P$8,1) | Q12: =(IF(Q$4<Q$14,0,Q$15+(Q$16-Q$15)/MAX(Q$17-Q$14,1)*IF(OR(Q$4<=Q$17,Q$18="Linear*"),Q$4-Q$14,Q$17-Q$14)))*IF(LEFT(Q$19,7)="Nominal",Q$8,1) | R12: =(IF(R$4<R$14,0,R$15+(R$16-R$15)/MAX(R$17-R$14,1)*IF(OR(R$4<=R$17,R$18="Linear*"),R$4-R$14,R$17-R$14)))*IF(LEFT(R$19,7)="Nominal",R$8,1) | S12: =(IF(S$4<S$14,0,S$15+(S$16-S$15)/MAX(S$17-S$14,1)*IF(OR(S$4<=S$17,S$18="Linear*"),S$4-S$14,S$17-S$14)))*IF(LEFT(S$19,7)="Nominal",S$8,1) | ... AC12: =(IF(AC$4<AC$14,0,AC$15+(AC$16-AC$15)/MAX(AC$17-AC$14,1)*IF(OR(AC$4<=AC$17,AC$18="Linear*"),AC$4-AC$14,AC$17-AC$14)))*IF(LEFT(AC$19,7)="Nominal",AC$8,1) | AD12: =PATH(AD$4,AD$14,AD$17,AD$15,AD$16,AD$18="Linear*")*IF(LEFT(AD$19,7)="Nominal",AD$8,1) | AE12: =LOWER(Settings!$C$4)&".mit."&$A12&IF($C12="","","."&$C12&"."&$B12)&IF(INDEX(Variables!$D$5:$D$105,MATCH($A12,Variables!$A$5:$A$105,0))="","","."&INDEX(Variables!$D$5:$D$105,MATCH($A12,Variables!$A$5:$A$105,0)))&"."&AE$5 | AF12: =(IF(AF$4<AF$14,0,AF$15+(AF$16-AF$15)/MAX(AF$17-AF$14,1)*IF(OR(AF$4<=AF$17,AF$18="Linear*"),AF$4-AF$14,AF$17-AF$14)))*IF(LEFT(AF$19,7)="Nominal",AF$8,1) | AG12: =(IF(AG$4<AG$14,0,AG$15+(AG$16-AG$15)/MAX(AG$17-AG$14,1)*IF(OR(AG$4<=AG$17,AG$18="Linear*"),AG$4-AG$14,AG$17-AG$14)))*IF(LEFT(AG$19,7)="Nominal",AG$8,1) | AH12: =(IF(AH$4<AH$14,0,AH$15+(AH$16-AH$15)/MAX(AH$17-AH$14,1)*IF(OR(AH$4<=AH$17,AH$18="Linear*"),AH$4-AH$14,AH$17-AH$14)))*IF(LEFT(AH$19,7)="Nominal",AH$8,1) | AI12: =(IF(AI$4<AI$14,0,AI$15+(AI$16-AI$15)/MAX(AI$17-AI$14,1)*IF(OR(AI$4<=AI$17,AI$18="Linear*"),AI$4-AI$14,AI$17-AI$14)))*IF(LEFT(AI$19,7)="Nominal",AI$8,1) | AJ12: =(IF(AJ$4<AJ$14,0,AJ$15+(AJ$16-AJ$15)/MAX(AJ$17-AJ$14,1)*IF(OR(AJ$4<=AJ$17,AJ$18="Linear*"),AJ$4-AJ$14,AJ$17-AJ$14)))*IF(LEFT(AJ$19,7)="Nominal",AJ$8,1) | AK12: =(IF(AK$4<AK$14,0,AK$15+(AK$16-AK$15)/MAX(AK$17-AK$14,1)*IF(OR(AK$4<=AK$17,AK$18="Linear*"),AK$4-AK$14,AK$17-AK$14)))*IF(LEFT(AK$19,7)="Nominal",AK$8,1) | AL12: =(IF(AL$4<AL$14,0,AL$15+(AL$16-AL$15)/MAX(AL$17-AL$14,1)*IF(OR(AL$4<=AL$17,AL$18="Linear*"),AL$4-AL$14,AL$17-AL$14)))*IF(LEFT(AL$19,7)="Nominal",AL$8,1) | AM12: =(IF(AM$4<AM$14,0,AM$15+(AM$16-AM$15)/MAX(AM$17-AM$14,1)*IF(OR(AM$4<=AM$17,AM$18="Linear*"),AM$4-AM$14,AM$17-AM$14)))*IF(LEFT(AM$19,7)="Nominal",AM$8,1) | ... AW12: =(IF(AW$4<AW$14,0,AW$15+(AW$16-AW$15)/MAX(AW$17-AW$14,1)*IF(OR(AW$4<=AW$17,AW$18="Linear*"),AW$4-AW$14,AW$17-AW$14)))*IF(LEFT(AW$19,7)="Nominal",AW$8,1) | AX12: =PATH(AX$4,AX$14,AX$17,AX$15,AX$16,AX$18="Linear*")*IF(LEFT(AX$19,7)="Nominal",AX$8,1)
H13: Carbon tax (MTInputs rows 18-21, 265, 266)
A14: CPIntro | D14: 18 | H14: =INDEX(Variables!$B$5:$B$105,MATCH($A14,Variables!$A$5:$A$105,0))&IF($C14="",""," | "&INDEX(Mapping!$B$5:$B$26,MATCH($C14,Mapping!$A$5:$A$26,0))&" | "&INDEX(Mapping!$B$30:$B$41,MATCH($B14,Mapping!$A$30:$A$41,0))) | I14: =INDEX(Variables!$C$5:$C$105,MATCH($A14,Variables!$A$5:$A$105,0)) | J14: =INDEX(Variables!$E$5:$E$105,MATCH($A14,Variables!$A$5:$A$105,0)) | K14: =LOWER(Settings!$C$4)&".mit."&$A14&IF($C14="","","."&$C14&"."&$B14)&IF(INDEX(Variables!$D$5:$D$105,MATCH($A14,Variables!$A$5:$A$105,0))="","","."&INDEX(Variables!$D$5:$D$105,MATCH($A14,Variables!$A$5:$A$105,0)))&"."&K$5 | L14: =INDEX(MTInputs!$J$1:$AZ$415,$D14,MATCH(L$5,MTInputs!$J$5:$AZ$5,0)) | M14: =INDEX(MTInputs!$J$1:$AZ$415,$D14,MATCH(M$5,MTInputs!$J$5:$AZ$5,0)) | N14: =INDEX(MTInputs!$J$1:$AZ$415,$D14,MATCH(N$5,MTInputs!$J$5:$AZ$5,0)) | O14: =INDEX(MTInputs!$J$1:$AZ$415,$D14,MATCH(O$5,MTInputs!$J$5:$AZ$5,0)) | P14: =INDEX(MTInputs!$J$1:$AZ$415,$D14,MATCH(P$5,MTInputs!$J$5:$AZ$5,0)) | Q14: =INDEX(MTInputs!$J$1:$AZ$415,$D14,MATCH(Q$5,MTInputs!$J$5:$AZ$5,0)) | R14: =INDEX(MTInputs!$J$1:$AZ$415,$D14,MATCH(R$5,MTInputs!$J$5:$AZ$5,0)) | S14: =INDEX(MTInputs!$J$1:$AZ$415,$D14,MATCH(S$5,MTInputs!$J$5:$AZ$5,0)) | ... AD14: =INDEX(MTInputs!$J$1:$AZ$415,$D14,MATCH(AD$5,MTInputs!$J$5:$AZ$5,0)) | AE14: =LOWER(Settings!$C$4)&".mit."&$A14&IF($C14="","","."&$C14&"."&$B14)&IF(INDEX(Variables!$D$5:$D$105,MATCH($A14,Variables!$A$5:$A$105,0))="","","."&INDEX(Variables!$D$5:$D$105,MATCH($A14,Variables!$A$5:$A$105,0)))&"."&AE$5 | AF14: =INDEX(MTInputs!$J$1:$AZ$415,$D14,MATCH(AF$5,MTInputs!$J$5:$AZ$5,0)) | AG14: =INDEX(MTInputs!$J$1:$AZ$415,$D14,MATCH(AG$5,MTInputs!$J$5:$AZ$5,0)) | AH14: =INDEX(MTInputs!$J$1:$AZ$415,$D14,MATCH(AH$5,MTInputs!$J$5:$AZ$5,0)) | AI14: =INDEX(MTInputs!$J$1:$AZ$415,$D14,MATCH(AI$5,MTInputs!$J$5:$AZ$5,0)) | AJ14: =INDEX(MTInputs!$J$1:$AZ$415,$D14,MATCH(AJ$5,MTInputs!$J$5:$AZ$5,0)) | AK14: =INDEX(MTInputs!$J$1:$AZ$415,$D14,MATCH(AK$5,MTInputs!$J$5:$AZ$5,0)) | AL14: =INDEX(MTInputs!$J$1:$AZ$415,$D14,MATCH(AL$5,MTInputs!$J$5:$AZ$5,0)) | AM14: =INDEX(MTInputs!$J$1:$AZ$415,$D14,MATCH(AM$5,MTInputs!$J$5:$AZ$5,0)) | ... AX14: =INDEX(MTInputs!$J$1:$AZ$415,$D14,MATCH(AX$5,MTInputs!$J$5:$AZ$5,0))
A15: CPLevelStart | D15: 19 | H15: =INDEX(Variables!$B$5:$B$105,MATCH($A15,Variables!$A$5:$A$105,0))&IF($C15="",""," | "&INDEX(Mapping!$B$5:$B$26,MATCH($C15,Mapping!$A$5:$A$26,0))&" | "&INDEX(Mapping!$B$30:$B$41,MATCH($B15,Mapping!$A$30:$A$41,0))) | I15: =INDEX(Variables!$C$5:$C$105,MATCH($A15,Variables!$A$5:$A$105,0)) | J15: =INDEX(Variables!$E$5:$E$105,MATCH($A15,Variables!$A$5:$A$105,0)) | K15: =LOWER(Settings!$C$4)&".mit."&$A15&IF($C15="","","."&$C15&"."&$B15)&IF(INDEX(Variables!$D$5:$D$105,MATCH($A15,Variables!$A$5:$A$105,0))="","","."&INDEX(Variables!$D$5:$D$105,MATCH($A15,Variables!$A$5:$A$105,0)))&"."&K$5 | L15: =INDEX(MTInputs!$J$1:$AZ$415,$D15,MATCH(L$5,MTInputs!$J$5:$AZ$5,0)) | M15: =INDEX(MTInputs!$J$1:$AZ$415,$D15,MATCH(M$5,MTInputs!$J$5:$AZ$5,0)) | N15: =INDEX(MTInputs!$J$1:$AZ$415,$D15,MATCH(N$5,MTInputs!$J$5:$AZ$5,0)) | O15: =INDEX(MTInputs!$J$1:$AZ$415,$D15,MATCH(O$5,MTInputs!$J$5:$AZ$5,0)) | P15: =INDEX(MTInputs!$J$1:$AZ$415,$D15,MATCH(P$5,MTInputs!$J$5:$AZ$5,0)) | Q15: =INDEX(MTInputs!$J$1:$AZ$415,$D15,MATCH(Q$5,MTInputs!$J$5:$AZ$5,0)) | R15: =INDEX(MTInputs!$J$1:$AZ$415,$D15,MATCH(R$5,MTInputs!$J$5:$AZ$5,0)) | S15: =INDEX(MTInputs!$J$1:$AZ$415,$D15,MATCH(S$5,MTInputs!$J$5:$AZ$5,0)) | ... AD15: =INDEX(MTInputs!$J$1:$AZ$415,$D15,MATCH(AD$5,MTInputs!$J$5:$AZ$5,0)) | AE15: =LOWER(Settings!$C$4)&".mit."&$A15&IF($C15="","","."&$C15&"."&$B15)&IF(INDEX(Variables!$D$5:$D$105,MATCH($A15,Variables!$A$5:$A$105,0))="","","."&INDEX(Variables!$D$5:$D$105,MATCH($A15,Variables!$A$5:$A$105,0)))&"."&AE$5 | AF15: =INDEX(MTInputs!$J$1:$AZ$415,$D15,MATCH(AF$5,MTInputs!$J$5:$AZ$5,0)) | AG15: =INDEX(MTInputs!$J$1:$AZ$415,$D15,MATCH(AG$5,MTInputs!$J$5:$AZ$5,0)) | AH15: =INDEX(MTInputs!$J$1:$AZ$415,$D15,MATCH(AH$5,MTInputs!$J$5:$AZ$5,0)) | AI15: =INDEX(MTInputs!$J$1:$AZ$415,$D15,MATCH(AI$5,MTInputs!$J$5:$AZ$5,0)) | AJ15: =INDEX(MTInputs!$J$1:$AZ$415,$D15,MATCH(AJ$5,MTInputs!$J$5:$AZ$5,0)) | AK15: =INDEX(MTInputs!$J$1:$AZ$415,$D15,MATCH(AK$5,MTInputs!$J$5:$AZ$5,0)) | AL15: =INDEX(MTInputs!$J$1:$AZ$415,$D15,MATCH(AL$5,MTInputs!$J$5:$AZ$5,0)) | AM15: =INDEX(MTInputs!$J$1:$AZ$415,$D15,MATCH(AM$5,MTInputs!$J$5:$AZ$5,0)) | ... AX15: =INDEX(MTInputs!$J$1:$AZ$415,$D15,MATCH(AX$5,MTInputs!$J$5:$AZ$5,0))
A16: CPLevelTarget | D16: 20 | H16: =INDEX(Variables!$B$5:$B$105,MATCH($A16,Variables!$A$5:$A$105,0))&IF($C16="",""," | "&INDEX(Mapping!$B$5:$B$26,MATCH($C16,Mapping!$A$5:$A$26,0))&" | "&INDEX(Mapping!$B$30:$B$41,MATCH($B16,Mapping!$A$30:$A$41,0))) | I16: =INDEX(Variables!$C$5:$C$105,MATCH($A16,Variables!$A$5:$A$105,0)) | J16: =INDEX(Variables!$E$5:$E$105,MATCH($A16,Variables!$A$5:$A$105,0)) | K16: =LOWER(Settings!$C$4)&".mit."&$A16&IF($C16="","","."&$C16&"."&$B16)&IF(INDEX(Variables!$D$5:$D$105,MATCH($A16,Variables!$A$5:$A$105,0))="","","."&INDEX(Variables!$D$5:$D$105,MATCH($A16,Variables!$A$5:$A$105,0)))&"."&K$5 | L16: =INDEX(MTInputs!$J$1:$AZ$415,$D16,MATCH(L$5,MTInputs!$J$5:$AZ$5,0)) | M16: =INDEX(MTInputs!$J$1:$AZ$415,$D16,MATCH(M$5,MTInputs!$J$5:$AZ$5,0)) | N16: =INDEX(MTInputs!$J$1:$AZ$415,$D16,MATCH(N$5,MTInputs!$J$5:$AZ$5,0)) | O16: =INDEX(MTInputs!$J$1:$AZ$415,$D16,MATCH(O$5,MTInputs!$J$5:$AZ$5,0)) | P16: =INDEX(MTInputs!$J$1:$AZ$415,$D16,MATCH(P$5,MTInputs!$J$5:$AZ$5,0)) | Q16: =INDEX(MTInputs!$J$1:$AZ$415,$D16,MATCH(Q$5,MTInputs!$J$5:$AZ$5,0)) | R16: =INDEX(MTInputs!$J$1:$AZ$415,$D16,MATCH(R$5,MTInputs!$J$5:$AZ$5,0)) | S16: =INDEX(MTInputs!$J$1:$AZ$415,$D16,MATCH(S$5,MTInputs!$J$5:$AZ$5,0)) | ... AD16: =INDEX(MTInputs!$J$1:$AZ$415,$D16,MATCH(AD$5,MTInputs!$J$5:$AZ$5,0)) | AE16: =LOWER(Settings!$C$4)&".mit."&$A16&IF($C16="","","."&$C16&"."&$B16)&IF(INDEX(Variables!$D$5:$D$105,MATCH($A16,Variables!$A$5:$A$105,0))="","","."&INDEX(Variables!$D$5:$D$105,MATCH($A16,Variables!$A$5:$A$105,0)))&"."&AE$5 | AF16: =INDEX(MTInputs!$J$1:$AZ$415,$D16,MATCH(AF$5,MTInputs!$J$5:$AZ$5,0)) | AG16: =INDEX(MTInputs!$J$1:$AZ$415,$D16,MATCH(AG$5,MTInputs!$J$5:$AZ$5,0)) | AH16: =INDEX(MTInputs!$J$1:$AZ$415,$D16,MATCH(AH$5,MTInputs!$J$5:$AZ$5,0)) | AI16: =INDEX(MTInputs!$J$1:$AZ$415,$D16,MATCH(AI$5,MTInputs!$J$5:$AZ$5,0)) | AJ16: =INDEX(MTInputs!$J$1:$AZ$415,$D16,MATCH(AJ$5,MTInputs!$J$5:$AZ$5,0)) | AK16: =INDEX(MTInputs!$J$1:$AZ$415,$D16,MATCH(AK$5,MTInputs!$J$5:$AZ$5,0)) | AL16: =INDEX(MTInputs!$J$1:$AZ$415,$D16,MATCH(AL$5,MTInputs!$J$5:$AZ$5,0)) | AM16: =INDEX(MTInputs!$J$1:$AZ$415,$D16,MATCH(AM$5,MTInputs!$J$5:$AZ$5,0)) | ... AX16: =INDEX(MTInputs!$J$1:$AZ$415,$D16,MATCH(AX$5,MTInputs!$J$5:$AZ$5,0))
A17: CPOutro | D17: 21 | H17: =INDEX(Variables!$B$5:$B$105,MATCH($A17,Variables!$A$5:$A$105,0))&IF($C17="",""," | "&INDEX(Mapping!$B$5:$B$26,MATCH($C17,Mapping!$A$5:$A$26,0))&" | "&INDEX(Mapping!$B$30:$B$41,MATCH($B17,Mapping!$A$30:$A$41,0))) | I17: =INDEX(Variables!$C$5:$C$105,MATCH($A17,Variables!$A$5:$A$105,0)) | J17: =INDEX(Variables!$E$5:$E$105,MATCH($A17,Variables!$A$5:$A$105,0)) | K17: =LOWER(Settings!$C$4)&".mit."&$A17&IF($C17="","","."&$C17&"."&$B17)&IF(INDEX(Variables!$D$5:$D$105,MATCH($A17,Variables!$A$5:$A$105,0))="","","."&INDEX(Variables!$D$5:$D$105,MATCH($A17,Variables!$A$5:$A$105,0)))&"."&K$5 | L17: =INDEX(MTInputs!$J$1:$AZ$415,$D17,MATCH(L$5,MTInputs!$J$5:$AZ$5,0)) | M17: =INDEX(MTInputs!$J$1:$AZ$415,$D17,MATCH(M$5,MTInputs!$J$5:$AZ$5,0)) | N17: =INDEX(MTInputs!$J$1:$AZ$415,$D17,MATCH(N$5,MTInputs!$J$5:$AZ$5,0)) | O17: =INDEX(MTInputs!$J$1:$AZ$415,$D17,MATCH(O$5,MTInputs!$J$5:$AZ$5,0)) | P17: =INDEX(MTInputs!$J$1:$AZ$415,$D17,MATCH(P$5,MTInputs!$J$5:$AZ$5,0)) | Q17: =INDEX(MTInputs!$J$1:$AZ$415,$D17,MATCH(Q$5,MTInputs!$J$5:$AZ$5,0)) | R17: =INDEX(MTInputs!$J$1:$AZ$415,$D17,MATCH(R$5,MTInputs!$J$5:$AZ$5,0)) | S17: =INDEX(MTInputs!$J$1:$AZ$415,$D17,MATCH(S$5,MTInputs!$J$5:$AZ$5,0)) | ... AD17: =INDEX(MTInputs!$J$1:$AZ$415,$D17,MATCH(AD$5,MTInputs!$J$5:$AZ$5,0)) | AE17: =LOWER(Settings!$C$4)&".mit."&$A17&IF($C17="","","."&$C17&"."&$B17)&IF(INDEX(Variables!$D$5:$D$105,MATCH($A17,Variables!$A$5:$A$105,0))="","","."&INDEX(Variables!$D$5:$D$105,MATCH($A17,Variables!$A$5:$A$105,0)))&"."&AE$5 | AF17: =INDEX(MTInputs!$J$1:$AZ$415,$D17,MATCH(AF$5,MTInputs!$J$5:$AZ$5,0)) | AG17: =INDEX(MTInputs!$J$1:$AZ$415,$D17,MATCH(AG$5,MTInputs!$J$5:$AZ$5,0)) | AH17: =INDEX(MTInputs!$J$1:$AZ$415,$D17,MATCH(AH$5,MTInputs!$J$5:$AZ$5,0)) | AI17: =INDEX(MTInputs!$J$1:$AZ$415,$D17,MATCH(AI$5,MTInputs!$J$5:$AZ$5,0)) | AJ17: =INDEX(MTInputs!$J$1:$AZ$415,$D17,MATCH(AJ$5,MTInputs!$J$5:$AZ$5,0)) | AK17: =INDEX(MTInputs!$J$1:$AZ$415,$D17,MATCH(AK$5,MTInputs!$J$5:$AZ$5,0)) | AL17: =INDEX(MTInputs!$J$1:$AZ$415,$D17,MATCH(AL$5,MTInputs!$J$5:$AZ$5,0)) | AM17: =INDEX(MTInputs!$J$1:$AZ$415,$D17,MATCH(AM$5,MTInputs!$J$5:$AZ$5,0)) | ... AX17: =INDEX(MTInputs!$J$1:$AZ$415,$D17,MATCH(AX$5,MTInputs!$J$5:$AZ$5,0))
A18: ExtendCarbonPriceBeyondOutro | D18: 265 | H18: =INDEX(Variables!$B$5:$B$105,MATCH($A18,Variables!$A$5:$A$105,0))&IF($C18="",""," | "&INDEX(Mapping!$B$5:$B$26,MATCH($C18,Mapping!$A$5:$A$26,0))&" | "&INDEX(Mapping!$B$30:$B$41,MATCH($B18,Mapping!$A$30:$A$41,0))) | I18: =INDEX(Variables!$C$5:$C$105,MATCH($A18,Variables!$A$5:$A$105,0)) | J18: =INDEX(Variables!$E$5:$E$105,MATCH($A18,Variables!$A$5:$A$105,0)) | K18: =LOWER(Settings!$C$4)&".mit."&$A18&IF($C18="","","."&$C18&"."&$B18)&IF(INDEX(Variables!$D$5:$D$105,MATCH($A18,Variables!$A$5:$A$105,0))="","","."&INDEX(Variables!$D$5:$D$105,MATCH($A18,Variables!$A$5:$A$105,0)))&"."&K$5 | L18: =INDEX(MTInputs!$J$1:$AZ$415,$D18,MATCH(L$5,MTInputs!$J$5:$AZ$5,0)) | M18: =INDEX(MTInputs!$J$1:$AZ$415,$D18,MATCH(M$5,MTInputs!$J$5:$AZ$5,0)) | N18: =INDEX(MTInputs!$J$1:$AZ$415,$D18,MATCH(N$5,MTInputs!$J$5:$AZ$5,0)) | O18: =INDEX(MTInputs!$J$1:$AZ$415,$D18,MATCH(O$5,MTInputs!$J$5:$AZ$5,0)) | P18: =INDEX(MTInputs!$J$1:$AZ$415,$D18,MATCH(P$5,MTInputs!$J$5:$AZ$5,0)) | Q18: =INDEX(MTInputs!$J$1:$AZ$415,$D18,MATCH(Q$5,MTInputs!$J$5:$AZ$5,0)) | R18: =INDEX(MTInputs!$J$1:$AZ$415,$D18,MATCH(R$5,MTInputs!$J$5:$AZ$5,0)) | S18: =INDEX(MTInputs!$J$1:$AZ$415,$D18,MATCH(S$5,MTInputs!$J$5:$AZ$5,0)) | ... AD18: =INDEX(MTInputs!$J$1:$AZ$415,$D18,MATCH(AD$5,MTInputs!$J$5:$AZ$5,0)) | AE18: =LOWER(Settings!$C$4)&".mit."&$A18&IF($C18="","","."&$C18&"."&$B18)&IF(INDEX(Variables!$D$5:$D$105,MATCH($A18,Variables!$A$5:$A$105,0))="","","."&INDEX(Variables!$D$5:$D$105,MATCH($A18,Variables!$A$5:$A$105,0)))&"."&AE$5 | AF18: =INDEX(MTInputs!$J$1:$AZ$415,$D18,MATCH(AF$5,MTInputs!$J$5:$AZ$5,0)) | AG18: =INDEX(MTInputs!$J$1:$AZ$415,$D18,MATCH(AG$5,MTInputs!$J$5:$AZ$5,0)) | AH18: =INDEX(MTInputs!$J$1:$AZ$415,$D18,MATCH(AH$5,MTInputs!$J$5:$AZ$5,0)) | AI18: =INDEX(MTInputs!$J$1:$AZ$415,$D18,MATCH(AI$5,MTInputs!$J$5:$AZ$5,0)) | AJ18: =INDEX(MTInputs!$J$1:$AZ$415,$D18,MATCH(AJ$5,MTInputs!$J$5:$AZ$5,0)) | AK18: =INDEX(MTInputs!$J$1:$AZ$415,$D18,MATCH(AK$5,MTInputs!$J$5:$AZ$5,0)) | AL18: =INDEX(MTInputs!$J$1:$AZ$415,$D18,MATCH(AL$5,MTInputs!$J$5:$AZ$5,0)) | AM18: =INDEX(MTInputs!$J$1:$AZ$415,$D18,MATCH(AM$5,MTInputs!$J$5:$AZ$5,0)) | ... AX18: =INDEX(MTInputs!$J$1:$AZ$415,$D18,MATCH(AX$5,MTInputs!$J$5:$AZ$5,0))
A19: NomorReal | D19: 266 | H19: =INDEX(Variables!$B$5:$B$105,MATCH($A19,Variables!$A$5:$A$105,0))&IF($C19="",""," | "&INDEX(Mapping!$B$5:$B$26,MATCH($C19,Mapping!$A$5:$A$26,0))&" | "&INDEX(Mapping!$B$30:$B$41,MATCH($B19,Mapping!$A$30:$A$41,0))) | I19: =INDEX(Variables!$C$5:$C$105,MATCH($A19,Variables!$A$5:$A$105,0)) | J19: =INDEX(Variables!$E$5:$E$105,MATCH($A19,Variables!$A$5:$A$105,0)) | K19: =LOWER(Settings!$C$4)&".mit."&$A19&IF($C19="","","."&$C19&"."&$B19)&IF(INDEX(Variables!$D$5:$D$105,MATCH($A19,Variables!$A$5:$A$105,0))="","","."&INDEX(Variables!$D$5:$D$105,MATCH($A19,Variables!$A$5:$A$105,0)))&"."&K$5 | L19: =INDEX(MTInputs!$J$1:$AZ$415,$D19,MATCH(L$5,MTInputs!$J$5:$AZ$5,0)) | M19: =INDEX(MTInputs!$J$1:$AZ$415,$D19,MATCH(M$5,MTInputs!$J$5:$AZ$5,0)) | N19: =INDEX(MTInputs!$J$1:$AZ$415,$D19,MATCH(N$5,MTInputs!$J$5:$AZ$5,0)) | O19: =INDEX(MTInputs!$J$1:$AZ$415,$D19,MATCH(O$5,MTInputs!$J$5:$AZ$5,0)) | P19: =INDEX(MTInputs!$J$1:$AZ$415,$D19,MATCH(P$5,MTInputs!$J$5:$AZ$5,0)) | Q19: =INDEX(MTInputs!$J$1:$AZ$415,$D19,MATCH(Q$5,MTInputs!$J$5:$AZ$5,0)) | R19: =INDEX(MTInputs!$J$1:$AZ$415,$D19,MATCH(R$5,MTInputs!$J$5:$AZ$5,0)) | S19: =INDEX(MTInputs!$J$1:$AZ$415,$D19,MATCH(S$5,MTInputs!$J$5:$AZ$5,0)) | ... AD19: =INDEX(MTInputs!$J$1:$AZ$415,$D19,MATCH(AD$5,MTInputs!$J$5:$AZ$5,0)) | AE19: =LOWER(Settings!$C$4)&".mit."&$A19&IF($C19="","","."&$C19&"."&$B19)&IF(INDEX(Variables!$D$5:$D$105,MATCH($A19,Variables!$A$5:$A$105,0))="","","."&INDEX(Variables!$D$5:$D$105,MATCH($A19,Variables!$A$5:$A$105,0)))&"."&AE$5 | AF19: =INDEX(MTInputs!$J$1:$AZ$415,$D19,MATCH(AF$5,MTInputs!$J$5:$AZ$5,0)) | AG19: =INDEX(MTInputs!$J$1:$AZ$415,$D19,MATCH(AG$5,MTInputs!$J$5:$AZ$5,0)) | AH19: =INDEX(MTInputs!$J$1:$AZ$415,$D19,MATCH(AH$5,MTInputs!$J$5:$AZ$5,0)) | AI19: =INDEX(MTInputs!$J$1:$AZ$415,$D19,MATCH(AI$5,MTInputs!$J$5:$AZ$5,0)) | AJ19: =INDEX(MTInputs!$J$1:$AZ$415,$D19,MATCH(AJ$5,MTInputs!$J$5:$AZ$5,0)) | AK19: =INDEX(MTInputs!$J$1:$AZ$415,$D19,MATCH(AK$5,MTInputs!$J$5:$AZ$5,0)) | AL19: =INDEX(MTInputs!$J$1:$AZ$415,$D19,MATCH(AL$5,MTInputs!$J$5:$AZ$5,0)) | AM19: =INDEX(MTInputs!$J$1:$AZ$415,$D19,MATCH(AM$5,MTInputs!$J$5:$AZ$5,0)) | ... AX19: =INDEX(MTInputs!$J$1:$AZ$415,$D19,MATCH(AX$5,MTInputs!$J$5:$AZ$5,0))
H20: Carbon tax coverage: fuels (MTInputs rows 23-29)
A21: ctcov | B21: coa | C21: all | D21: 23 | H21: =INDEX(Variables!$B$5:$B$105,MATCH($A21,Variables!$A$5:$A$105,0))&IF($C21="",""," | "&INDEX(Mapping!$B$5:$B$26,MATCH($C21,Mapping!$A$5:$A$26,0))&" | "&INDEX(Mapping!$B$30:$B$41,MATCH($B21,Mapping!$A$30:$A$41,0))) | I21: =INDEX(Variables!$C$5:$C$105,MATCH($A21,Variables!$A$5:$A$105,0)) | J21: =INDEX(Variables!$E$5:$E$105,MATCH($A21,Variables!$A$5:$A$105,0)) | K21: =LOWER(Settings!$C$4)&".mit."&$A21&IF($C21="","","."&$C21&"."&$B21)&IF(INDEX(Variables!$D$5:$D$105,MATCH($A21,Variables!$A$5:$A$105,0))="","","."&INDEX(Variables!$D$5:$D$105,MATCH($A21,Variables!$A$5:$A$105,0)))&"."&K$5 | L21: =INDEX(MTInputs!$J$1:$AZ$415,$D21,MATCH(L$5,MTInputs!$J$5:$AZ$5,0)) | M21: =INDEX(MTInputs!$J$1:$AZ$415,$D21,MATCH(M$5,MTInputs!$J$5:$AZ$5,0)) | N21: =INDEX(MTInputs!$J$1:$AZ$415,$D21,MATCH(N$5,MTInputs!$J$5:$AZ$5,0)) | O21: =INDEX(MTInputs!$J$1:$AZ$415,$D21,MATCH(O$5,MTInputs!$J$5:$AZ$5,0)) | P21: =INDEX(MTInputs!$J$1:$AZ$415,$D21,MATCH(P$5,MTInputs!$J$5:$AZ$5,0)) | Q21: =INDEX(MTInputs!$J$1:$AZ$415,$D21,MATCH(Q$5,MTInputs!$J$5:$AZ$5,0)) | R21: =INDEX(MTInputs!$J$1:$AZ$415,$D21,MATCH(R$5,MTInputs!$J$5:$AZ$5,0)) | S21: =INDEX(MTInputs!$J$1:$AZ$415,$D21,MATCH(S$5,MTInputs!$J$5:$AZ$5,0)) | ... AD21: =INDEX(MTInputs!$J$1:$AZ$415,$D21,MATCH(AD$5,MTInputs!$J$5:$AZ$5,0)) | AE21: =LOWER(Settings!$C$4)&".mit."&$A21&IF($C21="","","."&$C21&"."&$B21)&IF(INDEX(Variables!$D$5:$D$105,MATCH($A21,Variables!$A$5:$A$105,0))="","","."&INDEX(Variables!$D$5:$D$105,MATCH($A21,Variables!$A$5:$A$105,0)))&"."&AE$5 | AF21: =INDEX(MTInputs!$J$1:$AZ$415,$D21,MATCH(AF$5,MTInputs!$J$5:$AZ$5,0)) | AG21: =INDEX(MTInputs!$J$1:$AZ$415,$D21,MATCH(AG$5,MTInputs!$J$5:$AZ$5,0)) | AH21: =INDEX(MTInputs!$J$1:$AZ$415,$D21,MATCH(AH$5,MTInputs!$J$5:$AZ$5,0)) | AI21: =INDEX(MTInputs!$J$1:$AZ$415,$D21,MATCH(AI$5,MTInputs!$J$5:$AZ$5,0)) | AJ21: =INDEX(MTInputs!$J$1:$AZ$415,$D21,MATCH(AJ$5,MTInputs!$J$5:$AZ$5,0)) | AK21: =INDEX(MTInputs!$J$1:$AZ$415,$D21,MATCH(AK$5,MTInputs!$J$5:$AZ$5,0)) | AL21: =INDEX(MTInputs!$J$1:$AZ$415,$D21,MATCH(AL$5,MTInputs!$J$5:$AZ$5,0)) | AM21: =INDEX(MTInputs!$J$1:$AZ$415,$D21,MATCH(AM$5,MTInputs!$J$5:$AZ$5,0)) | ... AX21: =INDEX(MTInputs!$J$1:$AZ$415,$D21,MATCH(AX$5,MTInputs!$J$5:$AZ$5,0))
A22: ctcov | B22: nga | C22: all | D22: 24 | H22: =INDEX(Variables!$B$5:$B$105,MATCH($A22,Variables!$A$5:$A$105,0))&IF($C22="",""," | "&INDEX(Mapping!$B$5:$B$26,MATCH($C22,Mapping!$A$5:$A$26,0))&" | "&INDEX(Mapping!$B$30:$B$41,MATCH($B22,Mapping!$A$30:$A$41,0))) | I22: =INDEX(Variables!$C$5:$C$105,MATCH($A22,Variables!$A$5:$A$105,0)) | J22: =INDEX(Variables!$E$5:$E$105,MATCH($A22,Variables!$A$5:$A$105,0)) | K22: =LOWER(Settings!$C$4)&".mit."&$A22&IF($C22="","","."&$C22&"."&$B22)&IF(INDEX(Variables!$D$5:$D$105,MATCH($A22,Variables!$A$5:$A$105,0))="","","."&INDEX(Variables!$D$5:$D$105,MATCH($A22,Variables!$A$5:$A$105,0)))&"."&K$5 | L22: =INDEX(MTInputs!$J$1:$AZ$415,$D22,MATCH(L$5,MTInputs!$J$5:$AZ$5,0)) | M22: =INDEX(MTInputs!$J$1:$AZ$415,$D22,MATCH(M$5,MTInputs!$J$5:$AZ$5,0)) | N22: =INDEX(MTInputs!$J$1:$AZ$415,$D22,MATCH(N$5,MTInputs!$J$5:$AZ$5,0)) | O22: =INDEX(MTInputs!$J$1:$AZ$415,$D22,MATCH(O$5,MTInputs!$J$5:$AZ$5,0)) | P22: =INDEX(MTInputs!$J$1:$AZ$415,$D22,MATCH(P$5,MTInputs!$J$5:$AZ$5,0)) | Q22: =INDEX(MTInputs!$J$1:$AZ$415,$D22,MATCH(Q$5,MTInputs!$J$5:$AZ$5,0)) | R22: =INDEX(MTInputs!$J$1:$AZ$415,$D22,MATCH(R$5,MTInputs!$J$5:$AZ$5,0)) | S22: =INDEX(MTInputs!$J$1:$AZ$415,$D22,MATCH(S$5,MTInputs!$J$5:$AZ$5,0)) | ... AD22: =INDEX(MTInputs!$J$1:$AZ$415,$D22,MATCH(AD$5,MTInputs!$J$5:$AZ$5,0)) | AE22: =LOWER(Settings!$C$4)&".mit."&$A22&IF($C22="","","."&$C22&"."&$B22)&IF(INDEX(Variables!$D$5:$D$105,MATCH($A22,Variables!$A$5:$A$105,0))="","","."&INDEX(Variables!$D$5:$D$105,MATCH($A22,Variables!$A$5:$A$105,0)))&"."&AE$5 | AF22: =INDEX(MTInputs!$J$1:$AZ$415,$D22,MATCH(AF$5,MTInputs!$J$5:$AZ$5,0)) | AG22: =INDEX(MTInputs!$J$1:$AZ$415,$D22,MATCH(AG$5,MTInputs!$J$5:$AZ$5,0)) | AH22: =INDEX(MTInputs!$J$1:$AZ$415,$D22,MATCH(AH$5,MTInputs!$J$5:$AZ$5,0)) | AI22: =INDEX(MTInputs!$J$1:$AZ$415,$D22,MATCH(AI$5,MTInputs!$J$5:$AZ$5,0)) | AJ22: =INDEX(MTInputs!$J$1:$AZ$415,$D22,MATCH(AJ$5,MTInputs!$J$5:$AZ$5,0)) | AK22: =INDEX(MTInputs!$J$1:$AZ$415,$D22,MATCH(AK$5,MTInputs!$J$5:$AZ$5,0)) | AL22: =INDEX(MTInputs!$J$1:$AZ$415,$D22,MATCH(AL$5,MTInputs!$J$5:$AZ$5,0)) | AM22: =INDEX(MTInputs!$J$1:$AZ$415,$D22,MATCH(AM$5,MTInputs!$J$5:$AZ$5,0)) | ... AX22: =INDEX(MTInputs!$J$1:$AZ$415,$D22,MATCH(AX$5,MTInputs!$J$5:$AZ$5,0))
A23: ctcov | B23: gso | C23: all | D23: 25 | H23: =INDEX(Variables!$B$5:$B$105,MATCH($A23,Variables!$A$5:$A$105,0))&IF($C23="",""," | "&INDEX(Mapping!$B$5:$B$26,MATCH($C23,Mapping!$A$5:$A$26,0))&" | "&INDEX(Mapping!$B$30:$B$41,MATCH($B23,Mapping!$A$30:$A$41,0))) | I23: =INDEX(Variables!$C$5:$C$105,MATCH($A23,Variables!$A$5:$A$105,0)) | J23: =INDEX(Variables!$E$5:$E$105,MATCH($A23,Variables!$A$5:$A$105,0)) | K23: =LOWER(Settings!$C$4)&".mit."&$A23&IF($C23="","","."&$C23&"."&$B23)&IF(INDEX(Variables!$D$5:$D$105,MATCH($A23,Variables!$A$5:$A$105,0))="","","."&INDEX(Variables!$D$5:$D$105,MATCH($A23,Variables!$A$5:$A$105,0)))&"."&K$5 | L23: =INDEX(MTInputs!$J$1:$AZ$415,$D23,MATCH(L$5,MTInputs!$J$5:$AZ$5,0)) | M23: =INDEX(MTInputs!$J$1:$AZ$415,$D23,MATCH(M$5,MTInputs!$J$5:$AZ$5,0)) | N23: =INDEX(MTInputs!$J$1:$AZ$415,$D23,MATCH(N$5,MTInputs!$J$5:$AZ$5,0)) | O23: =INDEX(MTInputs!$J$1:$AZ$415,$D23,MATCH(O$5,MTInputs!$J$5:$AZ$5,0)) | P23: =INDEX(MTInputs!$J$1:$AZ$415,$D23,MATCH(P$5,MTInputs!$J$5:$AZ$5,0)) | Q23: =INDEX(MTInputs!$J$1:$AZ$415,$D23,MATCH(Q$5,MTInputs!$J$5:$AZ$5,0)) | R23: =INDEX(MTInputs!$J$1:$AZ$415,$D23,MATCH(R$5,MTInputs!$J$5:$AZ$5,0)) | S23: =INDEX(MTInputs!$J$1:$AZ$415,$D23,MATCH(S$5,MTInputs!$J$5:$AZ$5,0)) | ... AD23: =INDEX(MTInputs!$J$1:$AZ$415,$D23,MATCH(AD$5,MTInputs!$J$5:$AZ$5,0)) | AE23: =LOWER(Settings!$C$4)&".mit."&$A23&IF($C23="","","."&$C23&"."&$B23)&IF(INDEX(Variables!$D$5:$D$105,MATCH($A23,Variables!$A$5:$A$105,0))="","","."&INDEX(Variables!$D$5:$D$105,MATCH($A23,Variables!$A$5:$A$105,0)))&"."&AE$5 | AF23: =INDEX(MTInputs!$J$1:$AZ$415,$D23,MATCH(AF$5,MTInputs!$J$5:$AZ$5,0)) | AG23: =INDEX(MTInputs!$J$1:$AZ$415,$D23,MATCH(AG$5,MTInputs!$J$5:$AZ$5,0)) | AH23: =INDEX(MTInputs!$J$1:$AZ$415,$D23,MATCH(AH$5,MTInputs!$J$5:$AZ$5,0)) | AI23: =INDEX(MTInputs!$J$1:$AZ$415,$D23,MATCH(AI$5,MTInputs!$J$5:$AZ$5,0)) | AJ23: =INDEX(MTInputs!$J$1:$AZ$415,$D23,MATCH(AJ$5,MTInputs!$J$5:$AZ$5,0)) | AK23: =INDEX(MTInputs!$J$1:$AZ$415,$D23,MATCH(AK$5,MTInputs!$J$5:$AZ$5,0)) | AL23: =INDEX(MTInputs!$J$1:$AZ$415,$D23,MATCH(AL$5,MTInputs!$J$5:$AZ$5,0)) | AM23: =INDEX(MTInputs!$J$1:$AZ$415,$D23,MATCH(AM$5,MTInputs!$J$5:$AZ$5,0)) | ... AX23: =INDEX(MTInputs!$J$1:$AZ$415,$D23,MATCH(AX$5,MTInputs!$J$5:$AZ$5,0))
A24: ctcov | B24: die | C24: all | D24: 26 | H24: =INDEX(Variables!$B$5:$B$105,MATCH($A24,Variables!$A$5:$A$105,0))&IF($C24="",""," | "&INDEX(Mapping!$B$5:$B$26,MATCH($C24,Mapping!$A$5:$A$26,0))&" | "&INDEX(Mapping!$B$30:$B$41,MATCH($B24,Mapping!$A$30:$A$41,0))) | I24: =INDEX(Variables!$C$5:$C$105,MATCH($A24,Variables!$A$5:$A$105,0)) | J24: =INDEX(Variables!$E$5:$E$105,MATCH($A24,Variables!$A$5:$A$105,0)) | K24: =LOWER(Settings!$C$4)&".mit."&$A24&IF($C24="","","."&$C24&"."&$B24)&IF(INDEX(Variables!$D$5:$D$105,MATCH($A24,Variables!$A$5:$A$105,0))="","","."&INDEX(Variables!$D$5:$D$105,MATCH($A24,Variables!$A$5:$A$105,0)))&"."&K$5 | L24: =INDEX(MTInputs!$J$1:$AZ$415,$D24,MATCH(L$5,MTInputs!$J$5:$AZ$5,0)) | M24: =INDEX(MTInputs!$J$1:$AZ$415,$D24,MATCH(M$5,MTInputs!$J$5:$AZ$5,0)) | N24: =INDEX(MTInputs!$J$1:$AZ$415,$D24,MATCH(N$5,MTInputs!$J$5:$AZ$5,0)) | O24: =INDEX(MTInputs!$J$1:$AZ$415,$D24,MATCH(O$5,MTInputs!$J$5:$AZ$5,0)) | P24: =INDEX(MTInputs!$J$1:$AZ$415,$D24,MATCH(P$5,MTInputs!$J$5:$AZ$5,0)) | Q24: =INDEX(MTInputs!$J$1:$AZ$415,$D24,MATCH(Q$5,MTInputs!$J$5:$AZ$5,0)) | R24: =INDEX(MTInputs!$J$1:$AZ$415,$D24,MATCH(R$5,MTInputs!$J$5:$AZ$5,0)) | S24: =INDEX(MTInputs!$J$1:$AZ$415,$D24,MATCH(S$5,MTInputs!$J$5:$AZ$5,0)) | ... AD24: =INDEX(MTInputs!$J$1:$AZ$415,$D24,MATCH(AD$5,MTInputs!$J$5:$AZ$5,0)) | AE24: =LOWER(Settings!$C$4)&".mit."&$A24&IF($C24="","","."&$C24&"."&$B24)&IF(INDEX(Variables!$D$5:$D$105,MATCH($A24,Variables!$A$5:$A$105,0))="","","."&INDEX(Variables!$D$5:$D$105,MATCH($A24,Variables!$A$5:$A$105,0)))&"."&AE$5 | AF24: =INDEX(MTInputs!$J$1:$AZ$415,$D24,MATCH(AF$5,MTInputs!$J$5:$AZ$5,0)) | AG24: =INDEX(MTInputs!$J$1:$AZ$415,$D24,MATCH(AG$5,MTInputs!$J$5:$AZ$5,0)) | AH24: =INDEX(MTInputs!$J$1:$AZ$415,$D24,MATCH(AH$5,MTInputs!$J$5:$AZ$5,0)) | AI24: =INDEX(MTInputs!$J$1:$AZ$415,$D24,MATCH(AI$5,MTInputs!$J$5:$AZ$5,0)) | AJ24: =INDEX(MTInputs!$J$1:$AZ$415,$D24,MATCH(AJ$5,MTInputs!$J$5:$AZ$5,0)) | AK24: =INDEX(MTInputs!$J$1:$AZ$415,$D24,MATCH(AK$5,MTInputs!$J$5:$AZ$5,0)) | AL24: =INDEX(MTInputs!$J$1:$AZ$415,$D24,MATCH(AL$5,MTInputs!$J$5:$AZ$5,0)) | AM24: =INDEX(MTInputs!$J$1:$AZ$415,$D24,MATCH(AM$5,MTInputs!$J$5:$AZ$5,0)) | ... AX24: =INDEX(MTInputs!$J$1:$AZ$415,$D24,MATCH(AX$5,MTInputs!$J$5:$AZ$5,0))
A25: ctcov | B25: lpg | C25: all | D25: 27 | H25: =INDEX(Variables!$B$5:$B$105,MATCH($A25,Variables!$A$5:$A$105,0))&IF($C25="",""," | "&INDEX(Mapping!$B$5:$B$26,MATCH($C25,Mapping!$A$5:$A$26,0))&" | "&INDEX(Mapping!$B$30:$B$41,MATCH($B25,Mapping!$A$30:$A$41,0))) | I25: =INDEX(Variables!$C$5:$C$105,MATCH($A25,Variables!$A$5:$A$105,0)) | J25: =INDEX(Variables!$E$5:$E$105,MATCH($A25,Variables!$A$5:$A$105,0)) | K25: =LOWER(Settings!$C$4)&".mit."&$A25&IF($C25="","","."&$C25&"."&$B25)&IF(INDEX(Variables!$D$5:$D$105,MATCH($A25,Variables!$A$5:$A$105,0))="","","."&INDEX(Variables!$D$5:$D$105,MATCH($A25,Variables!$A$5:$A$105,0)))&"."&K$5 | L25: =INDEX(MTInputs!$J$1:$AZ$415,$D25,MATCH(L$5,MTInputs!$J$5:$AZ$5,0)) | M25: =INDEX(MTInputs!$J$1:$AZ$415,$D25,MATCH(M$5,MTInputs!$J$5:$AZ$5,0)) | N25: =INDEX(MTInputs!$J$1:$AZ$415,$D25,MATCH(N$5,MTInputs!$J$5:$AZ$5,0)) | O25: =INDEX(MTInputs!$J$1:$AZ$415,$D25,MATCH(O$5,MTInputs!$J$5:$AZ$5,0)) | P25: =INDEX(MTInputs!$J$1:$AZ$415,$D25,MATCH(P$5,MTInputs!$J$5:$AZ$5,0)) | Q25: =INDEX(MTInputs!$J$1:$AZ$415,$D25,MATCH(Q$5,MTInputs!$J$5:$AZ$5,0)) | R25: =INDEX(MTInputs!$J$1:$AZ$415,$D25,MATCH(R$5,MTInputs!$J$5:$AZ$5,0)) | S25: =INDEX(MTInputs!$J$1:$AZ$415,$D25,MATCH(S$5,MTInputs!$J$5:$AZ$5,0)) | ... AD25: =INDEX(MTInputs!$J$1:$AZ$415,$D25,MATCH(AD$5,MTInputs!$J$5:$AZ$5,0)) | AE25: =LOWER(Settings!$C$4)&".mit."&$A25&IF($C25="","","."&$C25&"."&$B25)&IF(INDEX(Variables!$D$5:$D$105,MATCH($A25,Variables!$A$5:$A$105,0))="","","."&INDEX(Variables!$D$5:$D$105,MATCH($A25,Variables!$A$5:$A$105,0)))&"."&AE$5 | AF25: =INDEX(MTInputs!$J$1:$AZ$415,$D25,MATCH(AF$5,MTInputs!$J$5:$AZ$5,0)) | AG25: =INDEX(MTInputs!$J$1:$AZ$415,$D25,MATCH(AG$5,MTInputs!$J$5:$AZ$5,0)) | AH25: =INDEX(MTInputs!$J$1:$AZ$415,$D25,MATCH(AH$5,MTInputs!$J$5:$AZ$5,0)) | AI25: =INDEX(MTInputs!$J$1:$AZ$415,$D25,MATCH(AI$5,MTInputs!$J$5:$AZ$5,0)) | AJ25: =INDEX(MTInputs!$J$1:$AZ$415,$D25,MATCH(AJ$5,MTInputs!$J$5:$AZ$5,0)) | AK25: =INDEX(MTInputs!$J$1:$AZ$415,$D25,MATCH(AK$5,MTInputs!$J$5:$AZ$5,0)) | AL25: =INDEX(MTInputs!$J$1:$AZ$415,$D25,MATCH(AL$5,MTInputs!$J$5:$AZ$5,0)) | AM25: =INDEX(MTInputs!$J$1:$AZ$415,$D25,MATCH(AM$5,MTInputs!$J$5:$AZ$5,0)) | ... AX25: =INDEX(MTInputs!$J$1:$AZ$415,$D25,MATCH(AX$5,MTInputs!$J$5:$AZ$5,0))
