Workbook

Sheet Results
A1: Egypt carbon pricing and CBAM: results, 2030
A2: Results only. Every number is a link (green) to the Calculations sheet, where the working is explained row by row. Columns C to H are the six scenarios.
A4: Results in 2030 | B4: Unit | C4: =Calculations!C66 -> 1A | D4: =Calculations!D66 -> 2A | E4: =Calculations!E66 -> 2B | F4: =Calculations!F66 -> 3A | G4: =Calculations!G66 -> 3B | H4: =Calculations!H66 -> 3C
A5: Scenario | C5: =Calculations!C67 -> Comprehensive levy | D5: =Calculations!D67 -> Upstream levy | E5: =Calculations!E67 -> Upstream levy, household refunds | F5: =Calculations!F67 -> Downstream industry price | G5: =Calculations!G67 -> 3A with feebate (revenue neutral) | H5: =Calculations!H67 -> 3A with abatement fund
A6: What is priced | C6: Energy CO2, all sectors, plus CBAM process emissions | D6: Energy CO2, all sectors | E6: Energy CO2, all sectors | F6: CBAM products: energy and process emissions | G6: As 3A | H6: As 3A | I6: CBAM products: the seven EU CBAM goods made in Egypt. In 3A to 3C, diesel and gasoline are excluded from the price.
A7: Use of revenue | C7: Public investment (1) | D7: Public investment (1) | E7: Household refunds (2) | F7: Household refunds (2) | G7: Returned to firms per unit of output (feebate) | H7: Abatement fund for industry | I7: (1) Public investment raises GDP (in CPAT, 2030 GDP is about 0.4% higher than with household refunds), which raises energy demand; this is why 2A cuts less than 2B. (2) Refunds to the bottom 40% of households, assuming 90% coverage.
A8: Carbon price ($/t CO2) | B8: $/t | C8: =Calculations!C73 -> 20 | D8: =Calculations!D73 -> 20 | E8: =Calculations!E73 -> 20 | F8: =Calculations!F73 -> 20 | G8: =Calculations!G73 -> 20 | H8: =Calculations!H73 -> 20 | I8: Carbon price in 2030 (input, Calculations 2a).
A9: Share of national emissions priced | B9: % | C9: =Calculations!C35 -> 0.71499793 | D9: =Calculations!D35 -> 0.6419205 | E9: =Calculations!E35 -> 0.6419725 | F9: =Calculations!F35 -> 0.14998937 | G9: =Calculations!G35 -> 0.14998937 | H9: =Calculations!H35 -> 0.14998937 | I9: Share of national emissions that face a carbon price. National emissions use Egypt's 2022 inventory shares (energy CO2 about 65% of the total; see Calculations, Walk 2). 3A to 3C price the seven CBAM products only, so their coverage is the block's emissions (65.3 Mt in 2030) ÷ national GHG (Walk 5).
A10: Carbon revenue, $bn | B10: $bn | C10: =Calculations!C25 -> 5.5989499 | D10: =Calculations!D25 -> 5.0351389 | E10: =Calculations!E25 -> 4.9651389 | F10: =Calculations!F25 -> 1.1481353 | G10: =Calculations!G25 -> 0 | H10: =Calculations!H25 -> 0 | I10: Carbon revenue in 2030. Gross where revenue is used for public investment (1A, 2A) or household refunds (2B, 3A): the figure is before the money is spent. Net where it is rebated to firms (3B) or put into a fund (3C), so these show zero.
A11: Emission cut, Mt CO2e | B11: Mt | C11: =Calculations!C12 -> 40.683839 | D11: =Calculations!D12 -> 37.546416 | E11: =Calculations!E12 -> 41.098416 | F11: =Calculations!F12 -> 7.8078388 | G11: =Calculations!G12 -> 5.7961617 | H11: =Calculations!H12 -> 12.972229 | I11: Cut in national GHG, adjusted for the CBAM block.
A12: Cut as share of national emissions | B12: % | C12: =Calculations!C17 -> 0.093474164 | D12: =Calculations!D17 -> 0.086265701 | E12: =Calculations!E17 -> 0.094426687 | F12: =Calculations!F17 -> 0.017939094 | G12: =Calculations!G17 -> 0.013317115 | H12: =Calculations!H17 -> 0.029804666 | I12: The cut as a share of baseline national GHG (435 Mt in 2030: CPAT's energy CO2 at the inventory's 65% share; CPAT's own total is 536 Mt).
A13: Share of heavy-industry emissions priced | B13: % | C13: =Calculations!C45 -> 1 | D13: =Calculations!D45 -> 0.4825602 | E13: =Calculations!E45 -> 0.4825602 | F13: =Calculations!F45 -> 1 | G13: =Calculations!G45 -> 1 | H13: =Calculations!H45 -> 1 | I13: Share of CBAM-block emissions that face the price.
A14: Heavy industry: total emissions | B14: % | C14: =Calculations!C43 -> -0.12062876 | D14: =Calculations!D43 -> -0.072568933 | E14: =Calculations!E43 -> -0.072568933 | F14: =Calculations!F43 -> -0.12062876 | G14: =Calculations!G43 -> -0.08869515 | H14: =Calculations!H43 -> -0.19811444 | I14: Total block emissions change: output and efficiency together.
A15: of which emissions intensity | B15: % | C15: =Calculations!C44 -> -0.088745466 | D15: =Calculations!D44 -> -0.055166747 | E15: =Calculations!E44 -> -0.055166747 | F15: =Calculations!F44 -> -0.088745466 | G15: =Calculations!G44 -> -0.08869515 | H15: =Calculations!H44 -> -0.16904055 | I15: Change in emissions per tonne of output, products weighted by their emissions at policy output.
A16: of which output, emissions-weighted | B16: % | C16: =(1+C14)/(1+C15)-1 -> -0.034988347 | D16: =(1+D14)/(1+D15)-1 -> -0.018418261 | E16: =(1+E14)/(1+E15)-1 -> -0.018418261 | F16: =(1+F14)/(1+F15)-1 -> -0.034988347 | G16: =(1+G14)/(1+G15)-1 -> 0 | H16: =(1+H14)/(1+H15)-1 -> -0.034988347 | I16: (1 + T) ÷ (1 + N) − 1: the output effect on block emissions, i.e. output change weighted by each product's emissions.
A17: EU border charge per tonne exported | B17: % | C17: =Calculations!C52 -> -0.38618183 | D17: =Calculations!D52 -> -0.20602871 | E17: =Calculations!E52 -> -0.20602871 | F17: =Calculations!F52 -> -0.38618183 | G17: =Calculations!G52 -> -0.083994426 | H17: =Calculations!H52 -> -0.43710282 | I17: Change in the obligation per tonne of EU exports. Credit rules: an explicit carbon price counts; an output-based rebate (3B) makes it ineligible; a decarbonization fund (3C) does not add to the price credited but does not invalidate it.
A18: of which emissions intensity of EU exports | B18: % | C18: =Calculations!C53 -> -0.083994426 | D18: =Calculations!D53 -> -0.055287267 | E18: =Calculations!E53 -> -0.055287267 | F18: =Calculations!F53 -> -0.083994426 | G18: =Calculations!G53 -> -0.083994426 | H18: =Calculations!H53 -> -0.15998421 | I18: Change in emissions per tonne of EU exports, products weighted by their EU exports.
A19: of which Egyptian carbon price credit | B19: % | C19: =Calculations!C54 -> -0.30218741 | D19: =Calculations!D54 -> -0.15074144 | E19: =Calculations!E54 -> -0.15074144 | F19: =Calculations!F54 -> -0.30218741 | G19: =Calculations!G54 -> 0 | H19: =Calculations!H54 -> -0.27711861 | I19: The EU deducts the carbon price effectively paid in Egypt: the carbon price weighted by its coverage. Under the current interpretation of the rules, an output-based rebate (3B) invalidates the credit; an abatement fund (3C) does not, but earns no extra credit.
A20: Premature deaths avoided in 2030 | B20: deaths | C20: =Calculations!C30 -> 1659.0841 | D20: =Calculations!D30 -> 1639.2941 | E20: =Calculations!E30 -> 1799.3912 | F20: =Calculations!F30 -> 60.623943 | G20: =Calculations!G30 -> 45.004282 | H20: =Calculations!H30 -> 100.72284 | I20: Deaths avoided in the year 2030 (annual, not cumulative) from lower local air pollution. 3A and 3C scale 3B by the total emission cut (see Calculations, Walk 4). In 1A to 2B, mostly from lower fuel use in food and agriculture (about 60% of the fall in fine-particle pollution in CPAT) and road transport (about 25%).
A22: Memo: checks
A23: Credit eligible (1 = yes) | B23: flag | C23: =Calculations!C55 -> 1 | D23: =Calculations!D55 -> 1 | E23: =Calculations!E55 -> 1 | F23: =Calculations!F55 -> 1 | G23: =Calculations!G55 -> 0 | H23: =Calculations!H55 -> 1 | I23: 0 in 3B: the output-based rebate makes the Egyptian price ineligible.
A24: Shortcut: obligation change = −r − (1 − r) × τ^EGY ÷ τ^EU | B24: % | C24: =Calculations!C63 -> -0.38618183 | D24: =Calculations!D63 -> -0.20568092 | E24: =Calculations!E63 -> -0.20568092 | F24: =Calculations!F63 -> -0.38618183 | G24: =Calculations!G63 -> -0.083994426 | H24: =Calculations!H63 -> -0.43710282 | I24: r is the fall in emissions per tonne of EU exports; τ^EGY = τ × S × (1 − θ), the Egyptian carbon price credited (feebates not creditable); τ^EU = γ × p^EU, the EU price after phase-in (0.485 × 125 ≈ 61). See Calculations, Walk 8.
A26: Scope: the CBAM block is the seven products with production in Egypt (BF-BOF steel is excluded as it has no output).
A27: Left out to keep it simple: solving the fund price (a fixed shadow price of $20 is used) and output effects of the fund.
A28: All six CPAT runs are final (raw results of 7 October). In 3A to 3C diesel and gasoline are excluded from the carbon price.
A29: Timing: results apply long-run responses in full by 2030. With a price rising linearly from 2026 to $20 in 2030, about 40% of the response is likely by 2030 (about 70% if the full price applies from 2027); see rows 31 to 51 and methodology Appendix H.
A31: Alternative: 2030 with partial adjustment (methodology Appendix H)
A32: Share of the long-run response achieved by 2030, k | B32: share | C32: 1 | I32: Input. Share of the long-run response reached by 2030. Published adjustment speeds (about a third of the remaining gap closed each year) give about 70% for a $20 price in place from 2027 and about 40% for a price rising linearly from zero in 2026 to $20 in 2030. Set to 100% to reproduce the main table.
A35: Results in 2030, partial adjustment | B35: Unit | C35: =C4 -> 1A | D35: =D4 -> 2A | E35: =E4 -> 2B | F35: =F4 -> 3A | G35: =G4 -> 3B | H35: =H4 -> 3C
A36: Scenario | C36: =C5 -> Comprehensive levy | D36: =D5 -> Upstream levy | E36: =E5 -> Upstream levy, household refunds | F36: =F5 -> Downstream industry price | G36: =G5 -> 3A with feebate (revenue neutral) | H36: =H5 -> 3A with abatement fund
A37: What is priced | C37: =C6 -> Energy CO2, all sectors, plus CBAM process emissions | D37: =D6 -> Energy CO2, all sectors | E37: =E6 -> Energy CO2, all sectors | F37: =F6 -> CBAM products: energy and process emissions | G37: =G6 -> As 3A | H37: =H6 -> As 3A | I37: CBAM products: the seven EU CBAM goods made in Egypt. In 3A to 3C, diesel and gasoline are excluded from the price.
A38: Use of revenue | C38: =C7 -> Public investment (1) | D38: =D7 -> Public investment (1) | E38: =E7 -> Household refunds (2) | F38: =F7 -> Household refunds (2) | G38: =G7 -> Returned to firms per unit of output (feebate) | H38: =H7 -> Abatement fund for industry | I38: (1) Public investment raises GDP (in CPAT, 2030 GDP is about 0.4% higher than with household refunds), which raises energy demand; this is why 2A cuts less than 2B. (2) Refunds to the bottom 40% of households, assuming 90% coverage.
A39: Carbon price ($/t CO2) | B39: $/t | C39: =C8 -> 20 | D39: =D8 -> 20 | E39: =E8 -> 20 | F39: =F8 -> 20 | G39: =G8 -> 20 | H39: =H8 -> 20 | I39: Unchanged.
A40: Share of national emissions priced | B40: % | C40: =C9 -> 0.71499793 | D40: =D9 -> 0.6419205 | E40: =E9 -> 0.6419725 | F40: =F9 -> 0.14998937 | G40: =G9 -> 0.14998937 | H40: =H9 -> 0.14998937 | I40: Unchanged.
A41: Carbon revenue, $bn | B41: $bn | C41: =IF(C10=0,0,C10+C$8*(1-$C$32)*C11/1000) -> 5.5989499 | D41: =IF(D10=0,0,D10+D$8*(1-$C$32)*D11/1000) -> 5.0351389 | E41: =IF(E10=0,0,E10+E$8*(1-$C$32)*E11/1000) -> 4.9651389 | F41: =IF(F10=0,0,F10+F$8*(1-$C$32)*F11/1000) -> 1.1481353 | G41: =IF(G10=0,0,G10+G$8*(1-$C$32)*G11/1000) -> 0 | H41: =IF(H10=0,0,H10+H$8*(1-$C$32)*H11/1000) -> 0 | I41: Main revenue plus τ × (1 − k) × cut: less abatement leaves more emissions to tax. Zero stays zero for 3B and 3C (net of refunds and fund).
A42: Emission cut, Mt CO2e | B42: Mt | C42: =$C$32*C11 -> 40.683839 | D42: =$C$32*D11 -> 37.546416 | E42: =$C$32*E11 -> 41.098416 | F42: =$C$32*F11 -> 7.8078388 | G42: =$C$32*G11 -> 5.7961617 | H42: =$C$32*H11 -> 12.972229 | I42: k × main cut.
A43: Cut as share of national emissions | B43: % | C43: =$C$32*C12 -> 0.093474164 | D43: =$C$32*D12 -> 0.086265701 | E43: =$C$32*E12 -> 0.094426687 | F43: =$C$32*F12 -> 0.017939094 | G43: =$C$32*G12 -> 0.013317115 | H43: =$C$32*H12 -> 0.029804666 | I43: k × main share.
A44: Share of heavy-industry emissions priced | B44: % | C44: =C13 -> 1 | D44: =D13 -> 0.4825602 | E44: =E13 -> 0.4825602 | F44: =F13 -> 1 | G44: =G13 -> 1 | H44: =H13 -> 1 | I44: Unchanged.
A45: Heavy industry: total emissions | B45: % | C45: =(1+C14)^$C$32-1 -> -0.12062876 | D45: =(1+D14)^$C$32-1 -> -0.072568933 | E45: =(1+E14)^$C$32-1 -> -0.072568933 | F45: =(1+F14)^$C$32-1 -> -0.12062876 | G45: =(1+G14)^$C$32-1 -> -0.08869515 | H45: =(1+H14)^$C$32-1 -> -0.19811444 | I45: (1 + main change)^k − 1.
A46: of which emissions intensity | B46: % | C46: =(1+C15)^$C$32-1 -> -0.088745466 | D46: =(1+D15)^$C$32-1 -> -0.055166747 | E46: =(1+E15)^$C$32-1 -> -0.055166747 | F46: =(1+F15)^$C$32-1 -> -0.088745466 | G46: =(1+G15)^$C$32-1 -> -0.08869515 | H46: =(1+H15)^$C$32-1 -> -0.16904055 | I46: (1 + main change)^k − 1.
...

Sheet Calculations
A1: Egypt carbon pricing and CBAM: calculations, 2030
A2: THE STORY. For each result we start from the CPAT answer and make a few adjustments for the seven CBAM products, which CPAT only treats roughly. Section 1 walks through each result: CPAT, then Adjustment 1, 2, 3, then the result. The Results sheet repeats the final lines. Section 2 holds the inputs (blue). Section 3 gathers the numbers the walks use (click + at the left to open the detail). The product-by-product work is on the Product detail sheet. Columns C to H are the six scenarios; column I explains each row.
A3: Scenario | C3: =C66 -> 1A | D3: =D66 -> 2A | E3: =E66 -> 2B | F3: =F66 -> 3A | G3: =G66 -> 3B | H3: =H66 -> 3C
A4: 1. THE WALKS: from the CPAT answer to each result
A5: Each walk starts from what CPAT says, then makes the adjustments for the CBAM products, one line each. The last line (bold) is the result shown on the Results sheet.
A6: Walk 1. Emission cut, −ΔE_tot
A7: CPAT gives a national cut. It already includes a rough cut for the CBAM products, so we take that out and put in the cut we calculate for them: fuel first, then process.
A8: CPAT: national emission cut | B8: Mt | C8: =C115 -> 37.757 | D8: =D115 -> 37.757 | E8: =E115 -> 41.309 | F8: =F115 -> 4.881 | G8: =G115 -> 2.058 | H8: =H115 -> 5.143 | I8: From CPAT.
A9: Adjustment 1: remove CPAT's own cut for the CBAM products | B9: Mt | C9: =C136+C137 -> -4.948 | D9: =D136+D137 -> -4.948 | E9: =E136+E137 -> -4.948 | F9: =F136+F137 -> -4.948 | G9: =G136+G137 -> -2.052 | H9: =H136+H137 -> -5.104 | I9: What CPAT assumed for fuel and process emissions of the block (3d).
A10: Adjustment 2: add the block's fuel cut | B10: Mt | C10: =-C134 -> 4.6029975 | D10: =-D134 -> 4.2590572 | E10: =-E134 -> 4.2590572 | F10: =-F134 -> 4.6029975 | G10: =-G134 -> 3.61319 | H10: =-H134 -> 7.719358 | I10: Our calculated fuel cut: price response, output response and fund.
A11: Adjustment 3: add the block's process cut | B11: Mt | C11: =-C135 -> 3.2718412 | D11: =-D135 -> 0.4783592 | E11: =-E135 -> 0.4783592 | F11: =-F135 -> 3.2718412 | G11: =-G135 -> 2.1769717 | H11: =-H135 -> 5.2138708 | I11: Our calculated process cut (zero unless process emissions are priced, or the fund applies).
A12: Emission cut, −ΔE_tot | B12: Mt | C12: =SUM(C8:C11) -> 40.683839 | D12: =SUM(D8:D11) -> 37.546416 | E12: =SUM(E8:E11) -> 41.098416 | F12: =SUM(F8:F11) -> 7.8078388 | G12: =SUM(G8:G11) -> 5.7961617 | H12: =SUM(H8:H11) -> 12.972229 | I12: Sum of the lines above.
A13: Walk 2. Cut as a share of national GHG, −ΔE_tot/E^0_tot
A14: The cut from Walk 1 divided by baseline national GHG. National GHG keeps CPAT's 2030 energy CO2 but uses the 2022 inventory's energy share (65%).
A15: Emission cut, −ΔE_tot | B15: Mt | C15: =C12 -> 40.683839 | D15: =D12 -> 37.546416 | E15: =E12 -> 41.098416 | F15: =F12 -> 7.8078388 | G15: =G12 -> 5.7961617 | H15: =H12 -> 12.972229 | I15: From Walk 1.
A16: Baseline national GHG, E^0_tot (inventory shares) | B16: Mt | C16: =C94/$C$85 -> 435.24154 | D16: =D94/$C$85 -> 435.24154 | E16: =E94/$C$85 -> 435.24154 | F16: =F94/$C$85 -> 435.24154 | G16: =G94/$C$85 -> 435.24154 | H16: =H94/$C$85 -> 435.24154 | I16: CPAT baseline energy CO2 ÷ its share of national GHG in Egypt's 2022 inventory (65%, input in 2b). Replaces CPAT's own total (row 92), which has more waste and process emissions than the inventory.
A17: Cut, % of national GHG, −ΔE_tot/E^0_tot | B17: % | C17: =C15/C16 -> 0.093474164 | D17: =D15/D16 -> 0.086265701 | E17: =E15/E16 -> 0.094426687 | F17: =F15/F16 -> 0.017939094 | G17: =G15/G16 -> 0.013317115 | H17: =H15/H16 -> 0.029804666 | I17: K ÷ baseline GHG.
A18: Walk 3. Carbon revenue, R
A19: CPAT gives the receipts it collects. We correct the part that comes from the CBAM products, add fees on their process emissions, and subtract anything handed back (feebate refund, fund).
A20: CPAT: carbon receipts | B20: US$bn | C20: =C117 -> 5.07 | D20: =D117 -> 5.07 | E20: =E117 -> 5 | F20: =F117 -> 0.32 | G20: =G117 -> 0 | H20: =H117 -> 0.32 | I20: From CPAT.
A21: Adjustment 1: correct fuel payments for the CBAM products | B21: US$bn | C21: =IF(C$72=1,C139-C117,C$73*C138/1000) -> -0.041739951 | D21: =IF(D$72=1,D139-D117,D$73*D138/1000) -> -0.034861144 | E21: =IF(E$72=1,E139-E117,E$73*E138/1000) -> -0.034861144 | F21: =IF(F$72=1,F139-F117,F$73*F138/1000) -> 0.25744552 | G21: =IF(G$72=1,G139-G117,G$73*G138/1000) -> 0.59724167 | H21: =IF(H$72=1,H139-H117,H$73*H138/1000) -> 0.19511831 | I21: CBAM-sector-only runs: replace CPAT receipts by the block's own fuel payments. Full-coverage runs: price × fuel adjustment.
A22: Adjustment 2: add fees on process emissions | B22: US$bn | C22: =C140 -> 0.57068981 | D22: =D140 -> 0 | E22: =E140 -> 0 | F22: =F140 -> 0.57068981 | G22: =G140 -> 0.5925872 | H22: =H140 -> 0.53184922 | I22: Zero where process emissions are not priced.
A23: Adjustment 3: subtract the feebate refund | B23: US$bn | C23: =-C141 -> 0 | D23: =-D141 -> 0 | E23: =-E141 -> 0 | F23: =-F141 -> 0 | G23: =-G141 -> -1.1898289 | H23: =-H141 -> 0 | I23: 3B only.
A24: Adjustment 4: subtract the fund outlay | B24: US$bn | C24: =-C142 -> 0 | D24: =-D142 -> 0 | E24: =-E142 -> 0 | F24: =-F142 -> 0 | G24: =-G142 -> 0 | H24: =-H142 -> -1.0469675 | I24: 3C only.
A25: Carbon revenue, R | B25: US$bn | C25: =SUM(C20:C24) -> 5.5989499 | D25: =SUM(D20:D24) -> 5.0351389 | E25: =SUM(E20:E24) -> 4.9651389 | F25: =SUM(F20:F24) -> 1.1481353 | G25: =SUM(G20:G24) -> 0 | H25: =SUM(H20:H24) -> 0 | I25: Sum of the lines above.
A26: Walk 4. Premature deaths avoided, D
A27: CPAT reports deaths avoided in each year; we use 2030 (annual, not cumulative). We scale CPAT's count by the block's fuel adjustment. In 3A and 3C, CPAT's counts are distorted by fuel switching (they even show more deaths), so their deaths avoided are 3B's, scaled by the total emission cut (K) relative to 3B.
A28: CPAT: deaths avoided | B28: deaths | C28: =C118 -> 1539 | D28: =D118 -> 1539 | E28: =E118 -> 1698 | F28: =F118 -> -38 | G28: =G118 -> 13 | H28: =H118 -> -30 | I28: From CPAT: deaths averted in 2030 by age group (annual, not cumulative).
A29: Adjustment 1: deaths from the block's fuel adjustment | B29: deaths | C29: =IF(C116=0,$C$119*C138,C118*C138/C116) -> 120.08409 | D29: =IF(D116=0,$C$119*D138,D118*D138/D116) -> 100.29405 | E29: =IF(E116=0,$C$119*E138,E118*E138/E116) -> 101.39122 | F29: =$G$30*F12/$G$12-F118 -> 98.623943 | G29: =IF(G116=0,$C$119*G138,G118*G138/G116) -> 32.004282 | H29: =$G$30*H12/$G$12-H118 -> 130.72284 | I29: 1A to 2B and 3B: CPAT deaths × (1 + fuel adjustment ÷ CPAT energy CO2 change). 3A and 3C: 3B deaths avoided × (scenario K ÷ 3B K), minus CPAT's own count.
A30: Premature deaths avoided, D | B30: deaths | C30: =SUM(C28:C29) -> 1659.0841 | D30: =SUM(D28:D29) -> 1639.2941 | E30: =SUM(E28:E29) -> 1799.3912 | F30: =SUM(F28:F29) -> 60.623943 | G30: =SUM(G28:G29) -> 45.004282 | H30: =SUM(H28:H29) -> 100.72284 | I30: Sum of the lines above.
A31: Walk 5. Coverage of national GHG, C
A32: 1A to 2B: CPAT tells us how much of energy CO2 is priced, and we add the CBAM products' process emissions when they are priced. 3A to 3C: coverage is the CBAM block's own emissions. All are shares of national GHG as defined in Walk 2 (inventory shares).
A33: CPAT: priced energy CO2 as a share of national GHG | B33: % | C33: =C91*C94/C16 -> 0.6419205 | D33: =D91*D94/D16 -> 0.6419205 | E33: =E91*E94/E16 -> 0.6419725 | F33: =F91*F94/F16 -> 0.035984 | G33: =G91*G94/G16 -> 0.039091 | H33: =H91*H94/H16 -> 0.035971 | I33: CPAT coverage × baseline energy CO2 ÷ national GHG (Walk 2).
A34: Adjustment 1: add CBAM process emissions, if priced | B34: % | C34: =C$69*C122/C16 -> 0.073077427 | D34: =D$69*D122/D16 -> 0 | E34: =E$69*E122/E16 -> 0 | F34: =F$69*F122/F16 -> 0.073077427 | G34: =G$69*G122/G16 -> 0.073077427 | H34: =H$69*H122/H16 -> 0.073077427 | I34: Zero where process emissions are not priced.
A35: Coverage of national GHG, C | B35: % | C35: =IF(C$72=1,(C121+C122)/C16,SUM(C33:C34)) -> 0.71499793 | D35: =IF(D$72=1,(D121+D122)/D16,SUM(D33:D34)) -> 0.6419205 | E35: =IF(E$72=1,(E121+E122)/E16,SUM(E33:E34)) -> 0.6419725 | F35: =IF(F$72=1,(F121+F122)/F16,SUM(F33:F34)) -> 0.14998937 | G35: =IF(G$72=1,(G121+G122)/G16,SUM(G33:G34)) -> 0.14998937 | H35: =IF(H$72=1,(H121+H122)/H16,SUM(H33:H34)) -> 0.14998937 | I35: 1A to 2B: CPAT's priced energy CO2 plus CBAM process emissions if priced. 3A to 3C price the seven CBAM products only, so coverage is the block's baseline emissions (fuel plus process) ÷ national GHG. CPAT cannot isolate these products: its sub-industry energy data for Egypt are empty except iron and steel (methodology Appendix G).
A36: Walk 6. CBAM block emissions (ΔE_CBAM/E^0_CBAM, I, S)
A37: We start from baseline emissions of the seven products and add the effect of lower output, then of higher fuel efficiency, then of lower process emissions per tonne.
A38: Baseline block emissions | B38: Mt | C38: =C121+C122 -> 65.281605 | D38: =D121+D122 -> 65.281605 | E38: =E121+E122 -> 65.281605 | F38: =F121+F122 -> 65.281605 | G38: =G121+G122 -> 65.281605 | H38: =H121+H122 -> 65.281605 | I38: Fuel plus process, from Product detail.
A39: Adjustment 1: output effect | B39: Mt | C39: =(C125+C126)-C38 -> -2.2840954 | D39: =(D125+D126)-D38 -> -1.2023737 | E39: =(E125+E126)-E38 -> -1.2023737 | F39: =(F125+F126)-F38 -> -2.2840954 | G39: =(G125+G126)-G38 -> 0 | H39: =(H125+H126)-H38 -> -2.2840954 | I39: Less output at baseline intensity. Driven by the product elasticities.
A40: Adjustment 2: fuel efficiency effect | B40: Mt | C40: =C123-C125 -> -3.4934274 | D40: =D123-D125 -> -3.5350428 | E40: =E123-E125 -> -3.5350428 | F40: =F123-F125 -> -3.4934274 | G40: =G123-G125 -> -3.61319 | H40: =H123-H125 -> -6.6097879 | I40: Cleaner fuel use per tonne. Includes the fund.
...

Sheet Product detail
A1: Egypt CBAM block: calculations for each product, 2030
A2: This sheet holds the seven-product calculation. Inputs (blue) come first, then the baseline, then six steps, each a table with products in rows and scenarios in columns. The last block adds the products up into the few totals that the Calculations sheet uses. Scenario settings and parameters are linked in green from the Calculations sheet.
A4: A. Linked settings (from the Calculations sheet)
A5: Scenario | C5: =Calculations!C66 -> 1A | D5: =Calculations!D66 -> 2A | E5: =Calculations!E66 -> 2B | F5: =Calculations!F66 -> 3A | G5: =Calculations!G66 -> 3B | H5: =Calculations!H66 -> 3C
A6: Carbon price on the CBAM block, τ | B6: US$/t | C6: =Calculations!C73 -> 20 | D6: =Calculations!D73 -> 20 | E6: =Calculations!E73 -> 20 | F6: =Calculations!F73 -> 20 | G6: =Calculations!G73 -> 20 | H6: =Calculations!H73 -> 20 | I6: Linked from the Calculations sheet.
A7: Process emissions priced, π (1 = yes) | B7: flag | C7: =Calculations!C69 -> 1 | D7: =Calculations!D69 -> 0 | E7: =Calculations!E69 -> 0 | F7: =Calculations!F69 -> 1 | G7: =Calculations!G69 -> 1 | H7: =Calculations!H69 -> 1 | I7: Linked from the Calculations sheet.
A8: Rebate (feebate) share, θ | B8: share | C8: =Calculations!C70 -> 0 | D8: =Calculations!D70 -> 0 | E8: =Calculations!E70 -> 0 | F8: =Calculations!F70 -> 0 | G8: =Calculations!G70 -> 1 | H8: =Calculations!H70 -> 0 | I8: Linked from the Calculations sheet.
A9: Fund switch, φ | B9: share | C9: =Calculations!C71 -> 0 | D9: =Calculations!D71 -> 0 | E9: =Calculations!E71 -> 0 | F9: =Calculations!F71 -> 0 | G9: =Calculations!G71 -> 0 | H9: =Calculations!H71 -> 1 | I9: Linked from the Calculations sheet.
A10: Fuel-intensity response (−β^f) | B10: per US$/t | C10: =Calculations!$C$77 -> -0.0057108749 | I10: Linked from the Calculations sheet.
A11: Years from 2024 to 2030 | B11: years | C11: =Calculations!$C$78 -> 6 | I11: Linked from the Calculations sheet.
A12: Fund shadow price, ψ | B12: US$/t | C12: =Calculations!$C$79 -> 20 | I12: Linked from the Calculations sheet.
A14: B. Product inputs (blue = typed input)
A15: B1. Production, prices and emission factors | C15: 2024 output, Y^2024 (kt) | D15: Growth per year, g | E15: Fuel EF, σ^f = σ^fc + σ^fp (t/t) | F15: Process CO2 EF, σ^np (t/t) | G15: Non-CO2 process EF, σ^no (t/t) | H15: Price, p (US$/t)
A16: DRI-EAF steel | C16: 6400 | D16: 0.02 | E16: 0.57099077 | F16: 0.03790102 | G16: 0 | H16: 530 | I16: 2024 output: DRI-EAF steel = Midrex DRI production 6.37 Mt (2024), taken as steel tonnes; scrap-EAF = worldsteel crude steel 10.7 Mt less DRI-EAF; clinker = USGS cement 50 Mt x 0.8 clinker ratio (assumed); ammonia = USGS 3.9 Mt N (2024) = 4.74 Mt NH3; urea = 7.0 Mt (capacity 7.2-7.3 Mt running at full rates, Argus 2026; exports about 4.5 Mt a year); ammonium nitrate = 1.5 Mt (nitrogen balance: USGS ammonia N less urea N, about 100 kt merchant ammonia; Abu Qir alone has 0.88 Mt capacity). The earlier EBRD total of 6.18 Mt covered only plants exporting to the EU; aluminum = Egyptalum capacity about 310 kt, flat to 2030. Growth 2024-30: products not limited by capacity grow with IMF real GDP forecasts (about 5% a year): scrap-EAF steel and clinker (clinker capacity 60 Mt, USGS). Fertilizers 2.9% a year: 2.5 Mt of announced additions (Daily News Egypt, Sept 2026) on 13.2 Mt. DRI-EAF 2%: DRI plants run at rated capacity, so growth assumes half of the idle 1.76 Mt ESISCO plant restarts (Midrex). Aluminum 0%: no new line before 2030. Prices: see note on the aluminum row. Emission factors: methodology Appendix D.
A17: Scrap-EAF steel | C17: 4300 | D17: 0.05 | E17: 0.04488 | F17: 0.04398115 | G17: 0 | H17: 530
A18: Gray clinker | C18: 40000 | D18: 0.05 | E18: 0.3135685 | F18: 0.53702616 | G18: 0 | H18: 35
A19: Ammonia | C19: 4736 | D19: 0.0293 | E19: 1.97472 | F19: 0 | G19: 0 | H19: 400
A20: Urea | C20: 7000 | D20: 0.0293 | E20: 0.1122 | F20: 0 | G20: 0 | H20: 340
A21: Ammonium nitrate | C21: 1500 | D21: 0.0293 | E21: 0.1122 | F21: 0 | G21: 0.9944125 | H21: 320
A22: Primary aluminum | C22: 300 | D22: 0 | E22: 0.12342 | F22: 1.623493 | G22: 0.774 | H22: 2600 | I22: Prices (2024 basis, $/t): steel billet 530 for both steel routes (Egyptian billet ex-works $521–533, SteelOrbis 2026); clinker 35 (Mediterranean clinker FOB, CW Research); ammonia 400 (Middle East FOB, 2024 range about $300–450, Argus/QCIntel); urea 340 (World Bank Pink Sheet 2024 average, $338); ammonium nitrate 320 (urea price × Egypt's domestic AN/urea price ratio, 0.93); aluminum 2,600 (Egyptalum export value $452m / 174 kt, FY2023/24; LME 2024 average $2,419).
A23: B2. Product responses and exports | C23: Price elasticity of physical output, ε | D23: EU exports, X (kt) | E23: Process semi-elasticity, β^np (per US$/t) | F23: Process semi-elasticity, β^no (per US$/t)
A24: DRI-EAF steel | C24: -0.4 | D24: 610 | E24: 0.0034469507 | F24: 0 | I24: EU exports: aluminum = Egyptalum exports 174 kt (FY2023/24) x 96% to EU markets; fertilizers = EBRD 1.45 Mt to the EU, split by product (assumed); steel scaled to EU iron and steel imports from Egypt (US$0.6bn, UN Comtrade) with an assumed split; clinker is a study assumption. Elasticities and semi-elasticities: methodology Appendix C.
A25: Scrap-EAF steel | C25: -0.4 | D25: 320 | E25: 0.0016366491 | F25: 0
A26: Gray clinker | C26: -0.1 | D26: 800 | E26: 0.0033464675 | F26: 0
A27: Ammonia | C27: -0.4 | D27: 97 | E27: 0 | F27: 0
A28: Urea | C28: -0.4 | D28: 1289 | E28: 0 | F28: 0
A29: Ammonium nitrate | C29: -0.4 | D29: 64 | E29: 0 | F29: 0.0078858436
A30: Primary aluminum | C30: -0.5 | D30: 167 | E30: 0.0019988245 | F30: 0.0019988245
A32: C. Baseline for each product, 2030 (independent of scenario)
A33: C1. Baseline | C33: Output (kt) | D33: Fuel emissions (Mt) | E33: Process emissions (Mt) | F33: Intensity (t/t) | G33: Exports × intensity
A34: DRI-EAF steel | C34: =C16*(1+D16)^$C$11 -> 7207.4395 | D34: =C34*E16/1000 -> 4.1153814 | E34: =C34*(F16+G16)/1000 -> 0.27316931 | F34: =E16+F16+G16 -> 0.60889179 | G34: =D24*F34 -> 371.42399 | I34: Output Y^0 = Y^2024 × (1 + g)^years. Fuel emissions E^f,0 = Y^0 × σ^f ÷ 1000 (kt to Mt). Process emissions E^p,0 = Y^0 × (σ^np + σ^no) ÷ 1000 (kt to Mt). Emissions per tonne σ^0 = σ^f + σ^np + σ^no. Exports × intensity = X × σ^0.
A35: Scrap-EAF steel | C35: =C17*(1+D17)^$C$11 -> 5762.4113 | D35: =C35*E17/1000 -> 0.25861702 | E35: =C35*(F17+G17)/1000 -> 0.25343747 | F35: =E17+F17+G17 -> 0.08886115 | G35: =D25*F35 -> 28.435568
A36: Gray clinker | C36: =C18*(1+D18)^$C$11 -> 53603.826 | D36: =C36*E18/1000 -> 16.808471 | E36: =C36*(F18+G18)/1000 -> 28.786657 | F36: =E18+F18+G18 -> 0.85059466 | G36: =D26*F36 -> 680.47573
A37: Ammonia | C37: =C19*(1+D19)^$C$11 -> 5632.0115 | D37: =C37*E19/1000 -> 11.121646 | E37: =C37*(F19+G19)/1000 -> 0 | F37: =E19+F19+G19 -> 1.97472 | G37: =D27*F37 -> 191.54784
A38: Urea | C38: =C20*(1+D20)^$C$11 -> 8324.3413 | D38: =C38*E20/1000 -> 0.93399109 | E38: =C38*(F20+G20)/1000 -> 0 | F38: =E20+F20+G20 -> 0.1122 | G38: =D28*F38 -> 144.6258
A39: Ammonium nitrate | C39: =C21*(1+D21)^$C$11 -> 1783.7874 | D39: =C39*E21/1000 -> 0.20014095 | E39: =C39*(F21+G21)/1000 -> 1.7738205 | F39: =E21+F21+G21 -> 1.1066125 | G39: =D29*F39 -> 70.8232
A40: Primary aluminum | C40: =C22*(1+D22)^$C$11 -> 300 | D40: =C40*E22/1000 -> 0.037026 | E40: =C40*(F22+G22)/1000 -> 0.71924791 | F40: =E22+F22+G22 -> 2.520913 | G40: =D30*F40 -> 420.99248
A41: Total | D41: =SUM(D34:D40) -> 33.475273 | E41: =SUM(E34:E40) -> 31.806332 | G41: =SUM(G34:G40) -> 1908.3246
A43: D. Product calculations under each scenario
A44: Six steps, in order. Rows are products and columns are scenarios.
...

Sheet Data
A1: Include | B1: Country | C1: Scenario | D1: CPATIndicator | E1: CPATCode | F1: MTCode | G1: Tab | H1: Variable | I1: Unit | J1: SubScenario | K1: 2022 | L1: 2023 | M1: 2024 | N1: 2025 | O1: 2026 | P1: 2027 | Q1: 2028 | R1: 2029 | S1: 2030 | T1: 2031 | U1: 2032 | V1: 2033 | W1: 2034 | X1: 2035 | Y1: 2036 | Z1: 2037 | AA1: 2038 | AB1: 2039 | AC1: 2040 | AD1: 2041 | AF1: Year read by the lookups | AG1: 2030
B2: Egypt | C2: EGY1A | D2: Emissions coverage | E2: egy.mit.co2cov.2 | F2: egy.mit.co2cov.2_EGY1A | G2: mit | H2: co2cov | I2: pc | J2: 2 | K2: 0 | L2: 0 | M2: 0 | N2: 0 | O2: 0.98816 | P2: 0.98743 | Q2: 0.98751 | R2: 0.98747 | S2: 0.98757 | T2: 0.98764 | U2: 0.98774 | V2: 0.98783 | W2: 0.98794 | X2: 0.98804 | Y2: 0.98815 | Z2: 0.98826 | AA2: 0.98838 | AB2: 0.98852 | AC2: 0.98867 | AD2: 0.98879 | AF2: Raw CPAT results: paste the full export (all columns, header in row 1) over columns A to AD. Lookups match the MTCode in column F and read the year in AG1 from the header row.
B3: Egypt | C3: EGY1A | D3: Carbon tax trajectory | E3: egy.mit.cptraj.2 | F3: egy.mit.cptraj.2_EGY1A | G3: mit | H3: cptraj | I3: usdtco2 | J3: 2 | K3: 0 | L3: 0 | M3: 0 | N3: 0 | O3: 20 | P3: 20 | Q3: 20 | R3: 20 | S3: 20 | T3: 20 | U3: 20 | V3: 20 | W3: 20 | X3: 20 | Y3: 20 | Z3: 20 | AA3: 20 | AB3: 20 | AC3: 20 | AD3: 20
B4: Egypt | C4: EGY1A | D4: Effective carbon tax trajectory | E4: egy.mit.eff.cptraj.2 | F4: egy.mit.eff.cptraj.2_EGY1A | G4: mit | H4: effcptraj | I4: usdtco2 | J4: 2 | K4: 0 | L4: 0 | M4: 0 | N4: 0 | O4: 19.763 | P4: 19.749 | Q4: 19.75 | R4: 19.749 | S4: 19.751 | T4: 19.753 | U4: 19.755 | V4: 19.757 | W4: 19.759 | X4: 19.761 | Y4: 19.763 | Z4: 19.765 | AA4: 19.768 | AB4: 19.77 | AC4: 19.773 | AD4: 19.776
B5: Egypt | C5: EGY1A | D5: ETS Trajector\y | E5: egy.mit.etstraj.2 | F5: egy.mit.etstraj.2_EGY1A | G5: mit | H5: etstraj | I5: usdtco2 | J5: 2 | K5: 0 | L5: 0 | M5: 0 | N5: 0 | O5: 0 | P5: 0 | Q5: 0 | R5: 0 | S5: 0 | T5: 0 | U5: 0 | V5: 0 | W5: 0 | X5: 0 | Y5: 0 | Z5: 0 | AA5: 0 | AB5: 0 | AC5: 0 | AD5: 0
B6: Egypt | C6: EGY1A | D6: Emissions covered by sector: power sector | E6: egy.mit.co2cov.pow.cont.2 | F6: egy.mit.co2cov.pow.cont.2_EGY1A | G6: mit | H6: co2cov | I6: pc | J6: 2 | K6: 0 | L6: 0 | M6: 0 | N6: 0 | O6: 0.41588 | P6: 0.37506 | Q6: 0.37217 | R6: 0.36238 | S6: 0.35499 | T6: 0.34396 | U6: 0.3344 | V6: 0.32517 | W6: 0.31744 | X6: 0.31089 | Y6: 0.30582 | Z6: 0.30217 | AA6: 0.29995 | AB6: 0.29931 | AC6: 0.29971 | AD6: 0.29987
B7: Egypt | C7: EGY1A | D7: Emissions covered, transport sector | E7: egy.mit.co2cov.tra.cont.2 | F7: egy.mit.co2cov.tra.cont.2_EGY1A | G7: mit | H7: co2cov | I7: pc | J7: 2 | K7: 0 | L7: 0 | M7: 0 | N7: 0 | O7: 0.20507 | P7: 0.22464 | Q7: 0.23215 | R7: 0.24313 | S7: 0.25567 | T7: 0.27133 | U7: 0.28647 | V7: 0.30132 | W7: 0.31507 | X7: 0.32769 | Y7: 0.33898 | Z7: 0.34908 | AA7: 0.35805 | AB7: 0.36579 | AC7: 0.37257 | AD7: 0.37897
B8: Egypt | C8: EGY1A | D8: Emissions covered, residential sector | E8: egy.mit.co2cov.res.cont.2 | F8: egy.mit.co2cov.res.cont.2_EGY1A | G8: mit | H8: co2cov | I8: pc | J8: 2 | K8: 0 | L8: 0 | M8: 0 | N8: 0 | O8: 0.0811 | P8: 0.08257 | Q8: 0.0797 | R8: 0.07794 | S8: 0.07581 | T8: 0.07391 | U8: 0.07186 | V8: 0.06983 | W8: 0.06773 | X8: 0.06564 | Y8: 0.06355 | Z8: 0.06149 | AA8: 0.05942 | AB8: 0.05734 | AC8: 0.05529 | AD8: 0.05339
B9: Egypt | C9: EGY1A | D9: Emissions covered, industry | E9: egy.mit.co2cov.ind.cont.2 | F9: egy.mit.co2cov.ind.cont.2_EGY1A | G9: mit | H9: co2cov | I9: pc | J9: 2 | K9: 0 | L9: 0 | M9: 0 | N9: 0 | O9: 0.28621 | P9: 0.30527 | Q9: 0.30359 | R9: 0.30412 | S9: 0.30119 | T9: 0.29853 | U9: 0.2951 | V9: 0.29162 | W9: 0.28779 | X9: 0.28391 | Y9: 0.27988 | Z9: 0.27561 | AA9: 0.27106 | AB9: 0.26617 | AC9: 0.26118 | AD9: 0.25664
B10: Egypt | C10: EGY1A | D10: Emissions covered, other energy use | E10: egy.mit.co2cov.oth.cont.2 | F10: egy.mit.co2cov.oth.cont.2_EGY1A | G10: mit | H10: co2cov | I10: pc | J10: 2 | K10: 0 | L10: 0 | M10: 0 | N10: 0 | O10: 0 | P10: 0 | Q10: 0 | R10: 0 | S10: 0 | T10: 0 | U10: 0 | V10: 0 | W10: 0 | X10: 0 | Y10: 0 | Z10: 0 | AA10: 0 | AB10: 0 | AC10: 0 | AD10: 0
B11: Egypt | C11: EGY1A | D11: Effect on GDP: Baseline GDP growth | E11: egy.mit.gdp.pre.pct.2 | F11: egy.mit.gdp.pre.pct.2_EGY1A | G11: mit | H11: gdp | I11: pc | J11: 2 | K11: 0.06651 | L11: 0.0376 | M11: 0.02399 | N11: 0.04392 | O11: 0.0424 | P11: 0.04829 | Q11: 0.05535 | R11: 0.05227 | S11: 0.04842 | T11: 0.04789 | U11: 0.04736 | V11: 0.04682 | W11: 0.04629 | X11: 0.04576 | Y11: 0.04523 | Z11: 0.0447 | AA11: 0.04417 | AB11: 0.04364 | AC11: 0.0431 | AD11: 0.04257
B12: Egypt | C12: EGY1A | D12: Effect on GDP: - Carbon tax | E12: egy.mit.gdp.exc.pct.2 | F12: egy.mit.gdp.exc.pct.2_EGY1A | G12: mit | H12: gdp | I12: pc | J12: 2 | K12: 0 | L12: 0 | M12: 0 | N12: 0 | O12: -0.00455 | P12: -0.00723 | Q12: -0.00684 | R12: -0.0069 | S12: -0.00623 | T12: -0.00555 | U12: -0.00531 | V12: -0.00484 | W12: -0.0043 | X12: -0.00385 | Y12: -0.0036 | Z12: -0.0036 | AA12: -0.00361 | AB12: -0.00361 | AC12: -0.00351 | AD12: -0.00337
B13: Egypt | C13: EGY1A | D13: Effect on GDP: Personal income tax | E13: egy.mit.gdp.pit.pct.2 | F13: egy.mit.gdp.pit.pct.2_EGY1A | G13: mit | H13: gdp | I13: pc | J13: 2 | K13: 0 | L13: 0 | M13: 0 | N13: 0 | O13: 0 | P13: 0 | Q13: 0 | R13: 0 | S13: 0 | T13: 0 | U13: 0 | V13: 0 | W13: 0 | X13: 0 | Y13: 0 | Z13: 0 | AA13: 0 | AB13: 0 | AC13: 0 | AD13: 0
B14: Egypt | C14: EGY1A | D14: Effect on GDP: Public investment | E14: egy.mit.gdp.inv.pct.2 | F14: egy.mit.gdp.inv.pct.2_EGY1A | G14: mit | H14: gdp | I14: pc | J14: 2 | K14: 0 | L14: 0 | M14: 0 | N14: 0 | O14: 0.00762 | P14: 0.00932 | Q14: 0.009 | R14: 0.0083 | S14: 0.00857 | T14: 0.00942 | U14: 0.0106 | V14: 0.01164 | W14: 0.0137 | X14: 0.01509 | Y14: 0.0163 | Z14: 0.01672 | AA14: 0.01701 | AB14: 0.01736 | AC14: 0.01753 | AD14: 0.0177
... B21: Egypt | C21: EGY1A | D21: Total revenues, % of GDP (policy) | E21: egy.mit.rev.new.pct.2 | F21: egy.mit.rev.new.pct.2_EGY1A | G21: mit | H21: rev | I21: pc | J21: 2 | K21: -0.05845 | L21: -0.04678 | M21: -0.06658 | N21: -0.06182 | O21: -0.0499 | P21: -0.04395 | Q21: -0.04232 | R21: -0.04065 | S21: -0.03945 | T21: -0.03788 | U21: -0.03659 | V21: -0.03523 | W21: -0.03384 | X21: -0.0324 | Y21: -0.03083 | Z21: -0.0292 | AA21: -0.02745 | AB21: -0.02561 | AC21: -0.02398 | AD21: -0.02409
B22: Egypt | C22: EGY1A | D22: Base erosion, % of GDP | E22: egy.mit.ers | F22: egy.mit.ers_EGY1A | J22: 2 | K22: 0 | L22: 2.844543e-05 | M22: 2.4134132e-05 | N22: 2.2817555e-05 | O22: 0.0053636661 | P22: 0.0053659141 | Q22: 0.0046214763 | R22: 0.0044533418 | S22: 0.0043312021 | T22: 0.0043848434 | U22: 0.0044145522 | V22: 0.0044542808 | W22: 0.0044620307 | X22: 0.0044483116 | Y22: 0.0044052265 | Z22: 0.004334692 | AA22: 0.004253877 | AB22: 0.0041590791 | AC22: 0.0040817358 | AD22: 0.0039995942
B23: Egypt | C23: EGY1A | D23: Revenues - Carbon tax, % of GDP | E23: egy.mit.rcp | F23: egy.mit.rcp_EGY1A | J23: 2 | K23: 0 | L23: 0 | M23: 0 | N23: 0 | O23: 0.0070282371 | P23: 0.006701828 | Q23: 0.0067128398 | R23: 0.0066464777 | S23: 0.0066269031 | T23: 0.0065958403 | U23: 0.0065890349 | V23: 0.0065916109 | W23: 0.0066108686 | X23: 0.0066452374 | Y23: 0.0066940648 | Z23: 0.0067584028 | AA23: 0.0068350129 | AB23: 0.0069255174 | AC23: 0.0070254208 | AD23: 0.0071193586
B24: Egypt | C24: EGY1A | D24: Power sector carbon tax revenues | E24: egy.mit.rcp.pow | F24: egy.mit.rcp.pow_EGY1A | J24: 2 | K24: 0 | L24: 0 | M24: 0 | N24: 0 | O24: 0.0029270922 | P24: 0.0025178419 | Q24: 0.002502541 | R24: 0.0024125462 | S24: 0.0023562919 | T24: 0.0022722221 | U24: 0.0022066032 | V24: 0.0021463513 | W24: 0.0021013205 | X24: 0.0020685205 | Y24: 0.0020496382 | Z24: 0.0020444865 | AA24: 0.002052318 | AB24: 0.0020749249 | AC24: 0.0021075771 | AD24: 0.0021368177
B25: Egypt | C25: EGY1A | D25: Transport sector carbon tax revenues | E25: egy.mit.rcp.trs | F25: egy.mit.rcp.trs_EGY1A | J25: 2 | K25: 0 | L25: 0 | M25: 0 | N25: 0 | O25: 0.0015159442 | P25: 0.0015803728 | Q25: 0.0016329483 | R25: 0.0016902768 | S25: 0.0017682525 | T25: 0.0018632853 | U25: 0.0019609651 | V25: 0.0020594437 | W25: 0.0021561355 | X25: 0.0022509149 | Y25: 0.0023427458 | Z25: 0.0024331066 | AA25: 0.0025214725 | AB25: 0.002607871 | AC25: 0.0026924358 | AD25: 0.0027733899
B26: Egypt | C26: EGY1A | D26: Buildings sector carbon tax revenues | E26: egy.mit.rcp.bld | F26: egy.mit.rcp.bld_EGY1A | J26: 2 | K26: 0 | L26: 0 | M26: 0 | N26: 0 | O26: 0.00057080737 | P26: 0.00055429561 | Q26: 0.00053593011 | R26: 0.00051891866 | S26: 0.00050321994 | T26: 0.00048827703 | U26: 0.0004741956 | V26: 0.0004609044 | W26: 0.0004483774 | X26: 0.00043676856 | Y26: 0.00042588811 | Z26: 0.00041603046 | AA26: 0.00040658211 | AB26: 0.00039750716 | AC26: 0.0003888042 | AD26: 0.00038044664
B27: Egypt | C27: EGY1A | D27: Industry sector carbon tax revenues | E27: egy.mit.rcp.ind | F27: egy.mit.rcp.ind_EGY1A | J27: 2 | K27: 0 | L27: 0 | M27: 0 | N27: 0 | O27: 0.0020143933 | P27: 0.0020493177 | Q27: 0.0020414204 | R27: 0.0020247361 | S27: 0.0019991388 | T27: 0.0019720558 | U27: 0.001947271 | V27: 0.0019249114 | W27: 0.0019050352 | X27: 0.0018890334 | Y27: 0.0018757926 | Z27: 0.0018647792 | AA27: 0.0018546403 | AB27: 0.0018452143 | AC27: 0.0018366036 | AD27: 0.0018287044
B28: Egypt | C28: EGY1A | D28: Baseline ln(GDP per capita) | E28: egy.mit.ln.gdppc | F28: egy.mit.ln.gdppc_EGY1A | G28: mit | H28: lngdppc | I28: unitless | J28: 1 | K28: 6.3 | L28: 6.34 | M28: 6.37 | N28: 6.41 | O28: 6.45 | P28: 6.5 | Q28: 6.55 | R28: 6.6 | S28: 6.65 | T28: 6.7 | U28: 6.74 | V28: 6.79 | W28: 6.83 | X28: 6.88 | Y28: 6.92 | Z28: 6.97 | AA28: 7.01 | AB28: 7.05 | AC28: 7.09 | AD28: 7.14
B29: Egypt | C29: EGY1A | D29: Baseline GDP | E29: egy.mit.gdp.pre.lvl.1 | F29: egy.mit.gdp.pre.lvl.1_EGY1A | G29: mit | H29: gdp | I29: usdbn | J29: 1 | K29: 546.97092 | L29: 567.53857 | M29: 581.15269 | N29: 606.67916 | O29: 632.40058 | P29: 662.94058 | Q29: 699.63644 | R29: 736.20368 | S29: 771.84975 | T29: 808.8116 | U29: 847.11364 | V29: 886.77935 | W29: 927.83114 | X29: 970.29029 | Y29: 1014.1768 | Z29: 1059.5094 | AA29: 1106.3053 | AB29: 1154.5801 | AC29: 1204.3479 | AD29: 1255.6209
B30: Egypt | C30: EGY1A | D30: Post-policy GDP | E30: egy.mit.gdp.pst.lvl.2 | F30: egy.mit.gdp.pst.lvl.2_EGY1A | G30: mit | H30: gdp | I30: usdbn | J30: 2 | K30: 546.97092 | L30: 567.53857 | M30: 581.15269 | N30: 606.67916 | O30: 632.40064 | P30: 664.88294 | Q30: 701.01918 | R30: 737.7146 | S30: 772.87859 | T30: 810.61479 | U30: 850.24184 | V30: 891.25848 | W30: 933.85896 | X30: 979.01452 | Y30: 1025.089 | Z30: 1072.388 | AA30: 1120.206 | AB30: 1169.4007 | AC30: 1220.2219 | AD30: 1272.507
B31: Egypt | C31: EGY1A | D31: Population | E31: egy.mit.pop.mn | F31: egy.mit.pop.mn_EGY1A | G31: mit | H31: pop | I31: mn | J31: 1 | K31: 103.6 | L31: 105.2 | M31: 106.6 | N31: 107.9 | O31: 110.058 | P31: 112.25916 | Q31: 114.50434 | R31: 116.79443 | S31: 120.29826 | T31: 125.11019 | U31: 130.1146 | V31: 135.31918 | W31: 140.73195 | X31: 146.36123 | Y31: 152.21568 | Z31: 158.3043 | AA31: 164.63647 | AB31: 171.22193 | AC31: 178.07081 | AD31: 185.19364
B32: Egypt | C32: EGY1A | D32: Total GHG emissions, exc. LULUCF (baseline) | E32: egy.mit.ghg.tot.exc.1 | F32: egy.mit.ghg.tot.exc.1_EGY1A | G32: mit | H32: emis | I32: mtco2e | J32: 1 | K32: 400.912 | L32: 412.105 | M32: 450.924 | N32: 467.515 | O32: 473.648 | P32: 484.763 | Q32: 501.104 | R32: 518.139 | S32: 535.623 | T32: 555.043 | U32: 576.999 | V32: 601.287 | W32: 626.831 | X32: 653.747 | Y32: 682.01 | Z32: 711.827 | AA32: 743.304 | AB32: 776.605 | AC32: 811.925 | AD32: 848.157
B33: Egypt | C33: EGY1A | D33: Total GHG emissions, inc. LULUCF (baseline) | E33: egy.mit.ghg.tot.inc.1 | F33: egy.mit.ghg.tot.inc.1_EGY1A | G33: mit | H33: emis | I33: mtco2e | J33: 1 | K33: 400.912 | L33: 412.105 | M33: 450.924 | N33: 467.515 | O33: 473.648 | P33: 484.763 | Q33: 501.104 | R33: 518.139 | S33: 535.623 | T33: 555.043 | U33: 576.999 | V33: 601.287 | W33: 626.831 | X33: 653.747 | Y33: 682.01 | Z33: 711.827 | AA33: 743.304 | AB33: 776.605 | AC33: 811.925 | AD33: 848.157
B34: Egypt | C34: EGY1A | D34: Energy-related GHG emissions (baseline) | E34: egy.mit.ghg.enr.tot.1 | F34: egy.mit.ghg.enr.tot.1_EGY1A | G34: mit | H34: emis | I34: mtco2e | J34: 1 | K34: 213.939 | L34: 210.133 | M34: 236.548 | N34: 245.532 | O34: 247.516 | P34: 253.847 | Q34: 264.069 | R34: 274.969 | S34: 286.428 | T34: 299.23 | U34: 312.897 | V34: 327.613 | W34: 343.276 | X34: 359.992 | Y34: 377.725 | Z34: 396.674 | AA34: 416.933 | AB34: 438.654 | AC34: 462.022 | AD34: 485.918
B35: Egypt | C35: EGY1A | D35: Industrial processes GHG emissions (baseline) | E35: egy.mit.ghg.ipr.tot.1 | F35: egy.mit.ghg.ipr.tot.1_EGY1A | G35: mit | H35: emis | I35: mtco2e | J35: 1 | K35: 52.2 | L35: 56.903 | M35: 67.059 | N35: 72.5 | O35: 74.569 | P35: 76.99 | Q35: 79.929 | R35: 82.77 | S35: 85.454 | T35: 88.177 | U35: 90.929 | V35: 93.73 | W35: 96.58 | X35: 99.478 | Y35: 102.424 | Z35: 105.418 | AA35: 108.459 | AB35: 111.547 | AC35: 114.681 | AD35: 117.86
B36: Egypt | C36: EGY1A | D36: Agriculture, GHG emissions (baseline) | E36: egy.mit.ghg.agr.tot.1 | F36: egy.mit.ghg.agr.tot.1_EGY1A | G36: mit | H36: emis | I36: mtco2e | J36: 1 | K36: 41.563 | L36: 43.505 | M36: 44.234 | N36: 44.885 | O36: 45.614 | P36: 46.396 | Q36: 47.424 | R36: 48.524 | S36: 49.628 | T36: 50.838 | U36: 52.455 | V36: 54.397 | W36: 56.407 | X36: 58.486 | Y36: 60.638 | Z36: 62.864 | AA36: 65.166 | AB36: 67.548 | AC36: 70.012 | AD36: 72.56
B37: Egypt | C37: EGY1A | D37: Waste GHG emissions (baseline) | E37: egy.mit.ghg.wst.tot.1 | F37: egy.mit.ghg.wst.tot.1_EGY1A | G37: mit | H37: emis | I37: mtco2e | J37: 1 | K37: 93.209 | L37: 101.564 | M37: 103.083 | N37: 104.597 | O37: 105.948 | P37: 107.531 | Q37: 109.682 | R37: 111.875 | S37: 114.113 | T37: 116.798 | U37: 120.718 | V37: 125.546 | W37: 130.568 | X37: 135.791 | Y37: 141.223 | Z37: 146.872 | AA37: 152.746 | AB37: 158.856 | AC37: 165.21 | AD37: 171.819
B38: Egypt | C38: EGY1A | D38: LULUCF, GHG emissions (baseline) | E38: egy.mit.ghg.lucf.tot.1 | F38: egy.mit.ghg.lucf.tot.1_EGY1A | G38: mit | H38: emis | I38: mtco2e | J38: 1 | K38: 0 | L38: 0 | M38: 0 | N38: 0 | O38: 0 | P38: 0 | Q38: 0 | R38: 0 | S38: 0 | T38: 0 | U38: 0 | V38: 0 | W38: 0 | X38: 0 | Y38: 0 | Z38: 0 | AA38: 0 | AB38: 0 | AC38: 0 | AD38: 0
B39: Egypt | C39: EGY1A | D39: Total CO2 emissions - baseline | E39: egy.mit.co2.tot.1 | F39: egy.mit.co2.tot.1_EGY1A | G39: mit | H39: emis | I39: mtco2 | J39: 1 | K39: 307.637 | L39: 315.625 | M39: 350.605 | N39: 364.723 | O39: 369.176 | P39: 378.155 | Q39: 391.945 | R39: 406.364 | S39: 421.246 | T39: 437.519 | U39: 455.457 | V39: 475.305 | W39: 496.254 | X39: 518.414 | Y39: 541.754 | Z39: 566.478 | AA39: 592.682 | AB39: 620.525 | AC39: 650.194 | AD39: 680.584
... B73: Egypt | C73: EGY1A | D73: Energy related CO2 emissions - Other (policy) | E73: egy.mit.co2.oth.2 | F73: egy.mit.co2.oth.2_EGY1A | G73: mit | H73: emis | I73: mtco2 | J73: 2 | K73: 0.294 | L73: 0.268 | M73: 0.317 | N73: 0.417 | O73: 0.316 | P73: 0.376 | Q73: 0.398 | R73: 0.409 | S73: 0.411 | T73: 0.41 | U73: 0.409 | V73: 0.408 | W73: 0.406 | X73: 0.405 | Y73: 0.404 | Z73: 0.403 | AA73: 0.401 | AB73: 0.4 | AC73: 0.399 | AD73: 0.398
B74: Egypt | C74: EGY1A | D74: Change in CO2 emissions - (policy vs. baseline) | E74: egy.mit.co2.tot.red.pct | F74: egy.mit.co2.tot.red.pct_EGY1A | G74: mit | H74: co2red | I74: mtco2 | J74: t | K74: 0 | L74: 0 | M74: 0 | N74: 0 | O74: -0.086 | P74: -0.097 | Q74: -0.086 | R74: -0.085 | S74: -0.083 | T74: -0.085 | U74: -0.084 | V74: -0.084 | W74: -0.082 | X74: -0.08 | Y74: -0.077 | Z74: -0.074 | AA74: -0.07 | AB74: -0.066 | AC74: -0.062 | AD74: -0.058
B75: Egypt | C75: EGY1A | D75: Total GHG emissions, excl LULUCF - baseline | E75: egy.mit.ghg.tot.exc.fuel.1 | F75: egy.mit.ghg.tot.exc.fuel.1_EGY1A | G75: mit | H75: emis | I75: mtco2e | J75: 1 | K75: 400.912 | L75: 412.105 | M75: 450.924 | N75: 467.515 | O75: 473.648 | P75: 484.763 | Q75: 501.104 | R75: 518.139 | S75: 535.623 | T75: 555.043 | U75: 576.999 | V75: 601.287 | W75: 626.831 | X75: 653.747 | Y75: 682.01 | Z75: 711.827 | AA75: 743.304 | AB75: 776.605 | AC75: 811.925 | AD75: 848.157
B76: Egypt | C76: EGY1A | D76: Carbon dioxide (CO2) - baseline | E76: egy.mit.co2.tot.1 | F76: egy.mit.co2.tot.1_EGY1A | G76: mit | H76: emis | I76: mtco2 | J76: 1 | K76: 307.637 | L76: 315.625 | M76: 350.605 | N76: 364.723 | O76: 369.176 | P76: 378.155 | Q76: 391.945 | R76: 406.364 | S76: 421.246 | T76: 437.519 | U76: 455.457 | V76: 475.305 | W76: 496.254 | X76: 518.414 | Y76: 541.754 | Z76: 566.478 | AA76: 592.682 | AB76: 620.525 | AC76: 650.194 | AD76: 680.584
B77: Egypt | C77: EGY1A | D77: Methane (CH4) - baseline | E77: egy.mit.ch4.tot.1 | F77: egy.mit.ch4.tot.1_EGY1A | G77: mit | H77: emis | I77: mtco2e | J77: 1 | K77: 53.088 | L77: 55.678 | M77: 56.592 | N77: 57.34 | O77: 58.083 | P77: 59.234 | Q77: 60.428 | R77: 61.667 | S77: 62.922 | T77: 64.748 | U77: 67.185 | V77: 69.717 | W77: 72.347 | X77: 75.078 | Y77: 77.915 | Z77: 80.859 | AA77: 83.917 | AB77: 87.093 | AC77: 90.39 | AD77: 93.815
B78: Egypt | C78: EGY1A | D78: Nitrous oxide (N2O) - baseline | E78: egy.mit.nox.tot.1 | F78: egy.mit.nox.tot.1_EGY1A | G78: mit | H78: emis | I78: mtco2e | J78: 1 | K78: 28.488 | L78: 28.577 | M78: 29.32 | N78: 29.875 | O78: 30.368 | P78: 30.834 | Q78: 31.558 | R78: 32.325 | S78: 33.096 | T78: 33.832 | U78: 34.822 | V78: 36.127 | W78: 37.48 | X78: 38.883 | Y78: 40.336 | Z78: 41.842 | AA78: 43.404 | AB78: 45.023 | AC78: 46.703 | AD78: 48.438
B79: Egypt | C79: EGY1A | D79: F-gases (PFCs, HFCs, SF6, NF3) - baseline | E79: egy.mit.fga.tot.1 | F79: egy.mit.fga.tot.1_EGY1A | G79: mit | H79: emis | I79: mtco2e | J79: 1 | K79: 11.699 | L79: 12.225 | M79: 14.407 | N79: 15.576 | O79: 16.02 | P79: 16.54 | Q79: 17.172 | R79: 17.782 | S79: 18.359 | T79: 18.944 | U79: 19.535 | V79: 20.137 | W79: 20.749 | X79: 21.372 | Y79: 22.005 | Z79: 22.648 | AA79: 23.301 | AB79: 23.965 | AC79: 24.638 | AD79: 25.321
...
