Workbook
Name in_iso: Screen!$C$5
Name in_f1: Screen!$C$8
Name in_f2: Screen!$C$9
Name in_f3: Screen!$C$10
Name in_rebate: Screen!$C$11
Name in_cap: Screen!$C$12
Name in_tstep: Screen!$C$15
Name in_fstep: Screen!$C$16
Name in_elas: Screen!$C$19
Name in_kappa: Screen!$C$20
Name in_rise_lo: Screen!$C$21
Name in_rise_hi: Screen!$C$22
Name in_rise_miss: Screen!$C$23
Name in_gas_rep: Screen!$C$24
Name in_sw_floor: Screen!$C$25
Name in_sw_miss: Screen!$C$26
Name in_hr_coal: Screen!$C$27
Name in_hr_gas: Screen!$C$28
Name in_whole_sh: Screen!$C$29
Name in_res_sh: Screen!$C$30
Name in_q40: Screen!$C$31
Name in_phase: Screen!$C$32
Name in_pt3: Screen!$C$33
Name in_pt2: Screen!$C$34
Name in_pt1: Screen!$C$35
Name in_pt_hi: Screen!$C$36
Name in_pt_oth: Screen!$C$37
Name in_b40_li: Screen!$C$38
Name in_b40_lmi: Screen!$C$39
Name in_b40_umi: Screen!$C$40
Name in_b40_hi: Screen!$C$41
Name sel_row: Screen!$H$5

Sheet Screen
B2: Carbon tax vs feebate: feasibility screen (power sector)
B3: Most abatement each instrument gets without breaking three political limits. Yellow cells are inputs. Screening only: priors are placeholders, see notes below.
B5: Country (ISO3) | C5: ZAF | G5: Row in Countries | H5: =MATCH(in_iso,Countries!$A$1:$A$174,0)
B7: Political limits | C7: Value | D7: Note | G7: Selected country
B8: F1 max tariff rise (%) | C8: 10 | D8: First-year rise in residential tariff | G8: Country | H8: =INDEX(Countries!$B$1:$B$174,sel_row)
B9: F2 max bottom-40% burden (% of consumption) | C9: 0.5 | D9: Net of rebate | G9: Income | H9: =INDEX(Countries!$C$1:$C$174,sel_row)
B10: F3 max coal/oil generator payment (% of revenue) | C10: 15 | D10: Unpassed tax + net feebate payment | G10: Baseline power CO2 (Mt) | H10: =INDEX(Countries!$Q$1:$Q$174,sel_row)
B11: Share of tax revenue rebated to bottom 40% | C11: 0 | D11: 0-1 | G11: Average intensity (t/MWh) | H11: =INDEX(Countries!$R$1:$R$174,sel_row)
B12: Rate cap ($/tCO2) | C12: 200 | D12: Upper bound for tax and feebate rates | G12: Residential tariff ($/MWh) | H12: =INDEX(Countries!$V$1:$V$174,sel_row)
G13: Pass-through | H13: =INDEX(Countries!$W$1:$W$174,sel_row)
B14: Grid | C14: Value | D14: Note | G14: Switching price ($/t) | H14: =INDEX(Countries!$Y$1:$Y$174,sel_row)
B15: Grid: tax step ($/t) | C15: 10 | D15: Rows of the grid | G15: Max substitution share | H15: =INDEX(Countries!$X$1:$X$174,sel_row)
B16: Grid: feebate step ($/t) | C16: 20 | D16: Columns of the grid | G16: Feebate/tax abatement at $50 | H16: =INDEX(Countries!$AR$1:$AR$174,sel_row)
G17: Tariff rise from $50 tax (%) | H17: =INDEX(Countries!$AS$1:$AS$174,sel_row)
B18: Priors (assumptions: replace with country evidence or CPAT) | C18: Value | D18: Note
B19: Electricity demand elasticity | C19: -0.3 | D19: Long run | G19: Best under limits | H19: E (%) | I19: Tax $/t | J19: Feebate $/t | K19: F1 | L19: F2 | M19: F3 | N19: Binding
B20: Max share of coal+oil output displaceable by 2030 | C20: 0.4 | G20: Carbon tax / ETS | H20: =INDEX(Countries!$AJ$1:$AJ$174,sel_row) | I20: =INDEX(Countries!$AI$1:$AI$174,sel_row) | J20: =0 | K20: =INDEX(Countries!$AB$1:$AB$174,sel_row)*I20 | L20: =INDEX(Countries!$AC$1:$AC$174,sel_row)*I20 | M20: =INDEX(Countries!$AD$1:$AD$174,sel_row)*I20+INDEX(Countries!$AE$1:$AE$174,sel_row)*J20 | N20: =INDEX(Countries!$AK$1:$AK$174,sel_row)
B21: kappa multiplier at RISE score 0 | C21: 0.5 | G21: Feebate | H21: =INDEX(Countries!$AN$1:$AN$174,sel_row) | I21: =0 | J21: =INDEX(Countries!$AM$1:$AM$174,sel_row) | K21: =INDEX(Countries!$AB$1:$AB$174,sel_row)*I21 | L21: =INDEX(Countries!$AC$1:$AC$174,sel_row)*I21 | M21: =INDEX(Countries!$AD$1:$AD$174,sel_row)*I21+INDEX(Countries!$AE$1:$AE$174,sel_row)*J21 | N21: =INDEX(Countries!$AO$1:$AO$174,sel_row)
B22: kappa multiplier at RISE score 100 | C22: 1 | G22: Hybrid (tax + feebate) | H22: =INDEX(Countries!$AT$1:$AT$174,sel_row) | I22: =INDEX(Countries!$AU$1:$AU$174,sel_row) | J22: =INDEX(Countries!$AV$1:$AV$174,sel_row) | K22: =INDEX(Countries!$AB$1:$AB$174,sel_row)*I22 | L22: =INDEX(Countries!$AC$1:$AC$174,sel_row)*I22 | M22: =INDEX(Countries!$AD$1:$AD$174,sel_row)*I22+INDEX(Countries!$AE$1:$AE$174,sel_row)*J22 | N22: =INDEX(Countries!$AZ$1:$AZ$174,sel_row)
B23: RISE score when missing | C23: 35 | D23: Median
B24: Share of displaced output replaced by gas | C24: 0.3 | D24: Rest clean | G24: +1pp on F1 buys, tax only (pp E) | H24: =INDEX(Countries!$AL$1:$AL$174,sel_row)
B25: Lowest switching price ($/t) | C25: 15 | D25: Non-price barriers
B26: Switching price when no gas price ($/t) | C26: 50 | G26: Abatement E (%) by tax (rows) and feebate (columns). Green = within all three limits; bold border = best feasible cell.
B27: Coal heat rate (GJ/MWh) | C27: 10 | G27: Tax $/t \ Feebate $/t | H27: =in_fstep*0 | I27: =in_fstep*1 | J27: =in_fstep*2 | K27: =in_fstep*3 | L27: =in_fstep*4 | M27: =in_fstep*5 | N27: =in_fstep*6 | O27: =in_fstep*7 | P27: =in_fstep*8 | Q27: =in_fstep*9 | R27: =in_fstep*10
B28: Gas heat rate (GJ/MWh) | C28: 7 | D28: CCGT | G28: =in_tstep*0 | H28: =100*(1-(1-$H$44*(1-EXP(-($G28+H$27)/$I$44)))*(1-MIN(ABS(in_elas)*$J$44*$K$44*$G28/$L$44,1))) | I28: =100*(1-(1-$H$44*(1-EXP(-($G28+I$27)/$I$44)))*(1-MIN(ABS(in_elas)*$J$44*$K$44*$G28/$L$44,1))) | J28: =100*(1-(1-$H$44*(1-EXP(-($G28+J$27)/$I$44)))*(1-MIN(ABS(in_elas)*$J$44*$K$44*$G28/$L$44,1))) | K28: =100*(1-(1-$H$44*(1-EXP(-($G28+K$27)/$I$44)))*(1-MIN(ABS(in_elas)*$J$44*$K$44*$G28/$L$44,1))) | L28: =100*(1-(1-$H$44*(1-EXP(-($G28+L$27)/$I$44)))*(1-MIN(ABS(in_elas)*$J$44*$K$44*$G28/$L$44,1))) | M28: =100*(1-(1-$H$44*(1-EXP(-($G28+M$27)/$I$44)))*(1-MIN(ABS(in_elas)*$J$44*$K$44*$G28/$L$44,1))) | N28: =100*(1-(1-$H$44*(1-EXP(-($G28+N$27)/$I$44)))*(1-MIN(ABS(in_elas)*$J$44*$K$44*$G28/$L$44,1))) | O28: =100*(1-(1-$H$44*(1-EXP(-($G28+O$27)/$I$44)))*(1-MIN(ABS(in_elas)*$J$44*$K$44*$G28/$L$44,1))) | ... R28: =100*(1-(1-$H$44*(1-EXP(-($G28+R$27)/$I$44)))*(1-MIN(ABS(in_elas)*$J$44*$K$44*$G28/$L$44,1)))
B29: Wholesale price / residential tariff | C29: 0.6 | G29: =in_tstep*1 | H29: =100*(1-(1-$H$44*(1-EXP(-($G29+H$27)/$I$44)))*(1-MIN(ABS(in_elas)*$J$44*$K$44*$G29/$L$44,1))) | I29: =100*(1-(1-$H$44*(1-EXP(-($G29+I$27)/$I$44)))*(1-MIN(ABS(in_elas)*$J$44*$K$44*$G29/$L$44,1))) | J29: =100*(1-(1-$H$44*(1-EXP(-($G29+J$27)/$I$44)))*(1-MIN(ABS(in_elas)*$J$44*$K$44*$G29/$L$44,1))) | K29: =100*(1-(1-$H$44*(1-EXP(-($G29+K$27)/$I$44)))*(1-MIN(ABS(in_elas)*$J$44*$K$44*$G29/$L$44,1))) | L29: =100*(1-(1-$H$44*(1-EXP(-($G29+L$27)/$I$44)))*(1-MIN(ABS(in_elas)*$J$44*$K$44*$G29/$L$44,1))) | M29: =100*(1-(1-$H$44*(1-EXP(-($G29+M$27)/$I$44)))*(1-MIN(ABS(in_elas)*$J$44*$K$44*$G29/$L$44,1))) | N29: =100*(1-(1-$H$44*(1-EXP(-($G29+N$27)/$I$44)))*(1-MIN(ABS(in_elas)*$J$44*$K$44*$G29/$L$44,1))) | O29: =100*(1-(1-$H$44*(1-EXP(-($G29+O$27)/$I$44)))*(1-MIN(ABS(in_elas)*$J$44*$K$44*$G29/$L$44,1))) | ... R29: =100*(1-(1-$H$44*(1-EXP(-($G29+R$27)/$I$44)))*(1-MIN(ABS(in_elas)*$J$44*$K$44*$G29/$L$44,1)))
B30: Residential share of electricity sales | C30: 0.35 | G30: =in_tstep*2 | H30: =100*(1-(1-$H$44*(1-EXP(-($G30+H$27)/$I$44)))*(1-MIN(ABS(in_elas)*$J$44*$K$44*$G30/$L$44,1))) | I30: =100*(1-(1-$H$44*(1-EXP(-($G30+I$27)/$I$44)))*(1-MIN(ABS(in_elas)*$J$44*$K$44*$G30/$L$44,1))) | J30: =100*(1-(1-$H$44*(1-EXP(-($G30+J$27)/$I$44)))*(1-MIN(ABS(in_elas)*$J$44*$K$44*$G30/$L$44,1))) | K30: =100*(1-(1-$H$44*(1-EXP(-($G30+K$27)/$I$44)))*(1-MIN(ABS(in_elas)*$J$44*$K$44*$G30/$L$44,1))) | L30: =100*(1-(1-$H$44*(1-EXP(-($G30+L$27)/$I$44)))*(1-MIN(ABS(in_elas)*$J$44*$K$44*$G30/$L$44,1))) | M30: =100*(1-(1-$H$44*(1-EXP(-($G30+M$27)/$I$44)))*(1-MIN(ABS(in_elas)*$J$44*$K$44*$G30/$L$44,1))) | N30: =100*(1-(1-$H$44*(1-EXP(-($G30+N$27)/$I$44)))*(1-MIN(ABS(in_elas)*$J$44*$K$44*$G30/$L$44,1))) | O30: =100*(1-(1-$H$44*(1-EXP(-($G30+O$27)/$I$44)))*(1-MIN(ABS(in_elas)*$J$44*$K$44*$G30/$L$44,1))) | ... R30: =100*(1-(1-$H$44*(1-EXP(-($G30+R$27)/$I$44)))*(1-MIN(ABS(in_elas)*$J$44*$K$44*$G30/$L$44,1)))
B31: Bottom-40% share of residential use | C31: 0.2 | G31: =in_tstep*3 | H31: =100*(1-(1-$H$44*(1-EXP(-($G31+H$27)/$I$44)))*(1-MIN(ABS(in_elas)*$J$44*$K$44*$G31/$L$44,1))) | I31: =100*(1-(1-$H$44*(1-EXP(-($G31+I$27)/$I$44)))*(1-MIN(ABS(in_elas)*$J$44*$K$44*$G31/$L$44,1))) | J31: =100*(1-(1-$H$44*(1-EXP(-($G31+J$27)/$I$44)))*(1-MIN(ABS(in_elas)*$J$44*$K$44*$G31/$L$44,1))) | K31: =100*(1-(1-$H$44*(1-EXP(-($G31+K$27)/$I$44)))*(1-MIN(ABS(in_elas)*$J$44*$K$44*$G31/$L$44,1))) | L31: =100*(1-(1-$H$44*(1-EXP(-($G31+L$27)/$I$44)))*(1-MIN(ABS(in_elas)*$J$44*$K$44*$G31/$L$44,1))) | M31: =100*(1-(1-$H$44*(1-EXP(-($G31+M$27)/$I$44)))*(1-MIN(ABS(in_elas)*$J$44*$K$44*$G31/$L$44,1))) | N31: =100*(1-(1-$H$44*(1-EXP(-($G31+N$27)/$I$44)))*(1-MIN(ABS(in_elas)*$J$44*$K$44*$G31/$L$44,1))) | O31: =100*(1-(1-$H$44*(1-EXP(-($G31+O$27)/$I$44)))*(1-MIN(ABS(in_elas)*$J$44*$K$44*$G31/$L$44,1))) | ... R31: =100*(1-(1-$H$44*(1-EXP(-($G31+R$27)/$I$44)))*(1-MIN(ABS(in_elas)*$J$44*$K$44*$G31/$L$44,1)))
B32: Phase-in years | C32: 1 | D32: Tax reached in equal steps | G32: =in_tstep*4 | H32: =100*(1-(1-$H$44*(1-EXP(-($G32+H$27)/$I$44)))*(1-MIN(ABS(in_elas)*$J$44*$K$44*$G32/$L$44,1))) | I32: =100*(1-(1-$H$44*(1-EXP(-($G32+I$27)/$I$44)))*(1-MIN(ABS(in_elas)*$J$44*$K$44*$G32/$L$44,1))) | J32: =100*(1-(1-$H$44*(1-EXP(-($G32+J$27)/$I$44)))*(1-MIN(ABS(in_elas)*$J$44*$K$44*$G32/$L$44,1))) | K32: =100*(1-(1-$H$44*(1-EXP(-($G32+K$27)/$I$44)))*(1-MIN(ABS(in_elas)*$J$44*$K$44*$G32/$L$44,1))) | L32: =100*(1-(1-$H$44*(1-EXP(-($G32+L$27)/$I$44)))*(1-MIN(ABS(in_elas)*$J$44*$K$44*$G32/$L$44,1))) | M32: =100*(1-(1-$H$44*(1-EXP(-($G32+M$27)/$I$44)))*(1-MIN(ABS(in_elas)*$J$44*$K$44*$G32/$L$44,1))) | N32: =100*(1-(1-$H$44*(1-EXP(-($G32+N$27)/$I$44)))*(1-MIN(ABS(in_elas)*$J$44*$K$44*$G32/$L$44,1))) | O32: =100*(1-(1-$H$44*(1-EXP(-($G32+O$27)/$I$44)))*(1-MIN(ABS(in_elas)*$J$44*$K$44*$G32/$L$44,1))) | ... R32: =100*(1-(1-$H$44*(1-EXP(-($G32+R$27)/$I$44)))*(1-MIN(ABS(in_elas)*$J$44*$K$44*$G32/$L$44,1)))
B33: Pass-through: wholesale market (PSRT 3) | C33: 1 | G33: =in_tstep*5 | H33: =100*(1-(1-$H$44*(1-EXP(-($G33+H$27)/$I$44)))*(1-MIN(ABS(in_elas)*$J$44*$K$44*$G33/$L$44,1))) | I33: =100*(1-(1-$H$44*(1-EXP(-($G33+I$27)/$I$44)))*(1-MIN(ABS(in_elas)*$J$44*$K$44*$G33/$L$44,1))) | J33: =100*(1-(1-$H$44*(1-EXP(-($G33+J$27)/$I$44)))*(1-MIN(ABS(in_elas)*$J$44*$K$44*$G33/$L$44,1))) | K33: =100*(1-(1-$H$44*(1-EXP(-($G33+K$27)/$I$44)))*(1-MIN(ABS(in_elas)*$J$44*$K$44*$G33/$L$44,1))) | L33: =100*(1-(1-$H$44*(1-EXP(-($G33+L$27)/$I$44)))*(1-MIN(ABS(in_elas)*$J$44*$K$44*$G33/$L$44,1))) | M33: =100*(1-(1-$H$44*(1-EXP(-($G33+M$27)/$I$44)))*(1-MIN(ABS(in_elas)*$J$44*$K$44*$G33/$L$44,1))) | N33: =100*(1-(1-$H$44*(1-EXP(-($G33+N$27)/$I$44)))*(1-MIN(ABS(in_elas)*$J$44*$K$44*$G33/$L$44,1))) | O33: =100*(1-(1-$H$44*(1-EXP(-($G33+O$27)/$I$44)))*(1-MIN(ABS(in_elas)*$J$44*$K$44*$G33/$L$44,1))) | ... R33: =100*(1-(1-$H$44*(1-EXP(-($G33+R$27)/$I$44)))*(1-MIN(ABS(in_elas)*$J$44*$K$44*$G33/$L$44,1)))
B34: Pass-through: single buyer (PSRT 2) | C34: 0.6 | G34: =in_tstep*6 | H34: =100*(1-(1-$H$44*(1-EXP(-($G34+H$27)/$I$44)))*(1-MIN(ABS(in_elas)*$J$44*$K$44*$G34/$L$44,1))) | I34: =100*(1-(1-$H$44*(1-EXP(-($G34+I$27)/$I$44)))*(1-MIN(ABS(in_elas)*$J$44*$K$44*$G34/$L$44,1))) | J34: =100*(1-(1-$H$44*(1-EXP(-($G34+J$27)/$I$44)))*(1-MIN(ABS(in_elas)*$J$44*$K$44*$G34/$L$44,1))) | K34: =100*(1-(1-$H$44*(1-EXP(-($G34+K$27)/$I$44)))*(1-MIN(ABS(in_elas)*$J$44*$K$44*$G34/$L$44,1))) | L34: =100*(1-(1-$H$44*(1-EXP(-($G34+L$27)/$I$44)))*(1-MIN(ABS(in_elas)*$J$44*$K$44*$G34/$L$44,1))) | M34: =100*(1-(1-$H$44*(1-EXP(-($G34+M$27)/$I$44)))*(1-MIN(ABS(in_elas)*$J$44*$K$44*$G34/$L$44,1))) | N34: =100*(1-(1-$H$44*(1-EXP(-($G34+N$27)/$I$44)))*(1-MIN(ABS(in_elas)*$J$44*$K$44*$G34/$L$44,1))) | O34: =100*(1-(1-$H$44*(1-EXP(-($G34+O$27)/$I$44)))*(1-MIN(ABS(in_elas)*$J$44*$K$44*$G34/$L$44,1))) | ... R34: =100*(1-(1-$H$44*(1-EXP(-($G34+R$27)/$I$44)))*(1-MIN(ABS(in_elas)*$J$44*$K$44*$G34/$L$44,1)))
B35: Pass-through: vertically integrated (PSRT 1) | C35: 0.4 | G35: =in_tstep*7 | H35: =100*(1-(1-$H$44*(1-EXP(-($G35+H$27)/$I$44)))*(1-MIN(ABS(in_elas)*$J$44*$K$44*$G35/$L$44,1))) | I35: =100*(1-(1-$H$44*(1-EXP(-($G35+I$27)/$I$44)))*(1-MIN(ABS(in_elas)*$J$44*$K$44*$G35/$L$44,1))) | J35: =100*(1-(1-$H$44*(1-EXP(-($G35+J$27)/$I$44)))*(1-MIN(ABS(in_elas)*$J$44*$K$44*$G35/$L$44,1))) | K35: =100*(1-(1-$H$44*(1-EXP(-($G35+K$27)/$I$44)))*(1-MIN(ABS(in_elas)*$J$44*$K$44*$G35/$L$44,1))) | L35: =100*(1-(1-$H$44*(1-EXP(-($G35+L$27)/$I$44)))*(1-MIN(ABS(in_elas)*$J$44*$K$44*$G35/$L$44,1))) | M35: =100*(1-(1-$H$44*(1-EXP(-($G35+M$27)/$I$44)))*(1-MIN(ABS(in_elas)*$J$44*$K$44*$G35/$L$44,1))) | N35: =100*(1-(1-$H$44*(1-EXP(-($G35+N$27)/$I$44)))*(1-MIN(ABS(in_elas)*$J$44*$K$44*$G35/$L$44,1))) | O35: =100*(1-(1-$H$44*(1-EXP(-($G35+O$27)/$I$44)))*(1-MIN(ABS(in_elas)*$J$44*$K$44*$G35/$L$44,1))) | ... R35: =100*(1-(1-$H$44*(1-EXP(-($G35+R$27)/$I$44)))*(1-MIN(ABS(in_elas)*$J$44*$K$44*$G35/$L$44,1)))
B36: Pass-through: no PSRT data, high income | C36: 0.9 | G36: =in_tstep*8 | H36: =100*(1-(1-$H$44*(1-EXP(-($G36+H$27)/$I$44)))*(1-MIN(ABS(in_elas)*$J$44*$K$44*$G36/$L$44,1))) | I36: =100*(1-(1-$H$44*(1-EXP(-($G36+I$27)/$I$44)))*(1-MIN(ABS(in_elas)*$J$44*$K$44*$G36/$L$44,1))) | J36: =100*(1-(1-$H$44*(1-EXP(-($G36+J$27)/$I$44)))*(1-MIN(ABS(in_elas)*$J$44*$K$44*$G36/$L$44,1))) | K36: =100*(1-(1-$H$44*(1-EXP(-($G36+K$27)/$I$44)))*(1-MIN(ABS(in_elas)*$J$44*$K$44*$G36/$L$44,1))) | L36: =100*(1-(1-$H$44*(1-EXP(-($G36+L$27)/$I$44)))*(1-MIN(ABS(in_elas)*$J$44*$K$44*$G36/$L$44,1))) | M36: =100*(1-(1-$H$44*(1-EXP(-($G36+M$27)/$I$44)))*(1-MIN(ABS(in_elas)*$J$44*$K$44*$G36/$L$44,1))) | N36: =100*(1-(1-$H$44*(1-EXP(-($G36+N$27)/$I$44)))*(1-MIN(ABS(in_elas)*$J$44*$K$44*$G36/$L$44,1))) | O36: =100*(1-(1-$H$44*(1-EXP(-($G36+O$27)/$I$44)))*(1-MIN(ABS(in_elas)*$J$44*$K$44*$G36/$L$44,1))) | ... R36: =100*(1-(1-$H$44*(1-EXP(-($G36+R$27)/$I$44)))*(1-MIN(ABS(in_elas)*$J$44*$K$44*$G36/$L$44,1)))
B37: Pass-through: no PSRT data, other | C37: 0.6 | G37: =in_tstep*9 | H37: =100*(1-(1-$H$44*(1-EXP(-($G37+H$27)/$I$44)))*(1-MIN(ABS(in_elas)*$J$44*$K$44*$G37/$L$44,1))) | I37: =100*(1-(1-$H$44*(1-EXP(-($G37+I$27)/$I$44)))*(1-MIN(ABS(in_elas)*$J$44*$K$44*$G37/$L$44,1))) | J37: =100*(1-(1-$H$44*(1-EXP(-($G37+J$27)/$I$44)))*(1-MIN(ABS(in_elas)*$J$44*$K$44*$G37/$L$44,1))) | K37: =100*(1-(1-$H$44*(1-EXP(-($G37+K$27)/$I$44)))*(1-MIN(ABS(in_elas)*$J$44*$K$44*$G37/$L$44,1))) | L37: =100*(1-(1-$H$44*(1-EXP(-($G37+L$27)/$I$44)))*(1-MIN(ABS(in_elas)*$J$44*$K$44*$G37/$L$44,1))) | M37: =100*(1-(1-$H$44*(1-EXP(-($G37+M$27)/$I$44)))*(1-MIN(ABS(in_elas)*$J$44*$K$44*$G37/$L$44,1))) | N37: =100*(1-(1-$H$44*(1-EXP(-($G37+N$27)/$I$44)))*(1-MIN(ABS(in_elas)*$J$44*$K$44*$G37/$L$44,1))) | O37: =100*(1-(1-$H$44*(1-EXP(-($G37+O$27)/$I$44)))*(1-MIN(ABS(in_elas)*$J$44*$K$44*$G37/$L$44,1))) | ... R37: =100*(1-(1-$H$44*(1-EXP(-($G37+R$27)/$I$44)))*(1-MIN(ABS(in_elas)*$J$44*$K$44*$G37/$L$44,1)))
B38: Bottom-40% electricity budget share: low income | C38: 0.02 | D38: Placeholder | G38: =in_tstep*10 | H38: =100*(1-(1-$H$44*(1-EXP(-($G38+H$27)/$I$44)))*(1-MIN(ABS(in_elas)*$J$44*$K$44*$G38/$L$44,1))) | I38: =100*(1-(1-$H$44*(1-EXP(-($G38+I$27)/$I$44)))*(1-MIN(ABS(in_elas)*$J$44*$K$44*$G38/$L$44,1))) | J38: =100*(1-(1-$H$44*(1-EXP(-($G38+J$27)/$I$44)))*(1-MIN(ABS(in_elas)*$J$44*$K$44*$G38/$L$44,1))) | K38: =100*(1-(1-$H$44*(1-EXP(-($G38+K$27)/$I$44)))*(1-MIN(ABS(in_elas)*$J$44*$K$44*$G38/$L$44,1))) | L38: =100*(1-(1-$H$44*(1-EXP(-($G38+L$27)/$I$44)))*(1-MIN(ABS(in_elas)*$J$44*$K$44*$G38/$L$44,1))) | M38: =100*(1-(1-$H$44*(1-EXP(-($G38+M$27)/$I$44)))*(1-MIN(ABS(in_elas)*$J$44*$K$44*$G38/$L$44,1))) | N38: =100*(1-(1-$H$44*(1-EXP(-($G38+N$27)/$I$44)))*(1-MIN(ABS(in_elas)*$J$44*$K$44*$G38/$L$44,1))) | O38: =100*(1-(1-$H$44*(1-EXP(-($G38+O$27)/$I$44)))*(1-MIN(ABS(in_elas)*$J$44*$K$44*$G38/$L$44,1))) | ... R38: =100*(1-(1-$H$44*(1-EXP(-($G38+R$27)/$I$44)))*(1-MIN(ABS(in_elas)*$J$44*$K$44*$G38/$L$44,1)))
B39: ... lower middle income | C39: 0.035 | D39: Placeholder
B40: ... upper middle income | C40: 0.04 | D40: Placeholder
B41: ... high income | C41: 0.03 | D41: Placeholder
G42: Grid parameters (from Countries)
B43: Notes | H43: smax | I43: tsw | J43: phi | K43: eavg | L43: pres | M43: a1 | N43: a2 | O43: a3t | P43: a3f
...

Sheet Countries
A1: Countries: all metrics are live formulas on the Data tab and the Screen inputs
A2: Rates in $/tCO2. E = abatement, % of baseline fossil power CO2. Hybrid: tax searched in 11 steps up to its cap; feebate fills the remaining F3 room.
A3: Country | D3: Data | Q3: Parameters | AB3: Coefficients | AF3: Tax only | AM3: Feebate only | AP3: At $50/t | AT3: Hybrid (best mix) | BB3: Hybrid search: feebate | BM3: Hybrid search: E
A4: ISO3 | B4: Country | C4: Income | D4: Coal gen TWh | E4: Gas gen TWh | F4: Oil gen TWh | G4: Total gen TWh | H4: Coal CO2 Mt | I4: Gas CO2 Mt | J4: Oil CO2 Mt | K4: Res. tariff $/kWh | L4: Coal price power $/GJ | M4: Gas price power $/GJ | N4: Gas price ind. $/GJ | O4: Market structure (PSRT) | P4: RISE RE score | Q4: Baseline CO2 Mt | R4: Avg intensity t/MWh | S4: Coal t/MWh | T4: Gas t/MWh | U4: Coal+oil t/MWh | V4: Tariff $/MWh | W4: Pass-through | X4: Max substitution share | Y4: Switching price $/t | Z4: B40 elec. budget share | AA4: Coal+oil gen share | AB4: F1 per $ tax | AC4: F2 per $ tax | AD4: F3 per $ tax | AE4: F3 per $ feebate | AF4: Tax cap from F1 | AG4: Tax cap from F2 | AH4: Tax cap from F3 | AI4: Best tax $/t | AJ4: Tax: E % | AK4: Tax: binding | AL4: Tax: +1pp F1 buys (pp E) | AM4: Best feebate $/t | AN4: Feebate: E % | AO4: Feebate: binding | AP4: E at $50 tax | AQ4: E at $50 feebate | AR4: Feebate/tax abatement ratio | AS4: F1 at $50 tax | AT4: Hybrid: E % | AU4: Hybrid: tax $/t | AV4: Hybrid: feebate $/t | AW4: Hybrid: F1 | AX4: Hybrid: F2 | AY4: Hybrid: F3 | AZ4: Hybrid: binding | BA4: Hybrid: Mt saved | BB4: Feebate at k=0 | BC4: Feebate at k=1 | BD4: Feebate at k=2 | BE4: Feebate at k=3 | BF4: Feebate at k=4 | BG4: Feebate at k=5 | BH4: Feebate at k=6 | BI4: Feebate at k=7 | BJ4: Feebate at k=8 | BK4: Feebate at k=9 | BL4: Feebate at k=10 | BM4: E at k=0 | BN4: E at k=1 | BO4: E at k=2 | BP4: E at k=3 | BQ4: E at k=4 | BR4: E at k=5 | BS4: E at k=6 | BT4: E at k=7 | BU4: E at k=8 | BV4: E at k=9 | BW4: E at k=10
A5: ABW | B5: =INDEX(Data!$B:$B,MATCH($A5,Data!$A:$A,0)) | C5: =INDEX(Data!$D:$D,MATCH($A5,Data!$A:$A,0)) | D5: =SUMIFS(Data!$G:$G,Data!$A:$A,$A5,Data!$F:$F,"gen_coal_twh") | E5: =SUMIFS(Data!$G:$G,Data!$A:$A,$A5,Data!$F:$F,"gen_gas_twh") | F5: =SUMIFS(Data!$G:$G,Data!$A:$A,$A5,Data!$F:$F,"gen_oil_twh") | G5: =SUMIFS(Data!$G:$G,Data!$A:$A,$A5,Data!$F:$F,"gen_total_twh") | H5: =SUMIFS(Data!$G:$G,Data!$A:$A,$A5,Data!$F:$F,"em_coal_mt") | I5: =SUMIFS(Data!$G:$G,Data!$A:$A,$A5,Data!$F:$F,"em_gas_mt") | J5: =SUMIFS(Data!$G:$G,Data!$A:$A,$A5,Data!$F:$F,"em_oil_mt") | K5: =IF(COUNTIFS(Data!$A:$A,$A5,Data!$F:$F,"price_electricity_residential_usd_kwh")=0,"",SUMIFS(Data!$G:$G,Data!$A:$A,$A5,Data!$F:$F,"price_electricity_residential_usd_kwh")) | L5: =IF(COUNTIFS(Data!$A:$A,$A5,Data!$F:$F,"price_coal_power_usd_gj")=0,"",SUMIFS(Data!$G:$G,Data!$A:$A,$A5,Data!$F:$F,"price_coal_power_usd_gj")) | M5: =IF(COUNTIFS(Data!$A:$A,$A5,Data!$F:$F,"price_gas_power_usd_gj")=0,"",SUMIFS(Data!$G:$G,Data!$A:$A,$A5,Data!$F:$F,"price_gas_power_usd_gj")) | N5: =IF(COUNTIFS(Data!$A:$A,$A5,Data!$F:$F,"price_gas_industry_usd_gj")=0,"",SUMIFS(Data!$G:$G,Data!$A:$A,$A5,Data!$F:$F,"price_gas_industry_usd_gj")) | O5: =IF(COUNTIFS(Data!$A:$A,$A5,Data!$F:$F,"power_market_structure")=0,"",SUMIFS(Data!$G:$G,Data!$A:$A,$A5,Data!$F:$F,"power_market_structure")) | P5: =IF(COUNTIFS(Data!$A:$A,$A5,Data!$F:$F,"rise_renewable_energy_score")=0,"",SUMIFS(Data!$G:$G,Data!$A:$A,$A5,Data!$F:$F,"rise_renewable_energy_score")) | Q5: =H5+I5+J5 | R5: =Q5/G5 | S5: =IF(D5>0,H5/D5,0.85) | T5: =IF(E5>0,I5/E5,0.4) | U5: =IF(D5+F5>0,(H5+J5)/(D5+F5),0) | V5: =K5*1000 | W5: =IF(O5=3,in_pt3,IF(O5=2,in_pt2,IF(O5=1,in_pt1,IF(C5="High income",in_pt_hi,in_pt_oth)))) | X5: =IF(Q5>0,in_kappa*(in_rise_lo+(in_rise_hi-in_rise_lo)*IF(P5="",in_rise_miss,P5)/100)*(D5+F5)*MAX(U5-in_gas_rep*T5,0)/Q5,0) | Y5: =IF(IF(M5="",N5,M5)="",MAX(in_sw_floor,in_sw_miss),MAX(in_sw_floor,(IF(M5="",N5,M5)*in_hr_gas-L5*in_hr_coal)/MAX(S5-T5,0.1))) | Z5: =IF(C5="Low income",in_b40_li,IF(C5="Lower middle income",in_b40_lmi,IF(C5="Upper middle income",in_b40_umi,IF(C5="High income",in_b40_hi,0.03)))) | AA5: =(D5+F5)/G5 | AB5: =100*W5*R5/V5/in_phase | AC5: =100*Z5*W5*R5/V5*(1-IF(W5>0,MIN(in_rebate/(W5*in_res_sh*in_q40),1),1)) | AD5: =IF(AA5>0,100*U5*(1-W5)/(in_whole_sh*V5),0) | AE5: =IF(AA5>0,100*MAX(U5-R5,0)/(in_whole_sh*V5),0) | AF5: =IF(AB5>0,in_f1/AB5,in_cap) | AG5: =IF(AC5>0,in_f2/AC5,in_cap) | AH5: =IF(AD5>0,in_f3/AD5,in_cap) | AI5: =MIN(in_cap,AF5,AG5,AH5) | AJ5: =100*(1-(1-X5*(1-EXP(-((AI5)+(0))/Y5)))*(1-MIN(ABS(in_elas)*W5*R5*(AI5)/V5,1))) | AK5: =IF(AI5>=in_cap-1E-9,"rate cap",TRIM(IF(ABS(AI5-AF5)<1E-9,"F1 ","")&IF(ABS(AI5-AG5)<1E-9,"F2 ","")&IF(ABS(AI5-AH5)<1E-9,"F3",""))) | AL5: =100*(1-(1-X5*(1-EXP(-((MIN(in_cap,IF(AB5>0,(in_f1+1)/AB5,in_cap),AG5,AH5))+(0))/Y5)))*(1-MIN(ABS(in_elas)*W5*R5*(MIN(in_cap,IF(AB5>0,(in_f1+1)/AB5,in_cap),AG5,AH5))/V5,1)))-AJ5 | AM5: =MIN(in_cap,IF(AE5>0,in_f3/AE5,in_cap)) | AN5: =100*(1-(1-X5*(1-EXP(-((0)+(AM5))/Y5)))*(1-MIN(ABS(in_elas)*W5*R5*(0)/V5,1))) | AO5: =IF(AM5>=in_cap-1E-9,"rate cap","F3") | AP5: =100*(1-(1-X5*(1-EXP(-((50)+(0))/Y5)))*(1-MIN(ABS(in_elas)*W5*R5*(50)/V5,1))) | AQ5: =100*(1-(1-X5*(1-EXP(-((0)+(50))/Y5)))*(1-MIN(ABS(in_elas)*W5*R5*(0)/V5,1))) | AR5: =IF(AP5>0,AQ5/AP5,"") | AS5: =50*AB5 | AT5: =MAX(BM5:BW5) | AU5: =AI5*(MATCH(AT5,BM5:BW5,0)-1)/10 | AV5: =INDEX(BB5:BL5,1,(MATCH(AT5,BM5:BW5,0)-1)+1) | AW5: =AB5*AU5 | AX5: =AC5*AU5 | AY5: =AD5*AU5+AE5*AV5 | AZ5: =TRIM(IF(AND(AU5>0,ABS(AU5-AF5)<1E-6),"F1 ","")&IF(AND(AU5>0,ABS(AU5-AG5)<1E-6),"F2 ","")&IF(AY5>=in_f3-1E-6,"F3 ","")&IF(AV5>=in_cap-1E-9,"rate cap","")) | BA5: =Q5*AT5/100 | BB5: =MAX(0,MIN(in_cap,IF(AE5>0,(in_f3-AD5*AI5*0/10)/AE5,in_cap))) | BC5: =MAX(0,MIN(in_cap,IF(AE5>0,(in_f3-AD5*AI5*1/10)/AE5,in_cap))) | BD5: =MAX(0,MIN(in_cap,IF(AE5>0,(in_f3-AD5*AI5*2/10)/AE5,in_cap))) | BE5: =MAX(0,MIN(in_cap,IF(AE5>0,(in_f3-AD5*AI5*3/10)/AE5,in_cap))) | BF5: =MAX(0,MIN(in_cap,IF(AE5>0,(in_f3-AD5*AI5*4/10)/AE5,in_cap))) | BG5: =MAX(0,MIN(in_cap,IF(AE5>0,(in_f3-AD5*AI5*5/10)/AE5,in_cap))) | BH5: =MAX(0,MIN(in_cap,IF(AE5>0,(in_f3-AD5*AI5*6/10)/AE5,in_cap))) | BI5: =MAX(0,MIN(in_cap,IF(AE5>0,(in_f3-AD5*AI5*7/10)/AE5,in_cap))) | BJ5: =MAX(0,MIN(in_cap,IF(AE5>0,(in_f3-AD5*AI5*8/10)/AE5,in_cap))) | BK5: =MAX(0,MIN(in_cap,IF(AE5>0,(in_f3-AD5*AI5*9/10)/AE5,in_cap))) | BL5: =MAX(0,MIN(in_cap,IF(AE5>0,(in_f3-AD5*AI5*10/10)/AE5,in_cap))) | BM5: =100*(1-(1-X5*(1-EXP(-((AI5*0/10)+(BB5))/Y5)))*(1-MIN(ABS(in_elas)*W5*R5*(AI5*0/10)/V5,1))) | BN5: =100*(1-(1-X5*(1-EXP(-((AI5*1/10)+(BC5))/Y5)))*(1-MIN(ABS(in_elas)*W5*R5*(AI5*1/10)/V5,1))) | BO5: =100*(1-(1-X5*(1-EXP(-((AI5*2/10)+(BD5))/Y5)))*(1-MIN(ABS(in_elas)*W5*R5*(AI5*2/10)/V5,1))) | BP5: =100*(1-(1-X5*(1-EXP(-((AI5*3/10)+(BE5))/Y5)))*(1-MIN(ABS(in_elas)*W5*R5*(AI5*3/10)/V5,1))) | BQ5: =100*(1-(1-X5*(1-EXP(-((AI5*4/10)+(BF5))/Y5)))*(1-MIN(ABS(in_elas)*W5*R5*(AI5*4/10)/V5,1))) | BR5: =100*(1-(1-X5*(1-EXP(-((AI5*5/10)+(BG5))/Y5)))*(1-MIN(ABS(in_elas)*W5*R5*(AI5*5/10)/V5,1))) | BS5: =100*(1-(1-X5*(1-EXP(-((AI5*6/10)+(BH5))/Y5)))*(1-MIN(ABS(in_elas)*W5*R5*(AI5*6/10)/V5,1))) | BT5: =100*(1-(1-X5*(1-EXP(-((AI5*7/10)+(BI5))/Y5)))*(1-MIN(ABS(in_elas)*W5*R5*(AI5*7/10)/V5,1))) | BU5: =100*(1-(1-X5*(1-EXP(-((AI5*8/10)+(BJ5))/Y5)))*(1-MIN(ABS(in_elas)*W5*R5*(AI5*8/10)/V5,1))) | BV5: =100*(1-(1-X5*(1-EXP(-((AI5*9/10)+(BK5))/Y5)))*(1-MIN(ABS(in_elas)*W5*R5*(AI5*9/10)/V5,1))) | BW5: =100*(1-(1-X5*(1-EXP(-((AI5*10/10)+(BL5))/Y5)))*(1-MIN(ABS(in_elas)*W5*R5*(AI5*10/10)/V5,1)))
A6: AFG | B6: =INDEX(Data!$B:$B,MATCH($A6,Data!$A:$A,0)) | C6: =INDEX(Data!$D:$D,MATCH($A6,Data!$A:$A,0)) | D6: =SUMIFS(Data!$G:$G,Data!$A:$A,$A6,Data!$F:$F,"gen_coal_twh") | E6: =SUMIFS(Data!$G:$G,Data!$A:$A,$A6,Data!$F:$F,"gen_gas_twh") | F6: =SUMIFS(Data!$G:$G,Data!$A:$A,$A6,Data!$F:$F,"gen_oil_twh") | G6: =SUMIFS(Data!$G:$G,Data!$A:$A,$A6,Data!$F:$F,"gen_total_twh") | H6: =SUMIFS(Data!$G:$G,Data!$A:$A,$A6,Data!$F:$F,"em_coal_mt") | I6: =SUMIFS(Data!$G:$G,Data!$A:$A,$A6,Data!$F:$F,"em_gas_mt") | J6: =SUMIFS(Data!$G:$G,Data!$A:$A,$A6,Data!$F:$F,"em_oil_mt") | K6: =IF(COUNTIFS(Data!$A:$A,$A6,Data!$F:$F,"price_electricity_residential_usd_kwh")=0,"",SUMIFS(Data!$G:$G,Data!$A:$A,$A6,Data!$F:$F,"price_electricity_residential_usd_kwh")) | L6: =IF(COUNTIFS(Data!$A:$A,$A6,Data!$F:$F,"price_coal_power_usd_gj")=0,"",SUMIFS(Data!$G:$G,Data!$A:$A,$A6,Data!$F:$F,"price_coal_power_usd_gj")) | M6: =IF(COUNTIFS(Data!$A:$A,$A6,Data!$F:$F,"price_gas_power_usd_gj")=0,"",SUMIFS(Data!$G:$G,Data!$A:$A,$A6,Data!$F:$F,"price_gas_power_usd_gj")) | N6: =IF(COUNTIFS(Data!$A:$A,$A6,Data!$F:$F,"price_gas_industry_usd_gj")=0,"",SUMIFS(Data!$G:$G,Data!$A:$A,$A6,Data!$F:$F,"price_gas_industry_usd_gj")) | O6: =IF(COUNTIFS(Data!$A:$A,$A6,Data!$F:$F,"power_market_structure")=0,"",SUMIFS(Data!$G:$G,Data!$A:$A,$A6,Data!$F:$F,"power_market_structure")) | P6: =IF(COUNTIFS(Data!$A:$A,$A6,Data!$F:$F,"rise_renewable_energy_score")=0,"",SUMIFS(Data!$G:$G,Data!$A:$A,$A6,Data!$F:$F,"rise_renewable_energy_score")) | Q6: =H6+I6+J6 | R6: =Q6/G6 | S6: =IF(D6>0,H6/D6,0.85) | T6: =IF(E6>0,I6/E6,0.4) | U6: =IF(D6+F6>0,(H6+J6)/(D6+F6),0) | V6: =K6*1000 | W6: =IF(O6=3,in_pt3,IF(O6=2,in_pt2,IF(O6=1,in_pt1,IF(C6="High income",in_pt_hi,in_pt_oth)))) | X6: =IF(Q6>0,in_kappa*(in_rise_lo+(in_rise_hi-in_rise_lo)*IF(P6="",in_rise_miss,P6)/100)*(D6+F6)*MAX(U6-in_gas_rep*T6,0)/Q6,0) | Y6: =IF(IF(M6="",N6,M6)="",MAX(in_sw_floor,in_sw_miss),MAX(in_sw_floor,(IF(M6="",N6,M6)*in_hr_gas-L6*in_hr_coal)/MAX(S6-T6,0.1))) | Z6: =IF(C6="Low income",in_b40_li,IF(C6="Lower middle income",in_b40_lmi,IF(C6="Upper middle income",in_b40_umi,IF(C6="High income",in_b40_hi,0.03)))) | AA6: =(D6+F6)/G6 | AB6: =100*W6*R6/V6/in_phase | AC6: =100*Z6*W6*R6/V6*(1-IF(W6>0,MIN(in_rebate/(W6*in_res_sh*in_q40),1),1)) | AD6: =IF(AA6>0,100*U6*(1-W6)/(in_whole_sh*V6),0) | AE6: =IF(AA6>0,100*MAX(U6-R6,0)/(in_whole_sh*V6),0) | AF6: =IF(AB6>0,in_f1/AB6,in_cap) | AG6: =IF(AC6>0,in_f2/AC6,in_cap) | AH6: =IF(AD6>0,in_f3/AD6,in_cap) | AI6: =MIN(in_cap,AF6,AG6,AH6) | AJ6: =100*(1-(1-X6*(1-EXP(-((AI6)+(0))/Y6)))*(1-MIN(ABS(in_elas)*W6*R6*(AI6)/V6,1))) | AK6: =IF(AI6>=in_cap-1E-9,"rate cap",TRIM(IF(ABS(AI6-AF6)<1E-9,"F1 ","")&IF(ABS(AI6-AG6)<1E-9,"F2 ","")&IF(ABS(AI6-AH6)<1E-9,"F3",""))) | AL6: =100*(1-(1-X6*(1-EXP(-((MIN(in_cap,IF(AB6>0,(in_f1+1)/AB6,in_cap),AG6,AH6))+(0))/Y6)))*(1-MIN(ABS(in_elas)*W6*R6*(MIN(in_cap,IF(AB6>0,(in_f1+1)/AB6,in_cap),AG6,AH6))/V6,1)))-AJ6 | AM6: =MIN(in_cap,IF(AE6>0,in_f3/AE6,in_cap)) | AN6: =100*(1-(1-X6*(1-EXP(-((0)+(AM6))/Y6)))*(1-MIN(ABS(in_elas)*W6*R6*(0)/V6,1))) | AO6: =IF(AM6>=in_cap-1E-9,"rate cap","F3") | AP6: =100*(1-(1-X6*(1-EXP(-((50)+(0))/Y6)))*(1-MIN(ABS(in_elas)*W6*R6*(50)/V6,1))) | AQ6: =100*(1-(1-X6*(1-EXP(-((0)+(50))/Y6)))*(1-MIN(ABS(in_elas)*W6*R6*(0)/V6,1))) | AR6: =IF(AP6>0,AQ6/AP6,"") | AS6: =50*AB6 | AT6: =MAX(BM6:BW6) | AU6: =AI6*(MATCH(AT6,BM6:BW6,0)-1)/10 | AV6: =INDEX(BB6:BL6,1,(MATCH(AT6,BM6:BW6,0)-1)+1) | AW6: =AB6*AU6 | AX6: =AC6*AU6 | AY6: =AD6*AU6+AE6*AV6 | AZ6: =TRIM(IF(AND(AU6>0,ABS(AU6-AF6)<1E-6),"F1 ","")&IF(AND(AU6>0,ABS(AU6-AG6)<1E-6),"F2 ","")&IF(AY6>=in_f3-1E-6,"F3 ","")&IF(AV6>=in_cap-1E-9,"rate cap","")) | BA6: =Q6*AT6/100 | BB6: =MAX(0,MIN(in_cap,IF(AE6>0,(in_f3-AD6*AI6*0/10)/AE6,in_cap))) | BC6: =MAX(0,MIN(in_cap,IF(AE6>0,(in_f3-AD6*AI6*1/10)/AE6,in_cap))) | BD6: =MAX(0,MIN(in_cap,IF(AE6>0,(in_f3-AD6*AI6*2/10)/AE6,in_cap))) | BE6: =MAX(0,MIN(in_cap,IF(AE6>0,(in_f3-AD6*AI6*3/10)/AE6,in_cap))) | BF6: =MAX(0,MIN(in_cap,IF(AE6>0,(in_f3-AD6*AI6*4/10)/AE6,in_cap))) | BG6: =MAX(0,MIN(in_cap,IF(AE6>0,(in_f3-AD6*AI6*5/10)/AE6,in_cap))) | BH6: =MAX(0,MIN(in_cap,IF(AE6>0,(in_f3-AD6*AI6*6/10)/AE6,in_cap))) | BI6: =MAX(0,MIN(in_cap,IF(AE6>0,(in_f3-AD6*AI6*7/10)/AE6,in_cap))) | BJ6: =MAX(0,MIN(in_cap,IF(AE6>0,(in_f3-AD6*AI6*8/10)/AE6,in_cap))) | BK6: =MAX(0,MIN(in_cap,IF(AE6>0,(in_f3-AD6*AI6*9/10)/AE6,in_cap))) | BL6: =MAX(0,MIN(in_cap,IF(AE6>0,(in_f3-AD6*AI6*10/10)/AE6,in_cap))) | BM6: =100*(1-(1-X6*(1-EXP(-((AI6*0/10)+(BB6))/Y6)))*(1-MIN(ABS(in_elas)*W6*R6*(AI6*0/10)/V6,1))) | BN6: =100*(1-(1-X6*(1-EXP(-((AI6*1/10)+(BC6))/Y6)))*(1-MIN(ABS(in_elas)*W6*R6*(AI6*1/10)/V6,1))) | BO6: =100*(1-(1-X6*(1-EXP(-((AI6*2/10)+(BD6))/Y6)))*(1-MIN(ABS(in_elas)*W6*R6*(AI6*2/10)/V6,1))) | BP6: =100*(1-(1-X6*(1-EXP(-((AI6*3/10)+(BE6))/Y6)))*(1-MIN(ABS(in_elas)*W6*R6*(AI6*3/10)/V6,1))) | BQ6: =100*(1-(1-X6*(1-EXP(-((AI6*4/10)+(BF6))/Y6)))*(1-MIN(ABS(in_elas)*W6*R6*(AI6*4/10)/V6,1))) | BR6: =100*(1-(1-X6*(1-EXP(-((AI6*5/10)+(BG6))/Y6)))*(1-MIN(ABS(in_elas)*W6*R6*(AI6*5/10)/V6,1))) | BS6: =100*(1-(1-X6*(1-EXP(-((AI6*6/10)+(BH6))/Y6)))*(1-MIN(ABS(in_elas)*W6*R6*(AI6*6/10)/V6,1))) | BT6: =100*(1-(1-X6*(1-EXP(-((AI6*7/10)+(BI6))/Y6)))*(1-MIN(ABS(in_elas)*W6*R6*(AI6*7/10)/V6,1))) | BU6: =100*(1-(1-X6*(1-EXP(-((AI6*8/10)+(BJ6))/Y6)))*(1-MIN(ABS(in_elas)*W6*R6*(AI6*8/10)/V6,1))) | BV6: =100*(1-(1-X6*(1-EXP(-((AI6*9/10)+(BK6))/Y6)))*(1-MIN(ABS(in_elas)*W6*R6*(AI6*9/10)/V6,1))) | BW6: =100*(1-(1-X6*(1-EXP(-((AI6*10/10)+(BL6))/Y6)))*(1-MIN(ABS(in_elas)*W6*R6*(AI6*10/10)/V6,1)))
A7: AGO | B7: =INDEX(Data!$B:$B,MATCH($A7,Data!$A:$A,0)) | C7: =INDEX(Data!$D:$D,MATCH($A7,Data!$A:$A,0)) | D7: =SUMIFS(Data!$G:$G,Data!$A:$A,$A7,Data!$F:$F,"gen_coal_twh") | E7: =SUMIFS(Data!$G:$G,Data!$A:$A,$A7,Data!$F:$F,"gen_gas_twh") | F7: =SUMIFS(Data!$G:$G,Data!$A:$A,$A7,Data!$F:$F,"gen_oil_twh") | G7: =SUMIFS(Data!$G:$G,Data!$A:$A,$A7,Data!$F:$F,"gen_total_twh") | H7: =SUMIFS(Data!$G:$G,Data!$A:$A,$A7,Data!$F:$F,"em_coal_mt") | I7: =SUMIFS(Data!$G:$G,Data!$A:$A,$A7,Data!$F:$F,"em_gas_mt") | J7: =SUMIFS(Data!$G:$G,Data!$A:$A,$A7,Data!$F:$F,"em_oil_mt") | K7: =IF(COUNTIFS(Data!$A:$A,$A7,Data!$F:$F,"price_electricity_residential_usd_kwh")=0,"",SUMIFS(Data!$G:$G,Data!$A:$A,$A7,Data!$F:$F,"price_electricity_residential_usd_kwh")) | L7: =IF(COUNTIFS(Data!$A:$A,$A7,Data!$F:$F,"price_coal_power_usd_gj")=0,"",SUMIFS(Data!$G:$G,Data!$A:$A,$A7,Data!$F:$F,"price_coal_power_usd_gj")) | M7: =IF(COUNTIFS(Data!$A:$A,$A7,Data!$F:$F,"price_gas_power_usd_gj")=0,"",SUMIFS(Data!$G:$G,Data!$A:$A,$A7,Data!$F:$F,"price_gas_power_usd_gj")) | N7: =IF(COUNTIFS(Data!$A:$A,$A7,Data!$F:$F,"price_gas_industry_usd_gj")=0,"",SUMIFS(Data!$G:$G,Data!$A:$A,$A7,Data!$F:$F,"price_gas_industry_usd_gj")) | O7: =IF(COUNTIFS(Data!$A:$A,$A7,Data!$F:$F,"power_market_structure")=0,"",SUMIFS(Data!$G:$G,Data!$A:$A,$A7,Data!$F:$F,"power_market_structure")) | P7: =IF(COUNTIFS(Data!$A:$A,$A7,Data!$F:$F,"rise_renewable_energy_score")=0,"",SUMIFS(Data!$G:$G,Data!$A:$A,$A7,Data!$F:$F,"rise_renewable_energy_score")) | Q7: =H7+I7+J7 | R7: =Q7/G7 | S7: =IF(D7>0,H7/D7,0.85) | T7: =IF(E7>0,I7/E7,0.4) | U7: =IF(D7+F7>0,(H7+J7)/(D7+F7),0) | V7: =K7*1000 | W7: =IF(O7=3,in_pt3,IF(O7=2,in_pt2,IF(O7=1,in_pt1,IF(C7="High income",in_pt_hi,in_pt_oth)))) | X7: =IF(Q7>0,in_kappa*(in_rise_lo+(in_rise_hi-in_rise_lo)*IF(P7="",in_rise_miss,P7)/100)*(D7+F7)*MAX(U7-in_gas_rep*T7,0)/Q7,0) | Y7: =IF(IF(M7="",N7,M7)="",MAX(in_sw_floor,in_sw_miss),MAX(in_sw_floor,(IF(M7="",N7,M7)*in_hr_gas-L7*in_hr_coal)/MAX(S7-T7,0.1))) | Z7: =IF(C7="Low income",in_b40_li,IF(C7="Lower middle income",in_b40_lmi,IF(C7="Upper middle income",in_b40_umi,IF(C7="High income",in_b40_hi,0.03)))) | AA7: =(D7+F7)/G7 | AB7: =100*W7*R7/V7/in_phase | AC7: =100*Z7*W7*R7/V7*(1-IF(W7>0,MIN(in_rebate/(W7*in_res_sh*in_q40),1),1)) | AD7: =IF(AA7>0,100*U7*(1-W7)/(in_whole_sh*V7),0) | AE7: =IF(AA7>0,100*MAX(U7-R7,0)/(in_whole_sh*V7),0) | AF7: =IF(AB7>0,in_f1/AB7,in_cap) | AG7: =IF(AC7>0,in_f2/AC7,in_cap) | AH7: =IF(AD7>0,in_f3/AD7,in_cap) | AI7: =MIN(in_cap,AF7,AG7,AH7) | AJ7: =100*(1-(1-X7*(1-EXP(-((AI7)+(0))/Y7)))*(1-MIN(ABS(in_elas)*W7*R7*(AI7)/V7,1))) | AK7: =IF(AI7>=in_cap-1E-9,"rate cap",TRIM(IF(ABS(AI7-AF7)<1E-9,"F1 ","")&IF(ABS(AI7-AG7)<1E-9,"F2 ","")&IF(ABS(AI7-AH7)<1E-9,"F3",""))) | AL7: =100*(1-(1-X7*(1-EXP(-((MIN(in_cap,IF(AB7>0,(in_f1+1)/AB7,in_cap),AG7,AH7))+(0))/Y7)))*(1-MIN(ABS(in_elas)*W7*R7*(MIN(in_cap,IF(AB7>0,(in_f1+1)/AB7,in_cap),AG7,AH7))/V7,1)))-AJ7 | AM7: =MIN(in_cap,IF(AE7>0,in_f3/AE7,in_cap)) | AN7: =100*(1-(1-X7*(1-EXP(-((0)+(AM7))/Y7)))*(1-MIN(ABS(in_elas)*W7*R7*(0)/V7,1))) | AO7: =IF(AM7>=in_cap-1E-9,"rate cap","F3") | AP7: =100*(1-(1-X7*(1-EXP(-((50)+(0))/Y7)))*(1-MIN(ABS(in_elas)*W7*R7*(50)/V7,1))) | AQ7: =100*(1-(1-X7*(1-EXP(-((0)+(50))/Y7)))*(1-MIN(ABS(in_elas)*W7*R7*(0)/V7,1))) | AR7: =IF(AP7>0,AQ7/AP7,"") | AS7: =50*AB7 | AT7: =MAX(BM7:BW7) | AU7: =AI7*(MATCH(AT7,BM7:BW7,0)-1)/10 | AV7: =INDEX(BB7:BL7,1,(MATCH(AT7,BM7:BW7,0)-1)+1) | AW7: =AB7*AU7 | AX7: =AC7*AU7 | AY7: =AD7*AU7+AE7*AV7 | AZ7: =TRIM(IF(AND(AU7>0,ABS(AU7-AF7)<1E-6),"F1 ","")&IF(AND(AU7>0,ABS(AU7-AG7)<1E-6),"F2 ","")&IF(AY7>=in_f3-1E-6,"F3 ","")&IF(AV7>=in_cap-1E-9,"rate cap","")) | BA7: =Q7*AT7/100 | BB7: =MAX(0,MIN(in_cap,IF(AE7>0,(in_f3-AD7*AI7*0/10)/AE7,in_cap))) | BC7: =MAX(0,MIN(in_cap,IF(AE7>0,(in_f3-AD7*AI7*1/10)/AE7,in_cap))) | BD7: =MAX(0,MIN(in_cap,IF(AE7>0,(in_f3-AD7*AI7*2/10)/AE7,in_cap))) | BE7: =MAX(0,MIN(in_cap,IF(AE7>0,(in_f3-AD7*AI7*3/10)/AE7,in_cap))) | BF7: =MAX(0,MIN(in_cap,IF(AE7>0,(in_f3-AD7*AI7*4/10)/AE7,in_cap))) | BG7: =MAX(0,MIN(in_cap,IF(AE7>0,(in_f3-AD7*AI7*5/10)/AE7,in_cap))) | BH7: =MAX(0,MIN(in_cap,IF(AE7>0,(in_f3-AD7*AI7*6/10)/AE7,in_cap))) | BI7: =MAX(0,MIN(in_cap,IF(AE7>0,(in_f3-AD7*AI7*7/10)/AE7,in_cap))) | BJ7: =MAX(0,MIN(in_cap,IF(AE7>0,(in_f3-AD7*AI7*8/10)/AE7,in_cap))) | BK7: =MAX(0,MIN(in_cap,IF(AE7>0,(in_f3-AD7*AI7*9/10)/AE7,in_cap))) | BL7: =MAX(0,MIN(in_cap,IF(AE7>0,(in_f3-AD7*AI7*10/10)/AE7,in_cap))) | BM7: =100*(1-(1-X7*(1-EXP(-((AI7*0/10)+(BB7))/Y7)))*(1-MIN(ABS(in_elas)*W7*R7*(AI7*0/10)/V7,1))) | BN7: =100*(1-(1-X7*(1-EXP(-((AI7*1/10)+(BC7))/Y7)))*(1-MIN(ABS(in_elas)*W7*R7*(AI7*1/10)/V7,1))) | BO7: =100*(1-(1-X7*(1-EXP(-((AI7*2/10)+(BD7))/Y7)))*(1-MIN(ABS(in_elas)*W7*R7*(AI7*2/10)/V7,1))) | BP7: =100*(1-(1-X7*(1-EXP(-((AI7*3/10)+(BE7))/Y7)))*(1-MIN(ABS(in_elas)*W7*R7*(AI7*3/10)/V7,1))) | BQ7: =100*(1-(1-X7*(1-EXP(-((AI7*4/10)+(BF7))/Y7)))*(1-MIN(ABS(in_elas)*W7*R7*(AI7*4/10)/V7,1))) | BR7: =100*(1-(1-X7*(1-EXP(-((AI7*5/10)+(BG7))/Y7)))*(1-MIN(ABS(in_elas)*W7*R7*(AI7*5/10)/V7,1))) | BS7: =100*(1-(1-X7*(1-EXP(-((AI7*6/10)+(BH7))/Y7)))*(1-MIN(ABS(in_elas)*W7*R7*(AI7*6/10)/V7,1))) | BT7: =100*(1-(1-X7*(1-EXP(-((AI7*7/10)+(BI7))/Y7)))*(1-MIN(ABS(in_elas)*W7*R7*(AI7*7/10)/V7,1))) | BU7: =100*(1-(1-X7*(1-EXP(-((AI7*8/10)+(BJ7))/Y7)))*(1-MIN(ABS(in_elas)*W7*R7*(AI7*8/10)/V7,1))) | BV7: =100*(1-(1-X7*(1-EXP(-((AI7*9/10)+(BK7))/Y7)))*(1-MIN(ABS(in_elas)*W7*R7*(AI7*9/10)/V7,1))) | BW7: =100*(1-(1-X7*(1-EXP(-((AI7*10/10)+(BL7))/Y7)))*(1-MIN(ABS(in_elas)*W7*R7*(AI7*10/10)/V7,1)))
A8: ARE | B8: =INDEX(Data!$B:$B,MATCH($A8,Data!$A:$A,0)) | C8: =INDEX(Data!$D:$D,MATCH($A8,Data!$A:$A,0)) | D8: =SUMIFS(Data!$G:$G,Data!$A:$A,$A8,Data!$F:$F,"gen_coal_twh") | E8: =SUMIFS(Data!$G:$G,Data!$A:$A,$A8,Data!$F:$F,"gen_gas_twh") | F8: =SUMIFS(Data!$G:$G,Data!$A:$A,$A8,Data!$F:$F,"gen_oil_twh") | G8: =SUMIFS(Data!$G:$G,Data!$A:$A,$A8,Data!$F:$F,"gen_total_twh") | H8: =SUMIFS(Data!$G:$G,Data!$A:$A,$A8,Data!$F:$F,"em_coal_mt") | I8: =SUMIFS(Data!$G:$G,Data!$A:$A,$A8,Data!$F:$F,"em_gas_mt") | J8: =SUMIFS(Data!$G:$G,Data!$A:$A,$A8,Data!$F:$F,"em_oil_mt") | K8: =IF(COUNTIFS(Data!$A:$A,$A8,Data!$F:$F,"price_electricity_residential_usd_kwh")=0,"",SUMIFS(Data!$G:$G,Data!$A:$A,$A8,Data!$F:$F,"price_electricity_residential_usd_kwh")) | L8: =IF(COUNTIFS(Data!$A:$A,$A8,Data!$F:$F,"price_coal_power_usd_gj")=0,"",SUMIFS(Data!$G:$G,Data!$A:$A,$A8,Data!$F:$F,"price_coal_power_usd_gj")) | M8: =IF(COUNTIFS(Data!$A:$A,$A8,Data!$F:$F,"price_gas_power_usd_gj")=0,"",SUMIFS(Data!$G:$G,Data!$A:$A,$A8,Data!$F:$F,"price_gas_power_usd_gj")) | N8: =IF(COUNTIFS(Data!$A:$A,$A8,Data!$F:$F,"price_gas_industry_usd_gj")=0,"",SUMIFS(Data!$G:$G,Data!$A:$A,$A8,Data!$F:$F,"price_gas_industry_usd_gj")) | O8: =IF(COUNTIFS(Data!$A:$A,$A8,Data!$F:$F,"power_market_structure")=0,"",SUMIFS(Data!$G:$G,Data!$A:$A,$A8,Data!$F:$F,"power_market_structure")) | P8: =IF(COUNTIFS(Data!$A:$A,$A8,Data!$F:$F,"rise_renewable_energy_score")=0,"",SUMIFS(Data!$G:$G,Data!$A:$A,$A8,Data!$F:$F,"rise_renewable_energy_score")) | Q8: =H8+I8+J8 | R8: =Q8/G8 | S8: =IF(D8>0,H8/D8,0.85) | T8: =IF(E8>0,I8/E8,0.4) | U8: =IF(D8+F8>0,(H8+J8)/(D8+F8),0) | V8: =K8*1000 | W8: =IF(O8=3,in_pt3,IF(O8=2,in_pt2,IF(O8=1,in_pt1,IF(C8="High income",in_pt_hi,in_pt_oth)))) | X8: =IF(Q8>0,in_kappa*(in_rise_lo+(in_rise_hi-in_rise_lo)*IF(P8="",in_rise_miss,P8)/100)*(D8+F8)*MAX(U8-in_gas_rep*T8,0)/Q8,0) | Y8: =IF(IF(M8="",N8,M8)="",MAX(in_sw_floor,in_sw_miss),MAX(in_sw_floor,(IF(M8="",N8,M8)*in_hr_gas-L8*in_hr_coal)/MAX(S8-T8,0.1))) | Z8: =IF(C8="Low income",in_b40_li,IF(C8="Lower middle income",in_b40_lmi,IF(C8="Upper middle income",in_b40_umi,IF(C8="High income",in_b40_hi,0.03)))) | AA8: =(D8+F8)/G8 | AB8: =100*W8*R8/V8/in_phase | AC8: =100*Z8*W8*R8/V8*(1-IF(W8>0,MIN(in_rebate/(W8*in_res_sh*in_q40),1),1)) | AD8: =IF(AA8>0,100*U8*(1-W8)/(in_whole_sh*V8),0) | AE8: =IF(AA8>0,100*MAX(U8-R8,0)/(in_whole_sh*V8),0) | AF8: =IF(AB8>0,in_f1/AB8,in_cap) | AG8: =IF(AC8>0,in_f2/AC8,in_cap) | AH8: =IF(AD8>0,in_f3/AD8,in_cap) | AI8: =MIN(in_cap,AF8,AG8,AH8) | AJ8: =100*(1-(1-X8*(1-EXP(-((AI8)+(0))/Y8)))*(1-MIN(ABS(in_elas)*W8*R8*(AI8)/V8,1))) | AK8: =IF(AI8>=in_cap-1E-9,"rate cap",TRIM(IF(ABS(AI8-AF8)<1E-9,"F1 ","")&IF(ABS(AI8-AG8)<1E-9,"F2 ","")&IF(ABS(AI8-AH8)<1E-9,"F3",""))) | AL8: =100*(1-(1-X8*(1-EXP(-((MIN(in_cap,IF(AB8>0,(in_f1+1)/AB8,in_cap),AG8,AH8))+(0))/Y8)))*(1-MIN(ABS(in_elas)*W8*R8*(MIN(in_cap,IF(AB8>0,(in_f1+1)/AB8,in_cap),AG8,AH8))/V8,1)))-AJ8 | AM8: =MIN(in_cap,IF(AE8>0,in_f3/AE8,in_cap)) | AN8: =100*(1-(1-X8*(1-EXP(-((0)+(AM8))/Y8)))*(1-MIN(ABS(in_elas)*W8*R8*(0)/V8,1))) | AO8: =IF(AM8>=in_cap-1E-9,"rate cap","F3") | AP8: =100*(1-(1-X8*(1-EXP(-((50)+(0))/Y8)))*(1-MIN(ABS(in_elas)*W8*R8*(50)/V8,1))) | AQ8: =100*(1-(1-X8*(1-EXP(-((0)+(50))/Y8)))*(1-MIN(ABS(in_elas)*W8*R8*(0)/V8,1))) | AR8: =IF(AP8>0,AQ8/AP8,"") | AS8: =50*AB8 | AT8: =MAX(BM8:BW8) | AU8: =AI8*(MATCH(AT8,BM8:BW8,0)-1)/10 | AV8: =INDEX(BB8:BL8,1,(MATCH(AT8,BM8:BW8,0)-1)+1) | AW8: =AB8*AU8 | AX8: =AC8*AU8 | AY8: =AD8*AU8+AE8*AV8 | AZ8: =TRIM(IF(AND(AU8>0,ABS(AU8-AF8)<1E-6),"F1 ","")&IF(AND(AU8>0,ABS(AU8-AG8)<1E-6),"F2 ","")&IF(AY8>=in_f3-1E-6,"F3 ","")&IF(AV8>=in_cap-1E-9,"rate cap","")) | BA8: =Q8*AT8/100 | BB8: =MAX(0,MIN(in_cap,IF(AE8>0,(in_f3-AD8*AI8*0/10)/AE8,in_cap))) | BC8: =MAX(0,MIN(in_cap,IF(AE8>0,(in_f3-AD8*AI8*1/10)/AE8,in_cap))) | BD8: =MAX(0,MIN(in_cap,IF(AE8>0,(in_f3-AD8*AI8*2/10)/AE8,in_cap))) | BE8: =MAX(0,MIN(in_cap,IF(AE8>0,(in_f3-AD8*AI8*3/10)/AE8,in_cap))) | BF8: =MAX(0,MIN(in_cap,IF(AE8>0,(in_f3-AD8*AI8*4/10)/AE8,in_cap))) | BG8: =MAX(0,MIN(in_cap,IF(AE8>0,(in_f3-AD8*AI8*5/10)/AE8,in_cap))) | BH8: =MAX(0,MIN(in_cap,IF(AE8>0,(in_f3-AD8*AI8*6/10)/AE8,in_cap))) | BI8: =MAX(0,MIN(in_cap,IF(AE8>0,(in_f3-AD8*AI8*7/10)/AE8,in_cap))) | BJ8: =MAX(0,MIN(in_cap,IF(AE8>0,(in_f3-AD8*AI8*8/10)/AE8,in_cap))) | BK8: =MAX(0,MIN(in_cap,IF(AE8>0,(in_f3-AD8*AI8*9/10)/AE8,in_cap))) | BL8: =MAX(0,MIN(in_cap,IF(AE8>0,(in_f3-AD8*AI8*10/10)/AE8,in_cap))) | BM8: =100*(1-(1-X8*(1-EXP(-((AI8*0/10)+(BB8))/Y8)))*(1-MIN(ABS(in_elas)*W8*R8*(AI8*0/10)/V8,1))) | BN8: =100*(1-(1-X8*(1-EXP(-((AI8*1/10)+(BC8))/Y8)))*(1-MIN(ABS(in_elas)*W8*R8*(AI8*1/10)/V8,1))) | BO8: =100*(1-(1-X8*(1-EXP(-((AI8*2/10)+(BD8))/Y8)))*(1-MIN(ABS(in_elas)*W8*R8*(AI8*2/10)/V8,1))) | BP8: =100*(1-(1-X8*(1-EXP(-((AI8*3/10)+(BE8))/Y8)))*(1-MIN(ABS(in_elas)*W8*R8*(AI8*3/10)/V8,1))) | BQ8: =100*(1-(1-X8*(1-EXP(-((AI8*4/10)+(BF8))/Y8)))*(1-MIN(ABS(in_elas)*W8*R8*(AI8*4/10)/V8,1))) | BR8: =100*(1-(1-X8*(1-EXP(-((AI8*5/10)+(BG8))/Y8)))*(1-MIN(ABS(in_elas)*W8*R8*(AI8*5/10)/V8,1))) | BS8: =100*(1-(1-X8*(1-EXP(-((AI8*6/10)+(BH8))/Y8)))*(1-MIN(ABS(in_elas)*W8*R8*(AI8*6/10)/V8,1))) | BT8: =100*(1-(1-X8*(1-EXP(-((AI8*7/10)+(BI8))/Y8)))*(1-MIN(ABS(in_elas)*W8*R8*(AI8*7/10)/V8,1))) | BU8: =100*(1-(1-X8*(1-EXP(-((AI8*8/10)+(BJ8))/Y8)))*(1-MIN(ABS(in_elas)*W8*R8*(AI8*8/10)/V8,1))) | BV8: =100*(1-(1-X8*(1-EXP(-((AI8*9/10)+(BK8))/Y8)))*(1-MIN(ABS(in_elas)*W8*R8*(AI8*9/10)/V8,1))) | BW8: =100*(1-(1-X8*(1-EXP(-((AI8*10/10)+(BL8))/Y8)))*(1-MIN(ABS(in_elas)*W8*R8*(AI8*10/10)/V8,1)))
A9: ARG | B9: =INDEX(Data!$B:$B,MATCH($A9,Data!$A:$A,0)) | C9: =INDEX(Data!$D:$D,MATCH($A9,Data!$A:$A,0)) | D9: =SUMIFS(Data!$G:$G,Data!$A:$A,$A9,Data!$F:$F,"gen_coal_twh") | E9: =SUMIFS(Data!$G:$G,Data!$A:$A,$A9,Data!$F:$F,"gen_gas_twh") | F9: =SUMIFS(Data!$G:$G,Data!$A:$A,$A9,Data!$F:$F,"gen_oil_twh") | G9: =SUMIFS(Data!$G:$G,Data!$A:$A,$A9,Data!$F:$F,"gen_total_twh") | H9: =SUMIFS(Data!$G:$G,Data!$A:$A,$A9,Data!$F:$F,"em_coal_mt") | I9: =SUMIFS(Data!$G:$G,Data!$A:$A,$A9,Data!$F:$F,"em_gas_mt") | J9: =SUMIFS(Data!$G:$G,Data!$A:$A,$A9,Data!$F:$F,"em_oil_mt") | K9: =IF(COUNTIFS(Data!$A:$A,$A9,Data!$F:$F,"price_electricity_residential_usd_kwh")=0,"",SUMIFS(Data!$G:$G,Data!$A:$A,$A9,Data!$F:$F,"price_electricity_residential_usd_kwh")) | L9: =IF(COUNTIFS(Data!$A:$A,$A9,Data!$F:$F,"price_coal_power_usd_gj")=0,"",SUMIFS(Data!$G:$G,Data!$A:$A,$A9,Data!$F:$F,"price_coal_power_usd_gj")) | M9: =IF(COUNTIFS(Data!$A:$A,$A9,Data!$F:$F,"price_gas_power_usd_gj")=0,"",SUMIFS(Data!$G:$G,Data!$A:$A,$A9,Data!$F:$F,"price_gas_power_usd_gj")) | N9: =IF(COUNTIFS(Data!$A:$A,$A9,Data!$F:$F,"price_gas_industry_usd_gj")=0,"",SUMIFS(Data!$G:$G,Data!$A:$A,$A9,Data!$F:$F,"price_gas_industry_usd_gj")) | O9: =IF(COUNTIFS(Data!$A:$A,$A9,Data!$F:$F,"power_market_structure")=0,"",SUMIFS(Data!$G:$G,Data!$A:$A,$A9,Data!$F:$F,"power_market_structure")) | P9: =IF(COUNTIFS(Data!$A:$A,$A9,Data!$F:$F,"rise_renewable_energy_score")=0,"",SUMIFS(Data!$G:$G,Data!$A:$A,$A9,Data!$F:$F,"rise_renewable_energy_score")) | Q9: =H9+I9+J9 | R9: =Q9/G9 | S9: =IF(D9>0,H9/D9,0.85) | T9: =IF(E9>0,I9/E9,0.4) | U9: =IF(D9+F9>0,(H9+J9)/(D9+F9),0) | V9: =K9*1000 | W9: =IF(O9=3,in_pt3,IF(O9=2,in_pt2,IF(O9=1,in_pt1,IF(C9="High income",in_pt_hi,in_pt_oth)))) | X9: =IF(Q9>0,in_kappa*(in_rise_lo+(in_rise_hi-in_rise_lo)*IF(P9="",in_rise_miss,P9)/100)*(D9+F9)*MAX(U9-in_gas_rep*T9,0)/Q9,0) | Y9: =IF(IF(M9="",N9,M9)="",MAX(in_sw_floor,in_sw_miss),MAX(in_sw_floor,(IF(M9="",N9,M9)*in_hr_gas-L9*in_hr_coal)/MAX(S9-T9,0.1))) | Z9: =IF(C9="Low income",in_b40_li,IF(C9="Lower middle income",in_b40_lmi,IF(C9="Upper middle income",in_b40_umi,IF(C9="High income",in_b40_hi,0.03)))) | AA9: =(D9+F9)/G9 | AB9: =100*W9*R9/V9/in_phase | AC9: =100*Z9*W9*R9/V9*(1-IF(W9>0,MIN(in_rebate/(W9*in_res_sh*in_q40),1),1)) | AD9: =IF(AA9>0,100*U9*(1-W9)/(in_whole_sh*V9),0) | AE9: =IF(AA9>0,100*MAX(U9-R9,0)/(in_whole_sh*V9),0) | AF9: =IF(AB9>0,in_f1/AB9,in_cap) | AG9: =IF(AC9>0,in_f2/AC9,in_cap) | AH9: =IF(AD9>0,in_f3/AD9,in_cap) | AI9: =MIN(in_cap,AF9,AG9,AH9) | AJ9: =100*(1-(1-X9*(1-EXP(-((AI9)+(0))/Y9)))*(1-MIN(ABS(in_elas)*W9*R9*(AI9)/V9,1))) | AK9: =IF(AI9>=in_cap-1E-9,"rate cap",TRIM(IF(ABS(AI9-AF9)<1E-9,"F1 ","")&IF(ABS(AI9-AG9)<1E-9,"F2 ","")&IF(ABS(AI9-AH9)<1E-9,"F3",""))) | AL9: =100*(1-(1-X9*(1-EXP(-((MIN(in_cap,IF(AB9>0,(in_f1+1)/AB9,in_cap),AG9,AH9))+(0))/Y9)))*(1-MIN(ABS(in_elas)*W9*R9*(MIN(in_cap,IF(AB9>0,(in_f1+1)/AB9,in_cap),AG9,AH9))/V9,1)))-AJ9 | AM9: =MIN(in_cap,IF(AE9>0,in_f3/AE9,in_cap)) | AN9: =100*(1-(1-X9*(1-EXP(-((0)+(AM9))/Y9)))*(1-MIN(ABS(in_elas)*W9*R9*(0)/V9,1))) | AO9: =IF(AM9>=in_cap-1E-9,"rate cap","F3") | AP9: =100*(1-(1-X9*(1-EXP(-((50)+(0))/Y9)))*(1-MIN(ABS(in_elas)*W9*R9*(50)/V9,1))) | AQ9: =100*(1-(1-X9*(1-EXP(-((0)+(50))/Y9)))*(1-MIN(ABS(in_elas)*W9*R9*(0)/V9,1))) | AR9: =IF(AP9>0,AQ9/AP9,"") | AS9: =50*AB9 | AT9: =MAX(BM9:BW9) | AU9: =AI9*(MATCH(AT9,BM9:BW9,0)-1)/10 | AV9: =INDEX(BB9:BL9,1,(MATCH(AT9,BM9:BW9,0)-1)+1) | AW9: =AB9*AU9 | AX9: =AC9*AU9 | AY9: =AD9*AU9+AE9*AV9 | AZ9: =TRIM(IF(AND(AU9>0,ABS(AU9-AF9)<1E-6),"F1 ","")&IF(AND(AU9>0,ABS(AU9-AG9)<1E-6),"F2 ","")&IF(AY9>=in_f3-1E-6,"F3 ","")&IF(AV9>=in_cap-1E-9,"rate cap","")) | BA9: =Q9*AT9/100 | BB9: =MAX(0,MIN(in_cap,IF(AE9>0,(in_f3-AD9*AI9*0/10)/AE9,in_cap))) | BC9: =MAX(0,MIN(in_cap,IF(AE9>0,(in_f3-AD9*AI9*1/10)/AE9,in_cap))) | BD9: =MAX(0,MIN(in_cap,IF(AE9>0,(in_f3-AD9*AI9*2/10)/AE9,in_cap))) | BE9: =MAX(0,MIN(in_cap,IF(AE9>0,(in_f3-AD9*AI9*3/10)/AE9,in_cap))) | BF9: =MAX(0,MIN(in_cap,IF(AE9>0,(in_f3-AD9*AI9*4/10)/AE9,in_cap))) | BG9: =MAX(0,MIN(in_cap,IF(AE9>0,(in_f3-AD9*AI9*5/10)/AE9,in_cap))) | BH9: =MAX(0,MIN(in_cap,IF(AE9>0,(in_f3-AD9*AI9*6/10)/AE9,in_cap))) | BI9: =MAX(0,MIN(in_cap,IF(AE9>0,(in_f3-AD9*AI9*7/10)/AE9,in_cap))) | BJ9: =MAX(0,MIN(in_cap,IF(AE9>0,(in_f3-AD9*AI9*8/10)/AE9,in_cap))) | BK9: =MAX(0,MIN(in_cap,IF(AE9>0,(in_f3-AD9*AI9*9/10)/AE9,in_cap))) | BL9: =MAX(0,MIN(in_cap,IF(AE9>0,(in_f3-AD9*AI9*10/10)/AE9,in_cap))) | BM9: =100*(1-(1-X9*(1-EXP(-((AI9*0/10)+(BB9))/Y9)))*(1-MIN(ABS(in_elas)*W9*R9*(AI9*0/10)/V9,1))) | BN9: =100*(1-(1-X9*(1-EXP(-((AI9*1/10)+(BC9))/Y9)))*(1-MIN(ABS(in_elas)*W9*R9*(AI9*1/10)/V9,1))) | BO9: =100*(1-(1-X9*(1-EXP(-((AI9*2/10)+(BD9))/Y9)))*(1-MIN(ABS(in_elas)*W9*R9*(AI9*2/10)/V9,1))) | BP9: =100*(1-(1-X9*(1-EXP(-((AI9*3/10)+(BE9))/Y9)))*(1-MIN(ABS(in_elas)*W9*R9*(AI9*3/10)/V9,1))) | BQ9: =100*(1-(1-X9*(1-EXP(-((AI9*4/10)+(BF9))/Y9)))*(1-MIN(ABS(in_elas)*W9*R9*(AI9*4/10)/V9,1))) | BR9: =100*(1-(1-X9*(1-EXP(-((AI9*5/10)+(BG9))/Y9)))*(1-MIN(ABS(in_elas)*W9*R9*(AI9*5/10)/V9,1))) | BS9: =100*(1-(1-X9*(1-EXP(-((AI9*6/10)+(BH9))/Y9)))*(1-MIN(ABS(in_elas)*W9*R9*(AI9*6/10)/V9,1))) | BT9: =100*(1-(1-X9*(1-EXP(-((AI9*7/10)+(BI9))/Y9)))*(1-MIN(ABS(in_elas)*W9*R9*(AI9*7/10)/V9,1))) | BU9: =100*(1-(1-X9*(1-EXP(-((AI9*8/10)+(BJ9))/Y9)))*(1-MIN(ABS(in_elas)*W9*R9*(AI9*8/10)/V9,1))) | BV9: =100*(1-(1-X9*(1-EXP(-((AI9*9/10)+(BK9))/Y9)))*(1-MIN(ABS(in_elas)*W9*R9*(AI9*9/10)/V9,1))) | BW9: =100*(1-(1-X9*(1-EXP(-((AI9*10/10)+(BL9))/Y9)))*(1-MIN(ABS(in_elas)*W9*R9*(AI9*10/10)/V9,1)))
A10: ARM | B10: =INDEX(Data!$B:$B,MATCH($A10,Data!$A:$A,0)) | C10: =INDEX(Data!$D:$D,MATCH($A10,Data!$A:$A,0)) | D10: =SUMIFS(Data!$G:$G,Data!$A:$A,$A10,Data!$F:$F,"gen_coal_twh") | E10: =SUMIFS(Data!$G:$G,Data!$A:$A,$A10,Data!$F:$F,"gen_gas_twh") | F10: =SUMIFS(Data!$G:$G,Data!$A:$A,$A10,Data!$F:$F,"gen_oil_twh") | G10: =SUMIFS(Data!$G:$G,Data!$A:$A,$A10,Data!$F:$F,"gen_total_twh") | H10: =SUMIFS(Data!$G:$G,Data!$A:$A,$A10,Data!$F:$F,"em_coal_mt") | I10: =SUMIFS(Data!$G:$G,Data!$A:$A,$A10,Data!$F:$F,"em_gas_mt") | J10: =SUMIFS(Data!$G:$G,Data!$A:$A,$A10,Data!$F:$F,"em_oil_mt") | K10: =IF(COUNTIFS(Data!$A:$A,$A10,Data!$F:$F,"price_electricity_residential_usd_kwh")=0,"",SUMIFS(Data!$G:$G,Data!$A:$A,$A10,Data!$F:$F,"price_electricity_residential_usd_kwh")) | L10: =IF(COUNTIFS(Data!$A:$A,$A10,Data!$F:$F,"price_coal_power_usd_gj")=0,"",SUMIFS(Data!$G:$G,Data!$A:$A,$A10,Data!$F:$F,"price_coal_power_usd_gj")) | M10: =IF(COUNTIFS(Data!$A:$A,$A10,Data!$F:$F,"price_gas_power_usd_gj")=0,"",SUMIFS(Data!$G:$G,Data!$A:$A,$A10,Data!$F:$F,"price_gas_power_usd_gj")) | N10: =IF(COUNTIFS(Data!$A:$A,$A10,Data!$F:$F,"price_gas_industry_usd_gj")=0,"",SUMIFS(Data!$G:$G,Data!$A:$A,$A10,Data!$F:$F,"price_gas_industry_usd_gj")) | O10: =IF(COUNTIFS(Data!$A:$A,$A10,Data!$F:$F,"power_market_structure")=0,"",SUMIFS(Data!$G:$G,Data!$A:$A,$A10,Data!$F:$F,"power_market_structure")) | P10: =IF(COUNTIFS(Data!$A:$A,$A10,Data!$F:$F,"rise_renewable_energy_score")=0,"",SUMIFS(Data!$G:$G,Data!$A:$A,$A10,Data!$F:$F,"rise_renewable_energy_score")) | Q10: =H10+I10+J10 | R10: =Q10/G10 | S10: =IF(D10>0,H10/D10,0.85) | T10: =IF(E10>0,I10/E10,0.4) | U10: =IF(D10+F10>0,(H10+J10)/(D10+F10),0) | V10: =K10*1000 | W10: =IF(O10=3,in_pt3,IF(O10=2,in_pt2,IF(O10=1,in_pt1,IF(C10="High income",in_pt_hi,in_pt_oth)))) | X10: =IF(Q10>0,in_kappa*(in_rise_lo+(in_rise_hi-in_rise_lo)*IF(P10="",in_rise_miss,P10)/100)*(D10+F10)*MAX(U10-in_gas_rep*T10,0)/Q10,0) | Y10: =IF(IF(M10="",N10,M10)="",MAX(in_sw_floor,in_sw_miss),MAX(in_sw_floor,(IF(M10="",N10,M10)*in_hr_gas-L10*in_hr_coal)/MAX(S10-T10,0.1))) | Z10: =IF(C10="Low income",in_b40_li,IF(C10="Lower middle income",in_b40_lmi,IF(C10="Upper middle income",in_b40_umi,IF(C10="High income",in_b40_hi,0.03)))) | AA10: =(D10+F10)/G10 | AB10: =100*W10*R10/V10/in_phase | AC10: =100*Z10*W10*R10/V10*(1-IF(W10>0,MIN(in_rebate/(W10*in_res_sh*in_q40),1),1)) | AD10: =IF(AA10>0,100*U10*(1-W10)/(in_whole_sh*V10),0) | AE10: =IF(AA10>0,100*MAX(U10-R10,0)/(in_whole_sh*V10),0) | AF10: =IF(AB10>0,in_f1/AB10,in_cap) | AG10: =IF(AC10>0,in_f2/AC10,in_cap) | AH10: =IF(AD10>0,in_f3/AD10,in_cap) | AI10: =MIN(in_cap,AF10,AG10,AH10) | AJ10: =100*(1-(1-X10*(1-EXP(-((AI10)+(0))/Y10)))*(1-MIN(ABS(in_elas)*W10*R10*(AI10)/V10,1))) | AK10: =IF(AI10>=in_cap-1E-9,"rate cap",TRIM(IF(ABS(AI10-AF10)<1E-9,"F1 ","")&IF(ABS(AI10-AG10)<1E-9,"F2 ","")&IF(ABS(AI10-AH10)<1E-9,"F3",""))) | AL10: =100*(1-(1-X10*(1-EXP(-((MIN(in_cap,IF(AB10>0,(in_f1+1)/AB10,in_cap),AG10,AH10))+(0))/Y10)))*(1-MIN(ABS(in_elas)*W10*R10*(MIN(in_cap,IF(AB10>0,(in_f1+1)/AB10,in_cap),AG10,AH10))/V10,1)))-AJ10 | AM10: =MIN(in_cap,IF(AE10>0,in_f3/AE10,in_cap)) | AN10: =100*(1-(1-X10*(1-EXP(-((0)+(AM10))/Y10)))*(1-MIN(ABS(in_elas)*W10*R10*(0)/V10,1))) | AO10: =IF(AM10>=in_cap-1E-9,"rate cap","F3") | AP10: =100*(1-(1-X10*(1-EXP(-((50)+(0))/Y10)))*(1-MIN(ABS(in_elas)*W10*R10*(50)/V10,1))) | AQ10: =100*(1-(1-X10*(1-EXP(-((0)+(50))/Y10)))*(1-MIN(ABS(in_elas)*W10*R10*(0)/V10,1))) | AR10: =IF(AP10>0,AQ10/AP10,"") | AS10: =50*AB10 | AT10: =MAX(BM10:BW10) | AU10: =AI10*(MATCH(AT10,BM10:BW10,0)-1)/10 | AV10: =INDEX(BB10:BL10,1,(MATCH(AT10,BM10:BW10,0)-1)+1) | AW10: =AB10*AU10 | AX10: =AC10*AU10 | AY10: =AD10*AU10+AE10*AV10 | AZ10: =TRIM(IF(AND(AU10>0,ABS(AU10-AF10)<1E-6),"F1 ","")&IF(AND(AU10>0,ABS(AU10-AG10)<1E-6),"F2 ","")&IF(AY10>=in_f3-1E-6,"F3 ","")&IF(AV10>=in_cap-1E-9,"rate cap","")) | BA10: =Q10*AT10/100 | BB10: =MAX(0,MIN(in_cap,IF(AE10>0,(in_f3-AD10*AI10*0/10)/AE10,in_cap))) | BC10: =MAX(0,MIN(in_cap,IF(AE10>0,(in_f3-AD10*AI10*1/10)/AE10,in_cap))) | BD10: =MAX(0,MIN(in_cap,IF(AE10>0,(in_f3-AD10*AI10*2/10)/AE10,in_cap))) | BE10: =MAX(0,MIN(in_cap,IF(AE10>0,(in_f3-AD10*AI10*3/10)/AE10,in_cap))) | BF10: =MAX(0,MIN(in_cap,IF(AE10>0,(in_f3-AD10*AI10*4/10)/AE10,in_cap))) | BG10: =MAX(0,MIN(in_cap,IF(AE10>0,(in_f3-AD10*AI10*5/10)/AE10,in_cap))) | BH10: =MAX(0,MIN(in_cap,IF(AE10>0,(in_f3-AD10*AI10*6/10)/AE10,in_cap))) | BI10: =MAX(0,MIN(in_cap,IF(AE10>0,(in_f3-AD10*AI10*7/10)/AE10,in_cap))) | BJ10: =MAX(0,MIN(in_cap,IF(AE10>0,(in_f3-AD10*AI10*8/10)/AE10,in_cap))) | BK10: =MAX(0,MIN(in_cap,IF(AE10>0,(in_f3-AD10*AI10*9/10)/AE10,in_cap))) | BL10: =MAX(0,MIN(in_cap,IF(AE10>0,(in_f3-AD10*AI10*10/10)/AE10,in_cap))) | BM10: =100*(1-(1-X10*(1-EXP(-((AI10*0/10)+(BB10))/Y10)))*(1-MIN(ABS(in_elas)*W10*R10*(AI10*0/10)/V10,1))) | BN10: =100*(1-(1-X10*(1-EXP(-((AI10*1/10)+(BC10))/Y10)))*(1-MIN(ABS(in_elas)*W10*R10*(AI10*1/10)/V10,1))) | BO10: =100*(1-(1-X10*(1-EXP(-((AI10*2/10)+(BD10))/Y10)))*(1-MIN(ABS(in_elas)*W10*R10*(AI10*2/10)/V10,1))) | BP10: =100*(1-(1-X10*(1-EXP(-((AI10*3/10)+(BE10))/Y10)))*(1-MIN(ABS(in_elas)*W10*R10*(AI10*3/10)/V10,1))) | BQ10: =100*(1-(1-X10*(1-EXP(-((AI10*4/10)+(BF10))/Y10)))*(1-MIN(ABS(in_elas)*W10*R10*(AI10*4/10)/V10,1))) | BR10: =100*(1-(1-X10*(1-EXP(-((AI10*5/10)+(BG10))/Y10)))*(1-MIN(ABS(in_elas)*W10*R10*(AI10*5/10)/V10,1))) | BS10: =100*(1-(1-X10*(1-EXP(-((AI10*6/10)+(BH10))/Y10)))*(1-MIN(ABS(in_elas)*W10*R10*(AI10*6/10)/V10,1))) | BT10: =100*(1-(1-X10*(1-EXP(-((AI10*7/10)+(BI10))/Y10)))*(1-MIN(ABS(in_elas)*W10*R10*(AI10*7/10)/V10,1))) | BU10: =100*(1-(1-X10*(1-EXP(-((AI10*8/10)+(BJ10))/Y10)))*(1-MIN(ABS(in_elas)*W10*R10*(AI10*8/10)/V10,1))) | BV10: =100*(1-(1-X10*(1-EXP(-((AI10*9/10)+(BK10))/Y10)))*(1-MIN(ABS(in_elas)*W10*R10*(AI10*9/10)/V10,1))) | BW10: =100*(1-(1-X10*(1-EXP(-((AI10*10/10)+(BL10))/Y10)))*(1-MIN(ABS(in_elas)*W10*R10*(AI10*10/10)/V10,1)))
A11: ATG | B11: =INDEX(Data!$B:$B,MATCH($A11,Data!$A:$A,0)) | C11: =INDEX(Data!$D:$D,MATCH($A11,Data!$A:$A,0)) | D11: =SUMIFS(Data!$G:$G,Data!$A:$A,$A11,Data!$F:$F,"gen_coal_twh") | E11: =SUMIFS(Data!$G:$G,Data!$A:$A,$A11,Data!$F:$F,"gen_gas_twh") | F11: =SUMIFS(Data!$G:$G,Data!$A:$A,$A11,Data!$F:$F,"gen_oil_twh") | G11: =SUMIFS(Data!$G:$G,Data!$A:$A,$A11,Data!$F:$F,"gen_total_twh") | H11: =SUMIFS(Data!$G:$G,Data!$A:$A,$A11,Data!$F:$F,"em_coal_mt") | I11: =SUMIFS(Data!$G:$G,Data!$A:$A,$A11,Data!$F:$F,"em_gas_mt") | J11: =SUMIFS(Data!$G:$G,Data!$A:$A,$A11,Data!$F:$F,"em_oil_mt") | K11: =IF(COUNTIFS(Data!$A:$A,$A11,Data!$F:$F,"price_electricity_residential_usd_kwh")=0,"",SUMIFS(Data!$G:$G,Data!$A:$A,$A11,Data!$F:$F,"price_electricity_residential_usd_kwh")) | L11: =IF(COUNTIFS(Data!$A:$A,$A11,Data!$F:$F,"price_coal_power_usd_gj")=0,"",SUMIFS(Data!$G:$G,Data!$A:$A,$A11,Data!$F:$F,"price_coal_power_usd_gj")) | M11: =IF(COUNTIFS(Data!$A:$A,$A11,Data!$F:$F,"price_gas_power_usd_gj")=0,"",SUMIFS(Data!$G:$G,Data!$A:$A,$A11,Data!$F:$F,"price_gas_power_usd_gj")) | N11: =IF(COUNTIFS(Data!$A:$A,$A11,Data!$F:$F,"price_gas_industry_usd_gj")=0,"",SUMIFS(Data!$G:$G,Data!$A:$A,$A11,Data!$F:$F,"price_gas_industry_usd_gj")) | O11: =IF(COUNTIFS(Data!$A:$A,$A11,Data!$F:$F,"power_market_structure")=0,"",SUMIFS(Data!$G:$G,Data!$A:$A,$A11,Data!$F:$F,"power_market_structure")) | P11: =IF(COUNTIFS(Data!$A:$A,$A11,Data!$F:$F,"rise_renewable_energy_score")=0,"",SUMIFS(Data!$G:$G,Data!$A:$A,$A11,Data!$F:$F,"rise_renewable_energy_score")) | Q11: =H11+I11+J11 | R11: =Q11/G11 | S11: =IF(D11>0,H11/D11,0.85) | T11: =IF(E11>0,I11/E11,0.4) | U11: =IF(D11+F11>0,(H11+J11)/(D11+F11),0) | V11: =K11*1000 | W11: =IF(O11=3,in_pt3,IF(O11=2,in_pt2,IF(O11=1,in_pt1,IF(C11="High income",in_pt_hi,in_pt_oth)))) | X11: =IF(Q11>0,in_kappa*(in_rise_lo+(in_rise_hi-in_rise_lo)*IF(P11="",in_rise_miss,P11)/100)*(D11+F11)*MAX(U11-in_gas_rep*T11,0)/Q11,0) | Y11: =IF(IF(M11="",N11,M11)="",MAX(in_sw_floor,in_sw_miss),MAX(in_sw_floor,(IF(M11="",N11,M11)*in_hr_gas-L11*in_hr_coal)/MAX(S11-T11,0.1))) | Z11: =IF(C11="Low income",in_b40_li,IF(C11="Lower middle income",in_b40_lmi,IF(C11="Upper middle income",in_b40_umi,IF(C11="High income",in_b40_hi,0.03)))) | AA11: =(D11+F11)/G11 | AB11: =100*W11*R11/V11/in_phase | AC11: =100*Z11*W11*R11/V11*(1-IF(W11>0,MIN(in_rebate/(W11*in_res_sh*in_q40),1),1)) | AD11: =IF(AA11>0,100*U11*(1-W11)/(in_whole_sh*V11),0) | AE11: =IF(AA11>0,100*MAX(U11-R11,0)/(in_whole_sh*V11),0) | AF11: =IF(AB11>0,in_f1/AB11,in_cap) | AG11: =IF(AC11>0,in_f2/AC11,in_cap) | AH11: =IF(AD11>0,in_f3/AD11,in_cap) | AI11: =MIN(in_cap,AF11,AG11,AH11) | AJ11: =100*(1-(1-X11*(1-EXP(-((AI11)+(0))/Y11)))*(1-MIN(ABS(in_elas)*W11*R11*(AI11)/V11,1))) | AK11: =IF(AI11>=in_cap-1E-9,"rate cap",TRIM(IF(ABS(AI11-AF11)<1E-9,"F1 ","")&IF(ABS(AI11-AG11)<1E-9,"F2 ","")&IF(ABS(AI11-AH11)<1E-9,"F3",""))) | AL11: =100*(1-(1-X11*(1-EXP(-((MIN(in_cap,IF(AB11>0,(in_f1+1)/AB11,in_cap),AG11,AH11))+(0))/Y11)))*(1-MIN(ABS(in_elas)*W11*R11*(MIN(in_cap,IF(AB11>0,(in_f1+1)/AB11,in_cap),AG11,AH11))/V11,1)))-AJ11 | AM11: =MIN(in_cap,IF(AE11>0,in_f3/AE11,in_cap)) | AN11: =100*(1-(1-X11*(1-EXP(-((0)+(AM11))/Y11)))*(1-MIN(ABS(in_elas)*W11*R11*(0)/V11,1))) | AO11: =IF(AM11>=in_cap-1E-9,"rate cap","F3") | AP11: =100*(1-(1-X11*(1-EXP(-((50)+(0))/Y11)))*(1-MIN(ABS(in_elas)*W11*R11*(50)/V11,1))) | AQ11: =100*(1-(1-X11*(1-EXP(-((0)+(50))/Y11)))*(1-MIN(ABS(in_elas)*W11*R11*(0)/V11,1))) | AR11: =IF(AP11>0,AQ11/AP11,"") | AS11: =50*AB11 | AT11: =MAX(BM11:BW11) | AU11: =AI11*(MATCH(AT11,BM11:BW11,0)-1)/10 | AV11: =INDEX(BB11:BL11,1,(MATCH(AT11,BM11:BW11,0)-1)+1) | AW11: =AB11*AU11 | AX11: =AC11*AU11 | AY11: =AD11*AU11+AE11*AV11 | AZ11: =TRIM(IF(AND(AU11>0,ABS(AU11-AF11)<1E-6),"F1 ","")&IF(AND(AU11>0,ABS(AU11-AG11)<1E-6),"F2 ","")&IF(AY11>=in_f3-1E-6,"F3 ","")&IF(AV11>=in_cap-1E-9,"rate cap","")) | BA11: =Q11*AT11/100 | BB11: =MAX(0,MIN(in_cap,IF(AE11>0,(in_f3-AD11*AI11*0/10)/AE11,in_cap))) | BC11: =MAX(0,MIN(in_cap,IF(AE11>0,(in_f3-AD11*AI11*1/10)/AE11,in_cap))) | BD11: =MAX(0,MIN(in_cap,IF(AE11>0,(in_f3-AD11*AI11*2/10)/AE11,in_cap))) | BE11: =MAX(0,MIN(in_cap,IF(AE11>0,(in_f3-AD11*AI11*3/10)/AE11,in_cap))) | BF11: =MAX(0,MIN(in_cap,IF(AE11>0,(in_f3-AD11*AI11*4/10)/AE11,in_cap))) | BG11: =MAX(0,MIN(in_cap,IF(AE11>0,(in_f3-AD11*AI11*5/10)/AE11,in_cap))) | BH11: =MAX(0,MIN(in_cap,IF(AE11>0,(in_f3-AD11*AI11*6/10)/AE11,in_cap))) | BI11: =MAX(0,MIN(in_cap,IF(AE11>0,(in_f3-AD11*AI11*7/10)/AE11,in_cap))) | BJ11: =MAX(0,MIN(in_cap,IF(AE11>0,(in_f3-AD11*AI11*8/10)/AE11,in_cap))) | BK11: =MAX(0,MIN(in_cap,IF(AE11>0,(in_f3-AD11*AI11*9/10)/AE11,in_cap))) | BL11: =MAX(0,MIN(in_cap,IF(AE11>0,(in_f3-AD11*AI11*10/10)/AE11,in_cap))) | BM11: =100*(1-(1-X11*(1-EXP(-((AI11*0/10)+(BB11))/Y11)))*(1-MIN(ABS(in_elas)*W11*R11*(AI11*0/10)/V11,1))) | BN11: =100*(1-(1-X11*(1-EXP(-((AI11*1/10)+(BC11))/Y11)))*(1-MIN(ABS(in_elas)*W11*R11*(AI11*1/10)/V11,1))) | BO11: =100*(1-(1-X11*(1-EXP(-((AI11*2/10)+(BD11))/Y11)))*(1-MIN(ABS(in_elas)*W11*R11*(AI11*2/10)/V11,1))) | BP11: =100*(1-(1-X11*(1-EXP(-((AI11*3/10)+(BE11))/Y11)))*(1-MIN(ABS(in_elas)*W11*R11*(AI11*3/10)/V11,1))) | BQ11: =100*(1-(1-X11*(1-EXP(-((AI11*4/10)+(BF11))/Y11)))*(1-MIN(ABS(in_elas)*W11*R11*(AI11*4/10)/V11,1))) | BR11: =100*(1-(1-X11*(1-EXP(-((AI11*5/10)+(BG11))/Y11)))*(1-MIN(ABS(in_elas)*W11*R11*(AI11*5/10)/V11,1))) | BS11: =100*(1-(1-X11*(1-EXP(-((AI11*6/10)+(BH11))/Y11)))*(1-MIN(ABS(in_elas)*W11*R11*(AI11*6/10)/V11,1))) | BT11: =100*(1-(1-X11*(1-EXP(-((AI11*7/10)+(BI11))/Y11)))*(1-MIN(ABS(in_elas)*W11*R11*(AI11*7/10)/V11,1))) | BU11: =100*(1-(1-X11*(1-EXP(-((AI11*8/10)+(BJ11))/Y11)))*(1-MIN(ABS(in_elas)*W11*R11*(AI11*8/10)/V11,1))) | BV11: =100*(1-(1-X11*(1-EXP(-((AI11*9/10)+(BK11))/Y11)))*(1-MIN(ABS(in_elas)*W11*R11*(AI11*9/10)/V11,1))) | BW11: =100*(1-(1-X11*(1-EXP(-((AI11*10/10)+(BL11))/Y11)))*(1-MIN(ABS(in_elas)*W11*R11*(AI11*10/10)/V11,1)))
