Workbook
Name p_alpha: Assumptions!$B$2
Name p_delta: Assumptions!$B$3
Name p_delta_g: Assumptions!$B$4
Name p_lambda_k: Assumptions!$B$5
Name p_lambda_f: Assumptions!$B$6
Name p_lambda_f_res: Assumptions!$B$7
Name p_res_threshold: Assumptions!$B$8
Name p_eta: Assumptions!$B$9
Name p_rk: Assumptions!$B$10
Name p_amort: Assumptions!$B$11
Name p_tr_target: Assumptions!$B$12
Name p_gov_take: Assumptions!$B$13
Name p_rent_decline: Assumptions!$B$14
Name p_programme: Assumptions!$B$15
Name p_pricing: Assumptions!$B$16
Name p_sh_grant: Assumptions!$B$17
Name p_sh_conc: Assumptions!$B$18
Name p_dis_year: Assumptions!$B$19
Name p_eps_k: Assumptions!$B$20
Name p_eps_g: Assumptions!$B$21
Name p_eps_a: Assumptions!$B$22
Name p_rho_a: Assumptions!$B$23
Name dl_iso: Data_long!$A$2:$A$937
Name dl_ind: Data_long!$B$2:$B$937
Name dl_year: Data_long!$C$2:$C$937
Name dl_val: Data_long!$D$2:$D$937

Sheet README
B2: DIGNAD-R Excel
B3: Version 0.1. Proof of concept: a recursive, formula-only DIGNAD-lite / DIGNAR-lite for 12 countries, 2024-2050.
B5: What it is | C5: A simplified DIGNAD (Debt-Investment-Growth and Natural Disasters) with the DIGNAR resource block, written entirely in Excel formulas, computed for all countries at once. It answers: what does the NMIM public investment need, financed by grants, concessional and commercial debt and earmarked carbon-pricing revenue, do to GDP, public debt, transfers and the poorest households, with and without a global fall in fossil rents?
B7: How it differs from DIGNAD-lite | C7: DIGNAD-lite (Python) solves the whole path at once with forward-looking savers. Here every year follows from the previous one: private capital closes a share of the gap to its desired level each year (p_lambda_k) instead of a forward-looking investment choice, and savers' consumption is not modelled. The supply side (production with public capital and efficiency), the budget, the three kinds of financing, the debt-elastic commercial rate, the fiscal rule, the resource block and the disaster shock follow DIGNAD-lite. See the Check sheet for how close the two are.
B9: How to use it | C9: Country sheet: pick a country (yellow cell); see the two scenarios and the charts. Assumptions sheet: change any yellow cell (named p_...), e.g. p_dis_year = 2030 for a disaster, p_pricing = 0 to drop the earmarked revenue, p_sh_grant for more grant financing. Everything recalculates (F9 if not automatic).
B11: Scenarios | C11: Baseline (B): no programme; fossil rents still fall (a global transition). Programme (P): the NMIM incremental budget need (capital builds public capital; land-use and non-CO2 spending does not), financed by p_sh_grant grants, p_sh_conc concessional loans and the rest commercial, less earmarked pricing revenue. P versus B isolates the programme; P versus 2024 is the total.
B13: Inputs (dashboard norms) | C13: Data_wide: one row per country, dashboard columns (same codes as the Tax and Macro-Fiscal Dashboard) then the augmented block (shaded; income-group defaults until the data are added to the dashboard), then __year columns. Data_long: annual paths (iso3, indicator, year, value, source). Spec: every input with its block and source.
B15: Outputs (for a master tool) | C15: Outputs sheet: results in the dashboard's long form (iso3, country, indicator, year, value, source), codes dig.*. Interface sheet: the contract - what the module needs and what it passes.
B17: Sheets | C17: Country (view), Assumptions, Data_wide, Data_long, Spec, Calib (per-country calibration, formulas), Model (one row per country-year, both scenarios, formulas), Outputs, Interface, Check.
B19: Read with care | C19: Illustrative calibration; four augmented inputs are income-group defaults. No energy savings, no private investment push, no exchange rate. A proof of concept, not a forecast.

Sheet Country
B2: DIGNAD-R Excel: one country
B3: Version 0.1. Recursive DIGNAD-lite / DIGNAR-lite, all formulas. Illustrative calibration.
B5: Country (pick) | C5: Kenya | E5: =INDEX(Calib!$A$2:$A$13,MATCH(C5,Calib!$B$2:$B$13,0))
B6: First row of the country in Model | C6: =MATCH(E5,Model!$A$2:$A$325,0)+1
B8: Calibration
B9: Public investment efficiency s | C9: =INDEX(Calib!$E$1:$E$13,MATCH($E$5,Calib!$A$2:$A$13,0)+1)
B10: Return on public capital | C10: =INDEX(Calib!$F$1:$F$13,MATCH($E$5,Calib!$A$2:$A$13,0)+1)
B11: Resource block on? (1 = DIGNAR) | C11: =INDEX(Calib!$M$1:$M$13,MATCH($E$5,Calib!$A$2:$A$13,0)+1)
B12: Rents at start, share of non-resource GDP | C12: =INDEX(Calib!$N$1:$N$13,MATCH($E$5,Calib!$A$2:$A$13,0)+1)
B13: Real commercial rate | C13: =INDEX(Calib!$K$1:$K$13,MATCH($E$5,Calib!$A$2:$A$13,0)+1)
B14: Concessional share of debt | C14: =INDEX(Calib!$J$1:$J$13,MATCH($E$5,Calib!$A$2:$A$13,0)+1)
B16: Results | C16: 2030 | D16: 2050
B17: GDP, programme vs baseline (%) | C17: =INDEX(Model!$AQ$1:$AQ$325,$C$6+6)*1 | D17: =INDEX(Model!$AQ$1:$AQ$325,$C$6+26)*1
B18: GDP vs 2024, programme (%) | C18: =INDEX(Model!$AR$1:$AR$325,$C$6+6)*1 | D18: =INDEX(Model!$AR$1:$AR$325,$C$6+26)*1
B19: GDP vs 2024, baseline (%) | C19: =INDEX(Model!$AS$1:$AS$325,$C$6+6)*1 | D19: =INDEX(Model!$AS$1:$AS$325,$C$6+26)*1
B20: Public debt, programme (% GDP) | C20: =INDEX(Model!$AN$1:$AN$325,$C$6+6)*100 | D20: =INDEX(Model!$AN$1:$AN$325,$C$6+26)*100
B21: Public debt, baseline (% GDP) | C21: =INDEX(Model!$X$1:$X$325,$C$6+6)*100 | D21: =INDEX(Model!$X$1:$X$325,$C$6+26)*100
B22: Debt added by the programme (pp) | C22: =INDEX(Model!$AT$1:$AT$325,$C$6+6)*1 | D22: =INDEX(Model!$AT$1:$AT$325,$C$6+26)*1
B23: Hand-to-mouth consumption, programme vs baseline (%) | C23: =INDEX(Model!$AU$1:$AU$325,$C$6+6)*1 | D23: =INDEX(Model!$AU$1:$AU$325,$C$6+26)*1
B24: Transfers, programme vs baseline (pp GDP) | C24: =INDEX(Model!$AV$1:$AV$325,$C$6+6)*1 | D24: =INDEX(Model!$AV$1:$AV$325,$C$6+26)*1
B25: Fossil rents (% GDP) | C25: =INDEX(Model!$G$1:$G$325,$C$6+6)*100 | D25: =INDEX(Model!$G$1:$G$325,$C$6+26)*100

Sheet Data_wide
A1: iso3 | B1: country | C1: region | D1: income | E1: gross_debt_pct_gdp | F1: tax_revenue_pct_gdp | G1: pefa_pi11_pim_score | H1: ids_multilateral_share_pct | I1: ids_private_creditor_rate_pct | J1: fossil_rents_total_pct_gdp | K1: public_investment_pct_gdp | L1: return_public_capital_pct | M1: hand_to_mouth_pct | N1: grants_pct_gdp | O1: fiscal_rule_speed | P1: gross_debt_pct_gdp__year | Q1: tax_revenue_pct_gdp__year | R1: pefa_pi11_pim_score__year | S1: ids_multilateral_share_pct__year | T1: ids_private_creditor_rate_pct__year | U1: fossil_rents_total_pct_gdp__year | V1: public_investment_pct_gdp__year | W1: return_public_capital_pct__year | X1: hand_to_mouth_pct__year | Y1: grants_pct_gdp__year | Z1: fiscal_rule_speed__year
A2: KEN | B2: Kenya | C2: Sub-Saharan Africa | D2: Lower middle income | E2: 67.338 | F2: 12.937 | G2: 2.5 | H2: 56.192 | I2: 9.47 | J2: 0 | K2: 5 | L2: 17 | M2: 50 | N2: 1 | O2: 0.05 | P2: 2024 | Q2: 2024 | R2: 2023 | S2: 2024 | T2: 2024 | U2: 2021 | V2: default | W2: default | X2: default | Y2: default | Z2: 2026 run
A3: SLE | B3: Sierra Leone | C3: Sub-Saharan Africa | D3: Low income | E3: 46.667 | F3: 6.418 | G3: 1.5 | H3: 70.108 | K3: 6 | L3: 20 | M3: 60 | N3: 2 | O3: 0.05 | P3: 2024 | Q3: 2024 | R3: 2022 | S3: 2024 | V3: default | W3: default | X3: default | Y3: default | Z3: 2026 run
A4: UGA | B4: Uganda | C4: Sub-Saharan Africa | D4: Low income | E4: 51.773 | F4: 12.921 | G4: 1.5 | H4: 61.433 | I4: 7.864 | J4: 0 | K4: 6 | L4: 20 | M4: 60 | N4: 2 | O4: 0.05 | P4: 2024 | Q4: 2024 | R4: 2024 | S4: 2024 | T4: 2024 | U4: 2021 | V4: default | W4: default | X4: default | Y4: default | Z4: 2026 run
A5: LBR | B5: Liberia | C5: Sub-Saharan Africa | D5: Low income | E5: 56.368 | F5: 11.618 | G5: 1.5 | H5: 90.077 | I5: 4.02 | J5: 0 | K5: 6 | L5: 20 | M5: 60 | N5: 2 | O5: 0.2 | P5: 2024 | Q5: 2024 | R5: 2021 | S5: 2024 | T5: 2023 | U5: 2021 | V5: default | W5: default | X5: default | Y5: default | Z5: 2026 run
A6: ETH | B6: Ethiopia | C6: Sub-Saharan Africa | D6: Low income | E6: 33.382 | F6: 6.159 | G6: 1.5 | H6: 46.347 | I6: 3.996 | J6: 0 | K6: 6 | L6: 20 | M6: 60 | N6: 2 | O6: 0.05 | P6: 2024 | Q6: 2024 | R6: 2019 | S6: 2024 | T6: 2024 | U6: 2021 | V6: default | W6: default | X6: default | Y6: default | Z6: 2026 run
A7: RWA | B7: Rwanda | C7: Sub-Saharan Africa | D7: Low income | E7: 63.385 | F7: 13.805 | G7: 3.5 | H7: 66.715 | I7: 4.724 | J7: 0.051 | K7: 6 | L7: 20 | M7: 60 | N7: 2 | O7: 0.05 | P7: 2024 | Q7: 2024 | R7: 2022 | S7: 2024 | T7: 2024 | U7: 2021 | V7: default | W7: default | X7: default | Y7: default | Z7: 2026 run
A8: MOZ | B8: Mozambique | C8: Sub-Saharan Africa | D8: Low income | E8: 91.411 | F8: 20.303 | G8: 1 | H8: 48.897 | I8: 0.25 | J8: 7.426 | K8: 6 | L8: 20 | M8: 60 | N8: 2 | O8: 0.2 | P8: 2024 | Q8: 2024 | R8: 2021 | S8: 2024 | T8: 2022 | U8: 2021 | V8: default | W8: default | X8: default | Y8: default | Z8: 2026 run
A9: GHA | B9: Ghana | C9: Sub-Saharan Africa | D9: Lower middle income | E9: 70.342 | F9: 13.27 | G9: 1 | H9: 34.204 | I9: 1.665 | J9: 4.426 | K9: 5 | L9: 17 | M9: 50 | N9: 1 | O9: 0.05 | P9: 2024 | Q9: 2024 | R9: 2018 | S9: 2024 | T9: 2022 | U9: 2021 | V9: default | W9: default | X9: default | Y9: default | Z9: 2026 run
A10: SEN | B10: Senegal | C10: Sub-Saharan Africa | D10: Lower middle income | E10: 132.395 | F10: 18.197 | G10: 1.5 | H10: 37.879 | I10: 6.367 | J10: 0.003 | K10: 5 | L10: 17 | M10: 50 | N10: 1 | O10: 0.05 | P10: 2024 | Q10: 2024 | R10: 2020 | S10: 2024 | T10: 2024 | U10: 2021 | V10: default | W10: default | X10: default | Y10: default | Z10: 2026 run
A11: AGO | B11: Angola | C11: Sub-Saharan Africa | D11: Lower middle income | E11: 57.107 | F11: 5.608 | H11: 13.443 | I11: 4.681 | J11: 29.286 | K11: 5 | L11: 17 | M11: 50 | N11: 1 | O11: 0.4 | P11: 2024 | Q11: 2024 | S11: 2024 | T11: 2024 | U11: 2021 | V11: default | W11: default | X11: default | Y11: default | Z11: 2026 run
A12: COG | B12: Congo, Rep. | C12: Sub-Saharan Africa | D12: Lower middle income | E12: 98.028 | F12: 10.585 | H12: 25.083 | I12: 5.5 | J12: 34.74 | K12: 5 | L12: 17 | M12: 50 | N12: 1 | O12: 0.4 | P12: 2024 | Q12: 2024 | S12: 2024 | T12: 2024 | U12: 2021 | V12: default | W12: default | X12: default | Y12: default | Z12: 2026 run
A13: TCD | B13: Chad | C13: Sub-Saharan Africa | D13: Low income | E13: 31.427 | F13: 7.372 | G13: 1.5 | H13: 31.116 | J13: 16.765 | K13: 6 | L13: 20 | M13: 60 | N13: 2 | O13: 0.2 | P13: 2024 | Q13: 2024 | R13: 2018 | S13: 2024 | U13: 2021 | V13: default | W13: default | X13: default | Y13: default | Z13: 2026 run

Sheet Data_long
A1: iso3 | B1: indicator | C1: year | D1: value | E1: source
A2: AGO | B2: pub_cap | C2: 2025 | D2: 0.2801 | E2: NMIM v0.2 via MacroFiscalModels
A3: AGO | B3: pub_cap | C3: 2026 | D3: 0.2899 | E3: NMIM v0.2 via MacroFiscalModels
A4: AGO | B4: pub_cap | C4: 2027 | D4: 0.2967 | E4: NMIM v0.2 via MacroFiscalModels
A5: AGO | B5: pub_cap | C5: 2028 | D5: 0.3027 | E5: NMIM v0.2 via MacroFiscalModels
A6: AGO | B6: pub_cap | C6: 2029 | D6: 0.3094 | E6: NMIM v0.2 via MacroFiscalModels
A7: AGO | B7: pub_cap | C7: 2030 | D7: 0.3129 | E7: NMIM v0.2 via MacroFiscalModels
A8: AGO | B8: pub_cap | C8: 2031 | D8: 0.3135 | E8: NMIM v0.2 via MacroFiscalModels
A9: AGO | B9: pub_cap | C9: 2032 | D9: 0.311 | E9: NMIM v0.2 via MacroFiscalModels
A10: AGO | B10: pub_cap | C10: 2033 | D10: 0.3176 | E10: NMIM v0.2 via MacroFiscalModels
A11: AGO | B11: pub_cap | C11: 2034 | D11: 0.3236 | E11: NMIM v0.2 via MacroFiscalModels
A12: AGO | B12: pub_cap | C12: 2035 | D12: 0.3332 | E12: NMIM v0.2 via MacroFiscalModels
A13: AGO | B13: pub_cap | C13: 2036 | D13: 0.3443 | E13: NMIM v0.2 via MacroFiscalModels
... A937: UGA | B937: rev | C937: 2050 | D937: 0 | E937: PriceFeasibility v0.1 x NMIM power CO2

Sheet Assumptions
A1: Name | B1: Value | C1: Description | D1: Source
A2: p_alpha | B2: 0.33 | C2: Private capital share | D2: Standard
A3: p_delta | B3: 0.07 | C3: Private depreciation | D3: Standard
A4: p_delta_g | B4: 0.04 | C4: Public depreciation | D4: Standard
A5: p_lambda_k | B5: 0.3 | C5: Private capital: share of the gap to desired capital closed each year | D5: Assumption (stands in for DIGNAD's forward-looking investment)
A6: p_lambda_f | B6: 0.05 | C6: Fiscal rule: primary-balance adjustment per unit of debt ratio above its start, if Data_wide has no fiscal_rule_speed | D6: As DIGNAD-lite
A7: p_lambda_f_res | B7: 0.2 | C7: Same, resource-rich countries (rents >= threshold) | D7: As DIGNAR-lite
A8: p_res_threshold | B8: 0.1 | C8: Rents threshold for the resource block (share of GDP) | D8: As the integrated run
A9: p_eta | B9: 0.05 | C9: Commercial rate premium per unit of debt ratio above its start | D9: As DIGNAD-lite
A10: p_rk | B10: 0.01 | C10: Concessional real rate | D10: As DIGNAD-lite
A11: p_amort | B11: 0.03 | C11: Repayment rate of new concessional loans | D11: As DIGNAD-lite
A12: p_tr_target | B12: 0.02 | C12: Transfers at the start (government consumption is the residual) | D12: As calibration.py
A13: p_gov_take | B13: 0.5 | C13: Government share of resource rents | D13: Assumption
... A23: p_rho_a | B23: 0.6 | C23: Disaster: TFP loss persistence | D23: As DIGNAD-lite

Sheet Spec
A1: block | B1: code | C1: label | D1: where | E1: source
A2: Dashboard | B2: gross_debt_pct_gdp | C2: Gross debt, general govt (% GDP) | D2: Data_wide | E2: IMF WEO (via the Tax and Macro-Fiscal Dashboard panel)
A3: Dashboard | B3: tax_revenue_pct_gdp | C3: Tax revenue (% GDP) | D3: Data_wide | E3: IMF WoRLD (via the Tax and Macro-Fiscal Dashboard panel)
A4: Dashboard | B4: pefa_pi11_pim_score | C4: PEFA PI-11 public investment management (1-4) | D4: Data_wide | E4: PEFA (via the Tax and Macro-Fiscal Dashboard panel)
A5: Dashboard | B5: ids_multilateral_share_pct | C5: Multilateral share of PPG external debt (%) | D5: Data_wide | E5: World Bank IDS (via the Tax and Macro-Fiscal Dashboard panel)
A6: Dashboard | B6: ids_private_creditor_rate_pct | C6: Interest rate, private creditors (%) | D6: Data_wide | E6: World Bank IDS (via the Tax and Macro-Fiscal Dashboard panel)
A7: Dashboard | B7: fossil_rents_total_pct_gdp | C7: Fossil rents, oil + gas + coal (% GDP) | D7: Data_wide | E7: WDI (via the Tax and Macro-Fiscal Dashboard panel)
A8: Augmented | B8: public_investment_pct_gdp | C8: Public investment (% GDP) | D8: Data_wide | E8: Default by income group (IMF ICSD orders of magnitude); candidate for dashboard Appendix C
A9: Augmented | B9: return_public_capital_pct | C9: Return on public capital (%) | D9: Data_wide | E9: Default by income group (IMF literature 10-25%)
A10: Augmented | B10: hand_to_mouth_pct | C10: Hand-to-mouth households (%) | D10: Data_wide | E10: Default by income group (Findex orders of magnitude); candidate: Findex
A11: Augmented | B11: grants_pct_gdp | C11: Grants (% GDP) | D11: Data_wide | E11: Default by income group; candidate: OECD CRS / IMF GFS
A12: Augmented | B12: fiscal_rule_speed | C12: Fiscal rule speed needed to stabilise debt | D12: Data_wide | E12: MacroFiscalModels integrated run: 0.05 default, 0.2 / 0.4 where it had to tighten (DIGNAR-lite starts at 0.2)
... A15: Augmented | B15: rev | C15: Feasible power carbon-pricing revenue (% GDP) | D15: Data_long | E15: PriceFeasibility v0.1 x NMIM power CO2

Sheet Calib
A1: iso3 | B1: country | C1: income | D1: k | E1: s | F1: Rg | G1: ig | H1: tax | I1: grants0 | J1: conc | K1: rstar | L1: rr | M1: res | N1: rents0 | O1: K0 | P1: KG0 | Q1: psi | R1: A | S1: GDP0 | T1: D0 | U1: Dk0 | V1: int0 | W1: rev0 | X1: g | Y1: trbar | Z1: lam_f | AA1: ratio0
A2: =Data_wide!$A$2 | B2: =Data_wide!$B$2 | C2: =Data_wide!$D$2 | D2: =MATCH(C2,{"Low income","Lower middle income","Upper middle income","High income"},0) | E2: =1-IF(ISNUMBER(Data_wide!$G$2),0.4-(Data_wide!$G$2-1)/3*0.27,CHOOSE(D2,0.4,0.27,0.27,0.13)) | F2: =Data_wide!$L$2/100 | G2: =Data_wide!$K$2/100 | H2: =Data_wide!$F$2/100 | I2: =Data_wide!$N$2/100 | J2: =IF(ISNUMBER(Data_wide!$H$2),Data_wide!$H$2/100,CHOOSE(D2,0.7,0.45,0.15,0)) | K2: =IF(ISNUMBER(Data_wide!$I$2),MIN(MAX(Data_wide!$I$2/100-0.03,0.03),0.08),IF(D2<3,0.04,0.03)) | L2: =IF(ISNUMBER(Data_wide!$J$2),Data_wide!$J$2/100,0) | M2: =IF(L2>=p_res_threshold,1,0) | N2: =IF(M2=1,L2/(1-L2),0) | O2: =p_alpha*(1-H2)/(K2+p_delta) | P2: =E2*G2/p_delta_g | Q2: =F2*P2 | R2: =1/(P2^Q2*O2^p_alpha) | S2: =1+N2 | T2: =Data_wide!$E$2/100*S2 | U2: =J2*T2 | V2: =p_rk*U2+K2*(T2-U2) | W2: =H2+p_gov_take*N2+I2 | X2: =MAX(0.05,W2-G2-V2-p_tr_target) | Y2: =W2-X2-G2-V2 | Z2: =IF(ISNUMBER(Data_wide!$O$2),Data_wide!$O$2,IF(M2=1,p_lambda_f_res,p_lambda_f)) | AA2: =T2/S2
A3: =Data_wide!$A$3 | B3: =Data_wide!$B$3 | C3: =Data_wide!$D$3 | D3: =MATCH(C3,{"Low income","Lower middle income","Upper middle income","High income"},0) | E3: =1-IF(ISNUMBER(Data_wide!$G$3),0.4-(Data_wide!$G$3-1)/3*0.27,CHOOSE(D3,0.4,0.27,0.27,0.13)) | F3: =Data_wide!$L$3/100 | G3: =Data_wide!$K$3/100 | H3: =Data_wide!$F$3/100 | I3: =Data_wide!$N$3/100 | J3: =IF(ISNUMBER(Data_wide!$H$3),Data_wide!$H$3/100,CHOOSE(D3,0.7,0.45,0.15,0)) | K3: =IF(ISNUMBER(Data_wide!$I$3),MIN(MAX(Data_wide!$I$3/100-0.03,0.03),0.08),IF(D3<3,0.04,0.03)) | L3: =IF(ISNUMBER(Data_wide!$J$3),Data_wide!$J$3/100,0) | M3: =IF(L3>=p_res_threshold,1,0) | N3: =IF(M3=1,L3/(1-L3),0) | O3: =p_alpha*(1-H3)/(K3+p_delta) | P3: =E3*G3/p_delta_g | Q3: =F3*P3 | R3: =1/(P3^Q3*O3^p_alpha) | S3: =1+N3 | T3: =Data_wide!$E$3/100*S3 | U3: =J3*T3 | V3: =p_rk*U3+K3*(T3-U3) | W3: =H3+p_gov_take*N3+I3 | X3: =MAX(0.05,W3-G3-V3-p_tr_target) | Y3: =W3-X3-G3-V3 | Z3: =IF(ISNUMBER(Data_wide!$O$3),Data_wide!$O$3,IF(M3=1,p_lambda_f_res,p_lambda_f)) | AA3: =T3/S3
A4: =Data_wide!$A$4 | B4: =Data_wide!$B$4 | C4: =Data_wide!$D$4 | D4: =MATCH(C4,{"Low income","Lower middle income","Upper middle income","High income"},0) | E4: =1-IF(ISNUMBER(Data_wide!$G$4),0.4-(Data_wide!$G$4-1)/3*0.27,CHOOSE(D4,0.4,0.27,0.27,0.13)) | F4: =Data_wide!$L$4/100 | G4: =Data_wide!$K$4/100 | H4: =Data_wide!$F$4/100 | I4: =Data_wide!$N$4/100 | J4: =IF(ISNUMBER(Data_wide!$H$4),Data_wide!$H$4/100,CHOOSE(D4,0.7,0.45,0.15,0)) | K4: =IF(ISNUMBER(Data_wide!$I$4),MIN(MAX(Data_wide!$I$4/100-0.03,0.03),0.08),IF(D4<3,0.04,0.03)) | L4: =IF(ISNUMBER(Data_wide!$J$4),Data_wide!$J$4/100,0) | M4: =IF(L4>=p_res_threshold,1,0) | N4: =IF(M4=1,L4/(1-L4),0) | O4: =p_alpha*(1-H4)/(K4+p_delta) | P4: =E4*G4/p_delta_g | Q4: =F4*P4 | R4: =1/(P4^Q4*O4^p_alpha) | S4: =1+N4 | T4: =Data_wide!$E$4/100*S4 | U4: =J4*T4 | V4: =p_rk*U4+K4*(T4-U4) | W4: =H4+p_gov_take*N4+I4 | X4: =MAX(0.05,W4-G4-V4-p_tr_target) | Y4: =W4-X4-G4-V4 | Z4: =IF(ISNUMBER(Data_wide!$O$4),Data_wide!$O$4,IF(M4=1,p_lambda_f_res,p_lambda_f)) | AA4: =T4/S4
A5: =Data_wide!$A$5 | B5: =Data_wide!$B$5 | C5: =Data_wide!$D$5 | D5: =MATCH(C5,{"Low income","Lower middle income","Upper middle income","High income"},0) | E5: =1-IF(ISNUMBER(Data_wide!$G$5),0.4-(Data_wide!$G$5-1)/3*0.27,CHOOSE(D5,0.4,0.27,0.27,0.13)) | F5: =Data_wide!$L$5/100 | G5: =Data_wide!$K$5/100 | H5: =Data_wide!$F$5/100 | I5: =Data_wide!$N$5/100 | J5: =IF(ISNUMBER(Data_wide!$H$5),Data_wide!$H$5/100,CHOOSE(D5,0.7,0.45,0.15,0)) | K5: =IF(ISNUMBER(Data_wide!$I$5),MIN(MAX(Data_wide!$I$5/100-0.03,0.03),0.08),IF(D5<3,0.04,0.03)) | L5: =IF(ISNUMBER(Data_wide!$J$5),Data_wide!$J$5/100,0) | M5: =IF(L5>=p_res_threshold,1,0) | N5: =IF(M5=1,L5/(1-L5),0) | O5: =p_alpha*(1-H5)/(K5+p_delta) | P5: =E5*G5/p_delta_g | Q5: =F5*P5 | R5: =1/(P5^Q5*O5^p_alpha) | S5: =1+N5 | T5: =Data_wide!$E$5/100*S5 | U5: =J5*T5 | V5: =p_rk*U5+K5*(T5-U5) | W5: =H5+p_gov_take*N5+I5 | X5: =MAX(0.05,W5-G5-V5-p_tr_target) | Y5: =W5-X5-G5-V5 | Z5: =IF(ISNUMBER(Data_wide!$O$5),Data_wide!$O$5,IF(M5=1,p_lambda_f_res,p_lambda_f)) | AA5: =T5/S5
A6: =Data_wide!$A$6 | B6: =Data_wide!$B$6 | C6: =Data_wide!$D$6 | D6: =MATCH(C6,{"Low income","Lower middle income","Upper middle income","High income"},0) | E6: =1-IF(ISNUMBER(Data_wide!$G$6),0.4-(Data_wide!$G$6-1)/3*0.27,CHOOSE(D6,0.4,0.27,0.27,0.13)) | F6: =Data_wide!$L$6/100 | G6: =Data_wide!$K$6/100 | H6: =Data_wide!$F$6/100 | I6: =Data_wide!$N$6/100 | J6: =IF(ISNUMBER(Data_wide!$H$6),Data_wide!$H$6/100,CHOOSE(D6,0.7,0.45,0.15,0)) | K6: =IF(ISNUMBER(Data_wide!$I$6),MIN(MAX(Data_wide!$I$6/100-0.03,0.03),0.08),IF(D6<3,0.04,0.03)) | L6: =IF(ISNUMBER(Data_wide!$J$6),Data_wide!$J$6/100,0) | M6: =IF(L6>=p_res_threshold,1,0) | N6: =IF(M6=1,L6/(1-L6),0) | O6: =p_alpha*(1-H6)/(K6+p_delta) | P6: =E6*G6/p_delta_g | Q6: =F6*P6 | R6: =1/(P6^Q6*O6^p_alpha) | S6: =1+N6 | T6: =Data_wide!$E$6/100*S6 | U6: =J6*T6 | V6: =p_rk*U6+K6*(T6-U6) | W6: =H6+p_gov_take*N6+I6 | X6: =MAX(0.05,W6-G6-V6-p_tr_target) | Y6: =W6-X6-G6-V6 | Z6: =IF(ISNUMBER(Data_wide!$O$6),Data_wide!$O$6,IF(M6=1,p_lambda_f_res,p_lambda_f)) | AA6: =T6/S6
A7: =Data_wide!$A$7 | B7: =Data_wide!$B$7 | C7: =Data_wide!$D$7 | D7: =MATCH(C7,{"Low income","Lower middle income","Upper middle income","High income"},0) | E7: =1-IF(ISNUMBER(Data_wide!$G$7),0.4-(Data_wide!$G$7-1)/3*0.27,CHOOSE(D7,0.4,0.27,0.27,0.13)) | F7: =Data_wide!$L$7/100 | G7: =Data_wide!$K$7/100 | H7: =Data_wide!$F$7/100 | I7: =Data_wide!$N$7/100 | J7: =IF(ISNUMBER(Data_wide!$H$7),Data_wide!$H$7/100,CHOOSE(D7,0.7,0.45,0.15,0)) | K7: =IF(ISNUMBER(Data_wide!$I$7),MIN(MAX(Data_wide!$I$7/100-0.03,0.03),0.08),IF(D7<3,0.04,0.03)) | L7: =IF(ISNUMBER(Data_wide!$J$7),Data_wide!$J$7/100,0) | M7: =IF(L7>=p_res_threshold,1,0) | N7: =IF(M7=1,L7/(1-L7),0) | O7: =p_alpha*(1-H7)/(K7+p_delta) | P7: =E7*G7/p_delta_g | Q7: =F7*P7 | R7: =1/(P7^Q7*O7^p_alpha) | S7: =1+N7 | T7: =Data_wide!$E$7/100*S7 | U7: =J7*T7 | V7: =p_rk*U7+K7*(T7-U7) | W7: =H7+p_gov_take*N7+I7 | X7: =MAX(0.05,W7-G7-V7-p_tr_target) | Y7: =W7-X7-G7-V7 | Z7: =IF(ISNUMBER(Data_wide!$O$7),Data_wide!$O$7,IF(M7=1,p_lambda_f_res,p_lambda_f)) | AA7: =T7/S7
A8: =Data_wide!$A$8 | B8: =Data_wide!$B$8 | C8: =Data_wide!$D$8 | D8: =MATCH(C8,{"Low income","Lower middle income","Upper middle income","High income"},0) | E8: =1-IF(ISNUMBER(Data_wide!$G$8),0.4-(Data_wide!$G$8-1)/3*0.27,CHOOSE(D8,0.4,0.27,0.27,0.13)) | F8: =Data_wide!$L$8/100 | G8: =Data_wide!$K$8/100 | H8: =Data_wide!$F$8/100 | I8: =Data_wide!$N$8/100 | J8: =IF(ISNUMBER(Data_wide!$H$8),Data_wide!$H$8/100,CHOOSE(D8,0.7,0.45,0.15,0)) | K8: =IF(ISNUMBER(Data_wide!$I$8),MIN(MAX(Data_wide!$I$8/100-0.03,0.03),0.08),IF(D8<3,0.04,0.03)) | L8: =IF(ISNUMBER(Data_wide!$J$8),Data_wide!$J$8/100,0) | M8: =IF(L8>=p_res_threshold,1,0) | N8: =IF(M8=1,L8/(1-L8),0) | O8: =p_alpha*(1-H8)/(K8+p_delta) | P8: =E8*G8/p_delta_g | Q8: =F8*P8 | R8: =1/(P8^Q8*O8^p_alpha) | S8: =1+N8 | T8: =Data_wide!$E$8/100*S8 | U8: =J8*T8 | V8: =p_rk*U8+K8*(T8-U8) | W8: =H8+p_gov_take*N8+I8 | X8: =MAX(0.05,W8-G8-V8-p_tr_target) | Y8: =W8-X8-G8-V8 | Z8: =IF(ISNUMBER(Data_wide!$O$8),Data_wide!$O$8,IF(M8=1,p_lambda_f_res,p_lambda_f)) | AA8: =T8/S8
A9: =Data_wide!$A$9 | B9: =Data_wide!$B$9 | C9: =Data_wide!$D$9 | D9: =MATCH(C9,{"Low income","Lower middle income","Upper middle income","High income"},0) | E9: =1-IF(ISNUMBER(Data_wide!$G$9),0.4-(Data_wide!$G$9-1)/3*0.27,CHOOSE(D9,0.4,0.27,0.27,0.13)) | F9: =Data_wide!$L$9/100 | G9: =Data_wide!$K$9/100 | H9: =Data_wide!$F$9/100 | I9: =Data_wide!$N$9/100 | J9: =IF(ISNUMBER(Data_wide!$H$9),Data_wide!$H$9/100,CHOOSE(D9,0.7,0.45,0.15,0)) | K9: =IF(ISNUMBER(Data_wide!$I$9),MIN(MAX(Data_wide!$I$9/100-0.03,0.03),0.08),IF(D9<3,0.04,0.03)) | L9: =IF(ISNUMBER(Data_wide!$J$9),Data_wide!$J$9/100,0) | M9: =IF(L9>=p_res_threshold,1,0) | N9: =IF(M9=1,L9/(1-L9),0) | O9: =p_alpha*(1-H9)/(K9+p_delta) | P9: =E9*G9/p_delta_g | Q9: =F9*P9 | R9: =1/(P9^Q9*O9^p_alpha) | S9: =1+N9 | T9: =Data_wide!$E$9/100*S9 | U9: =J9*T9 | V9: =p_rk*U9+K9*(T9-U9) | W9: =H9+p_gov_take*N9+I9 | X9: =MAX(0.05,W9-G9-V9-p_tr_target) | Y9: =W9-X9-G9-V9 | Z9: =IF(ISNUMBER(Data_wide!$O$9),Data_wide!$O$9,IF(M9=1,p_lambda_f_res,p_lambda_f)) | AA9: =T9/S9
A10: =Data_wide!$A$10 | B10: =Data_wide!$B$10 | C10: =Data_wide!$D$10 | D10: =MATCH(C10,{"Low income","Lower middle income","Upper middle income","High income"},0) | E10: =1-IF(ISNUMBER(Data_wide!$G$10),0.4-(Data_wide!$G$10-1)/3*0.27,CHOOSE(D10,0.4,0.27,0.27,0.13)) | F10: =Data_wide!$L$10/100 | G10: =Data_wide!$K$10/100 | H10: =Data_wide!$F$10/100 | I10: =Data_wide!$N$10/100 | J10: =IF(ISNUMBER(Data_wide!$H$10),Data_wide!$H$10/100,CHOOSE(D10,0.7,0.45,0.15,0)) | K10: =IF(ISNUMBER(Data_wide!$I$10),MIN(MAX(Data_wide!$I$10/100-0.03,0.03),0.08),IF(D10<3,0.04,0.03)) | L10: =IF(ISNUMBER(Data_wide!$J$10),Data_wide!$J$10/100,0) | M10: =IF(L10>=p_res_threshold,1,0) | N10: =IF(M10=1,L10/(1-L10),0) | O10: =p_alpha*(1-H10)/(K10+p_delta) | P10: =E10*G10/p_delta_g | Q10: =F10*P10 | R10: =1/(P10^Q10*O10^p_alpha) | S10: =1+N10 | T10: =Data_wide!$E$10/100*S10 | U10: =J10*T10 | V10: =p_rk*U10+K10*(T10-U10) | W10: =H10+p_gov_take*N10+I10 | X10: =MAX(0.05,W10-G10-V10-p_tr_target) | Y10: =W10-X10-G10-V10 | Z10: =IF(ISNUMBER(Data_wide!$O$10),Data_wide!$O$10,IF(M10=1,p_lambda_f_res,p_lambda_f)) | AA10: =T10/S10
A11: =Data_wide!$A$11 | B11: =Data_wide!$B$11 | C11: =Data_wide!$D$11 | D11: =MATCH(C11,{"Low income","Lower middle income","Upper middle income","High income"},0) | E11: =1-IF(ISNUMBER(Data_wide!$G$11),0.4-(Data_wide!$G$11-1)/3*0.27,CHOOSE(D11,0.4,0.27,0.27,0.13)) | F11: =Data_wide!$L$11/100 | G11: =Data_wide!$K$11/100 | H11: =Data_wide!$F$11/100 | I11: =Data_wide!$N$11/100 | J11: =IF(ISNUMBER(Data_wide!$H$11),Data_wide!$H$11/100,CHOOSE(D11,0.7,0.45,0.15,0)) | K11: =IF(ISNUMBER(Data_wide!$I$11),MIN(MAX(Data_wide!$I$11/100-0.03,0.03),0.08),IF(D11<3,0.04,0.03)) | L11: =IF(ISNUMBER(Data_wide!$J$11),Data_wide!$J$11/100,0) | M11: =IF(L11>=p_res_threshold,1,0) | N11: =IF(M11=1,L11/(1-L11),0) | O11: =p_alpha*(1-H11)/(K11+p_delta) | P11: =E11*G11/p_delta_g | Q11: =F11*P11 | R11: =1/(P11^Q11*O11^p_alpha) | S11: =1+N11 | T11: =Data_wide!$E$11/100*S11 | U11: =J11*T11 | V11: =p_rk*U11+K11*(T11-U11) | W11: =H11+p_gov_take*N11+I11 | X11: =MAX(0.05,W11-G11-V11-p_tr_target) | Y11: =W11-X11-G11-V11 | Z11: =IF(ISNUMBER(Data_wide!$O$11),Data_wide!$O$11,IF(M11=1,p_lambda_f_res,p_lambda_f)) | AA11: =T11/S11
A12: =Data_wide!$A$12 | B12: =Data_wide!$B$12 | C12: =Data_wide!$D$12 | D12: =MATCH(C12,{"Low income","Lower middle income","Upper middle income","High income"},0) | E12: =1-IF(ISNUMBER(Data_wide!$G$12),0.4-(Data_wide!$G$12-1)/3*0.27,CHOOSE(D12,0.4,0.27,0.27,0.13)) | F12: =Data_wide!$L$12/100 | G12: =Data_wide!$K$12/100 | H12: =Data_wide!$F$12/100 | I12: =Data_wide!$N$12/100 | J12: =IF(ISNUMBER(Data_wide!$H$12),Data_wide!$H$12/100,CHOOSE(D12,0.7,0.45,0.15,0)) | K12: =IF(ISNUMBER(Data_wide!$I$12),MIN(MAX(Data_wide!$I$12/100-0.03,0.03),0.08),IF(D12<3,0.04,0.03)) | L12: =IF(ISNUMBER(Data_wide!$J$12),Data_wide!$J$12/100,0) | M12: =IF(L12>=p_res_threshold,1,0) | N12: =IF(M12=1,L12/(1-L12),0) | O12: =p_alpha*(1-H12)/(K12+p_delta) | P12: =E12*G12/p_delta_g | Q12: =F12*P12 | R12: =1/(P12^Q12*O12^p_alpha) | S12: =1+N12 | T12: =Data_wide!$E$12/100*S12 | U12: =J12*T12 | V12: =p_rk*U12+K12*(T12-U12) | W12: =H12+p_gov_take*N12+I12 | X12: =MAX(0.05,W12-G12-V12-p_tr_target) | Y12: =W12-X12-G12-V12 | Z12: =IF(ISNUMBER(Data_wide!$O$12),Data_wide!$O$12,IF(M12=1,p_lambda_f_res,p_lambda_f)) | AA12: =T12/S12
A13: =Data_wide!$A$13 | B13: =Data_wide!$B$13 | C13: =Data_wide!$D$13 | D13: =MATCH(C13,{"Low income","Lower middle income","Upper middle income","High income"},0) | E13: =1-IF(ISNUMBER(Data_wide!$G$13),0.4-(Data_wide!$G$13-1)/3*0.27,CHOOSE(D13,0.4,0.27,0.27,0.13)) | F13: =Data_wide!$L$13/100 | G13: =Data_wide!$K$13/100 | H13: =Data_wide!$F$13/100 | I13: =Data_wide!$N$13/100 | J13: =IF(ISNUMBER(Data_wide!$H$13),Data_wide!$H$13/100,CHOOSE(D13,0.7,0.45,0.15,0)) | K13: =IF(ISNUMBER(Data_wide!$I$13),MIN(MAX(Data_wide!$I$13/100-0.03,0.03),0.08),IF(D13<3,0.04,0.03)) | L13: =IF(ISNUMBER(Data_wide!$J$13),Data_wide!$J$13/100,0) | M13: =IF(L13>=p_res_threshold,1,0) | N13: =IF(M13=1,L13/(1-L13),0) | O13: =p_alpha*(1-H13)/(K13+p_delta) | P13: =E13*G13/p_delta_g | Q13: =F13*P13 | R13: =1/(P13^Q13*O13^p_alpha) | S13: =1+N13 | T13: =Data_wide!$E$13/100*S13 | U13: =J13*T13 | V13: =p_rk*U13+K13*(T13-U13) | W13: =H13+p_gov_take*N13+I13 | X13: =MAX(0.05,W13-G13-V13-p_tr_target) | Y13: =W13-X13-G13-V13 | Z13: =IF(ISNUMBER(Data_wide!$O$13),Data_wide!$O$13,IF(M13=1,p_lambda_f_res,p_lambda_f)) | AA13: =T13/S13

Sheet Model
A1: iso3 | B1: year | C1: t | D1: crow | E1: dis | F1: tfp | G1: rents | H1: cap | I1: spend | J1: rev | K1: B_KG | L1: B_K | M1: B_Y | N1: B_Kstar | O1: B_GDP | P1: B_P | Q1: B_grants | R1: B_revenue | S1: B_tr | T1: B_prim | U1: B_interest | V1: B_D | W1: B_Dk | X1: B_ratio | Y1: B_rc | Z1: B_chtm | AA1: P_KG | AB1: P_K | AC1: P_Y | AD1: P_Kstar | AE1: P_GDP | AF1: P_P | AG1: P_grants | AH1: P_revenue | AI1: P_tr | AJ1: P_prim | AK1: P_interest | AL1: P_D | AM1: P_Dk | AN1: P_ratio | AO1: P_rc | AP1: P_chtm | AQ1: gdp_dev_prog | AR1: gdp_vs_2024_P | AS1: gdp_vs_2024_B | AT1: debt_diff_pp | AU1: chtm_dev_prog | AV1: tr_diff
A2: KEN | B2: 2024 | C2: 0 | D2: 2 | E2: =IF(AND(p_dis_year>0,B2=p_dis_year),1,0) | F2: =IF(AND(p_dis_year>0,B2>=p_dis_year),1-p_eps_a*p_rho_a^(B2-p_dis_year),1) | G2: =INDEX(Calib!$N$1:$N$13,$D2)*(1-p_rent_decline*MIN(1,C2/26)) | H2: =IF(C2=0,0,SUMIFS(dl_val,dl_iso,$A2,dl_ind,"pub_cap",dl_year,$B2)/100) | I2: =IF(C2=0,0,SUMIFS(dl_val,dl_iso,$A2,dl_ind,"pub_spend",dl_year,$B2)/100) | J2: =IF(C2=0,0,SUMIFS(dl_val,dl_iso,$A2,dl_ind,"rev",dl_year,$B2)/100) | K2: =INDEX(Calib!$P$1:$P$13,$D2) | L2: =INDEX(Calib!$O$1:$O$13,$D2) | M2: =1 | N2: =INDEX(Calib!$O$1:$O$13,$D2) | O2: =INDEX(Calib!$S$1:$S$13,$D2) | P2: =0 | Q2: =INDEX(Calib!$I$1:$I$13,$D2) | R2: =INDEX(Calib!$W$1:$W$13,$D2) | S2: =INDEX(Calib!$Y$1:$Y$13,$D2) | T2: =-INDEX(Calib!$V$1:$V$13,$D2) | U2: =INDEX(Calib!$V$1:$V$13,$D2) | V2: =INDEX(Calib!$T$1:$T$13,$D2) | W2: =INDEX(Calib!$U$1:$U$13,$D2) | X2: =V2/O2 | Y2: =INDEX(Calib!$K$1:$K$13,$D2) | Z2: =(1-INDEX(Calib!$H$1:$H$13,$D2))*(1-p_alpha)*M2+S2 | AA2: =INDEX(Calib!$P$1:$P$13,$D2) | AB2: =INDEX(Calib!$O$1:$O$13,$D2) | AC2: =1 | AD2: =INDEX(Calib!$O$1:$O$13,$D2) | AE2: =INDEX(Calib!$S$1:$S$13,$D2) | AF2: =0 | AG2: =INDEX(Calib!$I$1:$I$13,$D2) | AH2: =INDEX(Calib!$W$1:$W$13,$D2) | AI2: =INDEX(Calib!$Y$1:$Y$13,$D2) | AJ2: =-INDEX(Calib!$V$1:$V$13,$D2) | AK2: =INDEX(Calib!$V$1:$V$13,$D2) | AL2: =INDEX(Calib!$T$1:$T$13,$D2) | AM2: =INDEX(Calib!$U$1:$U$13,$D2) | AN2: =AL2/AE2 | AO2: =INDEX(Calib!$K$1:$K$13,$D2) | AP2: =(1-INDEX(Calib!$H$1:$H$13,$D2))*(1-p_alpha)*AC2+AI2 | AQ2: =(AE2/O2-1)*100 | AR2: =(AE2/AE2-1)*100 | AS2: =(O2/O2-1)*100 | AT2: =(AN2-X2)*100 | AU2: =(AP2/Z2-1)*100 | AV2: =(AI2-S2)*100
A3: KEN | B3: 2025 | C3: 1 | D3: 2 | E3: =IF(AND(p_dis_year>0,B3=p_dis_year),1,0) | F3: =IF(AND(p_dis_year>0,B3>=p_dis_year),1-p_eps_a*p_rho_a^(B3-p_dis_year),1) | G3: =INDEX(Calib!$N$1:$N$13,$D3)*(1-p_rent_decline*MIN(1,C3/26)) | H3: =IF(C3=0,0,SUMIFS(dl_val,dl_iso,$A3,dl_ind,"pub_cap",dl_year,$B3)/100) | I3: =IF(C3=0,0,SUMIFS(dl_val,dl_iso,$A3,dl_ind,"pub_spend",dl_year,$B3)/100) | J3: =IF(C3=0,0,SUMIFS(dl_val,dl_iso,$A3,dl_ind,"rev",dl_year,$B3)/100) | K3: =(1-p_delta_g)*K2*(1-p_eps_g*$E3)+INDEX(Calib!$E$1:$E$13,$D3)*(INDEX(Calib!$G$1:$G$13,$D3)+0*$H3) | L3: =L2*(1-p_eps_k*$E3)+p_lambda_k*(N3-L2*(1-p_eps_k*$E3)) | M3: =INDEX(Calib!$R$1:$R$13,$D3)*$F3*(K2*(1-p_eps_g*$E3))^INDEX(Calib!$Q$1:$Q$13,$D3)*(L2*(1-p_eps_k*$E3))^p_alpha | N3: =p_alpha*(1-INDEX(Calib!$H$1:$H$13,$D3))*M3/(INDEX(Calib!$K$1:$K$13,$D3)+p_delta) | O3: =M3+$G3 | P3: =0*($H3+$I3) | Q3: =INDEX(Calib!$I$1:$I$13,$D3)+p_sh_grant*P3 | R3: =INDEX(Calib!$H$1:$H$13,$D3)*M3+p_gov_take*$G3+Q3+0*p_pricing*$J3 | S3: =INDEX(Calib!$Y$1:$Y$13,$D3)-INDEX(Calib!$Z$1:$Z$13,$D3)*(V2/O2-INDEX(Calib!$AA$1:$AA$13,$D3)) | T3: =INDEX(Calib!$X$1:$X$13,$D3)+INDEX(Calib!$G$1:$G$13,$D3)+P3+S3-R3 | U3: =p_rk*W2+Y2*(V2-W2) | V3: =V2+U3+T3 | W3: =INDEX(Calib!$U$1:$U$13,$D3)+(W2-INDEX(Calib!$U$1:$U$13,$D3))*(1-p_amort)+p_sh_conc*P3 | X3: =V3/O3 | Y3: =INDEX(Calib!$K$1:$K$13,$D3)+p_eta*MAX(0,X3-INDEX(Calib!$AA$1:$AA$13,$D3)) | Z3: =(1-INDEX(Calib!$H$1:$H$13,$D3))*(1-p_alpha)*M3+S3 | AA3: =(1-p_delta_g)*AA2*(1-p_eps_g*$E3)+INDEX(Calib!$E$1:$E$13,$D3)*(INDEX(Calib!$G$1:$G$13,$D3)+p_programme*$H3) | AB3: =AB2*(1-p_eps_k*$E3)+p_lambda_k*(AD3-AB2*(1-p_eps_k*$E3)) | AC3: =INDEX(Calib!$R$1:$R$13,$D3)*$F3*(AA2*(1-p_eps_g*$E3))^INDEX(Calib!$Q$1:$Q$13,$D3)*(AB2*(1-p_eps_k*$E3))^p_alpha | AD3: =p_alpha*(1-INDEX(Calib!$H$1:$H$13,$D3))*AC3/(INDEX(Calib!$K$1:$K$13,$D3)+p_delta) | AE3: =AC3+$G3 | AF3: =p_programme*($H3+$I3) | AG3: =INDEX(Calib!$I$1:$I$13,$D3)+p_sh_grant*AF3 | AH3: =INDEX(Calib!$H$1:$H$13,$D3)*AC3+p_gov_take*$G3+AG3+p_programme*p_pricing*$J3 | AI3: =INDEX(Calib!$Y$1:$Y$13,$D3)-INDEX(Calib!$Z$1:$Z$13,$D3)*(AL2/AE2-INDEX(Calib!$AA$1:$AA$13,$D3)) | AJ3: =INDEX(Calib!$X$1:$X$13,$D3)+INDEX(Calib!$G$1:$G$13,$D3)+AF3+AI3-AH3 | AK3: =p_rk*AM2+AO2*(AL2-AM2) | AL3: =AL2+AK3+AJ3 | AM3: =INDEX(Calib!$U$1:$U$13,$D3)+(AM2-INDEX(Calib!$U$1:$U$13,$D3))*(1-p_amort)+p_sh_conc*AF3 | AN3: =AL3/AE3 | AO3: =INDEX(Calib!$K$1:$K$13,$D3)+p_eta*MAX(0,AN3-INDEX(Calib!$AA$1:$AA$13,$D3)) | AP3: =(1-INDEX(Calib!$H$1:$H$13,$D3))*(1-p_alpha)*AC3+AI3 | AQ3: =(AE3/O3-1)*100 | AR3: =(AE3/AE2-1)*100 | AS3: =(O3/O2-1)*100 | AT3: =(AN3-X3)*100 | AU3: =(AP3/Z3-1)*100 | AV3: =(AI3-S3)*100
A4: KEN | B4: 2026 | C4: 2 | D4: 2 | E4: =IF(AND(p_dis_year>0,B4=p_dis_year),1,0) | F4: =IF(AND(p_dis_year>0,B4>=p_dis_year),1-p_eps_a*p_rho_a^(B4-p_dis_year),1) | G4: =INDEX(Calib!$N$1:$N$13,$D4)*(1-p_rent_decline*MIN(1,C4/26)) | H4: =IF(C4=0,0,SUMIFS(dl_val,dl_iso,$A4,dl_ind,"pub_cap",dl_year,$B4)/100) | I4: =IF(C4=0,0,SUMIFS(dl_val,dl_iso,$A4,dl_ind,"pub_spend",dl_year,$B4)/100) | J4: =IF(C4=0,0,SUMIFS(dl_val,dl_iso,$A4,dl_ind,"rev",dl_year,$B4)/100) | K4: =(1-p_delta_g)*K3*(1-p_eps_g*$E4)+INDEX(Calib!$E$1:$E$13,$D4)*(INDEX(Calib!$G$1:$G$13,$D4)+0*$H4) | L4: =L3*(1-p_eps_k*$E4)+p_lambda_k*(N4-L3*(1-p_eps_k*$E4)) | M4: =INDEX(Calib!$R$1:$R$13,$D4)*$F4*(K3*(1-p_eps_g*$E4))^INDEX(Calib!$Q$1:$Q$13,$D4)*(L3*(1-p_eps_k*$E4))^p_alpha | N4: =p_alpha*(1-INDEX(Calib!$H$1:$H$13,$D4))*M4/(INDEX(Calib!$K$1:$K$13,$D4)+p_delta) | O4: =M4+$G4 | P4: =0*($H4+$I4) | Q4: =INDEX(Calib!$I$1:$I$13,$D4)+p_sh_grant*P4 | R4: =INDEX(Calib!$H$1:$H$13,$D4)*M4+p_gov_take*$G4+Q4+0*p_pricing*$J4 | S4: =INDEX(Calib!$Y$1:$Y$13,$D4)-INDEX(Calib!$Z$1:$Z$13,$D4)*(V3/O3-INDEX(Calib!$AA$1:$AA$13,$D4)) | T4: =INDEX(Calib!$X$1:$X$13,$D4)+INDEX(Calib!$G$1:$G$13,$D4)+P4+S4-R4 | U4: =p_rk*W3+Y3*(V3-W3) | V4: =V3+U4+T4 | W4: =INDEX(Calib!$U$1:$U$13,$D4)+(W3-INDEX(Calib!$U$1:$U$13,$D4))*(1-p_amort)+p_sh_conc*P4 | X4: =V4/O4 | Y4: =INDEX(Calib!$K$1:$K$13,$D4)+p_eta*MAX(0,X4-INDEX(Calib!$AA$1:$AA$13,$D4)) | Z4: =(1-INDEX(Calib!$H$1:$H$13,$D4))*(1-p_alpha)*M4+S4 | AA4: =(1-p_delta_g)*AA3*(1-p_eps_g*$E4)+INDEX(Calib!$E$1:$E$13,$D4)*(INDEX(Calib!$G$1:$G$13,$D4)+p_programme*$H4) | AB4: =AB3*(1-p_eps_k*$E4)+p_lambda_k*(AD4-AB3*(1-p_eps_k*$E4)) | AC4: =INDEX(Calib!$R$1:$R$13,$D4)*$F4*(AA3*(1-p_eps_g*$E4))^INDEX(Calib!$Q$1:$Q$13,$D4)*(AB3*(1-p_eps_k*$E4))^p_alpha | AD4: =p_alpha*(1-INDEX(Calib!$H$1:$H$13,$D4))*AC4/(INDEX(Calib!$K$1:$K$13,$D4)+p_delta) | AE4: =AC4+$G4 | AF4: =p_programme*($H4+$I4) | AG4: =INDEX(Calib!$I$1:$I$13,$D4)+p_sh_grant*AF4 | AH4: =INDEX(Calib!$H$1:$H$13,$D4)*AC4+p_gov_take*$G4+AG4+p_programme*p_pricing*$J4 | AI4: =INDEX(Calib!$Y$1:$Y$13,$D4)-INDEX(Calib!$Z$1:$Z$13,$D4)*(AL3/AE3-INDEX(Calib!$AA$1:$AA$13,$D4)) | AJ4: =INDEX(Calib!$X$1:$X$13,$D4)+INDEX(Calib!$G$1:$G$13,$D4)+AF4+AI4-AH4 | AK4: =p_rk*AM3+AO3*(AL3-AM3) | AL4: =AL3+AK4+AJ4 | AM4: =INDEX(Calib!$U$1:$U$13,$D4)+(AM3-INDEX(Calib!$U$1:$U$13,$D4))*(1-p_amort)+p_sh_conc*AF4 | AN4: =AL4/AE4 | AO4: =INDEX(Calib!$K$1:$K$13,$D4)+p_eta*MAX(0,AN4-INDEX(Calib!$AA$1:$AA$13,$D4)) | AP4: =(1-INDEX(Calib!$H$1:$H$13,$D4))*(1-p_alpha)*AC4+AI4 | AQ4: =(AE4/O4-1)*100 | AR4: =(AE4/AE2-1)*100 | AS4: =(O4/O2-1)*100 | AT4: =(AN4-X4)*100 | AU4: =(AP4/Z4-1)*100 | AV4: =(AI4-S4)*100
A5: KEN | B5: 2027 | C5: 3 | D5: 2 | E5: =IF(AND(p_dis_year>0,B5=p_dis_year),1,0) | F5: =IF(AND(p_dis_year>0,B5>=p_dis_year),1-p_eps_a*p_rho_a^(B5-p_dis_year),1) | G5: =INDEX(Calib!$N$1:$N$13,$D5)*(1-p_rent_decline*MIN(1,C5/26)) | H5: =IF(C5=0,0,SUMIFS(dl_val,dl_iso,$A5,dl_ind,"pub_cap",dl_year,$B5)/100) | I5: =IF(C5=0,0,SUMIFS(dl_val,dl_iso,$A5,dl_ind,"pub_spend",dl_year,$B5)/100) | J5: =IF(C5=0,0,SUMIFS(dl_val,dl_iso,$A5,dl_ind,"rev",dl_year,$B5)/100) | K5: =(1-p_delta_g)*K4*(1-p_eps_g*$E5)+INDEX(Calib!$E$1:$E$13,$D5)*(INDEX(Calib!$G$1:$G$13,$D5)+0*$H5) | L5: =L4*(1-p_eps_k*$E5)+p_lambda_k*(N5-L4*(1-p_eps_k*$E5)) | M5: =INDEX(Calib!$R$1:$R$13,$D5)*$F5*(K4*(1-p_eps_g*$E5))^INDEX(Calib!$Q$1:$Q$13,$D5)*(L4*(1-p_eps_k*$E5))^p_alpha | N5: =p_alpha*(1-INDEX(Calib!$H$1:$H$13,$D5))*M5/(INDEX(Calib!$K$1:$K$13,$D5)+p_delta) | O5: =M5+$G5 | P5: =0*($H5+$I5) | Q5: =INDEX(Calib!$I$1:$I$13,$D5)+p_sh_grant*P5 | R5: =INDEX(Calib!$H$1:$H$13,$D5)*M5+p_gov_take*$G5+Q5+0*p_pricing*$J5 | S5: =INDEX(Calib!$Y$1:$Y$13,$D5)-INDEX(Calib!$Z$1:$Z$13,$D5)*(V4/O4-INDEX(Calib!$AA$1:$AA$13,$D5)) | T5: =INDEX(Calib!$X$1:$X$13,$D5)+INDEX(Calib!$G$1:$G$13,$D5)+P5+S5-R5 | U5: =p_rk*W4+Y4*(V4-W4) | V5: =V4+U5+T5 | W5: =INDEX(Calib!$U$1:$U$13,$D5)+(W4-INDEX(Calib!$U$1:$U$13,$D5))*(1-p_amort)+p_sh_conc*P5 | X5: =V5/O5 | Y5: =INDEX(Calib!$K$1:$K$13,$D5)+p_eta*MAX(0,X5-INDEX(Calib!$AA$1:$AA$13,$D5)) | Z5: =(1-INDEX(Calib!$H$1:$H$13,$D5))*(1-p_alpha)*M5+S5 | AA5: =(1-p_delta_g)*AA4*(1-p_eps_g*$E5)+INDEX(Calib!$E$1:$E$13,$D5)*(INDEX(Calib!$G$1:$G$13,$D5)+p_programme*$H5) | AB5: =AB4*(1-p_eps_k*$E5)+p_lambda_k*(AD5-AB4*(1-p_eps_k*$E5)) | AC5: =INDEX(Calib!$R$1:$R$13,$D5)*$F5*(AA4*(1-p_eps_g*$E5))^INDEX(Calib!$Q$1:$Q$13,$D5)*(AB4*(1-p_eps_k*$E5))^p_alpha | AD5: =p_alpha*(1-INDEX(Calib!$H$1:$H$13,$D5))*AC5/(INDEX(Calib!$K$1:$K$13,$D5)+p_delta) | AE5: =AC5+$G5 | AF5: =p_programme*($H5+$I5) | AG5: =INDEX(Calib!$I$1:$I$13,$D5)+p_sh_grant*AF5 | AH5: =INDEX(Calib!$H$1:$H$13,$D5)*AC5+p_gov_take*$G5+AG5+p_programme*p_pricing*$J5 | AI5: =INDEX(Calib!$Y$1:$Y$13,$D5)-INDEX(Calib!$Z$1:$Z$13,$D5)*(AL4/AE4-INDEX(Calib!$AA$1:$AA$13,$D5)) | AJ5: =INDEX(Calib!$X$1:$X$13,$D5)+INDEX(Calib!$G$1:$G$13,$D5)+AF5+AI5-AH5 | AK5: =p_rk*AM4+AO4*(AL4-AM4) | AL5: =AL4+AK5+AJ5 | AM5: =INDEX(Calib!$U$1:$U$13,$D5)+(AM4-INDEX(Calib!$U$1:$U$13,$D5))*(1-p_amort)+p_sh_conc*AF5 | AN5: =AL5/AE5 | AO5: =INDEX(Calib!$K$1:$K$13,$D5)+p_eta*MAX(0,AN5-INDEX(Calib!$AA$1:$AA$13,$D5)) | AP5: =(1-INDEX(Calib!$H$1:$H$13,$D5))*(1-p_alpha)*AC5+AI5 | AQ5: =(AE5/O5-1)*100 | AR5: =(AE5/AE2-1)*100 | AS5: =(O5/O2-1)*100 | AT5: =(AN5-X5)*100 | AU5: =(AP5/Z5-1)*100 | AV5: =(AI5-S5)*100
A6: KEN | B6: 2028 | C6: 4 | D6: 2 | E6: =IF(AND(p_dis_year>0,B6=p_dis_year),1,0) | F6: =IF(AND(p_dis_year>0,B6>=p_dis_year),1-p_eps_a*p_rho_a^(B6-p_dis_year),1) | G6: =INDEX(Calib!$N$1:$N$13,$D6)*(1-p_rent_decline*MIN(1,C6/26)) | H6: =IF(C6=0,0,SUMIFS(dl_val,dl_iso,$A6,dl_ind,"pub_cap",dl_year,$B6)/100) | I6: =IF(C6=0,0,SUMIFS(dl_val,dl_iso,$A6,dl_ind,"pub_spend",dl_year,$B6)/100) | J6: =IF(C6=0,0,SUMIFS(dl_val,dl_iso,$A6,dl_ind,"rev",dl_year,$B6)/100) | K6: =(1-p_delta_g)*K5*(1-p_eps_g*$E6)+INDEX(Calib!$E$1:$E$13,$D6)*(INDEX(Calib!$G$1:$G$13,$D6)+0*$H6) | L6: =L5*(1-p_eps_k*$E6)+p_lambda_k*(N6-L5*(1-p_eps_k*$E6)) | M6: =INDEX(Calib!$R$1:$R$13,$D6)*$F6*(K5*(1-p_eps_g*$E6))^INDEX(Calib!$Q$1:$Q$13,$D6)*(L5*(1-p_eps_k*$E6))^p_alpha | N6: =p_alpha*(1-INDEX(Calib!$H$1:$H$13,$D6))*M6/(INDEX(Calib!$K$1:$K$13,$D6)+p_delta) | O6: =M6+$G6 | P6: =0*($H6+$I6) | Q6: =INDEX(Calib!$I$1:$I$13,$D6)+p_sh_grant*P6 | R6: =INDEX(Calib!$H$1:$H$13,$D6)*M6+p_gov_take*$G6+Q6+0*p_pricing*$J6 | S6: =INDEX(Calib!$Y$1:$Y$13,$D6)-INDEX(Calib!$Z$1:$Z$13,$D6)*(V5/O5-INDEX(Calib!$AA$1:$AA$13,$D6)) | T6: =INDEX(Calib!$X$1:$X$13,$D6)+INDEX(Calib!$G$1:$G$13,$D6)+P6+S6-R6 | U6: =p_rk*W5+Y5*(V5-W5) | V6: =V5+U6+T6 | W6: =INDEX(Calib!$U$1:$U$13,$D6)+(W5-INDEX(Calib!$U$1:$U$13,$D6))*(1-p_amort)+p_sh_conc*P6 | X6: =V6/O6 | Y6: =INDEX(Calib!$K$1:$K$13,$D6)+p_eta*MAX(0,X6-INDEX(Calib!$AA$1:$AA$13,$D6)) | Z6: =(1-INDEX(Calib!$H$1:$H$13,$D6))*(1-p_alpha)*M6+S6 | AA6: =(1-p_delta_g)*AA5*(1-p_eps_g*$E6)+INDEX(Calib!$E$1:$E$13,$D6)*(INDEX(Calib!$G$1:$G$13,$D6)+p_programme*$H6) | AB6: =AB5*(1-p_eps_k*$E6)+p_lambda_k*(AD6-AB5*(1-p_eps_k*$E6)) | AC6: =INDEX(Calib!$R$1:$R$13,$D6)*$F6*(AA5*(1-p_eps_g*$E6))^INDEX(Calib!$Q$1:$Q$13,$D6)*(AB5*(1-p_eps_k*$E6))^p_alpha | AD6: =p_alpha*(1-INDEX(Calib!$H$1:$H$13,$D6))*AC6/(INDEX(Calib!$K$1:$K$13,$D6)+p_delta) | AE6: =AC6+$G6 | AF6: =p_programme*($H6+$I6) | AG6: =INDEX(Calib!$I$1:$I$13,$D6)+p_sh_grant*AF6 | AH6: =INDEX(Calib!$H$1:$H$13,$D6)*AC6+p_gov_take*$G6+AG6+p_programme*p_pricing*$J6 | AI6: =INDEX(Calib!$Y$1:$Y$13,$D6)-INDEX(Calib!$Z$1:$Z$13,$D6)*(AL5/AE5-INDEX(Calib!$AA$1:$AA$13,$D6)) | AJ6: =INDEX(Calib!$X$1:$X$13,$D6)+INDEX(Calib!$G$1:$G$13,$D6)+AF6+AI6-AH6 | AK6: =p_rk*AM5+AO5*(AL5-AM5) | AL6: =AL5+AK6+AJ6 | AM6: =INDEX(Calib!$U$1:$U$13,$D6)+(AM5-INDEX(Calib!$U$1:$U$13,$D6))*(1-p_amort)+p_sh_conc*AF6 | AN6: =AL6/AE6 | AO6: =INDEX(Calib!$K$1:$K$13,$D6)+p_eta*MAX(0,AN6-INDEX(Calib!$AA$1:$AA$13,$D6)) | AP6: =(1-INDEX(Calib!$H$1:$H$13,$D6))*(1-p_alpha)*AC6+AI6 | AQ6: =(AE6/O6-1)*100 | AR6: =(AE6/AE2-1)*100 | AS6: =(O6/O2-1)*100 | AT6: =(AN6-X6)*100 | AU6: =(AP6/Z6-1)*100 | AV6: =(AI6-S6)*100
A7: KEN | B7: 2029 | C7: 5 | D7: 2 | E7: =IF(AND(p_dis_year>0,B7=p_dis_year),1,0) | F7: =IF(AND(p_dis_year>0,B7>=p_dis_year),1-p_eps_a*p_rho_a^(B7-p_dis_year),1) | G7: =INDEX(Calib!$N$1:$N$13,$D7)*(1-p_rent_decline*MIN(1,C7/26)) | H7: =IF(C7=0,0,SUMIFS(dl_val,dl_iso,$A7,dl_ind,"pub_cap",dl_year,$B7)/100) | I7: =IF(C7=0,0,SUMIFS(dl_val,dl_iso,$A7,dl_ind,"pub_spend",dl_year,$B7)/100) | J7: =IF(C7=0,0,SUMIFS(dl_val,dl_iso,$A7,dl_ind,"rev",dl_year,$B7)/100) | K7: =(1-p_delta_g)*K6*(1-p_eps_g*$E7)+INDEX(Calib!$E$1:$E$13,$D7)*(INDEX(Calib!$G$1:$G$13,$D7)+0*$H7) | L7: =L6*(1-p_eps_k*$E7)+p_lambda_k*(N7-L6*(1-p_eps_k*$E7)) | M7: =INDEX(Calib!$R$1:$R$13,$D7)*$F7*(K6*(1-p_eps_g*$E7))^INDEX(Calib!$Q$1:$Q$13,$D7)*(L6*(1-p_eps_k*$E7))^p_alpha | N7: =p_alpha*(1-INDEX(Calib!$H$1:$H$13,$D7))*M7/(INDEX(Calib!$K$1:$K$13,$D7)+p_delta) | O7: =M7+$G7 | P7: =0*($H7+$I7) | Q7: =INDEX(Calib!$I$1:$I$13,$D7)+p_sh_grant*P7 | R7: =INDEX(Calib!$H$1:$H$13,$D7)*M7+p_gov_take*$G7+Q7+0*p_pricing*$J7 | S7: =INDEX(Calib!$Y$1:$Y$13,$D7)-INDEX(Calib!$Z$1:$Z$13,$D7)*(V6/O6-INDEX(Calib!$AA$1:$AA$13,$D7)) | T7: =INDEX(Calib!$X$1:$X$13,$D7)+INDEX(Calib!$G$1:$G$13,$D7)+P7+S7-R7 | U7: =p_rk*W6+Y6*(V6-W6) | V7: =V6+U7+T7 | W7: =INDEX(Calib!$U$1:$U$13,$D7)+(W6-INDEX(Calib!$U$1:$U$13,$D7))*(1-p_amort)+p_sh_conc*P7 | X7: =V7/O7 | Y7: =INDEX(Calib!$K$1:$K$13,$D7)+p_eta*MAX(0,X7-INDEX(Calib!$AA$1:$AA$13,$D7)) | Z7: =(1-INDEX(Calib!$H$1:$H$13,$D7))*(1-p_alpha)*M7+S7 | AA7: =(1-p_delta_g)*AA6*(1-p_eps_g*$E7)+INDEX(Calib!$E$1:$E$13,$D7)*(INDEX(Calib!$G$1:$G$13,$D7)+p_programme*$H7) | AB7: =AB6*(1-p_eps_k*$E7)+p_lambda_k*(AD7-AB6*(1-p_eps_k*$E7)) | AC7: =INDEX(Calib!$R$1:$R$13,$D7)*$F7*(AA6*(1-p_eps_g*$E7))^INDEX(Calib!$Q$1:$Q$13,$D7)*(AB6*(1-p_eps_k*$E7))^p_alpha | AD7: =p_alpha*(1-INDEX(Calib!$H$1:$H$13,$D7))*AC7/(INDEX(Calib!$K$1:$K$13,$D7)+p_delta) | AE7: =AC7+$G7 | AF7: =p_programme*($H7+$I7) | AG7: =INDEX(Calib!$I$1:$I$13,$D7)+p_sh_grant*AF7 | AH7: =INDEX(Calib!$H$1:$H$13,$D7)*AC7+p_gov_take*$G7+AG7+p_programme*p_pricing*$J7 | AI7: =INDEX(Calib!$Y$1:$Y$13,$D7)-INDEX(Calib!$Z$1:$Z$13,$D7)*(AL6/AE6-INDEX(Calib!$AA$1:$AA$13,$D7)) | AJ7: =INDEX(Calib!$X$1:$X$13,$D7)+INDEX(Calib!$G$1:$G$13,$D7)+AF7+AI7-AH7 | AK7: =p_rk*AM6+AO6*(AL6-AM6) | AL7: =AL6+AK7+AJ7 | AM7: =INDEX(Calib!$U$1:$U$13,$D7)+(AM6-INDEX(Calib!$U$1:$U$13,$D7))*(1-p_amort)+p_sh_conc*AF7 | AN7: =AL7/AE7 | AO7: =INDEX(Calib!$K$1:$K$13,$D7)+p_eta*MAX(0,AN7-INDEX(Calib!$AA$1:$AA$13,$D7)) | AP7: =(1-INDEX(Calib!$H$1:$H$13,$D7))*(1-p_alpha)*AC7+AI7 | AQ7: =(AE7/O7-1)*100 | AR7: =(AE7/AE2-1)*100 | AS7: =(O7/O2-1)*100 | AT7: =(AN7-X7)*100 | AU7: =(AP7/Z7-1)*100 | AV7: =(AI7-S7)*100
A8: KEN | B8: 2030 | C8: 6 | D8: 2 | E8: =IF(AND(p_dis_year>0,B8=p_dis_year),1,0) | F8: =IF(AND(p_dis_year>0,B8>=p_dis_year),1-p_eps_a*p_rho_a^(B8-p_dis_year),1) | G8: =INDEX(Calib!$N$1:$N$13,$D8)*(1-p_rent_decline*MIN(1,C8/26)) | H8: =IF(C8=0,0,SUMIFS(dl_val,dl_iso,$A8,dl_ind,"pub_cap",dl_year,$B8)/100) | I8: =IF(C8=0,0,SUMIFS(dl_val,dl_iso,$A8,dl_ind,"pub_spend",dl_year,$B8)/100) | J8: =IF(C8=0,0,SUMIFS(dl_val,dl_iso,$A8,dl_ind,"rev",dl_year,$B8)/100) | K8: =(1-p_delta_g)*K7*(1-p_eps_g*$E8)+INDEX(Calib!$E$1:$E$13,$D8)*(INDEX(Calib!$G$1:$G$13,$D8)+0*$H8) | L8: =L7*(1-p_eps_k*$E8)+p_lambda_k*(N8-L7*(1-p_eps_k*$E8)) | M8: =INDEX(Calib!$R$1:$R$13,$D8)*$F8*(K7*(1-p_eps_g*$E8))^INDEX(Calib!$Q$1:$Q$13,$D8)*(L7*(1-p_eps_k*$E8))^p_alpha | N8: =p_alpha*(1-INDEX(Calib!$H$1:$H$13,$D8))*M8/(INDEX(Calib!$K$1:$K$13,$D8)+p_delta) | O8: =M8+$G8 | P8: =0*($H8+$I8) | Q8: =INDEX(Calib!$I$1:$I$13,$D8)+p_sh_grant*P8 | R8: =INDEX(Calib!$H$1:$H$13,$D8)*M8+p_gov_take*$G8+Q8+0*p_pricing*$J8 | S8: =INDEX(Calib!$Y$1:$Y$13,$D8)-INDEX(Calib!$Z$1:$Z$13,$D8)*(V7/O7-INDEX(Calib!$AA$1:$AA$13,$D8)) | T8: =INDEX(Calib!$X$1:$X$13,$D8)+INDEX(Calib!$G$1:$G$13,$D8)+P8+S8-R8 | U8: =p_rk*W7+Y7*(V7-W7) | V8: =V7+U8+T8 | W8: =INDEX(Calib!$U$1:$U$13,$D8)+(W7-INDEX(Calib!$U$1:$U$13,$D8))*(1-p_amort)+p_sh_conc*P8 | X8: =V8/O8 | Y8: =INDEX(Calib!$K$1:$K$13,$D8)+p_eta*MAX(0,X8-INDEX(Calib!$AA$1:$AA$13,$D8)) | Z8: =(1-INDEX(Calib!$H$1:$H$13,$D8))*(1-p_alpha)*M8+S8 | AA8: =(1-p_delta_g)*AA7*(1-p_eps_g*$E8)+INDEX(Calib!$E$1:$E$13,$D8)*(INDEX(Calib!$G$1:$G$13,$D8)+p_programme*$H8) | AB8: =AB7*(1-p_eps_k*$E8)+p_lambda_k*(AD8-AB7*(1-p_eps_k*$E8)) | AC8: =INDEX(Calib!$R$1:$R$13,$D8)*$F8*(AA7*(1-p_eps_g*$E8))^INDEX(Calib!$Q$1:$Q$13,$D8)*(AB7*(1-p_eps_k*$E8))^p_alpha | AD8: =p_alpha*(1-INDEX(Calib!$H$1:$H$13,$D8))*AC8/(INDEX(Calib!$K$1:$K$13,$D8)+p_delta) | AE8: =AC8+$G8 | AF8: =p_programme*($H8+$I8) | AG8: =INDEX(Calib!$I$1:$I$13,$D8)+p_sh_grant*AF8 | AH8: =INDEX(Calib!$H$1:$H$13,$D8)*AC8+p_gov_take*$G8+AG8+p_programme*p_pricing*$J8 | AI8: =INDEX(Calib!$Y$1:$Y$13,$D8)-INDEX(Calib!$Z$1:$Z$13,$D8)*(AL7/AE7-INDEX(Calib!$AA$1:$AA$13,$D8)) | AJ8: =INDEX(Calib!$X$1:$X$13,$D8)+INDEX(Calib!$G$1:$G$13,$D8)+AF8+AI8-AH8 | AK8: =p_rk*AM7+AO7*(AL7-AM7) | AL8: =AL7+AK8+AJ8 | AM8: =INDEX(Calib!$U$1:$U$13,$D8)+(AM7-INDEX(Calib!$U$1:$U$13,$D8))*(1-p_amort)+p_sh_conc*AF8 | AN8: =AL8/AE8 | AO8: =INDEX(Calib!$K$1:$K$13,$D8)+p_eta*MAX(0,AN8-INDEX(Calib!$AA$1:$AA$13,$D8)) | AP8: =(1-INDEX(Calib!$H$1:$H$13,$D8))*(1-p_alpha)*AC8+AI8 | AQ8: =(AE8/O8-1)*100 | AR8: =(AE8/AE2-1)*100 | AS8: =(O8/O2-1)*100 | AT8: =(AN8-X8)*100 | AU8: =(AP8/Z8-1)*100 | AV8: =(AI8-S8)*100
A9: KEN | B9: 2031 | C9: 7 | D9: 2 | E9: =IF(AND(p_dis_year>0,B9=p_dis_year),1,0) | F9: =IF(AND(p_dis_year>0,B9>=p_dis_year),1-p_eps_a*p_rho_a^(B9-p_dis_year),1) | G9: =INDEX(Calib!$N$1:$N$13,$D9)*(1-p_rent_decline*MIN(1,C9/26)) | H9: =IF(C9=0,0,SUMIFS(dl_val,dl_iso,$A9,dl_ind,"pub_cap",dl_year,$B9)/100) | I9: =IF(C9=0,0,SUMIFS(dl_val,dl_iso,$A9,dl_ind,"pub_spend",dl_year,$B9)/100) | J9: =IF(C9=0,0,SUMIFS(dl_val,dl_iso,$A9,dl_ind,"rev",dl_year,$B9)/100) | K9: =(1-p_delta_g)*K8*(1-p_eps_g*$E9)+INDEX(Calib!$E$1:$E$13,$D9)*(INDEX(Calib!$G$1:$G$13,$D9)+0*$H9) | L9: =L8*(1-p_eps_k*$E9)+p_lambda_k*(N9-L8*(1-p_eps_k*$E9)) | M9: =INDEX(Calib!$R$1:$R$13,$D9)*$F9*(K8*(1-p_eps_g*$E9))^INDEX(Calib!$Q$1:$Q$13,$D9)*(L8*(1-p_eps_k*$E9))^p_alpha | N9: =p_alpha*(1-INDEX(Calib!$H$1:$H$13,$D9))*M9/(INDEX(Calib!$K$1:$K$13,$D9)+p_delta) | O9: =M9+$G9 | P9: =0*($H9+$I9) | Q9: =INDEX(Calib!$I$1:$I$13,$D9)+p_sh_grant*P9 | R9: =INDEX(Calib!$H$1:$H$13,$D9)*M9+p_gov_take*$G9+Q9+0*p_pricing*$J9 | S9: =INDEX(Calib!$Y$1:$Y$13,$D9)-INDEX(Calib!$Z$1:$Z$13,$D9)*(V8/O8-INDEX(Calib!$AA$1:$AA$13,$D9)) | T9: =INDEX(Calib!$X$1:$X$13,$D9)+INDEX(Calib!$G$1:$G$13,$D9)+P9+S9-R9 | U9: =p_rk*W8+Y8*(V8-W8) | V9: =V8+U9+T9 | W9: =INDEX(Calib!$U$1:$U$13,$D9)+(W8-INDEX(Calib!$U$1:$U$13,$D9))*(1-p_amort)+p_sh_conc*P9 | X9: =V9/O9 | Y9: =INDEX(Calib!$K$1:$K$13,$D9)+p_eta*MAX(0,X9-INDEX(Calib!$AA$1:$AA$13,$D9)) | Z9: =(1-INDEX(Calib!$H$1:$H$13,$D9))*(1-p_alpha)*M9+S9 | AA9: =(1-p_delta_g)*AA8*(1-p_eps_g*$E9)+INDEX(Calib!$E$1:$E$13,$D9)*(INDEX(Calib!$G$1:$G$13,$D9)+p_programme*$H9) | AB9: =AB8*(1-p_eps_k*$E9)+p_lambda_k*(AD9-AB8*(1-p_eps_k*$E9)) | AC9: =INDEX(Calib!$R$1:$R$13,$D9)*$F9*(AA8*(1-p_eps_g*$E9))^INDEX(Calib!$Q$1:$Q$13,$D9)*(AB8*(1-p_eps_k*$E9))^p_alpha | AD9: =p_alpha*(1-INDEX(Calib!$H$1:$H$13,$D9))*AC9/(INDEX(Calib!$K$1:$K$13,$D9)+p_delta) | AE9: =AC9+$G9 | AF9: =p_programme*($H9+$I9) | AG9: =INDEX(Calib!$I$1:$I$13,$D9)+p_sh_grant*AF9 | AH9: =INDEX(Calib!$H$1:$H$13,$D9)*AC9+p_gov_take*$G9+AG9+p_programme*p_pricing*$J9 | AI9: =INDEX(Calib!$Y$1:$Y$13,$D9)-INDEX(Calib!$Z$1:$Z$13,$D9)*(AL8/AE8-INDEX(Calib!$AA$1:$AA$13,$D9)) | AJ9: =INDEX(Calib!$X$1:$X$13,$D9)+INDEX(Calib!$G$1:$G$13,$D9)+AF9+AI9-AH9 | AK9: =p_rk*AM8+AO8*(AL8-AM8) | AL9: =AL8+AK9+AJ9 | AM9: =INDEX(Calib!$U$1:$U$13,$D9)+(AM8-INDEX(Calib!$U$1:$U$13,$D9))*(1-p_amort)+p_sh_conc*AF9 | AN9: =AL9/AE9 | AO9: =INDEX(Calib!$K$1:$K$13,$D9)+p_eta*MAX(0,AN9-INDEX(Calib!$AA$1:$AA$13,$D9)) | AP9: =(1-INDEX(Calib!$H$1:$H$13,$D9))*(1-p_alpha)*AC9+AI9 | AQ9: =(AE9/O9-1)*100 | AR9: =(AE9/AE2-1)*100 | AS9: =(O9/O2-1)*100 | AT9: =(AN9-X9)*100 | AU9: =(AP9/Z9-1)*100 | AV9: =(AI9-S9)*100
A10: KEN | B10: 2032 | C10: 8 | D10: 2 | E10: =IF(AND(p_dis_year>0,B10=p_dis_year),1,0) | F10: =IF(AND(p_dis_year>0,B10>=p_dis_year),1-p_eps_a*p_rho_a^(B10-p_dis_year),1) | G10: =INDEX(Calib!$N$1:$N$13,$D10)*(1-p_rent_decline*MIN(1,C10/26)) | H10: =IF(C10=0,0,SUMIFS(dl_val,dl_iso,$A10,dl_ind,"pub_cap",dl_year,$B10)/100) | I10: =IF(C10=0,0,SUMIFS(dl_val,dl_iso,$A10,dl_ind,"pub_spend",dl_year,$B10)/100) | J10: =IF(C10=0,0,SUMIFS(dl_val,dl_iso,$A10,dl_ind,"rev",dl_year,$B10)/100) | K10: =(1-p_delta_g)*K9*(1-p_eps_g*$E10)+INDEX(Calib!$E$1:$E$13,$D10)*(INDEX(Calib!$G$1:$G$13,$D10)+0*$H10) | L10: =L9*(1-p_eps_k*$E10)+p_lambda_k*(N10-L9*(1-p_eps_k*$E10)) | M10: =INDEX(Calib!$R$1:$R$13,$D10)*$F10*(K9*(1-p_eps_g*$E10))^INDEX(Calib!$Q$1:$Q$13,$D10)*(L9*(1-p_eps_k*$E10))^p_alpha | N10: =p_alpha*(1-INDEX(Calib!$H$1:$H$13,$D10))*M10/(INDEX(Calib!$K$1:$K$13,$D10)+p_delta) | O10: =M10+$G10 | P10: =0*($H10+$I10) | Q10: =INDEX(Calib!$I$1:$I$13,$D10)+p_sh_grant*P10 | R10: =INDEX(Calib!$H$1:$H$13,$D10)*M10+p_gov_take*$G10+Q10+0*p_pricing*$J10 | S10: =INDEX(Calib!$Y$1:$Y$13,$D10)-INDEX(Calib!$Z$1:$Z$13,$D10)*(V9/O9-INDEX(Calib!$AA$1:$AA$13,$D10)) | T10: =INDEX(Calib!$X$1:$X$13,$D10)+INDEX(Calib!$G$1:$G$13,$D10)+P10+S10-R10 | U10: =p_rk*W9+Y9*(V9-W9) | V10: =V9+U10+T10 | W10: =INDEX(Calib!$U$1:$U$13,$D10)+(W9-INDEX(Calib!$U$1:$U$13,$D10))*(1-p_amort)+p_sh_conc*P10 | X10: =V10/O10 | Y10: =INDEX(Calib!$K$1:$K$13,$D10)+p_eta*MAX(0,X10-INDEX(Calib!$AA$1:$AA$13,$D10)) | Z10: =(1-INDEX(Calib!$H$1:$H$13,$D10))*(1-p_alpha)*M10+S10 | AA10: =(1-p_delta_g)*AA9*(1-p_eps_g*$E10)+INDEX(Calib!$E$1:$E$13,$D10)*(INDEX(Calib!$G$1:$G$13,$D10)+p_programme*$H10) | AB10: =AB9*(1-p_eps_k*$E10)+p_lambda_k*(AD10-AB9*(1-p_eps_k*$E10)) | AC10: =INDEX(Calib!$R$1:$R$13,$D10)*$F10*(AA9*(1-p_eps_g*$E10))^INDEX(Calib!$Q$1:$Q$13,$D10)*(AB9*(1-p_eps_k*$E10))^p_alpha | AD10: =p_alpha*(1-INDEX(Calib!$H$1:$H$13,$D10))*AC10/(INDEX(Calib!$K$1:$K$13,$D10)+p_delta) | AE10: =AC10+$G10 | AF10: =p_programme*($H10+$I10) | AG10: =INDEX(Calib!$I$1:$I$13,$D10)+p_sh_grant*AF10 | AH10: =INDEX(Calib!$H$1:$H$13,$D10)*AC10+p_gov_take*$G10+AG10+p_programme*p_pricing*$J10 | AI10: =INDEX(Calib!$Y$1:$Y$13,$D10)-INDEX(Calib!$Z$1:$Z$13,$D10)*(AL9/AE9-INDEX(Calib!$AA$1:$AA$13,$D10)) | AJ10: =INDEX(Calib!$X$1:$X$13,$D10)+INDEX(Calib!$G$1:$G$13,$D10)+AF10+AI10-AH10 | AK10: =p_rk*AM9+AO9*(AL9-AM9) | AL10: =AL9+AK10+AJ10 | AM10: =INDEX(Calib!$U$1:$U$13,$D10)+(AM9-INDEX(Calib!$U$1:$U$13,$D10))*(1-p_amort)+p_sh_conc*AF10 | AN10: =AL10/AE10 | AO10: =INDEX(Calib!$K$1:$K$13,$D10)+p_eta*MAX(0,AN10-INDEX(Calib!$AA$1:$AA$13,$D10)) | AP10: =(1-INDEX(Calib!$H$1:$H$13,$D10))*(1-p_alpha)*AC10+AI10 | AQ10: =(AE10/O10-1)*100 | AR10: =(AE10/AE2-1)*100 | AS10: =(O10/O2-1)*100 | AT10: =(AN10-X10)*100 | AU10: =(AP10/Z10-1)*100 | AV10: =(AI10-S10)*100
A11: KEN | B11: 2033 | C11: 9 | D11: 2 | E11: =IF(AND(p_dis_year>0,B11=p_dis_year),1,0) | F11: =IF(AND(p_dis_year>0,B11>=p_dis_year),1-p_eps_a*p_rho_a^(B11-p_dis_year),1) | G11: =INDEX(Calib!$N$1:$N$13,$D11)*(1-p_rent_decline*MIN(1,C11/26)) | H11: =IF(C11=0,0,SUMIFS(dl_val,dl_iso,$A11,dl_ind,"pub_cap",dl_year,$B11)/100) | I11: =IF(C11=0,0,SUMIFS(dl_val,dl_iso,$A11,dl_ind,"pub_spend",dl_year,$B11)/100) | J11: =IF(C11=0,0,SUMIFS(dl_val,dl_iso,$A11,dl_ind,"rev",dl_year,$B11)/100) | K11: =(1-p_delta_g)*K10*(1-p_eps_g*$E11)+INDEX(Calib!$E$1:$E$13,$D11)*(INDEX(Calib!$G$1:$G$13,$D11)+0*$H11) | L11: =L10*(1-p_eps_k*$E11)+p_lambda_k*(N11-L10*(1-p_eps_k*$E11)) | M11: =INDEX(Calib!$R$1:$R$13,$D11)*$F11*(K10*(1-p_eps_g*$E11))^INDEX(Calib!$Q$1:$Q$13,$D11)*(L10*(1-p_eps_k*$E11))^p_alpha | N11: =p_alpha*(1-INDEX(Calib!$H$1:$H$13,$D11))*M11/(INDEX(Calib!$K$1:$K$13,$D11)+p_delta) | O11: =M11+$G11 | P11: =0*($H11+$I11) | Q11: =INDEX(Calib!$I$1:$I$13,$D11)+p_sh_grant*P11 | R11: =INDEX(Calib!$H$1:$H$13,$D11)*M11+p_gov_take*$G11+Q11+0*p_pricing*$J11 | S11: =INDEX(Calib!$Y$1:$Y$13,$D11)-INDEX(Calib!$Z$1:$Z$13,$D11)*(V10/O10-INDEX(Calib!$AA$1:$AA$13,$D11)) | T11: =INDEX(Calib!$X$1:$X$13,$D11)+INDEX(Calib!$G$1:$G$13,$D11)+P11+S11-R11 | U11: =p_rk*W10+Y10*(V10-W10) | V11: =V10+U11+T11 | W11: =INDEX(Calib!$U$1:$U$13,$D11)+(W10-INDEX(Calib!$U$1:$U$13,$D11))*(1-p_amort)+p_sh_conc*P11 | X11: =V11/O11 | Y11: =INDEX(Calib!$K$1:$K$13,$D11)+p_eta*MAX(0,X11-INDEX(Calib!$AA$1:$AA$13,$D11)) | Z11: =(1-INDEX(Calib!$H$1:$H$13,$D11))*(1-p_alpha)*M11+S11 | AA11: =(1-p_delta_g)*AA10*(1-p_eps_g*$E11)+INDEX(Calib!$E$1:$E$13,$D11)*(INDEX(Calib!$G$1:$G$13,$D11)+p_programme*$H11) | AB11: =AB10*(1-p_eps_k*$E11)+p_lambda_k*(AD11-AB10*(1-p_eps_k*$E11)) | AC11: =INDEX(Calib!$R$1:$R$13,$D11)*$F11*(AA10*(1-p_eps_g*$E11))^INDEX(Calib!$Q$1:$Q$13,$D11)*(AB10*(1-p_eps_k*$E11))^p_alpha | AD11: =p_alpha*(1-INDEX(Calib!$H$1:$H$13,$D11))*AC11/(INDEX(Calib!$K$1:$K$13,$D11)+p_delta) | AE11: =AC11+$G11 | AF11: =p_programme*($H11+$I11) | AG11: =INDEX(Calib!$I$1:$I$13,$D11)+p_sh_grant*AF11 | AH11: =INDEX(Calib!$H$1:$H$13,$D11)*AC11+p_gov_take*$G11+AG11+p_programme*p_pricing*$J11 | AI11: =INDEX(Calib!$Y$1:$Y$13,$D11)-INDEX(Calib!$Z$1:$Z$13,$D11)*(AL10/AE10-INDEX(Calib!$AA$1:$AA$13,$D11)) | AJ11: =INDEX(Calib!$X$1:$X$13,$D11)+INDEX(Calib!$G$1:$G$13,$D11)+AF11+AI11-AH11 | AK11: =p_rk*AM10+AO10*(AL10-AM10) | AL11: =AL10+AK11+AJ11 | AM11: =INDEX(Calib!$U$1:$U$13,$D11)+(AM10-INDEX(Calib!$U$1:$U$13,$D11))*(1-p_amort)+p_sh_conc*AF11 | AN11: =AL11/AE11 | AO11: =INDEX(Calib!$K$1:$K$13,$D11)+p_eta*MAX(0,AN11-INDEX(Calib!$AA$1:$AA$13,$D11)) | AP11: =(1-INDEX(Calib!$H$1:$H$13,$D11))*(1-p_alpha)*AC11+AI11 | AQ11: =(AE11/O11-1)*100 | AR11: =(AE11/AE2-1)*100 | AS11: =(O11/O2-1)*100 | AT11: =(AN11-X11)*100 | AU11: =(AP11/Z11-1)*100 | AV11: =(AI11-S11)*100
A12: KEN | B12: 2034 | C12: 10 | D12: 2 | E12: =IF(AND(p_dis_year>0,B12=p_dis_year),1,0) | F12: =IF(AND(p_dis_year>0,B12>=p_dis_year),1-p_eps_a*p_rho_a^(B12-p_dis_year),1) | G12: =INDEX(Calib!$N$1:$N$13,$D12)*(1-p_rent_decline*MIN(1,C12/26)) | H12: =IF(C12=0,0,SUMIFS(dl_val,dl_iso,$A12,dl_ind,"pub_cap",dl_year,$B12)/100) | I12: =IF(C12=0,0,SUMIFS(dl_val,dl_iso,$A12,dl_ind,"pub_spend",dl_year,$B12)/100) | J12: =IF(C12=0,0,SUMIFS(dl_val,dl_iso,$A12,dl_ind,"rev",dl_year,$B12)/100) | K12: =(1-p_delta_g)*K11*(1-p_eps_g*$E12)+INDEX(Calib!$E$1:$E$13,$D12)*(INDEX(Calib!$G$1:$G$13,$D12)+0*$H12) | L12: =L11*(1-p_eps_k*$E12)+p_lambda_k*(N12-L11*(1-p_eps_k*$E12)) | M12: =INDEX(Calib!$R$1:$R$13,$D12)*$F12*(K11*(1-p_eps_g*$E12))^INDEX(Calib!$Q$1:$Q$13,$D12)*(L11*(1-p_eps_k*$E12))^p_alpha | N12: =p_alpha*(1-INDEX(Calib!$H$1:$H$13,$D12))*M12/(INDEX(Calib!$K$1:$K$13,$D12)+p_delta) | O12: =M12+$G12 | P12: =0*($H12+$I12) | Q12: =INDEX(Calib!$I$1:$I$13,$D12)+p_sh_grant*P12 | R12: =INDEX(Calib!$H$1:$H$13,$D12)*M12+p_gov_take*$G12+Q12+0*p_pricing*$J12 | S12: =INDEX(Calib!$Y$1:$Y$13,$D12)-INDEX(Calib!$Z$1:$Z$13,$D12)*(V11/O11-INDEX(Calib!$AA$1:$AA$13,$D12)) | T12: =INDEX(Calib!$X$1:$X$13,$D12)+INDEX(Calib!$G$1:$G$13,$D12)+P12+S12-R12 | U12: =p_rk*W11+Y11*(V11-W11) | V12: =V11+U12+T12 | W12: =INDEX(Calib!$U$1:$U$13,$D12)+(W11-INDEX(Calib!$U$1:$U$13,$D12))*(1-p_amort)+p_sh_conc*P12 | X12: =V12/O12 | Y12: =INDEX(Calib!$K$1:$K$13,$D12)+p_eta*MAX(0,X12-INDEX(Calib!$AA$1:$AA$13,$D12)) | Z12: =(1-INDEX(Calib!$H$1:$H$13,$D12))*(1-p_alpha)*M12+S12 | AA12: =(1-p_delta_g)*AA11*(1-p_eps_g*$E12)+INDEX(Calib!$E$1:$E$13,$D12)*(INDEX(Calib!$G$1:$G$13,$D12)+p_programme*$H12) | AB12: =AB11*(1-p_eps_k*$E12)+p_lambda_k*(AD12-AB11*(1-p_eps_k*$E12)) | AC12: =INDEX(Calib!$R$1:$R$13,$D12)*$F12*(AA11*(1-p_eps_g*$E12))^INDEX(Calib!$Q$1:$Q$13,$D12)*(AB11*(1-p_eps_k*$E12))^p_alpha | AD12: =p_alpha*(1-INDEX(Calib!$H$1:$H$13,$D12))*AC12/(INDEX(Calib!$K$1:$K$13,$D12)+p_delta) | AE12: =AC12+$G12 | AF12: =p_programme*($H12+$I12) | AG12: =INDEX(Calib!$I$1:$I$13,$D12)+p_sh_grant*AF12 | AH12: =INDEX(Calib!$H$1:$H$13,$D12)*AC12+p_gov_take*$G12+AG12+p_programme*p_pricing*$J12 | AI12: =INDEX(Calib!$Y$1:$Y$13,$D12)-INDEX(Calib!$Z$1:$Z$13,$D12)*(AL11/AE11-INDEX(Calib!$AA$1:$AA$13,$D12)) | AJ12: =INDEX(Calib!$X$1:$X$13,$D12)+INDEX(Calib!$G$1:$G$13,$D12)+AF12+AI12-AH12 | AK12: =p_rk*AM11+AO11*(AL11-AM11) | AL12: =AL11+AK12+AJ12 | AM12: =INDEX(Calib!$U$1:$U$13,$D12)+(AM11-INDEX(Calib!$U$1:$U$13,$D12))*(1-p_amort)+p_sh_conc*AF12 | AN12: =AL12/AE12 | AO12: =INDEX(Calib!$K$1:$K$13,$D12)+p_eta*MAX(0,AN12-INDEX(Calib!$AA$1:$AA$13,$D12)) | AP12: =(1-INDEX(Calib!$H$1:$H$13,$D12))*(1-p_alpha)*AC12+AI12 | AQ12: =(AE12/O12-1)*100 | AR12: =(AE12/AE2-1)*100 | AS12: =(O12/O2-1)*100 | AT12: =(AN12-X12)*100 | AU12: =(AP12/Z12-1)*100 | AV12: =(AI12-S12)*100
