Workbook

Sheet Settings
A1: CPAT industry kernel - Egypt prototype v0.17
A3: Country code | B3: egy | C3: First component of every code; CPAT convention (egy.mit.<var>.<sector>.<fuel>.<type>.<scenario>)
A4: Price group for industry sectors | B4: ind | C4: C2 retail-price group the four sectors read (pow / res / ind / tra)
A5: Elasticity column | B5: Industries | C5: Column of the master elasticity table (Transport / Residential / Industries / Services)
A6: Base year | B6: 2022 | C6: MTInputs FirstYearCalculations; energy in the base year is read from Data_Energy, later years from the kernel
A7: Additional policy-induced efficiency (alpha+) | B7: =INDEX(MTInputs!$F$8:$F$415,MATCH("AdditionalEfficiencyIndustrial",MTInputs!$H$8:$H$415,0)) -> 0 | C7: Read from the MTInputs column by NameOfParameter; this is the only MTInputs dependency of the kernel rows
A8: Carbon price start year (info) | B8: =INDEX(MTInputs!$F$8:$F$415,MATCH("CPIntro",MTInputs!$H$8:$H$415,0)) -> 2026 | C8: For reference: the policy scenario new-policy wedge (nce) starts here
A9: Carbon price target (info) | B9: =INDEX(MTInputs!$F$8:$F$415,MATCH("CPLevelTarget",MTInputs!$H$8:$H$415,0)) -> 50 | C9: $/tCO2
A10: Policy bundle for scenario 2 (EGY) | B10: LEGACY | C10: Bundle run as policy scenario 2 (Scenarios section 2). LEGACY = CPAT default (regression vs v0.3/legacy). Check-sheet legacy comparisons are valid for LEGACY only.
A12: Kernel (every energy cell, year t >= 2023):
A13: F(t) = F(t-1) * (1+g)^(eY*delta) * (1+psi) * (p(t)/p(t-1))^eU * [ (s(t)/s(t-1))^eF / (1 + a + a+) ]^(1+eU)
A14: p = post-tax price (atp), s = shadow price (shp) = atp + sigma*ssc, g = post-policy GDP growth, delta = income-elasticity discount, psi = exogenous shock
A16: Sheets
A17: Manual inputs | C17: Legacy 'Manual inputs' Process Emissions section (rows 18-47, same positions): CBAM process coverage switches, product emission factors, half-elasticities.
A18: Scenarios | C18: EGY: carbon price paths, policy bundles 1A-3C (+LEGACY), active-bundle series mirrored into Data_Prices by code, pass-through factors, interface contract between work streams.
A19: Mitigation_Industry | C19: Kernel sheet in the CPAT Mitigation layout (columns A-AI, years K-AI): 4 CBAM sectors x 2 scenarios, each scenario followed by the 156-row CBAM goods block (legacy Mitigation 5881-6036 / 12198-12353). All formulas; codes built from components.
A20: MTInputs | C20: The 415-row CPAT parameter column, copied unchanged (columns A-I of the MTInputs sheet).
A21: Data_Energy | C21: Base-year energy matrix, fuel x sector, ktoe (Mitigation B4 rows 583-602).
A22: Data_Prices | C22: Pre-tax price before new policies (pbc), new-policy wedge (nce), shadow price (shp), sector coverage (tcf), share of shadow price on efficiency (ssc); both scenarios. Plus carbon price (cptraj) and auctioned ETS price (etstraj) trajectories for the CBAM block. v0.4: scenario-2 cptraj/etstraj/nce read Scenarios; interface rows pptraj, encov, obrsh, obrrb, fundsh, fundsp.
A23: Data_Macro | C23: GDP growth, income-elasticity discount factor, exogenous shock; both scenarios.
A24: Data_Elast | C24: Master elasticity table (income, usage, efficiency, AEEI) by fuel group x sector group, plus the fuel-group map.
A25: Check | C25: Kernel output against the values stored in CPAT_1_0pre_456 for the same rows; max absolute and relative differences. v0.3: plus CBAM block rows vs legacy (rows from 583). v0.4: plus Scenarios regression section. v0.5: Task A identity section (row 1429). v0.6: Task B section (row 1443). v0.7: Task C section (row 1455). v0.8: Task K section (row 1464). v0.9: Task D section (row 1476). v0.10: Task H section (row 1489). v0.11: Task L section (row 1506). v0.12 (Stream 2 merged): Task F section (row 1520), Task I section (row 1552), Task J section (row 1667). v0.13: Task G section (row 1831). v0.14: Task M section (row 1861). v0.15: T1/T5 section (row 1881). v0.16: v0.16 section (row 1907). v0.17: carve-out section (row 1919).
A27: Version log
A28: v0.1 | C28: Initial kernel (egypt+mitigation).
A29: v0.2 | C29: Conformed to NORMS.md: MTInputs used/unused colouring, hidden MT/Dashboard placeholder columns, CPAT colours, title band. No formula changes.
A30: v0.3 | C30: TASK-1: CBAM goods / process emissions block (legacy Mitigation 12198-12353, 156 rows, cols A-AI) added after each scenario; 'Manual inputs' rows 18-47; cptraj/etstraj in Data_Prices; MTInputs F117:F121 linked to Manual inputs row 22. Carbon Tax/ETS rows now read the scenario trajectories (legacy: hard zeros, broken K refs). Legacy WIP bugs fixed: fuel emissions by sector M..AE hard-coded; aluminium fuel-ER relative ref; missing post-policy process total; product-price year header. Kernel rows unchanged (regression diff 0).
A31: v0.4 | B31: 2026-10-02 | C31: Task E: Scenarios sheet (price paths LEGACY/ZERO/FLAT20_2028/RAMP_EG3/RAMP50_2034; bundles LEGACY,1A,2A,2B,3A,3B,3C; selector Settings!B10). Scenario-2 cptraj/etstraj/nce now = active-bundle series (nce = cptraj x encov x factor). New interface rows pptraj/encov/obrsh/obrrb/fundsh/fundsp (both scenarios). CBAM block o4 = fundsp, o5 = fundsh x o155, o6 = obrrb; Additional ER rows o107-o114 read o4 instead of o5. Manual inputs E21 = bundle process flag. LEGACY: regression diff vs v0.3 ~1e-15 (floating point of cptraj x factor).
A32: v0.5 | B32: 2026-10-02 | C32: Task A: CBAM block output codes unique (cpef/cpep, emisf/emisp, emrf/emrp; combined emis/emr in spare rows o135/o136). Revenues fixed: o147-o154 = post-policy fuel CO2 x fuel inclusion + post-policy process x process inclusion (legacy: pre-policy process x fuel inclusion, no fuel revenue); split revf/revp in o137/o138, o155 = sum. Changed by design: scenario-2 revenue rows (LEGACY o155 2030: 1697.5 -> fuel only, process not covered); all other values identical to v0.4.
A33: v0.6 | B33: 2026-10-02 | C33: Task B: 4-way EF split (fc, fp, np, no) with coverage switches per bundle (Scenarios M:P, all 1; block o28). Price rows use covered EFs (fuel group fc+fp, process group np+no); process ER and revenues act on the covered share (o85-o92 I:J). Full process EF floored per category. Post-policy emissions by category in o13-o16 (emisfc/emisfp/emisnp/emisno.cbam.tot). All values identical to v0.5 with switches = 1.
A34: v0.7 | B34: 2026-10-02 | C34: Task C: CBAM process emissions (np + no) priced at pptraj (new block row o63) in the process price rows, process ER, revp, product revenues and np/no emissions; fuel CO2 stays on cptraj (o2). All values identical to v0.6 (every bundle uses the same energy and process path).
A35: v0.8 | B35: 2026-10-02 | C35: Task K: CBAM metrics in block spare rows: cbcov (o39), cbint (o40), cbintch (o41), EU-export-weighted cbintchx (o51) and cbcovx (o52). New rows only; no existing value changes.
A36: v0.9 | B36: 2026-10-02 | C36: Task D: IPCC-inferred process semi-elasticities by product and category (np, no) with technical potential ERmax (Manual inputs rows 53-60); block o118-o125 apply them per category. Selector Manual inputs E50 (IPCC default; ADHOC reproduces v0.8). Anchors are placeholders equal to the ad hoc values (results unchanged) pending the IPCC research report.
A37: v0.10 | B37: 2026-10-02 | C37: Task H: CBAM output responds to the carbon cost net of the output-based rebate, Q = Qbase x (1 + dp_net)^eps (Manual inputs rows 66-73, switch E63; eps placeholder -0.5). New codes cbqch, emrq, emrt; block o75-o82 redefined as the net cost increase. OFF (and the LEGACY bundle) reproduces v0.9.
A38: v0.11 | B38: 2026-10-02 | C38: Task L: CBAM obligations on EU exports (cbobl, cbobl0, cbobch, cbobchu in block o94/o105/o116/o127) with EU price (placeholder 100), CBAM phase-in factor and deduction convention (Manual inputs rows 75-82, selector E76 = FULL).
A39: v0.12 | B39: 2026-10-02 | C39: T2 merge: Stream 2 (branch v0.7 -> Stream2_v1/v2/v3) integrated into the mainline v0.11 by re-applying the branch steps (build_v0_12.py imports build_stream2_v1/v2/v3). Task F: new sheets Data_EF, Emissions_Industry (eco2 = ener x EF), MTInputs EmissionsFactCO2 / EFsAdjustmentNonAnnexI green; check (d) now conditions on the explicit price o2 + o3 (branch used o1, a cascade to the year row). Task I: new sheet Rebate_Industry (Fund-independent output-based rebate per t = MIN(obrrb x EU benchmark, carbon cost per t), sector rebate share, net prices atpn); kernel ener usage term reads atpn (1368 cells, asserted); ppin memo since Task H (v0.10) already deducts obrrb in the output response (basis covered EF; Task I basis EU benchmark -> CAVEATS). Task J: new sheet Fund_Industry (F = phi x pre-fund revenue rev0, shadow price s by 15 Newton rows, RATE|COST rule); process abatement rebuilt for the v0.9 per-category ERmax form (wm = Q x cov x EF x ERmax, wp = wm x e^-beta P, 16 rows np/no); block o5 = F, '+o4' inside the process price term of o118-o125 (np and no) and o15/o16 (440 block cells, asserted against v0.11); Data_Prices shp.<fuel>.ind.2 = s x pass-through, ssc.<sector>.2 = ssc_fund (260 cells); Scenarios fundsp row 49 = s. Check sections F (row 1520), I (row 1552), J (row 1667) store the pre-step values per bundle computed inside this build. Regression vs v0.11: all Check summaries 0 for every bundle; Mitigation_Industry identical to v0.11 for LEGACY, 1A, 2A, 2B, 3A (max |diff| 0); changed by design: 3B 873; 3C 1.9e+03. Sheets list above not extended (keeps row 25 fixed).
A40: v0.13 | B40: 2026-10-02 | C40: Task G: new sheet IPPU_Industry. CPAT IPPU baseline by gas and industrial energy CO2 stored (CPAT Mitigation rows 7566-7570, 6590); CPAT-method IPPU (all IPPU x industrial energy CO2 growth, kernel change only) vs kernel IPPU = block process np+no (o145) + fp counted as IPPU (ammonia feedstock flag) + non-block remainder (CPAT baseline - block baseline; IppuOther NONE holds it, CPAT scales it). Double-count correction row iprdc. Reconciliation of block fuel CO2 with Task F sector energy CO2 by sector (report only). Manual inputs rows 84-95 (switch E85, fp flags E88:E95). Check section row 1831. 2030, bundle 3A scenario 2: CPAT-method IPPU 85.3, kernel IPPU 84.7 MtCO2e (block 34.0, non-block 50.7), correction -0.52. Regression vs v0.12: all prior sheets identical for every bundle (max |diff| 0); new rows only.
A41: v0.14 | B41: 2026-10-02 | C41: Task M: new sheets CPAT_National (CPAT national outputs of runs EG1-EG4 from the TASK-2b csv, stored) and Table2_Industry (bundle -> run mapping; CPAT series of the mapped run; kernel series; Table 2 columns J K L M N O P Q R T U AR per year; live summary row + stored 2030 snapshot of all bundles vs rebuild v0.1 K). Composition in deltas: K = dGHG CPAT + IPPU replacement (Task G kernel IPPU) + industry energy replacement (kernel sectors + non-kernel industry scaled with the run for All sectors). P = gross (CPAT receipts adjusted / kernel sectors) + process revenue - rebates - fund. Q = CPAT deaths x dEnergy CO2 ratio. Check section row 1861. 2030 K: 1A -27.7, 2A -25.7, 2B -27.0, 3A -9.7, 3B -6.6, 3C -17.3. Regression vs v0.13: all prior sheets identical for every bundle (max |diff| 0); new sheets only.
A42: v0.15 | B42: 2026-10-02 | C42: T5: S1 emission factors H30:K37 = Egypt CBAM EF v0.1 (EGY_CBAM_EF_v0.1.xlsx; urea np 0 CBAM rule, M35 1.1256; AN no 0.9944 integrated HNO3 N2O, M36 0.8462); S:V memo restated. T1: Task D semi-elasticities applied (E50 IPCC; rows 53-60 ER at $100 = IPCC AR6 central, USD2019: DRI 0.3433, scrap 0.1810, BF 0.2803, clinker 0.3352, AN no 0.6179 (50 % abatement blend), Al 0.2164 np+no, ammonia/urea 0). Fuel ER (rows 40-47) and fund unchanged. Table 2 snapshot refilled; rebuild column = AdHoc rebuild v0.2. Check row 1881. 2030 K: 1A -29.8 (v0.14 -27.7), 2A -25.8 (v0.14 -25.7), 2B -27.1 (v0.14 -27.0), 3A -11.8 (v0.14 -9.7), 3B -8.6 (v0.14 -6.6), 3C -23.9 (v0.14 -17.3).
... A44: v0.17 | B44: 2026-10-02 | C44: Final Table 2: sheet CarveOut_Table2 = CBAM carve-out v0.3 in live formulas (active bundle) + stored 6-bundle snapshot; O on FULL, NOPHASE memo. No other formulas changed. Check row 1919. 2030 K: 1A -37.4, 2A -33.1, 2B -34.8, 3A -22.8, 3B -19.1, 3C -33.0.

Sheet Manual inputs
B1: CPAT Manual inputs
B2: Replicates the legacy 'Manual inputs' tab at the same row/column positions. Only the Process Emissions section (rows 18-47, used by the CBAM block) is ported; other rows are left blank so legacy references port 1:1.
B3: Change only green cells. Row 22 feeds MTInputs F117:F121 (as in legacy).
A18: . | B18: Process Emissions
B19: Non-Fuel Process Emissions Coverage (CBAM goods only) for ETS and Carbon Tax
H20: mining & chemicals | I20: iron and steel | J20: non-ferrous metals | K20: machinery | L20: cement
D21: Include non-fuel process emissions in ETS/CT? (legacy Dashboard!G20; v0.4: set by the active bundle, Scenarios) | E21: =Scenarios!$G$27=1 -> FALSE | H21: TRUE | I21: TRUE | J21: TRUE | L21: TRUE
H22: =AND($E$21,'Manual inputs'!H21) -> FALSE | I22: =AND($E$21,'Manual inputs'!I21) -> FALSE | J22: =AND($E$21,'Manual inputs'!J21) -> FALSE | K22: FALSE | L22: =AND($E$21,'Manual inputs'!L21) -> FALSE
S27: S:V memo (v0.15): implied GJ/t = S1 EF x 1000 / tCO2 per TJ (not read by formulas).
B28: Emission Factors | H28: SCOPE 1 (tCO₂e/t, NH₃ integrated) | O28: SCOPE 2 + TOTALS | S28: EF INPUTS | W28: LATEST MAY 2026 EU DEFAULTS + BENCHMARKS | AD28: CONFIDENCE
D29: Product | E29: Unit | F29: CN codes | G29: Route | H29: S1.fc | I29: S1.fp | J29: S1.np | K29: S1.no | L29: S1 own | M29: Embed NH₃ | N29: S1 incl NH₃ | O29: S2 | P29: S2 in CBAM scope? | Q29: S1+S2 total | R29: CBAM- equiv | S29: fc GJ/t | T29: fc EF | U29: fp GJ/t | V29: fp EF | W29: EU def base | X29: mark up | Y29: EU def 2026 | Z29: EU bench | AA29: Gap vs def | AB29: Gap vs bench | AC29: Latest EU regulatory note (May 2026) | AD29: S1.fc / S1.fp confidence | AE29: S1.np / S1.no confidence
D30: DRI-EAF steel | E30: t crude steel | F30: 7207 10 (D); 7207 12 (D); 7208/7209 flat (partial); 7214 rebar | G30: Midrex NG shaft furnace + EAF | H30: 0.17797725 | I30: 0.39301352 | J30: 0.03790102 | K30: 0 | L30: =SUM(H30:K30) -> 0.60889179 | M30: 0 | N30: =L30+M30 -> 0.60889179 | O30: 0.25 | P30: 0 | Q30: =N30+O30 -> 0.85889179 | R30: =N30+O30*P30 -> 0.60889179 | S30: 3.172 | T30: 56.1 | U30: 7.006 | V30: 56.1 | W30: 1.82 | X30: 0.1 | Y30: =W30*(1+X30) -> 2.002 | Z30: 0.481 | AA30: =R30-Y30 -> -1.3931082 | AB30: =R30-Z30 -> 0.12789179 | AC30: DRI-EAF. Default base 1.820 ×1.10 markup = 2.002 (2026). Benchmark 0.481 (final IR 2025/2620). CAUTION: CBAM default matrix for HRC CN 7208 may assign only BF-BOF route (4.454) — 'DRI default vacancy' risk for flat products. | AD30: v0.15 EF: Egypt CBAM EF v0.1 (egypt+mitigation/EmissionFactors/EGY_CBAM_EF_v0.1.xlsx Products; EGY_CBAM_EF_Methodology_v0.1.md). Prior: S1.fc: Est: Midrex heat:reductant ratio 5:24 GJ/t NG. Total EF Auth (WSA 2023 / S1.fp: Est: Midrex standard ratio; IPCC 2006 Vol2 2C1; WSA 2023. Total Auth; | AE30: v0.15 EF: Egypt CBAM EF v0.1 (egypt+mitigation/EmissionFactors/EGY_CBAM_EF_v0.1.xlsx Products; EGY_CBAM_EF_Methodology_v0.1.md). Prior: S1.np: Auth: IPCC 2006 2C1 — DRI process CO2 = 0 / S1.no: Auth: IPCC 2006 2C1
D31: Scrap-EAF steel | E31: t crude steel | F31: 7206 10; 7207 10 (E); 7214 rebar; 7208 HRC (E-route); 7216 sections | G31: Scrap-EAF | H31: 0.04488 | I31: 0 | J31: 0.04398115 | K31: 0 | L31: =SUM(H31:K31) -> 0.08886115 | M31: 0 | N31: =L31+M31 -> 0.08886115 | O31: 0.25 | P31: 0 | Q31: =N31+O31 -> 0.33886115 | R31: =N31+O31*P31 -> 0.08886115 | S31: 0.8 | T31: 56.1 | U31: 0 | V31: 0 | W31: 0.72 | X31: 0.1 | Y31: =W31*(1+X31) -> 0.792 | Z31: 0.072 | AA31: =R31-Y31 -> -0.70313885 | AB31: =R31-Z31 -> 0.01686115 | AC31: Scrap-EAF. Default base 0.720 ×1.10 = 0.792 (2026). Benchmark 0.072 (final, scrap route). | AD31: v0.15 EF: Egypt CBAM EF v0.1 (egypt+mitigation/EmissionFactors/EGY_CBAM_EF_v0.1.xlsx Products; EGY_CBAM_EF_Methodology_v0.1.md). Prior: S1.fc: Est: IEA Egypt sector average; WSA 2023 scrap-EAF range 2-3 GJ/t. Tota / S1.fp: Auth: no reductant in scrap melting process | AE31: v0.15 EF: Egypt CBAM EF v0.1 (egypt+mitigation/EmissionFactors/EGY_CBAM_EF_v0.1.xlsx Products; EGY_CBAM_EF_Methodology_v0.1.md). Prior: S1.np: Est: IPCC 2006 Vol2 2C1 default 0.01-0.02 tCO2/t for scrap-EAF / S1.no: Auth: IPCC 2006 2C1
D32: BF-BOF steel (reference) | E32: t crude steel | F32: 7206 10 (C); 7207 10 (C); 7209 CR (C-route); 7208 HRC (C-route) | G32: BF-BOF coal/coke | H32: 0.1683 | I32: 1.2566803 | J32: 0.05276542 | K32: 0 | L32: =SUM(H32:K32) -> 1.4777457 | M32: 0 | N32: =L32+M32 -> 1.4777457 | O32: 0.1875 | P32: 0 | Q32: =N32+O32 -> 1.6652457 | R32: =N32+O32*P32 -> 1.4777457 | S32: 1.751 | T32: 96.1 | U32: 13.077 | V32: 96.1 | W32: 2.8 | X32: 0.1 | Y32: =W32*(1+X32) -> 3.08 | Z32: 1.37 | AA32: =R32-Y32 -> -1.6022543 | AB32: =R32-Z32 -> 0.10774569 | AC32: BF-BOF reference. Default base 2.800 ×1.10 = 3.080 (2026). Benchmark 1.370 (final IR 2025/2620). | AD32: v0.15 EF: Egypt CBAM EF v0.1 (egypt+mitigation/EmissionFactors/EGY_CBAM_EF_v0.1.xlsx Products; EGY_CBAM_EF_Methodology_v0.1.md). Prior: S1.fc: Prox: WSA 2023 global BF-BOF average. No Egypt-specific data (no produ / S1.fp: Prox: WSA 2023 BF standard; IPCC 2006 Vol2 2C1. Split Est within proxy | AE32: v0.15 EF: Egypt CBAM EF v0.1 (egypt+mitigation/EmissionFactors/EGY_CBAM_EF_v0.1.xlsx Products; EGY_CBAM_EF_Methodology_v0.1.md). Prior: S1.np: Auth: IPCC 2006 Vol2 2C1 default 0.22-0.28 tCO2/t crude steel / S1.no: Auth: IPCC 2006 2C1
D33: Grey clinker (dry-process) | E33: t clinker | F33: 2523 10 (clinker); 2523 21; 2523 29 Portland cement | G33: Dry rotary kiln | H33: 0.3135685 | I33: 0 | J33: 0.53702616 | K33: 0 | L33: =SUM(H33:K33) -> 0.85059466 | M33: 0 | N33: =L33+M33 -> 0.85059466 | O33: 0.05625 | P33: 1 | Q33: =N33+O33 -> 0.90684466 | R33: =N33+O33*P33 -> 0.90684466 | S33: 3.263 | T33: 96.1 | U33: 0 | V33: 0 | W33: 1.58 | X33: 0.1 | Y33: =W33*(1+X33) -> 1.738 | Z33: 0.666 | AA33: =R33-Y33 -> -0.83115534 | AB33: =R33-Z33 -> 0.24084466 | AC33: Cement clinker. Default base 1.580 ×1.10 = 1.738 (2026). Benchmark 0.666 (col B). S2 IN CBAM scope. | AD33: v0.15 EF: Egypt CBAM EF v0.1 (egypt+mitigation/EmissionFactors/EGY_CBAM_EF_v0.1.xlsx Products; EGY_CBAM_EF_Methodology_v0.1.md). Prior: S1.fc: Est: IEA Egypt cement sector; CSI/GCCA GNR Egypt 2022. Total AukCoa / S1.fp: Auth: cement production has no chemical reductant fuel | AE33: v0.15 EF: Egypt CBAM EF v0.1 (egypt+mitigation/EmissionFactors/EGY_CBAM_EF_v0.1.xlsx Products; EGY_CBAM_EF_Methodology_v0.1.md). Prior: S1.np: Auth: IPCC 2006 2A1 stoichiometric constant (44/100 × fraction CaCO3 i / S1.no: Auth
D34: Ammonia (net merchant) | E34: t NH3 | F34: 2814 10 (anhydrous ammonia) | G34: Steam methane reforming (SMR) + Haber-Bosch synthesis | H34: 0.71247 | I34: 1.26225 | J34: 0 | K34: 0 | L34: =SUM(H34:K34) -> 1.97472 | M34: 0 | N34: =L34+M34 -> 1.97472 | O34: 0.0375 | P34: 1 | Q34: =N34+O34 -> 2.01222 | R34: =N34+O34*P34 -> 2.01222 | S34: 12.7 | T34: 56.1 | U34: 22.5 | V34: 56.1 | W34: 2.05 | X34: 0.01 | Y34: =W34*(1+X34) -> 2.0705 | Z34: 1.484 | AA34: =R34-Y34 -> -0.05828 | AB34: =R34-Z34 -> 0.52822 | AC34: Egypt ammonia 2026 default = 2.07 tCO2e/t (incl 1% fertiliser markup; Argus 17 Dec 2025). Benchmark 1.522 → 1.484 after 2.5% reduction in 2026. S2 IN CBAM scope. | AD34: v0.15 EF: Egypt CBAM EF v0.1 (egypt+mitigation/EmissionFactors/EGY_CBAM_EF_v0.1.xlsx Products; EGY_CBAM_EF_Methodology_v0.1.md). Prior: S1.fc: Est: IFA/EFMA BAT Vol.1; combustion ~6-8 GJ/t NH3. Total Auth (IFA sta / S1.fp: Est: IFA/EFMA BAT Vol.1 standard SMR ~24-28 GJ/t NH3. Total Auth; comb | AE34: v0.15 EF: Egypt CBAM EF v0.1 (egypt+mitigation/EmissionFactors/EGY_CBAM_EF_v0.1.xlsx Products; EGY_CBAM_EF_Methodology_v0.1.md). Prior: S1.np: Auth: NH3 synthesis has no carbon process emissions / S1.no: Auth
D35: Urea | E35: t urea | F35: 3102 10 (urea >= 45% N) | G35: Urea synthesis from captured CO2 + NH3 feedstock | H35: 0.1122 | I35: 0 | J35: 0 | K35: 0 | L35: =SUM(H35:K35) -> 0.1122 | M35: 1.1255904 | N35: =L35+M35 -> 1.2377904 | O35: 0.0375 | P35: 1 | Q35: =N35+O35 -> 1.2752904 | R35: =N35+O35*P35 -> 1.2752904 | S35: 2 | T35: 56.1 | U35: 0 | V35: 0 | W35: 1.39 | X35: 0.01 | Y35: =W35*(1+X35) -> 1.4039 | Z35: 0.902 | AA35: =R35-Y35 -> -0.1286096 | AB35: =R35-Z35 -> 0.3732904 | AC35: NH₃ INTEGRATED in headline. Egypt urea 2026 default = 1.404 tCO2e/t (incl 1% markup; Sandbag Feb 2026). Benchmark col B 0.902 (col A 0.053 for actual-data pathway). SEFA chain uses ammonia benchmark 1.522. S2 IN CBAM scope. | AD35: v0.15 EF: Egypt CBAM EF v0.1 (egypt+mitigation/EmissionFactors/EGY_CBAM_EF_v0.1.xlsx Products; EGY_CBAM_EF_Methodology_v0.1.md). Urea np = 0 (CBAM rule: urea-bound CO2 not deducted; prototype -0.733). Prior: S1.fc: Est: IFA/EFMA; small relative to NH3 chain. ~1.5-2.5 GJ/t urea typical / S1.fp: Auth: no additional reductant/feedstock in urea synthesis itself | AE35: v0.15 EF: Egypt CBAM EF v0.1 (egypt+mitigation/EmissionFactors/EGY_CBAM_EF_v0.1.xlsx Products; EGY_CBAM_EF_Methodology_v0.1.md). Urea np = 0 (CBAM rule: urea-bound CO2 not deducted; prototype -0.733). Prior: S1.np: Auth: IPCC 2006 Vol2 3G stoichiometric constant. 44/60 = 0.733 tCO2 ab / S1.no: Auth
D36: Ammonium nitrate | E36: t AN | F36: 3102 30 (AN >= 28% N); 3102 40 (CAN) | G36: Ostwald process (NH3 → HNO3) + neutralisation (HNO3 + NH3 → NH4NO3) | H36: 0.1122 | I36: 0 | J36: 0 | K36: 0.9944125 | L36: =SUM(H36:K36) -> 1.1066125 | M36: 0.8462122 | N36: =L36+M36 -> 1.9528247 | O36: 0.04375 | P36: 1 | Q36: =N36+O36 -> 1.9965747 | R36: =N36+O36*P36 -> 1.9965747 | S36: 2 | T36: 56.1 | U36: 0 | V36: 0 | W36: 2.64 | X36: 0.01 | Y36: =W36*(1+X36) -> 2.6664 | Z36: 0.302 | AA36: =R36-Y36 -> -0.6698253 | AB36: =R36-Z36 -> 1.6945747 | AC36: NH₃ INTEGRATED in headline. AN/CAN. Default base ~2.64 ×1.01 = 2.666 (2026, N2O-driven). Benchmark 0.302. S2 IN CBAM scope. Default value highly sensitive to assumed N2O abatement. | AD36: v0.15 EF: Egypt CBAM EF v0.1 (egypt+mitigation/EmissionFactors/EGY_CBAM_EF_v0.1.xlsx Products; EGY_CBAM_EF_Methodology_v0.1.md). AN no = integrated HNO3 N2O 0.79 x 1.2588 (kernel convention; EF workbook books it as precursor); 50 % N2O abatement assumed (VERIFY). Prior: S1.fc: Est: IFA/EFMA BAT Vol.3; 1.5-2.5 GJ/t AN typical. Total direct EF less / S1.fp: Auth: HNO3 and neutralisation have no reductant | AE36: v0.15 EF: Egypt CBAM EF v0.1 (egypt+mitigation/EmissionFactors/EGY_CBAM_EF_v0.1.xlsx Products; EGY_CBAM_EF_Methodology_v0.1.md). AN no = integrated HNO3 N2O 0.79 x 1.2588 (kernel convention; EF workbook books it as precursor); 50 % N2O abatement assumed (VERIFY). Prior: S1.np: Auth: AN chemistry (NH4NO3) contains no carbon / S1.no: Est: IPCC 2006 2B2; GWP AR6 AII.1.2. CRITICAL: range 0.21 (with high-e
D37: Primary aluminium | E37: t Al | F37: 7601 10 (unwrought primary); 7601 20 (alloys, semi-finished); 7604 (bars/rods); 7606 (sheet/plate) | G37: Hall-Héroult electrolysis + carbon anode prebaking | H37: 0.12342 | I37: 0 | J37: 1.623493 | K37: 0.774 | L37: =SUM(H37:K37) -> 2.520913 | M37: 0 | N37: =L37+M37 -> 2.520913 | O37: 6.75 | P37: 0 | Q37: =N37+O37 -> 9.270913 | R37: =N37+O37*P37 -> 2.520913 | S37: 1.582 | T37: 78 | U37: 0 | V37: 0 | W37: 2.06 | X37: 0.1 | Y37: =W37*(1+X37) -> 2.266 | Z37: 1.423 | AA37: =R37-Y37 -> 0.25491304 | AB37: =R37-Z37 -> 1.097913 | AC37: Primary aluminium. Default base 2.060 ×1.10 = 2.266 (2026). Benchmark 1.423. S2 NOT in CBAM scope (direct emissions only). | AD37: v0.15 EF: Egypt CBAM EF v0.1 (egypt+mitigation/EmissionFactors/EGY_CBAM_EF_v0.1.xlsx Products; EGY_CBAM_EF_Methodology_v0.1.md). Prior: S1.fc: Est: IAI 2023 smelter profile; 1.5-2.5 GJ/t range. Weighted EF 78 kgCO / S1.fp: Auth: Hall-Héroult is electrolytic; reduction is electrical not fuel-d | AE37: v0.15 EF: Egypt CBAM EF v0.1 (egypt+mitigation/EmissionFactors/EGY_CBAM_EF_v0.1.xlsx Products; EGY_CBAM_EF_Methodology_v0.1.md). Prior: S1.np: Auth: IPCC 2006 Vol2 2C3 default 1.5 tCO2/t Al for prebaked anodes. Ra / S1.no: Est: IAI 2023 Egypt country profile. Global prebaked average 0.38 tCO2
B38: Legacy ad hoc semi-elasticities (AdHocCalculations; one beta for np + no; no documented source). Used only when E50 = ADHOC, and by the fund placeholder (block o107-o114)
D39: Process | E39: Half Elasticity | F39: ER at $100 (%)
D40: DRI-EAF steel | E40: 0.0010536052 | F40: 0.1
D41: Scrap-EAF steel | E41: 0.00020202707 | F41: 0.02
D42: BF-BOF steel reference | E42: 0.00051293294 | F42: 0.05
D43: Grey clinker dry-process | E43: 0.00083381609 | F43: 0.08
D44: Ammonia net | E44: 0.0019845094 | F44: 0.18
D45: Urea | E45: 0 | F45: 0
D46: AN | E46: 0.010498221 | F46: 0.65
D47: Primary aluminium | E47: 0.00083381609 | F47: 0.08
B49: Process-emission semi-elasticities (Task D, v0.9): inferred from IPCC; used by CBAM block rows o118-o125
D50: Semi-elasticity set used by the block (IPCC / ADHOC) | E50: IPCC | F50: ADHOC = rows 40-47 with ERmax = 1 (reproduces v0.8)
D51: ER(P) = ERmax x (1 - exp(-beta x P)); beta = -ln(1 - ER*/ERmax)/P* from the anchor (P*, ER*); semi-elasticity at P = 0 = ERmax x beta. np = non-fuel process CO2, no = non-CO2 process (Manual inputs J, K). ERmax = technical potential by ~2035 with commercial technology; CCS and process change are excluded (no Egyptian CO2 storage or H2-DRI before 2035).
D52: Product | E52: np ERmax | F52: np anchor P* ($/t) | G52: np ER at P* | H52: np beta (1/$) | I52: no ERmax | J52: no anchor P* ($/t) | K52: no ER at P* | L52: no beta (1/$) | M52: np semi-el. at P=0 (%/$) | N52: no semi-el. at P=0 (%/$) | O52: np ER at $20 | P52: no ER at $20 | Q52: np lever and source | R52: no lever and source | S52: Confidence | T52: beta.np used | U52: ERmax.np used | V52: beta.no used | W52: ERmax.no used
D53: DRI-EAF steel | E53: 1 | F53: 122 | G53: 0.3433 | H53: =IF(OR(E53=0,G53=0),0,-LN(1-G53/E53)/F53) -> 0.0034469507 | I53: 0 | J53: 122 | K53: 0 | L53: =IF(OR(I53=0,K53=0),0,-LN(1-K53/I53)/J53) -> 0 | M53: =E53*H53 -> 0.0034469507 | N53: =I53*L53 -> 0 | O53: =E53*(1-EXP(-H53*20)) -> 0.066616398 | P53: =I53*(1-EXP(-L53*20)) -> 0 | Q53: IPCC AR6 WGIII Table 11.3/12.3 cost-bucket MACC, central (mean 2030 & long-run), USD2019; ER at $100 (Option A: ERmax 1, P* 122 = USD2019 100 deflated to USD2024, US GDP deflator ~1.22; v0.16). Derivation: egypt+mitigation/ProcessEmissions_CarbonPrice_Response; spec TASK-D v0.2. Lever: H2/NG-DRI, scrap share, CCS on shaft | R53: n/a (no ERmax 0) | S53: Medium | T53: =IF($E$50="ADHOC",$E$40,H53) -> 0.0034469507 | U53: =IF($E$50="ADHOC",1,E53) -> 1 | V53: =IF($E$50="ADHOC",$E$40,L53) -> 0 | W53: =IF($E$50="ADHOC",1,I53) -> 0
D54: Scrap-EAF steel | E54: 1 | F54: 122 | G54: 0.181 | H54: =IF(OR(E54=0,G54=0),0,-LN(1-G54/E54)/F54) -> 0.0016366491 | I54: 0 | J54: 122 | K54: 0 | L54: =IF(OR(I54=0,K54=0),0,-LN(1-K54/I54)/J54) -> 0 | M54: =E54*H54 -> 0.0016366491 | N54: =I54*L54 -> 0 | O54: =E54*(1-EXP(-H54*20)) -> 0.032203056 | P54: =I54*(1-EXP(-L54*20)) -> 0 | Q54: IPCC AR6 WGIII Table 11.3/12.3 cost-bucket MACC, central (mean 2030 & long-run), USD2019; ER at $100 (Option A: ERmax 1, P* 122 = USD2019 100 deflated to USD2024, US GDP deflator ~1.22; v0.16). Derivation: egypt+mitigation/ProcessEmissions_CarbonPrice_Response; spec TASK-D v0.2. Lever: electrode / carbon-input efficiency | R54: n/a (no ERmax 0) | S54: Low | T54: =IF($E$50="ADHOC",$E$41,H54) -> 0.0016366491 | U54: =IF($E$50="ADHOC",1,E54) -> 1 | V54: =IF($E$50="ADHOC",$E$41,L54) -> 0 | W54: =IF($E$50="ADHOC",1,I54) -> 0
D55: BF-BOF steel (reference) | E55: 1 | F55: 122 | G55: 0.2803 | H55: =IF(OR(E55=0,G55=0),0,-LN(1-G55/E55)/F55) -> 0.0026960723 | I55: 0 | J55: 122 | K55: 0 | L55: =IF(OR(I55=0,K55=0),0,-LN(1-K55/I55)/J55) -> 0 | M55: =E55*H55 -> 0.0026960723 | N55: =I55*L55 -> 0 | O55: =E55*(1-EXP(-H55*20)) -> 0.052493466 | P55: =I55*(1-EXP(-L55*20)) -> 0 | Q55: IPCC AR6 WGIII Table 11.3/12.3 cost-bucket MACC, central (mean 2030 & long-run), USD2019; ER at $100 (Option A: ERmax 1, P* 122 = USD2019 100 deflated to USD2024, US GDP deflator ~1.22; v0.16). Derivation: egypt+mitigation/ProcessEmissions_CarbonPrice_Response; spec TASK-D v0.2. Lever: top-gas recycling, DRI substitution, CCS | R55: n/a (no ERmax 0) | S55: Medium | T55: =IF($E$50="ADHOC",$E$42,H55) -> 0.0026960723 | U55: =IF($E$50="ADHOC",1,E55) -> 1 | V55: =IF($E$50="ADHOC",$E$42,L55) -> 0 | W55: =IF($E$50="ADHOC",1,I55) -> 0
D56: Grey clinker (dry-process) | E56: 1 | F56: 122 | G56: 0.3352 | H56: =IF(OR(E56=0,G56=0),0,-LN(1-G56/E56)/F56) -> 0.0033464675 | I56: 0 | J56: 122 | K56: 0 | L56: =IF(OR(I56=0,K56=0),0,-LN(1-K56/I56)/J56) -> 0 | M56: =E56*H56 -> 0.0033464675 | N56: =I56*L56 -> 0 | O56: =E56*(1-EXP(-H56*20)) -> 0.064738725 | P56: =I56*(1-EXP(-L56*20)) -> 0 | Q56: IPCC AR6 WGIII Table 11.3/12.3 cost-bucket MACC, central (mean 2030 & long-run), USD2019; ER at $100 (Option A: ERmax 1, P* 122 = USD2019 100 deflated to USD2024, US GDP deflator ~1.22; v0.16). Derivation: egypt+mitigation/ProcessEmissions_CarbonPrice_Response; spec TASK-D v0.2. Lever: clinker substitution (SCMs, LC3), CCS | R56: n/a (no ERmax 0) | S56: Medium | T56: =IF($E$50="ADHOC",$E$43,H56) -> 0.0033464675 | U56: =IF($E$50="ADHOC",1,E56) -> 1 | V56: =IF($E$50="ADHOC",$E$43,L56) -> 0 | W56: =IF($E$50="ADHOC",1,I56) -> 0
D57: Ammonia (net merchant) | E57: 0 | F57: 122 | G57: 0 | H57: =IF(OR(E57=0,G57=0),0,-LN(1-G57/E57)/F57) -> 0 | I57: 0 | J57: 122 | K57: 0 | L57: =IF(OR(I57=0,K57=0),0,-LN(1-K57/I57)/J57) -> 0 | M57: =E57*H57 -> 0 | N57: =I57*L57 -> 0 | O57: =E57*(1-EXP(-H57*20)) -> 0 | P57: =I57*(1-EXP(-L57*20)) -> 0 | Q57: n/a (np ERmax 0): none: np = 0 (SMR feedstock CO2 is fp; CCS / blue lever not routed to fp - caveat) | R57: n/a (no ERmax 0) | S57: Low | T57: =IF($E$50="ADHOC",$E$44,H57) -> 0 | U57: =IF($E$50="ADHOC",1,E57) -> 0 | V57: =IF($E$50="ADHOC",$E$44,L57) -> 0 | W57: =IF($E$50="ADHOC",1,I57) -> 0
D58: Urea | E58: 0 | F58: 122 | G58: 0 | H58: =IF(OR(E58=0,G58=0),0,-LN(1-G58/E58)/F58) -> 0 | I58: 0 | J58: 122 | K58: 0 | L58: =IF(OR(I58=0,K58=0),0,-LN(1-K58/I58)/J58) -> 0 | M58: =E58*H58 -> 0 | N58: =I58*L58 -> 0 | O58: =E58*(1-EXP(-H58*20)) -> 0 | P58: =I58*(1-EXP(-L58*20)) -> 0 | Q58: n/a (np ERmax 0): none: inherits ammonia (np = 0 under CBAM rule) | R58: n/a (no ERmax 0) | S58: Low | T58: =IF($E$50="ADHOC",$E$45,H58) -> 0 | U58: =IF($E$50="ADHOC",1,E58) -> 0 | V58: =IF($E$50="ADHOC",$E$45,L58) -> 0 | W58: =IF($E$50="ADHOC",1,I58) -> 0
D59: Ammonium nitrate | E59: 0 | F59: 122 | G59: 0 | H59: =IF(OR(E59=0,G59=0),0,-LN(1-G59/E59)/F59) -> 0 | I59: 1 | J59: 122 | K59: 0.6179 | L59: =IF(OR(I59=0,K59=0),0,-LN(1-K59/I59)/J59) -> 0.0078858436 | M59: =E59*H59 -> 0 | N59: =I59*L59 -> 0.0078858436 | O59: =E59*(1-EXP(-H59*20)) -> 0 | P59: =I59*(1-EXP(-L59*20)) -> 0.14590844 | Q59: n/a (np ERmax 0): - | R59: IPCC AR6 WGIII Table 11.3/12.3 cost-bucket MACC, central (mean 2030 & long-run), USD2019; ER at $100 (Option A: ERmax 1, P* 122 = USD2019 100 deflated to USD2024, US GDP deflator ~1.22; v0.16). Derivation: egypt+mitigation/ProcessEmissions_CarbonPrice_Response; spec TASK-D v0.2. Lever: tertiary N2O abatement in HNO3 (blend: unabated 0.7210 / abated 0.3292 at 50 % abated share, N2O-weighted) | S59: Medium | T59: =IF($E$50="ADHOC",$E$46,H59) -> 0 | U59: =IF($E$50="ADHOC",1,E59) -> 0 | V59: =IF($E$50="ADHOC",$E$46,L59) -> 0.0078858436 | W59: =IF($E$50="ADHOC",1,I59) -> 1
...

Sheet Scenarios
B1: Scenarios (EGY): carbon price paths, policy bundles, active-bundle series
B2: Policy scenario 2 runs the bundle selected in Settings!B10 (one at a time). Section 4 is mirrored into Data_Prices by code. LEGACY reproduces v0.3 / CPAT default values exactly.
B3: Change only green cells. Bundles from EgyptResultsInitial.docx Table 1/2.
A5: 1 | B5: Carbon price paths ($/ton CO2 real)
B6: Path | C6: Description | D6: Source | I6: Unit | J6: Scenario | K6: 2021 | L6: 2022 | M6: 2023 | N6: 2024 | O6: 2025 | P6: 2026 | Q6: 2027 | R6: 2028 | S6: 2029 | T6: 2030 | U6: 2031 | V6: 2032 | W6: 2033 | X6: 2034 | Y6: 2035 | Z6: 2036 | AA6: 2037 | AB6: 2038 | AC6: 2039 | AD6: 2040 | AE6: 2041 | AF6: 2042 | AG6: 2043 | AH6: 2044 | AI6: 2045
B7: LEGACY_CP | C7: CPAT default carbon tax path in the legacy file | D7: CPAT 1.0pre_456 Mitigation row 8582 (cptraj.2) | I7: $/ton CO2 real | J7: EGY | L7: 0 | M7: 0 | N7: 0 | O7: 0 | P7: 0 | Q7: 12.5 | R7: 25 | S7: 37.5 | T7: 50 | U7: 62.5 | V7: 75 | W7: 87.5 | X7: 100 | Y7: 112.5 | Z7: 125 | AA7: 137.5 | AB7: 150 | AC7: 162.5 | AD7: 175 | AE7: 187.5
B8: LEGACY_ETS | C8: CPAT default auctioned ETS path in the legacy file | D8: CPAT 1.0pre_456 Mitigation row 8583 (etstraj.2) | I8: $/ton CO2 real | J8: EGY | L8: 0 | M8: 0 | N8: 0 | O8: 0 | P8: 0 | Q8: 0 | R8: 0 | S8: 0 | T8: 0 | U8: 0 | V8: 0 | W8: 0 | X8: 0 | Y8: 0 | Z8: 0 | AA8: 0 | AB8: 0 | AC8: 0 | AD8: 0 | AE8: 0
B9: ZERO | C9: No price | D9: - | I9: $/ton CO2 real | J9: EGY | K9: 0 | L9: 0 | M9: 0 | N9: 0 | O9: 0 | P9: 0 | Q9: 0 | R9: 0 | S9: 0 | T9: 0 | U9: 0 | V9: 0 | W9: 0 | X9: 0 | Y9: 0 | Z9: 0 | AA9: 0 | AB9: 0 | AC9: 0 | AD9: 0 | AE9: 0 | AF9: 0 | AG9: 0 | AH9: 0 | AI9: 0
B10: FLAT20_2028 | C10: USD20/tCO2 flat from 2028 | D10: EgyptResultsInitial 1A/2A/2B; CPAT runs EG1/EG2 | I10: $/ton CO2 real | J10: EGY | K10: 0 | L10: 0 | M10: 0 | N10: 0 | O10: 0 | P10: 0 | Q10: 0 | R10: 20 | S10: 20 | T10: 20 | U10: 20 | V10: 20 | W10: 20 | X10: 20 | Y10: 20 | Z10: 20 | AA10: 20 | AB10: 20 | AC10: 20 | AD10: 20 | AE10: 20 | AF10: 20 | AG10: 20 | AH10: 20 | AI10: 20
B11: RAMP_EG3 | C11: USD5 in 2028, +7.5/yr (USD20 in 2030, USD50 in 2034, keeps rising) | D11: CPAT run EG3 (Outputs), behind the reported 3A-3C numbers | I11: $/ton CO2 real | J11: EGY | K11: 0 | L11: 0 | M11: 0 | N11: 0 | O11: 0 | P11: 0 | Q11: 0 | R11: 5 | S11: 12.5 | T11: 20 | U11: 27.5 | V11: 35 | W11: 42.5 | X11: 50 | Y11: 57.5 | Z11: 65 | AA11: 72.5 | AB11: 80 | AC11: 87.5 | AD11: 95 | AE11: 102.5 | AF11: 110 | AG11: 117.5 | AH11: 125 | AI11: 132.5
B12: RAMP50_2034 | C12: USD5 in 2028, +7.5/yr to USD50 in 2034, flat after | D12: EgyptResultsInitial text ('USD5 to USD50 by 2034') | I12: $/ton CO2 real | J12: EGY | K12: 0 | L12: 0 | M12: 0 | N12: 0 | O12: 0 | P12: 0 | Q12: 0 | R12: 5 | S12: 12.5 | T12: 20 | U12: 27.5 | V12: 35 | W12: 42.5 | X12: 50 | Y12: 50 | Z12: 50 | AA12: 50 | AB12: 50 | AC12: 50 | AD12: 50 | AE12: 50 | AF12: 50 | AG12: 50 | AH12: 50 | AI12: 50
B13: Kernel and Data_Prices use 2022-2041 (L..AE), the CPAT data horizon. Reported EgyptResultsInitial metrics refer to 2030, when every non-legacy bundle prices USD20/tCO2. RAMP_EG3 (3A-3C default) and RAMP50_2034 differ only after 2034.
A15: 2 | B15: Policy bundles (one row per bundle)
B16: Bundle | C16: Name | D16: Energy CO2 price path | E16: ETS path | F16: Industry energy covered (share) | G16: Process emissions covered (0/1) | H16: Process price path | I16: OBR share (theta) | J16: Fund share (phi) | K16: Revenue use | L16: Energy scope in main CPAT (Task M) | M16: fc covered (0/1) | N16: fp covered (0/1) | O16: np covered (0/1) | P16: no covered (0/1)
B17: LEGACY | C17: CPAT default policy scenario (regression) | D17: LEGACY_CP | E17: LEGACY_ETS | F17: 1 | G17: 0 | H17: LEGACY_CP | I17: 0 | J17: 0 | K17: CPAT default | L17: All sectors | M17: 1 | N17: 1 | O17: 1 | P17: 1
B18: 1A | C18: Comprehensive levy + CBAM process fee | D18: FLAT20_2028 | E18: ZERO | F18: 1 | G18: 1 | H18: FLAT20_2028 | I18: 0 | J18: 0 | K18: Public investment (non-green) | L18: All sectors | M18: 1 | N18: 1 | O18: 1 | P18: 1
B19: 2A | C19: Upstream levy, public investment | D19: FLAT20_2028 | E19: ZERO | F19: 1 | G19: 0 | H19: FLAT20_2028 | I19: 0 | J19: 0 | K19: Public investment (non-green) | L19: All sectors | M19: 1 | N19: 1 | O19: 1 | P19: 1
B20: 2B | C20: Upstream levy, households | D20: FLAT20_2028 | E20: ZERO | F20: 1 | G20: 0 | H20: FLAT20_2028 | I20: 0 | J20: 0 | K20: Households (per capita) | L20: All sectors | M20: 1 | N20: 1 | O20: 1 | P20: 1
B21: 3A | C21: Downstream heavy industry, households | D21: RAMP_EG3 | E21: ZERO | F21: 1 | G21: 1 | H21: RAMP_EG3 | I21: 0 | J21: 0 | K21: Households (per capita) | L21: Industry only | M21: 1 | N21: 1 | O21: 1 | P21: 1
B22: 3B | C22: Downstream heavy industry, free allocation (benchmark) | D22: RAMP_EG3 | E22: ZERO | F22: 1 | G22: 1 | H22: RAMP_EG3 | I22: 1 | J22: 0 | K22: Firms: output-based free allocation | L22: Industry only | M22: 1 | N22: 1 | O22: 1 | P22: 1
B23: 3C | C23: Downstream heavy industry, abatement rebate | D23: RAMP_EG3 | E23: ZERO | F23: 1 | G23: 1 | H23: RAMP_EG3 | I23: 0 | J23: 1 | K23: Firms: abatement rebate fund | L23: Industry only | M23: 1 | N23: 1 | O23: 1 | P23: 1
A25: 3 | B25: Active bundle (policy scenario 2) and carbon price pass-through factors
B26: Bundle | C26: Name | D26: Energy CO2 price path | E26: ETS path | F26: Industry energy covered (share) | G26: Process emissions covered (0/1) | H26: Process price path | I26: OBR share (theta) | J26: Fund share (phi) | K26: Revenue use | L26: Energy scope in main CPAT (Task M) | M26: fc covered (0/1) | N26: fp covered (0/1) | O26: np covered (0/1) | P26: no covered (0/1)
B27: =Settings!$B$10 -> LEGACY | C27: =INDEX(C$17:C$23,MATCH($B$27,$B$17:$B$23,0)) -> CPAT default policy scenario (regression) | D27: =INDEX(D$17:D$23,MATCH($B$27,$B$17:$B$23,0)) -> LEGACY_CP | E27: =INDEX(E$17:E$23,MATCH($B$27,$B$17:$B$23,0)) -> LEGACY_ETS | F27: =INDEX(F$17:F$23,MATCH($B$27,$B$17:$B$23,0)) -> 1 | G27: =INDEX(G$17:G$23,MATCH($B$27,$B$17:$B$23,0)) -> 0 | H27: =INDEX(H$17:H$23,MATCH($B$27,$B$17:$B$23,0)) -> LEGACY_CP | I27: =INDEX(I$17:I$23,MATCH($B$27,$B$17:$B$23,0)) -> 0 | J27: =INDEX(J$17:J$23,MATCH($B$27,$B$17:$B$23,0)) -> 0 | ... P27: =INDEX(P$17:P$23,MATCH($B$27,$B$17:$B$23,0)) -> 1
B29: Fuel | C29: Pass-through factor: price units per $/ton CO2 | E29: Factor | I29: Unit | J29: Source
B30: coa | C30: CO2 content per native unit (tCO2/unit) | E30: 0.1 | I30: $/GJ per $/tCO2 | J30: Implied by CPAT: legacy nce.2 / cptraj.2 (exactly proportional)
B31: nga | C31: CO2 content per native unit (tCO2/unit) | E31: 0.0558 | I31: $/GJ per $/tCO2 | J31: Implied by CPAT: legacy nce.2 / cptraj.2 (exactly proportional)
B32: gso | C32: CO2 content per native unit (tCO2/unit) | E32: 0.0023142275 | I32: $/liter per $/tCO2 | J32: Implied by CPAT: legacy nce.2 / cptraj.2 (exactly proportional)
B33: die | C33: CO2 content per native unit (tCO2/unit) | E33: 0.0026408351 | I33: $/liter per $/tCO2 | J33: Implied by CPAT: legacy nce.2 / cptraj.2 (exactly proportional)
B34: lpg | C34: CO2 content per native unit (tCO2/unit) | E34: 0.0017684866 | I34: $/liter per $/tCO2 | J34: Implied by CPAT: legacy nce.2 / cptraj.2 (exactly proportional)
B35: ker | C35: CO2 content per native unit (tCO2/unit) | E35: 0.0025591064 | I35: $/liter per $/tCO2 | J35: Implied by CPAT: legacy nce.2 / cptraj.2 (exactly proportional)
B36: oop | C36: CO2 content per native unit (tCO2/unit) | E36: 0.469404 | I36: $/bbl per $/tCO2 | J36: Implied by CPAT: legacy nce.2 / cptraj.2 (exactly proportional)
B37: bio | C37: CO2 content per native unit (tCO2/unit) | E37: 0 | I37: $/GJ per $/tCO2 | J37: Implied by CPAT: legacy nce.2 / cptraj.2 (exactly proportional)
B38: ren | C38: CO2 content per native unit (tCO2/unit) | E38: 0 | I38: $/kwh per $/tCO2 | J38: Implied by CPAT: legacy nce.2 / cptraj.2 (exactly proportional)
A40: 4 | B40: Active-bundle series for scenario 2 (read by Data_Prices via code in column G)
B41: Variable | C41: Description | D41: Written by | E41: Unit | F41: Source | G41: Input Code | H41: Read by | J41: Scenario | K41: 2021 | L41: 2022 | M41: 2023 | N41: 2024 | O41: 2025 | P41: 2026 | Q41: 2027 | R41: 2028 | S41: 2029 | T41: 2030 | U41: 2031 | V41: 2032 | W41: 2033 | X41: 2034 | Y41: 2035 | Z41: 2036 | AA41: 2037 | AB41: 2038 | AC41: 2039 | AD41: 2040 | AE41: 2041 | AF41: 2042 | AG41: 2043 | AH41: 2044 | AI41: 2045
B42: cptraj | C42: Carbon price on energy CO2 (active bundle) | D42: Stream 2 (E) | E42: $/ton CO2 real | F42: Scenarios | G42: egy.mit.cptraj.2 | H42: kernel via nce; CBAM block o2 (fuel CO2 only from v0.7) | J42: EGY | K42: =INDEX(K$7:K$12,MATCH($D$27,$B$7:$B$12,0)) -> 0 | L42: =INDEX(L$7:L$12,MATCH($D$27,$B$7:$B$12,0)) -> 0 | M42: =INDEX(M$7:M$12,MATCH($D$27,$B$7:$B$12,0)) -> 0 | N42: =INDEX(N$7:N$12,MATCH($D$27,$B$7:$B$12,0)) -> 0 | O42: =INDEX(O$7:O$12,MATCH($D$27,$B$7:$B$12,0)) -> 0 | P42: =INDEX(P$7:P$12,MATCH($D$27,$B$7:$B$12,0)) -> 0 | Q42: =INDEX(Q$7:Q$12,MATCH($D$27,$B$7:$B$12,0)) -> 12.5 | R42: =INDEX(R$7:R$12,MATCH($D$27,$B$7:$B$12,0)) -> 25 | ... AI42: =INDEX(AI$7:AI$12,MATCH($D$27,$B$7:$B$12,0)) -> 0
B43: etstraj | C43: Auctioned ETS price (active bundle) | D43: Stream 2 (E) | E43: $/ton CO2 real | F43: Scenarios | G43: egy.mit.etstraj.2 | H43: CBAM block o3 | J43: EGY | K43: =INDEX(K$7:K$12,MATCH($E$27,$B$7:$B$12,0)) -> 0 | L43: =INDEX(L$7:L$12,MATCH($E$27,$B$7:$B$12,0)) -> 0 | M43: =INDEX(M$7:M$12,MATCH($E$27,$B$7:$B$12,0)) -> 0 | N43: =INDEX(N$7:N$12,MATCH($E$27,$B$7:$B$12,0)) -> 0 | O43: =INDEX(O$7:O$12,MATCH($E$27,$B$7:$B$12,0)) -> 0 | P43: =INDEX(P$7:P$12,MATCH($E$27,$B$7:$B$12,0)) -> 0 | Q43: =INDEX(Q$7:Q$12,MATCH($E$27,$B$7:$B$12,0)) -> 0 | R43: =INDEX(R$7:R$12,MATCH($E$27,$B$7:$B$12,0)) -> 0 | ... AI43: =INDEX(AI$7:AI$12,MATCH($E$27,$B$7:$B$12,0)) -> 0
B44: pptraj | C44: Carbon price on CBAM process emissions = process path x process flag | D44: Stream 2 (E) | E44: $/ton CO2 real | F44: Scenarios | G44: egy.mit.pptraj.2 | H44: CBAM block o63 (Task C, process price); Stream 1 L: CBAM obligations | J44: EGY | K44: =INDEX(K$7:K$12,MATCH($H$27,$B$7:$B$12,0))*$G$27 -> 0 | L44: =INDEX(L$7:L$12,MATCH($H$27,$B$7:$B$12,0))*$G$27 -> 0 | M44: =INDEX(M$7:M$12,MATCH($H$27,$B$7:$B$12,0))*$G$27 -> 0 | N44: =INDEX(N$7:N$12,MATCH($H$27,$B$7:$B$12,0))*$G$27 -> 0 | O44: =INDEX(O$7:O$12,MATCH($H$27,$B$7:$B$12,0))*$G$27 -> 0 | P44: =INDEX(P$7:P$12,MATCH($H$27,$B$7:$B$12,0))*$G$27 -> 0 | Q44: =INDEX(Q$7:Q$12,MATCH($H$27,$B$7:$B$12,0))*$G$27 -> 0 | R44: =INDEX(R$7:R$12,MATCH($H$27,$B$7:$B$12,0))*$G$27 -> 0 | ... AI44: =INDEX(AI$7:AI$12,MATCH($H$27,$B$7:$B$12,0))*$G$27 -> 0
B45: encov | C45: Share of industry energy CO2 covered by the energy price | D45: Stream 2 (E) | E45: share | F45: Scenarios | G45: egy.mit.encov.2 | H45: nce (this sheet) | J45: EGY | K45: =$F$27 -> 1 | L45: =$F$27 -> 1 | M45: =$F$27 -> 1 | N45: =$F$27 -> 1 | O45: =$F$27 -> 1 | P45: =$F$27 -> 1 | Q45: =$F$27 -> 1 | R45: =$F$27 -> 1 | ... AI45: =$F$27 -> 1
...

Sheet Mitigation_Industry
B1: Fuel | C1: Sector | D1: Description | E1: Unit | F1: Source | G1: Input Code | H1: Output Code | I1: Note | J1: Helper | K1: 2021 | L1: 2022 | M1: 2023 | N1: 2024 | O1: 2025 | P1: 2026 | Q1: 2027 | R1: 2028 | S1: 2029 | T1: 2030 | U1: 2031 | V1: 2032 | W1: 2033 | X1: 2034 | Y1: 2035 | Z1: 2036 | AA1: 2037 | AB1: 2038 | AC1: 2039 | AD1: 2040 | AE1: 2041 | AF1: 2042 | AG1: 2043 | AH1: 2044 | AI1: 2045
B2: Mitigation Module - Egypt: Industry kernel
A3: 7 | B3: Industrial sector - Baseline (CBAM sectors: iron and steel, cement, non-ferrous metals, mining & chemicals)
B5: Iron and steel | C5: irn | D5: Fuel Type | E5: Unit | F5: Variable Code | G5: Input Code (data-table key) | H5: Output Code | I5: Scenario | J5: 1 | K5: 2021 | L5: 2022 | M5: 2023 | N5: 2024 | O5: 2025 | P5: 2026 | Q5: 2027 | R5: 2028 | S5: 2029 | T5: 2030 | U5: 2031 | V5: 2032 | W5: 2033 | X5: 2034 | Y5: 2035 | Z5: 2036 | AA5: 2037 | AB5: 2038 | AC5: 2039 | AD5: 2040 | AE5: 2041 | AF5: 2042 | AG5: 2043 | AH5: 2044 | AI5: 2045
B6: Pre-tax price: price before any new policy (supply cost + VAT + existing excise, subsidies and carbon prices)
B7: coa | C7: =$C$5 -> irn | D7: Coal | E7: $/GJ | F7: ptp | G7: =Settings!$B$3&".mit.pbc."&Settings!$B$4&"."&$B7&".a."&$J$5 -> egy.mit.pbc.ind.coa.a.1 | H7: =Settings!$B$3&".mit.ptp."&$C$5&"."&$B7&".e."&$J$5 -> egy.mit.ptp.irn.coa.e.1 | K7: =INDEX(Data_Prices!K:K,MATCH($G7,Data_Prices!$A:$A,0)) -> 11.182902 | L7: =INDEX(Data_Prices!L:L,MATCH($G7,Data_Prices!$A:$A,0)) -> 10.523361 | M7: =INDEX(Data_Prices!M:M,MATCH($G7,Data_Prices!$A:$A,0)) -> 10.299561 | N7: =INDEX(Data_Prices!N:N,MATCH($G7,Data_Prices!$A:$A,0)) -> 9.5775284 | O7: =INDEX(Data_Prices!O:O,MATCH($G7,Data_Prices!$A:$A,0)) -> 8.4854783 | P7: =INDEX(Data_Prices!P:P,MATCH($G7,Data_Prices!$A:$A,0)) -> 9.0871922 | Q7: =INDEX(Data_Prices!Q:Q,MATCH($G7,Data_Prices!$A:$A,0)) -> 9.2229237 | R7: =INDEX(Data_Prices!R:R,MATCH($G7,Data_Prices!$A:$A,0)) -> 9.158565 | S7: =INDEX(Data_Prices!S:S,MATCH($G7,Data_Prices!$A:$A,0)) -> 9.0895479 | T7: =INDEX(Data_Prices!T:T,MATCH($G7,Data_Prices!$A:$A,0)) -> 9.0156817 | U7: =INDEX(Data_Prices!U:U,MATCH($G7,Data_Prices!$A:$A,0)) -> 8.9443978 | V7: =INDEX(Data_Prices!V:V,MATCH($G7,Data_Prices!$A:$A,0)) -> 8.9443978 | W7: =INDEX(Data_Prices!W:W,MATCH($G7,Data_Prices!$A:$A,0)) -> 8.9443978 | X7: =INDEX(Data_Prices!X:X,MATCH($G7,Data_Prices!$A:$A,0)) -> 8.9443978 | Y7: =INDEX(Data_Prices!Y:Y,MATCH($G7,Data_Prices!$A:$A,0)) -> 8.9443978 | Z7: =INDEX(Data_Prices!Z:Z,MATCH($G7,Data_Prices!$A:$A,0)) -> 8.9443978 | AA7: =INDEX(Data_Prices!AA:AA,MATCH($G7,Data_Prices!$A:$A,0)) -> 8.9443978 | AB7: =INDEX(Data_Prices!AB:AB,MATCH($G7,Data_Prices!$A:$A,0)) -> 8.9443978 | AC7: =INDEX(Data_Prices!AC:AC,MATCH($G7,Data_Prices!$A:$A,0)) -> 8.9443978 | AD7: =INDEX(Data_Prices!AD:AD,MATCH($G7,Data_Prices!$A:$A,0)) -> 8.9443978 | AE7: =INDEX(Data_Prices!AE:AE,MATCH($G7,Data_Prices!$A:$A,0)) -> 8.9443978
B8: nga | C8: =$C$5 -> irn | D8: Natural gas | E8: $/GJ | F8: ptp | G8: =Settings!$B$3&".mit.pbc."&Settings!$B$4&"."&$B8&".a."&$J$5 -> egy.mit.pbc.ind.nga.a.1 | H8: =Settings!$B$3&".mit.ptp."&$C$5&"."&$B8&".e."&$J$5 -> egy.mit.ptp.irn.nga.e.1 | K8: =INDEX(Data_Prices!K:K,MATCH($G8,Data_Prices!$A:$A,0)) -> 6.0634636 | L8: =INDEX(Data_Prices!L:L,MATCH($G8,Data_Prices!$A:$A,0)) -> 5.4510151 | M8: =INDEX(Data_Prices!M:M,MATCH($G8,Data_Prices!$A:$A,0)) -> 5.1193563 | N8: =INDEX(Data_Prices!N:N,MATCH($G8,Data_Prices!$A:$A,0)) -> 5.0821846 | O8: =INDEX(Data_Prices!O:O,MATCH($G8,Data_Prices!$A:$A,0)) -> 5.0821846 | P8: =INDEX(Data_Prices!P:P,MATCH($G8,Data_Prices!$A:$A,0)) -> 5.0821846 | Q8: =INDEX(Data_Prices!Q:Q,MATCH($G8,Data_Prices!$A:$A,0)) -> 5.0821846 | R8: =INDEX(Data_Prices!R:R,MATCH($G8,Data_Prices!$A:$A,0)) -> 5.0821846 | S8: =INDEX(Data_Prices!S:S,MATCH($G8,Data_Prices!$A:$A,0)) -> 5.0821846 | T8: =INDEX(Data_Prices!T:T,MATCH($G8,Data_Prices!$A:$A,0)) -> 5.0821846 | U8: =INDEX(Data_Prices!U:U,MATCH($G8,Data_Prices!$A:$A,0)) -> 5.0821846 | V8: =INDEX(Data_Prices!V:V,MATCH($G8,Data_Prices!$A:$A,0)) -> 5.0821846 | W8: =INDEX(Data_Prices!W:W,MATCH($G8,Data_Prices!$A:$A,0)) -> 5.0821846 | X8: =INDEX(Data_Prices!X:X,MATCH($G8,Data_Prices!$A:$A,0)) -> 5.0821846 | Y8: =INDEX(Data_Prices!Y:Y,MATCH($G8,Data_Prices!$A:$A,0)) -> 5.0821846 | Z8: =INDEX(Data_Prices!Z:Z,MATCH($G8,Data_Prices!$A:$A,0)) -> 5.0821846 | AA8: =INDEX(Data_Prices!AA:AA,MATCH($G8,Data_Prices!$A:$A,0)) -> 5.0821846 | AB8: =INDEX(Data_Prices!AB:AB,MATCH($G8,Data_Prices!$A:$A,0)) -> 5.0821846 | AC8: =INDEX(Data_Prices!AC:AC,MATCH($G8,Data_Prices!$A:$A,0)) -> 5.0821846 | AD8: =INDEX(Data_Prices!AD:AD,MATCH($G8,Data_Prices!$A:$A,0)) -> 5.0821846 | AE8: =INDEX(Data_Prices!AE:AE,MATCH($G8,Data_Prices!$A:$A,0)) -> 5.0821846
B9: gso | C9: =$C$5 -> irn | D9: Gasoline | E9: $/liter | F9: ptp | G9: =Settings!$B$3&".mit.pbc."&Settings!$B$4&"."&$B9&".a."&$J$5 -> egy.mit.pbc.ind.gso.a.1 | H9: =Settings!$B$3&".mit.ptp."&$C$5&"."&$B9&".e."&$J$5 -> egy.mit.ptp.irn.gso.e.1 | K9: =INDEX(Data_Prices!K:K,MATCH($G9,Data_Prices!$A:$A,0)) -> 0.67114653 | L9: =INDEX(Data_Prices!L:L,MATCH($G9,Data_Prices!$A:$A,0)) -> 0.61197798 | M9: =INDEX(Data_Prices!M:M,MATCH($G9,Data_Prices!$A:$A,0)) -> 0.61180975 | N9: =INDEX(Data_Prices!N:N,MATCH($G9,Data_Prices!$A:$A,0)) -> 0.6035831 | O9: =INDEX(Data_Prices!O:O,MATCH($G9,Data_Prices!$A:$A,0)) -> 0.6035831 | P9: =INDEX(Data_Prices!P:P,MATCH($G9,Data_Prices!$A:$A,0)) -> 0.6035831 | Q9: =INDEX(Data_Prices!Q:Q,MATCH($G9,Data_Prices!$A:$A,0)) -> 0.6035831 | R9: =INDEX(Data_Prices!R:R,MATCH($G9,Data_Prices!$A:$A,0)) -> 0.6035831 | S9: =INDEX(Data_Prices!S:S,MATCH($G9,Data_Prices!$A:$A,0)) -> 0.6035831 | T9: =INDEX(Data_Prices!T:T,MATCH($G9,Data_Prices!$A:$A,0)) -> 0.6035831 | U9: =INDEX(Data_Prices!U:U,MATCH($G9,Data_Prices!$A:$A,0)) -> 0.6035831 | V9: =INDEX(Data_Prices!V:V,MATCH($G9,Data_Prices!$A:$A,0)) -> 0.6035831 | W9: =INDEX(Data_Prices!W:W,MATCH($G9,Data_Prices!$A:$A,0)) -> 0.6035831 | X9: =INDEX(Data_Prices!X:X,MATCH($G9,Data_Prices!$A:$A,0)) -> 0.6035831 | Y9: =INDEX(Data_Prices!Y:Y,MATCH($G9,Data_Prices!$A:$A,0)) -> 0.6035831 | Z9: =INDEX(Data_Prices!Z:Z,MATCH($G9,Data_Prices!$A:$A,0)) -> 0.6035831 | AA9: =INDEX(Data_Prices!AA:AA,MATCH($G9,Data_Prices!$A:$A,0)) -> 0.6035831 | AB9: =INDEX(Data_Prices!AB:AB,MATCH($G9,Data_Prices!$A:$A,0)) -> 0.6035831 | AC9: =INDEX(Data_Prices!AC:AC,MATCH($G9,Data_Prices!$A:$A,0)) -> 0.6035831 | AD9: =INDEX(Data_Prices!AD:AD,MATCH($G9,Data_Prices!$A:$A,0)) -> 0.6035831 | AE9: =INDEX(Data_Prices!AE:AE,MATCH($G9,Data_Prices!$A:$A,0)) -> 0.6035831
B10: die | C10: =$C$5 -> irn | D10: Diesel | E10: $/liter | F10: ptp | G10: =Settings!$B$3&".mit.pbc."&Settings!$B$4&"."&$B10&".a."&$J$5 -> egy.mit.pbc.ind.die.a.1 | H10: =Settings!$B$3&".mit.ptp."&$C$5&"."&$B10&".e."&$J$5 -> egy.mit.ptp.irn.die.e.1 | K10: =INDEX(Data_Prices!K:K,MATCH($G10,Data_Prices!$A:$A,0)) -> 0.55971121 | L10: =INDEX(Data_Prices!L:L,MATCH($G10,Data_Prices!$A:$A,0)) -> 0.49458873 | M10: =INDEX(Data_Prices!M:M,MATCH($G10,Data_Prices!$A:$A,0)) -> 0.50778655 | N10: =INDEX(Data_Prices!N:N,MATCH($G10,Data_Prices!$A:$A,0)) -> 0.47043643 | O10: =INDEX(Data_Prices!O:O,MATCH($G10,Data_Prices!$A:$A,0)) -> 0.47043643 | P10: =INDEX(Data_Prices!P:P,MATCH($G10,Data_Prices!$A:$A,0)) -> 0.47043643 | Q10: =INDEX(Data_Prices!Q:Q,MATCH($G10,Data_Prices!$A:$A,0)) -> 0.47043643 | R10: =INDEX(Data_Prices!R:R,MATCH($G10,Data_Prices!$A:$A,0)) -> 0.47043643 | S10: =INDEX(Data_Prices!S:S,MATCH($G10,Data_Prices!$A:$A,0)) -> 0.47043643 | T10: =INDEX(Data_Prices!T:T,MATCH($G10,Data_Prices!$A:$A,0)) -> 0.47043643 | U10: =INDEX(Data_Prices!U:U,MATCH($G10,Data_Prices!$A:$A,0)) -> 0.47043643 | V10: =INDEX(Data_Prices!V:V,MATCH($G10,Data_Prices!$A:$A,0)) -> 0.47043643 | W10: =INDEX(Data_Prices!W:W,MATCH($G10,Data_Prices!$A:$A,0)) -> 0.47043643 | X10: =INDEX(Data_Prices!X:X,MATCH($G10,Data_Prices!$A:$A,0)) -> 0.47043643 | Y10: =INDEX(Data_Prices!Y:Y,MATCH($G10,Data_Prices!$A:$A,0)) -> 0.47043643 | Z10: =INDEX(Data_Prices!Z:Z,MATCH($G10,Data_Prices!$A:$A,0)) -> 0.47043643 | AA10: =INDEX(Data_Prices!AA:AA,MATCH($G10,Data_Prices!$A:$A,0)) -> 0.47043643 | AB10: =INDEX(Data_Prices!AB:AB,MATCH($G10,Data_Prices!$A:$A,0)) -> 0.47043643 | AC10: =INDEX(Data_Prices!AC:AC,MATCH($G10,Data_Prices!$A:$A,0)) -> 0.47043643 | AD10: =INDEX(Data_Prices!AD:AD,MATCH($G10,Data_Prices!$A:$A,0)) -> 0.47043643 | AE10: =INDEX(Data_Prices!AE:AE,MATCH($G10,Data_Prices!$A:$A,0)) -> 0.47043643
B11: lpg | C11: =$C$5 -> irn | D11: LPG | E11: $/liter | F11: ptp | G11: =Settings!$B$3&".mit.pbc."&Settings!$B$4&"."&$B11&".a."&$J$5 -> egy.mit.pbc.ind.lpg.a.1 | H11: =Settings!$B$3&".mit.ptp."&$C$5&"."&$B11&".e."&$J$5 -> egy.mit.ptp.irn.lpg.e.1 | K11: =INDEX(Data_Prices!K:K,MATCH($G11,Data_Prices!$A:$A,0)) -> 0.20036669 | L11: =INDEX(Data_Prices!L:L,MATCH($G11,Data_Prices!$A:$A,0)) -> 0.15734474 | M11: =INDEX(Data_Prices!M:M,MATCH($G11,Data_Prices!$A:$A,0)) -> 0.16448404 | N11: =INDEX(Data_Prices!N:N,MATCH($G11,Data_Prices!$A:$A,0)) -> 0.15070908 | O11: =INDEX(Data_Prices!O:O,MATCH($G11,Data_Prices!$A:$A,0)) -> 0.15070908 | P11: =INDEX(Data_Prices!P:P,MATCH($G11,Data_Prices!$A:$A,0)) -> 0.15070908 | Q11: =INDEX(Data_Prices!Q:Q,MATCH($G11,Data_Prices!$A:$A,0)) -> 0.15070908 | R11: =INDEX(Data_Prices!R:R,MATCH($G11,Data_Prices!$A:$A,0)) -> 0.15070908 | S11: =INDEX(Data_Prices!S:S,MATCH($G11,Data_Prices!$A:$A,0)) -> 0.15070908 | T11: =INDEX(Data_Prices!T:T,MATCH($G11,Data_Prices!$A:$A,0)) -> 0.15070908 | U11: =INDEX(Data_Prices!U:U,MATCH($G11,Data_Prices!$A:$A,0)) -> 0.15070908 | V11: =INDEX(Data_Prices!V:V,MATCH($G11,Data_Prices!$A:$A,0)) -> 0.15070908 | W11: =INDEX(Data_Prices!W:W,MATCH($G11,Data_Prices!$A:$A,0)) -> 0.15070908 | X11: =INDEX(Data_Prices!X:X,MATCH($G11,Data_Prices!$A:$A,0)) -> 0.15070908 | Y11: =INDEX(Data_Prices!Y:Y,MATCH($G11,Data_Prices!$A:$A,0)) -> 0.15070908 | Z11: =INDEX(Data_Prices!Z:Z,MATCH($G11,Data_Prices!$A:$A,0)) -> 0.15070908 | AA11: =INDEX(Data_Prices!AA:AA,MATCH($G11,Data_Prices!$A:$A,0)) -> 0.15070908 | AB11: =INDEX(Data_Prices!AB:AB,MATCH($G11,Data_Prices!$A:$A,0)) -> 0.15070908 | AC11: =INDEX(Data_Prices!AC:AC,MATCH($G11,Data_Prices!$A:$A,0)) -> 0.15070908 | AD11: =INDEX(Data_Prices!AD:AD,MATCH($G11,Data_Prices!$A:$A,0)) -> 0.15070908 | AE11: =INDEX(Data_Prices!AE:AE,MATCH($G11,Data_Prices!$A:$A,0)) -> 0.15070908
B12: ker | C12: =$C$5 -> irn | D12: Kerosene | E12: $/liter | F12: ptp | G12: =Settings!$B$3&".mit.pbc."&Settings!$B$4&"."&$B12&".a."&$J$5 -> egy.mit.pbc.ind.ker.a.1 | H12: =Settings!$B$3&".mit.ptp."&$C$5&"."&$B12&".e."&$J$5 -> egy.mit.ptp.irn.ker.e.1 | K12: =INDEX(Data_Prices!K:K,MATCH($G12,Data_Prices!$A:$A,0)) -> 0.48429424 | L12: =INDEX(Data_Prices!L:L,MATCH($G12,Data_Prices!$A:$A,0)) -> 0.45642817 | M12: =INDEX(Data_Prices!M:M,MATCH($G12,Data_Prices!$A:$A,0)) -> 0.4316892 | N12: =INDEX(Data_Prices!N:N,MATCH($G12,Data_Prices!$A:$A,0)) -> 0.42507558 | O12: =INDEX(Data_Prices!O:O,MATCH($G12,Data_Prices!$A:$A,0)) -> 0.42507558 | P12: =INDEX(Data_Prices!P:P,MATCH($G12,Data_Prices!$A:$A,0)) -> 0.42507558 | Q12: =INDEX(Data_Prices!Q:Q,MATCH($G12,Data_Prices!$A:$A,0)) -> 0.42507558 | R12: =INDEX(Data_Prices!R:R,MATCH($G12,Data_Prices!$A:$A,0)) -> 0.42507558 | S12: =INDEX(Data_Prices!S:S,MATCH($G12,Data_Prices!$A:$A,0)) -> 0.42507558 | T12: =INDEX(Data_Prices!T:T,MATCH($G12,Data_Prices!$A:$A,0)) -> 0.42507558 | U12: =INDEX(Data_Prices!U:U,MATCH($G12,Data_Prices!$A:$A,0)) -> 0.42507558 | V12: =INDEX(Data_Prices!V:V,MATCH($G12,Data_Prices!$A:$A,0)) -> 0.42507558 | W12: =INDEX(Data_Prices!W:W,MATCH($G12,Data_Prices!$A:$A,0)) -> 0.42507558 | X12: =INDEX(Data_Prices!X:X,MATCH($G12,Data_Prices!$A:$A,0)) -> 0.42507558 | Y12: =INDEX(Data_Prices!Y:Y,MATCH($G12,Data_Prices!$A:$A,0)) -> 0.42507558 | Z12: =INDEX(Data_Prices!Z:Z,MATCH($G12,Data_Prices!$A:$A,0)) -> 0.42507558 | AA12: =INDEX(Data_Prices!AA:AA,MATCH($G12,Data_Prices!$A:$A,0)) -> 0.42507558 | AB12: =INDEX(Data_Prices!AB:AB,MATCH($G12,Data_Prices!$A:$A,0)) -> 0.42507558 | AC12: =INDEX(Data_Prices!AC:AC,MATCH($G12,Data_Prices!$A:$A,0)) -> 0.42507558 | AD12: =INDEX(Data_Prices!AD:AD,MATCH($G12,Data_Prices!$A:$A,0)) -> 0.42507558 | AE12: =INDEX(Data_Prices!AE:AE,MATCH($G12,Data_Prices!$A:$A,0)) -> 0.42507558
B13: oop | C13: =$C$5 -> irn | D13: Other oil products | E13: $/bbl | F13: ptp | G13: =Settings!$B$3&".mit.pbc."&Settings!$B$4&"."&$B13&".a."&$J$5 -> egy.mit.pbc.ind.oop.a.1 | H13: =Settings!$B$3&".mit.ptp."&$C$5&"."&$B13&".e."&$J$5 -> egy.mit.ptp.irn.oop.e.1 | K13: =INDEX(Data_Prices!K:K,MATCH($G13,Data_Prices!$A:$A,0)) -> 41.500338 | L13: =INDEX(Data_Prices!L:L,MATCH($G13,Data_Prices!$A:$A,0)) -> 34.41537 | M13: =INDEX(Data_Prices!M:M,MATCH($G13,Data_Prices!$A:$A,0)) -> 37.368961 | N13: =INDEX(Data_Prices!N:N,MATCH($G13,Data_Prices!$A:$A,0)) -> 28.982761 | O13: =INDEX(Data_Prices!O:O,MATCH($G13,Data_Prices!$A:$A,0)) -> 15 | P13: =INDEX(Data_Prices!P:P,MATCH($G13,Data_Prices!$A:$A,0)) -> 24.25863 | Q13: =INDEX(Data_Prices!Q:Q,MATCH($G13,Data_Prices!$A:$A,0)) -> 15 | R13: =INDEX(Data_Prices!R:R,MATCH($G13,Data_Prices!$A:$A,0)) -> 15 | S13: =INDEX(Data_Prices!S:S,MATCH($G13,Data_Prices!$A:$A,0)) -> 15 | T13: =INDEX(Data_Prices!T:T,MATCH($G13,Data_Prices!$A:$A,0)) -> 15 | U13: =INDEX(Data_Prices!U:U,MATCH($G13,Data_Prices!$A:$A,0)) -> 15 | V13: =INDEX(Data_Prices!V:V,MATCH($G13,Data_Prices!$A:$A,0)) -> 15 | W13: =INDEX(Data_Prices!W:W,MATCH($G13,Data_Prices!$A:$A,0)) -> 15 | X13: =INDEX(Data_Prices!X:X,MATCH($G13,Data_Prices!$A:$A,0)) -> 15 | Y13: =INDEX(Data_Prices!Y:Y,MATCH($G13,Data_Prices!$A:$A,0)) -> 15 | Z13: =INDEX(Data_Prices!Z:Z,MATCH($G13,Data_Prices!$A:$A,0)) -> 15 | AA13: =INDEX(Data_Prices!AA:AA,MATCH($G13,Data_Prices!$A:$A,0)) -> 15 | AB13: =INDEX(Data_Prices!AB:AB,MATCH($G13,Data_Prices!$A:$A,0)) -> 15 | AC13: =INDEX(Data_Prices!AC:AC,MATCH($G13,Data_Prices!$A:$A,0)) -> 15 | AD13: =INDEX(Data_Prices!AD:AD,MATCH($G13,Data_Prices!$A:$A,0)) -> 15 | AE13: =INDEX(Data_Prices!AE:AE,MATCH($G13,Data_Prices!$A:$A,0)) -> 15
B14: bio | C14: =$C$5 -> irn | D14: Biomass | E14: $/GJ | F14: ptp | G14: =Settings!$B$3&".mit.pbc."&Settings!$B$4&"."&$B14&".a."&$J$5 -> egy.mit.pbc.ind.bio.a.1 | H14: =Settings!$B$3&".mit.ptp."&$C$5&"."&$B14&".e."&$J$5 -> egy.mit.ptp.irn.bio.e.1 | K14: =INDEX(Data_Prices!K:K,MATCH($G14,Data_Prices!$A:$A,0)) -> 15.334551 | L14: =INDEX(Data_Prices!L:L,MATCH($G14,Data_Prices!$A:$A,0)) -> 14.199528 | M14: =INDEX(Data_Prices!M:M,MATCH($G14,Data_Prices!$A:$A,0)) -> 13.840442 | N14: =INDEX(Data_Prices!N:N,MATCH($G14,Data_Prices!$A:$A,0)) -> 13.567727 | O14: =INDEX(Data_Prices!O:O,MATCH($G14,Data_Prices!$A:$A,0)) -> 13.567727 | P14: =INDEX(Data_Prices!P:P,MATCH($G14,Data_Prices!$A:$A,0)) -> 13.567727 | Q14: =INDEX(Data_Prices!Q:Q,MATCH($G14,Data_Prices!$A:$A,0)) -> 13.567727 | R14: =INDEX(Data_Prices!R:R,MATCH($G14,Data_Prices!$A:$A,0)) -> 13.567727 | S14: =INDEX(Data_Prices!S:S,MATCH($G14,Data_Prices!$A:$A,0)) -> 13.567727 | T14: =INDEX(Data_Prices!T:T,MATCH($G14,Data_Prices!$A:$A,0)) -> 13.567727 | U14: =INDEX(Data_Prices!U:U,MATCH($G14,Data_Prices!$A:$A,0)) -> 13.567727 | V14: =INDEX(Data_Prices!V:V,MATCH($G14,Data_Prices!$A:$A,0)) -> 13.567727 | W14: =INDEX(Data_Prices!W:W,MATCH($G14,Data_Prices!$A:$A,0)) -> 13.567727 | X14: =INDEX(Data_Prices!X:X,MATCH($G14,Data_Prices!$A:$A,0)) -> 13.567727 | Y14: =INDEX(Data_Prices!Y:Y,MATCH($G14,Data_Prices!$A:$A,0)) -> 13.567727 | Z14: =INDEX(Data_Prices!Z:Z,MATCH($G14,Data_Prices!$A:$A,0)) -> 13.567727 | AA14: =INDEX(Data_Prices!AA:AA,MATCH($G14,Data_Prices!$A:$A,0)) -> 13.567727 | AB14: =INDEX(Data_Prices!AB:AB,MATCH($G14,Data_Prices!$A:$A,0)) -> 13.567727 | AC14: =INDEX(Data_Prices!AC:AC,MATCH($G14,Data_Prices!$A:$A,0)) -> 13.567727 | AD14: =INDEX(Data_Prices!AD:AD,MATCH($G14,Data_Prices!$A:$A,0)) -> 13.567727 | AE14: =INDEX(Data_Prices!AE:AE,MATCH($G14,Data_Prices!$A:$A,0)) -> 13.567727
