Workbook

Sheet Table2
A1: Table 2. Simulated outcomes of carbon policy scenarios for Egypt, 2030 (USD 20/tCO2 in 2030 in all scenarios)
A2: All rows are hard-coded from the final CBAM carve-out (EGYPT_CarveOut_Table2_v1.3), except row O, which is computed live on sheet 'CBAM_calc' as the export-weighted change in the embedded emission intensity of CBAM products only. Change the yellow cells on 'Scenarios' and 'CBAM_data' to test alternatives.
A4: Code | B4: Indicator | C4: Unit | D4: 1A | E4: 2A | F4: 2B | G4: 3A | H4: 3B | I4: 3C | J4: Source
A5: J | B5: Coverage of national GHG emissions | C5: % | D5: 63.209336 | E5: 57.335111 | F5: 57.335111 | G5: 13.915632 | H5: 13.915632 | I5: 13.915632 | J5: Hard-coded: CBAM carve-out v1.3
A6: P | B6: Carbon revenue | C6: USD bn | D6: 6.8594937 | E6: 6.2668867 | F6: 6.2294418 | G6: 1.5352489 | H6: 0.64253707 | I6: 0.40605024 | J6: Hard-coded: CBAM carve-out v1.3
A7: K | B7: Emission reduction vs baseline | C7: MtCO2e | D7: -37.389792 | E7: -33.077155 | F7: -34.827655 | G7: -22.766318 | H7: -19.140348 | I7: -33.039563 | J7: Hard-coded: CBAM carve-out v1.3
A8: M | B8: CBAM coverage (share of CBAM-sector embedded emissions priced) | C8: % | D8: 100 | E8: 44.212685 | F8: 44.212685 | G8: 100 | H8: 100 | I8: 100 | J8: Hard-coded: CBAM carve-out v1.3
A9: N | B9: CBAM-sector emission intensity change | C9: % | D9: -5.7721192 | E9: -2.144387 | F9: -2.2593898 | G9: -5.7721192 | H9: -5.7984149 | I9: -23.071731 | J9: Hard-coded: CBAM carve-out v1.3
A10: O | B10: CBAM obligations (change in embedded emissions per tonne exported to the EU) | C10: % | D10: =CBAM_calc!C5 -> -5.4226768 | E10: =CBAM_calc!D5 -> -2.5530187 | F10: =CBAM_calc!E5 -> -2.6899362 | G10: =CBAM_calc!F5 -> -5.4226768 | H10: =CBAM_calc!G5 -> -5.4226768 | I10: =CBAM_calc!H5 -> -20.741844 | J10: LIVE: CBAM_calc row 5 (CBAM-product intensity only)
A11: Q | B11: Premature deaths avoided (local air pollution) | C11: deaths | D11: 1501.1341 | E11: 1456.3479 | F11: 1517.1987 | G11: 551.58951 | H11: 490.67565 | I11: 646.3092 | J11: Hard-coded: CBAM carve-out v1.3
A13: Memo
A14: O-pub | B14: CBAM obligations, initial (published) Table 2 | C14: % | D14: -26.1 | E14: -13.9 | F14: -13.9 | G14: -26.1 | H14: -7.6 | I14: -30.4
A18: Scenario definitions
A19: 1A | B19: Upstream carbon levy on all fossil fuels plus process emissions; revenue to general budget
A20: 2A | B20: Upstream carbon levy on fossil fuels; revenue to households
A21: 2B | B21: Upstream carbon levy on fossil fuels; revenue to green investment
A22: 3A | B22: Downstream carbon price on heavy industry (fuel and process); revenue to households
A23: 3B | B23: As 3A, with output-based free allocation (rebate) to industry
A24: 3C | B24: As 3A, with an industrial abatement rebate (fund)

Sheet CBAM_calc
A1: CBAM obligations, 2030: % change in embedded emissions per tonne exported to the EU (CBAM products only)
A2: O = sum_i X_i x EI_i(policy) / sum_i X_i x EI0_i - 1 (X = 2024 EU exports; EI = direct fuel + process intensity). The EU price and phase-in cancel out. Rows 6-7: memo only, not used in Table 2.
A4: Row | B4: Convention | C4: 1A | D4: 2A | E4: 2B | F4: 3A | G4: 3B | H4: 3C
A5: O | B5: Embedded-intensity change (CBAM products only) -> Table 2 row O | C5: =100*(SUMIF(CBAM_data!$A$4:$A$45,"1A",CBAM_data!$AD$4:$AD$45)/SUMIF(CBAM_data!$A$4:$A$45,"1A",CBAM_data!$AC$4:$AC$45)-1) -> -5.4226768 | D5: =100*(SUMIF(CBAM_data!$A$4:$A$45,"2A",CBAM_data!$AD$4:$AD$45)/SUMIF(CBAM_data!$A$4:$A$45,"2A",CBAM_data!$AC$4:$AC$45)-1) -> -2.5530187 | E5: =100*(SUMIF(CBAM_data!$A$4:$A$45,"2B",CBAM_data!$AD$4:$AD$45)/SUMIF(CBAM_data!$A$4:$A$45,"2B",CBAM_data!$AC$4:$AC$45)-1) -> -2.6899362 | F5: =100*(SUMIF(CBAM_data!$A$4:$A$45,"3A",CBAM_data!$AD$4:$AD$45)/SUMIF(CBAM_data!$A$4:$A$45,"3A",CBAM_data!$AC$4:$AC$45)-1) -> -5.4226768 | G5: =100*(SUMIF(CBAM_data!$A$4:$A$45,"3B",CBAM_data!$AD$4:$AD$45)/SUMIF(CBAM_data!$A$4:$A$45,"3B",CBAM_data!$AC$4:$AC$45)-1) -> -5.4226768 | H5: =100*(SUMIF(CBAM_data!$A$4:$A$45,"3C",CBAM_data!$AD$4:$AD$45)/SUMIF(CBAM_data!$A$4:$A$45,"3C",CBAM_data!$AC$4:$AC$45)-1) -> -20.741844
A6: O | B6: Memo: obligation net of Egyptian carbon-price deduction, full implementation | C6: =100*(SUMIF(CBAM_data!$A$4:$A$45,"1A",CBAM_data!$Z$4:$Z$45)/SUMIF(CBAM_data!$A$4:$A$45,"1A",CBAM_data!$Y$4:$Y$45)-1) -> -24.338141 | D6: =100*(SUMIF(CBAM_data!$A$4:$A$45,"2A",CBAM_data!$Z$4:$Z$45)/SUMIF(CBAM_data!$A$4:$A$45,"2A",CBAM_data!$Y$4:$Y$45)-1) -> -12.529929 | E6: =100*(SUMIF(CBAM_data!$A$4:$A$45,"2B",CBAM_data!$Z$4:$Z$45)/SUMIF(CBAM_data!$A$4:$A$45,"2B",CBAM_data!$Y$4:$Y$45)-1) -> -12.639463 | F6: =100*(SUMIF(CBAM_data!$A$4:$A$45,"3A",CBAM_data!$Z$4:$Z$45)/SUMIF(CBAM_data!$A$4:$A$45,"3A",CBAM_data!$Y$4:$Y$45)-1) -> -24.338141 | G6: =100*(SUMIF(CBAM_data!$A$4:$A$45,"3B",CBAM_data!$Z$4:$Z$45)/SUMIF(CBAM_data!$A$4:$A$45,"3B",CBAM_data!$Y$4:$Y$45)-1) -> -5.4226768 | H6: =100*(SUMIF(CBAM_data!$A$4:$A$45,"3C",CBAM_data!$Z$4:$Z$45)/SUMIF(CBAM_data!$A$4:$A$45,"3C",CBAM_data!$Y$4:$Y$45)-1) -> -36.593475
A7: O | B7: Memo: obligation net of Egyptian carbon-price deduction, 2030 phase-in | C7: =100*(SUMIF(CBAM_data!$A$4:$A$45,"1A",CBAM_data!$AB$4:$AB$45)/SUMIF(CBAM_data!$A$4:$A$45,"1A",CBAM_data!$AA$4:$AA$45)-1) -> -44.423635 | D7: =100*(SUMIF(CBAM_data!$A$4:$A$45,"2A",CBAM_data!$AB$4:$AB$45)/SUMIF(CBAM_data!$A$4:$A$45,"2A",CBAM_data!$AA$4:$AA$45)-1) -> -23.123967 | E7: =100*(SUMIF(CBAM_data!$A$4:$A$45,"2B",CBAM_data!$AB$4:$AB$45)/SUMIF(CBAM_data!$A$4:$A$45,"2B",CBAM_data!$AA$4:$AA$45)-1) -> -23.204424 | F7: =100*(SUMIF(CBAM_data!$A$4:$A$45,"3A",CBAM_data!$AB$4:$AB$45)/SUMIF(CBAM_data!$A$4:$A$45,"3A",CBAM_data!$AA$4:$AA$45)-1) -> -44.423635 | G7: =100*(SUMIF(CBAM_data!$A$4:$A$45,"3B",CBAM_data!$AB$4:$AB$45)/SUMIF(CBAM_data!$A$4:$A$45,"3B",CBAM_data!$AA$4:$AA$45)-1) -> -5.4226768 | H7: =100*(SUMIF(CBAM_data!$A$4:$A$45,"3C",CBAM_data!$AB$4:$AB$45)/SUMIF(CBAM_data!$A$4:$A$45,"3C",CBAM_data!$AA$4:$AA$45)-1) -> -53.42562

Sheet Assumptions
A1: Assumptions. Table 2 row O uses only F1-F10 below (CBAM-product intensity). Inputs A1-A7 drive the memo rows 6-7 on CBAM_calc only.
A2: Orange = key contestable assumption; yellow = other input. All other cells are formulas or fixed data.
A4: Ref | B4: Assumption | C4: Value | D4: Unit | E4: Basis / comment
A5: A1 | B5: EU allowance (CBAM certificate) price in 2030 | C5: 100 | D5: USD/tCO2 | E5: Kept from the initial analysis (about EUR 90/t at 1.10 USD/EUR). Treated as a real 2030 price. Please replace with your preferred EU ETS outlook for 2030. A higher price lowers the share of the obligation offset by Egypt's USD 20 price.
A6: A2 | B6: CBAM convention used in Table 2 row O | C6: Full implementation | E6: 'Full implementation': CBF = 1, as in the initial table (structural exposure once EU free allocation has ended, 2034 onwards). '2030 phase-in': CBF = value in A3; the 2030 obligation is then much smaller, so the same domestic payment offsets a larger share of it.
A7: A3 | B7: CBAM factor in 2030 (CBF, 2030 phase-in convention only) | C7: 0.485 | D7: share | E7: Share of embedded emissions charged in 2030 = 1 - EU ETS free allocation share. Regulation (EU) 2023/956 Art. 31; Directive 2003/87/EC Art. 10a(1a). Schedule below.
A8: A4 | B8: CBAM factor used (CBF) | C8: =IF(C6="Full implementation",1,C7) -> 1 | D8: share | E8: Formula.
A9: A5 | B9: Scale the domestic-price deduction by CBF? | C9: No | D9: Yes/No | E9: 'No': the carbon price effectively paid in Egypt is deducted in full (Art. 9). 'Yes': the deduction is reduced in line with the EU free allocation still given to EU producers. The EU implementing rules on this interaction are not final. With 'Yes', the result equals the full-implementation result.
A10: A6 | B10: Deduction scaling used (S) | C10: =IF(C9="Yes",C8,1) -> 1 | D10: share | E10: Formula.
A11: A7 | B11: Net the 3C industrial abatement rebate off the deductible price? | C11: No | D11: Yes/No | E11: 'No' as in the initial table. Art. 9 deducts the price 'effectively paid', taking into account any rebate or compensation. Under 'Yes', the 3C fund (Scenarios!G) is allocated to products in proportion to the carbon payment and subtracted. The 3B output-based rebate is always netted.
A13: EU CBAM phase-in (CBF = share of embedded emissions charged)
B14: Year | C14: 2026 | D14: 2027 | E14: 2028 | F14: 2029 | G14: 2030 | H14: 2031 | I14: 2032 | J14: 2033 | K14: 2034
B15: CBF | C15: 0.025 | D15: 0.05 | E15: 0.1 | F15: 0.225 | G15: 0.485 | H15: 0.61 | I15: 0.735 | J15: 0.86 | K15: 1
A18: Fixed assumptions (built into the product data)
A19: F1. Metric (row O): % change in CBAM obligations per tonne exported to the EU in 2030, measured as the change in embedded emissions of CBAM products only, weighted by 2024 EU export volumes (export mix and volumes held fixed).
A20: F2. O = sum_i X_i x EI_i / sum_i X_i x EI0_i - 1. Obligation = CBF x P_EU x EI, so the EU price and phase-in cancel. No deduction for the Egyptian carbon price is applied (memo rows 6-7 on CBAM_calc show that variant).
A21: F3. EI = direct embedded emissions per tonne (fuel combustion + process). Indirect (electricity) emissions are not included. Urea-bound CO2 is not deducted (CBAM rule). Actual (verified) emissions are assumed, not EU default values.
A22: F4. d_i = carbon price effectively paid in Egypt per tonne of product = tau_fuel x fuel intensity + tau_process x process intensity, less output-based rebates (3B) and, if A7 = Yes, the 3C fund. Floored at zero.
A23: F5. Domestic price USD 20/tCO2 in 2030 in all scenarios. 2A and 2B price fuel only (upstream levy); process emissions are unpriced there. 1A and 3A-3C price fuel and process emissions.
A24: F6. Policy fuel intensity = baseline x (1 + i_f), where i_f is CPAT's fuel-intensity response (one third of CPAT's industry fuel response; 3A-3C use the 1A value as the CBAM sectors are fully priced), plus, in 3C, the kernel's fund-financed fuel abatement.
A25: F7. Policy process intensity = industry kernel (CPAT_Industry_Kernel_Egypt_v1.3) process abatement response.
A26: F8. Products: DRI-EAF and scrap-EAF steel, grey clinker, ammonia, urea, ammonium nitrate, primary aluminium (BF-BOF steel not produced in Egypt). Baseline intensities: Egypt CBAM EF v0.1 (Methodology App. A).
A27: F9. EU export volumes: 2024 (kt): see CBAM_data column C.
A28: F10. Row O uses the same CBAM-product intensities as row N; it differs from N only by weighting (EU exports rather than output).

Sheet Scenarios
A1: Scenario parameters for the CBAM calculation (2030)
A3: Scenario | B3: Carbon price on fuel CO2 (USD/t) | C3: Carbon price on process emissions (USD/t) | D3: Output-based rebate rate (USD/t, 3B) | E3: Fuel-intensity response i_f (CPAT) | F3: 3C abatement fund (USD bn) | G3: Description
A4: 1A | B4: 20 | C4: 20 | D4: 0 | E4: -0.048686824 | F4: 0 | G4: Upstream carbon levy on all fossil fuels plus process emissions; revenue to general budget
A5: 2A | B5: 20 | C5: 0 | D5: 0 | E5: -0.048686824 | F5: 0 | G5: Upstream carbon levy on fossil fuels; revenue to households
A6: 2B | B6: 20 | C6: 0 | D6: 0 | E6: -0.051297883 | F6: 0 | G6: Upstream carbon levy on fossil fuels; revenue to green investment
A7: 3A | B7: 20 | C7: 20 | D7: 0 | E7: -0.048686824 | F7: 0 | G7: Downstream carbon price on heavy industry (fuel and process); revenue to households
A8: 3B | B8: 20 | C8: 20 | D8: 20 | E8: -0.048686824 | F8: 0 | G8: As 3A, with output-based free allocation (rebate) to industry
A9: 3C | B9: 20 | C9: 20 | D9: 0 | E9: -0.048686824 | F9: 0.92458406 | G9: As 3A, with an industrial abatement rebate (fund)

Sheet CBAM_data
A1: CBAM products by scenario, 2030. Columns C-H are data from kernel v1.3 (hard-coded); columns I onwards are formulas.
A3: Scenario | B3: Product | C3: EU exports 2024 (kt) | D3: Output 2030, policy (kt) | E3: Baseline fuel intensity EI0f (tCO2/t) | F3: Baseline process intensity EI0p (tCO2e/t) | G3: Kernel extra fuel abatement (tCO2/t; 3C fund) | H3: Policy process intensity (tCO2e/t; kernel) | I3: tau fuel | J3: tau process | K3: Rebate rate | L3: i_f | M3: Policy fuel intensity | N3: Policy embedded intensity EI | O3: Carbon price paid, gross (USD/t product) | P3: Output-based rebate (USD/t product) | Q3: Carbon payment (USD m) | R3: 3C fund share | S3: 3C fund netted (USD/t product) | T3: Deductible price d (USD/t product) | U3: Baseline obligation (USD/t) | V3: Policy obligation (USD/t) | W3: X x baseline | X3: X x policy | Y3: Full impl.: X x baseline | Z3: Full impl.: X x policy | AA3: 2030: X x baseline | AB3: 2030: X x policy | AC3: X x baseline EI (ktCO2e) | AD3: X x policy EI (ktCO2e)
A4: 1A | B4: DRI-EAF steel | C4: 580 | D4: 6550.518 | E4: 0.57099077 | F4: 0.03790102 | G4: 0 | H4: 0.035376191 | I4: =INDEX(Scenarios!$B$4:$B$9,MATCH($A4,Scenarios!$A$4:$A$9,0)) -> 20 | J4: =INDEX(Scenarios!$C$4:$C$9,MATCH($A4,Scenarios!$A$4:$A$9,0)) -> 20 | K4: =INDEX(Scenarios!$D$4:$D$9,MATCH($A4,Scenarios!$A$4:$A$9,0)) -> 0 | L4: =INDEX(Scenarios!$E$4:$E$9,MATCH($A4,Scenarios!$A$4:$A$9,0)) -> -0.048686824 | M4: =E4*(1+L4)+G4 -> 0.54319104 | N4: =M4+H4 -> 0.57856723 | O4: =I4*M4+J4*H4 -> 11.571345 | P4: =MIN(K4,I4)*E4+MIN(K4,J4)*F4 -> 0 | Q4: =MAX(0,O4-P4)*D4/1000 -> 75.798301 | R4: =IF(SUM($Q$4:$Q$10)=0,0,Q4/SUM($Q$4:$Q$10)) -> 0.068647678 | S4: =IF(Assumptions!$C$11="Yes",INDEX(Scenarios!$F$4:$F$9,MATCH($A4,Scenarios!$A$4:$A$9,0))*1000*R4/D4*1000,0) -> 0 | T4: =MAX(0,O4-P4-S4) -> 11.571345 | U4: =Assumptions!$C$8*Assumptions!$C$5*(E4+F4) -> 60.889179 | V4: =MAX(0,Assumptions!$C$8*Assumptions!$C$5*N4-Assumptions!$C$10*T4) -> 46.285379 | W4: =C4*U4 -> 35315.724 | X4: =C4*V4 -> 26845.52 | Y4: =C4*Assumptions!$C$5*(E4+F4) -> 35315.724 | Z4: =C4*MAX(0,Assumptions!$C$5*N4-T4) -> 26845.52 | AA4: =C4*Assumptions!$C$7*Assumptions!$C$5*(E4+F4) -> 17128.126 | AB4: =C4*MAX(0,Assumptions!$C$7*Assumptions!$C$5*N4-IF(Assumptions!$C$9="Yes",Assumptions!$C$7,1)*T4) -> 9563.7164 | AC4: =C4*(E4+F4) -> 353.15724 | AD4: =C4*N4 -> 335.569
A5: 1A | B5: Scrap-EAF steel | C5: 300 | D5: 6206.9385 | E5: 0.04488 | F5: 0.04398115 | G5: 0 | H5: 0.042564823 | I5: =INDEX(Scenarios!$B$4:$B$9,MATCH($A5,Scenarios!$A$4:$A$9,0)) -> 20 | J5: =INDEX(Scenarios!$C$4:$C$9,MATCH($A5,Scenarios!$A$4:$A$9,0)) -> 20 | K5: =INDEX(Scenarios!$D$4:$D$9,MATCH($A5,Scenarios!$A$4:$A$9,0)) -> 0 | L5: =INDEX(Scenarios!$E$4:$E$9,MATCH($A5,Scenarios!$A$4:$A$9,0)) -> -0.048686824 | M5: =E5*(1+L5)+G5 -> 0.042694935 | N5: =M5+H5 -> 0.085259758 | O5: =I5*M5+J5*H5 -> 1.7051952 | P5: =MIN(K5,I5)*E5+MIN(K5,J5)*F5 -> 0 | Q5: =MAX(0,O5-P5)*D5/1000 -> 10.584041 | R5: =IF(SUM($Q$4:$Q$10)=0,0,Q5/SUM($Q$4:$Q$10)) -> 0.0095855693 | S5: =IF(Assumptions!$C$11="Yes",INDEX(Scenarios!$F$4:$F$9,MATCH($A5,Scenarios!$A$4:$A$9,0))*1000*R5/D5*1000,0) -> 0 | T5: =MAX(0,O5-P5-S5) -> 1.7051952 | U5: =Assumptions!$C$8*Assumptions!$C$5*(E5+F5) -> 8.886115 | V5: =MAX(0,Assumptions!$C$8*Assumptions!$C$5*N5-Assumptions!$C$10*T5) -> 6.8207806 | W5: =C5*U5 -> 2665.8345 | X5: =C5*V5 -> 2046.2342 | Y5: =C5*Assumptions!$C$5*(E5+F5) -> 2665.8345 | Z5: =C5*MAX(0,Assumptions!$C$5*N5-T5) -> 2046.2342 | AA5: =C5*Assumptions!$C$7*Assumptions!$C$5*(E5+F5) -> 1292.9297 | AB5: =C5*MAX(0,Assumptions!$C$7*Assumptions!$C$5*N5-IF(Assumptions!$C$9="Yes",Assumptions!$C$7,1)*T5) -> 728.97093 | AC5: =C5*(E5+F5) -> 26.658345 | AD5: =C5*N5 -> 25.577927
A6: 1A | B6: Grey clinker (dry-process) | C6: 800 | D6: 56538.734 | E6: 0.3135685 | F6: 0.53702616 | G6: 0 | H6: 0.50225977 | I6: =INDEX(Scenarios!$B$4:$B$9,MATCH($A6,Scenarios!$A$4:$A$9,0)) -> 20 | J6: =INDEX(Scenarios!$C$4:$C$9,MATCH($A6,Scenarios!$A$4:$A$9,0)) -> 20 | K6: =INDEX(Scenarios!$D$4:$D$9,MATCH($A6,Scenarios!$A$4:$A$9,0)) -> 0 | L6: =INDEX(Scenarios!$E$4:$E$9,MATCH($A6,Scenarios!$A$4:$A$9,0)) -> -0.048686824 | M6: =E6*(1+L6)+G6 -> 0.29830185 | N6: =M6+H6 -> 0.80056162 | O6: =I6*M6+J6*H6 -> 16.011232 | P6: =MIN(K6,I6)*E6+MIN(K6,J6)*F6 -> 0 | Q6: =MAX(0,O6-P6)*D6/1000 -> 905.25481 | R6: =IF(SUM($Q$4:$Q$10)=0,0,Q6/SUM($Q$4:$Q$10)) -> 0.81985532 | S6: =IF(Assumptions!$C$11="Yes",INDEX(Scenarios!$F$4:$F$9,MATCH($A6,Scenarios!$A$4:$A$9,0))*1000*R6/D6*1000,0) -> 0 | T6: =MAX(0,O6-P6-S6) -> 16.011232 | U6: =Assumptions!$C$8*Assumptions!$C$5*(E6+F6) -> 85.059466 | V6: =MAX(0,Assumptions!$C$8*Assumptions!$C$5*N6-Assumptions!$C$10*T6) -> 64.044929 | W6: =C6*U6 -> 68047.573 | X6: =C6*V6 -> 51235.943 | Y6: =C6*Assumptions!$C$5*(E6+F6) -> 68047.573 | Z6: =C6*MAX(0,Assumptions!$C$5*N6-T6) -> 51235.943 | AA6: =C6*Assumptions!$C$7*Assumptions!$C$5*(E6+F6) -> 33003.073 | AB6: =C6*MAX(0,Assumptions!$C$7*Assumptions!$C$5*N6-IF(Assumptions!$C$9="Yes",Assumptions!$C$7,1)*T6) -> 18252.805 | AC6: =C6*(E6+F6) -> 680.47573 | AD6: =C6*N6 -> 640.44929
A7: 1A | B7: Ammonia (net) | C7: 120 | D7: 1950.1858 | E7: 1.97472 | F7: 0 | G7: 0 | H7: 0 | I7: =INDEX(Scenarios!$B$4:$B$9,MATCH($A7,Scenarios!$A$4:$A$9,0)) -> 20 | J7: =INDEX(Scenarios!$C$4:$C$9,MATCH($A7,Scenarios!$A$4:$A$9,0)) -> 20 | K7: =INDEX(Scenarios!$D$4:$D$9,MATCH($A7,Scenarios!$A$4:$A$9,0)) -> 0 | L7: =INDEX(Scenarios!$E$4:$E$9,MATCH($A7,Scenarios!$A$4:$A$9,0)) -> -0.048686824 | M7: =E7*(1+L7)+G7 -> 1.8785772 | N7: =M7+H7 -> 1.8785772 | O7: =I7*M7+J7*H7 -> 37.571543 | P7: =MIN(K7,I7)*E7+MIN(K7,J7)*F7 -> 0 | Q7: =MAX(0,O7-P7)*D7/1000 -> 73.27149 | R7: =IF(SUM($Q$4:$Q$10)=0,0,Q7/SUM($Q$4:$Q$10)) -> 0.066359239 | S7: =IF(Assumptions!$C$11="Yes",INDEX(Scenarios!$F$4:$F$9,MATCH($A7,Scenarios!$A$4:$A$9,0))*1000*R7/D7*1000,0) -> 0 | T7: =MAX(0,O7-P7-S7) -> 37.571543 | U7: =Assumptions!$C$8*Assumptions!$C$5*(E7+F7) -> 197.472 | V7: =MAX(0,Assumptions!$C$8*Assumptions!$C$5*N7-Assumptions!$C$10*T7) -> 150.28617 | W7: =C7*U7 -> 23696.64 | X7: =C7*V7 -> 18034.341 | Y7: =C7*Assumptions!$C$5*(E7+F7) -> 23696.64 | Z7: =C7*MAX(0,Assumptions!$C$5*N7-T7) -> 18034.341 | AA7: =C7*Assumptions!$C$7*Assumptions!$C$5*(E7+F7) -> 11492.87 | AB7: =C7*MAX(0,Assumptions!$C$7*Assumptions!$C$5*N7-IF(Assumptions!$C$9="Yes",Assumptions!$C$7,1)*T7) -> 6424.7339 | AC7: =C7*(E7+F7) -> 236.9664 | AD7: =C7*N7 -> 225.42926
A8: 1A | B8: Urea | C8: 1600 | D8: 3181.1553 | E8: 0.1122 | F8: 0 | G8: 0 | H8: 0 | I8: =INDEX(Scenarios!$B$4:$B$9,MATCH($A8,Scenarios!$A$4:$A$9,0)) -> 20 | J8: =INDEX(Scenarios!$C$4:$C$9,MATCH($A8,Scenarios!$A$4:$A$9,0)) -> 20 | K8: =INDEX(Scenarios!$D$4:$D$9,MATCH($A8,Scenarios!$A$4:$A$9,0)) -> 0 | L8: =INDEX(Scenarios!$E$4:$E$9,MATCH($A8,Scenarios!$A$4:$A$9,0)) -> -0.048686824 | M8: =E8*(1+L8)+G8 -> 0.10673734 | N8: =M8+H8 -> 0.10673734 | O8: =I8*M8+J8*H8 -> 2.1347468 | P8: =MIN(K8,I8)*E8+MIN(K8,J8)*F8 -> 0 | Q8: =MAX(0,O8-P8)*D8/1000 -> 6.7909609 | R8: =IF(SUM($Q$4:$Q$10)=0,0,Q8/SUM($Q$4:$Q$10)) -> 0.0061503185 | S8: =IF(Assumptions!$C$11="Yes",INDEX(Scenarios!$F$4:$F$9,MATCH($A8,Scenarios!$A$4:$A$9,0))*1000*R8/D8*1000,0) -> 0 | T8: =MAX(0,O8-P8-S8) -> 2.1347468 | U8: =Assumptions!$C$8*Assumptions!$C$5*(E8+F8) -> 11.22 | V8: =MAX(0,Assumptions!$C$8*Assumptions!$C$5*N8-Assumptions!$C$10*T8) -> 8.5389871 | W8: =C8*U8 -> 17952 | X8: =C8*V8 -> 13662.379 | Y8: =C8*Assumptions!$C$5*(E8+F8) -> 17952 | Z8: =C8*MAX(0,Assumptions!$C$5*N8-T8) -> 13662.379 | AA8: =C8*Assumptions!$C$7*Assumptions!$C$5*(E8+F8) -> 8706.72 | AB8: =C8*MAX(0,Assumptions!$C$7*Assumptions!$C$5*N8-IF(Assumptions!$C$9="Yes",Assumptions!$C$7,1)*T8) -> 4867.2226 | AC8: =C8*(E8+F8) -> 179.52 | AD8: =C8*N8 -> 170.77974
A9: 1A | B9: Ammonium nitrate | C9: 80 | D9: 661.20268 | E9: 0.1122 | F9: 0.9944125 | G9: 0 | H9: 0.84931933 | I9: =INDEX(Scenarios!$B$4:$B$9,MATCH($A9,Scenarios!$A$4:$A$9,0)) -> 20 | J9: =INDEX(Scenarios!$C$4:$C$9,MATCH($A9,Scenarios!$A$4:$A$9,0)) -> 20 | K9: =INDEX(Scenarios!$D$4:$D$9,MATCH($A9,Scenarios!$A$4:$A$9,0)) -> 0 | L9: =INDEX(Scenarios!$E$4:$E$9,MATCH($A9,Scenarios!$A$4:$A$9,0)) -> -0.048686824 | M9: =E9*(1+L9)+G9 -> 0.10673734 | N9: =M9+H9 -> 0.95605667 | O9: =I9*M9+J9*H9 -> 19.121133 | P9: =MIN(K9,I9)*E9+MIN(K9,J9)*F9 -> 0 | Q9: =MAX(0,O9-P9)*D9/1000 -> 12.642945 | R9: =IF(SUM($Q$4:$Q$10)=0,0,Q9/SUM($Q$4:$Q$10)) -> 0.011450241 | S9: =IF(Assumptions!$C$11="Yes",INDEX(Scenarios!$F$4:$F$9,MATCH($A9,Scenarios!$A$4:$A$9,0))*1000*R9/D9*1000,0) -> 0 | T9: =MAX(0,O9-P9-S9) -> 19.121133 | U9: =Assumptions!$C$8*Assumptions!$C$5*(E9+F9) -> 110.66125 | V9: =MAX(0,Assumptions!$C$8*Assumptions!$C$5*N9-Assumptions!$C$10*T9) -> 76.484533 | W9: =C9*U9 -> 8852.9 | X9: =C9*V9 -> 6118.7627 | Y9: =C9*Assumptions!$C$5*(E9+F9) -> 8852.9 | Z9: =C9*MAX(0,Assumptions!$C$5*N9-T9) -> 6118.7627 | AA9: =C9*Assumptions!$C$7*Assumptions!$C$5*(E9+F9) -> 4293.6565 | AB9: =C9*MAX(0,Assumptions!$C$7*Assumptions!$C$5*N9-IF(Assumptions!$C$9="Yes",Assumptions!$C$7,1)*T9) -> 2179.8092 | AC9: =C9*(E9+F9) -> 88.529 | AD9: =C9*N9 -> 76.484533
A10: 1A | B10: Primary aluminium | C10: 167 | D10: 409.37519 | E10: 0.12342 | F10: 2.397493 | G10: 0 | H10: 2.3035401 | I10: =INDEX(Scenarios!$B$4:$B$9,MATCH($A10,Scenarios!$A$4:$A$9,0)) -> 20 | J10: =INDEX(Scenarios!$C$4:$C$9,MATCH($A10,Scenarios!$A$4:$A$9,0)) -> 20 | K10: =INDEX(Scenarios!$D$4:$D$9,MATCH($A10,Scenarios!$A$4:$A$9,0)) -> 0 | L10: =INDEX(Scenarios!$E$4:$E$9,MATCH($A10,Scenarios!$A$4:$A$9,0)) -> -0.048686824 | M10: =E10*(1+L10)+G10 -> 0.11741107 | N10: =M10+H10 -> 2.4209512 | O10: =I10*M10+J10*H10 -> 48.419024 | P10: =MIN(K10,I10)*E10+MIN(K10,J10)*F10 -> 0 | Q10: =MAX(0,O10-P10)*D10/1000 -> 19.821548 | R10: =IF(SUM($Q$4:$Q$10)=0,0,Q10/SUM($Q$4:$Q$10)) -> 0.017951632 | S10: =IF(Assumptions!$C$11="Yes",INDEX(Scenarios!$F$4:$F$9,MATCH($A10,Scenarios!$A$4:$A$9,0))*1000*R10/D10*1000,0) -> 0 | T10: =MAX(0,O10-P10-S10) -> 48.419024 | U10: =Assumptions!$C$8*Assumptions!$C$5*(E10+F10) -> 252.0913 | V10: =MAX(0,Assumptions!$C$8*Assumptions!$C$5*N10-Assumptions!$C$10*T10) -> 193.6761 | W10: =C10*U10 -> 42099.248 | X10: =C10*V10 -> 32343.908 | Y10: =C10*Assumptions!$C$5*(E10+F10) -> 42099.248 | Z10: =C10*MAX(0,Assumptions!$C$5*N10-T10) -> 32343.908 | AA10: =C10*Assumptions!$C$7*Assumptions!$C$5*(E10+F10) -> 20418.135 | AB10: =C10*MAX(0,Assumptions!$C$7*Assumptions!$C$5*N10-IF(Assumptions!$C$9="Yes",Assumptions!$C$7,1)*T10) -> 11522.517 | AC10: =C10*(E10+F10) -> 420.99248 | AD10: =C10*N10 -> 404.29885
A11: 2A | B11: DRI-EAF steel | C11: 580 | D11: 6553.7778 | E11: 0.57099077 | F11: 0.03790102 | G11: 0 | H11: 0.03790102 | I11: =INDEX(Scenarios!$B$4:$B$9,MATCH($A11,Scenarios!$A$4:$A$9,0)) -> 20 | J11: =INDEX(Scenarios!$C$4:$C$9,MATCH($A11,Scenarios!$A$4:$A$9,0)) -> 0 | K11: =INDEX(Scenarios!$D$4:$D$9,MATCH($A11,Scenarios!$A$4:$A$9,0)) -> 0 | L11: =INDEX(Scenarios!$E$4:$E$9,MATCH($A11,Scenarios!$A$4:$A$9,0)) -> -0.048686824 | M11: =E11*(1+L11)+G11 -> 0.54319104 | N11: =M11+H11 -> 0.58109206 | O11: =I11*M11+J11*H11 -> 10.863821 | P11: =MIN(K11,I11)*E11+MIN(K11,J11)*F11 -> 0 | Q11: =MAX(0,O11-P11)*D11/1000 -> 71.199068 | R11: =IF(SUM($Q$11:$Q$17)=0,0,Q11/SUM($Q$11:$Q$17)) -> 0.13918629 | S11: =IF(Assumptions!$C$11="Yes",INDEX(Scenarios!$F$4:$F$9,MATCH($A11,Scenarios!$A$4:$A$9,0))*1000*R11/D11*1000,0) -> 0 | T11: =MAX(0,O11-P11-S11) -> 10.863821 | U11: =Assumptions!$C$8*Assumptions!$C$5*(E11+F11) -> 60.889179 | V11: =MAX(0,Assumptions!$C$8*Assumptions!$C$5*N11-Assumptions!$C$10*T11) -> 47.245385 | W11: =C11*U11 -> 35315.724 | X11: =C11*V11 -> 27402.324 | Y11: =C11*Assumptions!$C$5*(E11+F11) -> 35315.724 | Z11: =C11*MAX(0,Assumptions!$C$5*N11-T11) -> 27402.324 | AA11: =C11*Assumptions!$C$7*Assumptions!$C$5*(E11+F11) -> 17128.126 | AB11: =C11*MAX(0,Assumptions!$C$7*Assumptions!$C$5*N11-IF(Assumptions!$C$9="Yes",Assumptions!$C$7,1)*T11) -> 10045.104 | AC11: =C11*(E11+F11) -> 353.15724 | AD11: =C11*N11 -> 337.0334
A12: 2A | B12: Scrap-EAF steel | C12: 300 | D12: 6210.9464 | E12: 0.04488 | F12: 0.04398115 | G12: 0 | H12: 0.04398115 | I12: =INDEX(Scenarios!$B$4:$B$9,MATCH($A12,Scenarios!$A$4:$A$9,0)) -> 20 | J12: =INDEX(Scenarios!$C$4:$C$9,MATCH($A12,Scenarios!$A$4:$A$9,0)) -> 0 | K12: =INDEX(Scenarios!$D$4:$D$9,MATCH($A12,Scenarios!$A$4:$A$9,0)) -> 0 | L12: =INDEX(Scenarios!$E$4:$E$9,MATCH($A12,Scenarios!$A$4:$A$9,0)) -> -0.048686824 | M12: =E12*(1+L12)+G12 -> 0.042694935 | N12: =M12+H12 -> 0.086676085 | O12: =I12*M12+J12*H12 -> 0.85389871 | P12: =MIN(K12,I12)*E12+MIN(K12,J12)*F12 -> 0 | Q12: =MAX(0,O12-P12)*D12/1000 -> 5.3035191 | R12: =IF(SUM($Q$11:$Q$17)=0,0,Q12/SUM($Q$11:$Q$17)) -> 0.010367792 | S12: =IF(Assumptions!$C$11="Yes",INDEX(Scenarios!$F$4:$F$9,MATCH($A12,Scenarios!$A$4:$A$9,0))*1000*R12/D12*1000,0) -> 0 | T12: =MAX(0,O12-P12-S12) -> 0.85389871 | U12: =Assumptions!$C$8*Assumptions!$C$5*(E12+F12) -> 8.886115 | V12: =MAX(0,Assumptions!$C$8*Assumptions!$C$5*N12-Assumptions!$C$10*T12) -> 7.8137098 | W12: =C12*U12 -> 2665.8345 | X12: =C12*V12 -> 2344.1129 | Y12: =C12*Assumptions!$C$5*(E12+F12) -> 2665.8345 | Z12: =C12*MAX(0,Assumptions!$C$5*N12-T12) -> 2344.1129 | AA12: =C12*Assumptions!$C$7*Assumptions!$C$5*(E12+F12) -> 1292.9297 | AB12: =C12*MAX(0,Assumptions!$C$7*Assumptions!$C$5*N12-IF(Assumptions!$C$9="Yes",Assumptions!$C$7,1)*T12) -> 1004.9674 | AC12: =C12*(E12+F12) -> 26.658345 | AD12: =C12*N12 -> 26.002826
A13: 2A | B13: Grey clinker (dry-process) | C13: 800 | D13: 59092.434 | E13: 0.3135685 | F13: 0.53702616 | G13: 0 | H13: 0.53702616 | I13: =INDEX(Scenarios!$B$4:$B$9,MATCH($A13,Scenarios!$A$4:$A$9,0)) -> 20 | J13: =INDEX(Scenarios!$C$4:$C$9,MATCH($A13,Scenarios!$A$4:$A$9,0)) -> 0 | K13: =INDEX(Scenarios!$D$4:$D$9,MATCH($A13,Scenarios!$A$4:$A$9,0)) -> 0 | L13: =INDEX(Scenarios!$E$4:$E$9,MATCH($A13,Scenarios!$A$4:$A$9,0)) -> -0.048686824 | M13: =E13*(1+L13)+G13 -> 0.29830185 | N13: =M13+H13 -> 0.83532801 | O13: =I13*M13+J13*H13 -> 5.9660369 | P13: =MIN(K13,I13)*E13+MIN(K13,J13)*F13 -> 0 | Q13: =MAX(0,O13-P13)*D13/1000 -> 352.54764 | R13: =IF(SUM($Q$11:$Q$17)=0,0,Q13/SUM($Q$11:$Q$17)) -> 0.68919159 | S13: =IF(Assumptions!$C$11="Yes",INDEX(Scenarios!$F$4:$F$9,MATCH($A13,Scenarios!$A$4:$A$9,0))*1000*R13/D13*1000,0) -> 0 | T13: =MAX(0,O13-P13-S13) -> 5.9660369 | U13: =Assumptions!$C$8*Assumptions!$C$5*(E13+F13) -> 85.059466 | V13: =MAX(0,Assumptions!$C$8*Assumptions!$C$5*N13-Assumptions!$C$10*T13) -> 77.566764 | W13: =C13*U13 -> 68047.573 | X13: =C13*V13 -> 62053.411 | Y13: =C13*Assumptions!$C$5*(E13+F13) -> 68047.573 | Z13: =C13*MAX(0,Assumptions!$C$5*N13-T13) -> 62053.411 | AA13: =C13*Assumptions!$C$7*Assumptions!$C$5*(E13+F13) -> 33003.073 | AB13: =C13*MAX(0,Assumptions!$C$7*Assumptions!$C$5*N13-IF(Assumptions!$C$9="Yes",Assumptions!$C$7,1)*T13) -> 27637.897 | AC13: =C13*(E13+F13) -> 680.47573 | AD13: =C13*N13 -> 668.2624
A14: 2A | B14: Ammonia (net) | C14: 120 | D14: 1950.1858 | E14: 1.97472 | F14: 0 | G14: 0 | H14: 0 | I14: =INDEX(Scenarios!$B$4:$B$9,MATCH($A14,Scenarios!$A$4:$A$9,0)) -> 20 | J14: =INDEX(Scenarios!$C$4:$C$9,MATCH($A14,Scenarios!$A$4:$A$9,0)) -> 0 | K14: =INDEX(Scenarios!$D$4:$D$9,MATCH($A14,Scenarios!$A$4:$A$9,0)) -> 0 | L14: =INDEX(Scenarios!$E$4:$E$9,MATCH($A14,Scenarios!$A$4:$A$9,0)) -> -0.048686824 | M14: =E14*(1+L14)+G14 -> 1.8785772 | N14: =M14+H14 -> 1.8785772 | O14: =I14*M14+J14*H14 -> 37.571543 | P14: =MIN(K14,I14)*E14+MIN(K14,J14)*F14 -> 0 | Q14: =MAX(0,O14-P14)*D14/1000 -> 73.27149 | R14: =IF(SUM($Q$11:$Q$17)=0,0,Q14/SUM($Q$11:$Q$17)) -> 0.14323765 | S14: =IF(Assumptions!$C$11="Yes",INDEX(Scenarios!$F$4:$F$9,MATCH($A14,Scenarios!$A$4:$A$9,0))*1000*R14/D14*1000,0) -> 0 | T14: =MAX(0,O14-P14-S14) -> 37.571543 | U14: =Assumptions!$C$8*Assumptions!$C$5*(E14+F14) -> 197.472 | V14: =MAX(0,Assumptions!$C$8*Assumptions!$C$5*N14-Assumptions!$C$10*T14) -> 150.28617 | W14: =C14*U14 -> 23696.64 | X14: =C14*V14 -> 18034.341 | Y14: =C14*Assumptions!$C$5*(E14+F14) -> 23696.64 | Z14: =C14*MAX(0,Assumptions!$C$5*N14-T14) -> 18034.341 | AA14: =C14*Assumptions!$C$7*Assumptions!$C$5*(E14+F14) -> 11492.87 | AB14: =C14*MAX(0,Assumptions!$C$7*Assumptions!$C$5*N14-IF(Assumptions!$C$9="Yes",Assumptions!$C$7,1)*T14) -> 6424.7339 | AC14: =C14*(E14+F14) -> 236.9664 | AD14: =C14*N14 -> 225.42926
A15: 2A | B15: Urea | C15: 1600 | D15: 3181.1553 | E15: 0.1122 | F15: 0 | G15: 0 | H15: 0 | I15: =INDEX(Scenarios!$B$4:$B$9,MATCH($A15,Scenarios!$A$4:$A$9,0)) -> 20 | J15: =INDEX(Scenarios!$C$4:$C$9,MATCH($A15,Scenarios!$A$4:$A$9,0)) -> 0 | K15: =INDEX(Scenarios!$D$4:$D$9,MATCH($A15,Scenarios!$A$4:$A$9,0)) -> 0 | L15: =INDEX(Scenarios!$E$4:$E$9,MATCH($A15,Scenarios!$A$4:$A$9,0)) -> -0.048686824 | M15: =E15*(1+L15)+G15 -> 0.10673734 | N15: =M15+H15 -> 0.10673734 | O15: =I15*M15+J15*H15 -> 2.1347468 | P15: =MIN(K15,I15)*E15+MIN(K15,J15)*F15 -> 0 | Q15: =MAX(0,O15-P15)*D15/1000 -> 6.7909609 | R15: =IF(SUM($Q$11:$Q$17)=0,0,Q15/SUM($Q$11:$Q$17)) -> 0.013275576 | S15: =IF(Assumptions!$C$11="Yes",INDEX(Scenarios!$F$4:$F$9,MATCH($A15,Scenarios!$A$4:$A$9,0))*1000*R15/D15*1000,0) -> 0 | T15: =MAX(0,O15-P15-S15) -> 2.1347468 | U15: =Assumptions!$C$8*Assumptions!$C$5*(E15+F15) -> 11.22 | V15: =MAX(0,Assumptions!$C$8*Assumptions!$C$5*N15-Assumptions!$C$10*T15) -> 8.5389871 | W15: =C15*U15 -> 17952 | X15: =C15*V15 -> 13662.379 | Y15: =C15*Assumptions!$C$5*(E15+F15) -> 17952 | Z15: =C15*MAX(0,Assumptions!$C$5*N15-T15) -> 13662.379 | AA15: =C15*Assumptions!$C$7*Assumptions!$C$5*(E15+F15) -> 8706.72 | AB15: =C15*MAX(0,Assumptions!$C$7*Assumptions!$C$5*N15-IF(Assumptions!$C$9="Yes",Assumptions!$C$7,1)*T15) -> 4867.2226 | AC15: =C15*(E15+F15) -> 179.52 | AD15: =C15*N15 -> 170.77974
A16: 2A | B16: Ammonium nitrate | C16: 80 | D16: 681.30126 | E16: 0.1122 | F16: 0.9944125 | G16: 0 | H16: 0.9944125 | I16: =INDEX(Scenarios!$B$4:$B$9,MATCH($A16,Scenarios!$A$4:$A$9,0)) -> 20 | J16: =INDEX(Scenarios!$C$4:$C$9,MATCH($A16,Scenarios!$A$4:$A$9,0)) -> 0 | K16: =INDEX(Scenarios!$D$4:$D$9,MATCH($A16,Scenarios!$A$4:$A$9,0)) -> 0 | L16: =INDEX(Scenarios!$E$4:$E$9,MATCH($A16,Scenarios!$A$4:$A$9,0)) -> -0.048686824 | M16: =E16*(1+L16)+G16 -> 0.10673734 | N16: =M16+H16 -> 1.1011498 | O16: =I16*M16+J16*H16 -> 2.1347468 | P16: =MIN(K16,I16)*E16+MIN(K16,J16)*F16 -> 0 | Q16: =MAX(0,O16-P16)*D16/1000 -> 1.4544057 | R16: =IF(SUM($Q$11:$Q$17)=0,0,Q16/SUM($Q$11:$Q$17)) -> 0.002843202 | S16: =IF(Assumptions!$C$11="Yes",INDEX(Scenarios!$F$4:$F$9,MATCH($A16,Scenarios!$A$4:$A$9,0))*1000*R16/D16*1000,0) -> 0 | T16: =MAX(0,O16-P16-S16) -> 2.1347468 | U16: =Assumptions!$C$8*Assumptions!$C$5*(E16+F16) -> 110.66125 | V16: =MAX(0,Assumptions!$C$8*Assumptions!$C$5*N16-Assumptions!$C$10*T16) -> 107.98024 | W16: =C16*U16 -> 8852.9 | X16: =C16*V16 -> 8638.419 | Y16: =C16*Assumptions!$C$5*(E16+F16) -> 8852.9 | Z16: =C16*MAX(0,Assumptions!$C$5*N16-T16) -> 8638.419 | AA16: =C16*Assumptions!$C$7*Assumptions!$C$5*(E16+F16) -> 4293.6565 | AB16: =C16*MAX(0,Assumptions!$C$7*Assumptions!$C$5*N16-IF(Assumptions!$C$9="Yes",Assumptions!$C$7,1)*T16) -> 4101.6816 | AC16: =C16*(E16+F16) -> 88.529 | AD16: =C16*N16 -> 88.091987
A17: 2A | B17: Primary aluminium | C17: 167 | D17: 413.44029 | E17: 0.12342 | F17: 2.397493 | G17: 0 | H17: 2.397493 | I17: =INDEX(Scenarios!$B$4:$B$9,MATCH($A17,Scenarios!$A$4:$A$9,0)) -> 20 | J17: =INDEX(Scenarios!$C$4:$C$9,MATCH($A17,Scenarios!$A$4:$A$9,0)) -> 0 | K17: =INDEX(Scenarios!$D$4:$D$9,MATCH($A17,Scenarios!$A$4:$A$9,0)) -> 0 | L17: =INDEX(Scenarios!$E$4:$E$9,MATCH($A17,Scenarios!$A$4:$A$9,0)) -> -0.048686824 | M17: =E17*(1+L17)+G17 -> 0.11741107 | N17: =M17+H17 -> 2.5149041 | O17: =I17*M17+J17*H17 -> 2.3482214 | P17: =MIN(K17,I17)*E17+MIN(K17,J17)*F17 -> 0 | Q17: =MAX(0,O17-P17)*D17/1000 -> 0.97084934 | R17: =IF(SUM($Q$11:$Q$17)=0,0,Q17/SUM($Q$11:$Q$17)) -> 0.0018979029 | S17: =IF(Assumptions!$C$11="Yes",INDEX(Scenarios!$F$4:$F$9,MATCH($A17,Scenarios!$A$4:$A$9,0))*1000*R17/D17*1000,0) -> 0 | T17: =MAX(0,O17-P17-S17) -> 2.3482214 | U17: =Assumptions!$C$8*Assumptions!$C$5*(E17+F17) -> 252.0913 | V17: =MAX(0,Assumptions!$C$8*Assumptions!$C$5*N17-Assumptions!$C$10*T17) -> 249.14219 | W17: =C17*U17 -> 42099.248 | X17: =C17*V17 -> 41606.746 | Y17: =C17*Assumptions!$C$5*(E17+F17) -> 42099.248 | Z17: =C17*MAX(0,Assumptions!$C$5*N17-T17) -> 41606.746 | AA17: =C17*Assumptions!$C$7*Assumptions!$C$5*(E17+F17) -> 20418.135 | AB17: =C17*MAX(0,Assumptions!$C$7*Assumptions!$C$5*N17-IF(Assumptions!$C$9="Yes",Assumptions!$C$7,1)*T17) -> 19977.313 | AC17: =C17*(E17+F17) -> 420.99248 | AD17: =C17*N17 -> 419.98899
A18: 2B | B18: DRI-EAF steel | C18: 580 | D18: 6553.7778 | E18: 0.57099077 | F18: 0.03790102 | G18: 0 | H18: 0.03790102 | I18: =INDEX(Scenarios!$B$4:$B$9,MATCH($A18,Scenarios!$A$4:$A$9,0)) -> 20 | J18: =INDEX(Scenarios!$C$4:$C$9,MATCH($A18,Scenarios!$A$4:$A$9,0)) -> 0 | K18: =INDEX(Scenarios!$D$4:$D$9,MATCH($A18,Scenarios!$A$4:$A$9,0)) -> 0 | L18: =INDEX(Scenarios!$E$4:$E$9,MATCH($A18,Scenarios!$A$4:$A$9,0)) -> -0.051297883 | M18: =E18*(1+L18)+G18 -> 0.54170015 | N18: =M18+H18 -> 0.57960117 | O18: =I18*M18+J18*H18 -> 10.834003 | P18: =MIN(K18,I18)*E18+MIN(K18,J18)*F18 -> 0 | Q18: =MAX(0,O18-P18)*D18/1000 -> 71.003649 | R18: =IF(SUM($Q$18:$Q$24)=0,0,Q18/SUM($Q$18:$Q$24)) -> 0.13918629 | S18: =IF(Assumptions!$C$11="Yes",INDEX(Scenarios!$F$4:$F$9,MATCH($A18,Scenarios!$A$4:$A$9,0))*1000*R18/D18*1000,0) -> 0 | T18: =MAX(0,O18-P18-S18) -> 10.834003 | U18: =Assumptions!$C$8*Assumptions!$C$5*(E18+F18) -> 60.889179 | V18: =MAX(0,Assumptions!$C$8*Assumptions!$C$5*N18-Assumptions!$C$10*T18) -> 47.126114 | W18: =C18*U18 -> 35315.724 | X18: =C18*V18 -> 27333.146 | Y18: =C18*Assumptions!$C$5*(E18+F18) -> 35315.724 | Z18: =C18*MAX(0,Assumptions!$C$5*N18-T18) -> 27333.146 | AA18: =C18*Assumptions!$C$7*Assumptions!$C$5*(E18+F18) -> 17128.126 | AB18: =C18*MAX(0,Assumptions!$C$7*Assumptions!$C$5*N18-IF(Assumptions!$C$9="Yes",Assumptions!$C$7,1)*T18) -> 10020.459 | AC18: =C18*(E18+F18) -> 353.15724 | AD18: =C18*N18 -> 336.16868
A19: 2B | B19: Scrap-EAF steel | C19: 300 | D19: 6210.9464 | E19: 0.04488 | F19: 0.04398115 | G19: 0 | H19: 0.04398115 | I19: =INDEX(Scenarios!$B$4:$B$9,MATCH($A19,Scenarios!$A$4:$A$9,0)) -> 20 | J19: =INDEX(Scenarios!$C$4:$C$9,MATCH($A19,Scenarios!$A$4:$A$9,0)) -> 0 | K19: =INDEX(Scenarios!$D$4:$D$9,MATCH($A19,Scenarios!$A$4:$A$9,0)) -> 0 | L19: =INDEX(Scenarios!$E$4:$E$9,MATCH($A19,Scenarios!$A$4:$A$9,0)) -> -0.051297883 | M19: =E19*(1+L19)+G19 -> 0.042577751 | N19: =M19+H19 -> 0.086558901 | O19: =I19*M19+J19*H19 -> 0.85155502 | P19: =MIN(K19,I19)*E19+MIN(K19,J19)*F19 -> 0 | Q19: =MAX(0,O19-P19)*D19/1000 -> 5.2889626 | R19: =IF(SUM($Q$18:$Q$24)=0,0,Q19/SUM($Q$18:$Q$24)) -> 0.010367792 | S19: =IF(Assumptions!$C$11="Yes",INDEX(Scenarios!$F$4:$F$9,MATCH($A19,Scenarios!$A$4:$A$9,0))*1000*R19/D19*1000,0) -> 0 | T19: =MAX(0,O19-P19-S19) -> 0.85155502 | U19: =Assumptions!$C$8*Assumptions!$C$5*(E19+F19) -> 8.886115 | V19: =MAX(0,Assumptions!$C$8*Assumptions!$C$5*N19-Assumptions!$C$10*T19) -> 7.8043351 | W19: =C19*U19 -> 2665.8345 | X19: =C19*V19 -> 2341.3005 | Y19: =C19*Assumptions!$C$5*(E19+F19) -> 2665.8345 | Z19: =C19*MAX(0,Assumptions!$C$5*N19-T19) -> 2341.3005 | AA19: =C19*Assumptions!$C$7*Assumptions!$C$5*(E19+F19) -> 1292.9297 | AB19: =C19*MAX(0,Assumptions!$C$7*Assumptions!$C$5*N19-IF(Assumptions!$C$9="Yes",Assumptions!$C$7,1)*T19) -> 1003.9655 | AC19: =C19*(E19+F19) -> 26.658345 | AD19: =C19*N19 -> 25.96767
A20: 2B | B20: Grey clinker (dry-process) | C20: 800 | D20: 59092.434 | E20: 0.3135685 | F20: 0.53702616 | G20: 0 | H20: 0.53702616 | I20: =INDEX(Scenarios!$B$4:$B$9,MATCH($A20,Scenarios!$A$4:$A$9,0)) -> 20 | J20: =INDEX(Scenarios!$C$4:$C$9,MATCH($A20,Scenarios!$A$4:$A$9,0)) -> 0 | K20: =INDEX(Scenarios!$D$4:$D$9,MATCH($A20,Scenarios!$A$4:$A$9,0)) -> 0 | L20: =INDEX(Scenarios!$E$4:$E$9,MATCH($A20,Scenarios!$A$4:$A$9,0)) -> -0.051297883 | M20: =E20*(1+L20)+G20 -> 0.2974831 | N20: =M20+H20 -> 0.83450926 | O20: =I20*M20+J20*H20 -> 5.949662 | P20: =MIN(K20,I20)*E20+MIN(K20,J20)*F20 -> 0 | Q20: =MAX(0,O20-P20)*D20/1000 -> 351.58001 | R20: =IF(SUM($Q$18:$Q$24)=0,0,Q20/SUM($Q$18:$Q$24)) -> 0.68919159 | S20: =IF(Assumptions!$C$11="Yes",INDEX(Scenarios!$F$4:$F$9,MATCH($A20,Scenarios!$A$4:$A$9,0))*1000*R20/D20*1000,0) -> 0 | T20: =MAX(0,O20-P20-S20) -> 5.949662 | U20: =Assumptions!$C$8*Assumptions!$C$5*(E20+F20) -> 85.059466 | V20: =MAX(0,Assumptions!$C$8*Assumptions!$C$5*N20-Assumptions!$C$10*T20) -> 77.501264 | W20: =C20*U20 -> 68047.573 | X20: =C20*V20 -> 62001.011 | Y20: =C20*Assumptions!$C$5*(E20+F20) -> 68047.573 | Z20: =C20*MAX(0,Assumptions!$C$5*N20-T20) -> 62001.011 | AA20: =C20*Assumptions!$C$7*Assumptions!$C$5*(E20+F20) -> 33003.073 | AB20: =C20*MAX(0,Assumptions!$C$7*Assumptions!$C$5*N20-IF(Assumptions!$C$9="Yes",Assumptions!$C$7,1)*T20) -> 27619.23 | AC20: =C20*(E20+F20) -> 680.47573 | AD20: =C20*N20 -> 667.60741
A21: 2B | B21: Ammonia (net) | C21: 120 | D21: 1950.1858 | E21: 1.97472 | F21: 0 | G21: 0 | H21: 0 | I21: =INDEX(Scenarios!$B$4:$B$9,MATCH($A21,Scenarios!$A$4:$A$9,0)) -> 20 | J21: =INDEX(Scenarios!$C$4:$C$9,MATCH($A21,Scenarios!$A$4:$A$9,0)) -> 0 | K21: =INDEX(Scenarios!$D$4:$D$9,MATCH($A21,Scenarios!$A$4:$A$9,0)) -> 0 | L21: =INDEX(Scenarios!$E$4:$E$9,MATCH($A21,Scenarios!$A$4:$A$9,0)) -> -0.051297883 | M21: =E21*(1+L21)+G21 -> 1.873421 | N21: =M21+H21 -> 1.873421 | O21: =I21*M21+J21*H21 -> 37.468421 | P21: =MIN(K21,I21)*E21+MIN(K21,J21)*F21 -> 0 | Q21: =MAX(0,O21-P21)*D21/1000 -> 73.070382 | R21: =IF(SUM($Q$18:$Q$24)=0,0,Q21/SUM($Q$18:$Q$24)) -> 0.14323765 | S21: =IF(Assumptions!$C$11="Yes",INDEX(Scenarios!$F$4:$F$9,MATCH($A21,Scenarios!$A$4:$A$9,0))*1000*R21/D21*1000,0) -> 0 | T21: =MAX(0,O21-P21-S21) -> 37.468421 | U21: =Assumptions!$C$8*Assumptions!$C$5*(E21+F21) -> 197.472 | V21: =MAX(0,Assumptions!$C$8*Assumptions!$C$5*N21-Assumptions!$C$10*T21) -> 149.87368 | W21: =C21*U21 -> 23696.64 | X21: =C21*V21 -> 17984.842 | Y21: =C21*Assumptions!$C$5*(E21+F21) -> 23696.64 | Z21: =C21*MAX(0,Assumptions!$C$5*N21-T21) -> 17984.842 | AA21: =C21*Assumptions!$C$7*Assumptions!$C$5*(E21+F21) -> 11492.87 | AB21: =C21*MAX(0,Assumptions!$C$7*Assumptions!$C$5*N21-IF(Assumptions!$C$9="Yes",Assumptions!$C$7,1)*T21) -> 6407.1 | AC21: =C21*(E21+F21) -> 236.9664 | AD21: =C21*N21 -> 224.81053
A22: 2B | B22: Urea | C22: 1600 | D22: 3181.1553 | E22: 0.1122 | F22: 0 | G22: 0 | H22: 0 | I22: =INDEX(Scenarios!$B$4:$B$9,MATCH($A22,Scenarios!$A$4:$A$9,0)) -> 20 | J22: =INDEX(Scenarios!$C$4:$C$9,MATCH($A22,Scenarios!$A$4:$A$9,0)) -> 0 | K22: =INDEX(Scenarios!$D$4:$D$9,MATCH($A22,Scenarios!$A$4:$A$9,0)) -> 0 | L22: =INDEX(Scenarios!$E$4:$E$9,MATCH($A22,Scenarios!$A$4:$A$9,0)) -> -0.051297883 | M22: =E22*(1+L22)+G22 -> 0.10644438 | N22: =M22+H22 -> 0.10644438 | O22: =I22*M22+J22*H22 -> 2.1288875 | P22: =MIN(K22,I22)*E22+MIN(K22,J22)*F22 -> 0 | Q22: =MAX(0,O22-P22)*D22/1000 -> 6.7723218 | R22: =IF(SUM($Q$18:$Q$24)=0,0,Q22/SUM($Q$18:$Q$24)) -> 0.013275576 | S22: =IF(Assumptions!$C$11="Yes",INDEX(Scenarios!$F$4:$F$9,MATCH($A22,Scenarios!$A$4:$A$9,0))*1000*R22/D22*1000,0) -> 0 | T22: =MAX(0,O22-P22-S22) -> 2.1288875 | U22: =Assumptions!$C$8*Assumptions!$C$5*(E22+F22) -> 11.22 | V22: =MAX(0,Assumptions!$C$8*Assumptions!$C$5*N22-Assumptions!$C$10*T22) -> 8.5155502 | W22: =C22*U22 -> 17952 | X22: =C22*V22 -> 13624.88 | Y22: =C22*Assumptions!$C$5*(E22+F22) -> 17952 | Z22: =C22*MAX(0,Assumptions!$C$5*N22-T22) -> 13624.88 | AA22: =C22*Assumptions!$C$7*Assumptions!$C$5*(E22+F22) -> 8706.72 | AB22: =C22*MAX(0,Assumptions!$C$7*Assumptions!$C$5*N22-IF(Assumptions!$C$9="Yes",Assumptions!$C$7,1)*T22) -> 4853.8636 | AC22: =C22*(E22+F22) -> 179.52 | AD22: =C22*N22 -> 170.311
A23: 2B | B23: Ammonium nitrate | C23: 80 | D23: 681.30126 | E23: 0.1122 | F23: 0.9944125 | G23: 0 | H23: 0.9944125 | I23: =INDEX(Scenarios!$B$4:$B$9,MATCH($A23,Scenarios!$A$4:$A$9,0)) -> 20 | J23: =INDEX(Scenarios!$C$4:$C$9,MATCH($A23,Scenarios!$A$4:$A$9,0)) -> 0 | K23: =INDEX(Scenarios!$D$4:$D$9,MATCH($A23,Scenarios!$A$4:$A$9,0)) -> 0 | L23: =INDEX(Scenarios!$E$4:$E$9,MATCH($A23,Scenarios!$A$4:$A$9,0)) -> -0.051297883 | M23: =E23*(1+L23)+G23 -> 0.10644438 | N23: =M23+H23 -> 1.1008569 | O23: =I23*M23+J23*H23 -> 2.1288875 | P23: =MIN(K23,I23)*E23+MIN(K23,J23)*F23 -> 0 | Q23: =MAX(0,O23-P23)*D23/1000 -> 1.4504138 | R23: =IF(SUM($Q$18:$Q$24)=0,0,Q23/SUM($Q$18:$Q$24)) -> 0.002843202 | S23: =IF(Assumptions!$C$11="Yes",INDEX(Scenarios!$F$4:$F$9,MATCH($A23,Scenarios!$A$4:$A$9,0))*1000*R23/D23*1000,0) -> 0 | T23: =MAX(0,O23-P23-S23) -> 2.1288875 | U23: =Assumptions!$C$8*Assumptions!$C$5*(E23+F23) -> 110.66125 | V23: =MAX(0,Assumptions!$C$8*Assumptions!$C$5*N23-Assumptions!$C$10*T23) -> 107.9568 | W23: =C23*U23 -> 8852.9 | X23: =C23*V23 -> 8636.544 | Y23: =C23*Assumptions!$C$5*(E23+F23) -> 8852.9 | Z23: =C23*MAX(0,Assumptions!$C$5*N23-T23) -> 8636.544 | AA23: =C23*Assumptions!$C$7*Assumptions!$C$5*(E23+F23) -> 4293.6565 | AB23: =C23*MAX(0,Assumptions!$C$7*Assumptions!$C$5*N23-IF(Assumptions!$C$9="Yes",Assumptions!$C$7,1)*T23) -> 4101.0137 | AC23: =C23*(E23+F23) -> 88.529 | AD23: =C23*N23 -> 88.06855
A24: 2B | B24: Primary aluminium | C24: 167 | D24: 413.44029 | E24: 0.12342 | F24: 2.397493 | G24: 0 | H24: 2.397493 | I24: =INDEX(Scenarios!$B$4:$B$9,MATCH($A24,Scenarios!$A$4:$A$9,0)) -> 20 | J24: =INDEX(Scenarios!$C$4:$C$9,MATCH($A24,Scenarios!$A$4:$A$9,0)) -> 0 | K24: =INDEX(Scenarios!$D$4:$D$9,MATCH($A24,Scenarios!$A$4:$A$9,0)) -> 0 | L24: =INDEX(Scenarios!$E$4:$E$9,MATCH($A24,Scenarios!$A$4:$A$9,0)) -> -0.051297883 | M24: =E24*(1+L24)+G24 -> 0.11708882 | N24: =M24+H24 -> 2.5145819 | O24: =I24*M24+J24*H24 -> 2.3417763 | P24: =MIN(K24,I24)*E24+MIN(K24,J24)*F24 -> 0 | Q24: =MAX(0,O24-P24)*D24/1000 -> 0.96818466 | R24: =IF(SUM($Q$18:$Q$24)=0,0,Q24/SUM($Q$18:$Q$24)) -> 0.0018979029 | S24: =IF(Assumptions!$C$11="Yes",INDEX(Scenarios!$F$4:$F$9,MATCH($A24,Scenarios!$A$4:$A$9,0))*1000*R24/D24*1000,0) -> 0 | T24: =MAX(0,O24-P24-S24) -> 2.3417763 | U24: =Assumptions!$C$8*Assumptions!$C$5*(E24+F24) -> 252.0913 | V24: =MAX(0,Assumptions!$C$8*Assumptions!$C$5*N24-Assumptions!$C$10*T24) -> 249.11641 | W24: =C24*U24 -> 42099.248 | X24: =C24*V24 -> 41602.44 | Y24: =C24*Assumptions!$C$5*(E24+F24) -> 42099.248 | Z24: =C24*MAX(0,Assumptions!$C$5*N24-T24) -> 41602.44 | AA24: =C24*Assumptions!$C$7*Assumptions!$C$5*(E24+F24) -> 20418.135 | AB24: =C24*MAX(0,Assumptions!$C$7*Assumptions!$C$5*N24-IF(Assumptions!$C$9="Yes",Assumptions!$C$7,1)*T24) -> 19975.779 | AC24: =C24*(E24+F24) -> 420.99248 | AD24: =C24*N24 -> 419.93517
A25: 3A | B25: DRI-EAF steel | C25: 580 | D25: 6550.518 | E25: 0.57099077 | F25: 0.03790102 | G25: 0 | H25: 0.035376191 | I25: =INDEX(Scenarios!$B$4:$B$9,MATCH($A25,Scenarios!$A$4:$A$9,0)) -> 20 | J25: =INDEX(Scenarios!$C$4:$C$9,MATCH($A25,Scenarios!$A$4:$A$9,0)) -> 20 | K25: =INDEX(Scenarios!$D$4:$D$9,MATCH($A25,Scenarios!$A$4:$A$9,0)) -> 0 | L25: =INDEX(Scenarios!$E$4:$E$9,MATCH($A25,Scenarios!$A$4:$A$9,0)) -> -0.048686824 | M25: =E25*(1+L25)+G25 -> 0.54319104 | N25: =M25+H25 -> 0.57856723 | O25: =I25*M25+J25*H25 -> 11.571345 | P25: =MIN(K25,I25)*E25+MIN(K25,J25)*F25 -> 0 | Q25: =MAX(0,O25-P25)*D25/1000 -> 75.798301 | R25: =IF(SUM($Q$25:$Q$31)=0,0,Q25/SUM($Q$25:$Q$31)) -> 0.068647678 | S25: =IF(Assumptions!$C$11="Yes",INDEX(Scenarios!$F$4:$F$9,MATCH($A25,Scenarios!$A$4:$A$9,0))*1000*R25/D25*1000,0) -> 0 | T25: =MAX(0,O25-P25-S25) -> 11.571345 | U25: =Assumptions!$C$8*Assumptions!$C$5*(E25+F25) -> 60.889179 | V25: =MAX(0,Assumptions!$C$8*Assumptions!$C$5*N25-Assumptions!$C$10*T25) -> 46.285379 | W25: =C25*U25 -> 35315.724 | X25: =C25*V25 -> 26845.52 | Y25: =C25*Assumptions!$C$5*(E25+F25) -> 35315.724 | Z25: =C25*MAX(0,Assumptions!$C$5*N25-T25) -> 26845.52 | AA25: =C25*Assumptions!$C$7*Assumptions!$C$5*(E25+F25) -> 17128.126 | AB25: =C25*MAX(0,Assumptions!$C$7*Assumptions!$C$5*N25-IF(Assumptions!$C$9="Yes",Assumptions!$C$7,1)*T25) -> 9563.7164 | AC25: =C25*(E25+F25) -> 353.15724 | AD25: =C25*N25 -> 335.569
A26: 3A | B26: Scrap-EAF steel | C26: 300 | D26: 6206.9385 | E26: 0.04488 | F26: 0.04398115 | G26: 0 | H26: 0.042564823 | I26: =INDEX(Scenarios!$B$4:$B$9,MATCH($A26,Scenarios!$A$4:$A$9,0)) -> 20 | J26: =INDEX(Scenarios!$C$4:$C$9,MATCH($A26,Scenarios!$A$4:$A$9,0)) -> 20 | K26: =INDEX(Scenarios!$D$4:$D$9,MATCH($A26,Scenarios!$A$4:$A$9,0)) -> 0 | L26: =INDEX(Scenarios!$E$4:$E$9,MATCH($A26,Scenarios!$A$4:$A$9,0)) -> -0.048686824 | M26: =E26*(1+L26)+G26 -> 0.042694935 | N26: =M26+H26 -> 0.085259758 | O26: =I26*M26+J26*H26 -> 1.7051952 | P26: =MIN(K26,I26)*E26+MIN(K26,J26)*F26 -> 0 | Q26: =MAX(0,O26-P26)*D26/1000 -> 10.584041 | R26: =IF(SUM($Q$25:$Q$31)=0,0,Q26/SUM($Q$25:$Q$31)) -> 0.0095855693 | S26: =IF(Assumptions!$C$11="Yes",INDEX(Scenarios!$F$4:$F$9,MATCH($A26,Scenarios!$A$4:$A$9,0))*1000*R26/D26*1000,0) -> 0 | T26: =MAX(0,O26-P26-S26) -> 1.7051952 | U26: =Assumptions!$C$8*Assumptions!$C$5*(E26+F26) -> 8.886115 | V26: =MAX(0,Assumptions!$C$8*Assumptions!$C$5*N26-Assumptions!$C$10*T26) -> 6.8207806 | W26: =C26*U26 -> 2665.8345 | X26: =C26*V26 -> 2046.2342 | Y26: =C26*Assumptions!$C$5*(E26+F26) -> 2665.8345 | Z26: =C26*MAX(0,Assumptions!$C$5*N26-T26) -> 2046.2342 | AA26: =C26*Assumptions!$C$7*Assumptions!$C$5*(E26+F26) -> 1292.9297 | AB26: =C26*MAX(0,Assumptions!$C$7*Assumptions!$C$5*N26-IF(Assumptions!$C$9="Yes",Assumptions!$C$7,1)*T26) -> 728.97093 | AC26: =C26*(E26+F26) -> 26.658345 | AD26: =C26*N26 -> 25.577927
A27: 3A | B27: Grey clinker (dry-process) | C27: 800 | D27: 56538.734 | E27: 0.3135685 | F27: 0.53702616 | G27: 0 | H27: 0.50225977 | I27: =INDEX(Scenarios!$B$4:$B$9,MATCH($A27,Scenarios!$A$4:$A$9,0)) -> 20 | J27: =INDEX(Scenarios!$C$4:$C$9,MATCH($A27,Scenarios!$A$4:$A$9,0)) -> 20 | K27: =INDEX(Scenarios!$D$4:$D$9,MATCH($A27,Scenarios!$A$4:$A$9,0)) -> 0 | L27: =INDEX(Scenarios!$E$4:$E$9,MATCH($A27,Scenarios!$A$4:$A$9,0)) -> -0.048686824 | M27: =E27*(1+L27)+G27 -> 0.29830185 | N27: =M27+H27 -> 0.80056162 | O27: =I27*M27+J27*H27 -> 16.011232 | P27: =MIN(K27,I27)*E27+MIN(K27,J27)*F27 -> 0 | Q27: =MAX(0,O27-P27)*D27/1000 -> 905.25481 | R27: =IF(SUM($Q$25:$Q$31)=0,0,Q27/SUM($Q$25:$Q$31)) -> 0.81985532 | S27: =IF(Assumptions!$C$11="Yes",INDEX(Scenarios!$F$4:$F$9,MATCH($A27,Scenarios!$A$4:$A$9,0))*1000*R27/D27*1000,0) -> 0 | T27: =MAX(0,O27-P27-S27) -> 16.011232 | U27: =Assumptions!$C$8*Assumptions!$C$5*(E27+F27) -> 85.059466 | V27: =MAX(0,Assumptions!$C$8*Assumptions!$C$5*N27-Assumptions!$C$10*T27) -> 64.044929 | W27: =C27*U27 -> 68047.573 | X27: =C27*V27 -> 51235.943 | Y27: =C27*Assumptions!$C$5*(E27+F27) -> 68047.573 | Z27: =C27*MAX(0,Assumptions!$C$5*N27-T27) -> 51235.943 | AA27: =C27*Assumptions!$C$7*Assumptions!$C$5*(E27+F27) -> 33003.073 | AB27: =C27*MAX(0,Assumptions!$C$7*Assumptions!$C$5*N27-IF(Assumptions!$C$9="Yes",Assumptions!$C$7,1)*T27) -> 18252.805 | AC27: =C27*(E27+F27) -> 680.47573 | AD27: =C27*N27 -> 640.44929
A28: 3A | B28: Ammonia (net) | C28: 120 | D28: 1950.1858 | E28: 1.97472 | F28: 0 | G28: 0 | H28: 0 | I28: =INDEX(Scenarios!$B$4:$B$9,MATCH($A28,Scenarios!$A$4:$A$9,0)) -> 20 | J28: =INDEX(Scenarios!$C$4:$C$9,MATCH($A28,Scenarios!$A$4:$A$9,0)) -> 20 | K28: =INDEX(Scenarios!$D$4:$D$9,MATCH($A28,Scenarios!$A$4:$A$9,0)) -> 0 | L28: =INDEX(Scenarios!$E$4:$E$9,MATCH($A28,Scenarios!$A$4:$A$9,0)) -> -0.048686824 | M28: =E28*(1+L28)+G28 -> 1.8785772 | N28: =M28+H28 -> 1.8785772 | O28: =I28*M28+J28*H28 -> 37.571543 | P28: =MIN(K28,I28)*E28+MIN(K28,J28)*F28 -> 0 | Q28: =MAX(0,O28-P28)*D28/1000 -> 73.27149 | R28: =IF(SUM($Q$25:$Q$31)=0,0,Q28/SUM($Q$25:$Q$31)) -> 0.066359239 | S28: =IF(Assumptions!$C$11="Yes",INDEX(Scenarios!$F$4:$F$9,MATCH($A28,Scenarios!$A$4:$A$9,0))*1000*R28/D28*1000,0) -> 0 | T28: =MAX(0,O28-P28-S28) -> 37.571543 | U28: =Assumptions!$C$8*Assumptions!$C$5*(E28+F28) -> 197.472 | V28: =MAX(0,Assumptions!$C$8*Assumptions!$C$5*N28-Assumptions!$C$10*T28) -> 150.28617 | W28: =C28*U28 -> 23696.64 | X28: =C28*V28 -> 18034.341 | Y28: =C28*Assumptions!$C$5*(E28+F28) -> 23696.64 | Z28: =C28*MAX(0,Assumptions!$C$5*N28-T28) -> 18034.341 | AA28: =C28*Assumptions!$C$7*Assumptions!$C$5*(E28+F28) -> 11492.87 | AB28: =C28*MAX(0,Assumptions!$C$7*Assumptions!$C$5*N28-IF(Assumptions!$C$9="Yes",Assumptions!$C$7,1)*T28) -> 6424.7339 | AC28: =C28*(E28+F28) -> 236.9664 | AD28: =C28*N28 -> 225.42926
A29: 3A | B29: Urea | C29: 1600 | D29: 3181.1553 | E29: 0.1122 | F29: 0 | G29: 0 | H29: 0 | I29: =INDEX(Scenarios!$B$4:$B$9,MATCH($A29,Scenarios!$A$4:$A$9,0)) -> 20 | J29: =INDEX(Scenarios!$C$4:$C$9,MATCH($A29,Scenarios!$A$4:$A$9,0)) -> 20 | K29: =INDEX(Scenarios!$D$4:$D$9,MATCH($A29,Scenarios!$A$4:$A$9,0)) -> 0 | L29: =INDEX(Scenarios!$E$4:$E$9,MATCH($A29,Scenarios!$A$4:$A$9,0)) -> -0.048686824 | M29: =E29*(1+L29)+G29 -> 0.10673734 | N29: =M29+H29 -> 0.10673734 | O29: =I29*M29+J29*H29 -> 2.1347468 | P29: =MIN(K29,I29)*E29+MIN(K29,J29)*F29 -> 0 | Q29: =MAX(0,O29-P29)*D29/1000 -> 6.7909609 | R29: =IF(SUM($Q$25:$Q$31)=0,0,Q29/SUM($Q$25:$Q$31)) -> 0.0061503185 | S29: =IF(Assumptions!$C$11="Yes",INDEX(Scenarios!$F$4:$F$9,MATCH($A29,Scenarios!$A$4:$A$9,0))*1000*R29/D29*1000,0) -> 0 | T29: =MAX(0,O29-P29-S29) -> 2.1347468 | U29: =Assumptions!$C$8*Assumptions!$C$5*(E29+F29) -> 11.22 | V29: =MAX(0,Assumptions!$C$8*Assumptions!$C$5*N29-Assumptions!$C$10*T29) -> 8.5389871 | W29: =C29*U29 -> 17952 | X29: =C29*V29 -> 13662.379 | Y29: =C29*Assumptions!$C$5*(E29+F29) -> 17952 | Z29: =C29*MAX(0,Assumptions!$C$5*N29-T29) -> 13662.379 | AA29: =C29*Assumptions!$C$7*Assumptions!$C$5*(E29+F29) -> 8706.72 | AB29: =C29*MAX(0,Assumptions!$C$7*Assumptions!$C$5*N29-IF(Assumptions!$C$9="Yes",Assumptions!$C$7,1)*T29) -> 4867.2226 | AC29: =C29*(E29+F29) -> 179.52 | AD29: =C29*N29 -> 170.77974
A30: 3A | B30: Ammonium nitrate | C30: 80 | D30: 661.20268 | E30: 0.1122 | F30: 0.9944125 | G30: 0 | H30: 0.84931933 | I30: =INDEX(Scenarios!$B$4:$B$9,MATCH($A30,Scenarios!$A$4:$A$9,0)) -> 20 | J30: =INDEX(Scenarios!$C$4:$C$9,MATCH($A30,Scenarios!$A$4:$A$9,0)) -> 20 | K30: =INDEX(Scenarios!$D$4:$D$9,MATCH($A30,Scenarios!$A$4:$A$9,0)) -> 0 | L30: =INDEX(Scenarios!$E$4:$E$9,MATCH($A30,Scenarios!$A$4:$A$9,0)) -> -0.048686824 | M30: =E30*(1+L30)+G30 -> 0.10673734 | N30: =M30+H30 -> 0.95605667 | O30: =I30*M30+J30*H30 -> 19.121133 | P30: =MIN(K30,I30)*E30+MIN(K30,J30)*F30 -> 0 | Q30: =MAX(0,O30-P30)*D30/1000 -> 12.642945 | R30: =IF(SUM($Q$25:$Q$31)=0,0,Q30/SUM($Q$25:$Q$31)) -> 0.011450241 | S30: =IF(Assumptions!$C$11="Yes",INDEX(Scenarios!$F$4:$F$9,MATCH($A30,Scenarios!$A$4:$A$9,0))*1000*R30/D30*1000,0) -> 0 | T30: =MAX(0,O30-P30-S30) -> 19.121133 | U30: =Assumptions!$C$8*Assumptions!$C$5*(E30+F30) -> 110.66125 | V30: =MAX(0,Assumptions!$C$8*Assumptions!$C$5*N30-Assumptions!$C$10*T30) -> 76.484533 | W30: =C30*U30 -> 8852.9 | X30: =C30*V30 -> 6118.7627 | Y30: =C30*Assumptions!$C$5*(E30+F30) -> 8852.9 | Z30: =C30*MAX(0,Assumptions!$C$5*N30-T30) -> 6118.7627 | AA30: =C30*Assumptions!$C$7*Assumptions!$C$5*(E30+F30) -> 4293.6565 | AB30: =C30*MAX(0,Assumptions!$C$7*Assumptions!$C$5*N30-IF(Assumptions!$C$9="Yes",Assumptions!$C$7,1)*T30) -> 2179.8092 | AC30: =C30*(E30+F30) -> 88.529 | AD30: =C30*N30 -> 76.484533
A31: 3A | B31: Primary aluminium | C31: 167 | D31: 409.37519 | E31: 0.12342 | F31: 2.397493 | G31: 0 | H31: 2.3035401 | I31: =INDEX(Scenarios!$B$4:$B$9,MATCH($A31,Scenarios!$A$4:$A$9,0)) -> 20 | J31: =INDEX(Scenarios!$C$4:$C$9,MATCH($A31,Scenarios!$A$4:$A$9,0)) -> 20 | K31: =INDEX(Scenarios!$D$4:$D$9,MATCH($A31,Scenarios!$A$4:$A$9,0)) -> 0 | L31: =INDEX(Scenarios!$E$4:$E$9,MATCH($A31,Scenarios!$A$4:$A$9,0)) -> -0.048686824 | M31: =E31*(1+L31)+G31 -> 0.11741107 | N31: =M31+H31 -> 2.4209512 | O31: =I31*M31+J31*H31 -> 48.419024 | P31: =MIN(K31,I31)*E31+MIN(K31,J31)*F31 -> 0 | Q31: =MAX(0,O31-P31)*D31/1000 -> 19.821548 | R31: =IF(SUM($Q$25:$Q$31)=0,0,Q31/SUM($Q$25:$Q$31)) -> 0.017951632 | S31: =IF(Assumptions!$C$11="Yes",INDEX(Scenarios!$F$4:$F$9,MATCH($A31,Scenarios!$A$4:$A$9,0))*1000*R31/D31*1000,0) -> 0 | T31: =MAX(0,O31-P31-S31) -> 48.419024 | U31: =Assumptions!$C$8*Assumptions!$C$5*(E31+F31) -> 252.0913 | V31: =MAX(0,Assumptions!$C$8*Assumptions!$C$5*N31-Assumptions!$C$10*T31) -> 193.6761 | W31: =C31*U31 -> 42099.248 | X31: =C31*V31 -> 32343.908 | Y31: =C31*Assumptions!$C$5*(E31+F31) -> 42099.248 | Z31: =C31*MAX(0,Assumptions!$C$5*N31-T31) -> 32343.908 | AA31: =C31*Assumptions!$C$7*Assumptions!$C$5*(E31+F31) -> 20418.135 | AB31: =C31*MAX(0,Assumptions!$C$7*Assumptions!$C$5*N31-IF(Assumptions!$C$9="Yes",Assumptions!$C$7,1)*T31) -> 11522.517 | AC31: =C31*(E31+F31) -> 420.99248 | AD31: =C31*N31 -> 404.29885
A32: 3B | B32: DRI-EAF steel | C32: 580 | D32: 6603.4846 | E32: 0.57099077 | F32: 0.03790102 | G32: 0 | H32: 0.035376191 | I32: =INDEX(Scenarios!$B$4:$B$9,MATCH($A32,Scenarios!$A$4:$A$9,0)) -> 20 | J32: =INDEX(Scenarios!$C$4:$C$9,MATCH($A32,Scenarios!$A$4:$A$9,0)) -> 20 | K32: =INDEX(Scenarios!$D$4:$D$9,MATCH($A32,Scenarios!$A$4:$A$9,0)) -> 20 | L32: =INDEX(Scenarios!$E$4:$E$9,MATCH($A32,Scenarios!$A$4:$A$9,0)) -> -0.048686824 | M32: =E32*(1+L32)+G32 -> 0.54319104 | N32: =M32+H32 -> 0.57856723 | O32: =I32*M32+J32*H32 -> 11.571345 | P32: =MIN(K32,I32)*E32+MIN(K32,J32)*F32 -> 12.177836 | Q32: =MAX(0,O32-P32)*D32/1000 -> 0 | R32: =IF(SUM($Q$32:$Q$38)=0,0,Q32/SUM($Q$32:$Q$38)) -> 0 | S32: =IF(Assumptions!$C$11="Yes",INDEX(Scenarios!$F$4:$F$9,MATCH($A32,Scenarios!$A$4:$A$9,0))*1000*R32/D32*1000,0) -> 0 | T32: =MAX(0,O32-P32-S32) -> 0 | U32: =Assumptions!$C$8*Assumptions!$C$5*(E32+F32) -> 60.889179 | V32: =MAX(0,Assumptions!$C$8*Assumptions!$C$5*N32-Assumptions!$C$10*T32) -> 57.856723 | W32: =C32*U32 -> 35315.724 | X32: =C32*V32 -> 33556.9 | Y32: =C32*Assumptions!$C$5*(E32+F32) -> 35315.724 | Z32: =C32*MAX(0,Assumptions!$C$5*N32-T32) -> 33556.9 | AA32: =C32*Assumptions!$C$7*Assumptions!$C$5*(E32+F32) -> 17128.126 | AB32: =C32*MAX(0,Assumptions!$C$7*Assumptions!$C$5*N32-IF(Assumptions!$C$9="Yes",Assumptions!$C$7,1)*T32) -> 16275.096 | AC32: =C32*(E32+F32) -> 353.15724 | AD32: =C32*N32 -> 335.569
A33: 3B | B33: Scrap-EAF steel | C33: 300 | D33: 6215.0443 | E33: 0.04488 | F33: 0.04398115 | G33: 0 | H33: 0.042564823 | I33: =INDEX(Scenarios!$B$4:$B$9,MATCH($A33,Scenarios!$A$4:$A$9,0)) -> 20 | J33: =INDEX(Scenarios!$C$4:$C$9,MATCH($A33,Scenarios!$A$4:$A$9,0)) -> 20 | K33: =INDEX(Scenarios!$D$4:$D$9,MATCH($A33,Scenarios!$A$4:$A$9,0)) -> 20 | L33: =INDEX(Scenarios!$E$4:$E$9,MATCH($A33,Scenarios!$A$4:$A$9,0)) -> -0.048686824 | M33: =E33*(1+L33)+G33 -> 0.042694935 | N33: =M33+H33 -> 0.085259758 | O33: =I33*M33+J33*H33 -> 1.7051952 | P33: =MIN(K33,I33)*E33+MIN(K33,J33)*F33 -> 1.777223 | Q33: =MAX(0,O33-P33)*D33/1000 -> 0 | R33: =IF(SUM($Q$32:$Q$38)=0,0,Q33/SUM($Q$32:$Q$38)) -> 0 | S33: =IF(Assumptions!$C$11="Yes",INDEX(Scenarios!$F$4:$F$9,MATCH($A33,Scenarios!$A$4:$A$9,0))*1000*R33/D33*1000,0) -> 0 | T33: =MAX(0,O33-P33-S33) -> 0 | U33: =Assumptions!$C$8*Assumptions!$C$5*(E33+F33) -> 8.886115 | V33: =MAX(0,Assumptions!$C$8*Assumptions!$C$5*N33-Assumptions!$C$10*T33) -> 8.5259758 | W33: =C33*U33 -> 2665.8345 | X33: =C33*V33 -> 2557.7927 | Y33: =C33*Assumptions!$C$5*(E33+F33) -> 2665.8345 | Z33: =C33*MAX(0,Assumptions!$C$5*N33-T33) -> 2557.7927 | AA33: =C33*Assumptions!$C$7*Assumptions!$C$5*(E33+F33) -> 1292.9297 | AB33: =C33*MAX(0,Assumptions!$C$7*Assumptions!$C$5*N33-IF(Assumptions!$C$9="Yes",Assumptions!$C$7,1)*T33) -> 1240.5295 | AC33: =C33*(E33+F33) -> 26.658345 | AD33: =C33*N33 -> 25.577927
A34: 3B | B34: Grey clinker (dry-process) | C34: 800 | D34: 60753.588 | E34: 0.3135685 | F34: 0.53702616 | G34: 0 | H34: 0.50225977 | I34: =INDEX(Scenarios!$B$4:$B$9,MATCH($A34,Scenarios!$A$4:$A$9,0)) -> 20 | J34: =INDEX(Scenarios!$C$4:$C$9,MATCH($A34,Scenarios!$A$4:$A$9,0)) -> 20 | K34: =INDEX(Scenarios!$D$4:$D$9,MATCH($A34,Scenarios!$A$4:$A$9,0)) -> 20 | L34: =INDEX(Scenarios!$E$4:$E$9,MATCH($A34,Scenarios!$A$4:$A$9,0)) -> -0.048686824 | M34: =E34*(1+L34)+G34 -> 0.29830185 | N34: =M34+H34 -> 0.80056162 | O34: =I34*M34+J34*H34 -> 16.011232 | P34: =MIN(K34,I34)*E34+MIN(K34,J34)*F34 -> 17.011893 | Q34: =MAX(0,O34-P34)*D34/1000 -> 0 | R34: =IF(SUM($Q$32:$Q$38)=0,0,Q34/SUM($Q$32:$Q$38)) -> 0 | S34: =IF(Assumptions!$C$11="Yes",INDEX(Scenarios!$F$4:$F$9,MATCH($A34,Scenarios!$A$4:$A$9,0))*1000*R34/D34*1000,0) -> 0 | T34: =MAX(0,O34-P34-S34) -> 0 | U34: =Assumptions!$C$8*Assumptions!$C$5*(E34+F34) -> 85.059466 | V34: =MAX(0,Assumptions!$C$8*Assumptions!$C$5*N34-Assumptions!$C$10*T34) -> 80.056162 | W34: =C34*U34 -> 68047.573 | X34: =C34*V34 -> 64044.929 | Y34: =C34*Assumptions!$C$5*(E34+F34) -> 68047.573 | Z34: =C34*MAX(0,Assumptions!$C$5*N34-T34) -> 64044.929 | AA34: =C34*Assumptions!$C$7*Assumptions!$C$5*(E34+F34) -> 33003.073 | AB34: =C34*MAX(0,Assumptions!$C$7*Assumptions!$C$5*N34-IF(Assumptions!$C$9="Yes",Assumptions!$C$7,1)*T34) -> 31061.791 | AC34: =C34*(E34+F34) -> 680.47573 | AD34: =C34*N34 -> 640.44929
A35: 3B | B35: Ammonia (net) | C35: 120 | D35: 2033.9656 | E35: 1.97472 | F35: 0 | G35: 0 | H35: 0 | I35: =INDEX(Scenarios!$B$4:$B$9,MATCH($A35,Scenarios!$A$4:$A$9,0)) -> 20 | J35: =INDEX(Scenarios!$C$4:$C$9,MATCH($A35,Scenarios!$A$4:$A$9,0)) -> 20 | K35: =INDEX(Scenarios!$D$4:$D$9,MATCH($A35,Scenarios!$A$4:$A$9,0)) -> 20 | L35: =INDEX(Scenarios!$E$4:$E$9,MATCH($A35,Scenarios!$A$4:$A$9,0)) -> -0.048686824 | M35: =E35*(1+L35)+G35 -> 1.8785772 | N35: =M35+H35 -> 1.8785772 | O35: =I35*M35+J35*H35 -> 37.571543 | P35: =MIN(K35,I35)*E35+MIN(K35,J35)*F35 -> 39.4944 | Q35: =MAX(0,O35-P35)*D35/1000 -> 0 | R35: =IF(SUM($Q$32:$Q$38)=0,0,Q35/SUM($Q$32:$Q$38)) -> 0 | S35: =IF(Assumptions!$C$11="Yes",INDEX(Scenarios!$F$4:$F$9,MATCH($A35,Scenarios!$A$4:$A$9,0))*1000*R35/D35*1000,0) -> 0 | T35: =MAX(0,O35-P35-S35) -> 0 | U35: =Assumptions!$C$8*Assumptions!$C$5*(E35+F35) -> 197.472 | V35: =MAX(0,Assumptions!$C$8*Assumptions!$C$5*N35-Assumptions!$C$10*T35) -> 187.85772 | W35: =C35*U35 -> 23696.64 | X35: =C35*V35 -> 22542.926 | Y35: =C35*Assumptions!$C$5*(E35+F35) -> 23696.64 | Z35: =C35*MAX(0,Assumptions!$C$5*N35-T35) -> 22542.926 | AA35: =C35*Assumptions!$C$7*Assumptions!$C$5*(E35+F35) -> 11492.87 | AB35: =C35*MAX(0,Assumptions!$C$7*Assumptions!$C$5*N35-IF(Assumptions!$C$9="Yes",Assumptions!$C$7,1)*T35) -> 10933.319 | AC35: =C35*(E35+F35) -> 236.9664 | AD35: =C35*N35 -> 225.42926
A36: 3B | B36: Urea | C36: 1600 | D36: 3190.5342 | E36: 0.1122 | F36: 0 | G36: 0 | H36: 0 | I36: =INDEX(Scenarios!$B$4:$B$9,MATCH($A36,Scenarios!$A$4:$A$9,0)) -> 20 | J36: =INDEX(Scenarios!$C$4:$C$9,MATCH($A36,Scenarios!$A$4:$A$9,0)) -> 20 | K36: =INDEX(Scenarios!$D$4:$D$9,MATCH($A36,Scenarios!$A$4:$A$9,0)) -> 20 | L36: =INDEX(Scenarios!$E$4:$E$9,MATCH($A36,Scenarios!$A$4:$A$9,0)) -> -0.048686824 | M36: =E36*(1+L36)+G36 -> 0.10673734 | N36: =M36+H36 -> 0.10673734 | O36: =I36*M36+J36*H36 -> 2.1347468 | P36: =MIN(K36,I36)*E36+MIN(K36,J36)*F36 -> 2.244 | Q36: =MAX(0,O36-P36)*D36/1000 -> 0 | R36: =IF(SUM($Q$32:$Q$38)=0,0,Q36/SUM($Q$32:$Q$38)) -> 0 | S36: =IF(Assumptions!$C$11="Yes",INDEX(Scenarios!$F$4:$F$9,MATCH($A36,Scenarios!$A$4:$A$9,0))*1000*R36/D36*1000,0) -> 0 | T36: =MAX(0,O36-P36-S36) -> 0 | U36: =Assumptions!$C$8*Assumptions!$C$5*(E36+F36) -> 11.22 | V36: =MAX(0,Assumptions!$C$8*Assumptions!$C$5*N36-Assumptions!$C$10*T36) -> 10.673734 | W36: =C36*U36 -> 17952 | X36: =C36*V36 -> 17077.974 | Y36: =C36*Assumptions!$C$5*(E36+F36) -> 17952 | Z36: =C36*MAX(0,Assumptions!$C$5*N36-T36) -> 17077.974 | AA36: =C36*Assumptions!$C$7*Assumptions!$C$5*(E36+F36) -> 8706.72 | AB36: =C36*MAX(0,Assumptions!$C$7*Assumptions!$C$5*N36-IF(Assumptions!$C$9="Yes",Assumptions!$C$7,1)*T36) -> 8282.8175 | AC36: =C36*(E36+F36) -> 179.52 | AD36: =C36*N36 -> 170.77974
