Workbook

Sheet Cover
E2: Use these buttons to navigate to data -->
C21: Rethinking Power Sector Reform Data Repository
C23: Model status | D23: Draft final
C24: Date | D24: February 1 2019
C27: <-- Use this symbol to return to cover sheet
B34: DISCLAIMER
B35: This model has been prepared by the World Bank for its advisory services only. Although the World Bank has prepared the model with utmost care and diligence, the Bank cannot be held liable directly or indirectly for the adequacy, completeness or accuracy of the model structure, the assumptions used or results obtained from the model. Anyone using this model does so at their own risk. Model users should carry out their own due diligence and verify all assumptions, calculations and results presented in this model.

Sheet Utilities
B1: Utilities
B2: Colombia (Codensa) | C2: Private | D2: Codensa, a private distribution company, unbundled from the government-owned generation and distribution company Empresa de Energía de Bogotá (EEB), which serves 3.3 million customers in the capital and 100+ municipalities in Cundinamarca
B3: Dominican Republic (Edesur) | C3: Public | D3: Largest of three distribution companies
B4: Egypt, Arab Rep. (Alexandria) | C4: Public | D4: The Alexandria Electricity Distribution Company serves 2.6 million customers in Alexandria Governorate to K. 66 Alex/Matrouh Road.
B5: Egypt, Arab Rep. (Cairo North) | C5: Public | D5: The Cairo North Electricity Distribution Company serves 4.3 million customers in North and East Cairo Sectors, New Cairo, and El-Salam City in Cairo Governorate; and El-Obour City, Khanka, Shoubra El-kheima and El-Qanater in Qalyoubeya Governorate.
B6: Egypt, Arab Rep. (EEHC) | C6: Public | D6: Holding company
B7: India - Andhra Pradesh (APEPDCL) | C7: Public | D7: Eastern Power Distribution Company of Andhra Pradesh Ltd. (APEPDCL), a 100 percent state government-owned distribution company serving the districts of Eluru, Rajahmundry, Srikakulam, Visakhapatanam, and Vizianagaram
B8: India - Andhra Pradesh (APSPDCL) | C8: Public | D8: Southern Power Distribution Company of Andhra Pradesh Ltd. (APSPDCL), a 100 percent state government-owned distribution company with over 1.13 million customers, serving the districts of Anantapur, Chittor, Guntur, Kadapa, Krishna, Kurnool, Nellore, and Prakasam
B9: India - Odisha (CESCO) | C9: Public | D9: Central Electricity Supply Utility of Odisha (CESU) serving primarily domestic customers (90%- 69% rural and 21% urban)
B10: India - Odisha (WESCO) | C10: Public | D10: Western Electricity Supply Company of Odisha Limited (WESCO) is a public distribution company that served the entire western region of Odisha.
B11: India - Rajasthan (AVVN) | C11: Public | D11: Ajmer Vidyut Nigam Limited (AVVNL) which serves 11 districts of Rajasthan
B12: India - Rajasthan (JDVVN) | C12: Public | D12: Jodhpur Vidyut Nigam Limited (JdVVNL) which serves 10 districts
B13: India - Rajasthan (JVVN) | C13: Public | D13: Jaipur Vidyut Nigam Limited (JVVNL) which serves 12 districts
... B28: Vietnam (NPC) | C28: Public | D28: Northern Power Corporation (NPC), one of the five subsidiary distribution companies established during the sector’s reorganization in 2010, 100 percent owned by Viet Nam Electricity (EVN). NPC serves the northern region.
B30: Financial viability | D30: Large govt transfers | E30: Subsidized fuels | F30: Sustained net losses | G30: Large debt service | H30: Excessive payables | I30: Excessive receivables | J30: Sust. neg. operating CF
B31: Colombia (Codensa) | C31: Private | D31: No | E31: No | F31: No | G31: No | H31: No | I31: No | J31: Yes
B32: Dominican Republic (Edesur) | C32: Public | D32: No | E32: No | F32: Yes | G32: * | H32: * | I32: * | J32: Yes
B33: Egypt, Arab Rep. (EEHC) | C33: Public | D33: No | E33: Yes | F33: No | G33: No | H33: Yes | I33: Yes | J33: No
B34: India - Andhra Pradesh (APEPDCL) | C34: Public | D34: * | E34: No | F34: Yes | G34: No | H34: * | I34: * | J34: No
B35: India - Andhra Pradesh (APSPDCL) | C35: Public | D35: * | E35: No | F35: Yes | G35: No | H35: * | I35: * | J35: No
B36: India - Odisha (CESCO) | C36: Public | D36: * | E36: No | F36: Yes | G36: No | H36: * | I36: * | J36: No
B37: India - Odisha (WESCO) | C37: Public | D37: * | E37: No | F37: Yes | G37: No | H37: * | I37: * | J37: No
B38: India - Rajasthan (AVVN) | C38: Public | D38: * | E38: No | F38: Yes | G38: Yes | H38: No | I38: No | J38: No
B39: India - Rajasthan (JDVVN) | C39: Public | D39: * | E39: No | F39: Yes | G39: Yes | H39: No | I39: No | J39: No
B40: India - Rajasthan (JVVN) | C40: Public | D40: * | E40: No | F40: Yes | G40: Yes | H40: No | I40: No | J40: No
B41: Kenya (KPLC) | C41: Public | D41: No | E41: No | F41: No | G41: No | H41: No | I41: No | J41: Yes
B42: Morocco (ONEE) | C42: Public | D42: * | E42: * | F42: * | G42: * | H42: * | I42: * | J42: *
... B54: Vietnam (NPC) | C54: Public | D54: No | E54: No | F54: No | G54: No | H54: * | I54: * | J54: No
B56: Definitions
B57: Large government transfers: If total government transfers exceed 10% of C3 cost recovery
B58: Subsidized fuels: If utility receives fuels below market prices (qualitative information)
B59: Sustained net losses: If net losses exceed 5% of revenue (average of last three years)
B60: Large debt service: If total debt service (interest and principal payments) exceed 20% of C3 cost recovery
B61: Excessive payables: Payables exceed 50% of annual revenues
B62: Excessive receivables: Receivables exceed 50% of annual revenues
B63: Maturity mismatch: (Current liabilities / Non-current liabilities)/(Current assets / [Non-current assets + equity]) > 200%
B64: Large short-term debt: Short-term debt of more than 20% of assets
B65: Sustained negative operating CF: Negative net operating cash flow of more than 5% of revenue

Sheet Graphics
B1: Cost recovery analysis
B2: Country | D2: Operating Cost | E2: Capital Cost | F2: Cash Collected | G2: Billed tariff revenue
B3: ='Cost Recovery'!B187 -> Senegal | C3: =D3+E3 -> 0.35474683 | D3: ='Cost Recovery'!O187 -> 0.30759669 | E3: ='Cost Recovery'!O205 -> 0.047150139 | F3: ='Cost Recovery'!O259 -> 0.24547415 | G3: ='Cost Recovery'!O241 -> 0.25002728
B4: ='Cost Recovery'!B177 -> Dominican Republic | C4: =D4+E4 -> 0.30448818 | D4: ='Cost Recovery'!O177 -> 0.2974654 | E4: ='Cost Recovery'!O195 -> 0.0070227781 | F4: ='Cost Recovery'!O249 -> 0.18566127 | G4: ='Cost Recovery'!O231 -> 0.19994913 | Z4: Senegal | AA4: 1
B5: ='Cost Recovery'!B179 -> India - Andhra Pradesh | C5: =D5+E5 -> 0.2007346 | D5: ='Cost Recovery'!O179 -> 0.10155327 | E5: ='Cost Recovery'!O197 -> 0.099181326 | G5: ='Cost Recovery'!O233 -> 0.076257416 | Z5: Dominican Republic | AA5: 1
B6: ='Cost Recovery'!B182 -> Kenya | C6: =D6+E6 -> 0.19459796 | D6: ='Cost Recovery'!O182 -> 0.15014348 | E6: ='Cost Recovery'!O200 -> 0.044454477 | F6: ='Cost Recovery'!O254 -> 0.17453263 | G6: ='Cost Recovery'!O236 -> 0.17534188 | Z6: India | AA6: 1
B7: ='Cost Recovery'!B186 -> Philippines | C7: =D7+E7 -> 0.19401821 | D7: ='Cost Recovery'!O186 -> 0.17109672 | E7: ='Cost Recovery'!O204 -> 0.022921495 | F7: ='Cost Recovery'!O258 -> 0.18990399 | G7: ='Cost Recovery'!O240 -> 0.19008684 | Z7: Kenya | AA7: 1
B8: ='Cost Recovery'!B189 -> Tanzania | C8: =D8+E8 -> 0.18707758 | D8: ='Cost Recovery'!O189 -> 0.15834835 | E8: ='Cost Recovery'!O207 -> 0.028729228 | F8: ='Cost Recovery'!O261 -> 0.13044984 | G8: ='Cost Recovery'!O243 -> 0.12647004 | Z8: Philippines | AA8: 1
B9: ='Cost Recovery'!B190 -> Uganda | C9: =D9+E9 -> 0.18471029 | D9: ='Cost Recovery'!O190 -> 0.14351713 | E9: ='Cost Recovery'!O208 -> 0.041193168 | F9: ='Cost Recovery'!O262 -> 0.16700612 | G9: ='Cost Recovery'!O244 -> 0.17050627 | Z9: Tanzania | AA9: 1
B10: ='Cost Recovery'!B181 -> India - Rajasthan | C10: =D10+E10 -> 0.16574868 | D10: ='Cost Recovery'!O181 -> 0.1002091 | E10: ='Cost Recovery'!O199 -> 0.065539585 | G10: ='Cost Recovery'!O235 -> 0.073946319 | Z10: Uganda | AA10: 1
B11: ='Cost Recovery'!B183&"*" -> Morocco* | C11: =D11+E11 -> 0.14204824 | E11: ='Cost Recovery'!$O$219 -> 0.14204824 | G11: ='Cost Recovery'!O237 -> 0.11953096 | Z11: Morocco* | AA11: 1
B12: ='Cost Recovery'!B185 -> Peru | C12: =D12+E12 -> 0.13167423 | D12: ='Cost Recovery'!O185 -> 0.096827701 | E12: ='Cost Recovery'!O203 -> 0.03484653 | F12: ='Cost Recovery'!O257 -> 0.12780812 | G12: ='Cost Recovery'!O239 -> 0.12909938 | Z12: Peru | AA12: 1
B13: ='Cost Recovery'!B184 -> Pakistan | C13: =D13+E13 -> 0.1299432 | D13: ='Cost Recovery'!O184 -> 0.096981557 | E13: ='Cost Recovery'!O202 -> 0.032961639 | F13: ='Cost Recovery'!O256 -> 0.094787839 | G13: ='Cost Recovery'!O238 -> 0.10346324 | Z13: Pakistan | AA13: 1
B14: ='Cost Recovery'!B176 -> Colombia | C14: =D14+E14 -> 0.12258427 | D14: ='Cost Recovery'!O176 -> 0.084076824 | E14: ='Cost Recovery'!O194 -> 0.03850745 | F14: ='Cost Recovery'!O248 -> 0.1232462 | G14: ='Cost Recovery'!O230 -> 0.12756775 | Z14: Colombia | AA14: 1
B15: ='Cost Recovery'!B180 -> India - Odisha | C15: =D15+E15 -> 0.103407 | D15: ='Cost Recovery'!O180 -> 0.096008783 | E15: ='Cost Recovery'!O198 -> 0.0073982137 | F15: ='Cost Recovery'!O252 -> 0.086300865 | G15: ='Cost Recovery'!O234 -> 0.0945583 | Z15: Egypt, Arab Rep. | AA15: 1
B16: ='Cost Recovery'!B178 -> Egypt, Arab Rep. | C16: =D16+E16 -> 0.077737088 | D16: ='Cost Recovery'!O178 -> 0.043369216 | E16: ='Cost Recovery'!O196 -> 0.034367871 | F16: ='Cost Recovery'!O250 -> 0.03821378 | G16: ='Cost Recovery'!O232 -> 0.043142892 | Z16: Vietnam | AA16: 1
B17: ='Cost Recovery'!B192 -> Vietnam | C17: =D17+E17 -> 0.075398011 | D17: ='Cost Recovery'!O192 -> 0.06618744 | E17: ='Cost Recovery'!O210 -> 0.0092105706 | F17: ='Cost Recovery'!O264 -> 0.066735415 | G17: ='Cost Recovery'!O246 -> 0.067060325 | Z17: Ukraine | AA17: 1
B18: ='Cost Recovery'!B191 -> Ukraine | C18: =D18+E18 -> 0.059887353 | D18: ='Cost Recovery'!O191 -> 0.056252249 | E18: ='Cost Recovery'!O209 -> 0.0036351041 | G18: ='Cost Recovery'!O245 -> 0.063777527 | Z18: Tajikistan | AA18: 1
B19: ='Cost Recovery'!B188 -> Tajikistan | C19: =D19+E19 -> 0.025643252 | D19: ='Cost Recovery'!O188 -> 0.014586734 | E19: ='Cost Recovery'!O206 -> 0.011056518 | F19: ='Cost Recovery'!O260 -> 0.012815038 | G19: ='Cost Recovery'!O242 -> 0.017232131
C21: =AVERAGE(C3:C19) -> 0.15614382 | G21: =AVERAGE(G3:G19) -> 0.11929516
B26: Full-Cost Recovery (C3 or approximate)
B27: Country | C27: Unit | D27: Region | E27: Value | F27: Type
B28: ='Cost Recovery'!B24 -> India - Andhra Pradesh | C28: ='Cost Recovery'!C24 -> % | D28: ='Cost Recovery'!D24 -> SAR | E28: ='Cost Recovery'!O24 -> 0.37989174 | F28: =VLOOKUP(B28,'Cost Recovery'!B$21:E$37,4,FALSE) -> Public | S28: Row Labels | T28: Average of Value | U28: Row Labels | V28: Average of Value
B29: ='Cost Recovery'!B26 -> India - Rajasthan | C29: ='Cost Recovery'!C26 -> % | D29: ='Cost Recovery'!D26 -> SAR | E29: ='Cost Recovery'!O26 -> 0.44613519 | F29: =VLOOKUP(B29,'Cost Recovery'!B$21:E$37,4,FALSE) -> Public | S29: AFR | T29: 0.80124568 | U29: Mixed | V29: 0.94720748
B30: ='Cost Recovery'!B23 -> Egypt, Arab Rep. | C30: ='Cost Recovery'!C23 -> % | D30: ='Cost Recovery'!D23 -> MNA | E30: ='Cost Recovery'!O23 -> 0.55498467 | F30: =VLOOKUP(B30,'Cost Recovery'!B$21:E$37,4,FALSE) -> Public | S30: EAP | T30: 0.93457739 | U30: Private | V30: 0.98116387
B31: ='Cost Recovery'!B22 -> Dominican Republic | C31: ='Cost Recovery'!C22 -> % | D31: ='Cost Recovery'!D22 -> LAC | E31: ='Cost Recovery'!O22 -> 0.65667289 | F31: =VLOOKUP(B31,'Cost Recovery'!B$21:E$37,4,FALSE) -> Public | S31: ECA | T31: 0.86847648 | U31: Public | V31: 0.69426259
B32: ='Cost Recovery'!B33 -> Tajikistan | C32: ='Cost Recovery'!C33 -> % | D32: ='Cost Recovery'!D33 -> ECA | E32: ='Cost Recovery'!O33 -> 0.67199478 | F32: =VLOOKUP(B32,'Cost Recovery'!B$21:E$37,4,FALSE) -> Public | S32: LAC | T32: 0.89259054 | U32: Grand Total | V32: 0.78952956
B33: ='Cost Recovery'!B34 -> Tanzania | C33: ='Cost Recovery'!C34 -> % | D33: ='Cost Recovery'!D34 -> AFR | E33: ='Cost Recovery'!O34 -> 0.67602993 | F33: =VLOOKUP(B33,'Cost Recovery'!B$21:E$37,4,FALSE) -> Public | S33: MNA | T33: 0.69823308
B34: ='Cost Recovery'!B32 -> Senegal | C34: ='Cost Recovery'!C32 -> % | D34: ='Cost Recovery'!D32 -> AFR | E34: ='Cost Recovery'!O32 -> 0.70480485 | F34: =VLOOKUP(B34,'Cost Recovery'!B$21:E$37,4,FALSE) -> Public | S34: SAR | T34: 0.63416859
B35: ='Cost Recovery'!B29 -> Pakistan | C35: ='Cost Recovery'!C29 -> % | D35: ='Cost Recovery'!D29 -> SAR | E35: ='Cost Recovery'!O29 -> 0.79621897 | F35: =VLOOKUP(B35,'Cost Recovery'!B$21:E$37,4,FALSE) -> Mixed | S35: Grand Total | T35: 0.78952956
B36: ='Cost Recovery'!B28 -> Morocco | C36: ='Cost Recovery'!C28 -> % | D36: ='Cost Recovery'!D28 -> MNA | E36: ='Cost Recovery'!O28 -> 0.84148148 | F36: =VLOOKUP(B36,'Cost Recovery'!B$21:E$37,4,FALSE) -> Public
B37: ='Cost Recovery'!B37 -> Vietnam | C37: ='Cost Recovery'!C37 -> % | D37: ='Cost Recovery'!D37 -> EAP | E37: ='Cost Recovery'!O37 -> 0.8894177 | F37: =VLOOKUP(B37,'Cost Recovery'!B$21:E$37,4,FALSE) -> Public | S37: Row Labels | T37: Average of Value | U37: Row Labels | V37: Average of Value
B38: ='Cost Recovery'!B27 -> Kenya | C38: ='Cost Recovery'!C27 -> % | D38: ='Cost Recovery'!D27 -> AFR | E38: ='Cost Recovery'!O27 -> 0.90104686 | F38: =VLOOKUP(B38,'Cost Recovery'!B$21:E$37,4,FALSE) -> Public | S38: SAR | T38: =VLOOKUP(S38,$S$29:$T$34,2,FALSE) -> 0.63416859 | U38: Public | V38: =VLOOKUP(U38,U$29:V$31,2,FALSE) -> 0.69426259
B39: ='Cost Recovery'!B25 -> India - Odisha | C39: ='Cost Recovery'!C25 -> % | D39: ='Cost Recovery'!D25 -> SAR | E39: ='Cost Recovery'!O25 -> 0.91442845 | F39: =VLOOKUP(B39,'Cost Recovery'!B$21:E$37,4,FALSE) -> Public | S39: MNA | T39: =VLOOKUP(S39,$S$29:$T$34,2,FALSE) -> 0.69823308 | U39: Mixed | V39: =VLOOKUP(U39,U$29:V$31,2,FALSE) -> 0.94720748
B40: ='Cost Recovery'!B35 -> Uganda | C40: ='Cost Recovery'!C35 -> % | D40: ='Cost Recovery'!D35 -> AFR | E40: ='Cost Recovery'!O35 -> 0.9231011 | F40: =VLOOKUP(B40,'Cost Recovery'!B$21:E$37,4,FALSE) -> Private | S40: AFR | T40: =VLOOKUP(S40,$S$29:$T$34,2,FALSE) -> 0.80124568 | U40: Private | V40: =VLOOKUP(U40,U$29:V$31,2,FALSE) -> 0.98116387
B41: ='Cost Recovery'!B31 -> Philippines | C41: ='Cost Recovery'!C31 -> % | D41: ='Cost Recovery'!D31 -> EAP | E41: ='Cost Recovery'!O31 -> 0.97973708 | F41: =VLOOKUP(B41,'Cost Recovery'!B$21:E$37,4,FALSE) -> Private | S41: ECA | T41: =VLOOKUP(S41,$S$29:$T$34,2,FALSE) -> 0.86847648
B42: ='Cost Recovery'!B30 -> Peru | C42: ='Cost Recovery'!C30 -> % | D42: ='Cost Recovery'!D30 -> LAC | E42: ='Cost Recovery'!O30 -> 0.98044528 | F42: =VLOOKUP(B42,'Cost Recovery'!B$21:E$37,4,FALSE) -> Mixed | S42: LAC | T42: =VLOOKUP(S42,$S$29:$T$34,2,FALSE) -> 0.89259054
B43: ='Cost Recovery'!B21 -> Colombia | C43: ='Cost Recovery'!C21 -> % | D43: ='Cost Recovery'!D21 -> LAC | E43: ='Cost Recovery'!O21 -> 1.0406534 | F43: =VLOOKUP(B43,'Cost Recovery'!B$21:E$37,4,FALSE) -> Private | S43: EAP | T43: =VLOOKUP(S43,$S$29:$T$34,2,FALSE) -> 0.93457739
B44: ='Cost Recovery'!B36 -> Ukraine | C44: ='Cost Recovery'!C36 -> % | D44: ='Cost Recovery'!D36 -> ECA | E44: ='Cost Recovery'!O36 -> 1.0649582 | F44: =VLOOKUP(B44,'Cost Recovery'!B$21:E$37,4,FALSE) -> Mixed
B50: Full-Cost Recovery (C3 or approximate)- Utility level
...

Sheet Cost Recovery
B1: Cost recovery analysis - Country level | C1: Unit | D1: Region | E1: Type | F1: Pre-reform | G1: 2010 | H1: 2011 | I1: 2012 | J1: 2013 | K1: 2014 | L1: 2015 | M1: 2016 | N1: 2017 | O1: Average 2010-17 | P1: Change from Pre-Reform | Q1: Tariff contribution | R1: Cost contribution | S1: Min | T1: Max | U1: Coeff of Variation | X1: Source/comment
B2: Operating cost recovery (tariff revenues)
B3: Colombia | C3: % | D3: LAC | E3: Private | F3: =IFERROR(F230/F176,"n.a.") -> n.a. | G3: =IFERROR(G230/G176,"n.a.") -> 1.543569 | H3: =IFERROR(H230/H176,"n.a.") -> 1.4860379 | I3: =IFERROR(I230/I176,"n.a.") -> 1.5305283 | J3: =IFERROR(J230/J176,"n.a.") -> 1.5266911 | K3: =IFERROR(K230/K176,"n.a.") -> 1.5215409 | L3: =IFERROR(L230/L176,"n.a.") -> 1.5008171 | M3: =IFERROR(M230/M176,"n.a.") -> 1.5069675 | ... O3: =IFERROR(O230/O176,"n.a.") -> 1.517276 | X3: Tariffs/C1
B4: Dominican Republic | C4: % | D4: LAC | E4: Public | F4: =IFERROR(F231/F177,"n.a.") -> n.a. | G4: =IFERROR(G231/G177,"n.a.") -> 0.70642194 | H4: =IFERROR(H231/H177,"n.a.") -> 0.6523157 | I4: =IFERROR(I231/I177,"n.a.") -> 0.63449462 | J4: =IFERROR(J231/J177,"n.a.") -> 0.66518037 | K4: =IFERROR(K231/K177,"n.a.") -> 0.63367908 | L4: =IFERROR(L231/L177,"n.a.") -> 0.7792562 | M4: =IFERROR(M231/M177,"n.a.") -> n.a. | ... O4: =IFERROR(O231/O177,"n.a.") -> 0.6721761
B5: Egypt, Arab Rep. | C5: % | D5: MNA | E5: Public | F5: =IFERROR(F232/F178,"n.a.") -> n.a. | G5: =IFERROR(G232/G178,"n.a.") -> n.a. | H5: =IFERROR(H232/H178,"n.a.") -> 1.4603514 | I5: =IFERROR(I232/I178,"n.a.") -> 1.3554688 | J5: =IFERROR(J232/J178,"n.a.") -> 1.3995538 | K5: =IFERROR(K232/K178,"n.a.") -> 0.7276914 | L5: =IFERROR(L232/L178,"n.a.") -> 0.81326566 | M5: =IFERROR(M232/M178,"n.a.") -> 0.8127443 | ... O5: =IFERROR(O232/O178,"n.a.") -> 0.99478145
B6: India - Andhra Pradesh | C6: % | D6: SAR | E6: Public | F6: =IFERROR(F233/F179,"n.a.") -> n.a. | G6: =IFERROR(G233/G179,"n.a.") -> n.a. | H6: =IFERROR(H233/H179,"n.a.") -> 0.72486646 | I6: =IFERROR(I233/I179,"n.a.") -> 0.76088087 | J6: =IFERROR(J233/J179,"n.a.") -> 0.71445177 | K6: =IFERROR(K233/K179,"n.a.") -> 0.80237914 | L6: =IFERROR(L233/L179,"n.a.") -> 0.76140152 | M6: =IFERROR(M233/M179,"n.a.") -> n.a. | ... O6: =IFERROR(O233/O179,"n.a.") -> 0.75091048
B7: India - Odisha | C7: % | D7: SAR | E7: Public | F7: =IFERROR(F234/F180,"n.a.") -> n.a. | G7: =IFERROR(G234/G180,"n.a.") -> n.a. | H7: =IFERROR(H234/H180,"n.a.") -> 1.0176325 | I7: =IFERROR(I234/I180,"n.a.") -> 0.97872683 | J7: =IFERROR(J234/J180,"n.a.") -> 0.95638928 | K7: =IFERROR(K234/K180,"n.a.") -> 0.9831727 | L7: =IFERROR(L234/L180,"n.a.") -> 0.98939186 | M7: =IFERROR(M234/M180,"n.a.") -> n.a. | ... O7: =IFERROR(O234/O180,"n.a.") -> 0.98489219
B8: India - Rajasthan | C8: % | D8: SAR | E8: Public | F8: =IFERROR(F235/F181,"n.a.") -> n.a. | G8: =IFERROR(G235/G181,"n.a.") -> n.a. | H8: =IFERROR(H235/H181,"n.a.") -> 0.63881852 | I8: =IFERROR(I235/I181,"n.a.") -> 0.65606968 | J8: =IFERROR(J235/J181,"n.a.") -> 0.75097635 | K8: =IFERROR(K235/K181,"n.a.") -> 0.78224356 | L8: =IFERROR(L235/L181,"n.a.") -> 0.88924861 | M8: =IFERROR(M235/M181,"n.a.") -> n.a. | ... O8: =IFERROR(O235/O181,"n.a.") -> 0.73792022
B9: Kenya | C9: % | D9: AFR | E9: Public | F9: =IFERROR(F236/F182,"n.a.") -> n.a. | G9: =IFERROR(G236/G182,"n.a.") -> 1.1148206 | H9: =IFERROR(H236/H182,"n.a.") -> 1.1739996 | I9: =IFERROR(I236/I182,"n.a.") -> 1.1345275 | J9: =IFERROR(J236/J182,"n.a.") -> 1.1516351 | K9: =IFERROR(K236/K182,"n.a.") -> 1.1934046 | L9: =IFERROR(L236/L182,"n.a.") -> 1.20569 | M9: =IFERROR(M236/M182,"n.a.") -> 1.2368184 | ... O9: =IFERROR(O236/O182,"n.a.") -> 1.1678288
B10: Morocco | C10: % | D10: MNA | E10: Public | F10: =IFERROR(F237/F183,"n.a.") -> n.a. | G10: =IFERROR(G237/G183,"n.a.") -> n.a. | H10: =IFERROR(H237/H183,"n.a.") -> n.a. | I10: =IFERROR(I237/I183,"n.a.") -> n.a. | J10: =IFERROR(J237/J183,"n.a.") -> n.a. | K10: =IFERROR(K237/K183,"n.a.") -> n.a. | L10: =IFERROR(L237/L183,"n.a.") -> n.a. | M10: =IFERROR(M237/M183,"n.a.") -> n.a. | ... O10: =IFERROR(O237/O183,"n.a.") -> n.a.
B11: Pakistan | C11: % | D11: SAR | E11: Mixed | F11: =IFERROR(F238/F184,"n.a.") -> n.a. | G11: =IFERROR(G238/G184,"n.a.") -> n.a. | H11: =IFERROR(H238/H184,"n.a.") -> n.a. | I11: =IFERROR(I238/I184,"n.a.") -> n.a. | J11: =IFERROR(J238/J184,"n.a.") -> 0.84966469 | K11: =IFERROR(K238/K184,"n.a.") -> 0.97146573 | L11: =IFERROR(L238/L184,"n.a.") -> 1.1869367 | M11: =IFERROR(M238/M184,"n.a.") -> 1.3954035 | ... O11: =IFERROR(O238/O184,"n.a.") -> 1.0668342
B12: Peru | C12: % | D12: LAC | E12: Mixed | F12: =IFERROR(F239/F185,"n.a.") -> n.a. | G12: =IFERROR(G239/G185,"n.a.") -> 1.3933433 | H12: =IFERROR(H239/H185,"n.a.") -> 1.3694024 | I12: =IFERROR(I239/I185,"n.a.") -> 1.3403122 | J12: =IFERROR(J239/J185,"n.a.") -> 1.3097292 | K12: =IFERROR(K239/K185,"n.a.") -> 1.3041321 | L12: =IFERROR(L239/L185,"n.a.") -> 1.3186819 | M12: =IFERROR(M239/M185,"n.a.") -> 1.3130718 | ... O12: =IFERROR(O239/O185,"n.a.") -> 1.3332897
B13: Philippines | C13: % | D13: EAP | E13: Private | F13: =IFERROR(F240/F186,"n.a.") -> n.a. | G13: =IFERROR(G240/G186,"n.a.") -> 1.0809965 | H13: =IFERROR(H240/H186,"n.a.") -> 1.0992383 | I13: =IFERROR(I240/I186,"n.a.") -> 1.0938794 | J13: =IFERROR(J240/J186,"n.a.") -> 1.1118635 | K13: =IFERROR(K240/K186,"n.a.") -> 1.1362492 | L13: =IFERROR(L240/L186,"n.a.") -> 1.1317364 | M13: =IFERROR(M240/M186,"n.a.") -> 1.1459573 | ... O13: =IFERROR(O240/O186,"n.a.") -> 1.1109905
B14: Senegal | C14: % | D14: AFR | E14: Public | F14: =IFERROR(F241/F187,"n.a.") -> n.a. | G14: =IFERROR(G241/G187,"n.a.") -> 0.80986003 | H14: =IFERROR(H241/H187,"n.a.") -> 0.73287571 | I14: =IFERROR(I241/I187,"n.a.") -> 0.6783171 | J14: =IFERROR(J241/J187,"n.a.") -> 0.79165224 | K14: =IFERROR(K241/K187,"n.a.") -> 0.81517897 | L14: =IFERROR(L241/L187,"n.a.") -> 1.0245417 | M14: =IFERROR(M241/M187,"n.a.") -> 1.0565072 | ... O14: =IFERROR(O241/O187,"n.a.") -> 0.81284127
B15: Tajikistan | C15: % | D15: ECA | E15: Public | F15: =IFERROR(F242/F188,"n.a.") -> n.a. | G15: =IFERROR(G242/G188,"n.a.") -> n.a. | H15: =IFERROR(H242/H188,"n.a.") -> n.a. | I15: =IFERROR(I242/I188,"n.a.") -> n.a. | J15: =IFERROR(J242/J188,"n.a.") -> 1.087905 | K15: =IFERROR(K242/K188,"n.a.") -> 1.2127849 | L15: =IFERROR(L242/L188,"n.a.") -> 1.2977298 | M15: =IFERROR(M242/M188,"n.a.") -> 1.1529748 | ... O15: =IFERROR(O242/O188,"n.a.") -> 1.1813564
... B19: Vietnam | C19: % | D19: EAP | E19: Public | F19: =IFERROR(F246/F192,"n.a.") -> n.a. | G19: =IFERROR(G246/G192,"n.a.") -> 0.99921613 | H19: =IFERROR(H246/H192,"n.a.") -> 0.98310085 | I19: =IFERROR(I246/I192,"n.a.") -> 1.0377212 | J19: =IFERROR(J246/J192,"n.a.") -> 1.0223713 | K19: =IFERROR(K246/K192,"n.a.") -> 1.0130538 | L19: =IFERROR(L246/L192,"n.a.") -> 1.0201213 | M19: =IFERROR(M246/M192,"n.a.") -> 1.0125215 | ... O19: =IFERROR(O246/O192,"n.a.") -> 1.0131881
B20: Full-Cost Recovery (tariff revenues)
B21: Colombia | C21: % | D21: LAC | E21: Private | F21: =IFERROR(F230/F212,"n.a.") -> 0.55037313 | G21: =IFERROR(G230/G212,"n.a.") -> 0.93589667 | H21: =IFERROR(H230/H212,"n.a.") -> 1.0902277 | I21: =IFERROR(I230/I212,"n.a.") -> 1.1701546 | J21: =IFERROR(J230/J212,"n.a.") -> 1.0271786 | K21: =IFERROR(K230/K212,"n.a.") -> 1.0045184 | L21: =IFERROR(L230/L212,"n.a.") -> 1.052692 | M21: =IFERROR(M230/M212,"n.a.") -> 1.0244124 | ... O21: =IFERROR(O230/O212,"n.a.") -> 1.0406534 | P21: =IFERROR(O21-F21,"n.a.") -> 0.49028031 | Q21: =('Sales & Collections'!AE3-'Sales & Collections'!V3)/Costs!V95 -> 0.5528719 | R21: =('Sales & Collections'!AE3/Costs!AE95)-('Sales & Collections'!AE3/Costs!V95) -> -0.062591591 | S21: =MIN(G21:N21) -> 0.93589667 | T21: =MAX(G21:M21) -> 1.1701546 | U21: =IFERROR(STDEV(G21:N21)/GEOMEAN(G21:N21),"n.a.") -> 0.070167106 | X21: Tariffs/C3
B22: Dominican Republic | C22: % | D22: LAC | E22: Public | F22: =IFERROR(F231/F213,"n.a.") -> 1.0576471 | G22: =IFERROR(G231/G213,"n.a.") -> 0.70519218 | H22: =IFERROR(H231/H213,"n.a.") -> 0.64537084 | I22: =IFERROR(I231/I213,"n.a.") -> 0.62126843 | J22: =IFERROR(J231/J213,"n.a.") -> 0.64714685 | K22: =IFERROR(K231/K213,"n.a.") -> 0.61994635 | L22: =IFERROR(L231/L213,"n.a.") -> 0.7327526 | M22: =IFERROR(M231/M213,"n.a.") -> n.a. | ... O22: =IFERROR(O231/O213,"n.a.") -> 0.65667289 | P22: =IFERROR(O22-F22,"n.a.") -> -0.40097417 | Q22: =('Sales & Collections'!AE4-'Sales & Collections'!V4)/Costs!V96 -> 0.032779653 | R22: =('Sales & Collections'!AE4/Costs!AE96)-('Sales & Collections'!AE4/Costs!V96) -> -0.43375382 | S22: =MIN(G22:N22) -> 0.61994635 | T22: =MAX(G22:M22) -> 0.7327526 | U22: =IFERROR(STDEV(G22:N22)/GEOMEAN(G22:N22),"n.a.") -> 0.070339385
B23: Egypt, Arab Rep. | C23: % | D23: MNA | E23: Public | F23: =IFERROR(F232/F214,"n.a.") -> 0.21282051 | G23: =IFERROR(G232/G214,"n.a.") -> n.a. | H23: =IFERROR(H232/H214,"n.a.") -> 0.61743081 | I23: =IFERROR(I232/I214,"n.a.") -> 0.62214293 | J23: =IFERROR(J232/J214,"n.a.") -> 0.67704062 | K23: =IFERROR(K232/K214,"n.a.") -> 0.49802617 | L23: =IFERROR(L232/L214,"n.a.") -> 0.49020079 | M23: =IFERROR(M232/M214,"n.a.") -> 0.50356045 | ... O23: =IFERROR(O232/O214,"n.a.") -> 0.55498467 | P23: =IFERROR(O23-F23,"n.a.") -> 0.34216416 | Q23: =('Sales & Collections'!AE5-'Sales & Collections'!V5)/Costs!V97 -> 0.043575068 | R23: =('Sales & Collections'!AE5/Costs!AE97)-('Sales & Collections'!AE5/Costs!V97) -> 0.29858909 | S23: =MIN(G23:N23) -> 0.49020079 | T23: =MAX(G23:M23) -> 0.67704062 | U23: =IFERROR(STDEV(G23:N23)/GEOMEAN(G23:N23),"n.a.") -> 0.14281233
B24: India - Andhra Pradesh | C24: % | D24: SAR | E24: Public | F24: =IFERROR(F233/F215,"n.a.") -> 0.539801 | G24: =IFERROR(G233/G215,"n.a.") -> n.a. | H24: =IFERROR(H233/H215,"n.a.") -> 0.35638014 | I24: =IFERROR(I233/I215,"n.a.") -> 0.36412687 | J24: =IFERROR(J233/J215,"n.a.") -> 0.38234609 | K24: =IFERROR(K233/K215,"n.a.") -> 0.3678935 | L24: =IFERROR(L233/L215,"n.a.") -> 0.44054808 | M24: =IFERROR(M233/M215,"n.a.") -> n.a. | ... O24: =IFERROR(O233/O215,"n.a.") -> 0.37989174 | P24: =IFERROR(O24-F24,"n.a.") -> -0.15990925 | Q24: =('Sales & Collections'!AE6-'Sales & Collections'!V6)/Costs!V98 -> -0.10013597 | R24: =('Sales & Collections'!AE6/Costs!AE98)-('Sales & Collections'!AE6/Costs!V98) -> -0.059773287 | S24: =MIN(G24:N24) -> 0.35638014 | T24: =MAX(G24:M24) -> 0.44054808 | U24: =IFERROR(STDEV(G24:N24)/GEOMEAN(G24:N24),"n.a.") -> 0.089001706
B25: India - Odisha | C25: % | D25: SAR | E25: Public | F25: =IFERROR(F234/F216,"n.a.") -> 0.539801 | G25: =IFERROR(G234/G216,"n.a.") -> n.a. | H25: =IFERROR(H234/H216,"n.a.") -> 0.93758771 | I25: =IFERROR(I234/I216,"n.a.") -> 0.91515302 | J25: =IFERROR(J234/J216,"n.a.") -> 0.89531065 | K25: =IFERROR(K234/K216,"n.a.") -> 0.91668135 | L25: =IFERROR(L234/L216,"n.a.") -> 0.90692378 | M25: =IFERROR(M234/M216,"n.a.") -> n.a. | ... O25: =IFERROR(O234/O216,"n.a.") -> 0.91442845 | P25: =IFERROR(O25-F25,"n.a.") -> 0.37462746 | Q25: =('Sales & Collections'!AE7-'Sales & Collections'!V7)/Costs!V99 -> 0.0053784766 | R25: =('Sales & Collections'!AE7/Costs!AE99)-('Sales & Collections'!AE7/Costs!V99) -> 0.36924898 | S25: =MIN(G25:N25) -> 0.89531065 | T25: =MAX(G25:M25) -> 0.93758771 | U25: =IFERROR(STDEV(G25:N25)/GEOMEAN(G25:N25),"n.a.") -> 0.01697816
B26: India - Rajasthan | C26: % | D26: SAR | E26: Public | F26: =IFERROR(F235/F217,"n.a.") -> 0.539801 | G26: =IFERROR(G235/G217,"n.a.") -> n.a. | H26: =IFERROR(H235/H217,"n.a.") -> 0.38391318 | I26: =IFERROR(I235/I217,"n.a.") -> 0.41135686 | J26: =IFERROR(J235/J217,"n.a.") -> 0.47313733 | K26: =IFERROR(K235/K217,"n.a.") -> 0.428227 | L26: =IFERROR(L235/L217,"n.a.") -> 0.56686203 | M26: =IFERROR(M235/M217,"n.a.") -> n.a. | ... O26: =IFERROR(O235/O217,"n.a.") -> 0.44613519 | P26: =IFERROR(O26-F26,"n.a.") -> -0.09366581 | Q26: =('Sales & Collections'!AE8-'Sales & Collections'!V8)/Costs!V100 -> -0.11346068 | R26: =('Sales & Collections'!AE8/Costs!AE100)-('Sales & Collections'!AE8/Costs!V100) -> 0.019794873 | S26: =MIN(G26:N26) -> 0.38391318 | T26: =MAX(G26:M26) -> 0.56686203 | U26: =IFERROR(STDEV(G26:N26)/GEOMEAN(G26:N26),"n.a.") -> 0.15959813
B27: Kenya | C27: % | D27: AFR | E27: Public | F27: =IFERROR(F236/F218,"n.a.") -> 1.0639432 | G27: =IFERROR(G236/G218,"n.a.") -> 0.99283243 | H27: =IFERROR(H236/H218,"n.a.") -> 1.0053586 | I27: =IFERROR(I236/I218,"n.a.") -> 0.93871935 | J27: =IFERROR(J236/J218,"n.a.") -> 0.87485101 | K27: =IFERROR(K236/K218,"n.a.") -> 0.89240749 | L27: =IFERROR(L236/L218,"n.a.") -> 0.81330249 | M27: =IFERROR(M236/M218,"n.a.") -> 0.80030107 | ... O27: =IFERROR(O236/O218,"n.a.") -> 0.90104686 | P27: =IFERROR(O27-F27,"n.a.") -> -0.1628963 | Q27: =('Sales & Collections'!AE9-'Sales & Collections'!V9)/Costs!V101 -> 0.37974419 | R27: =('Sales & Collections'!AE9/Costs!AE101)-('Sales & Collections'!AE9/Costs!V101) -> -0.5426405 | S27: =MIN(G27:N27) -> 0.80030107 | T27: =MAX(G27:M27) -> 1.0053586 | U27: =IFERROR(STDEV(G27:N27)/GEOMEAN(G27:N27),"n.a.") -> 0.090004106
B28: Morocco | C28: % | D28: MNA | E28: Public | F28: =IFERROR(F237/F219,"n.a.") -> 1.0657734 | G28: =IFERROR(G237/G219,"n.a.") -> n.a. | H28: =IFERROR(H237/H219,"n.a.") -> n.a. | I28: =IFERROR(I237/I219,"n.a.") -> n.a. | J28: =IFERROR(J237/J219,"n.a.") -> 0.84148148 | K28: =IFERROR(K237/K219,"n.a.") -> n.a. | L28: =IFERROR(L237/L219,"n.a.") -> n.a. | M28: =IFERROR(M237/M219,"n.a.") -> n.a. | ... O28: =IFERROR(O237/O219,"n.a.") -> 0.84148148 | P28: =IFERROR(O28-F28,"n.a.") -> -0.22429197 | Q28: =('Sales & Collections'!AE10-'Sales & Collections'!V10)/Costs!V102 -> -0.3908832 | R28: =('Sales & Collections'!AE10/Costs!AE102)-('Sales & Collections'!AE10/Costs!V102) -> 0.16659124 | S28: =MIN(G28:N28) -> 0.84148148 | T28: =MAX(G28:M28) -> 0.84148148 | U28: =IFERROR(STDEV(G28:N28)/GEOMEAN(G28:N28),"n.a.") -> n.a.
B29: Pakistan | C29: % | D29: SAR | E29: Mixed | F29: =IFERROR(F238/F220,"n.a.") -> 0.90842491 | G29: =IFERROR(G238/G220,"n.a.") -> n.a. | H29: =IFERROR(H238/H220,"n.a.") -> n.a. | I29: =IFERROR(I238/I220,"n.a.") -> n.a. | J29: =IFERROR(J238/J220,"n.a.") -> 0.65705726 | K29: =IFERROR(K238/K220,"n.a.") -> 0.74903779 | L29: =IFERROR(L238/L220,"n.a.") -> 0.8677183 | M29: =IFERROR(M238/M220,"n.a.") -> 0.96846917 | ... O29: =IFERROR(O238/O220,"n.a.") -> 0.79621897 | P29: =IFERROR(O29-F29,"n.a.") -> -0.11220594 | Q29: =('Sales & Collections'!AE11-'Sales & Collections'!V11)/Costs!V103 -> -0.030031016 | R29: =('Sales & Collections'!AE11/Costs!AE103)-('Sales & Collections'!AE11/Costs!V103) -> -0.082174923 | S29: =MIN(G29:N29) -> 0.65705726 | T29: =MAX(G29:M29) -> 0.96846917 | U29: =IFERROR(STDEV(G29:N29)/GEOMEAN(G29:N29),"n.a.") -> 0.16968376
B30: Peru | C30: % | D30: LAC | E30: Mixed | F30: =IFERROR(F239/F221,"n.a.") -> 0.7575 | G30: =IFERROR(G239/G221,"n.a.") -> 1.0184226 | H30: =IFERROR(H239/H221,"n.a.") -> 1.0197177 | I30: =IFERROR(I239/I221,"n.a.") -> 1.0125604 | J30: =IFERROR(J239/J221,"n.a.") -> 0.98362552 | K30: =IFERROR(K239/K221,"n.a.") -> 0.94890369 | L30: =IFERROR(L239/L221,"n.a.") -> 0.96949243 | M30: =IFERROR(M239/M221,"n.a.") -> 0.92991165 | ... O30: =IFERROR(O239/O221,"n.a.") -> 0.98044528 | P30: =IFERROR(O30-F30,"n.a.") -> 0.22294528 | Q30: =('Sales & Collections'!AE12-'Sales & Collections'!V12)/Costs!V104 -> -0.25880066 | R30: =('Sales & Collections'!AE12/Costs!AE104)-('Sales & Collections'!AE12/Costs!V104) -> 0.48174594 | S30: =MIN(G30:N30) -> 0.92991165 | T30: =MAX(G30:M30) -> 1.0197177 | U30: =IFERROR(STDEV(G30:N30)/GEOMEAN(G30:N30),"n.a.") -> 0.036313325
B31: Philippines | C31: % | D31: EAP | E31: Private | F31: =IFERROR(F240/F222,"n.a.") -> 1.3195548 | G31: =IFERROR(G240/G222,"n.a.") -> 0.97809706 | H31: =IFERROR(H240/H222,"n.a.") -> 0.9926745 | I31: =IFERROR(I240/I222,"n.a.") -> 0.99937078 | J31: =IFERROR(J240/J222,"n.a.") -> 0.96215974 | K31: =IFERROR(K240/K222,"n.a.") -> 0.97595454 | L31: =IFERROR(L240/L222,"n.a.") -> 0.99048205 | M31: =IFERROR(M240/M222,"n.a.") -> 0.95320456 | ... O31: =IFERROR(O240/O222,"n.a.") -> 0.97973708 | P31: =IFERROR(O31-F31,"n.a.") -> -0.33981777 | Q31: =('Sales & Collections'!AE13-'Sales & Collections'!V13)/Costs!V105 -> 0.081313364 | R31: =('Sales & Collections'!AE13/Costs!AE105)-('Sales & Collections'!AE13/Costs!V105) -> -0.42113114 | S31: =MIN(G31:N31) -> 0.95320456 | T31: =MAX(G31:M31) -> 0.99937078 | U31: =IFERROR(STDEV(G31:N31)/GEOMEAN(G31:N31),"n.a.") -> 0.01716158
B32: Senegal | C32: % | D32: AFR | E32: Public | F32: =IFERROR(F241/F223,"n.a.") -> 0.88204591 | G32: =IFERROR(G241/G223,"n.a.") -> 0.7660452 | H32: =IFERROR(H241/H223,"n.a.") -> 0.67879803 | I32: =IFERROR(I241/I223,"n.a.") -> 0.54860314 | J32: =IFERROR(J241/J223,"n.a.") -> 0.65833515 | K32: =IFERROR(K241/K223,"n.a.") -> 0.71512207 | L32: =IFERROR(L241/L223,"n.a.") -> 0.85990348 | M32: =IFERROR(M241/M223,"n.a.") -> 0.87210791 | ... O32: =IFERROR(O241/O223,"n.a.") -> 0.70480485 | P32: =IFERROR(O32-F32,"n.a.") -> -0.17724106 | Q32: =('Sales & Collections'!AE14-'Sales & Collections'!V14)/Costs!V106 -> -0.33694784 | R32: =('Sales & Collections'!AE14/Costs!AE106)-('Sales & Collections'!AE14/Costs!V106) -> 0.15970678 | S32: =MIN(G32:N32) -> 0.54860314 | T32: =MAX(G32:M32) -> 0.87210791 | U32: =IFERROR(STDEV(G32:N32)/GEOMEAN(G32:N32),"n.a.") -> 0.15951332
B33: Tajikistan | C33: % | D33: ECA | E33: Public | F33: =IFERROR(F242/F224,"n.a.") -> 0.23809524 | G33: =IFERROR(G242/G224,"n.a.") -> n.a. | H33: =IFERROR(H242/H224,"n.a.") -> n.a. | I33: =IFERROR(I242/I224,"n.a.") -> n.a. | J33: =IFERROR(J242/J224,"n.a.") -> 0.52123301 | K33: =IFERROR(K242/K224,"n.a.") -> 0.72901724 | L33: =IFERROR(L242/L224,"n.a.") -> 0.82800002 | M33: =IFERROR(M242/M224,"n.a.") -> 0.70170828 | ... O33: =IFERROR(O242/O224,"n.a.") -> 0.67199478 | P33: =IFERROR(O33-F33,"n.a.") -> 0.43389954 | Q33: =('Sales & Collections'!AE15-'Sales & Collections'!V15)/Costs!V107 -> 0.37773522 | R33: =('Sales & Collections'!AE15/Costs!AE107)-('Sales & Collections'!AE15/Costs!V107) -> 0.056164325 | S33: =MIN(G33:N33) -> 0.52123301 | T33: =MAX(G33:M33) -> 0.82800002 | U33: =IFERROR(STDEV(G33:N33)/GEOMEAN(G33:N33),"n.a.") -> 0.18660774
... B37: Vietnam | C37: % | D37: EAP | E37: Public | F37: =IFERROR(F246/F228,"n.a.") -> 0.67292077 | G37: =IFERROR(G246/G228,"n.a.") -> 0.91028876 | H37: =IFERROR(H246/H228,"n.a.") -> 0.85904269 | I37: =IFERROR(I246/I228,"n.a.") -> 0.91485348 | J37: =IFERROR(J246/J228,"n.a.") -> 0.88108623 | K37: =IFERROR(K246/K228,"n.a.") -> 0.89217349 | L37: =IFERROR(L246/L228,"n.a.") -> 0.88883686 | M37: =IFERROR(M246/M228,"n.a.") -> 0.88340634 | ... O37: =IFERROR(O246/O228,"n.a.") -> 0.8894177 | P37: =IFERROR(O37-F37,"n.a.") -> 0.21649693 | Q37: =('Sales & Collections'!AE19-'Sales & Collections'!V19)/Costs!V111 -> -0.10833203 | R37: =('Sales & Collections'!AE19/Costs!AE111)-('Sales & Collections'!AE19/Costs!V111) -> 0.32482897 | S37: =MIN(G37:N37) -> 0.85904269 | T37: =MAX(G37:M37) -> 0.91485348 | U37: =IFERROR(STDEV(G37:N37)/GEOMEAN(G37:N37),"n.a.") -> 0.021108957
B38: Full Financial Cost Recovery (tariff revenues)
B39: Colombia | C39: % | D39: LAC | E39: Private | F39: =IFERROR(F230/Costs!V39,"n.a.") -> n.a. | G39: =IFERROR(G230/Costs!W39,"n.a.") -> 0.93589667 | H39: =IFERROR(H230/Costs!X39,"n.a.") -> 1.0902277 | I39: =IFERROR(I230/Costs!Y39,"n.a.") -> 1.1701546 | J39: =IFERROR(J230/Costs!Z39,"n.a.") -> 1.0271786 | K39: =IFERROR(K230/Costs!AA39,"n.a.") -> 1.0045184 | L39: =IFERROR(L230/Costs!AB39,"n.a.") -> 1.052692 | M39: =IFERROR(M230/Costs!AC39,"n.a.") -> 1.0244124 | ... O39: =IFERROR(O230/Costs!AE39,"n.a.") -> 1.0406534 | X39: Tariffs/C3
B40: Dominican Republic | C40: % | D40: LAC | E40: Public | F40: =IFERROR(F231/Costs!V40,"n.a.") -> n.a. | G40: =G22 -> 0.70519218 | H40: =H22 -> 0.64537084 | I40: =I22 -> 0.62126843 | J40: =J22 -> 0.64714685 | K40: =K22 -> 0.61994635 | L40: =L22 -> 0.7327526 | M40: =M22 -> n.a. | N40: =N22 -> n.a. | O40: =AVERAGE(G40:N40) -> 0.66194621
B41: Egypt, Arab Rep. | C41: % | D41: MNA | E41: Public | F41: =IFERROR(F232/Costs!V41,"n.a.") -> n.a. | G41: =IFERROR(G232/Costs!W41,"n.a.") -> n.a. | H41: =IFERROR(H232/Costs!X41,"n.a.") -> 0.61743081 | I41: =IFERROR(I232/Costs!Y41,"n.a.") -> 0.62214293 | J41: =IFERROR(J232/Costs!Z41,"n.a.") -> 0.67704062 | K41: =IFERROR(K232/Costs!AA41,"n.a.") -> 0.69506534 | L41: =IFERROR(L232/Costs!AB41,"n.a.") -> 0.65191951 | M41: =IFERROR(M232/Costs!AC41,"n.a.") -> 0.65565094 | ... O41: =IFERROR(O232/Costs!AE41,"n.a.") -> 0.65126463
B42: India - Andhra Pradesh | C42: % | D42: SAR | E42: Public | F42: =IFERROR(F233/Costs!V42,"n.a.") -> n.a. | G42: =IFERROR(G233/Costs!W42,"n.a.") -> n.a. | H42: =IFERROR(H233/Costs!X42,"n.a.") -> 0.39862488 | I42: =IFERROR(I233/Costs!Y42,"n.a.") -> 0.41184752 | J42: =IFERROR(J233/Costs!Z42,"n.a.") -> 0.39467739 | K42: =IFERROR(K233/Costs!AA42,"n.a.") -> 0.39290335 | L42: =IFERROR(L233/Costs!AB42,"n.a.") -> 0.47799705 | M42: =IFERROR(M233/Costs!AC42,"n.a.") -> n.a. | ... O42: =IFERROR(O233/Costs!AE42,"n.a.") -> 0.41273656
B43: India - Odisha | C43: % | D43: SAR | E43: Public | F43: =IFERROR(F234/Costs!V43,"n.a.") -> n.a. | G43: =IFERROR(G234/Costs!W43,"n.a.") -> n.a. | H43: =IFERROR(H234/Costs!X43,"n.a.") -> 0.93758771 | I43: =IFERROR(I234/Costs!Y43,"n.a.") -> 0.91515302 | J43: =IFERROR(J234/Costs!Z43,"n.a.") -> 0.89531065 | K43: =IFERROR(K234/Costs!AA43,"n.a.") -> 0.91668135 | L43: =IFERROR(L234/Costs!AB43,"n.a.") -> 0.90692378 | M43: =IFERROR(M234/Costs!AC43,"n.a.") -> n.a. | ... O43: =IFERROR(O234/Costs!AE43,"n.a.") -> 0.91442845
B44: India - Rajasthan | C44: % | D44: SAR | E44: Public | F44: =IFERROR(F235/Costs!V44,"n.a.") -> n.a. | G44: =IFERROR(G235/Costs!W44,"n.a.") -> n.a. | H44: =IFERROR(H235/Costs!X44,"n.a.") -> 0.40307895 | I44: =IFERROR(I235/Costs!Y44,"n.a.") -> 0.43949913 | J44: =IFERROR(J235/Costs!Z44,"n.a.") -> 0.50850465 | K44: =IFERROR(K235/Costs!AA44,"n.a.") -> 0.44355414 | L44: =IFERROR(L235/Costs!AB44,"n.a.") -> 0.59254638 | M44: =IFERROR(M235/Costs!AC44,"n.a.") -> n.a. | ... O44: =IFERROR(O235/Costs!AE44,"n.a.") -> 0.47005635
B45: Kenya | C45: % | D45: AFR | E45: Public | F45: =IFERROR(F236/Costs!V45,"n.a.") -> n.a. | G45: =IFERROR(G236/Costs!W45,"n.a.") -> 0.99768831 | H45: =IFERROR(H236/Costs!X45,"n.a.") -> 1.0149762 | I45: =IFERROR(I236/Costs!Y45,"n.a.") -> 0.9476729 | J45: =IFERROR(J236/Costs!Z45,"n.a.") -> 0.88446253 | K45: =IFERROR(K236/Costs!AA45,"n.a.") -> 0.90306655 | L45: =IFERROR(L236/Costs!AB45,"n.a.") -> 0.83210104 | M45: =IFERROR(M236/Costs!AC45,"n.a.") -> 0.82618325 | ... O45: =IFERROR(O236/Costs!AE45,"n.a.") -> 0.91402561
B46: Morocco | C46: % | D46: MNA | E46: Public | F46: =IFERROR(F237/Costs!V46,"n.a.") -> n.a. | G46: =G28 -> n.a. | H46: =H28 -> n.a. | I46: =I28 -> n.a. | J46: =J28 -> 0.84148148 | K46: =K28 -> n.a. | L46: =L28 -> n.a. | M46: =M28 -> n.a. | N46: =N28 -> n.a. | O46: =AVERAGE(G46:N46) -> 0.84148148
...

Sheet Costs
B1: Financial cost per unit - Country level | C1: Unit | D1: Region | E1: Type | F1: Pre-reform | G1: 2010 | H1: 2011 | I1: 2012 | J1: 2013 | K1: 2014 | L1: 2015 | M1: 2016 | N1: 2017 | O1: Average | R1: Financial cost per unit | S1: Unit | T1: Region | U1: Type | V1: 1987 | W1: 2010 | X1: 2011 | Y1: 2012 | Z1: 2013 | AA1: 2014 | AB1: 2015 | AC1: 2016 | AD1: 2017 | AE1: Average | AH1: Source
B2: A1 | R2: A1
B3: Colombia | C3: Current US$/kWh | D3: LAC | E3: Private | F3: n.a. | G3: 0.079219181 | H3: 0.087507206 | I3: 0.087998657 | J3: 0.084381364 | K3: 0.082776668 | L3: 0.064528803 | M3: 0.06751134 | N3: n.a. | O3: =IFERROR(AVERAGE(G3:N3),"n.a.") -> 0.079131888 | R3: Colombia | S3: 2017 US$/kWh | T3: LAC | U3: Private | V3: n.a. | W3: =IFERROR(G3*'Inflation adjustment'!$AH$3/'Inflation adjustment'!AA$3,"n.a.") -> 0.089051515 | X3: =IFERROR(H3*'Inflation adjustment'!$AH$3/'Inflation adjustment'!AB$3,"n.a.") -> 0.095357915 | Y3: =IFERROR(I3*'Inflation adjustment'!$AH$3/'Inflation adjustment'!AC$3,"n.a.") -> 0.093949327 | Z3: =IFERROR(J3*'Inflation adjustment'!$AH$3/'Inflation adjustment'!AD$3,"n.a.") -> 0.088786847 | AA3: =IFERROR(K3*'Inflation adjustment'!$AH$3/'Inflation adjustment'!AE$3,"n.a.") -> 0.085707995 | AB3: =IFERROR(L3*'Inflation adjustment'!$AH$3/'Inflation adjustment'!AF$3,"n.a.") -> 0.066734763 | AC3: =IFERROR(M3*'Inflation adjustment'!$AH$3/'Inflation adjustment'!AG$3,"n.a.") -> 0.068949406 | AD3: =IFERROR(N3*'Inflation adjustment'!$AH$3/'Inflation adjustment'!AH$3,"n.a.") -> n.a. | AE3: =IFERROR(AVERAGE(W3:AD3),"n.a.") -> 0.084076824 | AH3: Country models
B4: Dominican Republic | C4: Current US$/kWh | D4: LAC | E4: Public | F4: n.a. | G4: =G60 -> 0.22355185 | H4: =H60 -> 0.28297225 | I4: =I60 -> 0.31661839 | J4: =J60 -> 0.31498269 | K4: =K60 -> 0.31133266 | L4: =L60 -> 0.22560835 | M4: n.a. | N4: n.a. | O4: =IFERROR(AVERAGE(G4:N4),"n.a.") -> 0.2791777 | R4: Dominican Republic | S4: 2017 US$/kWh | T4: LAC | U4: Public | V4: n.a. | W4: =IFERROR(G4*'Inflation adjustment'!$AH$3/'Inflation adjustment'!AA$3,"n.a.") -> 0.25129812 | X4: =IFERROR(H4*'Inflation adjustment'!$AH$3/'Inflation adjustment'!AB$3,"n.a.") -> 0.3083591 | Y4: =IFERROR(I4*'Inflation adjustment'!$AH$3/'Inflation adjustment'!AC$3,"n.a.") -> 0.33802885 | Z4: =IFERROR(J4*'Inflation adjustment'!$AH$3/'Inflation adjustment'!AD$3,"n.a.") -> 0.33142768 | AA4: =IFERROR(K4*'Inflation adjustment'!$AH$3/'Inflation adjustment'!AE$3,"n.a.") -> 0.32235772 | AB4: =IFERROR(L4*'Inflation adjustment'!$AH$3/'Inflation adjustment'!AF$3,"n.a.") -> 0.23332092 | AC4: =IFERROR(M4*'Inflation adjustment'!$AH$3/'Inflation adjustment'!AG$3,"n.a.") -> n.a. | AD4: =IFERROR(N4*'Inflation adjustment'!$AH$3/'Inflation adjustment'!AH$3,"n.a.") -> n.a. | AE4: =IFERROR(AVERAGE(W4:AD4),"n.a.") -> 0.2974654
B5: Egypt, Arab Rep. | C5: Current US$/kWh | D5: MNA | E5: Public | F5: n.a. | G5: n.a. | H5: 0.026510711 | I5: 0.028679552 | J5: 0.026610193 | K5: 0.029395315 | L5: 0.034056403 | M5: 0.0373025 | N5: n.a. | O5: =IFERROR(AVERAGE(G5:N5),"n.a.") -> 0.030425779 | R5: Egypt, Arab Rep. | S5: 2017 US$/kWh | T5: MNA | U5: Public | V5: n.a. | W5: =IFERROR(G5*'Inflation adjustment'!$AH$3/'Inflation adjustment'!AA$3,"n.a.") -> n.a. | X5: =IFERROR(H5*'Inflation adjustment'!$AH$3/'Inflation adjustment'!AB$3,"n.a.") -> 0.028889119 | Y5: =IFERROR(I5*'Inflation adjustment'!$AH$3/'Inflation adjustment'!AC$3,"n.a.") -> 0.030618929 | Z5: =IFERROR(J5*'Inflation adjustment'!$AH$3/'Inflation adjustment'!AD$3,"n.a.") -> 0.02799949 | AA5: =IFERROR(K5*'Inflation adjustment'!$AH$3/'Inflation adjustment'!AE$3,"n.a.") -> 0.030436276 | AB5: =IFERROR(L5*'Inflation adjustment'!$AH$3/'Inflation adjustment'!AF$3,"n.a.") -> 0.035220644 | AC5: =IFERROR(M5*'Inflation adjustment'!$AH$3/'Inflation adjustment'!AG$3,"n.a.") -> 0.038097084 | AD5: =IFERROR(N5*'Inflation adjustment'!$AH$3/'Inflation adjustment'!AH$3,"n.a.") -> n.a. | AE5: =IFERROR(AVERAGE(W5:AD5),"n.a.") -> 0.031876924
B6: India - Andhra Pradesh | C6: Current US$/kWh | D6: SAR | E6: Public | F6: n.a. | G6: n.a. | H6: 0.082120363 | I6: 0.068505675 | J6: 0.097512196 | K6: 0.079654677 | L6: 0.084504626 | M6: n.a. | N6: n.a. | O6: =IFERROR(AVERAGE(G6:N6),"n.a.") -> 0.082459507 | R6: India - Andhra Pradesh | S6: 2017 US$/kWh | T6: SAR | U6: Public | V6: n.a. | W6: =IFERROR(G6*'Inflation adjustment'!$AH$3/'Inflation adjustment'!AA$3,"n.a.") -> n.a. | X6: =IFERROR(H6*'Inflation adjustment'!$AH$3/'Inflation adjustment'!AB$3,"n.a.") -> 0.089487791 | Y6: =IFERROR(I6*'Inflation adjustment'!$AH$3/'Inflation adjustment'!AC$3,"n.a.") -> 0.073138186 | Z6: =IFERROR(J6*'Inflation adjustment'!$AH$3/'Inflation adjustment'!AD$3,"n.a.") -> 0.10260323 | AA6: =IFERROR(K6*'Inflation adjustment'!$AH$3/'Inflation adjustment'!AE$3,"n.a.") -> 0.082475447 | AB6: =IFERROR(L6*'Inflation adjustment'!$AH$3/'Inflation adjustment'!AF$3,"n.a.") -> 0.087393473 | AC6: =IFERROR(M6*'Inflation adjustment'!$AH$3/'Inflation adjustment'!AG$3,"n.a.") -> n.a. | AD6: =IFERROR(N6*'Inflation adjustment'!$AH$3/'Inflation adjustment'!AH$3,"n.a.") -> n.a. | AE6: =IFERROR(AVERAGE(W6:AD6),"n.a.") -> 0.087019625
B7: India - Odisha | C7: Current US$/kWh | D7: SAR | E7: Public | F7: n.a. | G7: n.a. | H7: 0.086981732 | I7: 0.095092819 | J7: 0.09071712 | K7: 0.093779841 | L7: 0.088167148 | M7: n.a. | N7: n.a. | O7: =IFERROR(AVERAGE(G7:N7),"n.a.") -> 0.090947732 | R7: India - Odisha | S7: 2017 US$/kWh | T7: SAR | U7: Public | V7: n.a. | W7: =IFERROR(G7*'Inflation adjustment'!$AH$3/'Inflation adjustment'!AA$3,"n.a.") -> n.a. | X7: =IFERROR(H7*'Inflation adjustment'!$AH$3/'Inflation adjustment'!AB$3,"n.a.") -> 0.094785297 | Y7: =IFERROR(I7*'Inflation adjustment'!$AH$3/'Inflation adjustment'!AC$3,"n.a.") -> 0.10152321 | Z7: =IFERROR(J7*'Inflation adjustment'!$AH$3/'Inflation adjustment'!AD$3,"n.a.") -> 0.095453387 | AA7: =IFERROR(K7*'Inflation adjustment'!$AH$3/'Inflation adjustment'!AE$3,"n.a.") -> 0.097100818 | AB7: =IFERROR(L7*'Inflation adjustment'!$AH$3/'Inflation adjustment'!AF$3,"n.a.") -> 0.0911812 | AC7: =IFERROR(M7*'Inflation adjustment'!$AH$3/'Inflation adjustment'!AG$3,"n.a.") -> n.a. | AD7: =IFERROR(N7*'Inflation adjustment'!$AH$3/'Inflation adjustment'!AH$3,"n.a.") -> n.a. | AE7: =IFERROR(AVERAGE(W7:AD7),"n.a.") -> 0.096008783
B8: India - Rajasthan | C8: Current US$/kWh | D8: SAR | E8: Public | F8: n.a. | G8: n.a. | H8: 0.095805607 | I8: 0.085011699 | J8: 0.083681958 | K8: 0.098369235 | L8: 0.080206416 | M8: n.a. | N8: n.a. | O8: =IFERROR(AVERAGE(G8:N8),"n.a.") -> 0.088614983 | R8: India - Rajasthan | S8: 2017 US$/kWh | T8: SAR | U8: Public | V8: n.a. | W8: =IFERROR(G8*'Inflation adjustment'!$AH$3/'Inflation adjustment'!AA$3,"n.a.") -> n.a. | X8: =IFERROR(H8*'Inflation adjustment'!$AH$3/'Inflation adjustment'!AB$3,"n.a.") -> 0.10440081 | Y8: =IFERROR(I8*'Inflation adjustment'!$AH$3/'Inflation adjustment'!AC$3,"n.a.") -> 0.090760384 | Z8: =IFERROR(J8*'Inflation adjustment'!$AH$3/'Inflation adjustment'!AD$3,"n.a.") -> 0.088050925 | AA8: =IFERROR(K8*'Inflation adjustment'!$AH$3/'Inflation adjustment'!AE$3,"n.a.") -> 0.10185273 | AB8: =IFERROR(L8*'Inflation adjustment'!$AH$3/'Inflation adjustment'!AF$3,"n.a.") -> 0.082948325 | AC8: =IFERROR(M8*'Inflation adjustment'!$AH$3/'Inflation adjustment'!AG$3,"n.a.") -> n.a. | AD8: =IFERROR(N8*'Inflation adjustment'!$AH$3/'Inflation adjustment'!AH$3,"n.a.") -> n.a. | AE8: =IFERROR(AVERAGE(W8:AD8),"n.a.") -> 0.093602635
B9: Kenya | C9: Current US$/kWh | D9: AFR | E9: Public | F9: n.a. | G9: 0.16159701 | H9: 0.12128442 | I9: 0.16650468 | J9: 0.14590447 | K9: 0.14878772 | L9: 0.12721034 | M9: 0.11777459 | N9: n.a. | O9: =IFERROR(AVERAGE(G9:N9),"n.a.") -> 0.14129475 | R9: Kenya | S9: 2017 US$/kWh | T9: AFR | U9: Public | V9: n.a. | W9: =IFERROR(G9*'Inflation adjustment'!$AH$3/'Inflation adjustment'!AA$3,"n.a.") -> 0.18165371 | X9: =IFERROR(H9*'Inflation adjustment'!$AH$3/'Inflation adjustment'!AB$3,"n.a.") -> 0.13216545 | Y9: =IFERROR(I9*'Inflation adjustment'!$AH$3/'Inflation adjustment'!AC$3,"n.a.") -> 0.17776411 | Z9: =IFERROR(J9*'Inflation adjustment'!$AH$3/'Inflation adjustment'!AD$3,"n.a.") -> 0.15352202 | AA9: =IFERROR(K9*'Inflation adjustment'!$AH$3/'Inflation adjustment'!AE$3,"n.a.") -> 0.15405666 | AB9: =IFERROR(L9*'Inflation adjustment'!$AH$3/'Inflation adjustment'!AF$3,"n.a.") -> 0.13155911 | AC9: =IFERROR(M9*'Inflation adjustment'!$AH$3/'Inflation adjustment'!AG$3,"n.a.") -> 0.12028332 | AD9: =IFERROR(N9*'Inflation adjustment'!$AH$3/'Inflation adjustment'!AH$3,"n.a.") -> n.a. | AE9: =IFERROR(AVERAGE(W9:AD9),"n.a.") -> 0.15014348
B10: Morocco | C10: Current US$/kWh | D10: MNA | E10: Public | F10: n.a. | G10: n.a. | H10: n.a. | I10: n.a. | J10: n.a. | K10: n.a. | L10: n.a. | M10: n.a. | N10: n.a. | O10: =IFERROR(AVERAGE(G10:N10),"n.a.") -> n.a. | R10: Morocco | S10: 2017 US$/kWh | T10: MNA | U10: Public | V10: n.a. | W10: =IFERROR(G10*'Inflation adjustment'!$AH$3/'Inflation adjustment'!AA$3,"n.a.") -> n.a. | X10: =IFERROR(H10*'Inflation adjustment'!$AH$3/'Inflation adjustment'!AB$3,"n.a.") -> n.a. | Y10: =IFERROR(I10*'Inflation adjustment'!$AH$3/'Inflation adjustment'!AC$3,"n.a.") -> n.a. | Z10: =IFERROR(J10*'Inflation adjustment'!$AH$3/'Inflation adjustment'!AD$3,"n.a.") -> n.a. | AA10: =IFERROR(K10*'Inflation adjustment'!$AH$3/'Inflation adjustment'!AE$3,"n.a.") -> n.a. | AB10: =IFERROR(L10*'Inflation adjustment'!$AH$3/'Inflation adjustment'!AF$3,"n.a.") -> n.a. | AC10: =IFERROR(M10*'Inflation adjustment'!$AH$3/'Inflation adjustment'!AG$3,"n.a.") -> n.a. | AD10: =IFERROR(N10*'Inflation adjustment'!$AH$3/'Inflation adjustment'!AH$3,"n.a.") -> n.a. | AE10: =IFERROR(AVERAGE(W10:AD10),"n.a.") -> n.a.
B11: Pakistan | C11: Current US$/kWh | D11: SAR | E11: Mixed | F11: n.a. | G11: n.a. | H11: n.a. | I11: n.a. | J11: 0.090476352 | K11: 0.083579815 | L11: 0.077019315 | M11: 0.065316791 | N11: n.a. | O11: =IFERROR(AVERAGE(G11:N11),"n.a.") -> 0.079098068 | R11: Pakistan | S11: 2017 US$/kWh | T11: SAR | U11: Mixed | V11: n.a. | W11: =IFERROR(G11*'Inflation adjustment'!$AH$3/'Inflation adjustment'!AA$3,"n.a.") -> n.a. | X11: =IFERROR(H11*'Inflation adjustment'!$AH$3/'Inflation adjustment'!AB$3,"n.a.") -> n.a. | Y11: =IFERROR(I11*'Inflation adjustment'!$AH$3/'Inflation adjustment'!AC$3,"n.a.") -> n.a. | Z11: =IFERROR(J11*'Inflation adjustment'!$AH$3/'Inflation adjustment'!AD$3,"n.a.") -> 0.095200049 | AA11: =IFERROR(K11*'Inflation adjustment'!$AH$3/'Inflation adjustment'!AE$3,"n.a.") -> 0.086539585 | AB11: =IFERROR(L11*'Inflation adjustment'!$AH$3/'Inflation adjustment'!AF$3,"n.a.") -> 0.079652272 | AC11: =IFERROR(M11*'Inflation adjustment'!$AH$3/'Inflation adjustment'!AG$3,"n.a.") -> 0.06670811 | AD11: =IFERROR(N11*'Inflation adjustment'!$AH$3/'Inflation adjustment'!AH$3,"n.a.") -> n.a. | AE11: =IFERROR(AVERAGE(W11:AD11),"n.a.") -> 0.082025004
B12: Peru | C12: Current US$/kWh | D12: LAC | E12: Mixed | F12: n.a. | G12: 0.076105924 | H12: 0.079412779 | I12: 0.090800724 | J12: 0.093564209 | K12: 0.099215619 | L12: 0.097942808 | M12: 0.10407765 | N12: n.a. | O12: =IFERROR(AVERAGE(G12:N12),"n.a.") -> 0.09158853 | R12: Peru | S12: 2017 US$/kWh | T12: LAC | U12: Mixed | V12: n.a. | W12: =IFERROR(G12*'Inflation adjustment'!$AH$3/'Inflation adjustment'!AA$3,"n.a.") -> 0.085551854 | X12: =IFERROR(H12*'Inflation adjustment'!$AH$3/'Inflation adjustment'!AB$3,"n.a.") -> 0.086537296 | Y12: =IFERROR(I12*'Inflation adjustment'!$AH$3/'Inflation adjustment'!AC$3,"n.a.") -> 0.096940877 | Z12: =IFERROR(J12*'Inflation adjustment'!$AH$3/'Inflation adjustment'!AD$3,"n.a.") -> 0.09844912 | AA12: =IFERROR(K12*'Inflation adjustment'!$AH$3/'Inflation adjustment'!AE$3,"n.a.") -> 0.10272909 | AB12: =IFERROR(L12*'Inflation adjustment'!$AH$3/'Inflation adjustment'!AF$3,"n.a.") -> 0.10129105 | AC12: =IFERROR(M12*'Inflation adjustment'!$AH$3/'Inflation adjustment'!AG$3,"n.a.") -> 0.10629462 | AD12: =IFERROR(N12*'Inflation adjustment'!$AH$3/'Inflation adjustment'!AH$3,"n.a.") -> n.a. | AE12: =IFERROR(AVERAGE(W12:AD12),"n.a.") -> 0.096827701
B13: Philippines | C13: Current US$/kWh | D13: EAP | E13: Private | F13: n.a. | G13: 0.16446181 | H13: 0.17761957 | I13: 0.18995132 | J13: 0.18742841 | K13: 0.15195116 | L13: 0.1369573 | M13: 0.11775828 | N13: n.a. | O13: =IFERROR(AVERAGE(G13:N13),"n.a.") -> 0.16087541 | R13: Philippines | S13: 2017 US$/kWh | T13: EAP | U13: Private | V13: n.a. | W13: =IFERROR(G13*'Inflation adjustment'!$AH$3/'Inflation adjustment'!AA$3,"n.a.") -> 0.18487408 | X13: =IFERROR(H13*'Inflation adjustment'!$AH$3/'Inflation adjustment'!AB$3,"n.a.") -> 0.19355471 | Y13: =IFERROR(I13*'Inflation adjustment'!$AH$3/'Inflation adjustment'!AC$3,"n.a.") -> 0.20279627 | Z13: =IFERROR(J13*'Inflation adjustment'!$AH$3/'Inflation adjustment'!AD$3,"n.a.") -> 0.19721389 | AA13: =IFERROR(K13*'Inflation adjustment'!$AH$3/'Inflation adjustment'!AE$3,"n.a.") -> 0.15733212 | AB13: =IFERROR(L13*'Inflation adjustment'!$AH$3/'Inflation adjustment'!AF$3,"n.a.") -> 0.14163928 | AC13: =IFERROR(M13*'Inflation adjustment'!$AH$3/'Inflation adjustment'!AG$3,"n.a.") -> 0.12026666 | AD13: =IFERROR(N13*'Inflation adjustment'!$AH$3/'Inflation adjustment'!AH$3,"n.a.") -> n.a. | AE13: =IFERROR(AVERAGE(W13:AD13),"n.a.") -> 0.17109672
B14: Senegal | C14: Current US$/kWh | D14: AFR | E14: Public | F14: n.a. | G14: 0.27929705 | H14: 0.24968097 | I14: 0.24859571 | J14: 0.23533313 | K14: 0.24852823 | L14: 0.1808667 | M14: 0.19646559 | N14: n.a. | O14: =IFERROR(AVERAGE(G14:N14),"n.a.") -> 0.23410962 | R14: Senegal | S14: 2017 US$/kWh | T14: AFR | U14: Public | V14: n.a. | W14: =IFERROR(G14*'Inflation adjustment'!$AH$3/'Inflation adjustment'!AA$3,"n.a.") -> 0.31396216 | X14: =IFERROR(H14*'Inflation adjustment'!$AH$3/'Inflation adjustment'!AB$3,"n.a.") -> 0.2720811 | Y14: =IFERROR(I14*'Inflation adjustment'!$AH$3/'Inflation adjustment'!AC$3,"n.a.") -> 0.26540632 | Z14: =IFERROR(J14*'Inflation adjustment'!$AH$3/'Inflation adjustment'!AD$3,"n.a.") -> 0.24761968 | AA14: =IFERROR(K14*'Inflation adjustment'!$AH$3/'Inflation adjustment'!AE$3,"n.a.") -> 0.25732924 | AB14: =IFERROR(L14*'Inflation adjustment'!$AH$3/'Inflation adjustment'!AF$3,"n.a.") -> 0.18704975 | AC14: =IFERROR(M14*'Inflation adjustment'!$AH$3/'Inflation adjustment'!AG$3,"n.a.") -> 0.20065052 | AD14: =IFERROR(N14*'Inflation adjustment'!$AH$3/'Inflation adjustment'!AH$3,"n.a.") -> n.a. | AE14: =IFERROR(AVERAGE(W14:AD14),"n.a.") -> 0.24915697
B15: Tajikistan | C15: Current US$/kWh | D15: ECA | E15: Public | F15: n.a. | G15: n.a. | H15: n.a. | I15: n.a. | J15: 0.015599243 | K15: 0.01567062 | L15: 0.011713544 | M15: 0.013310213 | N15: n.a. | O15: =IFERROR(AVERAGE(G15:N15),"n.a.") -> 0.014073405 | R15: Tajikistan | S15: 2017 US$/kWh | T15: ECA | U15: Public | V15: n.a. | W15: =IFERROR(G15*'Inflation adjustment'!$AH$3/'Inflation adjustment'!AA$3,"n.a.") -> n.a. | X15: =IFERROR(H15*'Inflation adjustment'!$AH$3/'Inflation adjustment'!AB$3,"n.a.") -> n.a. | Y15: =IFERROR(I15*'Inflation adjustment'!$AH$3/'Inflation adjustment'!AC$3,"n.a.") -> n.a. | Z15: =IFERROR(J15*'Inflation adjustment'!$AH$3/'Inflation adjustment'!AD$3,"n.a.") -> 0.016413667 | AA15: =IFERROR(K15*'Inflation adjustment'!$AH$3/'Inflation adjustment'!AE$3,"n.a.") -> 0.016225556 | AB15: =IFERROR(L15*'Inflation adjustment'!$AH$3/'Inflation adjustment'!AF$3,"n.a.") -> 0.01211398 | AC15: =IFERROR(M15*'Inflation adjustment'!$AH$3/'Inflation adjustment'!AG$3,"n.a.") -> 0.013593735 | AD15: =IFERROR(N15*'Inflation adjustment'!$AH$3/'Inflation adjustment'!AH$3,"n.a.") -> n.a. | AE15: =IFERROR(AVERAGE(W15:AD15),"n.a.") -> 0.014586734
B16: Tanzania | C16: Current US$/kWh | D16: AFR | E16: Public | F16: n.a. | G16: n.a. | H16: n.a. | I16: 0.14448677 | J16: 0.16296886 | K16: n.a. | L16: 0.1232226 | M16: 0.10440412 | N16: n.a. | O16: =IFERROR(AVERAGE(G16:N16),"n.a.") -> 0.13377059 | R16: Tanzania | S16: 2017 US$/kWh | T16: AFR | U16: Public | V16: n.a. | W16: =IFERROR(G16*'Inflation adjustment'!$AH$3/'Inflation adjustment'!AA$3,"n.a.") -> n.a. | X16: =IFERROR(H16*'Inflation adjustment'!$AH$3/'Inflation adjustment'!AB$3,"n.a.") -> n.a. | Y16: =IFERROR(I16*'Inflation adjustment'!$AH$3/'Inflation adjustment'!AC$3,"n.a.") -> 0.1542573 | Z16: =IFERROR(J16*'Inflation adjustment'!$AH$3/'Inflation adjustment'!AD$3,"n.a.") -> 0.17147733 | AA16: n.a. | AB16: 0.12758622 | AC16: 0.10797324 | AD16: =IFERROR(N16*'Inflation adjustment'!$AH$3/'Inflation adjustment'!AH$3,"n.a.") -> n.a. | AE16: =IFERROR(AVERAGE(W16:AD16),"n.a.") -> 0.14032352
B17: Uganda | C17: Current US$/kWh | D17: AFR | E17: Private | F17: n.a. | G17: n.a. | H17: n.a. | I17: 0.14253815 | J17: 0.13925368 | K17: 0.13173169 | L17: 0.12073561 | M17: 0.11421765 | N17: n.a. | O17: =IFERROR(AVERAGE(G17:N17),"n.a.") -> 0.12969536 | R17: Uganda | S17: 2017 US$/kWh | T17: AFR | U17: Private | V17: n.a. | W17: =IFERROR(G17*'Inflation adjustment'!$AH$3/'Inflation adjustment'!AA$3,"n.a.") -> n.a. | X17: =IFERROR(H17*'Inflation adjustment'!$AH$3/'Inflation adjustment'!AB$3,"n.a.") -> n.a. | Y17: =IFERROR(I17*'Inflation adjustment'!$AH$3/'Inflation adjustment'!AC$3,"n.a.") -> 0.15217691 | Z17: =IFERROR(J17*'Inflation adjustment'!$AH$3/'Inflation adjustment'!AD$3,"n.a.") -> 0.146524 | AA17: =IFERROR(K17*'Inflation adjustment'!$AH$3/'Inflation adjustment'!AE$3,"n.a.") -> 0.13639664 | AB17: =IFERROR(L17*'Inflation adjustment'!$AH$3/'Inflation adjustment'!AF$3,"n.a.") -> 0.12486304 | AC17: =IFERROR(M17*'Inflation adjustment'!$AH$3/'Inflation adjustment'!AG$3,"n.a.") -> 0.11665061 | AD17: =IFERROR(N17*'Inflation adjustment'!$AH$3/'Inflation adjustment'!AH$3,"n.a.") -> n.a. | AE17: =IFERROR(AVERAGE(W17:AD17),"n.a.") -> 0.13532224
B18: Ukraine | C18: Current US$/kWh | D18: ECA | E18: Mixed | F18: n.a. | G18: n.a. | H18: n.a. | I18: 0.073287909 | J18: 0.069842227 | K18: 0.052412946 | L18: 0.040097189 | M18: 0.043199216 | N18: 0.045924694 | O18: =IFERROR(AVERAGE(G18:N18),"n.a.") -> 0.054127363 | R18: Ukraine | S18: 2017 US$/kWh | T18: ECA | U18: Mixed | V18: n.a. | W18: =IFERROR(G18*'Inflation adjustment'!$AH$3/'Inflation adjustment'!AA$3,"n.a.") -> n.a. | X18: =IFERROR(H18*'Inflation adjustment'!$AH$3/'Inflation adjustment'!AB$3,"n.a.") -> n.a. | Y18: =IFERROR(I18*'Inflation adjustment'!$AH$3/'Inflation adjustment'!AC$3,"n.a.") -> 0.078243806 | Z18: =IFERROR(J18*'Inflation adjustment'!$AH$3/'Inflation adjustment'!AD$3,"n.a.") -> 0.073488633 | AA18: =IFERROR(K18*'Inflation adjustment'!$AH$3/'Inflation adjustment'!AE$3,"n.a.") -> 0.054269019 | AB18: =IFERROR(L18*'Inflation adjustment'!$AH$3/'Inflation adjustment'!AF$3,"n.a.") -> 0.041467938 | AC18: =IFERROR(M18*'Inflation adjustment'!$AH$3/'Inflation adjustment'!AG$3,"n.a.") -> 0.044119407 | AD18: =IFERROR(N18*'Inflation adjustment'!$AH$3/'Inflation adjustment'!AH$3,"n.a.") -> 0.045924694 | AE18: =IFERROR(AVERAGE(W18:AD18),"n.a.") -> 0.056252249
B19: Vietnam | C19: Current US$/kWh | D19: EAP | E19: Public | F19: n.a. | G19: 0.050130776 | H19: 0.055452512 | I19: 0.058694803 | J19: 0.064884385 | K19: 0.067327743 | L19: 0.0696931 | M19: 0.072269036 | N19: n.a. | O19: =IFERROR(AVERAGE(G19:N19),"n.a.") -> 0.062636051 | R19: Vietnam | S19: 2017 US$/kWh | T19: EAP | U19: Public | V19: n.a. | W19: =IFERROR(G19*'Inflation adjustment'!$AH$3/'Inflation adjustment'!AA$3,"n.a.") -> 0.056352786 | X19: =IFERROR(H19*'Inflation adjustment'!$AH$3/'Inflation adjustment'!AB$3,"n.a.") -> 0.060427434 | Y19: =IFERROR(I19*'Inflation adjustment'!$AH$3/'Inflation adjustment'!AC$3,"n.a.") -> 0.06266388 | Z19: =IFERROR(J19*'Inflation adjustment'!$AH$3/'Inflation adjustment'!AD$3,"n.a.") -> 0.068271946 | AA19: =IFERROR(K19*'Inflation adjustment'!$AH$3/'Inflation adjustment'!AE$3,"n.a.") -> 0.069711985 | AB19: =IFERROR(L19*'Inflation adjustment'!$AH$3/'Inflation adjustment'!AF$3,"n.a.") -> 0.072075605 | AC19: =IFERROR(M19*'Inflation adjustment'!$AH$3/'Inflation adjustment'!AG$3,"n.a.") -> 0.073808446 | AD19: =IFERROR(N19*'Inflation adjustment'!$AH$3/'Inflation adjustment'!AH$3,"n.a.") -> n.a. | AE19: =IFERROR(AVERAGE(W19:AD19),"n.a.") -> 0.06618744
B20: A2 | R20: A2
B21: Colombia | C21: Current US$/kWh | D21: LAC | E21: Private | F21: n.a. | G21: 0.12812138 | H21: 0.1141869 | I21: 0.10817999 | J21: 0.11683024 | K21: 0.11498493 | L21: 0.081847087 | M21: 0.086783296 | N21: n.a. | O21: =IFERROR(AVERAGE(G21:N21),"n.a.") -> 0.10727626 | R21: Colombia | S21: 2017 US$/kWh | T21: LAC | U21: Private | V21: n.a. | W21: =IFERROR(G21*'Inflation adjustment'!$AH$3/'Inflation adjustment'!AA$3,"n.a.") -> 0.14402324 | X21: =IFERROR(H21*'Inflation adjustment'!$AH$3/'Inflation adjustment'!AB$3,"n.a.") -> 0.12443117 | Y21: =IFERROR(I21*'Inflation adjustment'!$AH$3/'Inflation adjustment'!AC$3,"n.a.") -> 0.11549537 | Z21: =IFERROR(J21*'Inflation adjustment'!$AH$3/'Inflation adjustment'!AD$3,"n.a.") -> 0.12292986 | AA21: =IFERROR(K21*'Inflation adjustment'!$AH$3/'Inflation adjustment'!AE$3,"n.a.") -> 0.11905683 | AB21: =IFERROR(L21*'Inflation adjustment'!$AH$3/'Inflation adjustment'!AF$3,"n.a.") -> 0.084645084 | AC21: =IFERROR(M21*'Inflation adjustment'!$AH$3/'Inflation adjustment'!AG$3,"n.a.") -> 0.088631876 | AD21: =IFERROR(N21*'Inflation adjustment'!$AH$3/'Inflation adjustment'!AH$3,"n.a.") -> n.a. | AE21: =IFERROR(AVERAGE(W21:AD21),"n.a.") -> 0.11417335
