Workbook

Sheet Summary
A1: Excise diagnostic: cross-country workbook (Uganda, Sierra Leone, Liberia)
A2: Data quality at a glance. All figures below are formulas over the other sheets.
A4: Indicator | B4: Sierra Leone | C4: Uganda | D4: Liberia | E4: How computed
A5: Cut-off date | B5: =Parameters!G5 -> 2026-04-27 | C5: =Parameters!G6 -> 2026-04-27 | D5: =Parameters!G7 -> 2026-09-29 | E5: Parameters
A6: Standard lines covered (of 30) | B6: =Std_Schedule!F41 -> 25 | C6: =Std_Schedule!L41 -> 26 | D6: =Std_Schedule!R41 -> 21 | E6: Std_Schedule coverage 1 + 2
A7: National rate rows (covered) | B7: =COUNTIFS(Std_Schedule_Code!$B$5:$B$191,"SLE",Std_Schedule_Code!$J$5:$J$191,">0") -> 69 | C7: =COUNTIFS(Std_Schedule_Code!$B$5:$B$191,"UGA",Std_Schedule_Code!$J$5:$J$191,">0") -> 62 | D7: =COUNTIFS(Std_Schedule_Code!$B$5:$B$191,"LBR",Std_Schedule_Code!$J$5:$J$191,">0") -> 38 | E7: Std_Schedule_Code rows with coverage 1 or 2
A8: Average DQ, schedule rows (covered) | B8: =IFERROR(AVERAGEIFS(Std_Schedule_Code!$AO$5:$AO$191,Std_Schedule_Code!$B$5:$B$191,"SLE",Std_Schedule_Code!$J$5:$J$191,">0"),"") -> 3.3188406 | C8: =IFERROR(AVERAGEIFS(Std_Schedule_Code!$AO$5:$AO$191,Std_Schedule_Code!$B$5:$B$191,"UGA",Std_Schedule_Code!$J$5:$J$191,">0"),"") -> 2 | D8: =IFERROR(AVERAGEIFS(Std_Schedule_Code!$AO$5:$AO$191,Std_Schedule_Code!$B$5:$B$191,"LBR",Std_Schedule_Code!$J$5:$J$191,">0"),"") -> 3.7105263 | E8: Mean of dq_score
A9: Share of schedule rows with DQ >= 4 | B9: =IFERROR(COUNTIFS(Std_Schedule_Code!$B$5:$B$191,"SLE",Std_Schedule_Code!$J$5:$J$191,">0",Std_Schedule_Code!$AO$5:$AO$191,">=4")/COUNTIFS(Std_Schedule_Code!$B$5:$B$191,"SLE",Std_Schedule_Code!$J$5:$J$191,">0"),"") -> 0.50724638 | C9: =IFERROR(COUNTIFS(Std_Schedule_Code!$B$5:$B$191,"UGA",Std_Schedule_Code!$J$5:$J$191,">0",Std_Schedule_Code!$AO$5:$AO$191,">=4")/COUNTIFS(Std_Schedule_Code!$B$5:$B$191,"UGA",Std_Schedule_Code!$J$5:$J$191,">0"),"") -> 0 | D9: =IFERROR(COUNTIFS(Std_Schedule_Code!$B$5:$B$191,"LBR",Std_Schedule_Code!$J$5:$J$191,">0",Std_Schedule_Code!$AO$5:$AO$191,">=4")/COUNTIFS(Std_Schedule_Code!$B$5:$B$191,"LBR",Std_Schedule_Code!$J$5:$J$191,">0"),"") -> 0.65789474 | E9: Rows verified or corrected
A10: Rows shown at last legible rate | B10: =COUNTIFS(Std_Schedule_Code!$B$5:$B$191,"SLE",Std_Schedule_Code!$O$5:$O$191,"last_legible") -> 16 | C10: =COUNTIFS(Std_Schedule_Code!$B$5:$B$191,"UGA",Std_Schedule_Code!$O$5:$O$191,"last_legible") -> 0 | D10: =COUNTIFS(Std_Schedule_Code!$B$5:$B$191,"LBR",Std_Schedule_Code!$O$5:$O$191,"last_legible") -> 0 | E10: Current rate not legible in the published law
A11: Standard lines with DQ <= 2 (incl. not-covered findings) | B11: =COUNTIF(Std_Schedule!J6:J35,"<=2") -> 16 | C11: =COUNTIF(Std_Schedule!P6:P35,"<=2") -> 30 | D11: =COUNTIF(Std_Schedule!V6:V35,"<=2") -> 3 | E11: Std_Schedule DQ columns
A12: Average DQ, country metrics | B12: =IFERROR(AVERAGE(Country_Metrics!G5:G41),"") -> 2.6857143 | C12: =IFERROR(AVERAGE(Country_Metrics!K5:K41),"") -> 1.8571429 | D12: =IFERROR(AVERAGE(Country_Metrics!O5:O41),"") -> 3.6857143 | E12: Mean of Country_Metrics DQ
A14: Sheets
A15: Country_Metrics | B15: (a) Overall metrics and the seven key questions by country, with DQ per cell.
A16: Std_Schedule | B16: (b) Human-readable standardized schedule: 30 standard lines x 3 countries, with coverage and DQ.
A17: Std_Schedule_Code | B17: (b) Code-readable schedule: one row per rate component; specific and ad valorem parts of hybrids on separate rows; USD computed by formula.
A18: Parameters | B18: Exchange rates, cut-off dates, GDP and conversion factors (inputs in blue).
A19: DQ_Scale | B19: Data-quality scale mapped from peer-review status.
A20: Sources | B20: Documents behind each country and version notes.
A22: Read before use
A23: Cut-off dates differ: Uganda and Sierra Leone at 27 April 2026 (WP v0.8); Liberia at 29 September 2026.
A24: Uganda lines are extracted but not yet peer reviewed, so they score DQ 2 throughout.
A25: Sierra Leone spirits, other fermented beverages and all SSB lines show the last legible (FA2023) rates; the FA2024 replacement rows are not legible (DQ 1).
A26: Liberia's 2026 rates read the 'Proposed' column of the December 2025 Act as in force; this is verified text with an open interpretation point (DQ 4).
A27: Mapping of HS 2206 (cider, perry, mead) to A3 differs between WP v0.8 (not mapped) and Liberia v0.3 (A3). The code sheet applies HS 2206 -> A3 for all three; the human-readable sheet keeps each report's coverage.
A28: The 'part' column groups codes into 1 Fuel, 2 Vehicles, 3 Health, 4 Other (plastics E7 placed in Other; gambling G1 in Health, following the WP's 'Health (other)' category; both placements are provisional).
A29: Editable inputs: blue cells (rate_value, conv_to_std_unit, ref_price_per_rate_unit, Parameters). To add a country, add a Parameters row and append rows to Std_Schedule_Code following the existing rows.

Sheet Country_Metrics
A1: Overall metrics and key questions by country
A2: Values as published in each diagnostic. Status column drives the DQ score (formula). Benchmarks from the process specification, section 9.
A4: Section | B4: ID | C4: Metric / question | D4: Unit | E4: SLE: Value | F4: SLE: Review status | G4: SLE: DQ | H4: SLE: Source / ref. | I4: UGA: Value | J4: UGA: Review status | K4: UGA: DQ | L4: UGA: Source / ref. | M4: LBR: Value | N4: LBR: Review status | O4: LBR: DQ | P4: LBR: Source / ref. | Q4: International reference | R4: Notes
A5: Context | B5: X1 | C5: Legal basis at cut-off | D5: text | E5: Excise Act 1982 as amended through Finance Act 2026 (eff. 1 Jan 2026) | F5: partly_verified | G5: =IF(F5="","",IFERROR(INDEX(DQ_Scale!$B$5:$B$14,MATCH(F5,DQ_Scale!$A$5:$A$14,0)),"")) -> 3 | H5: PR-01 | I5: Excise Duty Act 2014 as amended through the 2025 Amendment Acts (eff. 1 Jul 2025); 2026 Bill not assented | J5: not_reviewed | K5: =IF(J5="","",IFERROR(INDEX(DQ_Scale!$B$5:$B$14,MATCH(J5,DQ_Scale!$A$5:$A$14,0)),"")) -> 2 | L5: WP Table 13 | M5: Revenue Code Part IV, Ch. 11, as amended through the Tax Amendment Act of Dec 2025 (in force 1 Apr 2026; LRA from 1 May 2026) | N5: verified_open_point | O5: =IF(N5="","",IFERROR(INDEX(DQ_Scale!$B$5:$B$14,MATCH(N5,DQ_Scale!$A$5:$A$14,0)),"")) -> 4 | P5: PR-17, PR-01
A6: Context | B6: X2 | C6: Cut-off date | D6: date | E6: 2026-04-27 | F6: verified | G6: =IF(F6="","",IFERROR(INDEX(DQ_Scale!$B$5:$B$14,MATCH(F6,DQ_Scale!$A$5:$A$14,0)),"")) -> 5 | H6: WP s.7 | I6: 2026-04-27 | J6: verified | K6: =IF(J6="","",IFERROR(INDEX(DQ_Scale!$B$5:$B$14,MATCH(J6,DQ_Scale!$A$5:$A$14,0)),"")) -> 5 | L6: WP s.7 | M6: 2026-09-29 | N6: verified | O6: =IF(N6="","",IFERROR(INDEX(DQ_Scale!$B$5:$B$14,MATCH(N6,DQ_Scale!$A$5:$A$14,0)),"")) -> 5 | P6: v0.3 s.7
A7: Context | B7: X3 | C7: Working exchange rate | D7: LCU per USD | E7: NLe 22 (MoF 22.665-23; USD values may be ~4% high) | F7: assumption | G7: =IF(F7="","",IFERROR(INDEX(DQ_Scale!$B$5:$B$14,MATCH(F7,DQ_Scale!$A$5:$A$14,0)),"")) -> 1 | H7: PR-40 | I7: UGX 3,750 | J7: not_reviewed | K7: =IF(J7="","",IFERROR(INDEX(DQ_Scale!$B$5:$B$14,MATCH(J7,DQ_Scale!$A$5:$A$14,0)),"")) -> 2 | L7: WP Table 13 | M7: LRD 171.59 (CBL mid); excise rates printed in US$ | N7: verified | O7: =IF(N7="","",IFERROR(INDEX(DQ_Scale!$B$5:$B$14,MATCH(N7,DQ_Scale!$A$5:$A$14,0)),"")) -> 5 | P7: PR-39
A8: Context | B8: X4 | C8: Nominal GDP | D8: USD bn | E8: 7.5 (2026 working; MoF 2025 ~7.2) | F8: partly_verified | G8: =IF(F8="","",IFERROR(INDEX(DQ_Scale!$B$5:$B$14,MATCH(F8,DQ_Scale!$A$5:$A$14,0)),"")) -> 3 | H8: PR-41 | I8: 55 (WB 2024: 53.65) | J8: not_reviewed | K8: =IF(J8="","",IFERROR(INDEX(DQ_Scale!$B$5:$B$14,MATCH(J8,DQ_Scale!$A$5:$A$14,0)),"")) -> 2 | L8: WP Table 13 | M8: 5.25 (2025, WDI) | N8: verified | O8: =IF(N8="","",IFERROR(INDEX(DQ_Scale!$B$5:$B$14,MATCH(N8,DQ_Scale!$A$5:$A$14,0)),"")) -> 5 | P8: PR-41
A9: Context | B9: X5 | C9: Currency notation of rates | D9: text | E9: US$ -> 'Le' -> 'NLe'; 'Le' confirmed as new Leones | F9: verified | G9: =IF(F9="","",IFERROR(INDEX(DQ_Scale!$B$5:$B$14,MATCH(F9,DQ_Scale!$A$5:$A$14,0)),"")) -> 5 | H9: PR-07 | I9: UGX throughout | J9: not_reviewed | K9: =IF(J9="","",IFERROR(INDEX(DQ_Scale!$B$5:$B$14,MATCH(J9,DQ_Scale!$A$5:$A$14,0)),"")) -> 2 | M9: US$ / '$' (read as US$) | N9: verified | O9: =IF(N9="","",IFERROR(INDEX(DQ_Scale!$B$5:$B$14,MATCH(N9,DQ_Scale!$A$5:$A$14,0)),"")) -> 5 | P9: PR-16
A10: Context | B10: X6 | C10: Peer review (stage A5) | D10: entries | E10: 49 entries: 18 verified, 11 partly, 16 corrected, 4 not verified | G10: =IF(F10="","",IFERROR(INDEX(DQ_Scale!$B$5:$B$14,MATCH(F10,DQ_Scale!$A$5:$A$14,0)),"")) | H10: WP Annex D | I10: Not yet peer reviewed | K10: =IF(J10="","",IFERROR(INDEX(DQ_Scale!$B$5:$B$14,MATCH(J10,DQ_Scale!$A$5:$A$14,0)),"")) | L10: WP note v0.8 | M10: 49 entries: 22 verified, 11 partly, 14 corrected, 2 not verified | O10: =IF(N10="","",IFERROR(INDEX(DQ_Scale!$B$5:$B$14,MATCH(N10,DQ_Scale!$A$5:$A$14,0)),"")) | P10: v0.3 Annex B
A11: Revenue | B11: R1 | C11: Excise collected, all lines | D11: % of GDP | E11: 1.25-1.28% (2024-25) | F11: corrected | G11: =IF(F11="","",IFERROR(INDEX(DQ_Scale!$B$5:$B$14,MATCH(F11,DQ_Scale!$A$5:$A$14,0)),"")) -> 4 | H11: PR-48 | I11: n.a. (not collected for WP) | J11: data_gap | K11: =IF(J11="","",IFERROR(INDEX(DQ_Scale!$B$5:$B$14,MATCH(J11,DQ_Scale!$A$5:$A$14,0)),"")) -> 1 | M11: 0.373% (FY2024); 0.378% (FY2023) | N11: verified | O11: =IF(N11="","",IFERROR(INDEX(DQ_Scale!$B$5:$B$14,MATCH(N11,DQ_Scale!$A$5:$A$14,0)),"")) -> 5 | P11: PR-28, PR-29 | Q11: Africa avg 2.4%; low-income 2.2% (2021)
A12: Revenue | B12: R2 | C12: Excise plus excise-like levies collected | D12: % of GDP | E12: n.a. (levies not reported) | F12: data_gap | G12: =IF(F12="","",IFERROR(INDEX(DQ_Scale!$B$5:$B$14,MATCH(F12,DQ_Scale!$A$5:$A$14,0)),"")) -> 1 | I12: n.a. | J12: data_gap | K12: =IF(J12="","",IFERROR(INDEX(DQ_Scale!$B$5:$B$14,MATCH(J12,DQ_Scale!$A$5:$A$14,0)),"")) -> 1 | M12: 1.254% (FY2024: excise + Road Fund 0.665% + motor vehicle 0.215%) | N12: verified | O12: =IF(N12="","",IFERROR(INDEX(DQ_Scale!$B$5:$B$14,MATCH(N12,DQ_Scale!$A$5:$A$14,0)),"")) -> 5 | P12: PR-25, PR-38
A13: Revenue | B13: R3 | C13: Fuel excise collected | D13: % of GDP | E13: 1.12-1.15% (2024-25) | F13: corrected | G13: =IF(F13="","",IFERROR(INDEX(DQ_Scale!$B$5:$B$14,MATCH(F13,DQ_Scale!$A$5:$A$14,0)),"")) -> 4 | H13: PR-48 | I13: n.a. | J13: data_gap | K13: =IF(J13="","",IFERROR(INDEX(DQ_Scale!$B$5:$B$14,MATCH(J13,DQ_Scale!$A$5:$A$14,0)),"")) -> 1 | M13: Not in excise law. Road Fund line 0.665% (may include non-fuel receipts) | N13: partly_verified | O13: =IF(N13="","",IFERROR(INDEX(DQ_Scale!$B$5:$B$14,MATCH(N13,DQ_Scale!$A$5:$A$14,0)),"")) -> 3 | P13: PR-25, PR-48
A14: Revenue | B14: R4 | C14: Fuel excise implied at current rates | D14: % of GDP | E14: ~1.6% (1.58%, FA2026) | F14: estimate | G14: =IF(F14="","",IFERROR(INDEX(DQ_Scale!$B$5:$B$14,MATCH(F14,DQ_Scale!$A$5:$A$14,0)),"")) -> 2 | H14: WP Table 14 | I14: ~1.3% (1.29%) | J14: estimate | K14: =IF(J14="","",IFERROR(INDEX(DQ_Scale!$B$5:$B$14,MATCH(J14,DQ_Scale!$A$5:$A$14,0)),"")) -> 2 | L14: WP Table 14 | M14: 1.061% (levies; 2024 volume, 2025 GDP) | N14: estimate | O14: =IF(N14="","",IFERROR(INDEX(DQ_Scale!$B$5:$B$14,MATCH(N14,DQ_Scale!$A$5:$A$14,0)),"")) -> 2 | P14: C-11 | Q14: OECD 1.5-2.5%
A15: Revenue | B15: R5 | C15: Tobacco excise implied (upper bound) | D15: % of GDP | E15: 0.09-0.17% (5-10 cigarettes a day) | F15: estimate | G15: =IF(F15="","",IFERROR(INDEX(DQ_Scale!$B$5:$B$14,MATCH(F15,DQ_Scale!$A$5:$A$14,0)),"")) -> 2 | H15: PR-45 | I15: ~0.14% | J15: estimate | K15: =IF(J15="","",IFERROR(INDEX(DQ_Scale!$B$5:$B$14,MATCH(J15,DQ_Scale!$A$5:$A$14,0)),"")) -> 2 | L15: WP Table 14 | M15: 0.16% (8 a day) | N15: estimate | O15: =IF(N15="","",IFERROR(INDEX(DQ_Scale!$B$5:$B$14,MATCH(N15,DQ_Scale!$A$5:$A$14,0)),"")) -> 2 | P15: C-18 | Q15: South Africa ~0.4%; EU ~0.6%
A16: Revenue | B16: R6 | C16: Tobacco excise collected | D16: % of GDP / USD | E16: n.a. (within non-fuel 0.10-0.16%) | F16: data_gap | G16: =IF(F16="","",IFERROR(INDEX(DQ_Scale!$B$5:$B$14,MATCH(F16,DQ_Scale!$A$5:$A$14,0)),"")) -> 1 | I16: n.a. | J16: data_gap | K16: =IF(J16="","",IFERROR(INDEX(DQ_Scale!$B$5:$B$14,MATCH(J16,DQ_Scale!$A$5:$A$14,0)),"")) -> 1 | M16: US$0 on imported tobacco (FY2024, Q1 FY2025) | N16: verified | O16: =IF(N16="","",IFERROR(INDEX(DQ_Scale!$B$5:$B$14,MATCH(N16,DQ_Scale!$A$5:$A$14,0)),"")) -> 5 | P16: PR-28, PR-45
A17: Revenue | B17: R7 | C17: Alcohol excise implied | D17: % of GDP | E17: ~0.05% (indicative) | F17: assumption | G17: =IF(F17="","",IFERROR(INDEX(DQ_Scale!$B$5:$B$14,MATCH(F17,DQ_Scale!$A$5:$A$14,0)),"")) -> 1 | H17: WP Table 14 | I17: ~0.2% (indicative) | J17: assumption | K17: =IF(J17="","",IFERROR(INDEX(DQ_Scale!$B$5:$B$14,MATCH(J17,DQ_Scale!$A$5:$A$14,0)),"")) -> 1 | L17: WP Table 14 | M17: 0.347% at current rates (WHO recorded use, carried forward) | N17: estimate | O17: =IF(N17="","",IFERROR(INDEX(DQ_Scale!$B$5:$B$14,MATCH(N17,DQ_Scale!$A$5:$A$14,0)),"")) -> 2 | P17: C-24, PR-43 | Q17: OECD 0.4-0.6%
A18: Revenue | B18: R8 | C18: SSB excise | D18: % of GDP | E18: Not estimated (no volumes) | F18: data_gap | G18: =IF(F18="","",IFERROR(INDEX(DQ_Scale!$B$5:$B$14,MATCH(F18,DQ_Scale!$A$5:$A$14,0)),"")) -> 1 | I18: ~0.05% (indicative) | J18: assumption | K18: =IF(J18="","",IFERROR(INDEX(DQ_Scale!$B$5:$B$14,MATCH(J18,DQ_Scale!$A$5:$A$14,0)),"")) -> 1 | L18: WP Table 14 | M18: Imports collected FY2024: US$6.80m (0.142% of GDP); implied not estimated | N18: verified | O18: =IF(N18="","",IFERROR(INDEX(DQ_Scale!$B$5:$B$14,MATCH(N18,DQ_Scale!$A$5:$A$14,0)),"")) -> 5 | P18: PR-28
A19: Revenue | B19: R9 | C19: All non-fuel excise | D19: % of GDP | E19: 0.10-0.16% collected (2024-25) | F19: corrected | G19: =IF(F19="","",IFERROR(INDEX(DQ_Scale!$B$5:$B$14,MATCH(F19,DQ_Scale!$A$5:$A$14,0)),"")) -> 4 | H19: PR-48 | I19: ~0.4% implied (health lines) | J19: assumption | K19: =IF(J19="","",IFERROR(INDEX(DQ_Scale!$B$5:$B$14,MATCH(J19,DQ_Scale!$A$5:$A$14,0)),"")) -> 1 | L19: WP Table 7 | M19: 0.373% collected (all excise is non-fuel) | N19: verified | O19: =IF(N19="","",IFERROR(INDEX(DQ_Scale!$B$5:$B$14,MATCH(N19,DQ_Scale!$A$5:$A$14,0)),"")) -> 5 | P19: PR-28
A20: Rate intensity | B20: I1 | C20: Petrol: USD per liter | D20: USD/l | E20: 0.23 | F20: partly_verified | G20: =IF(F20="","",IFERROR(INDEX(DQ_Scale!$B$5:$B$14,MATCH(F20,DQ_Scale!$A$5:$A$14,0)),"")) -> 3 | H20: PR-12, PR-40 | I20: 0.41 | J20: not_reviewed | K20: =IF(J20="","",IFERROR(INDEX(DQ_Scale!$B$5:$B$14,MATCH(J20,DQ_Scale!$A$5:$A$14,0)),"")) -> 2 | M20: 0.0951 (levies only) | N20: partly_verified | O20: =IF(N20="","",IFERROR(INDEX(DQ_Scale!$B$5:$B$14,MATCH(N20,DQ_Scale!$A$5:$A$14,0)),"")) -> 3 | P20: C-12 | Q20: OECD 0.55; South Africa 0.20-0.25
A21: Rate intensity | B21: I2 | C21: Petrol: excise as % of pump price | D21: % | E21: 16% | F21: partly_verified | G21: =IF(F21="","",IFERROR(INDEX(DQ_Scale!$B$5:$B$14,MATCH(F21,DQ_Scale!$A$5:$A$14,0)),"")) -> 3 | H21: PR-42 | I21: 30% | J21: not_reviewed | K21: =IF(J21="","",IFERROR(INDEX(DQ_Scale!$B$5:$B$14,MATCH(J21,DQ_Scale!$A$5:$A$14,0)),"")) -> 2 | M21: 7.29% (June 2026 ceiling) | N21: partly_verified | O21: =IF(N21="","",IFERROR(INDEX(DQ_Scale!$B$5:$B$14,MATCH(N21,DQ_Scale!$A$5:$A$14,0)),"")) -> 3 | P21: C-13 | Q21: OECD 30-50%
A22: Rate intensity | B22: I3 | C22: Diesel: USD per liter / % of pump price | D22: USD/l; % | E22: 0.23 / 18% (pre-increase price) | F22: not_verified | G22: =IF(F22="","",IFERROR(INDEX(DQ_Scale!$B$5:$B$14,MATCH(F22,DQ_Scale!$A$5:$A$14,0)),"")) -> 2 | H22: PR-43 | I22: 0.33 / 24% | J22: not_reviewed | K22: =IF(J22="","",IFERROR(INDEX(DQ_Scale!$B$5:$B$14,MATCH(J22,DQ_Scale!$A$5:$A$14,0)),"")) -> 2 | M22: 0.0951 / 5.76% | N22: partly_verified | O22: =IF(N22="","",IFERROR(INDEX(DQ_Scale!$B$5:$B$14,MATCH(N22,DQ_Scale!$A$5:$A$14,0)),"")) -> 3 | P22: C-12, C-14
A23: Rate intensity | B23: I4 | C23: Cigarettes: USD per pack of 20 | D23: USD/pack | E23: 0.14 | F23: partly_verified | G23: =IF(F23="","",IFERROR(INDEX(DQ_Scale!$B$5:$B$14,MATCH(F23,DQ_Scale!$A$5:$A$14,0)),"")) -> 3 | H23: PR-20 | I23: 0.35-1.07 (4 tiers) | J23: not_reviewed | K23: =IF(J23="","",IFERROR(INDEX(DQ_Scale!$B$5:$B$14,MATCH(J23,DQ_Scale!$A$5:$A$14,0)),"")) -> 2 | M23: 0.50 | N23: verified_open_point | O23: =IF(N23="","",IFERROR(INDEX(DQ_Scale!$B$5:$B$14,MATCH(N23,DQ_Scale!$A$5:$A$14,0)),"")) -> 4 | P23: PR-09, PR-01
A24: Rate intensity | B24: I5 | C24: Cigarettes: excise as % of retail price | D24: % | E24: ~14% | F24: estimate | G24: =IF(F24="","",IFERROR(INDEX(DQ_Scale!$B$5:$B$14,MATCH(F24,DQ_Scale!$A$5:$A$14,0)),"")) -> 2 | H24: WP Table 14 | I24: 30-50% | J24: estimate | K24: =IF(J24="","",IFERROR(INDEX(DQ_Scale!$B$5:$B$14,MATCH(J24,DQ_Scale!$A$5:$A$14,0)),"")) -> 2 | L24: WP Table 14 | M24: 27.2% (at 2022 price) | N24: estimate | O24: =IF(N24="","",IFERROR(INDEX(DQ_Scale!$B$5:$B$14,MATCH(N24,DQ_Scale!$A$5:$A$14,0)),"")) -> 2 | P24: C-16a | Q24: WHO excise >=70%; total tax >=75%
A25: Rate intensity | B25: I6 | C25: Beer: USD per liter of pure alcohol | D25: USD/LPA | E25: 2.3-9.1 (by regime) | F25: verified | G25: =IF(F25="","",IFERROR(INDEX(DQ_Scale!$B$5:$B$14,MATCH(F25,DQ_Scale!$A$5:$A$14,0)),"")) -> 5 | H25: PR-22, PR-26 | I25: 4.8-10.9 (by local content) | J25: not_reviewed | K25: =IF(J25="","",IFERROR(INDEX(DQ_Scale!$B$5:$B$14,MATCH(J25,DQ_Scale!$A$5:$A$14,0)),"")) -> 2 | M25: 20.00 | N25: verified_open_point | O25: =IF(N25="","",IFERROR(INDEX(DQ_Scale!$B$5:$B$14,MATCH(N25,DQ_Scale!$A$5:$A$14,0)),"")) -> 4 | P25: C-19 | Q25: OECD 15-40
A26: Rate intensity | B26: I7 | C26: Spirits: USD per liter of pure alcohol | D26: USD/LPA | E26: 7.5 (FA2023; current not legible) | F26: last_legible | G26: =IF(F26="","",IFERROR(INDEX(DQ_Scale!$B$5:$B$14,MATCH(F26,DQ_Scale!$A$5:$A$14,0)),"")) -> 1 | H26: PR-27 | I26: 1.0 / 1.7 (specific floor) | J26: not_reviewed | K26: =IF(J26="","",IFERROR(INDEX(DQ_Scale!$B$5:$B$14,MATCH(J26,DQ_Scale!$A$5:$A$14,0)),"")) -> 2 | M26: 7.50 | N26: verified_open_point | O26: =IF(N26="","",IFERROR(INDEX(DQ_Scale!$B$5:$B$14,MATCH(N26,DQ_Scale!$A$5:$A$14,0)),"")) -> 4 | P26: C-19 | Q26: OECD 25-50
A27: Rate intensity | B27: I8 | C27: Soft drinks: USD per liter | D27: USD/l | E27: 0.10-0.50 by sugar (FA2023; current not legible) | F27: last_legible | G27: =IF(F27="","",IFERROR(INDEX(DQ_Scale!$B$5:$B$14,MATCH(F27,DQ_Scale!$A$5:$A$14,0)),"")) -> 1 | H27: PR-31 | I27: 0.07 | J27: not_reviewed | K27: =IF(J27="","",IFERROR(INDEX(DQ_Scale!$B$5:$B$14,MATCH(J27,DQ_Scale!$A$5:$A$14,0)),"")) -> 2 | M27: 0.45 flat | N27: verified_open_point | O27: =IF(N27="","",IFERROR(INDEX(DQ_Scale!$B$5:$B$14,MATCH(N27,DQ_Scale!$A$5:$A$14,0)),"")) -> 4 | P27: PR-11 | Q27: UK 0.23-0.30 (sugar-graduated); Mexico ~0.05 (flat)
A28: Rate intensity | B28: I9 | C28: Soft drinks: excise as % of price | D28: % | E28: n/a | F28: data_gap | G28: =IF(F28="","",IFERROR(INDEX(DQ_Scale!$B$5:$B$14,MATCH(F28,DQ_Scale!$A$5:$A$14,0)),"")) -> 1 | I28: ~6-10% | J28: estimate | K28: =IF(J28="","",IFERROR(INDEX(DQ_Scale!$B$5:$B$14,MATCH(J28,DQ_Scale!$A$5:$A$14,0)),"")) -> 2 | L28: WP Table 14 | M28: 43.7% at 2024 price, before pass-through (pre-reform 1.95%) | N28: estimate | O28: =IF(N28="","",IFERROR(INDEX(DQ_Scale!$B$5:$B$14,MATCH(N28,DQ_Scale!$A$5:$A$14,0)),"")) -> 2 | P28: C-39, PR-34
A29: Structure and base | B29: B1 | C29: Fuel use (liters per USD 1,000 of GDP) | D29: l per USD 1,000 | E29: ~69 (petrol + diesel) | F29: estimate | G29: =IF(F29="","",IFERROR(INDEX(DQ_Scale!$B$5:$B$14,MATCH(F29,DQ_Scale!$A$5:$A$14,0)),"")) -> 2 | H29: WP Table 7 | I29: ~35 (petrol + diesel) | J29: estimate | K29: =IF(J29="","",IFERROR(INDEX(DQ_Scale!$B$5:$B$14,MATCH(J29,DQ_Scale!$A$5:$A$14,0)),"")) -> 2 | L29: WP Table 7 | M29: ~122 (all petroleum, 2024) | N29: estimate | O29: =IF(N29="","",IFERROR(INDEX(DQ_Scale!$B$5:$B$14,MATCH(N29,DQ_Scale!$A$5:$A$14,0)),"")) -> 2 | P29: P-13 | R29: LBR includes all petroleum products; not comparable
A30: Structure and base | B30: B2 | C30: Standard lines covered (of 30) | D30: count | E30: =Std_Schedule!F41 -> 25 | F30: partly_verified | G30: =IF(F30="","",IFERROR(INDEX(DQ_Scale!$B$5:$B$14,MATCH(F30,DQ_Scale!$A$5:$A$14,0)),"")) -> 3 | H30: Std_Schedule | I30: =Std_Schedule!L41 -> 26 | J30: not_reviewed | K30: =IF(J30="","",IFERROR(INDEX(DQ_Scale!$B$5:$B$14,MATCH(J30,DQ_Scale!$A$5:$A$14,0)),"")) -> 2 | L30: Std_Schedule | M30: =Std_Schedule!R41 -> 21 | N30: verified_open_point | O30: =IF(N30="","",IFERROR(INDEX(DQ_Scale!$B$5:$B$14,MATCH(N30,DQ_Scale!$A$5:$A$14,0)),"")) -> 4 | P30: Std_Schedule | R30: Formula: covered (1 + 2) from Std_Schedule
A31: Structure and base | B31: B3 | C31: Specific rates indexed to inflation | D31: yes/no | E31: None | F31: partly_verified | G31: =IF(F31="","",IFERROR(INDEX(DQ_Scale!$B$5:$B$14,MATCH(F31,DQ_Scale!$A$5:$A$14,0)),"")) -> 3 | H31: WP Table 7 | I31: None | J31: not_reviewed | K31: =IF(J31="","",IFERROR(INDEX(DQ_Scale!$B$5:$B$14,MATCH(J31,DQ_Scale!$A$5:$A$14,0)),"")) -> 2 | L31: WP Table 7 | M31: Legislated from 1 Jan 2027 (s.1108(e)); first rates due 1 Dec 2026 | N31: verified | O31: =IF(N31="","",IFERROR(INDEX(DQ_Scale!$B$5:$B$14,MATCH(N31,DQ_Scale!$A$5:$A$14,0)),"")) -> 5 | P31: PR-04
A32: Structure and base | B32: B4 | C32: Differentiation by origin | D32: text | E32: Beer and wine 50-140% higher if imported; juice origin-neutral | F32: verified | G32: =IF(F32="","",IFERROR(INDEX(DQ_Scale!$B$5:$B$14,MATCH(F32,DQ_Scale!$A$5:$A$14,0)),"")) -> 5 | H32: PR-22, PR-24, PR-30 | I32: Cigarettes ~2x if imported; beer, spirits, wine by local raw material | J32: not_reviewed | K32: =IF(J32="","",IFERROR(INDEX(DQ_Scale!$B$5:$B$14,MATCH(J32,DQ_Scale!$A$5:$A$14,0)),"")) -> 2 | M32: Removed April 2026 except water (imported US$0.15/l; local nil) | N32: verified_open_point | O32: =IF(N32="","",IFERROR(INDEX(DQ_Scale!$B$5:$B$14,MATCH(N32,DQ_Scale!$A$5:$A$14,0)),"")) -> 4 | P32: PR-01, PR-11
A33: Structure and base | B33: B5 | C33: Excise-like levies outside excise law | D33: text | E33: Vehicle circulation levy; cellular surcharge (voice, data, mobile money) | F33: partly_verified | G33: =IF(F33="","",IFERROR(INDEX(DQ_Scale!$B$5:$B$14,MATCH(F33,DQ_Scale!$A$5:$A$14,0)),"")) -> 3 | H33: PR-15, PR-36, PR-37 | I33: None: telecoms and financial lines inside the Excise Duty Act | J33: not_reviewed | K33: =IF(J33="","",IFERROR(INDEX(DQ_Scale!$B$5:$B$14,MATCH(J33,DQ_Scale!$A$5:$A$14,0)),"")) -> 2 | M33: Road Fund and LPRC fuel levies; vehicle registration; telecom 5% surtax | N33: partly_verified | O33: =IF(N33="","",IFERROR(INDEX(DQ_Scale!$B$5:$B$14,MATCH(N33,DQ_Scale!$A$5:$A$14,0)),"")) -> 3 | P33: PR-23, PR-24, PR-06
A34: Key questions | B34: Q1 | C34: Coverage: what is taxed; which priority categories are absent? | D34: text | E34: 25 of 30 (21 in Excise Act, 4 levies). Absent: aviation fuel, first registration, traditional beer, sugar, luxury | F34: partly_verified | G34: =IF(F34="","",IFERROR(INDEX(DQ_Scale!$B$5:$B$14,MATCH(F34,DQ_Scale!$A$5:$A$14,0)),"")) -> 3 | H34: WP s.9.1 | I34: 26 of 30, all in the Excise Duty Act. Absent: vehicle circulation, e-cigarettes, gambling, other industrial inputs | J34: not_reviewed | K34: =IF(J34="","",IFERROR(INDEX(DQ_Scale!$B$5:$B$14,MATCH(J34,DQ_Scale!$A$5:$A$14,0)),"")) -> 2 | L34: WP s.9.1 | M34: 21 of 30 (16 in excise law incl. 2 partial; 5 levies). Fuel, plastics, mobile money, cement, edible oils outside excise law; aviation fuel exempt | N34: verified_open_point | O34: =IF(N34="","",IFERROR(INDEX(DQ_Scale!$B$5:$B$14,MATCH(N34,DQ_Scale!$A$5:$A$14,0)),"")) -> 4 | P34: v0.3 Table 9.1
A35: Key questions | B35: Q2 | C35: Structure: specific, ad valorem or hybrid; how differentiated? | D35: text | E35: Mostly specific in NLe; ad valorem local-content beer bands and industrial lines; sugar-graduated SSB design (FA2023); ABV bands | F35: partly_verified | G35: =IF(F35="","",IFERROR(INDEX(DQ_Scale!$B$5:$B$14,MATCH(F35,DQ_Scale!$A$5:$A$14,0)),"")) -> 3 | H35: WP s.9.3 | I35: 'Higher-of' hybrids for alcohol and beverages; specific fuel and cigarettes (4 tiers); ad valorem other tobacco, telecoms, finance, luxury | J35: not_reviewed | K35: =IF(J35="","",IFERROR(INDEX(DQ_Scale!$B$5:$B$14,MATCH(J35,DQ_Scale!$A$5:$A$14,0)),"")) -> 2 | L35: WP s.9.3 | M35: Specific for all beverages and tobacco, one rate for local and imported (except water); ad valorem 5-50% for luxury, sugar, gaming, pipes; fuel via levies only | N35: verified_open_point | O35: =IF(N35="","",IFERROR(INDEX(DQ_Scale!$B$5:$B$14,MATCH(N35,DQ_Scale!$A$5:$A$14,0)),"")) -> 4 | P35: v0.3 s.10
A36: Key questions | B36: Q3 | C36: Intensity: USD per unit, share of price, share of GDP | D36: text | E36: Fuel 55-69% of Uganda per liter; cigarettes 13-39% of Uganda; mainstream beer near parity; SSBs at or above peers on paper | F36: partly_verified | G36: =IF(F36="","",IFERROR(INDEX(DQ_Scale!$B$5:$B$14,MATCH(F36,DQ_Scale!$A$5:$A$14,0)),"")) -> 3 | H36: WP s.8.1 | I36: Petrol USD 0.41/l (30%); cigarettes USD 0.35-1.07/pack (30-50%); malt beer USD 10.9/LPA | J36: not_reviewed | K36: =IF(J36="","",IFERROR(INDEX(DQ_Scale!$B$5:$B$14,MATCH(J36,DQ_Scale!$A$5:$A$14,0)),"")) -> 2 | L36: WP s.8.1 | M36: Fuel levies USD 0.0951/l (7.29%); cigarettes USD 0.50/pack (27.2%); beer USD 20/LPA; spirits USD 7.5/LPA; SSBs USD 0.45/l | N36: partly_verified | O36: =IF(N36="","",IFERROR(INDEX(DQ_Scale!$B$5:$B$14,MATCH(N36,DQ_Scale!$A$5:$A$14,0)),"")) -> 3 | P36: v0.3 s.8.1
A37: Key questions | B37: Q4 | C37: Benchmarking against peers and reference levels | D37: text | E37: Below OECD on fuel, tobacco, alcohol; fuel revenue near OECD floor on a large base; total excise about half the African average | F37: partly_verified | G37: =IF(F37="","",IFERROR(INDEX(DQ_Scale!$B$5:$B$14,MATCH(F37,DQ_Scale!$A$5:$A$14,0)),"")) -> 3 | H37: WP s.8.4 | I37: Below OECD on fuel, tobacco, alcohol; cigarettes 30-50% of price vs WHO 70% | J37: not_reviewed | K37: =IF(J37="","",IFERROR(INDEX(DQ_Scale!$B$5:$B$14,MATCH(J37,DQ_Scale!$A$5:$A$14,0)),"")) -> 2 | L37: WP s.8.4 | M37: Excise 15.5% of African average; fuel 17.3% of OECD per liter; cigarettes 38.9% of WHO benchmark; beer in OECD range; spirits far below; SSBs above UK top band | N37: partly_verified | O37: =IF(N37="","",IFERROR(INDEX(DQ_Scale!$B$5:$B$14,MATCH(N37,DQ_Scale!$A$5:$A$14,0)),"")) -> 3 | P37: v0.3 s.8.4
A38: Key questions | B38: Q5 | C38: Erosion: which specific rates lose real value? | D38: text | E38: No indexation. 2024 switch from US$ to Leone rates cut beer ~70% and wine 70-90% in USD; FA2026 catch-up (fuel +79-147%, cigarettes +50%) | F38: partly_verified | G38: =IF(F38="","",IFERROR(INDEX(DQ_Scale!$B$5:$B$14,MATCH(F38,DQ_Scale!$A$5:$A$14,0)),"")) -> 3 | H38: WP Table 8 #10 | I38: No indexation. Tobacco unchanged FY2017/18-FY2024/25 then up to +100%; kerosene unchanged since 2018 | J38: not_reviewed | K38: =IF(J38="","",IFERROR(INDEX(DQ_Scale!$B$5:$B$14,MATCH(J38,DQ_Scale!$A$5:$A$14,0)),"")) -> 2 | L38: WP Table 8 #10 | M38: Rates in US$ (no LRD erosion); indexation from 1 Jan 2027. Alcohol rates swung twice in 16 months (local spirits 2.00 -> 0.50 -> 3.00) | N38: verified | O38: =IF(N38="","",IFERROR(INDEX(DQ_Scale!$B$5:$B$14,MATCH(N38,DQ_Scale!$A$5:$A$14,0)),"")) -> 5 | P38: PR-04, Table 10.3
A39: Key questions | B39: Q6 | C39: Coherence: where do differentiation devices stack into inversions or arbitrage? | D39: text | E39: Two beer regimes (1.3-4x gap by classification); wine below beer per LPA; origin gaps; kerosene 40% of diesel; three currency notations | F39: corrected | G39: =IF(F39="","",IFERROR(INDEX(DQ_Scale!$B$5:$B$14,MATCH(F39,DQ_Scale!$A$5:$A$14,0)),"")) -> 4 | H39: WP Table 8 | I39: Origin tiers on cigarettes (imported ~2x); local-content tiers on beer; kerosene 16% of diesel | J39: not_reviewed | K39: =IF(J39="","",IFERROR(INDEX(DQ_Scale!$B$5:$B$14,MATCH(J39,DQ_Scale!$A$5:$A$14,0)),"")) -> 2 | L39: WP Table 8 | M39: Spirits 0.375x beer per LPA; water excluded by s.1106(a) yet taxed; SSB flat with no sugar link; 'Current/Proposed' schedule; telecom 18% vs 15%; fuel outside law | N39: verified_open_point | O39: =IF(N39="","",IFERROR(INDEX(DQ_Scale!$B$5:$B$14,MATCH(N39,DQ_Scale!$A$5:$A$14,0)),"")) -> 4 | P39: v0.3 Table 8.3
A40: Key questions | B40: Q7 | C40: Price tracking: tax-inclusive prices vs CPI and incomes | D40: text | E40: Not answered: no retail price series | F40: data_gap | G40: =IF(F40="","",IFERROR(INDEX(DQ_Scale!$B$5:$B$14,MATCH(F40,DQ_Scale!$A$5:$A$14,0)),"")) -> 1 | I40: Not answered | J40: data_gap | K40: =IF(J40="","",IFERROR(INDEX(DQ_Scale!$B$5:$B$14,MATCH(J40,DQ_Scale!$A$5:$A$14,0)),"")) -> 1 | M40: Not answered: no retail price series | N40: data_gap | O40: =IF(N40="","",IFERROR(INDEX(DQ_Scale!$B$5:$B$14,MATCH(N40,DQ_Scale!$A$5:$A$14,0)),"")) -> 1
A41: Open items | B41: O1 | C41: Main open items | D41: text | E41: Publish legible FA2024 s.4(d)-(i) tables; confirm spirits and SSB rates; line-level NRA collections; configure import excise in ASYCUDA | G41: =IF(F41="","",IFERROR(INDEX(DQ_Scale!$B$5:$B$14,MATCH(F41,DQ_Scale!$A$5:$A$14,0)),"")) | H41: WP s.8.5 | I41: Peer review all lines (stage A5); obtain collections; track the 2026 Bill | K41: =IF(J41="","",IFERROR(INDEX(DQ_Scale!$B$5:$B$14,MATCH(J41,DQ_Scale!$A$5:$A$14,0)),"")) | L41: WP note v0.8 | M41: Confirm 'Proposed' rates in force; telecom rate; indexation formula and first rates; where tobacco excise is booked; split the Road Fund line | O41: =IF(N41="","",IFERROR(INDEX(DQ_Scale!$B$5:$B$14,MATCH(N41,DQ_Scale!$A$5:$A$14,0)),"")) | P41: v0.3 Annex B

Sheet Std_Schedule
A1: Standardized cross-country excise schedule (standard schedule v1.0): human-readable
A2: Coverage: 1 = in excise law; 2 = levy outside excise law; 0 = not covered. DQ = lowest DQ among the country's national lines on that row (formula from Std_Schedule_Code).
F4: Sierra Leone (WP v0.8; cut-off 27 Apr 2026) | L4: Uganda (WP v0.8; cut-off 27 Apr 2026; not peer reviewed) | R4: Liberia (v0.3; cut-off 29 Sep 2026)
A5: Part | B5: Typology | C5: Code | D5: Standard line | E5: Standard unit | F5: SLE: Cov. | G5: SLE: Statutory rate and structure | H5: SLE: USD per std unit | I5: SLE: % of price | J5: SLE: DQ | K5: SLE: Ref. / note | L5: UGA: Cov. | M5: UGA: Statutory rate and structure | N5: UGA: USD per std unit | O5: UGA: % of price | P5: UGA: DQ | Q5: UGA: Ref. / note | R5: LBR: Cov. | S5: LBR: Statutory rate and structure | T5: LBR: USD per std unit | U5: LBR: % of price | V5: LBR: DQ | W5: LBR: Ref. / note | X5: Cross-country note
A6: 1 Fuel | B6: energy_environment | C6: E1 | D6: Petrol | E6: per liter | F6: 1 | G6: NLe 5.00/l; specific | H6: 0.23 | I6: 16% | J6: =IF(COUNTIFS(Std_Schedule_Code!$B$5:$B$191,"SLE",Std_Schedule_Code!$G$5:$G$191,$C6)=0,"",_xlfn.MINIFS(Std_Schedule_Code!$AO$5:$AO$191,Std_Schedule_Code!$B$5:$B$191,"SLE",Std_Schedule_Code!$G$5:$G$191,$C6)) -> 3 | K6: PR-12 | L6: 1 | M6: UGX 1,550/l; specific | N6: 0.41 | O6: 30% | P6: =IF(COUNTIFS(Std_Schedule_Code!$B$5:$B$191,"UGA",Std_Schedule_Code!$G$5:$G$191,$C6)=0,"",_xlfn.MINIFS(Std_Schedule_Code!$AO$5:$AO$191,Std_Schedule_Code!$B$5:$B$191,"UGA",Std_Schedule_Code!$G$5:$G$191,$C6)) -> 2 | R6: 2 | S6: US$0.25/gal + US$0.11/gal (Levy) | T6: 0.0951 (to 0.1083) | U6: 7.29% of June 2026 ceiling | V6: =IF(COUNTIFS(Std_Schedule_Code!$B$5:$B$191,"LBR",Std_Schedule_Code!$G$5:$G$191,$C6)=0,"",_xlfn.MINIFS(Std_Schedule_Code!$AO$5:$AO$191,Std_Schedule_Code!$B$5:$B$191,"LBR",Std_Schedule_Code!$G$5:$G$191,$C6)) -> 3 | W6: PR-23, PR-24, PR-25 | X6: Liberia: fuel outside excise law; only earmarked levies.
A7: 1 Fuel | B7: energy_environment | C7: E2 | D7: Diesel, road | E7: per liter | F7: 1 | G7: NLe 5.00/l; specific; harmonized with petrol in FA2026 | H7: 0.23 | I7: 18% (pre-increase price) | J7: =IF(COUNTIFS(Std_Schedule_Code!$B$5:$B$191,"SLE",Std_Schedule_Code!$G$5:$G$191,$C7)=0,"",_xlfn.MINIFS(Std_Schedule_Code!$AO$5:$AO$191,Std_Schedule_Code!$B$5:$B$191,"SLE",Std_Schedule_Code!$G$5:$G$191,$C7)) -> 3 | K7: PR-12 | L7: 1 | M7: UGX 1,230/l; specific; nil for power generation | N7: 0.33 | O7: 24% | P7: =IF(COUNTIFS(Std_Schedule_Code!$B$5:$B$191,"UGA",Std_Schedule_Code!$G$5:$G$191,$C7)=0,"",_xlfn.MINIFS(Std_Schedule_Code!$AO$5:$AO$191,Std_Schedule_Code!$B$5:$B$191,"UGA",Std_Schedule_Code!$G$5:$G$191,$C7)) -> 2 | Q7: Diesel 21% below petrol | R7: 2 | S7: US$0.25/gal + US$0.11/gal (Levy) | T7: 0.0951 (to 0.1083) | U7: 5.76% of June 2026 ceiling | V7: =IF(COUNTIFS(Std_Schedule_Code!$B$5:$B$191,"LBR",Std_Schedule_Code!$G$5:$G$191,$C7)=0,"",_xlfn.MINIFS(Std_Schedule_Code!$AO$5:$AO$191,Std_Schedule_Code!$B$5:$B$191,"LBR",Std_Schedule_Code!$G$5:$G$191,$C7)) -> 3 | W7: PR-23, PR-24, PR-25
A8: 1 Fuel | B8: energy_environment | C8: E3 | D8: Kerosene | E8: per liter | F8: 1 | G8: NLe 2.00/l; specific | H8: 0.09 | I8: 8% | J8: =IF(COUNTIFS(Std_Schedule_Code!$B$5:$B$191,"SLE",Std_Schedule_Code!$G$5:$G$191,$C8)=0,"",_xlfn.MINIFS(Std_Schedule_Code!$AO$5:$AO$191,Std_Schedule_Code!$B$5:$B$191,"SLE",Std_Schedule_Code!$G$5:$G$191,$C8)) -> 2 | K8: PR-13 | L8: 1 | M8: UGX 200/l; specific | N8: 0.05 | O8: <5% | P8: =IF(COUNTIFS(Std_Schedule_Code!$B$5:$B$191,"UGA",Std_Schedule_Code!$G$5:$G$191,$C8)=0,"",_xlfn.MINIFS(Std_Schedule_Code!$AO$5:$AO$191,Std_Schedule_Code!$B$5:$B$191,"UGA",Std_Schedule_Code!$G$5:$G$191,$C8)) -> 2 | R8: 0 | S8: Not identified (confirm): Product scope of fuel levies not verified | T8: - | U8: - | V8: =IF(COUNTIFS(Std_Schedule_Code!$B$5:$B$191,"LBR",Std_Schedule_Code!$G$5:$G$191,$C8)=0,"",_xlfn.MINIFS(Std_Schedule_Code!$AO$5:$AO$191,Std_Schedule_Code!$B$5:$B$191,"LBR",Std_Schedule_Code!$G$5:$G$191,$C8)) -> 2 | W8: PR-24
A9: 1 Fuel | B9: energy_environment | C9: E4 | D9: Aviation fuel | E9: per liter | F9: 0 | G9: Not identified | H9: - | I9: - | J9: =IF(COUNTIFS(Std_Schedule_Code!$B$5:$B$191,"SLE",Std_Schedule_Code!$G$5:$G$191,$C9)=0,"",_xlfn.MINIFS(Std_Schedule_Code!$AO$5:$AO$191,Std_Schedule_Code!$B$5:$B$191,"SLE",Std_Schedule_Code!$G$5:$G$191,$C9)) -> 2 | L9: 1 | M9: UGX 630/l; nil for registered airlines | N9: 0.17 | O9: n/a | P9: =IF(COUNTIFS(Std_Schedule_Code!$B$5:$B$191,"UGA",Std_Schedule_Code!$G$5:$G$191,$C9)=0,"",_xlfn.MINIFS(Std_Schedule_Code!$AO$5:$AO$191,Std_Schedule_Code!$B$5:$B$191,"UGA",Std_Schedule_Code!$G$5:$G$191,$C9)) -> 2 | R9: 0 | S9: Not excisable: s.1107(a): aviation fuel exempt from excise | T9: - | U9: - | V9: =IF(COUNTIFS(Std_Schedule_Code!$B$5:$B$191,"LBR",Std_Schedule_Code!$G$5:$G$191,$C9)=0,"",_xlfn.MINIFS(Std_Schedule_Code!$AO$5:$AO$191,Std_Schedule_Code!$B$5:$B$191,"LBR",Std_Schedule_Code!$G$5:$G$191,$C9)) -> 4 | W9: PR-15
A10: 1 Fuel | B10: energy_environment | C10: E5 | D10: Heavy fuel oil / other gas oils | E10: per liter | F10: 1 | G10: NLe 7.40/l (fuel oil); specific | H10: 0.34 | I10: n/a | J10: =IF(COUNTIFS(Std_Schedule_Code!$B$5:$B$191,"SLE",Std_Schedule_Code!$G$5:$G$191,$C10)=0,"",_xlfn.MINIFS(Std_Schedule_Code!$AO$5:$AO$191,Std_Schedule_Code!$B$5:$B$191,"SLE",Std_Schedule_Code!$G$5:$G$191,$C10)) -> 2 | K10: PR-13 | L10: 1 | M10: UGX 630/l (other gas oils); specific | N10: 0.17 | O10: n/a | P10: =IF(COUNTIFS(Std_Schedule_Code!$B$5:$B$191,"UGA",Std_Schedule_Code!$G$5:$G$191,$C10)=0,"",_xlfn.MINIFS(Std_Schedule_Code!$AO$5:$AO$191,Std_Schedule_Code!$B$5:$B$191,"UGA",Std_Schedule_Code!$G$5:$G$191,$C10)) -> 2 | Q10: Definitions differ | R10: 0 | S10: Not identified (confirm): As E3 | T10: - | U10: - | V10: =IF(COUNTIFS(Std_Schedule_Code!$B$5:$B$191,"LBR",Std_Schedule_Code!$G$5:$G$191,$C10)=0,"",_xlfn.MINIFS(Std_Schedule_Code!$AO$5:$AO$191,Std_Schedule_Code!$B$5:$B$191,"LBR",Std_Schedule_Code!$G$5:$G$191,$C10)) -> 2 | W10: PR-24
A11: 1 Fuel | B11: energy_environment | C11: E6 | D11: Lubricants | E11: per liter | F11: 1 | G11: NLe 4.00/l; specific | H11: 0.18 | I11: n/a | J11: =IF(COUNTIFS(Std_Schedule_Code!$B$5:$B$191,"SLE",Std_Schedule_Code!$G$5:$G$191,$C11)=0,"",_xlfn.MINIFS(Std_Schedule_Code!$AO$5:$AO$191,Std_Schedule_Code!$B$5:$B$191,"SLE",Std_Schedule_Code!$G$5:$G$191,$C11)) -> 2 | K11: PR-13 | L11: 1 | M11: 15% ad valorem (motor vehicle, not aircraft) | N11: - | O11: 15% of value | P11: =IF(COUNTIFS(Std_Schedule_Code!$B$5:$B$191,"UGA",Std_Schedule_Code!$G$5:$G$191,$C11)=0,"",_xlfn.MINIFS(Std_Schedule_Code!$AO$5:$AO$191,Std_Schedule_Code!$B$5:$B$191,"UGA",Std_Schedule_Code!$G$5:$G$191,$C11)) -> 2 | R11: 0 | S11: Not excisable: Not in s.1106 | T11: - | U11: - | V11: =IF(COUNTIFS(Std_Schedule_Code!$B$5:$B$191,"LBR",Std_Schedule_Code!$G$5:$G$191,$C11)=0,"",_xlfn.MINIFS(Std_Schedule_Code!$AO$5:$AO$191,Std_Schedule_Code!$B$5:$B$191,"LBR",Std_Schedule_Code!$G$5:$G$191,$C11)) -> 4 | W11: PR-15
A12: 4 Other | B12: energy_environment | C12: E7 | D12: Plastic bags and packaging | E12: per kg | F12: 1 | G12: Le 16/kg: bags; bottles filled with beverages other than water | H12: 0.73 | I12: n/a | J12: =IF(COUNTIFS(Std_Schedule_Code!$B$5:$B$191,"SLE",Std_Schedule_Code!$G$5:$G$191,$C12)=0,"",_xlfn.MINIFS(Std_Schedule_Code!$AO$5:$AO$191,Std_Schedule_Code!$B$5:$B$191,"SLE",Std_Schedule_Code!$G$5:$G$191,$C12)) -> 5 | K12: PR-14 | L12: 1 | M12: UGX 10,000/kg (bags); granules 2.5% or USD 70/t | N12: 2.67 | O12: n/a | P12: =IF(COUNTIFS(Std_Schedule_Code!$B$5:$B$191,"UGA",Std_Schedule_Code!$G$5:$G$191,$C12)=0,"",_xlfn.MINIFS(Std_Schedule_Code!$AO$5:$AO$191,Std_Schedule_Code!$B$5:$B$191,"UGA",Std_Schedule_Code!$G$5:$G$191,$C12)) -> 2 | R12: 0 | S12: Not excisable: Not in s.1106 | T12: - | U12: - | V12: =IF(COUNTIFS(Std_Schedule_Code!$B$5:$B$191,"LBR",Std_Schedule_Code!$G$5:$G$191,$C12)=0,"",_xlfn.MINIFS(Std_Schedule_Code!$AO$5:$AO$191,Std_Schedule_Code!$B$5:$B$191,"LBR",Std_Schedule_Code!$G$5:$G$191,$C12)) -> 4 | W12: PR-15
A13: 2 Vehicles | B13: energy_environment | C13: E8 | D13: Vehicles: annual circulation | E13: per vehicle-year | F13: 2 | G13: NLe 500 (cars, trucks, buses); NLe 200 (motorbikes). Levy outside the Excise Act | H13: 23 / 9 | I13: n/a | J13: =IF(COUNTIFS(Std_Schedule_Code!$B$5:$B$191,"SLE",Std_Schedule_Code!$G$5:$G$191,$C13)=0,"",_xlfn.MINIFS(Std_Schedule_Code!$AO$5:$AO$191,Std_Schedule_Code!$B$5:$B$191,"SLE",Std_Schedule_Code!$G$5:$G$191,$C13)) -> 2 | K13: PR-15, PR-16 | L13: 0 | M13: Not in excise schedule | N13: - | O13: - | P13: =IF(COUNTIFS(Std_Schedule_Code!$B$5:$B$191,"UGA",Std_Schedule_Code!$G$5:$G$191,$C13)=0,"",_xlfn.MINIFS(Std_Schedule_Code!$AO$5:$AO$191,Std_Schedule_Code!$B$5:$B$191,"UGA",Std_Schedule_Code!$G$5:$G$191,$C13)) -> 2 | R13: 2 | S13: US$75 (compact car) to US$500 (heavy truck) base (Levy) | T13: 75-500 | U13: - | V13: =IF(COUNTIFS(Std_Schedule_Code!$B$5:$B$191,"LBR",Std_Schedule_Code!$G$5:$G$191,$C13)=0,"",_xlfn.MINIFS(Std_Schedule_Code!$AO$5:$AO$191,Std_Schedule_Code!$B$5:$B$191,"LBR",Std_Schedule_Code!$G$5:$G$191,$C13)) -> 2 | W13: PR-27, PR-38
A14: 2 Vehicles | B14: energy_environment | C14: E9 | D14: Vehicles: first registration / import | E14: per vehicle | F14: 0 | G14: Not in excise schedule | H14: - | I14: - | J14: =IF(COUNTIFS(Std_Schedule_Code!$B$5:$B$191,"SLE",Std_Schedule_Code!$G$5:$G$191,$C14)=0,"",_xlfn.MINIFS(Std_Schedule_Code!$AO$5:$AO$191,Std_Schedule_Code!$B$5:$B$191,"SLE",Std_Schedule_Code!$G$5:$G$191,$C14)) -> 2 | L14: 1 | M14: UGX 200,000 (motorcycles); specific | N14: 53 | O14: n/a | P14: =IF(COUNTIFS(Std_Schedule_Code!$B$5:$B$191,"UGA",Std_Schedule_Code!$G$5:$G$191,$C14)=0,"",_xlfn.MINIFS(Std_Schedule_Code!$AO$5:$AO$191,Std_Schedule_Code!$B$5:$B$191,"UGA",Std_Schedule_Code!$G$5:$G$191,$C14)) -> 2 | R14: 1 | S14: 10% (Partial: luxury only) | T14: >= 6,000 new; >= 3,000 used | U14: n/a (no price data) | V14: =IF(COUNTIFS(Std_Schedule_Code!$B$5:$B$191,"LBR",Std_Schedule_Code!$G$5:$G$191,$C14)=0,"",_xlfn.MINIFS(Std_Schedule_Code!$AO$5:$AO$191,Std_Schedule_Code!$B$5:$B$191,"LBR",Std_Schedule_Code!$G$5:$G$191,$C14)) -> 5 | W14: PR-14, PR-49
A15: 3 Health | B15: health | C15: T1 | D15: Cigarettes | E15: per pack of 20 | F15: 1 | G15: NLe 3/pack; single specific rate | H15: 0.14 | I15: ~14% | J15: =IF(COUNTIFS(Std_Schedule_Code!$B$5:$B$191,"SLE",Std_Schedule_Code!$G$5:$G$191,$C15)=0,"",_xlfn.MINIFS(Std_Schedule_Code!$AO$5:$AO$191,Std_Schedule_Code!$B$5:$B$191,"SLE",Std_Schedule_Code!$G$5:$G$191,$C15)) -> 3 | K15: PR-19, PR-20 | L15: 1 | M15: UGX 65,000-200,000 per 1,000 sticks; specific; 4 tiers by origin and pack type | N15: 0.35-1.07 | O15: 30-50% | P15: =IF(COUNTIFS(Std_Schedule_Code!$B$5:$B$191,"UGA",Std_Schedule_Code!$G$5:$G$191,$C15)=0,"",_xlfn.MINIFS(Std_Schedule_Code!$AO$5:$AO$191,Std_Schedule_Code!$B$5:$B$191,"UGA",Std_Schedule_Code!$G$5:$G$191,$C15)) -> 2 | R15: 1 | S15: $0.50 / pack of 20 sticks | T15: 0.50 | U15: 27.2% (at 2022 price) | V15: =IF(COUNTIFS(Std_Schedule_Code!$B$5:$B$191,"LBR",Std_Schedule_Code!$G$5:$G$191,$C15)=0,"",_xlfn.MINIFS(Std_Schedule_Code!$AO$5:$AO$191,Std_Schedule_Code!$B$5:$B$191,"LBR",Std_Schedule_Code!$G$5:$G$191,$C15)) -> 4 | W15: PR-09, PR-10 | X15: Uganda tiers by origin and pack; SLE and LBR single rate.
A16: 3 Health | B16: health | C16: T2 | D16: Cigars and other tobacco | E16: per pack / per kg | F16: 1 | G16: NLe 38/pack (cigars); NLe 98/kg (loose, homogenized); shisha NLe 98/kg + NLe 225/l | H16: 1.73/pack; 4.45/kg | I16: n/a | J16: =IF(COUNTIFS(Std_Schedule_Code!$B$5:$B$191,"SLE",Std_Schedule_Code!$G$5:$G$191,$C16)=0,"",_xlfn.MINIFS(Std_Schedule_Code!$AO$5:$AO$191,Std_Schedule_Code!$B$5:$B$191,"SLE",Std_Schedule_Code!$G$5:$G$191,$C16)) -> 2 | K16: PR-21 | L16: 1 | M16: 200% ad valorem | N16: - | O16: n/a | P16: =IF(COUNTIFS(Std_Schedule_Code!$B$5:$B$191,"UGA",Std_Schedule_Code!$G$5:$G$191,$C16)=0,"",_xlfn.MINIFS(Std_Schedule_Code!$AO$5:$AO$191,Std_Schedule_Code!$B$5:$B$191,"UGA",Std_Schedule_Code!$G$5:$G$191,$C16)) -> 2 | R16: 1 | S16: $0.50/pack; $0.25/stick; $25.00/Kg; 50% | T16: 0.50; 0.25/stick; 25.00/kg | U16: n/a (no price data) | V16: =IF(COUNTIFS(Std_Schedule_Code!$B$5:$B$191,"LBR",Std_Schedule_Code!$G$5:$G$191,$C16)=0,"",_xlfn.MINIFS(Std_Schedule_Code!$AO$5:$AO$191,Std_Schedule_Code!$B$5:$B$191,"LBR",Std_Schedule_Code!$G$5:$G$191,$C16)) -> 4 | W16: PR-09, PR-10
A17: 3 Health | B17: health | C17: T3 | D17: E-cigarettes and novel products | E17: per ml / per cartridge | F17: 1 | G17: NLe 0.75/ml (device); NLe 1.20/cartridge | H17: 0.03; 0.05 | I17: n/a | J17: =IF(COUNTIFS(Std_Schedule_Code!$B$5:$B$191,"SLE",Std_Schedule_Code!$G$5:$G$191,$C17)=0,"",_xlfn.MINIFS(Std_Schedule_Code!$AO$5:$AO$191,Std_Schedule_Code!$B$5:$B$191,"SLE",Std_Schedule_Code!$G$5:$G$191,$C17)) -> 2 | K17: PR-18, PR-21 | L17: 0 | M17: Not identified | N17: - | O17: - | P17: =IF(COUNTIFS(Std_Schedule_Code!$B$5:$B$191,"UGA",Std_Schedule_Code!$G$5:$G$191,$C17)=0,"",_xlfn.MINIFS(Std_Schedule_Code!$AO$5:$AO$191,Std_Schedule_Code!$B$5:$B$191,"UGA",Std_Schedule_Code!$G$5:$G$191,$C17)) -> 2 | R17: 1 | S17: $0.10 / mL; $15.00 / Kg | T17: 0.10/ml; 15.00/kg | U17: n/a (no price data) | V17: =IF(COUNTIFS(Std_Schedule_Code!$B$5:$B$191,"LBR",Std_Schedule_Code!$G$5:$G$191,$C17)=0,"",_xlfn.MINIFS(Std_Schedule_Code!$AO$5:$AO$191,Std_Schedule_Code!$B$5:$B$191,"LBR",Std_Schedule_Code!$G$5:$G$191,$C17)) -> 4 | W17: PR-09, PR-10
A18: 3 Health | B18: health | C18: A1 | D18: Beer, mainstream malt (5% ABV) | E18: per LPA | F18: 1 | G18: HS 2203: Le 10/l local; Le 15/l imported (also printed as Le 0.01 / 0.015 per cl); specific | H18: 9.1 / 13.6 | I18: 20% / 30% | J18: =IF(COUNTIFS(Std_Schedule_Code!$B$5:$B$191,"SLE",Std_Schedule_Code!$G$5:$G$191,$C18)=0,"",_xlfn.MINIFS(Std_Schedule_Code!$AO$5:$AO$191,Std_Schedule_Code!$B$5:$B$191,"SLE",Std_Schedule_Code!$G$5:$G$191,$C18)) -> 5 | K18: PR-22 | L18: 1 | M18: 60% or UGX 2,050/l; hybrid | N18: 10.9 | O18: ~29% | P18: =IF(COUNTIFS(Std_Schedule_Code!$B$5:$B$191,"UGA",Std_Schedule_Code!$G$5:$G$191,$C18)=0,"",_xlfn.MINIFS(Std_Schedule_Code!$AO$5:$AO$191,Std_Schedule_Code!$B$5:$B$191,"UGA",Std_Schedule_Code!$G$5:$G$191,$C18)) -> 2 | R18: 1 | S18: $1.00 / L | T18: 20.00 | U18: 36.7% (at 2024 price) | V18: =IF(COUNTIFS(Std_Schedule_Code!$B$5:$B$191,"LBR",Std_Schedule_Code!$G$5:$G$191,$C18)=0,"",_xlfn.MINIFS(Std_Schedule_Code!$AO$5:$AO$191,Std_Schedule_Code!$B$5:$B$191,"LBR",Std_Schedule_Code!$G$5:$G$191,$C18)) -> 4 | W18: PR-01, PR-02, PR-03
A19: 3 Health | B19: health | C19: A2 | D19: Beer, local-content concession (5% ABV) | E19: per LPA | F19: 1 | G19: Item 22.09 bands D1-D4: 5 / 8 / 12 / 15% ad valorem (<10% ABV) | H19: 2.3-6.8 | I19: 5-15% | J19: =IF(COUNTIFS(Std_Schedule_Code!$B$5:$B$191,"SLE",Std_Schedule_Code!$G$5:$G$191,$C19)=0,"",_xlfn.MINIFS(Std_Schedule_Code!$AO$5:$AO$191,Std_Schedule_Code!$B$5:$B$191,"SLE",Std_Schedule_Code!$G$5:$G$191,$C19)) -> 5 | K19: PR-25, PR-26 | L19: 1 | M19: >=75% local: 30% or UGX 900/l; Ugandan barley: 30% or UGX 950/l | N19: 4.8-5.1 | O19: ~13% | P19: =IF(COUNTIFS(Std_Schedule_Code!$B$5:$B$191,"UGA",Std_Schedule_Code!$G$5:$G$191,$C19)=0,"",_xlfn.MINIFS(Std_Schedule_Code!$AO$5:$AO$191,Std_Schedule_Code!$B$5:$B$191,"UGA",Std_Schedule_Code!$G$5:$G$191,$C19)) -> 2 | R19: 1 | S19: $1.00 / L | T19: 20.00 | U19: in A1 | V19: =IF(COUNTIFS(Std_Schedule_Code!$B$5:$B$191,"LBR",Std_Schedule_Code!$G$5:$G$191,$C19)=0,"",_xlfn.MINIFS(Std_Schedule_Code!$AO$5:$AO$191,Std_Schedule_Code!$B$5:$B$191,"LBR",Std_Schedule_Code!$G$5:$G$191,$C19)) -> 4 | W19: PR-01
A20: 3 Health | B20: health | C20: A3 | D20: Traditional / opaque beer (4% ABV) | E20: per LPA | F20: 0 | G20: Not identified (largely informal). HS 2206 cider/perry/mead line exists (FA2023, last legible); see code sheet | H20: - | I20: - | J20: =IF(COUNTIFS(Std_Schedule_Code!$B$5:$B$191,"SLE",Std_Schedule_Code!$G$5:$G$191,$C20)=0,"",_xlfn.MINIFS(Std_Schedule_Code!$AO$5:$AO$191,Std_Schedule_Code!$B$5:$B$191,"SLE",Std_Schedule_Code!$G$5:$G$191,$C20)) -> 1 | L20: 1 | M20: 12% or UGX 150/l; hybrid | N20: 1.0 | O20: ~10% | P20: =IF(COUNTIFS(Std_Schedule_Code!$B$5:$B$191,"UGA",Std_Schedule_Code!$G$5:$G$191,$C20)=0,"",_xlfn.MINIFS(Std_Schedule_Code!$AO$5:$AO$191,Std_Schedule_Code!$B$5:$B$191,"UGA",Std_Schedule_Code!$G$5:$G$191,$C20)) -> 2 | R20: 1 | S20: $1.00 / L | T20: 25.00 | U20: n/a (no price data) | V20: =IF(COUNTIFS(Std_Schedule_Code!$B$5:$B$191,"LBR",Std_Schedule_Code!$G$5:$G$191,$C20)=0,"",_xlfn.MINIFS(Std_Schedule_Code!$AO$5:$AO$191,Std_Schedule_Code!$B$5:$B$191,"LBR",Std_Schedule_Code!$G$5:$G$191,$C20)) -> 4 | W20: PR-01 | X20: Mapping of HS 2206 (cider, perry, mead; palm wine) to A3 differs between WP v0.8 and Liberia v0.3; settle in schedule v1.1.
A21: 3 Health | B21: health | C21: A4 | D21: Wine (12% ABV) | E21: per LPA | F21: 1 | G21: Le 6.30/l local; Le 12/l imported (10-20% ABV band); specific | H21: 2.4 / 4.5 | I21: n/a | J21: =IF(COUNTIFS(Std_Schedule_Code!$B$5:$B$191,"SLE",Std_Schedule_Code!$G$5:$G$191,$C21)=0,"",_xlfn.MINIFS(Std_Schedule_Code!$AO$5:$AO$191,Std_Schedule_Code!$B$5:$B$191,"SLE",Std_Schedule_Code!$G$5:$G$191,$C21)) -> 5 | K21: PR-24 | L21: 1 | M21: Local: 20% or UGX 2,000/l. Other: 80% or UGX 8,000/l | N21: 4.4 / 17.8 | O21: n/a | P21: =IF(COUNTIFS(Std_Schedule_Code!$B$5:$B$191,"UGA",Std_Schedule_Code!$G$5:$G$191,$C21)=0,"",_xlfn.MINIFS(Std_Schedule_Code!$AO$5:$AO$191,Std_Schedule_Code!$B$5:$B$191,"UGA",Std_Schedule_Code!$G$5:$G$191,$C21)) -> 2 | R21: 1 | S21: $1.00 / L | T21: 8.33 | U21: n/a (no price data) | V21: =IF(COUNTIFS(Std_Schedule_Code!$B$5:$B$191,"LBR",Std_Schedule_Code!$G$5:$G$191,$C21)=0,"",_xlfn.MINIFS(Std_Schedule_Code!$AO$5:$AO$191,Std_Schedule_Code!$B$5:$B$191,"LBR",Std_Schedule_Code!$G$5:$G$191,$C21)) -> 4 | W21: PR-01
A22: 3 Health | B22: health | C22: A5 | D22: Spirits (40% ABV) | E22: per LPA | F22: 1 | G22: HS 2208: specific. FA2023: US$3/l (>20% ABV); replaced by FA2024 s.4(e), rate not legible | H22: 7.5 (FA2023 rate) | I22: n/a | J22: =IF(COUNTIFS(Std_Schedule_Code!$B$5:$B$191,"SLE",Std_Schedule_Code!$G$5:$G$191,$C22)=0,"",_xlfn.MINIFS(Std_Schedule_Code!$AO$5:$AO$191,Std_Schedule_Code!$B$5:$B$191,"SLE",Std_Schedule_Code!$G$5:$G$191,$C22)) -> 1 | K22: PR-27 | L22: 1 | M22: Local: 60% or UGX 1,500/l. Imported: 100% or UGX 2,500/l. RTD: 80% or UGX 1,700/l | N22: 1.0 / 1.7 (specific floor) | O22: n/a | P22: =IF(COUNTIFS(Std_Schedule_Code!$B$5:$B$191,"UGA",Std_Schedule_Code!$G$5:$G$191,$C22)=0,"",_xlfn.MINIFS(Std_Schedule_Code!$AO$5:$AO$191,Std_Schedule_Code!$B$5:$B$191,"UGA",Std_Schedule_Code!$G$5:$G$191,$C22)) -> 2 | R22: 1 | S22: $3.00 / L | T22: 7.50 | U22: 73.1% (at 2024 price) | V22: =IF(COUNTIFS(Std_Schedule_Code!$B$5:$B$191,"LBR",Std_Schedule_Code!$G$5:$G$191,$C22)=0,"",_xlfn.MINIFS(Std_Schedule_Code!$AO$5:$AO$191,Std_Schedule_Code!$B$5:$B$191,"LBR",Std_Schedule_Code!$G$5:$G$191,$C22)) -> 4 | W22: PR-01, PR-03 | X22: Spirits per LPA below beer in SLE and LBR.
A23: 3 Health | B23: health | C23: S1 | D23: Carbonated and other soft drinks | E23: per liter | F23: 1 | G23: FA2023: US$0.10 / 0.30 / 0.50 per l for <15 / 15-25 / >25 g sugar per l; current rows not legible | H23: 0.10-0.50 | I23: n/a | J23: =IF(COUNTIFS(Std_Schedule_Code!$B$5:$B$191,"SLE",Std_Schedule_Code!$G$5:$G$191,$C23)=0,"",_xlfn.MINIFS(Std_Schedule_Code!$AO$5:$AO$191,Std_Schedule_Code!$B$5:$B$191,"SLE",Std_Schedule_Code!$G$5:$G$191,$C23)) -> 1 | K23: PR-31 | L23: 1 | M23: 12% or UGX 250/l; hybrid | N23: 0.07 | O23: ~6-10% | P23: =IF(COUNTIFS(Std_Schedule_Code!$B$5:$B$191,"UGA",Std_Schedule_Code!$G$5:$G$191,$C23)=0,"",_xlfn.MINIFS(Std_Schedule_Code!$AO$5:$AO$191,Std_Schedule_Code!$B$5:$B$191,"UGA",Std_Schedule_Code!$G$5:$G$191,$C23)) -> 2 | R23: 1 | S23: $0.45 / L | T23: 0.45 | U23: 43.7% (at 2024 price) | V23: =IF(COUNTIFS(Std_Schedule_Code!$B$5:$B$191,"LBR",Std_Schedule_Code!$G$5:$G$191,$C23)=0,"",_xlfn.MINIFS(Std_Schedule_Code!$AO$5:$AO$191,Std_Schedule_Code!$B$5:$B$191,"LBR",Std_Schedule_Code!$G$5:$G$191,$C23)) -> 4 | W23: PR-11, PR-12 | X23: SLE sugar-graduated (FA2023); UGA hybrid flat; LBR flat per liter.
A24: 3 Health | B24: health | C24: S2 | D24: Fruit and vegetable juice | E24: per liter | F24: 1 | G24: FA2023: US$0 (<5 g/l); 0.10 (5-15); 0.30 (15-25); 0.50 (>25) per l; origin-neutral | H24: 0-0.50 | I24: n/a | J24: =IF(COUNTIFS(Std_Schedule_Code!$B$5:$B$191,"SLE",Std_Schedule_Code!$G$5:$G$191,$C24)=0,"",_xlfn.MINIFS(Std_Schedule_Code!$AO$5:$AO$191,Std_Schedule_Code!$B$5:$B$191,"SLE",Std_Schedule_Code!$G$5:$G$191,$C24)) -> 1 | K24: PR-30 | L24: 1 | M24: 12% or UGX 250/l; concession for >=30% Ugandan pulp | N24: 0.07 | O24: ~6-10% | P24: =IF(COUNTIFS(Std_Schedule_Code!$B$5:$B$191,"UGA",Std_Schedule_Code!$G$5:$G$191,$C24)=0,"",_xlfn.MINIFS(Std_Schedule_Code!$AO$5:$AO$191,Std_Schedule_Code!$B$5:$B$191,"UGA",Std_Schedule_Code!$G$5:$G$191,$C24)) -> 2 | R24: 1 | S24: $0.45 / L | T24: 0.45 | U24: n/a (no price data) | V24: =IF(COUNTIFS(Std_Schedule_Code!$B$5:$B$191,"LBR",Std_Schedule_Code!$G$5:$G$191,$C24)=0,"",_xlfn.MINIFS(Std_Schedule_Code!$AO$5:$AO$191,Std_Schedule_Code!$B$5:$B$191,"LBR",Std_Schedule_Code!$G$5:$G$191,$C24)) -> 4 | W24: PR-11, PR-12
A25: 3 Health | B25: health | C25: S3 | D25: Energy drinks | E25: per liter | F25: 1 | G25: Within 'other non-alcoholic beverages' (as S1) | H25: 0.10-0.50 | I25: n/a | J25: =IF(COUNTIFS(Std_Schedule_Code!$B$5:$B$191,"SLE",Std_Schedule_Code!$G$5:$G$191,$C25)=0,"",_xlfn.MINIFS(Std_Schedule_Code!$AO$5:$AO$191,Std_Schedule_Code!$B$5:$B$191,"SLE",Std_Schedule_Code!$G$5:$G$191,$C25)) -> 1 | K25: PR-29 | L25: 1 | M25: Within non-alcoholic beverages: 12% or UGX 250/l | N25: 0.07 | O25: ~6-10% | P25: =IF(COUNTIFS(Std_Schedule_Code!$B$5:$B$191,"UGA",Std_Schedule_Code!$G$5:$G$191,$C25)=0,"",_xlfn.MINIFS(Std_Schedule_Code!$AO$5:$AO$191,Std_Schedule_Code!$B$5:$B$191,"UGA",Std_Schedule_Code!$G$5:$G$191,$C25)) -> 2 | R25: 1 | S25: $0.45 / L | T25: 0.45 | U25: n/a (no price data) | V25: =IF(COUNTIFS(Std_Schedule_Code!$B$5:$B$191,"LBR",Std_Schedule_Code!$G$5:$G$191,$C25)=0,"",_xlfn.MINIFS(Std_Schedule_Code!$AO$5:$AO$191,Std_Schedule_Code!$B$5:$B$191,"LBR",Std_Schedule_Code!$G$5:$G$191,$C25)) -> 4 | W25: PR-11
A26: 3 Health | B26: health | C26: S4 | D26: Bottled and processed water | E26: per liter | F26: 1 | G26: Within 'bottled or similarly packaged waters': US$0.10/l (<15 g/l) | H26: 0.10 | I26: n/a | J26: =IF(COUNTIFS(Std_Schedule_Code!$B$5:$B$191,"SLE",Std_Schedule_Code!$G$5:$G$191,$C26)=0,"",_xlfn.MINIFS(Std_Schedule_Code!$AO$5:$AO$191,Std_Schedule_Code!$B$5:$B$191,"SLE",Std_Schedule_Code!$G$5:$G$191,$C26)) -> 1 | K26: PR-29 | L26: 1 | M26: Hybrid: fixed plus ad valorem | N26: - | O26: - | P26: =IF(COUNTIFS(Std_Schedule_Code!$B$5:$B$191,"UGA",Std_Schedule_Code!$G$5:$G$191,$C26)=0,"",_xlfn.MINIFS(Std_Schedule_Code!$AO$5:$AO$191,Std_Schedule_Code!$B$5:$B$191,"UGA",Std_Schedule_Code!$G$5:$G$191,$C26)) -> 2 | R26: 1 | S26: $0.15 / L imported; NIL local | T26: 0.15 (imported) | U26: n/a (no price data) | V26: =IF(COUNTIFS(Std_Schedule_Code!$B$5:$B$191,"LBR",Std_Schedule_Code!$G$5:$G$191,$C26)=0,"",_xlfn.MINIFS(Std_Schedule_Code!$AO$5:$AO$191,Std_Schedule_Code!$B$5:$B$191,"LBR",Std_Schedule_Code!$G$5:$G$191,$C26)) -> 4 | W26: PR-11, PR-13
A27: 3 Health | B27: health | C27: G1 | D27: Gambling, betting and lotteries | E27: % of base | F27: 1 | G27: 10% of net wagered (gross gaming revenue) | H27: - | I27: - | J27: =IF(COUNTIFS(Std_Schedule_Code!$B$5:$B$191,"SLE",Std_Schedule_Code!$G$5:$G$191,$C27)=0,"",_xlfn.MINIFS(Std_Schedule_Code!$AO$5:$AO$191,Std_Schedule_Code!$B$5:$B$191,"SLE",Std_Schedule_Code!$G$5:$G$191,$C27)) -> 5 | K27: PR-32 | L27: 0 | M27: Not in excise schedule | N27: - | O27: - | P27: =IF(COUNTIFS(Std_Schedule_Code!$B$5:$B$191,"UGA",Std_Schedule_Code!$G$5:$G$191,$C27)=0,"",_xlfn.MINIFS(Std_Schedule_Code!$AO$5:$AO$191,Std_Schedule_Code!$B$5:$B$191,"UGA",Std_Schedule_Code!$G$5:$G$191,$C27)) -> 2 | R27: 1 | S27: 30% (Partial: equipment only) | T27: - | U27: - | V27: =IF(COUNTIFS(Std_Schedule_Code!$B$5:$B$191,"LBR",Std_Schedule_Code!$G$5:$G$191,$C27)=0,"",_xlfn.MINIFS(Std_Schedule_Code!$AO$5:$AO$191,Std_Schedule_Code!$B$5:$B$191,"LBR",Std_Schedule_Code!$G$5:$G$191,$C27)) -> 5 | W27: PR-14, PR-47, PR-49 | X27: Liberia taxes gaming equipment, Sierra Leone net wagered: different bases.
A28: 4 Other | B28: telecoms_digital | C28: D1 | D28: Voice and airtime | E28: per minute / % of fee | F28: 2 | G28: Cellular surcharge (FA2023 s.13): NLe 0.10 on-net; NLe 0.05 off-net; NLe 2 outgoing international | H28: 0.005 (on-net) | I28: - | J28: =IF(COUNTIFS(Std_Schedule_Code!$B$5:$B$191,"SLE",Std_Schedule_Code!$G$5:$G$191,$C28)=0,"",_xlfn.MINIFS(Std_Schedule_Code!$AO$5:$AO$191,Std_Schedule_Code!$B$5:$B$191,"SLE",Std_Schedule_Code!$G$5:$G$191,$C28)) -> 4 | K28: PR-36 | L28: 1 | M28: 12% of airtime fee; USD 0.09/min on incoming international calls (EAC partners excluded) | N28: - | O28: 12% of fee | P28: =IF(COUNTIFS(Std_Schedule_Code!$B$5:$B$191,"UGA",Std_Schedule_Code!$G$5:$G$191,$C28)=0,"",_xlfn.MINIFS(Std_Schedule_Code!$AO$5:$AO$191,Std_Schedule_Code!$B$5:$B$191,"UGA",Std_Schedule_Code!$G$5:$G$191,$C28)) -> 2 | R28: 2 | S28: 13% + 5% surtax (LRA notice: 15%) (Levy) | T28: 5-point surtax | U28: - | V28: =IF(COUNTIFS(Std_Schedule_Code!$B$5:$B$191,"LBR",Std_Schedule_Code!$G$5:$G$191,$C28)=0,"",_xlfn.MINIFS(Std_Schedule_Code!$AO$5:$AO$191,Std_Schedule_Code!$B$5:$B$191,"LBR",Std_Schedule_Code!$G$5:$G$191,$C28)) -> 3 | W28: PR-05, PR-06 | X28: Uganda inside excise law; SLE and LBR levies outside it.
A29: 4 Other | B29: telecoms_digital | C29: D2 | D29: Data and value-added services | E29: % of fee | F29: 2 | G29: Cellular surcharge: up to 5% of data recharge and bundle sales | H29: - | I29: <=5% | J29: =IF(COUNTIFS(Std_Schedule_Code!$B$5:$B$191,"SLE",Std_Schedule_Code!$G$5:$G$191,$C29)=0,"",_xlfn.MINIFS(Std_Schedule_Code!$AO$5:$AO$191,Std_Schedule_Code!$B$5:$B$191,"SLE",Std_Schedule_Code!$G$5:$G$191,$C29)) -> 5 | K29: PR-37 | L29: 1 | M29: 12% of fee (medical and education data exempt); 12% on SMS/MMS | N29: - | O29: 12% of fee | P29: =IF(COUNTIFS(Std_Schedule_Code!$B$5:$B$191,"UGA",Std_Schedule_Code!$G$5:$G$191,$C29)=0,"",_xlfn.MINIFS(Std_Schedule_Code!$AO$5:$AO$191,Std_Schedule_Code!$B$5:$B$191,"UGA",Std_Schedule_Code!$G$5:$G$191,$C29)) -> 2 | R29: 2 | S29: 13% + 5% surtax (LRA notice: 15%) (Levy) | T29: 5-point surtax | U29: - | V29: =IF(COUNTIFS(Std_Schedule_Code!$B$5:$B$191,"LBR",Std_Schedule_Code!$G$5:$G$191,$C29)=0,"",_xlfn.MINIFS(Std_Schedule_Code!$AO$5:$AO$191,Std_Schedule_Code!$B$5:$B$191,"LBR",Std_Schedule_Code!$G$5:$G$191,$C29)) -> 3 | W29: PR-06
A30: 4 Other | B30: financial_transactions | C30: F1 | D30: Mobile money and financial services | E30: % of value or fee | F30: 2 | G30: Cellular surcharge: 2% of mobile-money commissions | H30: - | I30: - | J30: =IF(COUNTIFS(Std_Schedule_Code!$B$5:$B$191,"SLE",Std_Schedule_Code!$G$5:$G$191,$C30)=0,"",_xlfn.MINIFS(Std_Schedule_Code!$AO$5:$AO$191,Std_Schedule_Code!$B$5:$B$191,"SLE",Std_Schedule_Code!$G$5:$G$191,$C30)) -> 5 | K30: PR-37 | L30: 1 | M30: 0.5% of mobile-money and agent withdrawals; 15% of bank fees | N30: - | O30: - | P30: =IF(COUNTIFS(Std_Schedule_Code!$B$5:$B$191,"UGA",Std_Schedule_Code!$G$5:$G$191,$C30)=0,"",_xlfn.MINIFS(Std_Schedule_Code!$AO$5:$AO$191,Std_Schedule_Code!$B$5:$B$191,"UGA",Std_Schedule_Code!$G$5:$G$191,$C30)) -> 2 | R30: 0 | S30: Not excisable: Not in s.1106; no levy found | T30: - | U30: - | V30: =IF(COUNTIFS(Std_Schedule_Code!$B$5:$B$191,"LBR",Std_Schedule_Code!$G$5:$G$191,$C30)=0,"",_xlfn.MINIFS(Std_Schedule_Code!$AO$5:$AO$191,Std_Schedule_Code!$B$5:$B$191,"LBR",Std_Schedule_Code!$G$5:$G$191,$C30)) -> 4 | W30: PR-15
A31: 4 Other | B31: industrial_residual | C31: I1 | D31: Cement | E31: per 50 kg bag | F31: 1 | G31: NLe 10/bag; specific (restored in FA2026) | H31: 0.45 | I31: n/a | J31: =IF(COUNTIFS(Std_Schedule_Code!$B$5:$B$191,"SLE",Std_Schedule_Code!$G$5:$G$191,$C31)=0,"",_xlfn.MINIFS(Std_Schedule_Code!$AO$5:$AO$191,Std_Schedule_Code!$B$5:$B$191,"SLE",Std_Schedule_Code!$G$5:$G$191,$C31)) -> 3 | K31: PR-33 | L31: 1 | M31: UGX 500/bag; specific | N31: 0.13 | O31: n/a | P31: =IF(COUNTIFS(Std_Schedule_Code!$B$5:$B$191,"UGA",Std_Schedule_Code!$G$5:$G$191,$C31)=0,"",_xlfn.MINIFS(Std_Schedule_Code!$AO$5:$AO$191,Std_Schedule_Code!$B$5:$B$191,"UGA",Std_Schedule_Code!$G$5:$G$191,$C31)) -> 2 | R31: 0 | S31: Not excisable: Not in s.1106 | T31: - | U31: - | V31: =IF(COUNTIFS(Std_Schedule_Code!$B$5:$B$191,"LBR",Std_Schedule_Code!$G$5:$G$191,$C31)=0,"",_xlfn.MINIFS(Std_Schedule_Code!$AO$5:$AO$191,Std_Schedule_Code!$B$5:$B$191,"LBR",Std_Schedule_Code!$G$5:$G$191,$C31)) -> 4 | W31: PR-15
A32: 4 Other | B32: industrial_residual | C32: I2 | D32: Edible oils | E32: per liter / % | F32: 1 | G32: 10% ad valorem (vegetable oils, palm olein, margarine) | H32: - | I32: - | J32: =IF(COUNTIFS(Std_Schedule_Code!$B$5:$B$191,"SLE",Std_Schedule_Code!$G$5:$G$191,$C32)=0,"",_xlfn.MINIFS(Std_Schedule_Code!$AO$5:$AO$191,Std_Schedule_Code!$B$5:$B$191,"SLE",Std_Schedule_Code!$G$5:$G$191,$C32)) -> 5 | K32: PR-35 | L32: 1 | M32: UGX 200/l (cooking oil); specific | N32: 0.05/l | O32: - | P32: =IF(COUNTIFS(Std_Schedule_Code!$B$5:$B$191,"UGA",Std_Schedule_Code!$G$5:$G$191,$C32)=0,"",_xlfn.MINIFS(Std_Schedule_Code!$AO$5:$AO$191,Std_Schedule_Code!$B$5:$B$191,"UGA",Std_Schedule_Code!$G$5:$G$191,$C32)) -> 2 | R32: 0 | S32: Not excisable: Not in s.1106 | T32: - | U32: - | V32: =IF(COUNTIFS(Std_Schedule_Code!$B$5:$B$191,"LBR",Std_Schedule_Code!$G$5:$G$191,$C32)=0,"",_xlfn.MINIFS(Std_Schedule_Code!$AO$5:$AO$191,Std_Schedule_Code!$B$5:$B$191,"LBR",Std_Schedule_Code!$G$5:$G$191,$C32)) -> 4 | W32: PR-15
