Workbook
Name PRETAX: _xlfn.LAMBDA(_xlpm.prev,_xlpm.growth,_xlpm.prev*(1+_xlpm.growth))
Name TAX: _xlfn.LAMBDA(_xlpm.base_tax,_xlpm.new_policy,_xlpm.base_tax+_xlpm.new_policy)
Name POSTTAX: _xlfn.LAMBDA(_xlpm.pre_tax_p,_xlpm.tax_p,_xlpm.pre_tax_p+_xlpm.tax_p)

Sheet ReadMe
A2: CPAT mitigation module - copy-pasteable prototype v0.8
A4: Purpose | B4: Auditable, copy-pasteable replacement of the CPAT mitigation price -> fuel-use chain. Each variable has one formula across all subsectors, fuels and years, and a whole scenario group copies to a new scenario and keeps working.
A5: Status | B5: v0.8 prototype: policies (carbon tax, fuel price reform, feebate shadow price) and price -> fuel use for transport, buildings, industry and other energy use. Power, emissions, revenue and ETS not yet.
A6: Layout (as legacy CPAT) | B6: Sections: 1. Policies (row 9), 3. Power sector (row 146, placeholder), 5. Transport (row 149), 6. Buildings (row 444), 7. Industrial (row 666), 8. Other energy use (row 1253), 11. Results - energy consumption (row 1329). Numbers follow the legacy Mitigation sheet.
A7: Nesting | B7: Across: scenario (outer) > year (inner). Down: sector section > subsector > variable > fuel. Each subsector: a heading line (its total fuel use), then sp, ctxnew, ntx, nce, tax, atp, shp, ener, each over the 8 fuels with one blank row (73 rows per subsector).
A8: Variables | B8: sp pre-tax price; ctxnew new carbon tax = carbon price x EF x fuel coverage x sector coverage; ntx new excise = fuel price reform path / GJ per unit; nce total new policy = ctxnew + ntx; tax = base tax + nce; atp after-tax price = sp + tax; shp shadow price = sector shadow price x EF x share impacting efficiency; ener fuel use (CPAT eq. 3.3.3): the usage term uses atp, the efficiency term (atp + shp), as legacy CPAT.
A9: Roll-up | B9: Sector sections show their total and the subsector heading lines; click + on a heading to see its variables (outline level 2). Section 1 shows the carbon price; its inputs and paths are rolled up. Buttons 1 / 2 / 3 at the top left set all levels.
A10: Section 1 (policies) | B10: Each input row reads MTInputs by its row number (column D, hidden) and the scenario number (row 5). Paths: carbon price as legacy (0 before CPIntro, linear to CPLevelTarget by CPOutro, linear continuation if Linear*); fuel price reform and feebates: 0 before the start year, linear from the starting to the final/target value, continuing linearly afterwards (one default). Shadow prices: by sector ($/tCO2) = feebate path (later + non-auctioned ETS, regulations); share impacting efficiency = feebate coverage x adjustment (1.0).
A11: Data step vs formulas | B11: Lookups happen in Inputs (one row per fuel|subsector), in Mitigation D:G (hidden; labels per variable in Variables G:J), the base-year column and the Section-1 input rows. Calculation cells contain no searching lookups; ctxnew, ntx and shp pick a Section-1 row by position with INDEX(range, position).
A12: LAMBDA column | B12: 2035 (orange) calls named LAMBDAs for sp, tax, atp and ener; drag it back over the row to use them everywhere, or drag 2034 forward. PRETAX(prev, growth) = prev*(1+growth); TAX(base_tax, new_policy) = base_tax+new_policy; POSTTAX(pre_tax_p, tax_p) = pre_tax_p+tax_p; FUELUSE(f_prev, p_now, p_prev, shp_now, shp_prev, gdp_g, eps_y, eps_u, eps_f, alpha) = f_prev*(1/(1+alpha))^(1+eps_u)*(1+gdp_g)^eps_y*(p_now/p_prev)^eps_u*((p_now+shp_now)/(p_prev+shp_prev))^(eps_f*(1+eps_u)).
A13: Codes | B13: Code column before each scenario group: country.mit.<variable>.<subsector>.<fuel>.<suffix>.<scenario> (e.g. egy.mit.ener.rod.gso.e.1). Scenario number at the top (row 5).
A14: Add a scenario | B14: MTInputs: copy the last scenario column one column right (its number updates) and edit its inputs. Mitigation: copy columns Z:AN and paste at AO; numbers, names, codes and all policy paths follow.
A15: Example | B15: Road (heading row 151): sp rows 152-159, ener rows 215-222.
... A17: Data | B17: Countries, Elasticities, Prices_dom, EnergyCons, WEO, EF_GHG; Mapping; Variables; MTInputs. Built by build_v0_8.py; checked by check_v0_8.py.

Sheet Settings
A2: Settings
B4: Country code | C4: EGY
B5: Country name | C5: =INDEX(Countries!$B$4:$B$1000,MATCH($C$4,Countries!$A$4:$A$1000,0))
B6: Income group (selects elasticities) | C6: =INDEX(Countries!$D$4:$D$1000,MATCH($C$4,Countries!$A$4:$A$1000,0))
B7: Base year | C7: 2022
B10: Version log
B11: Version | C11: Date | D11: Description | E11: Max abs regression diff
B12: 0.1 | C12: 2026-10-08 | D12: First build: design 2 price -> fuel-use prototype, Egypt base data, 2 scenarios. | E12: n/a (first version)
B13: 0.2 | C13: 2026-10-08 | D13: Inputs sheet by fuel|subsector (lookups separated from formulas); 4 hidden parameter columns D:G, global parameters; base year 2022 in column L; named LAMBDAs in 2035. | E13: 0 (vs v0.1)
B14: 0.3 | C14: 2026-10-08 | D14: Variable codes in column A; labels from Variables; code column per scenario with full CPAT codes (auto-numbered). | E14: 0 (vs v0.2)
B15: 0.4 | C15: 2026-10-08 | D15: Row outline: blocks roll up. | E15: 0 (vs v0.3)
B16: 0.5 | C16: 2026-10-08 | D16: White band text; summary lines under bands. | E16: 0 (vs v0.4)
B17: 0.6 | C17: 2026-10-08 | D17: MTInputs sheet per scenario; carbon price from MTInputs. | E17: 0 (vs v0.5)
B18: 0.7 | C18: 2026-10-08 | D18: Legacy CPAT section layout (1 Policies, 3 Power, 5-8 sectors, 11 Results; subsector > variable > fuel); policy wedges: new carbon tax with MTInputs coverage, new excise (fuel price reform), total new policy; feebate shadow price (not yet used). | E18: 0 (common codes vs v0.6)
B19: 0.8 | C19: 2026-10-08 | D19: Shadow price on the efficiency margin of fuel use; shadow prices by sector and share impacting efficiency in section 1; all policy paths continue linearly; biomass carbon-tax coverage TRUE. | E19: 0 (common codes vs v0.7, no feebate)

Sheet MTInputs
B1: MTInputs template - row structure copied exactly from legacy CPAT MTInputs
B2: Do not insert/delete rows. Columns D:E are hidden placeholders (MT values, Dashboard values).
B3: Rows must match legacy exactly. Green (EBF1DE) = used by module; grey (F2F2F2) = unused. See NORMS.md section 4. | J3: Scenario columns (Used for calculation): number in row 5, name in row 6. Red = changed from the template value. Copy the last column one to the right to add a scenario.
C5: FALSE | D5: <-- Should normally be "FALSE"! | J5: 1 | K5: =J5+1
D6: 6 | J6: Baseline (no carbon price) | K6: Carbon price $20/tCO2 from 2027
B7: Parameters | C7: unit | D7: MT values | E7: "Dashboard" values | F7: Used for calculation | G7: Defaults | H7: NameOfParameter | J7: Used for calculation | K7: Used for calculation
B8: Country | F8: Egypt | G8: Egypt | H8: Countryname | J8: Egypt | K8: Egypt
B9: Scenario identification
B10: Scenario ID | C10: # | F10: N/A | G10: N/A | H10: MSTScenarioID | J10: =J$5 | K10: =K$5
B11: Scenario status | C11: switch | F11: N/A | G11: N/A | J11: N/A | K11: N/A
B12: Scenario name | C12: name | F12: N/A | G12: N/A | J12: =J$6 | K12: =K$6
B13: Chosen policy | C13: switch | F13: - Carbon tax | G13: - Carbon tax | H13: ScenarioSelected | J13: - Carbon tax | K13: - Carbon tax
B14: Scenario status for macro | C14: # | F14: N/A | G14: N/A | J14: N/A | K14: N/A
B15: Scenario parameters override? | C15: # | F15: N/A | G15: N/A | J15: N/A | K15: N/A
B16: CPAT-side parameters override? | C16: switch | F16: Manual* | G16: Manual* | H16: CPATDefaultsOrUserDefined | J16: Manual* | K16: Manual*
B17: Carbon pricing: main inputs
A18: X | B18: Carbon pricing start year | C18: year | F18: 2026 | G18: 2027 | H18: CPIntro | J18: 2027 | K18: 2027
A19: X | B19: Starting carbon price | C19: nom. USD/tCO2 | F19: 0 | G19: 20 | H19: CPLevelStart | J19: 0 | K19: 20
B20: Target level of carbon price | C20: nom. USD/tCO2 | F20: 50 | G20: 50 | H20: CPLevelTarget | J20: 0 | K20: 20
A21: X | B21: Year to reach target level | C21: year | F21: 2030 | G21: 2035 | H21: CPOutro | J21: 2030 | K21: 2030
B22: Carbon pricing: fuel coverage
B23: Apply tax to coal? | C23: switch | F23: TRUE | G23: TRUE | H23: MCovCoa | J23: TRUE | K23: TRUE
B24: Apply tax to natural gas? | C24: switch | F24: TRUE | G24: TRUE | H24: MCovNga | J24: TRUE | K24: TRUE
B25: Apply tax to gasoline? | C25: switch | F25: TRUE | G25: TRUE | H25: MCovGso | J25: TRUE | K25: TRUE
B26: Apply tax to diesel? | C26: switch | F26: TRUE | G26: TRUE | H26: MCovDie | J26: TRUE | K26: TRUE
B27: Apply tax to LPG? | C27: switch | F27: TRUE | G27: TRUE | H27: MCovLpg | J27: TRUE | K27: TRUE
B28: Apply tax to kerosene? | C28: switch | F28: TRUE | G28: TRUE | H28: MCovKer | J28: TRUE | K28: TRUE
B29: Apply tax to non-road oil products? | C29: switch | F29: TRUE | G29: TRUE | H29: MCovOop | J29: TRUE | K29: TRUE
B30: Carbon pricing: sector coverage
B31: Apply tax to power sector? | C31: switch | F31: TRUE | G31: TRUE | H31: MCovPow | J31: TRUE | K31: TRUE
B32: Apply tax to road transportation? | C32: switch | F32: TRUE | G32: TRUE | H32: MCovRod | J32: TRUE | K32: TRUE
B33: Apply tax to rail transportation? | C33: switch | F33: TRUE | G33: TRUE | H33: MCovRal | J33: TRUE | K33: TRUE
B34: Apply tax to domestic aviation? | C34: switch | F34: TRUE | G34: TRUE | H34: MCovAvi | J34: TRUE | K34: TRUE
B35: Apply tax to domestic shipping? | C35: switch | F35: TRUE | G35: TRUE | H35: MCovNav | J35: TRUE | K35: TRUE
B36: Apply tax to residential sector? | C36: switch | F36: TRUE | G36: TRUE | H36: MCovRes | J36: TRUE | K36: TRUE
B37: Apply tax to food & forestry? | C37: switch | F37: TRUE | G37: TRUE | H37: MCovFoo | J37: TRUE | K37: TRUE
B38: Apply tax to services (private / public)? | C38: switch | F38: TRUE | G38: TRUE | H38: MCovSrv | J38: TRUE | K38: TRUE
B39: Apply tax to mining & chemicals? | C39: switch | F39: TRUE | G39: TRUE | H39: MCovMch | J39: TRUE | K39: TRUE
B40: Apply tax to iron and steel? | C40: switch | F40: TRUE | G40: TRUE | H40: MCovIrn | J40: TRUE | K40: TRUE
B41: Apply tax to non-ferrous metals? | C41: switch | F41: TRUE | G41: TRUE | H41: MCovNfm | J41: TRUE | K41: TRUE
...

Sheet Mitigation
A1: Variable | B1: Fuel | C1: Sector | D1: Param 1 | E1: Param 2 | F1: Param 3 | G1: Param 4 | H1: Description | I1: Unit | J1: Source | K1: Scenario 1: output code | Z1: Scenario 2: output code
A2: Mitigation module - price to fuel use (copy-pasteable, design 2, legacy CPAT sections)
A3: Scenario assumptions (one column group per scenario: code column + years; copy a whole group to add a scenario)
H4: Year | L4: =Settings!$C$7 | M4: =L4+1 | N4: =M4+1 | O4: =N4+1 | P4: =O4+1 | Q4: =P4+1 | R4: =Q4+1 | S4: =R4+1 | T4: =S4+1 | ... Y4: =X4+1 | AA4: =Settings!$C$7 | AB4: =AA4+1 | AC4: =AB4+1 | AD4: =AC4+1 | AE4: =AD4+1 | AF4: =AE4+1 | AG4: =AF4+1 | AH4: =AG4+1 | AI4: =AH4+1 | ... AN4: =AM4+1
H5: Scenario number (MTInputs column) | K5: 1 | L5: =K5 | M5: =L5 | N5: =M5 | O5: =N5 | P5: =O5 | Q5: =P5 | R5: =Q5 | S5: =R5 | ... Y5: =X5 | Z5: =K5+1 | AA5: =Z5 | AB5: =AA5 | AC5: =AB5 | AD5: =AC5 | AE5: =AD5 | AF5: =AE5 | AG5: =AF5 | AH5: =AG5 | ... AN5: =AM5
H6: Scenario name (from MTInputs) | L6: =INDEX(MTInputs!$J$6:$AZ$6,MATCH(L$5,MTInputs!$J$5:$AZ$5,0)) | AA6: =INDEX(MTInputs!$J$6:$AZ$6,MATCH(AA$5,MTInputs!$J$5:$AZ$5,0))
A7: gdp.pos.pct | H7: =INDEX(Variables!$B$5:$B$65,MATCH($A7,Variables!$A$5:$A$65,0))&IF($C7="",""," | "&INDEX(Mapping!$B$5:$B$25,MATCH($C7,Mapping!$A$5:$A$25,0))&" | "&INDEX(Mapping!$B$29:$B$38,MATCH($B7,Mapping!$A$29:$A$38,0))) | I7: =INDEX(Variables!$C$5:$C$65,MATCH($A7,Variables!$A$5:$A$65,0)) | J7: =INDEX(Variables!$E$5:$E$65,MATCH($A7,Variables!$A$5:$A$65,0)) | K7: =LOWER(Settings!$C$4)&".mit."&$A7&IF($C7="","","."&$C7&"."&$B7)&IF(INDEX(Variables!$D$5:$D$65,MATCH($A7,Variables!$A$5:$A$65,0))="","","."&INDEX(Variables!$D$5:$D$65,MATCH($A7,Variables!$A$5:$A$65,0)))&"."&K$5 | L7: =INDEX(WEO!$F$4:$AZ$1000,MATCH(Settings!$C$4&"|gdp_growth",WEO!$A$4:$A$1000,0),MATCH(L$4,WEO!$F$3:$AZ$3,0)) | M7: =INDEX(WEO!$F$4:$AZ$1000,MATCH(Settings!$C$4&"|gdp_growth",WEO!$A$4:$A$1000,0),MATCH(M$4,WEO!$F$3:$AZ$3,0)) | N7: =INDEX(WEO!$F$4:$AZ$1000,MATCH(Settings!$C$4&"|gdp_growth",WEO!$A$4:$A$1000,0),MATCH(N$4,WEO!$F$3:$AZ$3,0)) | O7: =INDEX(WEO!$F$4:$AZ$1000,MATCH(Settings!$C$4&"|gdp_growth",WEO!$A$4:$A$1000,0),MATCH(O$4,WEO!$F$3:$AZ$3,0)) | P7: =INDEX(WEO!$F$4:$AZ$1000,MATCH(Settings!$C$4&"|gdp_growth",WEO!$A$4:$A$1000,0),MATCH(P$4,WEO!$F$3:$AZ$3,0)) | Q7: =INDEX(WEO!$F$4:$AZ$1000,MATCH(Settings!$C$4&"|gdp_growth",WEO!$A$4:$A$1000,0),MATCH(Q$4,WEO!$F$3:$AZ$3,0)) | R7: =INDEX(WEO!$F$4:$AZ$1000,MATCH(Settings!$C$4&"|gdp_growth",WEO!$A$4:$A$1000,0),MATCH(R$4,WEO!$F$3:$AZ$3,0)) | S7: =INDEX(WEO!$F$4:$AZ$1000,MATCH(Settings!$C$4&"|gdp_growth",WEO!$A$4:$A$1000,0),MATCH(S$4,WEO!$F$3:$AZ$3,0)) | ... Y7: =INDEX(WEO!$F$4:$AZ$1000,MATCH(Settings!$C$4&"|gdp_growth",WEO!$A$4:$A$1000,0),MATCH(Y$4,WEO!$F$3:$AZ$3,0)) | Z7: =LOWER(Settings!$C$4)&".mit."&$A7&IF($C7="","","."&$C7&"."&$B7)&IF(INDEX(Variables!$D$5:$D$65,MATCH($A7,Variables!$A$5:$A$65,0))="","","."&INDEX(Variables!$D$5:$D$65,MATCH($A7,Variables!$A$5:$A$65,0)))&"."&Z$5 | AA7: =INDEX(WEO!$F$4:$AZ$1000,MATCH(Settings!$C$4&"|gdp_growth",WEO!$A$4:$A$1000,0),MATCH(AA$4,WEO!$F$3:$AZ$3,0)) | AB7: =INDEX(WEO!$F$4:$AZ$1000,MATCH(Settings!$C$4&"|gdp_growth",WEO!$A$4:$A$1000,0),MATCH(AB$4,WEO!$F$3:$AZ$3,0)) | AC7: =INDEX(WEO!$F$4:$AZ$1000,MATCH(Settings!$C$4&"|gdp_growth",WEO!$A$4:$A$1000,0),MATCH(AC$4,WEO!$F$3:$AZ$3,0)) | AD7: =INDEX(WEO!$F$4:$AZ$1000,MATCH(Settings!$C$4&"|gdp_growth",WEO!$A$4:$A$1000,0),MATCH(AD$4,WEO!$F$3:$AZ$3,0)) | AE7: =INDEX(WEO!$F$4:$AZ$1000,MATCH(Settings!$C$4&"|gdp_growth",WEO!$A$4:$A$1000,0),MATCH(AE$4,WEO!$F$3:$AZ$3,0)) | AF7: =INDEX(WEO!$F$4:$AZ$1000,MATCH(Settings!$C$4&"|gdp_growth",WEO!$A$4:$A$1000,0),MATCH(AF$4,WEO!$F$3:$AZ$3,0)) | AG7: =INDEX(WEO!$F$4:$AZ$1000,MATCH(Settings!$C$4&"|gdp_growth",WEO!$A$4:$A$1000,0),MATCH(AG$4,WEO!$F$3:$AZ$3,0)) | AH7: =INDEX(WEO!$F$4:$AZ$1000,MATCH(Settings!$C$4&"|gdp_growth",WEO!$A$4:$A$1000,0),MATCH(AH$4,WEO!$F$3:$AZ$3,0)) | ... AN7: =INDEX(WEO!$F$4:$AZ$1000,MATCH(Settings!$C$4&"|gdp_growth",WEO!$A$4:$A$1000,0),MATCH(AN$4,WEO!$F$3:$AZ$3,0))
A9: 1. Policies (scenario inputs from MTInputs by row and scenario number; policy paths) | D9: MTInputs row
A10: cptraj | H10: =INDEX(Variables!$B$5:$B$65,MATCH($A10,Variables!$A$5:$A$65,0))&IF($C10="",""," | "&INDEX(Mapping!$B$5:$B$25,MATCH($C10,Mapping!$A$5:$A$25,0))&" | "&INDEX(Mapping!$B$29:$B$38,MATCH($B10,Mapping!$A$29:$A$38,0))) | I10: =INDEX(Variables!$C$5:$C$65,MATCH($A10,Variables!$A$5:$A$65,0)) | J10: =INDEX(Variables!$E$5:$E$65,MATCH($A10,Variables!$A$5:$A$65,0)) | K10: =LOWER(Settings!$C$4)&".mit."&$A10&IF($C10="","","."&$C10&"."&$B10)&IF(INDEX(Variables!$D$5:$D$65,MATCH($A10,Variables!$A$5:$A$65,0))="","","."&INDEX(Variables!$D$5:$D$65,MATCH($A10,Variables!$A$5:$A$65,0)))&"."&K$5 | L10: =IF(L$4<L$12,0,L$13+(L$14-L$13)/MAX(L$15-L$12,1)*IF(OR(L$4<=L$15,L$16="Linear*"),L$4-L$12,L$15-L$12)) | M10: =IF(M$4<M$12,0,M$13+(M$14-M$13)/MAX(M$15-M$12,1)*IF(OR(M$4<=M$15,M$16="Linear*"),M$4-M$12,M$15-M$12)) | N10: =IF(N$4<N$12,0,N$13+(N$14-N$13)/MAX(N$15-N$12,1)*IF(OR(N$4<=N$15,N$16="Linear*"),N$4-N$12,N$15-N$12)) | O10: =IF(O$4<O$12,0,O$13+(O$14-O$13)/MAX(O$15-O$12,1)*IF(OR(O$4<=O$15,O$16="Linear*"),O$4-O$12,O$15-O$12)) | P10: =IF(P$4<P$12,0,P$13+(P$14-P$13)/MAX(P$15-P$12,1)*IF(OR(P$4<=P$15,P$16="Linear*"),P$4-P$12,P$15-P$12)) | Q10: =IF(Q$4<Q$12,0,Q$13+(Q$14-Q$13)/MAX(Q$15-Q$12,1)*IF(OR(Q$4<=Q$15,Q$16="Linear*"),Q$4-Q$12,Q$15-Q$12)) | R10: =IF(R$4<R$12,0,R$13+(R$14-R$13)/MAX(R$15-R$12,1)*IF(OR(R$4<=R$15,R$16="Linear*"),R$4-R$12,R$15-R$12)) | S10: =IF(S$4<S$12,0,S$13+(S$14-S$13)/MAX(S$15-S$12,1)*IF(OR(S$4<=S$15,S$16="Linear*"),S$4-S$12,S$15-S$12)) | ... Y10: =IF(Y$4<Y$12,0,Y$13+(Y$14-Y$13)/MAX(Y$15-Y$12,1)*IF(OR(Y$4<=Y$15,Y$16="Linear*"),Y$4-Y$12,Y$15-Y$12)) | Z10: =LOWER(Settings!$C$4)&".mit."&$A10&IF($C10="","","."&$C10&"."&$B10)&IF(INDEX(Variables!$D$5:$D$65,MATCH($A10,Variables!$A$5:$A$65,0))="","","."&INDEX(Variables!$D$5:$D$65,MATCH($A10,Variables!$A$5:$A$65,0)))&"."&Z$5 | AA10: =IF(AA$4<AA$12,0,AA$13+(AA$14-AA$13)/MAX(AA$15-AA$12,1)*IF(OR(AA$4<=AA$15,AA$16="Linear*"),AA$4-AA$12,AA$15-AA$12)) | AB10: =IF(AB$4<AB$12,0,AB$13+(AB$14-AB$13)/MAX(AB$15-AB$12,1)*IF(OR(AB$4<=AB$15,AB$16="Linear*"),AB$4-AB$12,AB$15-AB$12)) | AC10: =IF(AC$4<AC$12,0,AC$13+(AC$14-AC$13)/MAX(AC$15-AC$12,1)*IF(OR(AC$4<=AC$15,AC$16="Linear*"),AC$4-AC$12,AC$15-AC$12)) | AD10: =IF(AD$4<AD$12,0,AD$13+(AD$14-AD$13)/MAX(AD$15-AD$12,1)*IF(OR(AD$4<=AD$15,AD$16="Linear*"),AD$4-AD$12,AD$15-AD$12)) | AE10: =IF(AE$4<AE$12,0,AE$13+(AE$14-AE$13)/MAX(AE$15-AE$12,1)*IF(OR(AE$4<=AE$15,AE$16="Linear*"),AE$4-AE$12,AE$15-AE$12)) | AF10: =IF(AF$4<AF$12,0,AF$13+(AF$14-AF$13)/MAX(AF$15-AF$12,1)*IF(OR(AF$4<=AF$15,AF$16="Linear*"),AF$4-AF$12,AF$15-AF$12)) | AG10: =IF(AG$4<AG$12,0,AG$13+(AG$14-AG$13)/MAX(AG$15-AG$12,1)*IF(OR(AG$4<=AG$15,AG$16="Linear*"),AG$4-AG$12,AG$15-AG$12)) | AH10: =IF(AH$4<AH$12,0,AH$13+(AH$14-AH$13)/MAX(AH$15-AH$12,1)*IF(OR(AH$4<=AH$15,AH$16="Linear*"),AH$4-AH$12,AH$15-AH$12)) | ... AN10: =IF(AN$4<AN$12,0,AN$13+(AN$14-AN$13)/MAX(AN$15-AN$12,1)*IF(OR(AN$4<=AN$15,AN$16="Linear*"),AN$4-AN$12,AN$15-AN$12))
H11: Carbon tax (MTInputs rows 18-21, 265)
A12: CPIntro | D12: 18 | H12: =INDEX(Variables!$B$5:$B$65,MATCH($A12,Variables!$A$5:$A$65,0))&IF($C12="",""," | "&INDEX(Mapping!$B$5:$B$25,MATCH($C12,Mapping!$A$5:$A$25,0))&" | "&INDEX(Mapping!$B$29:$B$38,MATCH($B12,Mapping!$A$29:$A$38,0))) | I12: =INDEX(Variables!$C$5:$C$65,MATCH($A12,Variables!$A$5:$A$65,0)) | J12: =INDEX(Variables!$E$5:$E$65,MATCH($A12,Variables!$A$5:$A$65,0)) | K12: =LOWER(Settings!$C$4)&".mit."&$A12&IF($C12="","","."&$C12&"."&$B12)&IF(INDEX(Variables!$D$5:$D$65,MATCH($A12,Variables!$A$5:$A$65,0))="","","."&INDEX(Variables!$D$5:$D$65,MATCH($A12,Variables!$A$5:$A$65,0)))&"."&K$5 | L12: =INDEX(MTInputs!$J$1:$AZ$415,$D12,MATCH(L$5,MTInputs!$J$5:$AZ$5,0)) | M12: =INDEX(MTInputs!$J$1:$AZ$415,$D12,MATCH(M$5,MTInputs!$J$5:$AZ$5,0)) | N12: =INDEX(MTInputs!$J$1:$AZ$415,$D12,MATCH(N$5,MTInputs!$J$5:$AZ$5,0)) | O12: =INDEX(MTInputs!$J$1:$AZ$415,$D12,MATCH(O$5,MTInputs!$J$5:$AZ$5,0)) | P12: =INDEX(MTInputs!$J$1:$AZ$415,$D12,MATCH(P$5,MTInputs!$J$5:$AZ$5,0)) | Q12: =INDEX(MTInputs!$J$1:$AZ$415,$D12,MATCH(Q$5,MTInputs!$J$5:$AZ$5,0)) | R12: =INDEX(MTInputs!$J$1:$AZ$415,$D12,MATCH(R$5,MTInputs!$J$5:$AZ$5,0)) | S12: =INDEX(MTInputs!$J$1:$AZ$415,$D12,MATCH(S$5,MTInputs!$J$5:$AZ$5,0)) | ... Y12: =INDEX(MTInputs!$J$1:$AZ$415,$D12,MATCH(Y$5,MTInputs!$J$5:$AZ$5,0)) | Z12: =LOWER(Settings!$C$4)&".mit."&$A12&IF($C12="","","."&$C12&"."&$B12)&IF(INDEX(Variables!$D$5:$D$65,MATCH($A12,Variables!$A$5:$A$65,0))="","","."&INDEX(Variables!$D$5:$D$65,MATCH($A12,Variables!$A$5:$A$65,0)))&"."&Z$5 | AA12: =INDEX(MTInputs!$J$1:$AZ$415,$D12,MATCH(AA$5,MTInputs!$J$5:$AZ$5,0)) | AB12: =INDEX(MTInputs!$J$1:$AZ$415,$D12,MATCH(AB$5,MTInputs!$J$5:$AZ$5,0)) | AC12: =INDEX(MTInputs!$J$1:$AZ$415,$D12,MATCH(AC$5,MTInputs!$J$5:$AZ$5,0)) | AD12: =INDEX(MTInputs!$J$1:$AZ$415,$D12,MATCH(AD$5,MTInputs!$J$5:$AZ$5,0)) | AE12: =INDEX(MTInputs!$J$1:$AZ$415,$D12,MATCH(AE$5,MTInputs!$J$5:$AZ$5,0)) | AF12: =INDEX(MTInputs!$J$1:$AZ$415,$D12,MATCH(AF$5,MTInputs!$J$5:$AZ$5,0)) | AG12: =INDEX(MTInputs!$J$1:$AZ$415,$D12,MATCH(AG$5,MTInputs!$J$5:$AZ$5,0)) | AH12: =INDEX(MTInputs!$J$1:$AZ$415,$D12,MATCH(AH$5,MTInputs!$J$5:$AZ$5,0)) | ... AN12: =INDEX(MTInputs!$J$1:$AZ$415,$D12,MATCH(AN$5,MTInputs!$J$5:$AZ$5,0))
A13: CPLevelStart | D13: 19 | H13: =INDEX(Variables!$B$5:$B$65,MATCH($A13,Variables!$A$5:$A$65,0))&IF($C13="",""," | "&INDEX(Mapping!$B$5:$B$25,MATCH($C13,Mapping!$A$5:$A$25,0))&" | "&INDEX(Mapping!$B$29:$B$38,MATCH($B13,Mapping!$A$29:$A$38,0))) | I13: =INDEX(Variables!$C$5:$C$65,MATCH($A13,Variables!$A$5:$A$65,0)) | J13: =INDEX(Variables!$E$5:$E$65,MATCH($A13,Variables!$A$5:$A$65,0)) | K13: =LOWER(Settings!$C$4)&".mit."&$A13&IF($C13="","","."&$C13&"."&$B13)&IF(INDEX(Variables!$D$5:$D$65,MATCH($A13,Variables!$A$5:$A$65,0))="","","."&INDEX(Variables!$D$5:$D$65,MATCH($A13,Variables!$A$5:$A$65,0)))&"."&K$5 | L13: =INDEX(MTInputs!$J$1:$AZ$415,$D13,MATCH(L$5,MTInputs!$J$5:$AZ$5,0)) | M13: =INDEX(MTInputs!$J$1:$AZ$415,$D13,MATCH(M$5,MTInputs!$J$5:$AZ$5,0)) | N13: =INDEX(MTInputs!$J$1:$AZ$415,$D13,MATCH(N$5,MTInputs!$J$5:$AZ$5,0)) | O13: =INDEX(MTInputs!$J$1:$AZ$415,$D13,MATCH(O$5,MTInputs!$J$5:$AZ$5,0)) | P13: =INDEX(MTInputs!$J$1:$AZ$415,$D13,MATCH(P$5,MTInputs!$J$5:$AZ$5,0)) | Q13: =INDEX(MTInputs!$J$1:$AZ$415,$D13,MATCH(Q$5,MTInputs!$J$5:$AZ$5,0)) | R13: =INDEX(MTInputs!$J$1:$AZ$415,$D13,MATCH(R$5,MTInputs!$J$5:$AZ$5,0)) | S13: =INDEX(MTInputs!$J$1:$AZ$415,$D13,MATCH(S$5,MTInputs!$J$5:$AZ$5,0)) | ... Y13: =INDEX(MTInputs!$J$1:$AZ$415,$D13,MATCH(Y$5,MTInputs!$J$5:$AZ$5,0)) | Z13: =LOWER(Settings!$C$4)&".mit."&$A13&IF($C13="","","."&$C13&"."&$B13)&IF(INDEX(Variables!$D$5:$D$65,MATCH($A13,Variables!$A$5:$A$65,0))="","","."&INDEX(Variables!$D$5:$D$65,MATCH($A13,Variables!$A$5:$A$65,0)))&"."&Z$5 | AA13: =INDEX(MTInputs!$J$1:$AZ$415,$D13,MATCH(AA$5,MTInputs!$J$5:$AZ$5,0)) | AB13: =INDEX(MTInputs!$J$1:$AZ$415,$D13,MATCH(AB$5,MTInputs!$J$5:$AZ$5,0)) | AC13: =INDEX(MTInputs!$J$1:$AZ$415,$D13,MATCH(AC$5,MTInputs!$J$5:$AZ$5,0)) | AD13: =INDEX(MTInputs!$J$1:$AZ$415,$D13,MATCH(AD$5,MTInputs!$J$5:$AZ$5,0)) | AE13: =INDEX(MTInputs!$J$1:$AZ$415,$D13,MATCH(AE$5,MTInputs!$J$5:$AZ$5,0)) | AF13: =INDEX(MTInputs!$J$1:$AZ$415,$D13,MATCH(AF$5,MTInputs!$J$5:$AZ$5,0)) | AG13: =INDEX(MTInputs!$J$1:$AZ$415,$D13,MATCH(AG$5,MTInputs!$J$5:$AZ$5,0)) | AH13: =INDEX(MTInputs!$J$1:$AZ$415,$D13,MATCH(AH$5,MTInputs!$J$5:$AZ$5,0)) | ... AN13: =INDEX(MTInputs!$J$1:$AZ$415,$D13,MATCH(AN$5,MTInputs!$J$5:$AZ$5,0))
A14: CPLevelTarget | D14: 20 | H14: =INDEX(Variables!$B$5:$B$65,MATCH($A14,Variables!$A$5:$A$65,0))&IF($C14="",""," | "&INDEX(Mapping!$B$5:$B$25,MATCH($C14,Mapping!$A$5:$A$25,0))&" | "&INDEX(Mapping!$B$29:$B$38,MATCH($B14,Mapping!$A$29:$A$38,0))) | I14: =INDEX(Variables!$C$5:$C$65,MATCH($A14,Variables!$A$5:$A$65,0)) | J14: =INDEX(Variables!$E$5:$E$65,MATCH($A14,Variables!$A$5:$A$65,0)) | K14: =LOWER(Settings!$C$4)&".mit."&$A14&IF($C14="","","."&$C14&"."&$B14)&IF(INDEX(Variables!$D$5:$D$65,MATCH($A14,Variables!$A$5:$A$65,0))="","","."&INDEX(Variables!$D$5:$D$65,MATCH($A14,Variables!$A$5:$A$65,0)))&"."&K$5 | L14: =INDEX(MTInputs!$J$1:$AZ$415,$D14,MATCH(L$5,MTInputs!$J$5:$AZ$5,0)) | M14: =INDEX(MTInputs!$J$1:$AZ$415,$D14,MATCH(M$5,MTInputs!$J$5:$AZ$5,0)) | N14: =INDEX(MTInputs!$J$1:$AZ$415,$D14,MATCH(N$5,MTInputs!$J$5:$AZ$5,0)) | O14: =INDEX(MTInputs!$J$1:$AZ$415,$D14,MATCH(O$5,MTInputs!$J$5:$AZ$5,0)) | P14: =INDEX(MTInputs!$J$1:$AZ$415,$D14,MATCH(P$5,MTInputs!$J$5:$AZ$5,0)) | Q14: =INDEX(MTInputs!$J$1:$AZ$415,$D14,MATCH(Q$5,MTInputs!$J$5:$AZ$5,0)) | R14: =INDEX(MTInputs!$J$1:$AZ$415,$D14,MATCH(R$5,MTInputs!$J$5:$AZ$5,0)) | S14: =INDEX(MTInputs!$J$1:$AZ$415,$D14,MATCH(S$5,MTInputs!$J$5:$AZ$5,0)) | ... Y14: =INDEX(MTInputs!$J$1:$AZ$415,$D14,MATCH(Y$5,MTInputs!$J$5:$AZ$5,0)) | Z14: =LOWER(Settings!$C$4)&".mit."&$A14&IF($C14="","","."&$C14&"."&$B14)&IF(INDEX(Variables!$D$5:$D$65,MATCH($A14,Variables!$A$5:$A$65,0))="","","."&INDEX(Variables!$D$5:$D$65,MATCH($A14,Variables!$A$5:$A$65,0)))&"."&Z$5 | AA14: =INDEX(MTInputs!$J$1:$AZ$415,$D14,MATCH(AA$5,MTInputs!$J$5:$AZ$5,0)) | AB14: =INDEX(MTInputs!$J$1:$AZ$415,$D14,MATCH(AB$5,MTInputs!$J$5:$AZ$5,0)) | AC14: =INDEX(MTInputs!$J$1:$AZ$415,$D14,MATCH(AC$5,MTInputs!$J$5:$AZ$5,0)) | AD14: =INDEX(MTInputs!$J$1:$AZ$415,$D14,MATCH(AD$5,MTInputs!$J$5:$AZ$5,0)) | AE14: =INDEX(MTInputs!$J$1:$AZ$415,$D14,MATCH(AE$5,MTInputs!$J$5:$AZ$5,0)) | AF14: =INDEX(MTInputs!$J$1:$AZ$415,$D14,MATCH(AF$5,MTInputs!$J$5:$AZ$5,0)) | AG14: =INDEX(MTInputs!$J$1:$AZ$415,$D14,MATCH(AG$5,MTInputs!$J$5:$AZ$5,0)) | AH14: =INDEX(MTInputs!$J$1:$AZ$415,$D14,MATCH(AH$5,MTInputs!$J$5:$AZ$5,0)) | ... AN14: =INDEX(MTInputs!$J$1:$AZ$415,$D14,MATCH(AN$5,MTInputs!$J$5:$AZ$5,0))
A15: CPOutro | D15: 21 | H15: =INDEX(Variables!$B$5:$B$65,MATCH($A15,Variables!$A$5:$A$65,0))&IF($C15="",""," | "&INDEX(Mapping!$B$5:$B$25,MATCH($C15,Mapping!$A$5:$A$25,0))&" | "&INDEX(Mapping!$B$29:$B$38,MATCH($B15,Mapping!$A$29:$A$38,0))) | I15: =INDEX(Variables!$C$5:$C$65,MATCH($A15,Variables!$A$5:$A$65,0)) | J15: =INDEX(Variables!$E$5:$E$65,MATCH($A15,Variables!$A$5:$A$65,0)) | K15: =LOWER(Settings!$C$4)&".mit."&$A15&IF($C15="","","."&$C15&"."&$B15)&IF(INDEX(Variables!$D$5:$D$65,MATCH($A15,Variables!$A$5:$A$65,0))="","","."&INDEX(Variables!$D$5:$D$65,MATCH($A15,Variables!$A$5:$A$65,0)))&"."&K$5 | L15: =INDEX(MTInputs!$J$1:$AZ$415,$D15,MATCH(L$5,MTInputs!$J$5:$AZ$5,0)) | M15: =INDEX(MTInputs!$J$1:$AZ$415,$D15,MATCH(M$5,MTInputs!$J$5:$AZ$5,0)) | N15: =INDEX(MTInputs!$J$1:$AZ$415,$D15,MATCH(N$5,MTInputs!$J$5:$AZ$5,0)) | O15: =INDEX(MTInputs!$J$1:$AZ$415,$D15,MATCH(O$5,MTInputs!$J$5:$AZ$5,0)) | P15: =INDEX(MTInputs!$J$1:$AZ$415,$D15,MATCH(P$5,MTInputs!$J$5:$AZ$5,0)) | Q15: =INDEX(MTInputs!$J$1:$AZ$415,$D15,MATCH(Q$5,MTInputs!$J$5:$AZ$5,0)) | R15: =INDEX(MTInputs!$J$1:$AZ$415,$D15,MATCH(R$5,MTInputs!$J$5:$AZ$5,0)) | S15: =INDEX(MTInputs!$J$1:$AZ$415,$D15,MATCH(S$5,MTInputs!$J$5:$AZ$5,0)) | ... Y15: =INDEX(MTInputs!$J$1:$AZ$415,$D15,MATCH(Y$5,MTInputs!$J$5:$AZ$5,0)) | Z15: =LOWER(Settings!$C$4)&".mit."&$A15&IF($C15="","","."&$C15&"."&$B15)&IF(INDEX(Variables!$D$5:$D$65,MATCH($A15,Variables!$A$5:$A$65,0))="","","."&INDEX(Variables!$D$5:$D$65,MATCH($A15,Variables!$A$5:$A$65,0)))&"."&Z$5 | AA15: =INDEX(MTInputs!$J$1:$AZ$415,$D15,MATCH(AA$5,MTInputs!$J$5:$AZ$5,0)) | AB15: =INDEX(MTInputs!$J$1:$AZ$415,$D15,MATCH(AB$5,MTInputs!$J$5:$AZ$5,0)) | AC15: =INDEX(MTInputs!$J$1:$AZ$415,$D15,MATCH(AC$5,MTInputs!$J$5:$AZ$5,0)) | AD15: =INDEX(MTInputs!$J$1:$AZ$415,$D15,MATCH(AD$5,MTInputs!$J$5:$AZ$5,0)) | AE15: =INDEX(MTInputs!$J$1:$AZ$415,$D15,MATCH(AE$5,MTInputs!$J$5:$AZ$5,0)) | AF15: =INDEX(MTInputs!$J$1:$AZ$415,$D15,MATCH(AF$5,MTInputs!$J$5:$AZ$5,0)) | AG15: =INDEX(MTInputs!$J$1:$AZ$415,$D15,MATCH(AG$5,MTInputs!$J$5:$AZ$5,0)) | AH15: =INDEX(MTInputs!$J$1:$AZ$415,$D15,MATCH(AH$5,MTInputs!$J$5:$AZ$5,0)) | ... AN15: =INDEX(MTInputs!$J$1:$AZ$415,$D15,MATCH(AN$5,MTInputs!$J$5:$AZ$5,0))
A16: ExtendCarbonPriceBeyondOutro | D16: 265 | H16: =INDEX(Variables!$B$5:$B$65,MATCH($A16,Variables!$A$5:$A$65,0))&IF($C16="",""," | "&INDEX(Mapping!$B$5:$B$25,MATCH($C16,Mapping!$A$5:$A$25,0))&" | "&INDEX(Mapping!$B$29:$B$38,MATCH($B16,Mapping!$A$29:$A$38,0))) | I16: =INDEX(Variables!$C$5:$C$65,MATCH($A16,Variables!$A$5:$A$65,0)) | J16: =INDEX(Variables!$E$5:$E$65,MATCH($A16,Variables!$A$5:$A$65,0)) | K16: =LOWER(Settings!$C$4)&".mit."&$A16&IF($C16="","","."&$C16&"."&$B16)&IF(INDEX(Variables!$D$5:$D$65,MATCH($A16,Variables!$A$5:$A$65,0))="","","."&INDEX(Variables!$D$5:$D$65,MATCH($A16,Variables!$A$5:$A$65,0)))&"."&K$5 | L16: =INDEX(MTInputs!$J$1:$AZ$415,$D16,MATCH(L$5,MTInputs!$J$5:$AZ$5,0)) | M16: =INDEX(MTInputs!$J$1:$AZ$415,$D16,MATCH(M$5,MTInputs!$J$5:$AZ$5,0)) | N16: =INDEX(MTInputs!$J$1:$AZ$415,$D16,MATCH(N$5,MTInputs!$J$5:$AZ$5,0)) | O16: =INDEX(MTInputs!$J$1:$AZ$415,$D16,MATCH(O$5,MTInputs!$J$5:$AZ$5,0)) | P16: =INDEX(MTInputs!$J$1:$AZ$415,$D16,MATCH(P$5,MTInputs!$J$5:$AZ$5,0)) | Q16: =INDEX(MTInputs!$J$1:$AZ$415,$D16,MATCH(Q$5,MTInputs!$J$5:$AZ$5,0)) | R16: =INDEX(MTInputs!$J$1:$AZ$415,$D16,MATCH(R$5,MTInputs!$J$5:$AZ$5,0)) | S16: =INDEX(MTInputs!$J$1:$AZ$415,$D16,MATCH(S$5,MTInputs!$J$5:$AZ$5,0)) | ... Y16: =INDEX(MTInputs!$J$1:$AZ$415,$D16,MATCH(Y$5,MTInputs!$J$5:$AZ$5,0)) | Z16: =LOWER(Settings!$C$4)&".mit."&$A16&IF($C16="","","."&$C16&"."&$B16)&IF(INDEX(Variables!$D$5:$D$65,MATCH($A16,Variables!$A$5:$A$65,0))="","","."&INDEX(Variables!$D$5:$D$65,MATCH($A16,Variables!$A$5:$A$65,0)))&"."&Z$5 | AA16: =INDEX(MTInputs!$J$1:$AZ$415,$D16,MATCH(AA$5,MTInputs!$J$5:$AZ$5,0)) | AB16: =INDEX(MTInputs!$J$1:$AZ$415,$D16,MATCH(AB$5,MTInputs!$J$5:$AZ$5,0)) | AC16: =INDEX(MTInputs!$J$1:$AZ$415,$D16,MATCH(AC$5,MTInputs!$J$5:$AZ$5,0)) | AD16: =INDEX(MTInputs!$J$1:$AZ$415,$D16,MATCH(AD$5,MTInputs!$J$5:$AZ$5,0)) | AE16: =INDEX(MTInputs!$J$1:$AZ$415,$D16,MATCH(AE$5,MTInputs!$J$5:$AZ$5,0)) | AF16: =INDEX(MTInputs!$J$1:$AZ$415,$D16,MATCH(AF$5,MTInputs!$J$5:$AZ$5,0)) | AG16: =INDEX(MTInputs!$J$1:$AZ$415,$D16,MATCH(AG$5,MTInputs!$J$5:$AZ$5,0)) | AH16: =INDEX(MTInputs!$J$1:$AZ$415,$D16,MATCH(AH$5,MTInputs!$J$5:$AZ$5,0)) | ... AN16: =INDEX(MTInputs!$J$1:$AZ$415,$D16,MATCH(AN$5,MTInputs!$J$5:$AZ$5,0))
H17: Carbon tax coverage: fuels (MTInputs rows 23-29)
A18: ctcov | B18: coa | C18: all | D18: 23 | H18: =INDEX(Variables!$B$5:$B$65,MATCH($A18,Variables!$A$5:$A$65,0))&IF($C18="",""," | "&INDEX(Mapping!$B$5:$B$25,MATCH($C18,Mapping!$A$5:$A$25,0))&" | "&INDEX(Mapping!$B$29:$B$38,MATCH($B18,Mapping!$A$29:$A$38,0))) | I18: =INDEX(Variables!$C$5:$C$65,MATCH($A18,Variables!$A$5:$A$65,0)) | J18: =INDEX(Variables!$E$5:$E$65,MATCH($A18,Variables!$A$5:$A$65,0)) | K18: =LOWER(Settings!$C$4)&".mit."&$A18&IF($C18="","","."&$C18&"."&$B18)&IF(INDEX(Variables!$D$5:$D$65,MATCH($A18,Variables!$A$5:$A$65,0))="","","."&INDEX(Variables!$D$5:$D$65,MATCH($A18,Variables!$A$5:$A$65,0)))&"."&K$5 | L18: =INDEX(MTInputs!$J$1:$AZ$415,$D18,MATCH(L$5,MTInputs!$J$5:$AZ$5,0)) | M18: =INDEX(MTInputs!$J$1:$AZ$415,$D18,MATCH(M$5,MTInputs!$J$5:$AZ$5,0)) | N18: =INDEX(MTInputs!$J$1:$AZ$415,$D18,MATCH(N$5,MTInputs!$J$5:$AZ$5,0)) | O18: =INDEX(MTInputs!$J$1:$AZ$415,$D18,MATCH(O$5,MTInputs!$J$5:$AZ$5,0)) | P18: =INDEX(MTInputs!$J$1:$AZ$415,$D18,MATCH(P$5,MTInputs!$J$5:$AZ$5,0)) | Q18: =INDEX(MTInputs!$J$1:$AZ$415,$D18,MATCH(Q$5,MTInputs!$J$5:$AZ$5,0)) | R18: =INDEX(MTInputs!$J$1:$AZ$415,$D18,MATCH(R$5,MTInputs!$J$5:$AZ$5,0)) | S18: =INDEX(MTInputs!$J$1:$AZ$415,$D18,MATCH(S$5,MTInputs!$J$5:$AZ$5,0)) | ... Y18: =INDEX(MTInputs!$J$1:$AZ$415,$D18,MATCH(Y$5,MTInputs!$J$5:$AZ$5,0)) | Z18: =LOWER(Settings!$C$4)&".mit."&$A18&IF($C18="","","."&$C18&"."&$B18)&IF(INDEX(Variables!$D$5:$D$65,MATCH($A18,Variables!$A$5:$A$65,0))="","","."&INDEX(Variables!$D$5:$D$65,MATCH($A18,Variables!$A$5:$A$65,0)))&"."&Z$5 | AA18: =INDEX(MTInputs!$J$1:$AZ$415,$D18,MATCH(AA$5,MTInputs!$J$5:$AZ$5,0)) | AB18: =INDEX(MTInputs!$J$1:$AZ$415,$D18,MATCH(AB$5,MTInputs!$J$5:$AZ$5,0)) | AC18: =INDEX(MTInputs!$J$1:$AZ$415,$D18,MATCH(AC$5,MTInputs!$J$5:$AZ$5,0)) | AD18: =INDEX(MTInputs!$J$1:$AZ$415,$D18,MATCH(AD$5,MTInputs!$J$5:$AZ$5,0)) | AE18: =INDEX(MTInputs!$J$1:$AZ$415,$D18,MATCH(AE$5,MTInputs!$J$5:$AZ$5,0)) | AF18: =INDEX(MTInputs!$J$1:$AZ$415,$D18,MATCH(AF$5,MTInputs!$J$5:$AZ$5,0)) | AG18: =INDEX(MTInputs!$J$1:$AZ$415,$D18,MATCH(AG$5,MTInputs!$J$5:$AZ$5,0)) | AH18: =INDEX(MTInputs!$J$1:$AZ$415,$D18,MATCH(AH$5,MTInputs!$J$5:$AZ$5,0)) | ... AN18: =INDEX(MTInputs!$J$1:$AZ$415,$D18,MATCH(AN$5,MTInputs!$J$5:$AZ$5,0))
A19: ctcov | B19: nga | C19: all | D19: 24 | H19: =INDEX(Variables!$B$5:$B$65,MATCH($A19,Variables!$A$5:$A$65,0))&IF($C19="",""," | "&INDEX(Mapping!$B$5:$B$25,MATCH($C19,Mapping!$A$5:$A$25,0))&" | "&INDEX(Mapping!$B$29:$B$38,MATCH($B19,Mapping!$A$29:$A$38,0))) | I19: =INDEX(Variables!$C$5:$C$65,MATCH($A19,Variables!$A$5:$A$65,0)) | J19: =INDEX(Variables!$E$5:$E$65,MATCH($A19,Variables!$A$5:$A$65,0)) | K19: =LOWER(Settings!$C$4)&".mit."&$A19&IF($C19="","","."&$C19&"."&$B19)&IF(INDEX(Variables!$D$5:$D$65,MATCH($A19,Variables!$A$5:$A$65,0))="","","."&INDEX(Variables!$D$5:$D$65,MATCH($A19,Variables!$A$5:$A$65,0)))&"."&K$5 | L19: =INDEX(MTInputs!$J$1:$AZ$415,$D19,MATCH(L$5,MTInputs!$J$5:$AZ$5,0)) | M19: =INDEX(MTInputs!$J$1:$AZ$415,$D19,MATCH(M$5,MTInputs!$J$5:$AZ$5,0)) | N19: =INDEX(MTInputs!$J$1:$AZ$415,$D19,MATCH(N$5,MTInputs!$J$5:$AZ$5,0)) | O19: =INDEX(MTInputs!$J$1:$AZ$415,$D19,MATCH(O$5,MTInputs!$J$5:$AZ$5,0)) | P19: =INDEX(MTInputs!$J$1:$AZ$415,$D19,MATCH(P$5,MTInputs!$J$5:$AZ$5,0)) | Q19: =INDEX(MTInputs!$J$1:$AZ$415,$D19,MATCH(Q$5,MTInputs!$J$5:$AZ$5,0)) | R19: =INDEX(MTInputs!$J$1:$AZ$415,$D19,MATCH(R$5,MTInputs!$J$5:$AZ$5,0)) | S19: =INDEX(MTInputs!$J$1:$AZ$415,$D19,MATCH(S$5,MTInputs!$J$5:$AZ$5,0)) | ... Y19: =INDEX(MTInputs!$J$1:$AZ$415,$D19,MATCH(Y$5,MTInputs!$J$5:$AZ$5,0)) | Z19: =LOWER(Settings!$C$4)&".mit."&$A19&IF($C19="","","."&$C19&"."&$B19)&IF(INDEX(Variables!$D$5:$D$65,MATCH($A19,Variables!$A$5:$A$65,0))="","","."&INDEX(Variables!$D$5:$D$65,MATCH($A19,Variables!$A$5:$A$65,0)))&"."&Z$5 | AA19: =INDEX(MTInputs!$J$1:$AZ$415,$D19,MATCH(AA$5,MTInputs!$J$5:$AZ$5,0)) | AB19: =INDEX(MTInputs!$J$1:$AZ$415,$D19,MATCH(AB$5,MTInputs!$J$5:$AZ$5,0)) | AC19: =INDEX(MTInputs!$J$1:$AZ$415,$D19,MATCH(AC$5,MTInputs!$J$5:$AZ$5,0)) | AD19: =INDEX(MTInputs!$J$1:$AZ$415,$D19,MATCH(AD$5,MTInputs!$J$5:$AZ$5,0)) | AE19: =INDEX(MTInputs!$J$1:$AZ$415,$D19,MATCH(AE$5,MTInputs!$J$5:$AZ$5,0)) | AF19: =INDEX(MTInputs!$J$1:$AZ$415,$D19,MATCH(AF$5,MTInputs!$J$5:$AZ$5,0)) | AG19: =INDEX(MTInputs!$J$1:$AZ$415,$D19,MATCH(AG$5,MTInputs!$J$5:$AZ$5,0)) | AH19: =INDEX(MTInputs!$J$1:$AZ$415,$D19,MATCH(AH$5,MTInputs!$J$5:$AZ$5,0)) | ... AN19: =INDEX(MTInputs!$J$1:$AZ$415,$D19,MATCH(AN$5,MTInputs!$J$5:$AZ$5,0))
A20: ctcov | B20: gso | C20: all | D20: 25 | H20: =INDEX(Variables!$B$5:$B$65,MATCH($A20,Variables!$A$5:$A$65,0))&IF($C20="",""," | "&INDEX(Mapping!$B$5:$B$25,MATCH($C20,Mapping!$A$5:$A$25,0))&" | "&INDEX(Mapping!$B$29:$B$38,MATCH($B20,Mapping!$A$29:$A$38,0))) | I20: =INDEX(Variables!$C$5:$C$65,MATCH($A20,Variables!$A$5:$A$65,0)) | J20: =INDEX(Variables!$E$5:$E$65,MATCH($A20,Variables!$A$5:$A$65,0)) | K20: =LOWER(Settings!$C$4)&".mit."&$A20&IF($C20="","","."&$C20&"."&$B20)&IF(INDEX(Variables!$D$5:$D$65,MATCH($A20,Variables!$A$5:$A$65,0))="","","."&INDEX(Variables!$D$5:$D$65,MATCH($A20,Variables!$A$5:$A$65,0)))&"."&K$5 | L20: =INDEX(MTInputs!$J$1:$AZ$415,$D20,MATCH(L$5,MTInputs!$J$5:$AZ$5,0)) | M20: =INDEX(MTInputs!$J$1:$AZ$415,$D20,MATCH(M$5,MTInputs!$J$5:$AZ$5,0)) | N20: =INDEX(MTInputs!$J$1:$AZ$415,$D20,MATCH(N$5,MTInputs!$J$5:$AZ$5,0)) | O20: =INDEX(MTInputs!$J$1:$AZ$415,$D20,MATCH(O$5,MTInputs!$J$5:$AZ$5,0)) | P20: =INDEX(MTInputs!$J$1:$AZ$415,$D20,MATCH(P$5,MTInputs!$J$5:$AZ$5,0)) | Q20: =INDEX(MTInputs!$J$1:$AZ$415,$D20,MATCH(Q$5,MTInputs!$J$5:$AZ$5,0)) | R20: =INDEX(MTInputs!$J$1:$AZ$415,$D20,MATCH(R$5,MTInputs!$J$5:$AZ$5,0)) | S20: =INDEX(MTInputs!$J$1:$AZ$415,$D20,MATCH(S$5,MTInputs!$J$5:$AZ$5,0)) | ... Y20: =INDEX(MTInputs!$J$1:$AZ$415,$D20,MATCH(Y$5,MTInputs!$J$5:$AZ$5,0)) | Z20: =LOWER(Settings!$C$4)&".mit."&$A20&IF($C20="","","."&$C20&"."&$B20)&IF(INDEX(Variables!$D$5:$D$65,MATCH($A20,Variables!$A$5:$A$65,0))="","","."&INDEX(Variables!$D$5:$D$65,MATCH($A20,Variables!$A$5:$A$65,0)))&"."&Z$5 | AA20: =INDEX(MTInputs!$J$1:$AZ$415,$D20,MATCH(AA$5,MTInputs!$J$5:$AZ$5,0)) | AB20: =INDEX(MTInputs!$J$1:$AZ$415,$D20,MATCH(AB$5,MTInputs!$J$5:$AZ$5,0)) | AC20: =INDEX(MTInputs!$J$1:$AZ$415,$D20,MATCH(AC$5,MTInputs!$J$5:$AZ$5,0)) | AD20: =INDEX(MTInputs!$J$1:$AZ$415,$D20,MATCH(AD$5,MTInputs!$J$5:$AZ$5,0)) | AE20: =INDEX(MTInputs!$J$1:$AZ$415,$D20,MATCH(AE$5,MTInputs!$J$5:$AZ$5,0)) | AF20: =INDEX(MTInputs!$J$1:$AZ$415,$D20,MATCH(AF$5,MTInputs!$J$5:$AZ$5,0)) | AG20: =INDEX(MTInputs!$J$1:$AZ$415,$D20,MATCH(AG$5,MTInputs!$J$5:$AZ$5,0)) | AH20: =INDEX(MTInputs!$J$1:$AZ$415,$D20,MATCH(AH$5,MTInputs!$J$5:$AZ$5,0)) | ... AN20: =INDEX(MTInputs!$J$1:$AZ$415,$D20,MATCH(AN$5,MTInputs!$J$5:$AZ$5,0))
A21: ctcov | B21: die | C21: all | D21: 26 | H21: =INDEX(Variables!$B$5:$B$65,MATCH($A21,Variables!$A$5:$A$65,0))&IF($C21="",""," | "&INDEX(Mapping!$B$5:$B$25,MATCH($C21,Mapping!$A$5:$A$25,0))&" | "&INDEX(Mapping!$B$29:$B$38,MATCH($B21,Mapping!$A$29:$A$38,0))) | I21: =INDEX(Variables!$C$5:$C$65,MATCH($A21,Variables!$A$5:$A$65,0)) | J21: =INDEX(Variables!$E$5:$E$65,MATCH($A21,Variables!$A$5:$A$65,0)) | K21: =LOWER(Settings!$C$4)&".mit."&$A21&IF($C21="","","."&$C21&"."&$B21)&IF(INDEX(Variables!$D$5:$D$65,MATCH($A21,Variables!$A$5:$A$65,0))="","","."&INDEX(Variables!$D$5:$D$65,MATCH($A21,Variables!$A$5:$A$65,0)))&"."&K$5 | L21: =INDEX(MTInputs!$J$1:$AZ$415,$D21,MATCH(L$5,MTInputs!$J$5:$AZ$5,0)) | M21: =INDEX(MTInputs!$J$1:$AZ$415,$D21,MATCH(M$5,MTInputs!$J$5:$AZ$5,0)) | N21: =INDEX(MTInputs!$J$1:$AZ$415,$D21,MATCH(N$5,MTInputs!$J$5:$AZ$5,0)) | O21: =INDEX(MTInputs!$J$1:$AZ$415,$D21,MATCH(O$5,MTInputs!$J$5:$AZ$5,0)) | P21: =INDEX(MTInputs!$J$1:$AZ$415,$D21,MATCH(P$5,MTInputs!$J$5:$AZ$5,0)) | Q21: =INDEX(MTInputs!$J$1:$AZ$415,$D21,MATCH(Q$5,MTInputs!$J$5:$AZ$5,0)) | R21: =INDEX(MTInputs!$J$1:$AZ$415,$D21,MATCH(R$5,MTInputs!$J$5:$AZ$5,0)) | S21: =INDEX(MTInputs!$J$1:$AZ$415,$D21,MATCH(S$5,MTInputs!$J$5:$AZ$5,0)) | ... Y21: =INDEX(MTInputs!$J$1:$AZ$415,$D21,MATCH(Y$5,MTInputs!$J$5:$AZ$5,0)) | Z21: =LOWER(Settings!$C$4)&".mit."&$A21&IF($C21="","","."&$C21&"."&$B21)&IF(INDEX(Variables!$D$5:$D$65,MATCH($A21,Variables!$A$5:$A$65,0))="","","."&INDEX(Variables!$D$5:$D$65,MATCH($A21,Variables!$A$5:$A$65,0)))&"."&Z$5 | AA21: =INDEX(MTInputs!$J$1:$AZ$415,$D21,MATCH(AA$5,MTInputs!$J$5:$AZ$5,0)) | AB21: =INDEX(MTInputs!$J$1:$AZ$415,$D21,MATCH(AB$5,MTInputs!$J$5:$AZ$5,0)) | AC21: =INDEX(MTInputs!$J$1:$AZ$415,$D21,MATCH(AC$5,MTInputs!$J$5:$AZ$5,0)) | AD21: =INDEX(MTInputs!$J$1:$AZ$415,$D21,MATCH(AD$5,MTInputs!$J$5:$AZ$5,0)) | AE21: =INDEX(MTInputs!$J$1:$AZ$415,$D21,MATCH(AE$5,MTInputs!$J$5:$AZ$5,0)) | AF21: =INDEX(MTInputs!$J$1:$AZ$415,$D21,MATCH(AF$5,MTInputs!$J$5:$AZ$5,0)) | AG21: =INDEX(MTInputs!$J$1:$AZ$415,$D21,MATCH(AG$5,MTInputs!$J$5:$AZ$5,0)) | AH21: =INDEX(MTInputs!$J$1:$AZ$415,$D21,MATCH(AH$5,MTInputs!$J$5:$AZ$5,0)) | ... AN21: =INDEX(MTInputs!$J$1:$AZ$415,$D21,MATCH(AN$5,MTInputs!$J$5:$AZ$5,0))
A22: ctcov | B22: lpg | C22: all | D22: 27 | H22: =INDEX(Variables!$B$5:$B$65,MATCH($A22,Variables!$A$5:$A$65,0))&IF($C22="",""," | "&INDEX(Mapping!$B$5:$B$25,MATCH($C22,Mapping!$A$5:$A$25,0))&" | "&INDEX(Mapping!$B$29:$B$38,MATCH($B22,Mapping!$A$29:$A$38,0))) | I22: =INDEX(Variables!$C$5:$C$65,MATCH($A22,Variables!$A$5:$A$65,0)) | J22: =INDEX(Variables!$E$5:$E$65,MATCH($A22,Variables!$A$5:$A$65,0)) | K22: =LOWER(Settings!$C$4)&".mit."&$A22&IF($C22="","","."&$C22&"."&$B22)&IF(INDEX(Variables!$D$5:$D$65,MATCH($A22,Variables!$A$5:$A$65,0))="","","."&INDEX(Variables!$D$5:$D$65,MATCH($A22,Variables!$A$5:$A$65,0)))&"."&K$5 | L22: =INDEX(MTInputs!$J$1:$AZ$415,$D22,MATCH(L$5,MTInputs!$J$5:$AZ$5,0)) | M22: =INDEX(MTInputs!$J$1:$AZ$415,$D22,MATCH(M$5,MTInputs!$J$5:$AZ$5,0)) | N22: =INDEX(MTInputs!$J$1:$AZ$415,$D22,MATCH(N$5,MTInputs!$J$5:$AZ$5,0)) | O22: =INDEX(MTInputs!$J$1:$AZ$415,$D22,MATCH(O$5,MTInputs!$J$5:$AZ$5,0)) | P22: =INDEX(MTInputs!$J$1:$AZ$415,$D22,MATCH(P$5,MTInputs!$J$5:$AZ$5,0)) | Q22: =INDEX(MTInputs!$J$1:$AZ$415,$D22,MATCH(Q$5,MTInputs!$J$5:$AZ$5,0)) | R22: =INDEX(MTInputs!$J$1:$AZ$415,$D22,MATCH(R$5,MTInputs!$J$5:$AZ$5,0)) | S22: =INDEX(MTInputs!$J$1:$AZ$415,$D22,MATCH(S$5,MTInputs!$J$5:$AZ$5,0)) | ... Y22: =INDEX(MTInputs!$J$1:$AZ$415,$D22,MATCH(Y$5,MTInputs!$J$5:$AZ$5,0)) | Z22: =LOWER(Settings!$C$4)&".mit."&$A22&IF($C22="","","."&$C22&"."&$B22)&IF(INDEX(Variables!$D$5:$D$65,MATCH($A22,Variables!$A$5:$A$65,0))="","","."&INDEX(Variables!$D$5:$D$65,MATCH($A22,Variables!$A$5:$A$65,0)))&"."&Z$5 | AA22: =INDEX(MTInputs!$J$1:$AZ$415,$D22,MATCH(AA$5,MTInputs!$J$5:$AZ$5,0)) | AB22: =INDEX(MTInputs!$J$1:$AZ$415,$D22,MATCH(AB$5,MTInputs!$J$5:$AZ$5,0)) | AC22: =INDEX(MTInputs!$J$1:$AZ$415,$D22,MATCH(AC$5,MTInputs!$J$5:$AZ$5,0)) | AD22: =INDEX(MTInputs!$J$1:$AZ$415,$D22,MATCH(AD$5,MTInputs!$J$5:$AZ$5,0)) | AE22: =INDEX(MTInputs!$J$1:$AZ$415,$D22,MATCH(AE$5,MTInputs!$J$5:$AZ$5,0)) | AF22: =INDEX(MTInputs!$J$1:$AZ$415,$D22,MATCH(AF$5,MTInputs!$J$5:$AZ$5,0)) | AG22: =INDEX(MTInputs!$J$1:$AZ$415,$D22,MATCH(AG$5,MTInputs!$J$5:$AZ$5,0)) | AH22: =INDEX(MTInputs!$J$1:$AZ$415,$D22,MATCH(AH$5,MTInputs!$J$5:$AZ$5,0)) | ... AN22: =INDEX(MTInputs!$J$1:$AZ$415,$D22,MATCH(AN$5,MTInputs!$J$5:$AZ$5,0))
A23: ctcov | B23: ker | C23: all | D23: 28 | H23: =INDEX(Variables!$B$5:$B$65,MATCH($A23,Variables!$A$5:$A$65,0))&IF($C23="",""," | "&INDEX(Mapping!$B$5:$B$25,MATCH($C23,Mapping!$A$5:$A$25,0))&" | "&INDEX(Mapping!$B$29:$B$38,MATCH($B23,Mapping!$A$29:$A$38,0))) | I23: =INDEX(Variables!$C$5:$C$65,MATCH($A23,Variables!$A$5:$A$65,0)) | J23: =INDEX(Variables!$E$5:$E$65,MATCH($A23,Variables!$A$5:$A$65,0)) | K23: =LOWER(Settings!$C$4)&".mit."&$A23&IF($C23="","","."&$C23&"."&$B23)&IF(INDEX(Variables!$D$5:$D$65,MATCH($A23,Variables!$A$5:$A$65,0))="","","."&INDEX(Variables!$D$5:$D$65,MATCH($A23,Variables!$A$5:$A$65,0)))&"."&K$5 | L23: =INDEX(MTInputs!$J$1:$AZ$415,$D23,MATCH(L$5,MTInputs!$J$5:$AZ$5,0)) | M23: =INDEX(MTInputs!$J$1:$AZ$415,$D23,MATCH(M$5,MTInputs!$J$5:$AZ$5,0)) | N23: =INDEX(MTInputs!$J$1:$AZ$415,$D23,MATCH(N$5,MTInputs!$J$5:$AZ$5,0)) | O23: =INDEX(MTInputs!$J$1:$AZ$415,$D23,MATCH(O$5,MTInputs!$J$5:$AZ$5,0)) | P23: =INDEX(MTInputs!$J$1:$AZ$415,$D23,MATCH(P$5,MTInputs!$J$5:$AZ$5,0)) | Q23: =INDEX(MTInputs!$J$1:$AZ$415,$D23,MATCH(Q$5,MTInputs!$J$5:$AZ$5,0)) | R23: =INDEX(MTInputs!$J$1:$AZ$415,$D23,MATCH(R$5,MTInputs!$J$5:$AZ$5,0)) | S23: =INDEX(MTInputs!$J$1:$AZ$415,$D23,MATCH(S$5,MTInputs!$J$5:$AZ$5,0)) | ... Y23: =INDEX(MTInputs!$J$1:$AZ$415,$D23,MATCH(Y$5,MTInputs!$J$5:$AZ$5,0)) | Z23: =LOWER(Settings!$C$4)&".mit."&$A23&IF($C23="","","."&$C23&"."&$B23)&IF(INDEX(Variables!$D$5:$D$65,MATCH($A23,Variables!$A$5:$A$65,0))="","","."&INDEX(Variables!$D$5:$D$65,MATCH($A23,Variables!$A$5:$A$65,0)))&"."&Z$5 | AA23: =INDEX(MTInputs!$J$1:$AZ$415,$D23,MATCH(AA$5,MTInputs!$J$5:$AZ$5,0)) | AB23: =INDEX(MTInputs!$J$1:$AZ$415,$D23,MATCH(AB$5,MTInputs!$J$5:$AZ$5,0)) | AC23: =INDEX(MTInputs!$J$1:$AZ$415,$D23,MATCH(AC$5,MTInputs!$J$5:$AZ$5,0)) | AD23: =INDEX(MTInputs!$J$1:$AZ$415,$D23,MATCH(AD$5,MTInputs!$J$5:$AZ$5,0)) | AE23: =INDEX(MTInputs!$J$1:$AZ$415,$D23,MATCH(AE$5,MTInputs!$J$5:$AZ$5,0)) | AF23: =INDEX(MTInputs!$J$1:$AZ$415,$D23,MATCH(AF$5,MTInputs!$J$5:$AZ$5,0)) | AG23: =INDEX(MTInputs!$J$1:$AZ$415,$D23,MATCH(AG$5,MTInputs!$J$5:$AZ$5,0)) | AH23: =INDEX(MTInputs!$J$1:$AZ$415,$D23,MATCH(AH$5,MTInputs!$J$5:$AZ$5,0)) | ... AN23: =INDEX(MTInputs!$J$1:$AZ$415,$D23,MATCH(AN$5,MTInputs!$J$5:$AZ$5,0))
A24: ctcov | B24: oop | C24: all | D24: 29 | H24: =INDEX(Variables!$B$5:$B$65,MATCH($A24,Variables!$A$5:$A$65,0))&IF($C24="",""," | "&INDEX(Mapping!$B$5:$B$25,MATCH($C24,Mapping!$A$5:$A$25,0))&" | "&INDEX(Mapping!$B$29:$B$38,MATCH($B24,Mapping!$A$29:$A$38,0))) | I24: =INDEX(Variables!$C$5:$C$65,MATCH($A24,Variables!$A$5:$A$65,0)) | J24: =INDEX(Variables!$E$5:$E$65,MATCH($A24,Variables!$A$5:$A$65,0)) | K24: =LOWER(Settings!$C$4)&".mit."&$A24&IF($C24="","","."&$C24&"."&$B24)&IF(INDEX(Variables!$D$5:$D$65,MATCH($A24,Variables!$A$5:$A$65,0))="","","."&INDEX(Variables!$D$5:$D$65,MATCH($A24,Variables!$A$5:$A$65,0)))&"."&K$5 | L24: =INDEX(MTInputs!$J$1:$AZ$415,$D24,MATCH(L$5,MTInputs!$J$5:$AZ$5,0)) | M24: =INDEX(MTInputs!$J$1:$AZ$415,$D24,MATCH(M$5,MTInputs!$J$5:$AZ$5,0)) | N24: =INDEX(MTInputs!$J$1:$AZ$415,$D24,MATCH(N$5,MTInputs!$J$5:$AZ$5,0)) | O24: =INDEX(MTInputs!$J$1:$AZ$415,$D24,MATCH(O$5,MTInputs!$J$5:$AZ$5,0)) | P24: =INDEX(MTInputs!$J$1:$AZ$415,$D24,MATCH(P$5,MTInputs!$J$5:$AZ$5,0)) | Q24: =INDEX(MTInputs!$J$1:$AZ$415,$D24,MATCH(Q$5,MTInputs!$J$5:$AZ$5,0)) | R24: =INDEX(MTInputs!$J$1:$AZ$415,$D24,MATCH(R$5,MTInputs!$J$5:$AZ$5,0)) | S24: =INDEX(MTInputs!$J$1:$AZ$415,$D24,MATCH(S$5,MTInputs!$J$5:$AZ$5,0)) | ... Y24: =INDEX(MTInputs!$J$1:$AZ$415,$D24,MATCH(Y$5,MTInputs!$J$5:$AZ$5,0)) | Z24: =LOWER(Settings!$C$4)&".mit."&$A24&IF($C24="","","."&$C24&"."&$B24)&IF(INDEX(Variables!$D$5:$D$65,MATCH($A24,Variables!$A$5:$A$65,0))="","","."&INDEX(Variables!$D$5:$D$65,MATCH($A24,Variables!$A$5:$A$65,0)))&"."&Z$5 | AA24: =INDEX(MTInputs!$J$1:$AZ$415,$D24,MATCH(AA$5,MTInputs!$J$5:$AZ$5,0)) | AB24: =INDEX(MTInputs!$J$1:$AZ$415,$D24,MATCH(AB$5,MTInputs!$J$5:$AZ$5,0)) | AC24: =INDEX(MTInputs!$J$1:$AZ$415,$D24,MATCH(AC$5,MTInputs!$J$5:$AZ$5,0)) | AD24: =INDEX(MTInputs!$J$1:$AZ$415,$D24,MATCH(AD$5,MTInputs!$J$5:$AZ$5,0)) | AE24: =INDEX(MTInputs!$J$1:$AZ$415,$D24,MATCH(AE$5,MTInputs!$J$5:$AZ$5,0)) | AF24: =INDEX(MTInputs!$J$1:$AZ$415,$D24,MATCH(AF$5,MTInputs!$J$5:$AZ$5,0)) | AG24: =INDEX(MTInputs!$J$1:$AZ$415,$D24,MATCH(AG$5,MTInputs!$J$5:$AZ$5,0)) | AH24: =INDEX(MTInputs!$J$1:$AZ$415,$D24,MATCH(AH$5,MTInputs!$J$5:$AZ$5,0)) | ... AN24: =INDEX(MTInputs!$J$1:$AZ$415,$D24,MATCH(AN$5,MTInputs!$J$5:$AZ$5,0))
A25: ctcov | B25: bio | C25: all | H25: =INDEX(Variables!$B$5:$B$65,MATCH($A25,Variables!$A$5:$A$65,0))&IF($C25="",""," | "&INDEX(Mapping!$B$5:$B$25,MATCH($C25,Mapping!$A$5:$A$25,0))&" | "&INDEX(Mapping!$B$29:$B$38,MATCH($B25,Mapping!$A$29:$A$38,0))) | I25: =INDEX(Variables!$C$5:$C$65,MATCH($A25,Variables!$A$5:$A$65,0)) | J25: =INDEX(Variables!$E$5:$E$65,MATCH($A25,Variables!$A$5:$A$65,0)) | K25: =LOWER(Settings!$C$4)&".mit."&$A25&IF($C25="","","."&$C25&"."&$B25)&IF(INDEX(Variables!$D$5:$D$65,MATCH($A25,Variables!$A$5:$A$65,0))="","","."&INDEX(Variables!$D$5:$D$65,MATCH($A25,Variables!$A$5:$A$65,0)))&"."&K$5 | L25: TRUE | M25: TRUE | N25: TRUE | O25: TRUE | P25: TRUE | Q25: TRUE | R25: TRUE | S25: TRUE | T25: TRUE | U25: TRUE | V25: TRUE | W25: TRUE | X25: TRUE | Y25: TRUE | Z25: =LOWER(Settings!$C$4)&".mit."&$A25&IF($C25="","","."&$C25&"."&$B25)&IF(INDEX(Variables!$D$5:$D$65,MATCH($A25,Variables!$A$5:$A$65,0))="","","."&INDEX(Variables!$D$5:$D$65,MATCH($A25,Variables!$A$5:$A$65,0)))&"."&Z$5 | AA25: TRUE | AB25: TRUE | AC25: TRUE | AD25: TRUE | AE25: TRUE | AF25: TRUE | AG25: TRUE | AH25: TRUE | AI25: TRUE | AJ25: TRUE | AK25: TRUE | AL25: TRUE | AM25: TRUE | AN25: TRUE
H26: Carbon tax coverage: sectors (MTInputs rows 31-47)
A27: ctcov | B27: all | C27: pow | D27: 31 | H27: =INDEX(Variables!$B$5:$B$65,MATCH($A27,Variables!$A$5:$A$65,0))&IF($C27="",""," | "&INDEX(Mapping!$B$5:$B$25,MATCH($C27,Mapping!$A$5:$A$25,0))&" | "&INDEX(Mapping!$B$29:$B$38,MATCH($B27,Mapping!$A$29:$A$38,0))) | I27: =INDEX(Variables!$C$5:$C$65,MATCH($A27,Variables!$A$5:$A$65,0)) | J27: =INDEX(Variables!$E$5:$E$65,MATCH($A27,Variables!$A$5:$A$65,0)) | K27: =LOWER(Settings!$C$4)&".mit."&$A27&IF($C27="","","."&$C27&"."&$B27)&IF(INDEX(Variables!$D$5:$D$65,MATCH($A27,Variables!$A$5:$A$65,0))="","","."&INDEX(Variables!$D$5:$D$65,MATCH($A27,Variables!$A$5:$A$65,0)))&"."&K$5 | L27: =INDEX(MTInputs!$J$1:$AZ$415,$D27,MATCH(L$5,MTInputs!$J$5:$AZ$5,0)) | M27: =INDEX(MTInputs!$J$1:$AZ$415,$D27,MATCH(M$5,MTInputs!$J$5:$AZ$5,0)) | N27: =INDEX(MTInputs!$J$1:$AZ$415,$D27,MATCH(N$5,MTInputs!$J$5:$AZ$5,0)) | O27: =INDEX(MTInputs!$J$1:$AZ$415,$D27,MATCH(O$5,MTInputs!$J$5:$AZ$5,0)) | P27: =INDEX(MTInputs!$J$1:$AZ$415,$D27,MATCH(P$5,MTInputs!$J$5:$AZ$5,0)) | Q27: =INDEX(MTInputs!$J$1:$AZ$415,$D27,MATCH(Q$5,MTInputs!$J$5:$AZ$5,0)) | R27: =INDEX(MTInputs!$J$1:$AZ$415,$D27,MATCH(R$5,MTInputs!$J$5:$AZ$5,0)) | S27: =INDEX(MTInputs!$J$1:$AZ$415,$D27,MATCH(S$5,MTInputs!$J$5:$AZ$5,0)) | ... Y27: =INDEX(MTInputs!$J$1:$AZ$415,$D27,MATCH(Y$5,MTInputs!$J$5:$AZ$5,0)) | Z27: =LOWER(Settings!$C$4)&".mit."&$A27&IF($C27="","","."&$C27&"."&$B27)&IF(INDEX(Variables!$D$5:$D$65,MATCH($A27,Variables!$A$5:$A$65,0))="","","."&INDEX(Variables!$D$5:$D$65,MATCH($A27,Variables!$A$5:$A$65,0)))&"."&Z$5 | AA27: =INDEX(MTInputs!$J$1:$AZ$415,$D27,MATCH(AA$5,MTInputs!$J$5:$AZ$5,0)) | AB27: =INDEX(MTInputs!$J$1:$AZ$415,$D27,MATCH(AB$5,MTInputs!$J$5:$AZ$5,0)) | AC27: =INDEX(MTInputs!$J$1:$AZ$415,$D27,MATCH(AC$5,MTInputs!$J$5:$AZ$5,0)) | AD27: =INDEX(MTInputs!$J$1:$AZ$415,$D27,MATCH(AD$5,MTInputs!$J$5:$AZ$5,0)) | AE27: =INDEX(MTInputs!$J$1:$AZ$415,$D27,MATCH(AE$5,MTInputs!$J$5:$AZ$5,0)) | AF27: =INDEX(MTInputs!$J$1:$AZ$415,$D27,MATCH(AF$5,MTInputs!$J$5:$AZ$5,0)) | AG27: =INDEX(MTInputs!$J$1:$AZ$415,$D27,MATCH(AG$5,MTInputs!$J$5:$AZ$5,0)) | AH27: =INDEX(MTInputs!$J$1:$AZ$415,$D27,MATCH(AH$5,MTInputs!$J$5:$AZ$5,0)) | ... AN27: =INDEX(MTInputs!$J$1:$AZ$415,$D27,MATCH(AN$5,MTInputs!$J$5:$AZ$5,0))
A28: ctcov | B28: all | C28: rod | D28: 32 | H28: =INDEX(Variables!$B$5:$B$65,MATCH($A28,Variables!$A$5:$A$65,0))&IF($C28="",""," | "&INDEX(Mapping!$B$5:$B$25,MATCH($C28,Mapping!$A$5:$A$25,0))&" | "&INDEX(Mapping!$B$29:$B$38,MATCH($B28,Mapping!$A$29:$A$38,0))) | I28: =INDEX(Variables!$C$5:$C$65,MATCH($A28,Variables!$A$5:$A$65,0)) | J28: =INDEX(Variables!$E$5:$E$65,MATCH($A28,Variables!$A$5:$A$65,0)) | K28: =LOWER(Settings!$C$4)&".mit."&$A28&IF($C28="","","."&$C28&"."&$B28)&IF(INDEX(Variables!$D$5:$D$65,MATCH($A28,Variables!$A$5:$A$65,0))="","","."&INDEX(Variables!$D$5:$D$65,MATCH($A28,Variables!$A$5:$A$65,0)))&"."&K$5 | L28: =INDEX(MTInputs!$J$1:$AZ$415,$D28,MATCH(L$5,MTInputs!$J$5:$AZ$5,0)) | M28: =INDEX(MTInputs!$J$1:$AZ$415,$D28,MATCH(M$5,MTInputs!$J$5:$AZ$5,0)) | N28: =INDEX(MTInputs!$J$1:$AZ$415,$D28,MATCH(N$5,MTInputs!$J$5:$AZ$5,0)) | O28: =INDEX(MTInputs!$J$1:$AZ$415,$D28,MATCH(O$5,MTInputs!$J$5:$AZ$5,0)) | P28: =INDEX(MTInputs!$J$1:$AZ$415,$D28,MATCH(P$5,MTInputs!$J$5:$AZ$5,0)) | Q28: =INDEX(MTInputs!$J$1:$AZ$415,$D28,MATCH(Q$5,MTInputs!$J$5:$AZ$5,0)) | R28: =INDEX(MTInputs!$J$1:$AZ$415,$D28,MATCH(R$5,MTInputs!$J$5:$AZ$5,0)) | S28: =INDEX(MTInputs!$J$1:$AZ$415,$D28,MATCH(S$5,MTInputs!$J$5:$AZ$5,0)) | ... Y28: =INDEX(MTInputs!$J$1:$AZ$415,$D28,MATCH(Y$5,MTInputs!$J$5:$AZ$5,0)) | Z28: =LOWER(Settings!$C$4)&".mit."&$A28&IF($C28="","","."&$C28&"."&$B28)&IF(INDEX(Variables!$D$5:$D$65,MATCH($A28,Variables!$A$5:$A$65,0))="","","."&INDEX(Variables!$D$5:$D$65,MATCH($A28,Variables!$A$5:$A$65,0)))&"."&Z$5 | AA28: =INDEX(MTInputs!$J$1:$AZ$415,$D28,MATCH(AA$5,MTInputs!$J$5:$AZ$5,0)) | AB28: =INDEX(MTInputs!$J$1:$AZ$415,$D28,MATCH(AB$5,MTInputs!$J$5:$AZ$5,0)) | AC28: =INDEX(MTInputs!$J$1:$AZ$415,$D28,MATCH(AC$5,MTInputs!$J$5:$AZ$5,0)) | AD28: =INDEX(MTInputs!$J$1:$AZ$415,$D28,MATCH(AD$5,MTInputs!$J$5:$AZ$5,0)) | AE28: =INDEX(MTInputs!$J$1:$AZ$415,$D28,MATCH(AE$5,MTInputs!$J$5:$AZ$5,0)) | AF28: =INDEX(MTInputs!$J$1:$AZ$415,$D28,MATCH(AF$5,MTInputs!$J$5:$AZ$5,0)) | AG28: =INDEX(MTInputs!$J$1:$AZ$415,$D28,MATCH(AG$5,MTInputs!$J$5:$AZ$5,0)) | AH28: =INDEX(MTInputs!$J$1:$AZ$415,$D28,MATCH(AH$5,MTInputs!$J$5:$AZ$5,0)) | ... AN28: =INDEX(MTInputs!$J$1:$AZ$415,$D28,MATCH(AN$5,MTInputs!$J$5:$AZ$5,0))
A29: ctcov | B29: all | C29: ral | D29: 33 | H29: =INDEX(Variables!$B$5:$B$65,MATCH($A29,Variables!$A$5:$A$65,0))&IF($C29="",""," | "&INDEX(Mapping!$B$5:$B$25,MATCH($C29,Mapping!$A$5:$A$25,0))&" | "&INDEX(Mapping!$B$29:$B$38,MATCH($B29,Mapping!$A$29:$A$38,0))) | I29: =INDEX(Variables!$C$5:$C$65,MATCH($A29,Variables!$A$5:$A$65,0)) | J29: =INDEX(Variables!$E$5:$E$65,MATCH($A29,Variables!$A$5:$A$65,0)) | K29: =LOWER(Settings!$C$4)&".mit."&$A29&IF($C29="","","."&$C29&"."&$B29)&IF(INDEX(Variables!$D$5:$D$65,MATCH($A29,Variables!$A$5:$A$65,0))="","","."&INDEX(Variables!$D$5:$D$65,MATCH($A29,Variables!$A$5:$A$65,0)))&"."&K$5 | L29: =INDEX(MTInputs!$J$1:$AZ$415,$D29,MATCH(L$5,MTInputs!$J$5:$AZ$5,0)) | M29: =INDEX(MTInputs!$J$1:$AZ$415,$D29,MATCH(M$5,MTInputs!$J$5:$AZ$5,0)) | N29: =INDEX(MTInputs!$J$1:$AZ$415,$D29,MATCH(N$5,MTInputs!$J$5:$AZ$5,0)) | O29: =INDEX(MTInputs!$J$1:$AZ$415,$D29,MATCH(O$5,MTInputs!$J$5:$AZ$5,0)) | P29: =INDEX(MTInputs!$J$1:$AZ$415,$D29,MATCH(P$5,MTInputs!$J$5:$AZ$5,0)) | Q29: =INDEX(MTInputs!$J$1:$AZ$415,$D29,MATCH(Q$5,MTInputs!$J$5:$AZ$5,0)) | R29: =INDEX(MTInputs!$J$1:$AZ$415,$D29,MATCH(R$5,MTInputs!$J$5:$AZ$5,0)) | S29: =INDEX(MTInputs!$J$1:$AZ$415,$D29,MATCH(S$5,MTInputs!$J$5:$AZ$5,0)) | ... Y29: =INDEX(MTInputs!$J$1:$AZ$415,$D29,MATCH(Y$5,MTInputs!$J$5:$AZ$5,0)) | Z29: =LOWER(Settings!$C$4)&".mit."&$A29&IF($C29="","","."&$C29&"."&$B29)&IF(INDEX(Variables!$D$5:$D$65,MATCH($A29,Variables!$A$5:$A$65,0))="","","."&INDEX(Variables!$D$5:$D$65,MATCH($A29,Variables!$A$5:$A$65,0)))&"."&Z$5 | AA29: =INDEX(MTInputs!$J$1:$AZ$415,$D29,MATCH(AA$5,MTInputs!$J$5:$AZ$5,0)) | AB29: =INDEX(MTInputs!$J$1:$AZ$415,$D29,MATCH(AB$5,MTInputs!$J$5:$AZ$5,0)) | AC29: =INDEX(MTInputs!$J$1:$AZ$415,$D29,MATCH(AC$5,MTInputs!$J$5:$AZ$5,0)) | AD29: =INDEX(MTInputs!$J$1:$AZ$415,$D29,MATCH(AD$5,MTInputs!$J$5:$AZ$5,0)) | AE29: =INDEX(MTInputs!$J$1:$AZ$415,$D29,MATCH(AE$5,MTInputs!$J$5:$AZ$5,0)) | AF29: =INDEX(MTInputs!$J$1:$AZ$415,$D29,MATCH(AF$5,MTInputs!$J$5:$AZ$5,0)) | AG29: =INDEX(MTInputs!$J$1:$AZ$415,$D29,MATCH(AG$5,MTInputs!$J$5:$AZ$5,0)) | AH29: =INDEX(MTInputs!$J$1:$AZ$415,$D29,MATCH(AH$5,MTInputs!$J$5:$AZ$5,0)) | ... AN29: =INDEX(MTInputs!$J$1:$AZ$415,$D29,MATCH(AN$5,MTInputs!$J$5:$AZ$5,0))
A30: ctcov | B30: all | C30: avi | D30: 34 | H30: =INDEX(Variables!$B$5:$B$65,MATCH($A30,Variables!$A$5:$A$65,0))&IF($C30="",""," | "&INDEX(Mapping!$B$5:$B$25,MATCH($C30,Mapping!$A$5:$A$25,0))&" | "&INDEX(Mapping!$B$29:$B$38,MATCH($B30,Mapping!$A$29:$A$38,0))) | I30: =INDEX(Variables!$C$5:$C$65,MATCH($A30,Variables!$A$5:$A$65,0)) | J30: =INDEX(Variables!$E$5:$E$65,MATCH($A30,Variables!$A$5:$A$65,0)) | K30: =LOWER(Settings!$C$4)&".mit."&$A30&IF($C30="","","."&$C30&"."&$B30)&IF(INDEX(Variables!$D$5:$D$65,MATCH($A30,Variables!$A$5:$A$65,0))="","","."&INDEX(Variables!$D$5:$D$65,MATCH($A30,Variables!$A$5:$A$65,0)))&"."&K$5 | L30: =INDEX(MTInputs!$J$1:$AZ$415,$D30,MATCH(L$5,MTInputs!$J$5:$AZ$5,0)) | M30: =INDEX(MTInputs!$J$1:$AZ$415,$D30,MATCH(M$5,MTInputs!$J$5:$AZ$5,0)) | N30: =INDEX(MTInputs!$J$1:$AZ$415,$D30,MATCH(N$5,MTInputs!$J$5:$AZ$5,0)) | O30: =INDEX(MTInputs!$J$1:$AZ$415,$D30,MATCH(O$5,MTInputs!$J$5:$AZ$5,0)) | P30: =INDEX(MTInputs!$J$1:$AZ$415,$D30,MATCH(P$5,MTInputs!$J$5:$AZ$5,0)) | Q30: =INDEX(MTInputs!$J$1:$AZ$415,$D30,MATCH(Q$5,MTInputs!$J$5:$AZ$5,0)) | R30: =INDEX(MTInputs!$J$1:$AZ$415,$D30,MATCH(R$5,MTInputs!$J$5:$AZ$5,0)) | S30: =INDEX(MTInputs!$J$1:$AZ$415,$D30,MATCH(S$5,MTInputs!$J$5:$AZ$5,0)) | ... Y30: =INDEX(MTInputs!$J$1:$AZ$415,$D30,MATCH(Y$5,MTInputs!$J$5:$AZ$5,0)) | Z30: =LOWER(Settings!$C$4)&".mit."&$A30&IF($C30="","","."&$C30&"."&$B30)&IF(INDEX(Variables!$D$5:$D$65,MATCH($A30,Variables!$A$5:$A$65,0))="","","."&INDEX(Variables!$D$5:$D$65,MATCH($A30,Variables!$A$5:$A$65,0)))&"."&Z$5 | AA30: =INDEX(MTInputs!$J$1:$AZ$415,$D30,MATCH(AA$5,MTInputs!$J$5:$AZ$5,0)) | AB30: =INDEX(MTInputs!$J$1:$AZ$415,$D30,MATCH(AB$5,MTInputs!$J$5:$AZ$5,0)) | AC30: =INDEX(MTInputs!$J$1:$AZ$415,$D30,MATCH(AC$5,MTInputs!$J$5:$AZ$5,0)) | AD30: =INDEX(MTInputs!$J$1:$AZ$415,$D30,MATCH(AD$5,MTInputs!$J$5:$AZ$5,0)) | AE30: =INDEX(MTInputs!$J$1:$AZ$415,$D30,MATCH(AE$5,MTInputs!$J$5:$AZ$5,0)) | AF30: =INDEX(MTInputs!$J$1:$AZ$415,$D30,MATCH(AF$5,MTInputs!$J$5:$AZ$5,0)) | AG30: =INDEX(MTInputs!$J$1:$AZ$415,$D30,MATCH(AG$5,MTInputs!$J$5:$AZ$5,0)) | AH30: =INDEX(MTInputs!$J$1:$AZ$415,$D30,MATCH(AH$5,MTInputs!$J$5:$AZ$5,0)) | ... AN30: =INDEX(MTInputs!$J$1:$AZ$415,$D30,MATCH(AN$5,MTInputs!$J$5:$AZ$5,0))
A31: ctcov | B31: all | C31: nav | D31: 35 | H31: =INDEX(Variables!$B$5:$B$65,MATCH($A31,Variables!$A$5:$A$65,0))&IF($C31="",""," | "&INDEX(Mapping!$B$5:$B$25,MATCH($C31,Mapping!$A$5:$A$25,0))&" | "&INDEX(Mapping!$B$29:$B$38,MATCH($B31,Mapping!$A$29:$A$38,0))) | I31: =INDEX(Variables!$C$5:$C$65,MATCH($A31,Variables!$A$5:$A$65,0)) | J31: =INDEX(Variables!$E$5:$E$65,MATCH($A31,Variables!$A$5:$A$65,0)) | K31: =LOWER(Settings!$C$4)&".mit."&$A31&IF($C31="","","."&$C31&"."&$B31)&IF(INDEX(Variables!$D$5:$D$65,MATCH($A31,Variables!$A$5:$A$65,0))="","","."&INDEX(Variables!$D$5:$D$65,MATCH($A31,Variables!$A$5:$A$65,0)))&"."&K$5 | L31: =INDEX(MTInputs!$J$1:$AZ$415,$D31,MATCH(L$5,MTInputs!$J$5:$AZ$5,0)) | M31: =INDEX(MTInputs!$J$1:$AZ$415,$D31,MATCH(M$5,MTInputs!$J$5:$AZ$5,0)) | N31: =INDEX(MTInputs!$J$1:$AZ$415,$D31,MATCH(N$5,MTInputs!$J$5:$AZ$5,0)) | O31: =INDEX(MTInputs!$J$1:$AZ$415,$D31,MATCH(O$5,MTInputs!$J$5:$AZ$5,0)) | P31: =INDEX(MTInputs!$J$1:$AZ$415,$D31,MATCH(P$5,MTInputs!$J$5:$AZ$5,0)) | Q31: =INDEX(MTInputs!$J$1:$AZ$415,$D31,MATCH(Q$5,MTInputs!$J$5:$AZ$5,0)) | R31: =INDEX(MTInputs!$J$1:$AZ$415,$D31,MATCH(R$5,MTInputs!$J$5:$AZ$5,0)) | S31: =INDEX(MTInputs!$J$1:$AZ$415,$D31,MATCH(S$5,MTInputs!$J$5:$AZ$5,0)) | ... Y31: =INDEX(MTInputs!$J$1:$AZ$415,$D31,MATCH(Y$5,MTInputs!$J$5:$AZ$5,0)) | Z31: =LOWER(Settings!$C$4)&".mit."&$A31&IF($C31="","","."&$C31&"."&$B31)&IF(INDEX(Variables!$D$5:$D$65,MATCH($A31,Variables!$A$5:$A$65,0))="","","."&INDEX(Variables!$D$5:$D$65,MATCH($A31,Variables!$A$5:$A$65,0)))&"."&Z$5 | AA31: =INDEX(MTInputs!$J$1:$AZ$415,$D31,MATCH(AA$5,MTInputs!$J$5:$AZ$5,0)) | AB31: =INDEX(MTInputs!$J$1:$AZ$415,$D31,MATCH(AB$5,MTInputs!$J$5:$AZ$5,0)) | AC31: =INDEX(MTInputs!$J$1:$AZ$415,$D31,MATCH(AC$5,MTInputs!$J$5:$AZ$5,0)) | AD31: =INDEX(MTInputs!$J$1:$AZ$415,$D31,MATCH(AD$5,MTInputs!$J$5:$AZ$5,0)) | AE31: =INDEX(MTInputs!$J$1:$AZ$415,$D31,MATCH(AE$5,MTInputs!$J$5:$AZ$5,0)) | AF31: =INDEX(MTInputs!$J$1:$AZ$415,$D31,MATCH(AF$5,MTInputs!$J$5:$AZ$5,0)) | AG31: =INDEX(MTInputs!$J$1:$AZ$415,$D31,MATCH(AG$5,MTInputs!$J$5:$AZ$5,0)) | AH31: =INDEX(MTInputs!$J$1:$AZ$415,$D31,MATCH(AH$5,MTInputs!$J$5:$AZ$5,0)) | ... AN31: =INDEX(MTInputs!$J$1:$AZ$415,$D31,MATCH(AN$5,MTInputs!$J$5:$AZ$5,0))
A32: ctcov | B32: all | C32: res | D32: 36 | H32: =INDEX(Variables!$B$5:$B$65,MATCH($A32,Variables!$A$5:$A$65,0))&IF($C32="",""," | "&INDEX(Mapping!$B$5:$B$25,MATCH($C32,Mapping!$A$5:$A$25,0))&" | "&INDEX(Mapping!$B$29:$B$38,MATCH($B32,Mapping!$A$29:$A$38,0))) | I32: =INDEX(Variables!$C$5:$C$65,MATCH($A32,Variables!$A$5:$A$65,0)) | J32: =INDEX(Variables!$E$5:$E$65,MATCH($A32,Variables!$A$5:$A$65,0)) | K32: =LOWER(Settings!$C$4)&".mit."&$A32&IF($C32="","","."&$C32&"."&$B32)&IF(INDEX(Variables!$D$5:$D$65,MATCH($A32,Variables!$A$5:$A$65,0))="","","."&INDEX(Variables!$D$5:$D$65,MATCH($A32,Variables!$A$5:$A$65,0)))&"."&K$5 | L32: =INDEX(MTInputs!$J$1:$AZ$415,$D32,MATCH(L$5,MTInputs!$J$5:$AZ$5,0)) | M32: =INDEX(MTInputs!$J$1:$AZ$415,$D32,MATCH(M$5,MTInputs!$J$5:$AZ$5,0)) | N32: =INDEX(MTInputs!$J$1:$AZ$415,$D32,MATCH(N$5,MTInputs!$J$5:$AZ$5,0)) | O32: =INDEX(MTInputs!$J$1:$AZ$415,$D32,MATCH(O$5,MTInputs!$J$5:$AZ$5,0)) | P32: =INDEX(MTInputs!$J$1:$AZ$415,$D32,MATCH(P$5,MTInputs!$J$5:$AZ$5,0)) | Q32: =INDEX(MTInputs!$J$1:$AZ$415,$D32,MATCH(Q$5,MTInputs!$J$5:$AZ$5,0)) | R32: =INDEX(MTInputs!$J$1:$AZ$415,$D32,MATCH(R$5,MTInputs!$J$5:$AZ$5,0)) | S32: =INDEX(MTInputs!$J$1:$AZ$415,$D32,MATCH(S$5,MTInputs!$J$5:$AZ$5,0)) | ... Y32: =INDEX(MTInputs!$J$1:$AZ$415,$D32,MATCH(Y$5,MTInputs!$J$5:$AZ$5,0)) | Z32: =LOWER(Settings!$C$4)&".mit."&$A32&IF($C32="","","."&$C32&"."&$B32)&IF(INDEX(Variables!$D$5:$D$65,MATCH($A32,Variables!$A$5:$A$65,0))="","","."&INDEX(Variables!$D$5:$D$65,MATCH($A32,Variables!$A$5:$A$65,0)))&"."&Z$5 | AA32: =INDEX(MTInputs!$J$1:$AZ$415,$D32,MATCH(AA$5,MTInputs!$J$5:$AZ$5,0)) | AB32: =INDEX(MTInputs!$J$1:$AZ$415,$D32,MATCH(AB$5,MTInputs!$J$5:$AZ$5,0)) | AC32: =INDEX(MTInputs!$J$1:$AZ$415,$D32,MATCH(AC$5,MTInputs!$J$5:$AZ$5,0)) | AD32: =INDEX(MTInputs!$J$1:$AZ$415,$D32,MATCH(AD$5,MTInputs!$J$5:$AZ$5,0)) | AE32: =INDEX(MTInputs!$J$1:$AZ$415,$D32,MATCH(AE$5,MTInputs!$J$5:$AZ$5,0)) | AF32: =INDEX(MTInputs!$J$1:$AZ$415,$D32,MATCH(AF$5,MTInputs!$J$5:$AZ$5,0)) | AG32: =INDEX(MTInputs!$J$1:$AZ$415,$D32,MATCH(AG$5,MTInputs!$J$5:$AZ$5,0)) | AH32: =INDEX(MTInputs!$J$1:$AZ$415,$D32,MATCH(AH$5,MTInputs!$J$5:$AZ$5,0)) | ... AN32: =INDEX(MTInputs!$J$1:$AZ$415,$D32,MATCH(AN$5,MTInputs!$J$5:$AZ$5,0))
