Workbook
Name PRETAX: _xlfn.LAMBDA(_xlpm.prev,_xlpm.growth,_xlpm.prev*(1+_xlpm.growth))
Name TAX: _xlfn.LAMBDA(_xlpm.base_tax,_xlpm.cp,_xlpm.ef,_xlpm.cov,_xlpm.base_tax+_xlpm.cp*_xlpm.ef*_xlpm.cov)
Name POSTTAX: _xlfn.LAMBDA(_xlpm.pre_tax_p,_xlpm.tax_p,_xlpm.pre_tax_p+_xlpm.tax_p)

Sheet ReadMe
A2: CPAT mitigation module - copy-pasteable prototype v0.6
A4: Purpose | B4: Auditable, copy-pasteable replacement of the CPAT mitigation price -> fuel-use chain. Each block has one formula across all its cells, and a whole scenario group copies to a new scenario and keeps working.
A5: Status | B5: v0.6 prototype. Price -> fuel use only (no emissions, power or revenue yet).
A6: Layout (design 2) | B6: Columns A:C variable code, fuel, subsector; D:G parameters (hidden by default - click + above column H to show); H:J description, unit, source (looked up from Variables); then one group per scenario: output-code column, base year 2022 (column L for scenario 1, as in legacy Mitigation), 2023-2035.
A7: Nesting | B7: Across: scenario (outer) > year (inner). Down: variable block (outer) > subsector > fuel (inner). 16 CPAT energy-use subsectors x 8 fuels = 128 rows per block.
A8: Blocks | B8: Pre-tax price sp (row 16), Tax (row 147), After-tax price atp (row 278), Fuel use ener (row 409), Totals (row 540).
A9: Roll-up | B9: Each block rolls up under the white summary line below its green band: click + / - at the left of that line, or the 1 / 2 outline buttons (top left) to collapse / expand all. Blocks open collapsed, totals expanded. Copying a scenario group or dragging across includes the collapsed rows.
A10: Summary lines | B10: Fuel use: total fuel use (all subsectors and fuels). Tax: the policy carbon price (repeats the scenario assumption). Prices: no total (prices are not added up).
A11: Codes | B11: Each scenario group starts with a code column: country.mit.<variable>.<subsector>.<fuel>.<suffix>.<scenario>, e.g. egy.mit.ener.rod.gso.e.1 as in legacy CPAT. The scenario number sits at the top of the code column (row 5); scenario 1 is typed, every later group = previous group + 1, so a pasted group numbers itself. Labels, units, suffixes and sources come from sheet Variables by the variable code in column A.
A12: Data step vs formulas | B12: All lookups happen in sheet Inputs (one row per fuel|subsector) and in Mitigation D:G and the base-year column, each a single INDEX/MATCH on the fuel|subsector key. Calculation cells contain no lookups.
A13: Equations | B13: Pre-tax: p(t) = p(t-1) x (1 + growth). Tax: base tax + carbon price x EF x coverage (base tax = retail - supply cost, so it includes existing excise, subsidies and VAT). After-tax = pre-tax + tax. Fuel use: F(t) = F(t-1) x (1/(1+alpha))^(1+eps_U) x (1+g)^eps_Y x (p(t)/p(t-1))^eps_U x (p(t)/p(t-1))^(eps_F(1+eps_U)) (CPAT documentation 3.3.3, without the Covid factor and shadow price).
A14: LAMBDA column | B14: 2035 (orange, dark-red text) calls named LAMBDAs with the same equations; 2023-2034 are plain formulas. Drag the 2035 cell back over the row to use the LAMBDA everywhere, or drag 2034 forward to remove it. Names (Formulas > Name Manager): PRETAX(prev, growth) = prev*(1+growth); TAX(base_tax, cp, ef, cov) = base_tax+cp*ef*cov; POSTTAX(pre_tax_p, tax_p) = pre_tax_p+tax_p; FUELUSE(f_prev, p_now, p_prev, gdp_g, eps_y, eps_u, eps_f, alpha) = f_prev*(1/(1+alpha))^(1+eps_u)*(1+gdp_g)^eps_y*(p_now/p_prev)^eps_u*(p_now/p_prev)^(eps_f*(1+eps_u)).
A15: Parameters | B15: Global, not scenario-specific: scenarios differ only in their assumption rows (row 14 carbon price). Pre-tax price growth is an input in Inputs (0 % now).
... A22: Checks | B22: Row 567 (totals by subsector and by fuel minus total fuel use) should be 0. check_v0_6.py tests formula uniformity (values, labels, codes), the LAMBDA encoding and equivalence, the scenario-copy behaviour (including auto-numbering), an independent recomputation and the regression against the previous version.

Sheet Settings
A2: Settings
B4: Country code | C4: EGY
B5: Country name | C5: =INDEX(Countries!$B$4:$B$1000,MATCH($C$4,Countries!$A$4:$A$1000,0))
B6: Income group (selects elasticities) | C6: =INDEX(Countries!$D$4:$D$1000,MATCH($C$4,Countries!$A$4:$A$1000,0))
B7: Base year | C7: 2022
B10: Version log
B11: Version | C11: Date | D11: Description | E11: Max abs regression diff
B12: 0.1 | C12: 2026-10-08 | D12: First build: design 2 price -> fuel-use prototype, Egypt base data, 2 scenarios. | E12: n/a (first version)
B13: 0.2 | C13: 2026-10-08 | D13: Inputs sheet by fuel|subsector (lookups separated from formulas); 4 hidden parameter columns D:G, global parameters; base year 2022 in column L; named LAMBDAs in 2035. | E13: 0 (all Mitigation results vs v0.1)
B14: 0.3 | C14: 2026-10-08 | D14: Variable codes in column A; description, unit and source looked up from Variables; a code column before each scenario group generates the full CPAT code with country and scenario number (auto-numbered). | E14: 0 (all Mitigation results vs v0.2)
B15: 0.4 | C15: 2026-10-08 | D15: Row outline: each block rolls up under its band row (+/- on the band; blocks collapsed by default, totals open). | E15: 0 (all Mitigation results vs v0.3)
B16: 0.5 | C16: 2026-10-08 | D16: White text in the green bands; white summary line under each band (total fuel use, policy carbon price), visible when rolled up; totals-section grand total replaced by the fuel-use summary line. | E16: 0 (all Mitigation results vs v0.4)
B17: 0.6 | C17: 2026-10-08 | D17: MTInputs sheet (legacy rows, one Used-for-calculation column per scenario); carbon price computed from the MTInputs carbon-tax parameters by scenario number. | E17: 0 (all Mitigation results vs v0.5)

Sheet MTInputs
B1: MTInputs template - row structure copied exactly from legacy CPAT MTInputs
B2: Do not insert/delete rows. Columns D:E are hidden placeholders (MT values, Dashboard values).
B3: Rows must match legacy exactly. Green (EBF1DE) = used by module; grey (F2F2F2) = unused. See NORMS.md section 4. | J3: Scenario columns (Used for calculation): number in row 5, name in row 6. Red = changed from the template value. Copy the last column one to the right to add a scenario.
C5: FALSE | D5: <-- Should normally be "FALSE"! | J5: 1 | K5: =J5+1
D6: 6 | J6: Baseline (no carbon price) | K6: Carbon price $20/tCO2 from 2027
B7: Parameters | C7: unit | D7: MT values | E7: "Dashboard" values | F7: Used for calculation | G7: Defaults | H7: NameOfParameter | J7: Used for calculation | K7: Used for calculation
B8: Country | F8: Egypt | G8: Egypt | H8: Countryname | J8: Egypt | K8: Egypt
B9: Scenario identification
B10: Scenario ID | C10: # | F10: N/A | G10: N/A | H10: MSTScenarioID | J10: =J$5 | K10: =K$5
B11: Scenario status | C11: switch | F11: N/A | G11: N/A | J11: N/A | K11: N/A
B12: Scenario name | C12: name | F12: N/A | G12: N/A | J12: =J$6 | K12: =K$6
B13: Chosen policy | C13: switch | F13: - Carbon tax | G13: - Carbon tax | H13: ScenarioSelected | J13: - Carbon tax | K13: - Carbon tax
B14: Scenario status for macro | C14: # | F14: N/A | G14: N/A | J14: N/A | K14: N/A
B15: Scenario parameters override? | C15: # | F15: N/A | G15: N/A | J15: N/A | K15: N/A
B16: CPAT-side parameters override? | C16: switch | F16: Manual* | G16: Manual* | H16: CPATDefaultsOrUserDefined | J16: Manual* | K16: Manual*
B17: Carbon pricing: main inputs
A18: X | B18: Carbon pricing start year | C18: year | F18: 2026 | G18: 2027 | H18: CPIntro | J18: 2027 | K18: 2027
A19: X | B19: Starting carbon price | C19: nom. USD/tCO2 | F19: 0 | G19: 20 | H19: CPLevelStart | J19: 0 | K19: 20
B20: Target level of carbon price | C20: nom. USD/tCO2 | F20: 50 | G20: 50 | H20: CPLevelTarget | J20: 0 | K20: 20
A21: X | B21: Year to reach target level | C21: year | F21: 2030 | G21: 2035 | H21: CPOutro | J21: 2030 | K21: 2030
B22: Carbon pricing: fuel coverage
B23: Apply tax to coal? | C23: switch | F23: TRUE | G23: TRUE | H23: MCovCoa | J23: TRUE | K23: TRUE
B24: Apply tax to natural gas? | C24: switch | F24: TRUE | G24: TRUE | H24: MCovNga | J24: TRUE | K24: TRUE
B25: Apply tax to gasoline? | C25: switch | F25: TRUE | G25: TRUE | H25: MCovGso | J25: TRUE | K25: TRUE
B26: Apply tax to diesel? | C26: switch | F26: TRUE | G26: TRUE | H26: MCovDie | J26: TRUE | K26: TRUE
B27: Apply tax to LPG? | C27: switch | F27: TRUE | G27: TRUE | H27: MCovLpg | J27: TRUE | K27: TRUE
B28: Apply tax to kerosene? | C28: switch | F28: TRUE | G28: TRUE | H28: MCovKer | J28: TRUE | K28: TRUE
B29: Apply tax to non-road oil products? | C29: switch | F29: TRUE | G29: TRUE | H29: MCovOop | J29: TRUE | K29: TRUE
B30: Carbon pricing: sector coverage
B31: Apply tax to power sector? | C31: switch | F31: TRUE | G31: TRUE | H31: MCovPow | J31: TRUE | K31: TRUE
B32: Apply tax to road transportation? | C32: switch | F32: TRUE | G32: TRUE | H32: MCovRod | J32: TRUE | K32: TRUE
B33: Apply tax to rail transportation? | C33: switch | F33: TRUE | G33: TRUE | H33: MCovRal | J33: TRUE | K33: TRUE
B34: Apply tax to domestic aviation? | C34: switch | F34: TRUE | G34: TRUE | H34: MCovAvi | J34: TRUE | K34: TRUE
B35: Apply tax to domestic shipping? | C35: switch | F35: TRUE | G35: TRUE | H35: MCovNav | J35: TRUE | K35: TRUE
B36: Apply tax to residential sector? | C36: switch | F36: TRUE | G36: TRUE | H36: MCovRes | J36: TRUE | K36: TRUE
B37: Apply tax to food & forestry? | C37: switch | F37: TRUE | G37: TRUE | H37: MCovFoo | J37: TRUE | K37: TRUE
B38: Apply tax to services (private / public)? | C38: switch | F38: TRUE | G38: TRUE | H38: MCovSrv | J38: TRUE | K38: TRUE
B39: Apply tax to mining & chemicals? | C39: switch | F39: TRUE | G39: TRUE | H39: MCovMch | J39: TRUE | K39: TRUE
B40: Apply tax to iron and steel? | C40: switch | F40: TRUE | G40: TRUE | H40: MCovIrn | J40: TRUE | K40: TRUE
B41: Apply tax to non-ferrous metals? | C41: switch | F41: TRUE | G41: TRUE | H41: MCovNfm | J41: TRUE | K41: TRUE
...

Sheet Mitigation
A1: Variable | B1: Fuel | C1: Sector | D1: Param 1 | E1: Param 2 | F1: Param 3 | G1: Param 4 | H1: Description | I1: Unit | J1: Source | K1: Scenario 1: output code | Z1: Scenario 2: output code
A2: Mitigation module - price to fuel use (copy-pasteable, design 2)
A3: Scenario assumptions (one column group per scenario: code column + years; copy a whole group to add a scenario)
H4: Year | L4: =Settings!$C$7 | M4: =L4+1 | N4: =M4+1 | O4: =N4+1 | P4: =O4+1 | Q4: =P4+1 | R4: =Q4+1 | S4: =R4+1 | T4: =S4+1 | ... Y4: =X4+1 | AA4: =Settings!$C$7 | AB4: =AA4+1 | AC4: =AB4+1 | AD4: =AC4+1 | AE4: =AD4+1 | AF4: =AE4+1 | AG4: =AF4+1 | AH4: =AG4+1 | AI4: =AH4+1 | ... AN4: =AM4+1
H5: Scenario number (MTInputs column) | K5: 1 | L5: =K5 | M5: =L5 | N5: =M5 | O5: =N5 | P5: =O5 | Q5: =P5 | R5: =Q5 | S5: =R5 | ... Y5: =X5 | Z5: =K5+1 | AA5: =Z5 | AB5: =AA5 | AC5: =AB5 | AD5: =AC5 | AE5: =AD5 | AF5: =AE5 | AG5: =AF5 | AH5: =AG5 | ... AN5: =AM5
H6: Scenario name (from MTInputs) | L6: =INDEX(MTInputs!$J$6:$AZ$6,MATCH(L$5,MTInputs!$J$5:$AZ$5,0)) | AA6: =INDEX(MTInputs!$J$6:$AZ$6,MATCH(AA$5,MTInputs!$J$5:$AZ$5,0))
A7: gdp.pos.pct | H7: =INDEX(Variables!$B$5:$B$45,MATCH($A7,Variables!$A$5:$A$45,0))&IF($C7="",""," | "&INDEX(Mapping!$B$5:$B$21,MATCH($C7,Mapping!$A$5:$A$21,0))&" | "&INDEX(Mapping!$B$24:$B$32,MATCH($B7,Mapping!$A$24:$A$32,0))) | I7: =INDEX(Variables!$C$5:$C$45,MATCH($A7,Variables!$A$5:$A$45,0)) | J7: =INDEX(Variables!$E$5:$E$45,MATCH($A7,Variables!$A$5:$A$45,0)) | K7: =LOWER(Settings!$C$4)&".mit."&$A7&IF($C7="","","."&$C7&"."&$B7)&IF(INDEX(Variables!$D$5:$D$45,MATCH($A7,Variables!$A$5:$A$45,0))="","","."&INDEX(Variables!$D$5:$D$45,MATCH($A7,Variables!$A$5:$A$45,0)))&"."&K$5 | L7: =INDEX(WEO!$F$4:$AZ$1000,MATCH(Settings!$C$4&"|gdp_growth",WEO!$A$4:$A$1000,0),MATCH(L$4,WEO!$F$3:$AZ$3,0)) | M7: =INDEX(WEO!$F$4:$AZ$1000,MATCH(Settings!$C$4&"|gdp_growth",WEO!$A$4:$A$1000,0),MATCH(M$4,WEO!$F$3:$AZ$3,0)) | N7: =INDEX(WEO!$F$4:$AZ$1000,MATCH(Settings!$C$4&"|gdp_growth",WEO!$A$4:$A$1000,0),MATCH(N$4,WEO!$F$3:$AZ$3,0)) | O7: =INDEX(WEO!$F$4:$AZ$1000,MATCH(Settings!$C$4&"|gdp_growth",WEO!$A$4:$A$1000,0),MATCH(O$4,WEO!$F$3:$AZ$3,0)) | P7: =INDEX(WEO!$F$4:$AZ$1000,MATCH(Settings!$C$4&"|gdp_growth",WEO!$A$4:$A$1000,0),MATCH(P$4,WEO!$F$3:$AZ$3,0)) | Q7: =INDEX(WEO!$F$4:$AZ$1000,MATCH(Settings!$C$4&"|gdp_growth",WEO!$A$4:$A$1000,0),MATCH(Q$4,WEO!$F$3:$AZ$3,0)) | R7: =INDEX(WEO!$F$4:$AZ$1000,MATCH(Settings!$C$4&"|gdp_growth",WEO!$A$4:$A$1000,0),MATCH(R$4,WEO!$F$3:$AZ$3,0)) | S7: =INDEX(WEO!$F$4:$AZ$1000,MATCH(Settings!$C$4&"|gdp_growth",WEO!$A$4:$A$1000,0),MATCH(S$4,WEO!$F$3:$AZ$3,0)) | ... Y7: =INDEX(WEO!$F$4:$AZ$1000,MATCH(Settings!$C$4&"|gdp_growth",WEO!$A$4:$A$1000,0),MATCH(Y$4,WEO!$F$3:$AZ$3,0)) | Z7: =LOWER(Settings!$C$4)&".mit."&$A7&IF($C7="","","."&$C7&"."&$B7)&IF(INDEX(Variables!$D$5:$D$45,MATCH($A7,Variables!$A$5:$A$45,0))="","","."&INDEX(Variables!$D$5:$D$45,MATCH($A7,Variables!$A$5:$A$45,0)))&"."&Z$5 | AA7: =INDEX(WEO!$F$4:$AZ$1000,MATCH(Settings!$C$4&"|gdp_growth",WEO!$A$4:$A$1000,0),MATCH(AA$4,WEO!$F$3:$AZ$3,0)) | AB7: =INDEX(WEO!$F$4:$AZ$1000,MATCH(Settings!$C$4&"|gdp_growth",WEO!$A$4:$A$1000,0),MATCH(AB$4,WEO!$F$3:$AZ$3,0)) | AC7: =INDEX(WEO!$F$4:$AZ$1000,MATCH(Settings!$C$4&"|gdp_growth",WEO!$A$4:$A$1000,0),MATCH(AC$4,WEO!$F$3:$AZ$3,0)) | AD7: =INDEX(WEO!$F$4:$AZ$1000,MATCH(Settings!$C$4&"|gdp_growth",WEO!$A$4:$A$1000,0),MATCH(AD$4,WEO!$F$3:$AZ$3,0)) | AE7: =INDEX(WEO!$F$4:$AZ$1000,MATCH(Settings!$C$4&"|gdp_growth",WEO!$A$4:$A$1000,0),MATCH(AE$4,WEO!$F$3:$AZ$3,0)) | AF7: =INDEX(WEO!$F$4:$AZ$1000,MATCH(Settings!$C$4&"|gdp_growth",WEO!$A$4:$A$1000,0),MATCH(AF$4,WEO!$F$3:$AZ$3,0)) | AG7: =INDEX(WEO!$F$4:$AZ$1000,MATCH(Settings!$C$4&"|gdp_growth",WEO!$A$4:$A$1000,0),MATCH(AG$4,WEO!$F$3:$AZ$3,0)) | AH7: =INDEX(WEO!$F$4:$AZ$1000,MATCH(Settings!$C$4&"|gdp_growth",WEO!$A$4:$A$1000,0),MATCH(AH$4,WEO!$F$3:$AZ$3,0)) | ... AN7: =INDEX(WEO!$F$4:$AZ$1000,MATCH(Settings!$C$4&"|gdp_growth",WEO!$A$4:$A$1000,0),MATCH(AN$4,WEO!$F$3:$AZ$3,0))
A8: Policies - carbon tax (inputs looked up from MTInputs by scenario number)
A9: CPIntro | H9: =INDEX(Variables!$B$5:$B$45,MATCH($A9,Variables!$A$5:$A$45,0))&IF($C9="",""," | "&INDEX(Mapping!$B$5:$B$21,MATCH($C9,Mapping!$A$5:$A$21,0))&" | "&INDEX(Mapping!$B$24:$B$32,MATCH($B9,Mapping!$A$24:$A$32,0))) | I9: =INDEX(Variables!$C$5:$C$45,MATCH($A9,Variables!$A$5:$A$45,0)) | J9: =INDEX(Variables!$E$5:$E$45,MATCH($A9,Variables!$A$5:$A$45,0)) | K9: =LOWER(Settings!$C$4)&".mit."&$A9&IF($C9="","","."&$C9&"."&$B9)&IF(INDEX(Variables!$D$5:$D$45,MATCH($A9,Variables!$A$5:$A$45,0))="","","."&INDEX(Variables!$D$5:$D$45,MATCH($A9,Variables!$A$5:$A$45,0)))&"."&K$5 | L9: =INDEX(MTInputs!$J$8:$AZ$415,MATCH($A9,MTInputs!$H$8:$H$415,0),MATCH(L$5,MTInputs!$J$5:$AZ$5,0)) | M9: =INDEX(MTInputs!$J$8:$AZ$415,MATCH($A9,MTInputs!$H$8:$H$415,0),MATCH(M$5,MTInputs!$J$5:$AZ$5,0)) | N9: =INDEX(MTInputs!$J$8:$AZ$415,MATCH($A9,MTInputs!$H$8:$H$415,0),MATCH(N$5,MTInputs!$J$5:$AZ$5,0)) | O9: =INDEX(MTInputs!$J$8:$AZ$415,MATCH($A9,MTInputs!$H$8:$H$415,0),MATCH(O$5,MTInputs!$J$5:$AZ$5,0)) | P9: =INDEX(MTInputs!$J$8:$AZ$415,MATCH($A9,MTInputs!$H$8:$H$415,0),MATCH(P$5,MTInputs!$J$5:$AZ$5,0)) | Q9: =INDEX(MTInputs!$J$8:$AZ$415,MATCH($A9,MTInputs!$H$8:$H$415,0),MATCH(Q$5,MTInputs!$J$5:$AZ$5,0)) | R9: =INDEX(MTInputs!$J$8:$AZ$415,MATCH($A9,MTInputs!$H$8:$H$415,0),MATCH(R$5,MTInputs!$J$5:$AZ$5,0)) | S9: =INDEX(MTInputs!$J$8:$AZ$415,MATCH($A9,MTInputs!$H$8:$H$415,0),MATCH(S$5,MTInputs!$J$5:$AZ$5,0)) | ... Y9: =INDEX(MTInputs!$J$8:$AZ$415,MATCH($A9,MTInputs!$H$8:$H$415,0),MATCH(Y$5,MTInputs!$J$5:$AZ$5,0)) | Z9: =LOWER(Settings!$C$4)&".mit."&$A9&IF($C9="","","."&$C9&"."&$B9)&IF(INDEX(Variables!$D$5:$D$45,MATCH($A9,Variables!$A$5:$A$45,0))="","","."&INDEX(Variables!$D$5:$D$45,MATCH($A9,Variables!$A$5:$A$45,0)))&"."&Z$5 | AA9: =INDEX(MTInputs!$J$8:$AZ$415,MATCH($A9,MTInputs!$H$8:$H$415,0),MATCH(AA$5,MTInputs!$J$5:$AZ$5,0)) | AB9: =INDEX(MTInputs!$J$8:$AZ$415,MATCH($A9,MTInputs!$H$8:$H$415,0),MATCH(AB$5,MTInputs!$J$5:$AZ$5,0)) | AC9: =INDEX(MTInputs!$J$8:$AZ$415,MATCH($A9,MTInputs!$H$8:$H$415,0),MATCH(AC$5,MTInputs!$J$5:$AZ$5,0)) | AD9: =INDEX(MTInputs!$J$8:$AZ$415,MATCH($A9,MTInputs!$H$8:$H$415,0),MATCH(AD$5,MTInputs!$J$5:$AZ$5,0)) | AE9: =INDEX(MTInputs!$J$8:$AZ$415,MATCH($A9,MTInputs!$H$8:$H$415,0),MATCH(AE$5,MTInputs!$J$5:$AZ$5,0)) | AF9: =INDEX(MTInputs!$J$8:$AZ$415,MATCH($A9,MTInputs!$H$8:$H$415,0),MATCH(AF$5,MTInputs!$J$5:$AZ$5,0)) | AG9: =INDEX(MTInputs!$J$8:$AZ$415,MATCH($A9,MTInputs!$H$8:$H$415,0),MATCH(AG$5,MTInputs!$J$5:$AZ$5,0)) | AH9: =INDEX(MTInputs!$J$8:$AZ$415,MATCH($A9,MTInputs!$H$8:$H$415,0),MATCH(AH$5,MTInputs!$J$5:$AZ$5,0)) | ... AN9: =INDEX(MTInputs!$J$8:$AZ$415,MATCH($A9,MTInputs!$H$8:$H$415,0),MATCH(AN$5,MTInputs!$J$5:$AZ$5,0))
A10: CPLevelStart | H10: =INDEX(Variables!$B$5:$B$45,MATCH($A10,Variables!$A$5:$A$45,0))&IF($C10="",""," | "&INDEX(Mapping!$B$5:$B$21,MATCH($C10,Mapping!$A$5:$A$21,0))&" | "&INDEX(Mapping!$B$24:$B$32,MATCH($B10,Mapping!$A$24:$A$32,0))) | I10: =INDEX(Variables!$C$5:$C$45,MATCH($A10,Variables!$A$5:$A$45,0)) | J10: =INDEX(Variables!$E$5:$E$45,MATCH($A10,Variables!$A$5:$A$45,0)) | K10: =LOWER(Settings!$C$4)&".mit."&$A10&IF($C10="","","."&$C10&"."&$B10)&IF(INDEX(Variables!$D$5:$D$45,MATCH($A10,Variables!$A$5:$A$45,0))="","","."&INDEX(Variables!$D$5:$D$45,MATCH($A10,Variables!$A$5:$A$45,0)))&"."&K$5 | L10: =INDEX(MTInputs!$J$8:$AZ$415,MATCH($A10,MTInputs!$H$8:$H$415,0),MATCH(L$5,MTInputs!$J$5:$AZ$5,0)) | M10: =INDEX(MTInputs!$J$8:$AZ$415,MATCH($A10,MTInputs!$H$8:$H$415,0),MATCH(M$5,MTInputs!$J$5:$AZ$5,0)) | N10: =INDEX(MTInputs!$J$8:$AZ$415,MATCH($A10,MTInputs!$H$8:$H$415,0),MATCH(N$5,MTInputs!$J$5:$AZ$5,0)) | O10: =INDEX(MTInputs!$J$8:$AZ$415,MATCH($A10,MTInputs!$H$8:$H$415,0),MATCH(O$5,MTInputs!$J$5:$AZ$5,0)) | P10: =INDEX(MTInputs!$J$8:$AZ$415,MATCH($A10,MTInputs!$H$8:$H$415,0),MATCH(P$5,MTInputs!$J$5:$AZ$5,0)) | Q10: =INDEX(MTInputs!$J$8:$AZ$415,MATCH($A10,MTInputs!$H$8:$H$415,0),MATCH(Q$5,MTInputs!$J$5:$AZ$5,0)) | R10: =INDEX(MTInputs!$J$8:$AZ$415,MATCH($A10,MTInputs!$H$8:$H$415,0),MATCH(R$5,MTInputs!$J$5:$AZ$5,0)) | S10: =INDEX(MTInputs!$J$8:$AZ$415,MATCH($A10,MTInputs!$H$8:$H$415,0),MATCH(S$5,MTInputs!$J$5:$AZ$5,0)) | ... Y10: =INDEX(MTInputs!$J$8:$AZ$415,MATCH($A10,MTInputs!$H$8:$H$415,0),MATCH(Y$5,MTInputs!$J$5:$AZ$5,0)) | Z10: =LOWER(Settings!$C$4)&".mit."&$A10&IF($C10="","","."&$C10&"."&$B10)&IF(INDEX(Variables!$D$5:$D$45,MATCH($A10,Variables!$A$5:$A$45,0))="","","."&INDEX(Variables!$D$5:$D$45,MATCH($A10,Variables!$A$5:$A$45,0)))&"."&Z$5 | AA10: =INDEX(MTInputs!$J$8:$AZ$415,MATCH($A10,MTInputs!$H$8:$H$415,0),MATCH(AA$5,MTInputs!$J$5:$AZ$5,0)) | AB10: =INDEX(MTInputs!$J$8:$AZ$415,MATCH($A10,MTInputs!$H$8:$H$415,0),MATCH(AB$5,MTInputs!$J$5:$AZ$5,0)) | AC10: =INDEX(MTInputs!$J$8:$AZ$415,MATCH($A10,MTInputs!$H$8:$H$415,0),MATCH(AC$5,MTInputs!$J$5:$AZ$5,0)) | AD10: =INDEX(MTInputs!$J$8:$AZ$415,MATCH($A10,MTInputs!$H$8:$H$415,0),MATCH(AD$5,MTInputs!$J$5:$AZ$5,0)) | AE10: =INDEX(MTInputs!$J$8:$AZ$415,MATCH($A10,MTInputs!$H$8:$H$415,0),MATCH(AE$5,MTInputs!$J$5:$AZ$5,0)) | AF10: =INDEX(MTInputs!$J$8:$AZ$415,MATCH($A10,MTInputs!$H$8:$H$415,0),MATCH(AF$5,MTInputs!$J$5:$AZ$5,0)) | AG10: =INDEX(MTInputs!$J$8:$AZ$415,MATCH($A10,MTInputs!$H$8:$H$415,0),MATCH(AG$5,MTInputs!$J$5:$AZ$5,0)) | AH10: =INDEX(MTInputs!$J$8:$AZ$415,MATCH($A10,MTInputs!$H$8:$H$415,0),MATCH(AH$5,MTInputs!$J$5:$AZ$5,0)) | ... AN10: =INDEX(MTInputs!$J$8:$AZ$415,MATCH($A10,MTInputs!$H$8:$H$415,0),MATCH(AN$5,MTInputs!$J$5:$AZ$5,0))
A11: CPLevelTarget | H11: =INDEX(Variables!$B$5:$B$45,MATCH($A11,Variables!$A$5:$A$45,0))&IF($C11="",""," | "&INDEX(Mapping!$B$5:$B$21,MATCH($C11,Mapping!$A$5:$A$21,0))&" | "&INDEX(Mapping!$B$24:$B$32,MATCH($B11,Mapping!$A$24:$A$32,0))) | I11: =INDEX(Variables!$C$5:$C$45,MATCH($A11,Variables!$A$5:$A$45,0)) | J11: =INDEX(Variables!$E$5:$E$45,MATCH($A11,Variables!$A$5:$A$45,0)) | K11: =LOWER(Settings!$C$4)&".mit."&$A11&IF($C11="","","."&$C11&"."&$B11)&IF(INDEX(Variables!$D$5:$D$45,MATCH($A11,Variables!$A$5:$A$45,0))="","","."&INDEX(Variables!$D$5:$D$45,MATCH($A11,Variables!$A$5:$A$45,0)))&"."&K$5 | L11: =INDEX(MTInputs!$J$8:$AZ$415,MATCH($A11,MTInputs!$H$8:$H$415,0),MATCH(L$5,MTInputs!$J$5:$AZ$5,0)) | M11: =INDEX(MTInputs!$J$8:$AZ$415,MATCH($A11,MTInputs!$H$8:$H$415,0),MATCH(M$5,MTInputs!$J$5:$AZ$5,0)) | N11: =INDEX(MTInputs!$J$8:$AZ$415,MATCH($A11,MTInputs!$H$8:$H$415,0),MATCH(N$5,MTInputs!$J$5:$AZ$5,0)) | O11: =INDEX(MTInputs!$J$8:$AZ$415,MATCH($A11,MTInputs!$H$8:$H$415,0),MATCH(O$5,MTInputs!$J$5:$AZ$5,0)) | P11: =INDEX(MTInputs!$J$8:$AZ$415,MATCH($A11,MTInputs!$H$8:$H$415,0),MATCH(P$5,MTInputs!$J$5:$AZ$5,0)) | Q11: =INDEX(MTInputs!$J$8:$AZ$415,MATCH($A11,MTInputs!$H$8:$H$415,0),MATCH(Q$5,MTInputs!$J$5:$AZ$5,0)) | R11: =INDEX(MTInputs!$J$8:$AZ$415,MATCH($A11,MTInputs!$H$8:$H$415,0),MATCH(R$5,MTInputs!$J$5:$AZ$5,0)) | S11: =INDEX(MTInputs!$J$8:$AZ$415,MATCH($A11,MTInputs!$H$8:$H$415,0),MATCH(S$5,MTInputs!$J$5:$AZ$5,0)) | ... Y11: =INDEX(MTInputs!$J$8:$AZ$415,MATCH($A11,MTInputs!$H$8:$H$415,0),MATCH(Y$5,MTInputs!$J$5:$AZ$5,0)) | Z11: =LOWER(Settings!$C$4)&".mit."&$A11&IF($C11="","","."&$C11&"."&$B11)&IF(INDEX(Variables!$D$5:$D$45,MATCH($A11,Variables!$A$5:$A$45,0))="","","."&INDEX(Variables!$D$5:$D$45,MATCH($A11,Variables!$A$5:$A$45,0)))&"."&Z$5 | AA11: =INDEX(MTInputs!$J$8:$AZ$415,MATCH($A11,MTInputs!$H$8:$H$415,0),MATCH(AA$5,MTInputs!$J$5:$AZ$5,0)) | AB11: =INDEX(MTInputs!$J$8:$AZ$415,MATCH($A11,MTInputs!$H$8:$H$415,0),MATCH(AB$5,MTInputs!$J$5:$AZ$5,0)) | AC11: =INDEX(MTInputs!$J$8:$AZ$415,MATCH($A11,MTInputs!$H$8:$H$415,0),MATCH(AC$5,MTInputs!$J$5:$AZ$5,0)) | AD11: =INDEX(MTInputs!$J$8:$AZ$415,MATCH($A11,MTInputs!$H$8:$H$415,0),MATCH(AD$5,MTInputs!$J$5:$AZ$5,0)) | AE11: =INDEX(MTInputs!$J$8:$AZ$415,MATCH($A11,MTInputs!$H$8:$H$415,0),MATCH(AE$5,MTInputs!$J$5:$AZ$5,0)) | AF11: =INDEX(MTInputs!$J$8:$AZ$415,MATCH($A11,MTInputs!$H$8:$H$415,0),MATCH(AF$5,MTInputs!$J$5:$AZ$5,0)) | AG11: =INDEX(MTInputs!$J$8:$AZ$415,MATCH($A11,MTInputs!$H$8:$H$415,0),MATCH(AG$5,MTInputs!$J$5:$AZ$5,0)) | AH11: =INDEX(MTInputs!$J$8:$AZ$415,MATCH($A11,MTInputs!$H$8:$H$415,0),MATCH(AH$5,MTInputs!$J$5:$AZ$5,0)) | ... AN11: =INDEX(MTInputs!$J$8:$AZ$415,MATCH($A11,MTInputs!$H$8:$H$415,0),MATCH(AN$5,MTInputs!$J$5:$AZ$5,0))
A12: CPOutro | H12: =INDEX(Variables!$B$5:$B$45,MATCH($A12,Variables!$A$5:$A$45,0))&IF($C12="",""," | "&INDEX(Mapping!$B$5:$B$21,MATCH($C12,Mapping!$A$5:$A$21,0))&" | "&INDEX(Mapping!$B$24:$B$32,MATCH($B12,Mapping!$A$24:$A$32,0))) | I12: =INDEX(Variables!$C$5:$C$45,MATCH($A12,Variables!$A$5:$A$45,0)) | J12: =INDEX(Variables!$E$5:$E$45,MATCH($A12,Variables!$A$5:$A$45,0)) | K12: =LOWER(Settings!$C$4)&".mit."&$A12&IF($C12="","","."&$C12&"."&$B12)&IF(INDEX(Variables!$D$5:$D$45,MATCH($A12,Variables!$A$5:$A$45,0))="","","."&INDEX(Variables!$D$5:$D$45,MATCH($A12,Variables!$A$5:$A$45,0)))&"."&K$5 | L12: =INDEX(MTInputs!$J$8:$AZ$415,MATCH($A12,MTInputs!$H$8:$H$415,0),MATCH(L$5,MTInputs!$J$5:$AZ$5,0)) | M12: =INDEX(MTInputs!$J$8:$AZ$415,MATCH($A12,MTInputs!$H$8:$H$415,0),MATCH(M$5,MTInputs!$J$5:$AZ$5,0)) | N12: =INDEX(MTInputs!$J$8:$AZ$415,MATCH($A12,MTInputs!$H$8:$H$415,0),MATCH(N$5,MTInputs!$J$5:$AZ$5,0)) | O12: =INDEX(MTInputs!$J$8:$AZ$415,MATCH($A12,MTInputs!$H$8:$H$415,0),MATCH(O$5,MTInputs!$J$5:$AZ$5,0)) | P12: =INDEX(MTInputs!$J$8:$AZ$415,MATCH($A12,MTInputs!$H$8:$H$415,0),MATCH(P$5,MTInputs!$J$5:$AZ$5,0)) | Q12: =INDEX(MTInputs!$J$8:$AZ$415,MATCH($A12,MTInputs!$H$8:$H$415,0),MATCH(Q$5,MTInputs!$J$5:$AZ$5,0)) | R12: =INDEX(MTInputs!$J$8:$AZ$415,MATCH($A12,MTInputs!$H$8:$H$415,0),MATCH(R$5,MTInputs!$J$5:$AZ$5,0)) | S12: =INDEX(MTInputs!$J$8:$AZ$415,MATCH($A12,MTInputs!$H$8:$H$415,0),MATCH(S$5,MTInputs!$J$5:$AZ$5,0)) | ... Y12: =INDEX(MTInputs!$J$8:$AZ$415,MATCH($A12,MTInputs!$H$8:$H$415,0),MATCH(Y$5,MTInputs!$J$5:$AZ$5,0)) | Z12: =LOWER(Settings!$C$4)&".mit."&$A12&IF($C12="","","."&$C12&"."&$B12)&IF(INDEX(Variables!$D$5:$D$45,MATCH($A12,Variables!$A$5:$A$45,0))="","","."&INDEX(Variables!$D$5:$D$45,MATCH($A12,Variables!$A$5:$A$45,0)))&"."&Z$5 | AA12: =INDEX(MTInputs!$J$8:$AZ$415,MATCH($A12,MTInputs!$H$8:$H$415,0),MATCH(AA$5,MTInputs!$J$5:$AZ$5,0)) | AB12: =INDEX(MTInputs!$J$8:$AZ$415,MATCH($A12,MTInputs!$H$8:$H$415,0),MATCH(AB$5,MTInputs!$J$5:$AZ$5,0)) | AC12: =INDEX(MTInputs!$J$8:$AZ$415,MATCH($A12,MTInputs!$H$8:$H$415,0),MATCH(AC$5,MTInputs!$J$5:$AZ$5,0)) | AD12: =INDEX(MTInputs!$J$8:$AZ$415,MATCH($A12,MTInputs!$H$8:$H$415,0),MATCH(AD$5,MTInputs!$J$5:$AZ$5,0)) | AE12: =INDEX(MTInputs!$J$8:$AZ$415,MATCH($A12,MTInputs!$H$8:$H$415,0),MATCH(AE$5,MTInputs!$J$5:$AZ$5,0)) | AF12: =INDEX(MTInputs!$J$8:$AZ$415,MATCH($A12,MTInputs!$H$8:$H$415,0),MATCH(AF$5,MTInputs!$J$5:$AZ$5,0)) | AG12: =INDEX(MTInputs!$J$8:$AZ$415,MATCH($A12,MTInputs!$H$8:$H$415,0),MATCH(AG$5,MTInputs!$J$5:$AZ$5,0)) | AH12: =INDEX(MTInputs!$J$8:$AZ$415,MATCH($A12,MTInputs!$H$8:$H$415,0),MATCH(AH$5,MTInputs!$J$5:$AZ$5,0)) | ... AN12: =INDEX(MTInputs!$J$8:$AZ$415,MATCH($A12,MTInputs!$H$8:$H$415,0),MATCH(AN$5,MTInputs!$J$5:$AZ$5,0))
A13: ExtendCarbonPriceBeyondOutro | H13: =INDEX(Variables!$B$5:$B$45,MATCH($A13,Variables!$A$5:$A$45,0))&IF($C13="",""," | "&INDEX(Mapping!$B$5:$B$21,MATCH($C13,Mapping!$A$5:$A$21,0))&" | "&INDEX(Mapping!$B$24:$B$32,MATCH($B13,Mapping!$A$24:$A$32,0))) | I13: =INDEX(Variables!$C$5:$C$45,MATCH($A13,Variables!$A$5:$A$45,0)) | J13: =INDEX(Variables!$E$5:$E$45,MATCH($A13,Variables!$A$5:$A$45,0)) | K13: =LOWER(Settings!$C$4)&".mit."&$A13&IF($C13="","","."&$C13&"."&$B13)&IF(INDEX(Variables!$D$5:$D$45,MATCH($A13,Variables!$A$5:$A$45,0))="","","."&INDEX(Variables!$D$5:$D$45,MATCH($A13,Variables!$A$5:$A$45,0)))&"."&K$5 | L13: =INDEX(MTInputs!$J$8:$AZ$415,MATCH($A13,MTInputs!$H$8:$H$415,0),MATCH(L$5,MTInputs!$J$5:$AZ$5,0)) | M13: =INDEX(MTInputs!$J$8:$AZ$415,MATCH($A13,MTInputs!$H$8:$H$415,0),MATCH(M$5,MTInputs!$J$5:$AZ$5,0)) | N13: =INDEX(MTInputs!$J$8:$AZ$415,MATCH($A13,MTInputs!$H$8:$H$415,0),MATCH(N$5,MTInputs!$J$5:$AZ$5,0)) | O13: =INDEX(MTInputs!$J$8:$AZ$415,MATCH($A13,MTInputs!$H$8:$H$415,0),MATCH(O$5,MTInputs!$J$5:$AZ$5,0)) | P13: =INDEX(MTInputs!$J$8:$AZ$415,MATCH($A13,MTInputs!$H$8:$H$415,0),MATCH(P$5,MTInputs!$J$5:$AZ$5,0)) | Q13: =INDEX(MTInputs!$J$8:$AZ$415,MATCH($A13,MTInputs!$H$8:$H$415,0),MATCH(Q$5,MTInputs!$J$5:$AZ$5,0)) | R13: =INDEX(MTInputs!$J$8:$AZ$415,MATCH($A13,MTInputs!$H$8:$H$415,0),MATCH(R$5,MTInputs!$J$5:$AZ$5,0)) | S13: =INDEX(MTInputs!$J$8:$AZ$415,MATCH($A13,MTInputs!$H$8:$H$415,0),MATCH(S$5,MTInputs!$J$5:$AZ$5,0)) | ... Y13: =INDEX(MTInputs!$J$8:$AZ$415,MATCH($A13,MTInputs!$H$8:$H$415,0),MATCH(Y$5,MTInputs!$J$5:$AZ$5,0)) | Z13: =LOWER(Settings!$C$4)&".mit."&$A13&IF($C13="","","."&$C13&"."&$B13)&IF(INDEX(Variables!$D$5:$D$45,MATCH($A13,Variables!$A$5:$A$45,0))="","","."&INDEX(Variables!$D$5:$D$45,MATCH($A13,Variables!$A$5:$A$45,0)))&"."&Z$5 | AA13: =INDEX(MTInputs!$J$8:$AZ$415,MATCH($A13,MTInputs!$H$8:$H$415,0),MATCH(AA$5,MTInputs!$J$5:$AZ$5,0)) | AB13: =INDEX(MTInputs!$J$8:$AZ$415,MATCH($A13,MTInputs!$H$8:$H$415,0),MATCH(AB$5,MTInputs!$J$5:$AZ$5,0)) | AC13: =INDEX(MTInputs!$J$8:$AZ$415,MATCH($A13,MTInputs!$H$8:$H$415,0),MATCH(AC$5,MTInputs!$J$5:$AZ$5,0)) | AD13: =INDEX(MTInputs!$J$8:$AZ$415,MATCH($A13,MTInputs!$H$8:$H$415,0),MATCH(AD$5,MTInputs!$J$5:$AZ$5,0)) | AE13: =INDEX(MTInputs!$J$8:$AZ$415,MATCH($A13,MTInputs!$H$8:$H$415,0),MATCH(AE$5,MTInputs!$J$5:$AZ$5,0)) | AF13: =INDEX(MTInputs!$J$8:$AZ$415,MATCH($A13,MTInputs!$H$8:$H$415,0),MATCH(AF$5,MTInputs!$J$5:$AZ$5,0)) | AG13: =INDEX(MTInputs!$J$8:$AZ$415,MATCH($A13,MTInputs!$H$8:$H$415,0),MATCH(AG$5,MTInputs!$J$5:$AZ$5,0)) | AH13: =INDEX(MTInputs!$J$8:$AZ$415,MATCH($A13,MTInputs!$H$8:$H$415,0),MATCH(AH$5,MTInputs!$J$5:$AZ$5,0)) | ... AN13: =INDEX(MTInputs!$J$8:$AZ$415,MATCH($A13,MTInputs!$H$8:$H$415,0),MATCH(AN$5,MTInputs!$J$5:$AZ$5,0))
A14: cptraj | H14: =INDEX(Variables!$B$5:$B$45,MATCH($A14,Variables!$A$5:$A$45,0))&IF($C14="",""," | "&INDEX(Mapping!$B$5:$B$21,MATCH($C14,Mapping!$A$5:$A$21,0))&" | "&INDEX(Mapping!$B$24:$B$32,MATCH($B14,Mapping!$A$24:$A$32,0))) | I14: =INDEX(Variables!$C$5:$C$45,MATCH($A14,Variables!$A$5:$A$45,0)) | J14: =INDEX(Variables!$E$5:$E$45,MATCH($A14,Variables!$A$5:$A$45,0)) | K14: =LOWER(Settings!$C$4)&".mit."&$A14&IF($C14="","","."&$C14&"."&$B14)&IF(INDEX(Variables!$D$5:$D$45,MATCH($A14,Variables!$A$5:$A$45,0))="","","."&INDEX(Variables!$D$5:$D$45,MATCH($A14,Variables!$A$5:$A$45,0)))&"."&K$5 | L14: =IF(L$4<L$9,0,L$10+(L$11-L$10)/MAX(L$12-L$9,1)*IF(OR(L$4<=L$12,L$13="Linear*"),L$4-L$9,L$12-L$9)) | M14: =IF(M$4<M$9,0,M$10+(M$11-M$10)/MAX(M$12-M$9,1)*IF(OR(M$4<=M$12,M$13="Linear*"),M$4-M$9,M$12-M$9)) | N14: =IF(N$4<N$9,0,N$10+(N$11-N$10)/MAX(N$12-N$9,1)*IF(OR(N$4<=N$12,N$13="Linear*"),N$4-N$9,N$12-N$9)) | O14: =IF(O$4<O$9,0,O$10+(O$11-O$10)/MAX(O$12-O$9,1)*IF(OR(O$4<=O$12,O$13="Linear*"),O$4-O$9,O$12-O$9)) | P14: =IF(P$4<P$9,0,P$10+(P$11-P$10)/MAX(P$12-P$9,1)*IF(OR(P$4<=P$12,P$13="Linear*"),P$4-P$9,P$12-P$9)) | Q14: =IF(Q$4<Q$9,0,Q$10+(Q$11-Q$10)/MAX(Q$12-Q$9,1)*IF(OR(Q$4<=Q$12,Q$13="Linear*"),Q$4-Q$9,Q$12-Q$9)) | R14: =IF(R$4<R$9,0,R$10+(R$11-R$10)/MAX(R$12-R$9,1)*IF(OR(R$4<=R$12,R$13="Linear*"),R$4-R$9,R$12-R$9)) | S14: =IF(S$4<S$9,0,S$10+(S$11-S$10)/MAX(S$12-S$9,1)*IF(OR(S$4<=S$12,S$13="Linear*"),S$4-S$9,S$12-S$9)) | ... Y14: =IF(Y$4<Y$9,0,Y$10+(Y$11-Y$10)/MAX(Y$12-Y$9,1)*IF(OR(Y$4<=Y$12,Y$13="Linear*"),Y$4-Y$9,Y$12-Y$9)) | Z14: =LOWER(Settings!$C$4)&".mit."&$A14&IF($C14="","","."&$C14&"."&$B14)&IF(INDEX(Variables!$D$5:$D$45,MATCH($A14,Variables!$A$5:$A$45,0))="","","."&INDEX(Variables!$D$5:$D$45,MATCH($A14,Variables!$A$5:$A$45,0)))&"."&Z$5 | AA14: =IF(AA$4<AA$9,0,AA$10+(AA$11-AA$10)/MAX(AA$12-AA$9,1)*IF(OR(AA$4<=AA$12,AA$13="Linear*"),AA$4-AA$9,AA$12-AA$9)) | AB14: =IF(AB$4<AB$9,0,AB$10+(AB$11-AB$10)/MAX(AB$12-AB$9,1)*IF(OR(AB$4<=AB$12,AB$13="Linear*"),AB$4-AB$9,AB$12-AB$9)) | AC14: =IF(AC$4<AC$9,0,AC$10+(AC$11-AC$10)/MAX(AC$12-AC$9,1)*IF(OR(AC$4<=AC$12,AC$13="Linear*"),AC$4-AC$9,AC$12-AC$9)) | AD14: =IF(AD$4<AD$9,0,AD$10+(AD$11-AD$10)/MAX(AD$12-AD$9,1)*IF(OR(AD$4<=AD$12,AD$13="Linear*"),AD$4-AD$9,AD$12-AD$9)) | AE14: =IF(AE$4<AE$9,0,AE$10+(AE$11-AE$10)/MAX(AE$12-AE$9,1)*IF(OR(AE$4<=AE$12,AE$13="Linear*"),AE$4-AE$9,AE$12-AE$9)) | AF14: =IF(AF$4<AF$9,0,AF$10+(AF$11-AF$10)/MAX(AF$12-AF$9,1)*IF(OR(AF$4<=AF$12,AF$13="Linear*"),AF$4-AF$9,AF$12-AF$9)) | AG14: =IF(AG$4<AG$9,0,AG$10+(AG$11-AG$10)/MAX(AG$12-AG$9,1)*IF(OR(AG$4<=AG$12,AG$13="Linear*"),AG$4-AG$9,AG$12-AG$9)) | AH14: =IF(AH$4<AH$9,0,AH$10+(AH$11-AH$10)/MAX(AH$12-AH$9,1)*IF(OR(AH$4<=AH$12,AH$13="Linear*"),AH$4-AH$9,AH$12-AH$9)) | ... AN14: =IF(AN$4<AN$9,0,AN$10+(AN$11-AN$10)/MAX(AN$12-AN$9,1)*IF(OR(AN$4<=AN$12,AN$13="Linear*"),AN$4-AN$9,AN$12-AN$9))
A16: Pre-tax price: p(t) = p(t-1) x (1 + growth) | D16: growth
H17: No total: prices are not added up
A18: sp | B18: coa | C18: rod | D18: =INDEX(Inputs!$O$5:$O$132,MATCH($B18&"|"&$C18,Inputs!$A$5:$A$132,0)) | H18: =INDEX(Variables!$B$5:$B$45,MATCH($A18,Variables!$A$5:$A$45,0))&IF($C18="",""," | "&INDEX(Mapping!$B$5:$B$21,MATCH($C18,Mapping!$A$5:$A$21,0))&" | "&INDEX(Mapping!$B$24:$B$32,MATCH($B18,Mapping!$A$24:$A$32,0))) | I18: =INDEX(Variables!$C$5:$C$45,MATCH($A18,Variables!$A$5:$A$45,0)) | J18: =INDEX(Variables!$E$5:$E$45,MATCH($A18,Variables!$A$5:$A$45,0)) | K18: =LOWER(Settings!$C$4)&".mit."&$A18&IF($C18="","","."&$C18&"."&$B18)&IF(INDEX(Variables!$D$5:$D$45,MATCH($A18,Variables!$A$5:$A$45,0))="","","."&INDEX(Variables!$D$5:$D$45,MATCH($A18,Variables!$A$5:$A$45,0)))&"."&K$5 | L18: =INDEX(Inputs!$P$5:$P$132,MATCH($B18&"|"&$C18,Inputs!$A$5:$A$132,0)) | M18: =L18*(1+$D18) | N18: =M18*(1+$D18) | O18: =N18*(1+$D18) | P18: =O18*(1+$D18) | Q18: =P18*(1+$D18) | R18: =Q18*(1+$D18) | S18: =R18*(1+$D18) | T18: =S18*(1+$D18) | ... X18: =W18*(1+$D18) | Y18: =PRETAX(X18,$D18) | Z18: =LOWER(Settings!$C$4)&".mit."&$A18&IF($C18="","","."&$C18&"."&$B18)&IF(INDEX(Variables!$D$5:$D$45,MATCH($A18,Variables!$A$5:$A$45,0))="","","."&INDEX(Variables!$D$5:$D$45,MATCH($A18,Variables!$A$5:$A$45,0)))&"."&Z$5 | AA18: =INDEX(Inputs!$P$5:$P$132,MATCH($B18&"|"&$C18,Inputs!$A$5:$A$132,0)) | AB18: =AA18*(1+$D18) | AC18: =AB18*(1+$D18) | AD18: =AC18*(1+$D18) | AE18: =AD18*(1+$D18) | AF18: =AE18*(1+$D18) | AG18: =AF18*(1+$D18) | AH18: =AG18*(1+$D18) | AI18: =AH18*(1+$D18) | ... AM18: =AL18*(1+$D18) | AN18: =PRETAX(AM18,$D18)
A19: sp | B19: nga | C19: rod | D19: =INDEX(Inputs!$O$5:$O$132,MATCH($B19&"|"&$C19,Inputs!$A$5:$A$132,0)) | H19: =INDEX(Variables!$B$5:$B$45,MATCH($A19,Variables!$A$5:$A$45,0))&IF($C19="",""," | "&INDEX(Mapping!$B$5:$B$21,MATCH($C19,Mapping!$A$5:$A$21,0))&" | "&INDEX(Mapping!$B$24:$B$32,MATCH($B19,Mapping!$A$24:$A$32,0))) | I19: =INDEX(Variables!$C$5:$C$45,MATCH($A19,Variables!$A$5:$A$45,0)) | J19: =INDEX(Variables!$E$5:$E$45,MATCH($A19,Variables!$A$5:$A$45,0)) | K19: =LOWER(Settings!$C$4)&".mit."&$A19&IF($C19="","","."&$C19&"."&$B19)&IF(INDEX(Variables!$D$5:$D$45,MATCH($A19,Variables!$A$5:$A$45,0))="","","."&INDEX(Variables!$D$5:$D$45,MATCH($A19,Variables!$A$5:$A$45,0)))&"."&K$5 | L19: =INDEX(Inputs!$P$5:$P$132,MATCH($B19&"|"&$C19,Inputs!$A$5:$A$132,0)) | M19: =L19*(1+$D19) | N19: =M19*(1+$D19) | O19: =N19*(1+$D19) | P19: =O19*(1+$D19) | Q19: =P19*(1+$D19) | R19: =Q19*(1+$D19) | S19: =R19*(1+$D19) | T19: =S19*(1+$D19) | ... X19: =W19*(1+$D19) | Y19: =PRETAX(X19,$D19) | Z19: =LOWER(Settings!$C$4)&".mit."&$A19&IF($C19="","","."&$C19&"."&$B19)&IF(INDEX(Variables!$D$5:$D$45,MATCH($A19,Variables!$A$5:$A$45,0))="","","."&INDEX(Variables!$D$5:$D$45,MATCH($A19,Variables!$A$5:$A$45,0)))&"."&Z$5 | AA19: =INDEX(Inputs!$P$5:$P$132,MATCH($B19&"|"&$C19,Inputs!$A$5:$A$132,0)) | AB19: =AA19*(1+$D19) | AC19: =AB19*(1+$D19) | AD19: =AC19*(1+$D19) | AE19: =AD19*(1+$D19) | AF19: =AE19*(1+$D19) | AG19: =AF19*(1+$D19) | AH19: =AG19*(1+$D19) | AI19: =AH19*(1+$D19) | ... AM19: =AL19*(1+$D19) | AN19: =PRETAX(AM19,$D19)
A20: sp | B20: gso | C20: rod | D20: =INDEX(Inputs!$O$5:$O$132,MATCH($B20&"|"&$C20,Inputs!$A$5:$A$132,0)) | H20: =INDEX(Variables!$B$5:$B$45,MATCH($A20,Variables!$A$5:$A$45,0))&IF($C20="",""," | "&INDEX(Mapping!$B$5:$B$21,MATCH($C20,Mapping!$A$5:$A$21,0))&" | "&INDEX(Mapping!$B$24:$B$32,MATCH($B20,Mapping!$A$24:$A$32,0))) | I20: =INDEX(Variables!$C$5:$C$45,MATCH($A20,Variables!$A$5:$A$45,0)) | J20: =INDEX(Variables!$E$5:$E$45,MATCH($A20,Variables!$A$5:$A$45,0)) | K20: =LOWER(Settings!$C$4)&".mit."&$A20&IF($C20="","","."&$C20&"."&$B20)&IF(INDEX(Variables!$D$5:$D$45,MATCH($A20,Variables!$A$5:$A$45,0))="","","."&INDEX(Variables!$D$5:$D$45,MATCH($A20,Variables!$A$5:$A$45,0)))&"."&K$5 | L20: =INDEX(Inputs!$P$5:$P$132,MATCH($B20&"|"&$C20,Inputs!$A$5:$A$132,0)) | M20: =L20*(1+$D20) | N20: =M20*(1+$D20) | O20: =N20*(1+$D20) | P20: =O20*(1+$D20) | Q20: =P20*(1+$D20) | R20: =Q20*(1+$D20) | S20: =R20*(1+$D20) | T20: =S20*(1+$D20) | ... X20: =W20*(1+$D20) | Y20: =PRETAX(X20,$D20) | Z20: =LOWER(Settings!$C$4)&".mit."&$A20&IF($C20="","","."&$C20&"."&$B20)&IF(INDEX(Variables!$D$5:$D$45,MATCH($A20,Variables!$A$5:$A$45,0))="","","."&INDEX(Variables!$D$5:$D$45,MATCH($A20,Variables!$A$5:$A$45,0)))&"."&Z$5 | AA20: =INDEX(Inputs!$P$5:$P$132,MATCH($B20&"|"&$C20,Inputs!$A$5:$A$132,0)) | AB20: =AA20*(1+$D20) | AC20: =AB20*(1+$D20) | AD20: =AC20*(1+$D20) | AE20: =AD20*(1+$D20) | AF20: =AE20*(1+$D20) | AG20: =AF20*(1+$D20) | AH20: =AG20*(1+$D20) | AI20: =AH20*(1+$D20) | ... AM20: =AL20*(1+$D20) | AN20: =PRETAX(AM20,$D20)
A21: sp | B21: die | C21: rod | D21: =INDEX(Inputs!$O$5:$O$132,MATCH($B21&"|"&$C21,Inputs!$A$5:$A$132,0)) | H21: =INDEX(Variables!$B$5:$B$45,MATCH($A21,Variables!$A$5:$A$45,0))&IF($C21="",""," | "&INDEX(Mapping!$B$5:$B$21,MATCH($C21,Mapping!$A$5:$A$21,0))&" | "&INDEX(Mapping!$B$24:$B$32,MATCH($B21,Mapping!$A$24:$A$32,0))) | I21: =INDEX(Variables!$C$5:$C$45,MATCH($A21,Variables!$A$5:$A$45,0)) | J21: =INDEX(Variables!$E$5:$E$45,MATCH($A21,Variables!$A$5:$A$45,0)) | K21: =LOWER(Settings!$C$4)&".mit."&$A21&IF($C21="","","."&$C21&"."&$B21)&IF(INDEX(Variables!$D$5:$D$45,MATCH($A21,Variables!$A$5:$A$45,0))="","","."&INDEX(Variables!$D$5:$D$45,MATCH($A21,Variables!$A$5:$A$45,0)))&"."&K$5 | L21: =INDEX(Inputs!$P$5:$P$132,MATCH($B21&"|"&$C21,Inputs!$A$5:$A$132,0)) | M21: =L21*(1+$D21) | N21: =M21*(1+$D21) | O21: =N21*(1+$D21) | P21: =O21*(1+$D21) | Q21: =P21*(1+$D21) | R21: =Q21*(1+$D21) | S21: =R21*(1+$D21) | T21: =S21*(1+$D21) | ... X21: =W21*(1+$D21) | Y21: =PRETAX(X21,$D21) | Z21: =LOWER(Settings!$C$4)&".mit."&$A21&IF($C21="","","."&$C21&"."&$B21)&IF(INDEX(Variables!$D$5:$D$45,MATCH($A21,Variables!$A$5:$A$45,0))="","","."&INDEX(Variables!$D$5:$D$45,MATCH($A21,Variables!$A$5:$A$45,0)))&"."&Z$5 | AA21: =INDEX(Inputs!$P$5:$P$132,MATCH($B21&"|"&$C21,Inputs!$A$5:$A$132,0)) | AB21: =AA21*(1+$D21) | AC21: =AB21*(1+$D21) | AD21: =AC21*(1+$D21) | AE21: =AD21*(1+$D21) | AF21: =AE21*(1+$D21) | AG21: =AF21*(1+$D21) | AH21: =AG21*(1+$D21) | AI21: =AH21*(1+$D21) | ... AM21: =AL21*(1+$D21) | AN21: =PRETAX(AM21,$D21)
A22: sp | B22: lpg | C22: rod | D22: =INDEX(Inputs!$O$5:$O$132,MATCH($B22&"|"&$C22,Inputs!$A$5:$A$132,0)) | H22: =INDEX(Variables!$B$5:$B$45,MATCH($A22,Variables!$A$5:$A$45,0))&IF($C22="",""," | "&INDEX(Mapping!$B$5:$B$21,MATCH($C22,Mapping!$A$5:$A$21,0))&" | "&INDEX(Mapping!$B$24:$B$32,MATCH($B22,Mapping!$A$24:$A$32,0))) | I22: =INDEX(Variables!$C$5:$C$45,MATCH($A22,Variables!$A$5:$A$45,0)) | J22: =INDEX(Variables!$E$5:$E$45,MATCH($A22,Variables!$A$5:$A$45,0)) | K22: =LOWER(Settings!$C$4)&".mit."&$A22&IF($C22="","","."&$C22&"."&$B22)&IF(INDEX(Variables!$D$5:$D$45,MATCH($A22,Variables!$A$5:$A$45,0))="","","."&INDEX(Variables!$D$5:$D$45,MATCH($A22,Variables!$A$5:$A$45,0)))&"."&K$5 | L22: =INDEX(Inputs!$P$5:$P$132,MATCH($B22&"|"&$C22,Inputs!$A$5:$A$132,0)) | M22: =L22*(1+$D22) | N22: =M22*(1+$D22) | O22: =N22*(1+$D22) | P22: =O22*(1+$D22) | Q22: =P22*(1+$D22) | R22: =Q22*(1+$D22) | S22: =R22*(1+$D22) | T22: =S22*(1+$D22) | ... X22: =W22*(1+$D22) | Y22: =PRETAX(X22,$D22) | Z22: =LOWER(Settings!$C$4)&".mit."&$A22&IF($C22="","","."&$C22&"."&$B22)&IF(INDEX(Variables!$D$5:$D$45,MATCH($A22,Variables!$A$5:$A$45,0))="","","."&INDEX(Variables!$D$5:$D$45,MATCH($A22,Variables!$A$5:$A$45,0)))&"."&Z$5 | AA22: =INDEX(Inputs!$P$5:$P$132,MATCH($B22&"|"&$C22,Inputs!$A$5:$A$132,0)) | AB22: =AA22*(1+$D22) | AC22: =AB22*(1+$D22) | AD22: =AC22*(1+$D22) | AE22: =AD22*(1+$D22) | AF22: =AE22*(1+$D22) | AG22: =AF22*(1+$D22) | AH22: =AG22*(1+$D22) | AI22: =AH22*(1+$D22) | ... AM22: =AL22*(1+$D22) | AN22: =PRETAX(AM22,$D22)
A23: sp | B23: ker | C23: rod | D23: =INDEX(Inputs!$O$5:$O$132,MATCH($B23&"|"&$C23,Inputs!$A$5:$A$132,0)) | H23: =INDEX(Variables!$B$5:$B$45,MATCH($A23,Variables!$A$5:$A$45,0))&IF($C23="",""," | "&INDEX(Mapping!$B$5:$B$21,MATCH($C23,Mapping!$A$5:$A$21,0))&" | "&INDEX(Mapping!$B$24:$B$32,MATCH($B23,Mapping!$A$24:$A$32,0))) | I23: =INDEX(Variables!$C$5:$C$45,MATCH($A23,Variables!$A$5:$A$45,0)) | J23: =INDEX(Variables!$E$5:$E$45,MATCH($A23,Variables!$A$5:$A$45,0)) | K23: =LOWER(Settings!$C$4)&".mit."&$A23&IF($C23="","","."&$C23&"."&$B23)&IF(INDEX(Variables!$D$5:$D$45,MATCH($A23,Variables!$A$5:$A$45,0))="","","."&INDEX(Variables!$D$5:$D$45,MATCH($A23,Variables!$A$5:$A$45,0)))&"."&K$5 | L23: =INDEX(Inputs!$P$5:$P$132,MATCH($B23&"|"&$C23,Inputs!$A$5:$A$132,0)) | M23: =L23*(1+$D23) | N23: =M23*(1+$D23) | O23: =N23*(1+$D23) | P23: =O23*(1+$D23) | Q23: =P23*(1+$D23) | R23: =Q23*(1+$D23) | S23: =R23*(1+$D23) | T23: =S23*(1+$D23) | ... X23: =W23*(1+$D23) | Y23: =PRETAX(X23,$D23) | Z23: =LOWER(Settings!$C$4)&".mit."&$A23&IF($C23="","","."&$C23&"."&$B23)&IF(INDEX(Variables!$D$5:$D$45,MATCH($A23,Variables!$A$5:$A$45,0))="","","."&INDEX(Variables!$D$5:$D$45,MATCH($A23,Variables!$A$5:$A$45,0)))&"."&Z$5 | AA23: =INDEX(Inputs!$P$5:$P$132,MATCH($B23&"|"&$C23,Inputs!$A$5:$A$132,0)) | AB23: =AA23*(1+$D23) | AC23: =AB23*(1+$D23) | AD23: =AC23*(1+$D23) | AE23: =AD23*(1+$D23) | AF23: =AE23*(1+$D23) | AG23: =AF23*(1+$D23) | AH23: =AG23*(1+$D23) | AI23: =AH23*(1+$D23) | ... AM23: =AL23*(1+$D23) | AN23: =PRETAX(AM23,$D23)
A24: sp | B24: oop | C24: rod | D24: =INDEX(Inputs!$O$5:$O$132,MATCH($B24&"|"&$C24,Inputs!$A$5:$A$132,0)) | H24: =INDEX(Variables!$B$5:$B$45,MATCH($A24,Variables!$A$5:$A$45,0))&IF($C24="",""," | "&INDEX(Mapping!$B$5:$B$21,MATCH($C24,Mapping!$A$5:$A$21,0))&" | "&INDEX(Mapping!$B$24:$B$32,MATCH($B24,Mapping!$A$24:$A$32,0))) | I24: =INDEX(Variables!$C$5:$C$45,MATCH($A24,Variables!$A$5:$A$45,0)) | J24: =INDEX(Variables!$E$5:$E$45,MATCH($A24,Variables!$A$5:$A$45,0)) | K24: =LOWER(Settings!$C$4)&".mit."&$A24&IF($C24="","","."&$C24&"."&$B24)&IF(INDEX(Variables!$D$5:$D$45,MATCH($A24,Variables!$A$5:$A$45,0))="","","."&INDEX(Variables!$D$5:$D$45,MATCH($A24,Variables!$A$5:$A$45,0)))&"."&K$5 | L24: =INDEX(Inputs!$P$5:$P$132,MATCH($B24&"|"&$C24,Inputs!$A$5:$A$132,0)) | M24: =L24*(1+$D24) | N24: =M24*(1+$D24) | O24: =N24*(1+$D24) | P24: =O24*(1+$D24) | Q24: =P24*(1+$D24) | R24: =Q24*(1+$D24) | S24: =R24*(1+$D24) | T24: =S24*(1+$D24) | ... X24: =W24*(1+$D24) | Y24: =PRETAX(X24,$D24) | Z24: =LOWER(Settings!$C$4)&".mit."&$A24&IF($C24="","","."&$C24&"."&$B24)&IF(INDEX(Variables!$D$5:$D$45,MATCH($A24,Variables!$A$5:$A$45,0))="","","."&INDEX(Variables!$D$5:$D$45,MATCH($A24,Variables!$A$5:$A$45,0)))&"."&Z$5 | AA24: =INDEX(Inputs!$P$5:$P$132,MATCH($B24&"|"&$C24,Inputs!$A$5:$A$132,0)) | AB24: =AA24*(1+$D24) | AC24: =AB24*(1+$D24) | AD24: =AC24*(1+$D24) | AE24: =AD24*(1+$D24) | AF24: =AE24*(1+$D24) | AG24: =AF24*(1+$D24) | AH24: =AG24*(1+$D24) | AI24: =AH24*(1+$D24) | ... AM24: =AL24*(1+$D24) | AN24: =PRETAX(AM24,$D24)
A25: sp | B25: bio | C25: rod | D25: =INDEX(Inputs!$O$5:$O$132,MATCH($B25&"|"&$C25,Inputs!$A$5:$A$132,0)) | H25: =INDEX(Variables!$B$5:$B$45,MATCH($A25,Variables!$A$5:$A$45,0))&IF($C25="",""," | "&INDEX(Mapping!$B$5:$B$21,MATCH($C25,Mapping!$A$5:$A$21,0))&" | "&INDEX(Mapping!$B$24:$B$32,MATCH($B25,Mapping!$A$24:$A$32,0))) | I25: =INDEX(Variables!$C$5:$C$45,MATCH($A25,Variables!$A$5:$A$45,0)) | J25: =INDEX(Variables!$E$5:$E$45,MATCH($A25,Variables!$A$5:$A$45,0)) | K25: =LOWER(Settings!$C$4)&".mit."&$A25&IF($C25="","","."&$C25&"."&$B25)&IF(INDEX(Variables!$D$5:$D$45,MATCH($A25,Variables!$A$5:$A$45,0))="","","."&INDEX(Variables!$D$5:$D$45,MATCH($A25,Variables!$A$5:$A$45,0)))&"."&K$5 | L25: =INDEX(Inputs!$P$5:$P$132,MATCH($B25&"|"&$C25,Inputs!$A$5:$A$132,0)) | M25: =L25*(1+$D25) | N25: =M25*(1+$D25) | O25: =N25*(1+$D25) | P25: =O25*(1+$D25) | Q25: =P25*(1+$D25) | R25: =Q25*(1+$D25) | S25: =R25*(1+$D25) | T25: =S25*(1+$D25) | ... X25: =W25*(1+$D25) | Y25: =PRETAX(X25,$D25) | Z25: =LOWER(Settings!$C$4)&".mit."&$A25&IF($C25="","","."&$C25&"."&$B25)&IF(INDEX(Variables!$D$5:$D$45,MATCH($A25,Variables!$A$5:$A$45,0))="","","."&INDEX(Variables!$D$5:$D$45,MATCH($A25,Variables!$A$5:$A$45,0)))&"."&Z$5 | AA25: =INDEX(Inputs!$P$5:$P$132,MATCH($B25&"|"&$C25,Inputs!$A$5:$A$132,0)) | AB25: =AA25*(1+$D25) | AC25: =AB25*(1+$D25) | AD25: =AC25*(1+$D25) | AE25: =AD25*(1+$D25) | AF25: =AE25*(1+$D25) | AG25: =AF25*(1+$D25) | AH25: =AG25*(1+$D25) | AI25: =AH25*(1+$D25) | ... AM25: =AL25*(1+$D25) | AN25: =PRETAX(AM25,$D25)
A26: sp | B26: coa | C26: ral | D26: =INDEX(Inputs!$O$5:$O$132,MATCH($B26&"|"&$C26,Inputs!$A$5:$A$132,0)) | H26: =INDEX(Variables!$B$5:$B$45,MATCH($A26,Variables!$A$5:$A$45,0))&IF($C26="",""," | "&INDEX(Mapping!$B$5:$B$21,MATCH($C26,Mapping!$A$5:$A$21,0))&" | "&INDEX(Mapping!$B$24:$B$32,MATCH($B26,Mapping!$A$24:$A$32,0))) | I26: =INDEX(Variables!$C$5:$C$45,MATCH($A26,Variables!$A$5:$A$45,0)) | J26: =INDEX(Variables!$E$5:$E$45,MATCH($A26,Variables!$A$5:$A$45,0)) | K26: =LOWER(Settings!$C$4)&".mit."&$A26&IF($C26="","","."&$C26&"."&$B26)&IF(INDEX(Variables!$D$5:$D$45,MATCH($A26,Variables!$A$5:$A$45,0))="","","."&INDEX(Variables!$D$5:$D$45,MATCH($A26,Variables!$A$5:$A$45,0)))&"."&K$5 | L26: =INDEX(Inputs!$P$5:$P$132,MATCH($B26&"|"&$C26,Inputs!$A$5:$A$132,0)) | M26: =L26*(1+$D26) | N26: =M26*(1+$D26) | O26: =N26*(1+$D26) | P26: =O26*(1+$D26) | Q26: =P26*(1+$D26) | R26: =Q26*(1+$D26) | S26: =R26*(1+$D26) | T26: =S26*(1+$D26) | ... X26: =W26*(1+$D26) | Y26: =PRETAX(X26,$D26) | Z26: =LOWER(Settings!$C$4)&".mit."&$A26&IF($C26="","","."&$C26&"."&$B26)&IF(INDEX(Variables!$D$5:$D$45,MATCH($A26,Variables!$A$5:$A$45,0))="","","."&INDEX(Variables!$D$5:$D$45,MATCH($A26,Variables!$A$5:$A$45,0)))&"."&Z$5 | AA26: =INDEX(Inputs!$P$5:$P$132,MATCH($B26&"|"&$C26,Inputs!$A$5:$A$132,0)) | AB26: =AA26*(1+$D26) | AC26: =AB26*(1+$D26) | AD26: =AC26*(1+$D26) | AE26: =AD26*(1+$D26) | AF26: =AE26*(1+$D26) | AG26: =AF26*(1+$D26) | AH26: =AG26*(1+$D26) | AI26: =AH26*(1+$D26) | ... AM26: =AL26*(1+$D26) | AN26: =PRETAX(AM26,$D26)
A27: sp | B27: nga | C27: ral | D27: =INDEX(Inputs!$O$5:$O$132,MATCH($B27&"|"&$C27,Inputs!$A$5:$A$132,0)) | H27: =INDEX(Variables!$B$5:$B$45,MATCH($A27,Variables!$A$5:$A$45,0))&IF($C27="",""," | "&INDEX(Mapping!$B$5:$B$21,MATCH($C27,Mapping!$A$5:$A$21,0))&" | "&INDEX(Mapping!$B$24:$B$32,MATCH($B27,Mapping!$A$24:$A$32,0))) | I27: =INDEX(Variables!$C$5:$C$45,MATCH($A27,Variables!$A$5:$A$45,0)) | J27: =INDEX(Variables!$E$5:$E$45,MATCH($A27,Variables!$A$5:$A$45,0)) | K27: =LOWER(Settings!$C$4)&".mit."&$A27&IF($C27="","","."&$C27&"."&$B27)&IF(INDEX(Variables!$D$5:$D$45,MATCH($A27,Variables!$A$5:$A$45,0))="","","."&INDEX(Variables!$D$5:$D$45,MATCH($A27,Variables!$A$5:$A$45,0)))&"."&K$5 | L27: =INDEX(Inputs!$P$5:$P$132,MATCH($B27&"|"&$C27,Inputs!$A$5:$A$132,0)) | M27: =L27*(1+$D27) | N27: =M27*(1+$D27) | O27: =N27*(1+$D27) | P27: =O27*(1+$D27) | Q27: =P27*(1+$D27) | R27: =Q27*(1+$D27) | S27: =R27*(1+$D27) | T27: =S27*(1+$D27) | ... X27: =W27*(1+$D27) | Y27: =PRETAX(X27,$D27) | Z27: =LOWER(Settings!$C$4)&".mit."&$A27&IF($C27="","","."&$C27&"."&$B27)&IF(INDEX(Variables!$D$5:$D$45,MATCH($A27,Variables!$A$5:$A$45,0))="","","."&INDEX(Variables!$D$5:$D$45,MATCH($A27,Variables!$A$5:$A$45,0)))&"."&Z$5 | AA27: =INDEX(Inputs!$P$5:$P$132,MATCH($B27&"|"&$C27,Inputs!$A$5:$A$132,0)) | AB27: =AA27*(1+$D27) | AC27: =AB27*(1+$D27) | AD27: =AC27*(1+$D27) | AE27: =AD27*(1+$D27) | AF27: =AE27*(1+$D27) | AG27: =AF27*(1+$D27) | AH27: =AG27*(1+$D27) | AI27: =AH27*(1+$D27) | ... AM27: =AL27*(1+$D27) | AN27: =PRETAX(AM27,$D27)
A28: sp | B28: gso | C28: ral | D28: =INDEX(Inputs!$O$5:$O$132,MATCH($B28&"|"&$C28,Inputs!$A$5:$A$132,0)) | H28: =INDEX(Variables!$B$5:$B$45,MATCH($A28,Variables!$A$5:$A$45,0))&IF($C28="",""," | "&INDEX(Mapping!$B$5:$B$21,MATCH($C28,Mapping!$A$5:$A$21,0))&" | "&INDEX(Mapping!$B$24:$B$32,MATCH($B28,Mapping!$A$24:$A$32,0))) | I28: =INDEX(Variables!$C$5:$C$45,MATCH($A28,Variables!$A$5:$A$45,0)) | J28: =INDEX(Variables!$E$5:$E$45,MATCH($A28,Variables!$A$5:$A$45,0)) | K28: =LOWER(Settings!$C$4)&".mit."&$A28&IF($C28="","","."&$C28&"."&$B28)&IF(INDEX(Variables!$D$5:$D$45,MATCH($A28,Variables!$A$5:$A$45,0))="","","."&INDEX(Variables!$D$5:$D$45,MATCH($A28,Variables!$A$5:$A$45,0)))&"."&K$5 | L28: =INDEX(Inputs!$P$5:$P$132,MATCH($B28&"|"&$C28,Inputs!$A$5:$A$132,0)) | M28: =L28*(1+$D28) | N28: =M28*(1+$D28) | O28: =N28*(1+$D28) | P28: =O28*(1+$D28) | Q28: =P28*(1+$D28) | R28: =Q28*(1+$D28) | S28: =R28*(1+$D28) | T28: =S28*(1+$D28) | ... X28: =W28*(1+$D28) | Y28: =PRETAX(X28,$D28) | Z28: =LOWER(Settings!$C$4)&".mit."&$A28&IF($C28="","","."&$C28&"."&$B28)&IF(INDEX(Variables!$D$5:$D$45,MATCH($A28,Variables!$A$5:$A$45,0))="","","."&INDEX(Variables!$D$5:$D$45,MATCH($A28,Variables!$A$5:$A$45,0)))&"."&Z$5 | AA28: =INDEX(Inputs!$P$5:$P$132,MATCH($B28&"|"&$C28,Inputs!$A$5:$A$132,0)) | AB28: =AA28*(1+$D28) | AC28: =AB28*(1+$D28) | AD28: =AC28*(1+$D28) | AE28: =AD28*(1+$D28) | AF28: =AE28*(1+$D28) | AG28: =AF28*(1+$D28) | AH28: =AG28*(1+$D28) | AI28: =AH28*(1+$D28) | ... AM28: =AL28*(1+$D28) | AN28: =PRETAX(AM28,$D28)
A29: sp | B29: die | C29: ral | D29: =INDEX(Inputs!$O$5:$O$132,MATCH($B29&"|"&$C29,Inputs!$A$5:$A$132,0)) | H29: =INDEX(Variables!$B$5:$B$45,MATCH($A29,Variables!$A$5:$A$45,0))&IF($C29="",""," | "&INDEX(Mapping!$B$5:$B$21,MATCH($C29,Mapping!$A$5:$A$21,0))&" | "&INDEX(Mapping!$B$24:$B$32,MATCH($B29,Mapping!$A$24:$A$32,0))) | I29: =INDEX(Variables!$C$5:$C$45,MATCH($A29,Variables!$A$5:$A$45,0)) | J29: =INDEX(Variables!$E$5:$E$45,MATCH($A29,Variables!$A$5:$A$45,0)) | K29: =LOWER(Settings!$C$4)&".mit."&$A29&IF($C29="","","."&$C29&"."&$B29)&IF(INDEX(Variables!$D$5:$D$45,MATCH($A29,Variables!$A$5:$A$45,0))="","","."&INDEX(Variables!$D$5:$D$45,MATCH($A29,Variables!$A$5:$A$45,0)))&"."&K$5 | L29: =INDEX(Inputs!$P$5:$P$132,MATCH($B29&"|"&$C29,Inputs!$A$5:$A$132,0)) | M29: =L29*(1+$D29) | N29: =M29*(1+$D29) | O29: =N29*(1+$D29) | P29: =O29*(1+$D29) | Q29: =P29*(1+$D29) | R29: =Q29*(1+$D29) | S29: =R29*(1+$D29) | T29: =S29*(1+$D29) | ... X29: =W29*(1+$D29) | Y29: =PRETAX(X29,$D29) | Z29: =LOWER(Settings!$C$4)&".mit."&$A29&IF($C29="","","."&$C29&"."&$B29)&IF(INDEX(Variables!$D$5:$D$45,MATCH($A29,Variables!$A$5:$A$45,0))="","","."&INDEX(Variables!$D$5:$D$45,MATCH($A29,Variables!$A$5:$A$45,0)))&"."&Z$5 | AA29: =INDEX(Inputs!$P$5:$P$132,MATCH($B29&"|"&$C29,Inputs!$A$5:$A$132,0)) | AB29: =AA29*(1+$D29) | AC29: =AB29*(1+$D29) | AD29: =AC29*(1+$D29) | AE29: =AD29*(1+$D29) | AF29: =AE29*(1+$D29) | AG29: =AF29*(1+$D29) | AH29: =AG29*(1+$D29) | AI29: =AH29*(1+$D29) | ... AM29: =AL29*(1+$D29) | AN29: =PRETAX(AM29,$D29)
... A145: sp | B145: bio | C145: oen | D145: =INDEX(Inputs!$O$5:$O$132,MATCH($B145&"|"&$C145,Inputs!$A$5:$A$132,0)) | H145: =INDEX(Variables!$B$5:$B$45,MATCH($A145,Variables!$A$5:$A$45,0))&IF($C145="",""," | "&INDEX(Mapping!$B$5:$B$21,MATCH($C145,Mapping!$A$5:$A$21,0))&" | "&INDEX(Mapping!$B$24:$B$32,MATCH($B145,Mapping!$A$24:$A$32,0))) | I145: =INDEX(Variables!$C$5:$C$45,MATCH($A145,Variables!$A$5:$A$45,0)) | J145: =INDEX(Variables!$E$5:$E$45,MATCH($A145,Variables!$A$5:$A$45,0)) | K145: =LOWER(Settings!$C$4)&".mit."&$A145&IF($C145="","","."&$C145&"."&$B145)&IF(INDEX(Variables!$D$5:$D$45,MATCH($A145,Variables!$A$5:$A$45,0))="","","."&INDEX(Variables!$D$5:$D$45,MATCH($A145,Variables!$A$5:$A$45,0)))&"."&K$5 | L145: =INDEX(Inputs!$P$5:$P$132,MATCH($B145&"|"&$C145,Inputs!$A$5:$A$132,0)) | M145: =L145*(1+$D145) | N145: =M145*(1+$D145) | O145: =N145*(1+$D145) | P145: =O145*(1+$D145) | Q145: =P145*(1+$D145) | R145: =Q145*(1+$D145) | S145: =R145*(1+$D145) | T145: =S145*(1+$D145) | ... X145: =W145*(1+$D145) | Y145: =PRETAX(X145,$D145) | Z145: =LOWER(Settings!$C$4)&".mit."&$A145&IF($C145="","","."&$C145&"."&$B145)&IF(INDEX(Variables!$D$5:$D$45,MATCH($A145,Variables!$A$5:$A$45,0))="","","."&INDEX(Variables!$D$5:$D$45,MATCH($A145,Variables!$A$5:$A$45,0)))&"."&Z$5 | AA145: =INDEX(Inputs!$P$5:$P$132,MATCH($B145&"|"&$C145,Inputs!$A$5:$A$132,0)) | AB145: =AA145*(1+$D145) | AC145: =AB145*(1+$D145) | AD145: =AC145*(1+$D145) | AE145: =AD145*(1+$D145) | AF145: =AE145*(1+$D145) | AG145: =AF145*(1+$D145) | AH145: =AG145*(1+$D145) | AI145: =AH145*(1+$D145) | ... AM145: =AL145*(1+$D145) | AN145: =PRETAX(AM145,$D145)
A147: Tax: base tax + carbon price x EF x coverage | D147: base tax | E147: EF | F147: coverage
A148: cptraj.ref | H148: =INDEX(Variables!$B$5:$B$45,MATCH($A148,Variables!$A$5:$A$45,0))&IF($C148="",""," | "&INDEX(Mapping!$B$5:$B$21,MATCH($C148,Mapping!$A$5:$A$21,0))&" | "&INDEX(Mapping!$B$24:$B$32,MATCH($B148,Mapping!$A$24:$A$32,0))) | I148: =INDEX(Variables!$C$5:$C$45,MATCH($A148,Variables!$A$5:$A$45,0)) | J148: =INDEX(Variables!$E$5:$E$45,MATCH($A148,Variables!$A$5:$A$45,0)) | K148: =LOWER(Settings!$C$4)&".mit."&$A148&IF($C148="","","."&$C148&"."&$B148)&IF(INDEX(Variables!$D$5:$D$45,MATCH($A148,Variables!$A$5:$A$45,0))="","","."&INDEX(Variables!$D$5:$D$45,MATCH($A148,Variables!$A$5:$A$45,0)))&"."&K$5 | L148: =L$14 | M148: =M$14 | N148: =N$14 | O148: =O$14 | P148: =P$14 | Q148: =Q$14 | R148: =R$14 | S148: =S$14 | ... Y148: =Y$14 | Z148: =LOWER(Settings!$C$4)&".mit."&$A148&IF($C148="","","."&$C148&"."&$B148)&IF(INDEX(Variables!$D$5:$D$45,MATCH($A148,Variables!$A$5:$A$45,0))="","","."&INDEX(Variables!$D$5:$D$45,MATCH($A148,Variables!$A$5:$A$45,0)))&"."&Z$5 | AA148: =AA$14 | AB148: =AB$14 | AC148: =AC$14 | AD148: =AD$14 | AE148: =AE$14 | AF148: =AF$14 | AG148: =AG$14 | AH148: =AH$14 | ... AN148: =AN$14
A149: tax | B149: coa | C149: rod | D149: =INDEX(Inputs!$Q$5:$Q$132,MATCH($B149&"|"&$C149,Inputs!$A$5:$A$132,0)) | E149: =INDEX(Inputs!$R$5:$R$132,MATCH($B149&"|"&$C149,Inputs!$A$5:$A$132,0)) | F149: =INDEX(Inputs!$J$5:$J$132,MATCH($B149&"|"&$C149,Inputs!$A$5:$A$132,0)) | H149: =INDEX(Variables!$B$5:$B$45,MATCH($A149,Variables!$A$5:$A$45,0))&IF($C149="",""," | "&INDEX(Mapping!$B$5:$B$21,MATCH($C149,Mapping!$A$5:$A$21,0))&" | "&INDEX(Mapping!$B$24:$B$32,MATCH($B149,Mapping!$A$24:$A$32,0))) | I149: =INDEX(Variables!$C$5:$C$45,MATCH($A149,Variables!$A$5:$A$45,0)) | J149: =INDEX(Variables!$E$5:$E$45,MATCH($A149,Variables!$A$5:$A$45,0)) | K149: =LOWER(Settings!$C$4)&".mit."&$A149&IF($C149="","","."&$C149&"."&$B149)&IF(INDEX(Variables!$D$5:$D$45,MATCH($A149,Variables!$A$5:$A$45,0))="","","."&INDEX(Variables!$D$5:$D$45,MATCH($A149,Variables!$A$5:$A$45,0)))&"."&K$5 | L149: =$D149+L$14*$E149*$F149 | M149: =$D149+M$14*$E149*$F149 | N149: =$D149+N$14*$E149*$F149 | O149: =$D149+O$14*$E149*$F149 | P149: =$D149+P$14*$E149*$F149 | Q149: =$D149+Q$14*$E149*$F149 | R149: =$D149+R$14*$E149*$F149 | S149: =$D149+S$14*$E149*$F149 | ... X149: =$D149+X$14*$E149*$F149 | Y149: =TAX($D149,Y$14,$E149,$F149) | Z149: =LOWER(Settings!$C$4)&".mit."&$A149&IF($C149="","","."&$C149&"."&$B149)&IF(INDEX(Variables!$D$5:$D$45,MATCH($A149,Variables!$A$5:$A$45,0))="","","."&INDEX(Variables!$D$5:$D$45,MATCH($A149,Variables!$A$5:$A$45,0)))&"."&Z$5 | AA149: =$D149+AA$14*$E149*$F149 | AB149: =$D149+AB$14*$E149*$F149 | AC149: =$D149+AC$14*$E149*$F149 | AD149: =$D149+AD$14*$E149*$F149 | AE149: =$D149+AE$14*$E149*$F149 | AF149: =$D149+AF$14*$E149*$F149 | AG149: =$D149+AG$14*$E149*$F149 | AH149: =$D149+AH$14*$E149*$F149 | ... AM149: =$D149+AM$14*$E149*$F149 | AN149: =TAX($D149,AN$14,$E149,$F149)
A150: tax | B150: nga | C150: rod | D150: =INDEX(Inputs!$Q$5:$Q$132,MATCH($B150&"|"&$C150,Inputs!$A$5:$A$132,0)) | E150: =INDEX(Inputs!$R$5:$R$132,MATCH($B150&"|"&$C150,Inputs!$A$5:$A$132,0)) | F150: =INDEX(Inputs!$J$5:$J$132,MATCH($B150&"|"&$C150,Inputs!$A$5:$A$132,0)) | H150: =INDEX(Variables!$B$5:$B$45,MATCH($A150,Variables!$A$5:$A$45,0))&IF($C150="",""," | "&INDEX(Mapping!$B$5:$B$21,MATCH($C150,Mapping!$A$5:$A$21,0))&" | "&INDEX(Mapping!$B$24:$B$32,MATCH($B150,Mapping!$A$24:$A$32,0))) | I150: =INDEX(Variables!$C$5:$C$45,MATCH($A150,Variables!$A$5:$A$45,0)) | J150: =INDEX(Variables!$E$5:$E$45,MATCH($A150,Variables!$A$5:$A$45,0)) | K150: =LOWER(Settings!$C$4)&".mit."&$A150&IF($C150="","","."&$C150&"."&$B150)&IF(INDEX(Variables!$D$5:$D$45,MATCH($A150,Variables!$A$5:$A$45,0))="","","."&INDEX(Variables!$D$5:$D$45,MATCH($A150,Variables!$A$5:$A$45,0)))&"."&K$5 | L150: =$D150+L$14*$E150*$F150 | M150: =$D150+M$14*$E150*$F150 | N150: =$D150+N$14*$E150*$F150 | O150: =$D150+O$14*$E150*$F150 | P150: =$D150+P$14*$E150*$F150 | Q150: =$D150+Q$14*$E150*$F150 | R150: =$D150+R$14*$E150*$F150 | S150: =$D150+S$14*$E150*$F150 | ... X150: =$D150+X$14*$E150*$F150 | Y150: =TAX($D150,Y$14,$E150,$F150) | Z150: =LOWER(Settings!$C$4)&".mit."&$A150&IF($C150="","","."&$C150&"."&$B150)&IF(INDEX(Variables!$D$5:$D$45,MATCH($A150,Variables!$A$5:$A$45,0))="","","."&INDEX(Variables!$D$5:$D$45,MATCH($A150,Variables!$A$5:$A$45,0)))&"."&Z$5 | AA150: =$D150+AA$14*$E150*$F150 | AB150: =$D150+AB$14*$E150*$F150 | AC150: =$D150+AC$14*$E150*$F150 | AD150: =$D150+AD$14*$E150*$F150 | AE150: =$D150+AE$14*$E150*$F150 | AF150: =$D150+AF$14*$E150*$F150 | AG150: =$D150+AG$14*$E150*$F150 | AH150: =$D150+AH$14*$E150*$F150 | ... AM150: =$D150+AM$14*$E150*$F150 | AN150: =TAX($D150,AN$14,$E150,$F150)
A151: tax | B151: gso | C151: rod | D151: =INDEX(Inputs!$Q$5:$Q$132,MATCH($B151&"|"&$C151,Inputs!$A$5:$A$132,0)) | E151: =INDEX(Inputs!$R$5:$R$132,MATCH($B151&"|"&$C151,Inputs!$A$5:$A$132,0)) | F151: =INDEX(Inputs!$J$5:$J$132,MATCH($B151&"|"&$C151,Inputs!$A$5:$A$132,0)) | H151: =INDEX(Variables!$B$5:$B$45,MATCH($A151,Variables!$A$5:$A$45,0))&IF($C151="",""," | "&INDEX(Mapping!$B$5:$B$21,MATCH($C151,Mapping!$A$5:$A$21,0))&" | "&INDEX(Mapping!$B$24:$B$32,MATCH($B151,Mapping!$A$24:$A$32,0))) | I151: =INDEX(Variables!$C$5:$C$45,MATCH($A151,Variables!$A$5:$A$45,0)) | J151: =INDEX(Variables!$E$5:$E$45,MATCH($A151,Variables!$A$5:$A$45,0)) | K151: =LOWER(Settings!$C$4)&".mit."&$A151&IF($C151="","","."&$C151&"."&$B151)&IF(INDEX(Variables!$D$5:$D$45,MATCH($A151,Variables!$A$5:$A$45,0))="","","."&INDEX(Variables!$D$5:$D$45,MATCH($A151,Variables!$A$5:$A$45,0)))&"."&K$5 | L151: =$D151+L$14*$E151*$F151 | M151: =$D151+M$14*$E151*$F151 | N151: =$D151+N$14*$E151*$F151 | O151: =$D151+O$14*$E151*$F151 | P151: =$D151+P$14*$E151*$F151 | Q151: =$D151+Q$14*$E151*$F151 | R151: =$D151+R$14*$E151*$F151 | S151: =$D151+S$14*$E151*$F151 | ... X151: =$D151+X$14*$E151*$F151 | Y151: =TAX($D151,Y$14,$E151,$F151) | Z151: =LOWER(Settings!$C$4)&".mit."&$A151&IF($C151="","","."&$C151&"."&$B151)&IF(INDEX(Variables!$D$5:$D$45,MATCH($A151,Variables!$A$5:$A$45,0))="","","."&INDEX(Variables!$D$5:$D$45,MATCH($A151,Variables!$A$5:$A$45,0)))&"."&Z$5 | AA151: =$D151+AA$14*$E151*$F151 | AB151: =$D151+AB$14*$E151*$F151 | AC151: =$D151+AC$14*$E151*$F151 | AD151: =$D151+AD$14*$E151*$F151 | AE151: =$D151+AE$14*$E151*$F151 | AF151: =$D151+AF$14*$E151*$F151 | AG151: =$D151+AG$14*$E151*$F151 | AH151: =$D151+AH$14*$E151*$F151 | ... AM151: =$D151+AM$14*$E151*$F151 | AN151: =TAX($D151,AN$14,$E151,$F151)
A152: tax | B152: die | C152: rod | D152: =INDEX(Inputs!$Q$5:$Q$132,MATCH($B152&"|"&$C152,Inputs!$A$5:$A$132,0)) | E152: =INDEX(Inputs!$R$5:$R$132,MATCH($B152&"|"&$C152,Inputs!$A$5:$A$132,0)) | F152: =INDEX(Inputs!$J$5:$J$132,MATCH($B152&"|"&$C152,Inputs!$A$5:$A$132,0)) | H152: =INDEX(Variables!$B$5:$B$45,MATCH($A152,Variables!$A$5:$A$45,0))&IF($C152="",""," | "&INDEX(Mapping!$B$5:$B$21,MATCH($C152,Mapping!$A$5:$A$21,0))&" | "&INDEX(Mapping!$B$24:$B$32,MATCH($B152,Mapping!$A$24:$A$32,0))) | I152: =INDEX(Variables!$C$5:$C$45,MATCH($A152,Variables!$A$5:$A$45,0)) | J152: =INDEX(Variables!$E$5:$E$45,MATCH($A152,Variables!$A$5:$A$45,0)) | K152: =LOWER(Settings!$C$4)&".mit."&$A152&IF($C152="","","."&$C152&"."&$B152)&IF(INDEX(Variables!$D$5:$D$45,MATCH($A152,Variables!$A$5:$A$45,0))="","","."&INDEX(Variables!$D$5:$D$45,MATCH($A152,Variables!$A$5:$A$45,0)))&"."&K$5 | L152: =$D152+L$14*$E152*$F152 | M152: =$D152+M$14*$E152*$F152 | N152: =$D152+N$14*$E152*$F152 | O152: =$D152+O$14*$E152*$F152 | P152: =$D152+P$14*$E152*$F152 | Q152: =$D152+Q$14*$E152*$F152 | R152: =$D152+R$14*$E152*$F152 | S152: =$D152+S$14*$E152*$F152 | ... X152: =$D152+X$14*$E152*$F152 | Y152: =TAX($D152,Y$14,$E152,$F152) | Z152: =LOWER(Settings!$C$4)&".mit."&$A152&IF($C152="","","."&$C152&"."&$B152)&IF(INDEX(Variables!$D$5:$D$45,MATCH($A152,Variables!$A$5:$A$45,0))="","","."&INDEX(Variables!$D$5:$D$45,MATCH($A152,Variables!$A$5:$A$45,0)))&"."&Z$5 | AA152: =$D152+AA$14*$E152*$F152 | AB152: =$D152+AB$14*$E152*$F152 | AC152: =$D152+AC$14*$E152*$F152 | AD152: =$D152+AD$14*$E152*$F152 | AE152: =$D152+AE$14*$E152*$F152 | AF152: =$D152+AF$14*$E152*$F152 | AG152: =$D152+AG$14*$E152*$F152 | AH152: =$D152+AH$14*$E152*$F152 | ... AM152: =$D152+AM$14*$E152*$F152 | AN152: =TAX($D152,AN$14,$E152,$F152)
