Workbook
Name OBRSHARE: _xlfn.LAMBDA(_xlpm.benchmark,MIN(1,MAX(0,_xlpm.benchmark)))
Name COVERED: _xlfn.LAMBDA(_xlpm.emissions,_xlpm.coverage,SUMPRODUCT(_xlpm.emissions,_xlpm.coverage))
Name TAXEQUIV: _xlfn.LAMBDA(_xlpm.price,_xlpm.vadj,_xlpm.price*_xlpm.vadj)
Name REVFACTOR: _xlfn.LAMBDA(_xlpm.vadj,IF(_xlpm.vadj>0,1/_xlpm.vadj,0))
Name ETSCOVER: _xlfn.LAMBDA(_xlpm.apply,_xlpm.year,_xlpm.start_year,_xlpm.covered,IF(AND(LEFT(_xlpm.apply,3)="Yes",_xlpm.year>=_xlpm.start_year),IF(_xlpm.covered,1,0),0))
Name SHADOWSECTOR: _xlfn.LAMBDA(_xlpm.feebate,_xlpm.regulation,_xlpm.feebate+_xlpm.regulation)
Name SHADOWSHARE: _xlfn.LAMBDA(_xlpm.coverage,_xlpm.adjustment,IF(_xlpm.coverage,1,0)*_xlpm.adjustment)
Name RETAILPRICE: _xlfn.LAMBDA(_xlpm.sp,_xlpm.txo,_xlpm.vat_rate,(_xlpm.sp+_xlpm.txo)*(1+_xlpm.vat_rate))
Name VATPAY: _xlfn.LAMBDA(_xlpm.sp,_xlpm.txo,_xlpm.vat_rate,(_xlpm.sp+_xlpm.txo)*_xlpm.vat_rate)
Name TAXPART: _xlfn.LAMBDA(_xlpm.txo,MAX(_xlpm.txo,0))
Name SUBSIDYPART: _xlfn.LAMBDA(_xlpm.txo,MAX(-_xlpm.txo,0))
Name PERUNIT: _xlfn.LAMBDA(_xlpm.value_gj,_xlpm.gj_per_unit,_xlpm.value_gj*_xlpm.gj_per_unit)
Name CARBONTAX: _xlfn.LAMBDA(_xlpm.price,_xlpm.ef,_xlpm.fuel_cov,_xlpm.sector_cov,_xlpm.ets_cov,_xlpm.price*_xlpm.ef*_xlpm.fuel_cov*_xlpm.sector_cov*(1-_xlpm.ets_cov))
Name ETSCOST: _xlfn.LAMBDA(_xlpm.price,_xlpm.ef,_xlpm.ets_cov,_xlpm.obr,_xlpm.price*_xlpm.ef*_xlpm.ets_cov*(1-_xlpm.obr))
Name NEWEXCISE: _xlfn.LAMBDA(_xlpm.increase,_xlpm.gj_per_unit,_xlpm.increase/_xlpm.gj_per_unit)
Name NEWPOLICY: _xlfn.LAMBDA(_xlpm.carbon_tax,_xlpm.ets,_xlpm.excise,_xlpm.carbon_tax+_xlpm.ets+_xlpm.excise)
Name POSTTAX: _xlfn.LAMBDA(_xlpm.pre_policy_p,_xlpm.new_policy,_xlpm.vat_rate,MAX(_xlpm.pre_policy_p+_xlpm.new_policy*(1+_xlpm.vat_rate),0.01))
Name SHADOWEFF: _xlfn.LAMBDA(_xlpm.sector_price,_xlpm.share,_xlpm.ets_price,_xlpm.ets_cov,_xlpm.obr,_xlpm.ef,(_xlpm.sector_price*_xlpm.share+_xlpm.ets_price*_xlpm.ets_cov*_xlpm.obr)*_xlpm.ef)
Name REVENUE: _xlfn.LAMBDA(_xlpm.fuel_use,_xlpm.pj_per_ktoe,_xlpm.rate,_xlpm.fuel_use*_xlpm.pj_per_ktoe*_xlpm.rate)
Name EMISSIONS: _xlfn.LAMBDA(_xlpm.fuel_use,_xlpm.pj_per_ktoe,_xlpm.ef,_xlpm.fuel_use*_xlpm.pj_per_ktoe*_xlpm.ef)
Name NEWREVRATE: _xlfn.LAMBDA(_xlpm.carbon_tax,_xlpm.excise,_xlpm.ets,_xlpm.rev_factor,_xlpm.new_policy,_xlpm.vat_rate,_xlpm.carbon_tax+_xlpm.excise+_xlpm.ets*_xlpm.rev_factor+_xlpm.new_policy*_xlpm.vat_rate)

Sheet Mitigation
A1: Variable | B1: Fuel | C1: Sector | D1: Param 1 | E1: Param 2 | F1: Param 3 | G1: Param 4 | H1: Description | I1: Unit | J1: Source | K1: Scenario 1: output code | AF1: Scenario 2: output code
A2: CPAT-AI-Mitigation-MVP v1.02 - mitigation module: policies, prices, fuel use, revenues, CO2 (copy-pasteable)
A3: Scenario assumptions (one column group per scenario: code column + years; copy a whole group to add a scenario)
H4: Year | L4: =Settings!$C$7 | M4: =L4+1 | N4: =M4+1 | O4: =N4+1 | P4: =O4+1 | Q4: =P4+1 | R4: =Q4+1 | S4: =R4+1 | T4: =S4+1 | ... AD4: =AC4+1 | AG4: =Settings!$C$7 | AH4: =AG4+1 | AI4: =AH4+1 | AJ4: =AI4+1 | AK4: =AJ4+1 | AL4: =AK4+1 | AM4: =AL4+1 | AN4: =AM4+1 | AO4: =AN4+1 | ... AY4: =AX4+1
H5: Scenario number (MTInputs column) | K5: 1 | L5: =K5 | M5: =L5 | N5: =M5 | O5: =N5 | P5: =O5 | Q5: =P5 | R5: =Q5 | S5: =R5 | ... AD5: =AC5 | AF5: =K5+1 | AG5: =AF5 | AH5: =AG5 | AI5: =AH5 | AJ5: =AI5 | AK5: =AJ5 | AL5: =AK5 | AM5: =AL5 | AN5: =AM5 | ... AY5: =AX5
H6: Scenario name (from MTInputs) | L6: =INDEX(MTInputs!$J$6:$AZ$6,MATCH(L$5,MTInputs!$J$5:$AZ$5,0)) | AG6: =INDEX(MTInputs!$J$6:$AZ$6,MATCH(AG$5,MTInputs!$J$5:$AZ$5,0))
A7: gdp.pos.pct | H7: =INDEX(Variables!$B$5:$B$105,MATCH($A7,Variables!$A$5:$A$105,0))&IF($C7="",""," | "&INDEX(Mapping!$B$5:$B$26,MATCH($C7,Mapping!$A$5:$A$26,0))&" | "&INDEX(Mapping!$B$30:$B$41,MATCH($B7,Mapping!$A$30:$A$41,0))) | I7: =INDEX(Variables!$C$5:$C$105,MATCH($A7,Variables!$A$5:$A$105,0)) | J7: =INDEX(Variables!$E$5:$E$105,MATCH($A7,Variables!$A$5:$A$105,0)) | K7: =LOWER(Settings!$C$4)&".mit."&$A7&IF($C7="","","."&$C7&"."&$B7)&IF(INDEX(Variables!$D$5:$D$105,MATCH($A7,Variables!$A$5:$A$105,0))="","","."&INDEX(Variables!$D$5:$D$105,MATCH($A7,Variables!$A$5:$A$105,0)))&"."&K$5 | L7: =INDEX(WEO!$F$4:$AZ$1000,MATCH(Settings!$C$4&"|gdp_growth",WEO!$A$4:$A$1000,0),MATCH(L$4,WEO!$F$3:$AZ$3,0)) | M7: =INDEX(WEO!$F$4:$AZ$1000,MATCH(Settings!$C$4&"|gdp_growth",WEO!$A$4:$A$1000,0),MATCH(M$4,WEO!$F$3:$AZ$3,0)) | N7: =INDEX(WEO!$F$4:$AZ$1000,MATCH(Settings!$C$4&"|gdp_growth",WEO!$A$4:$A$1000,0),MATCH(N$4,WEO!$F$3:$AZ$3,0)) | O7: =INDEX(WEO!$F$4:$AZ$1000,MATCH(Settings!$C$4&"|gdp_growth",WEO!$A$4:$A$1000,0),MATCH(O$4,WEO!$F$3:$AZ$3,0)) | P7: =INDEX(WEO!$F$4:$AZ$1000,MATCH(Settings!$C$4&"|gdp_growth",WEO!$A$4:$A$1000,0),MATCH(P$4,WEO!$F$3:$AZ$3,0)) | Q7: =INDEX(WEO!$F$4:$AZ$1000,MATCH(Settings!$C$4&"|gdp_growth",WEO!$A$4:$A$1000,0),MATCH(Q$4,WEO!$F$3:$AZ$3,0)) | R7: =INDEX(WEO!$F$4:$AZ$1000,MATCH(Settings!$C$4&"|gdp_growth",WEO!$A$4:$A$1000,0),MATCH(R$4,WEO!$F$3:$AZ$3,0)) | S7: =INDEX(WEO!$F$4:$AZ$1000,MATCH(Settings!$C$4&"|gdp_growth",WEO!$A$4:$A$1000,0),MATCH(S$4,WEO!$F$3:$AZ$3,0)) | ... AD7: =INDEX(WEO!$F$4:$AZ$1000,MATCH(Settings!$C$4&"|gdp_growth",WEO!$A$4:$A$1000,0),MATCH(AD$4,WEO!$F$3:$AZ$3,0)) | AF7: =LOWER(Settings!$C$4)&".mit."&$A7&IF($C7="","","."&$C7&"."&$B7)&IF(INDEX(Variables!$D$5:$D$105,MATCH($A7,Variables!$A$5:$A$105,0))="","","."&INDEX(Variables!$D$5:$D$105,MATCH($A7,Variables!$A$5:$A$105,0)))&"."&AF$5 | AG7: =INDEX(WEO!$F$4:$AZ$1000,MATCH(Settings!$C$4&"|gdp_growth",WEO!$A$4:$A$1000,0),MATCH(AG$4,WEO!$F$3:$AZ$3,0)) | AH7: =INDEX(WEO!$F$4:$AZ$1000,MATCH(Settings!$C$4&"|gdp_growth",WEO!$A$4:$A$1000,0),MATCH(AH$4,WEO!$F$3:$AZ$3,0)) | AI7: =INDEX(WEO!$F$4:$AZ$1000,MATCH(Settings!$C$4&"|gdp_growth",WEO!$A$4:$A$1000,0),MATCH(AI$4,WEO!$F$3:$AZ$3,0)) | AJ7: =INDEX(WEO!$F$4:$AZ$1000,MATCH(Settings!$C$4&"|gdp_growth",WEO!$A$4:$A$1000,0),MATCH(AJ$4,WEO!$F$3:$AZ$3,0)) | AK7: =INDEX(WEO!$F$4:$AZ$1000,MATCH(Settings!$C$4&"|gdp_growth",WEO!$A$4:$A$1000,0),MATCH(AK$4,WEO!$F$3:$AZ$3,0)) | AL7: =INDEX(WEO!$F$4:$AZ$1000,MATCH(Settings!$C$4&"|gdp_growth",WEO!$A$4:$A$1000,0),MATCH(AL$4,WEO!$F$3:$AZ$3,0)) | AM7: =INDEX(WEO!$F$4:$AZ$1000,MATCH(Settings!$C$4&"|gdp_growth",WEO!$A$4:$A$1000,0),MATCH(AM$4,WEO!$F$3:$AZ$3,0)) | AN7: =INDEX(WEO!$F$4:$AZ$1000,MATCH(Settings!$C$4&"|gdp_growth",WEO!$A$4:$A$1000,0),MATCH(AN$4,WEO!$F$3:$AZ$3,0)) | ... AY7: =INDEX(WEO!$F$4:$AZ$1000,MATCH(Settings!$C$4&"|gdp_growth",WEO!$A$4:$A$1000,0),MATCH(AY$4,WEO!$F$3:$AZ$3,0))
A8: infl | H8: =INDEX(Variables!$B$5:$B$105,MATCH($A8,Variables!$A$5:$A$105,0))&IF($C8="",""," | "&INDEX(Mapping!$B$5:$B$26,MATCH($C8,Mapping!$A$5:$A$26,0))&" | "&INDEX(Mapping!$B$30:$B$41,MATCH($B8,Mapping!$A$30:$A$41,0))) | I8: =INDEX(Variables!$C$5:$C$105,MATCH($A8,Variables!$A$5:$A$105,0)) | J8: =INDEX(Variables!$E$5:$E$105,MATCH($A8,Variables!$A$5:$A$105,0)) | K8: =LOWER(Settings!$C$4)&".mit."&$A8&IF($C8="","","."&$C8&"."&$B8)&IF(INDEX(Variables!$D$5:$D$105,MATCH($A8,Variables!$A$5:$A$105,0))="","","."&INDEX(Variables!$D$5:$D$105,MATCH($A8,Variables!$A$5:$A$105,0)))&"."&K$5 | L8: =INDEX(WEO!$F$4:$AZ$1000,MATCH("USA|pcpi",WEO!$A$4:$A$1000,0),MATCH(Settings!$C$8,WEO!$F$3:$AZ$3,0))/INDEX(WEO!$F$4:$AZ$1000,MATCH("USA|pcpi",WEO!$A$4:$A$1000,0),MATCH(L$4,WEO!$F$3:$AZ$3,0)) | M8: =INDEX(WEO!$F$4:$AZ$1000,MATCH("USA|pcpi",WEO!$A$4:$A$1000,0),MATCH(Settings!$C$8,WEO!$F$3:$AZ$3,0))/INDEX(WEO!$F$4:$AZ$1000,MATCH("USA|pcpi",WEO!$A$4:$A$1000,0),MATCH(M$4,WEO!$F$3:$AZ$3,0)) | N8: =INDEX(WEO!$F$4:$AZ$1000,MATCH("USA|pcpi",WEO!$A$4:$A$1000,0),MATCH(Settings!$C$8,WEO!$F$3:$AZ$3,0))/INDEX(WEO!$F$4:$AZ$1000,MATCH("USA|pcpi",WEO!$A$4:$A$1000,0),MATCH(N$4,WEO!$F$3:$AZ$3,0)) | O8: =INDEX(WEO!$F$4:$AZ$1000,MATCH("USA|pcpi",WEO!$A$4:$A$1000,0),MATCH(Settings!$C$8,WEO!$F$3:$AZ$3,0))/INDEX(WEO!$F$4:$AZ$1000,MATCH("USA|pcpi",WEO!$A$4:$A$1000,0),MATCH(O$4,WEO!$F$3:$AZ$3,0)) | P8: =INDEX(WEO!$F$4:$AZ$1000,MATCH("USA|pcpi",WEO!$A$4:$A$1000,0),MATCH(Settings!$C$8,WEO!$F$3:$AZ$3,0))/INDEX(WEO!$F$4:$AZ$1000,MATCH("USA|pcpi",WEO!$A$4:$A$1000,0),MATCH(P$4,WEO!$F$3:$AZ$3,0)) | Q8: =INDEX(WEO!$F$4:$AZ$1000,MATCH("USA|pcpi",WEO!$A$4:$A$1000,0),MATCH(Settings!$C$8,WEO!$F$3:$AZ$3,0))/INDEX(WEO!$F$4:$AZ$1000,MATCH("USA|pcpi",WEO!$A$4:$A$1000,0),MATCH(Q$4,WEO!$F$3:$AZ$3,0)) | R8: =INDEX(WEO!$F$4:$AZ$1000,MATCH("USA|pcpi",WEO!$A$4:$A$1000,0),MATCH(Settings!$C$8,WEO!$F$3:$AZ$3,0))/INDEX(WEO!$F$4:$AZ$1000,MATCH("USA|pcpi",WEO!$A$4:$A$1000,0),MATCH(R$4,WEO!$F$3:$AZ$3,0)) | S8: =INDEX(WEO!$F$4:$AZ$1000,MATCH("USA|pcpi",WEO!$A$4:$A$1000,0),MATCH(Settings!$C$8,WEO!$F$3:$AZ$3,0))/INDEX(WEO!$F$4:$AZ$1000,MATCH("USA|pcpi",WEO!$A$4:$A$1000,0),MATCH(S$4,WEO!$F$3:$AZ$3,0)) | ... AD8: =INDEX(WEO!$F$4:$AZ$1000,MATCH("USA|pcpi",WEO!$A$4:$A$1000,0),MATCH(Settings!$C$8,WEO!$F$3:$AZ$3,0))/INDEX(WEO!$F$4:$AZ$1000,MATCH("USA|pcpi",WEO!$A$4:$A$1000,0),MATCH(AD$4,WEO!$F$3:$AZ$3,0)) | AF8: =LOWER(Settings!$C$4)&".mit."&$A8&IF($C8="","","."&$C8&"."&$B8)&IF(INDEX(Variables!$D$5:$D$105,MATCH($A8,Variables!$A$5:$A$105,0))="","","."&INDEX(Variables!$D$5:$D$105,MATCH($A8,Variables!$A$5:$A$105,0)))&"."&AF$5 | AG8: =INDEX(WEO!$F$4:$AZ$1000,MATCH("USA|pcpi",WEO!$A$4:$A$1000,0),MATCH(Settings!$C$8,WEO!$F$3:$AZ$3,0))/INDEX(WEO!$F$4:$AZ$1000,MATCH("USA|pcpi",WEO!$A$4:$A$1000,0),MATCH(AG$4,WEO!$F$3:$AZ$3,0)) | AH8: =INDEX(WEO!$F$4:$AZ$1000,MATCH("USA|pcpi",WEO!$A$4:$A$1000,0),MATCH(Settings!$C$8,WEO!$F$3:$AZ$3,0))/INDEX(WEO!$F$4:$AZ$1000,MATCH("USA|pcpi",WEO!$A$4:$A$1000,0),MATCH(AH$4,WEO!$F$3:$AZ$3,0)) | AI8: =INDEX(WEO!$F$4:$AZ$1000,MATCH("USA|pcpi",WEO!$A$4:$A$1000,0),MATCH(Settings!$C$8,WEO!$F$3:$AZ$3,0))/INDEX(WEO!$F$4:$AZ$1000,MATCH("USA|pcpi",WEO!$A$4:$A$1000,0),MATCH(AI$4,WEO!$F$3:$AZ$3,0)) | AJ8: =INDEX(WEO!$F$4:$AZ$1000,MATCH("USA|pcpi",WEO!$A$4:$A$1000,0),MATCH(Settings!$C$8,WEO!$F$3:$AZ$3,0))/INDEX(WEO!$F$4:$AZ$1000,MATCH("USA|pcpi",WEO!$A$4:$A$1000,0),MATCH(AJ$4,WEO!$F$3:$AZ$3,0)) | AK8: =INDEX(WEO!$F$4:$AZ$1000,MATCH("USA|pcpi",WEO!$A$4:$A$1000,0),MATCH(Settings!$C$8,WEO!$F$3:$AZ$3,0))/INDEX(WEO!$F$4:$AZ$1000,MATCH("USA|pcpi",WEO!$A$4:$A$1000,0),MATCH(AK$4,WEO!$F$3:$AZ$3,0)) | AL8: =INDEX(WEO!$F$4:$AZ$1000,MATCH("USA|pcpi",WEO!$A$4:$A$1000,0),MATCH(Settings!$C$8,WEO!$F$3:$AZ$3,0))/INDEX(WEO!$F$4:$AZ$1000,MATCH("USA|pcpi",WEO!$A$4:$A$1000,0),MATCH(AL$4,WEO!$F$3:$AZ$3,0)) | AM8: =INDEX(WEO!$F$4:$AZ$1000,MATCH("USA|pcpi",WEO!$A$4:$A$1000,0),MATCH(Settings!$C$8,WEO!$F$3:$AZ$3,0))/INDEX(WEO!$F$4:$AZ$1000,MATCH("USA|pcpi",WEO!$A$4:$A$1000,0),MATCH(AM$4,WEO!$F$3:$AZ$3,0)) | AN8: =INDEX(WEO!$F$4:$AZ$1000,MATCH("USA|pcpi",WEO!$A$4:$A$1000,0),MATCH(Settings!$C$8,WEO!$F$3:$AZ$3,0))/INDEX(WEO!$F$4:$AZ$1000,MATCH("USA|pcpi",WEO!$A$4:$A$1000,0),MATCH(AN$4,WEO!$F$3:$AZ$3,0)) | ... AY8: =INDEX(WEO!$F$4:$AZ$1000,MATCH("USA|pcpi",WEO!$A$4:$A$1000,0),MATCH(Settings!$C$8,WEO!$F$3:$AZ$3,0))/INDEX(WEO!$F$4:$AZ$1000,MATCH("USA|pcpi",WEO!$A$4:$A$1000,0),MATCH(AY$4,WEO!$F$3:$AZ$3,0))
A9: defl | H9: =INDEX(Variables!$B$5:$B$105,MATCH($A9,Variables!$A$5:$A$105,0))&IF($C9="",""," | "&INDEX(Mapping!$B$5:$B$26,MATCH($C9,Mapping!$A$5:$A$26,0))&" | "&INDEX(Mapping!$B$30:$B$41,MATCH($B9,Mapping!$A$30:$A$41,0))) | I9: =INDEX(Variables!$C$5:$C$105,MATCH($A9,Variables!$A$5:$A$105,0)) | J9: =INDEX(Variables!$E$5:$E$105,MATCH($A9,Variables!$A$5:$A$105,0)) | K9: =LOWER(Settings!$C$4)&".mit."&$A9&IF($C9="","","."&$C9&"."&$B9)&IF(INDEX(Variables!$D$5:$D$105,MATCH($A9,Variables!$A$5:$A$105,0))="","","."&INDEX(Variables!$D$5:$D$105,MATCH($A9,Variables!$A$5:$A$105,0)))&"."&K$5 | L9: =INDEX(WEO!$F$4:$AZ$1000,MATCH("USA|ngdp_d",WEO!$A$4:$A$1000,0),MATCH(Settings!$C$8,WEO!$F$3:$AZ$3,0))/INDEX(WEO!$F$4:$AZ$1000,MATCH("USA|ngdp_d",WEO!$A$4:$A$1000,0),MATCH(L$4,WEO!$F$3:$AZ$3,0)) | M9: =INDEX(WEO!$F$4:$AZ$1000,MATCH("USA|ngdp_d",WEO!$A$4:$A$1000,0),MATCH(Settings!$C$8,WEO!$F$3:$AZ$3,0))/INDEX(WEO!$F$4:$AZ$1000,MATCH("USA|ngdp_d",WEO!$A$4:$A$1000,0),MATCH(M$4,WEO!$F$3:$AZ$3,0)) | N9: =INDEX(WEO!$F$4:$AZ$1000,MATCH("USA|ngdp_d",WEO!$A$4:$A$1000,0),MATCH(Settings!$C$8,WEO!$F$3:$AZ$3,0))/INDEX(WEO!$F$4:$AZ$1000,MATCH("USA|ngdp_d",WEO!$A$4:$A$1000,0),MATCH(N$4,WEO!$F$3:$AZ$3,0)) | O9: =INDEX(WEO!$F$4:$AZ$1000,MATCH("USA|ngdp_d",WEO!$A$4:$A$1000,0),MATCH(Settings!$C$8,WEO!$F$3:$AZ$3,0))/INDEX(WEO!$F$4:$AZ$1000,MATCH("USA|ngdp_d",WEO!$A$4:$A$1000,0),MATCH(O$4,WEO!$F$3:$AZ$3,0)) | P9: =INDEX(WEO!$F$4:$AZ$1000,MATCH("USA|ngdp_d",WEO!$A$4:$A$1000,0),MATCH(Settings!$C$8,WEO!$F$3:$AZ$3,0))/INDEX(WEO!$F$4:$AZ$1000,MATCH("USA|ngdp_d",WEO!$A$4:$A$1000,0),MATCH(P$4,WEO!$F$3:$AZ$3,0)) | Q9: =INDEX(WEO!$F$4:$AZ$1000,MATCH("USA|ngdp_d",WEO!$A$4:$A$1000,0),MATCH(Settings!$C$8,WEO!$F$3:$AZ$3,0))/INDEX(WEO!$F$4:$AZ$1000,MATCH("USA|ngdp_d",WEO!$A$4:$A$1000,0),MATCH(Q$4,WEO!$F$3:$AZ$3,0)) | R9: =INDEX(WEO!$F$4:$AZ$1000,MATCH("USA|ngdp_d",WEO!$A$4:$A$1000,0),MATCH(Settings!$C$8,WEO!$F$3:$AZ$3,0))/INDEX(WEO!$F$4:$AZ$1000,MATCH("USA|ngdp_d",WEO!$A$4:$A$1000,0),MATCH(R$4,WEO!$F$3:$AZ$3,0)) | S9: =INDEX(WEO!$F$4:$AZ$1000,MATCH("USA|ngdp_d",WEO!$A$4:$A$1000,0),MATCH(Settings!$C$8,WEO!$F$3:$AZ$3,0))/INDEX(WEO!$F$4:$AZ$1000,MATCH("USA|ngdp_d",WEO!$A$4:$A$1000,0),MATCH(S$4,WEO!$F$3:$AZ$3,0)) | ... AD9: =INDEX(WEO!$F$4:$AZ$1000,MATCH("USA|ngdp_d",WEO!$A$4:$A$1000,0),MATCH(Settings!$C$8,WEO!$F$3:$AZ$3,0))/INDEX(WEO!$F$4:$AZ$1000,MATCH("USA|ngdp_d",WEO!$A$4:$A$1000,0),MATCH(AD$4,WEO!$F$3:$AZ$3,0)) | AF9: =LOWER(Settings!$C$4)&".mit."&$A9&IF($C9="","","."&$C9&"."&$B9)&IF(INDEX(Variables!$D$5:$D$105,MATCH($A9,Variables!$A$5:$A$105,0))="","","."&INDEX(Variables!$D$5:$D$105,MATCH($A9,Variables!$A$5:$A$105,0)))&"."&AF$5 | AG9: =INDEX(WEO!$F$4:$AZ$1000,MATCH("USA|ngdp_d",WEO!$A$4:$A$1000,0),MATCH(Settings!$C$8,WEO!$F$3:$AZ$3,0))/INDEX(WEO!$F$4:$AZ$1000,MATCH("USA|ngdp_d",WEO!$A$4:$A$1000,0),MATCH(AG$4,WEO!$F$3:$AZ$3,0)) | AH9: =INDEX(WEO!$F$4:$AZ$1000,MATCH("USA|ngdp_d",WEO!$A$4:$A$1000,0),MATCH(Settings!$C$8,WEO!$F$3:$AZ$3,0))/INDEX(WEO!$F$4:$AZ$1000,MATCH("USA|ngdp_d",WEO!$A$4:$A$1000,0),MATCH(AH$4,WEO!$F$3:$AZ$3,0)) | AI9: =INDEX(WEO!$F$4:$AZ$1000,MATCH("USA|ngdp_d",WEO!$A$4:$A$1000,0),MATCH(Settings!$C$8,WEO!$F$3:$AZ$3,0))/INDEX(WEO!$F$4:$AZ$1000,MATCH("USA|ngdp_d",WEO!$A$4:$A$1000,0),MATCH(AI$4,WEO!$F$3:$AZ$3,0)) | AJ9: =INDEX(WEO!$F$4:$AZ$1000,MATCH("USA|ngdp_d",WEO!$A$4:$A$1000,0),MATCH(Settings!$C$8,WEO!$F$3:$AZ$3,0))/INDEX(WEO!$F$4:$AZ$1000,MATCH("USA|ngdp_d",WEO!$A$4:$A$1000,0),MATCH(AJ$4,WEO!$F$3:$AZ$3,0)) | AK9: =INDEX(WEO!$F$4:$AZ$1000,MATCH("USA|ngdp_d",WEO!$A$4:$A$1000,0),MATCH(Settings!$C$8,WEO!$F$3:$AZ$3,0))/INDEX(WEO!$F$4:$AZ$1000,MATCH("USA|ngdp_d",WEO!$A$4:$A$1000,0),MATCH(AK$4,WEO!$F$3:$AZ$3,0)) | AL9: =INDEX(WEO!$F$4:$AZ$1000,MATCH("USA|ngdp_d",WEO!$A$4:$A$1000,0),MATCH(Settings!$C$8,WEO!$F$3:$AZ$3,0))/INDEX(WEO!$F$4:$AZ$1000,MATCH("USA|ngdp_d",WEO!$A$4:$A$1000,0),MATCH(AL$4,WEO!$F$3:$AZ$3,0)) | AM9: =INDEX(WEO!$F$4:$AZ$1000,MATCH("USA|ngdp_d",WEO!$A$4:$A$1000,0),MATCH(Settings!$C$8,WEO!$F$3:$AZ$3,0))/INDEX(WEO!$F$4:$AZ$1000,MATCH("USA|ngdp_d",WEO!$A$4:$A$1000,0),MATCH(AM$4,WEO!$F$3:$AZ$3,0)) | AN9: =INDEX(WEO!$F$4:$AZ$1000,MATCH("USA|ngdp_d",WEO!$A$4:$A$1000,0),MATCH(Settings!$C$8,WEO!$F$3:$AZ$3,0))/INDEX(WEO!$F$4:$AZ$1000,MATCH("USA|ngdp_d",WEO!$A$4:$A$1000,0),MATCH(AN$4,WEO!$F$3:$AZ$3,0)) | ... AY9: =INDEX(WEO!$F$4:$AZ$1000,MATCH("USA|ngdp_d",WEO!$A$4:$A$1000,0),MATCH(Settings!$C$8,WEO!$F$3:$AZ$3,0))/INDEX(WEO!$F$4:$AZ$1000,MATCH("USA|ngdp_d",WEO!$A$4:$A$1000,0),MATCH(AY$4,WEO!$F$3:$AZ$3,0))
A11: 1. Policies (scenario inputs from MTInputs by row and scenario number; policy paths) | D11: MTInputs row
A12: cptraj | H12: =INDEX(Variables!$B$5:$B$105,MATCH($A12,Variables!$A$5:$A$105,0))&IF($C12="",""," | "&INDEX(Mapping!$B$5:$B$26,MATCH($C12,Mapping!$A$5:$A$26,0))&" | "&INDEX(Mapping!$B$30:$B$41,MATCH($B12,Mapping!$A$30:$A$41,0))) | I12: =INDEX(Variables!$C$5:$C$105,MATCH($A12,Variables!$A$5:$A$105,0)) | J12: =INDEX(Variables!$E$5:$E$105,MATCH($A12,Variables!$A$5:$A$105,0)) | K12: =LOWER(Settings!$C$4)&".mit."&$A12&IF($C12="","","."&$C12&"."&$B12)&IF(INDEX(Variables!$D$5:$D$105,MATCH($A12,Variables!$A$5:$A$105,0))="","","."&INDEX(Variables!$D$5:$D$105,MATCH($A12,Variables!$A$5:$A$105,0)))&"."&K$5 | L12: =(IF(L$4<L$14,0,L$15+(L$16-L$15)/MAX(L$17-L$14,1)*IF(OR(L$4<=L$17,L$18="Linear*"),L$4-L$14,L$17-L$14)))*IF(LEFT(L$19,7)="Nominal",L$8,1) | M12: =(IF(M$4<M$14,0,M$15+(M$16-M$15)/MAX(M$17-M$14,1)*IF(OR(M$4<=M$17,M$18="Linear*"),M$4-M$14,M$17-M$14)))*IF(LEFT(M$19,7)="Nominal",M$8,1) | N12: =(IF(N$4<N$14,0,N$15+(N$16-N$15)/MAX(N$17-N$14,1)*IF(OR(N$4<=N$17,N$18="Linear*"),N$4-N$14,N$17-N$14)))*IF(LEFT(N$19,7)="Nominal",N$8,1) | O12: =(IF(O$4<O$14,0,O$15+(O$16-O$15)/MAX(O$17-O$14,1)*IF(OR(O$4<=O$17,O$18="Linear*"),O$4-O$14,O$17-O$14)))*IF(LEFT(O$19,7)="Nominal",O$8,1) | P12: =(IF(P$4<P$14,0,P$15+(P$16-P$15)/MAX(P$17-P$14,1)*IF(OR(P$4<=P$17,P$18="Linear*"),P$4-P$14,P$17-P$14)))*IF(LEFT(P$19,7)="Nominal",P$8,1) | Q12: =(IF(Q$4<Q$14,0,Q$15+(Q$16-Q$15)/MAX(Q$17-Q$14,1)*IF(OR(Q$4<=Q$17,Q$18="Linear*"),Q$4-Q$14,Q$17-Q$14)))*IF(LEFT(Q$19,7)="Nominal",Q$8,1) | R12: =(IF(R$4<R$14,0,R$15+(R$16-R$15)/MAX(R$17-R$14,1)*IF(OR(R$4<=R$17,R$18="Linear*"),R$4-R$14,R$17-R$14)))*IF(LEFT(R$19,7)="Nominal",R$8,1) | S12: =(IF(S$4<S$14,0,S$15+(S$16-S$15)/MAX(S$17-S$14,1)*IF(OR(S$4<=S$17,S$18="Linear*"),S$4-S$14,S$17-S$14)))*IF(LEFT(S$19,7)="Nominal",S$8,1) | ... AC12: =(IF(AC$4<AC$14,0,AC$15+(AC$16-AC$15)/MAX(AC$17-AC$14,1)*IF(OR(AC$4<=AC$17,AC$18="Linear*"),AC$4-AC$14,AC$17-AC$14)))*IF(LEFT(AC$19,7)="Nominal",AC$8,1) | AD12: =PATH(AD$4,AD$14,AD$17,AD$15,AD$16,AD$18="Linear*")*IF(LEFT(AD$19,7)="Nominal",AD$8,1) | AF12: =LOWER(Settings!$C$4)&".mit."&$A12&IF($C12="","","."&$C12&"."&$B12)&IF(INDEX(Variables!$D$5:$D$105,MATCH($A12,Variables!$A$5:$A$105,0))="","","."&INDEX(Variables!$D$5:$D$105,MATCH($A12,Variables!$A$5:$A$105,0)))&"."&AF$5 | AG12: =(IF(AG$4<AG$14,0,AG$15+(AG$16-AG$15)/MAX(AG$17-AG$14,1)*IF(OR(AG$4<=AG$17,AG$18="Linear*"),AG$4-AG$14,AG$17-AG$14)))*IF(LEFT(AG$19,7)="Nominal",AG$8,1) | AH12: =(IF(AH$4<AH$14,0,AH$15+(AH$16-AH$15)/MAX(AH$17-AH$14,1)*IF(OR(AH$4<=AH$17,AH$18="Linear*"),AH$4-AH$14,AH$17-AH$14)))*IF(LEFT(AH$19,7)="Nominal",AH$8,1) | AI12: =(IF(AI$4<AI$14,0,AI$15+(AI$16-AI$15)/MAX(AI$17-AI$14,1)*IF(OR(AI$4<=AI$17,AI$18="Linear*"),AI$4-AI$14,AI$17-AI$14)))*IF(LEFT(AI$19,7)="Nominal",AI$8,1) | AJ12: =(IF(AJ$4<AJ$14,0,AJ$15+(AJ$16-AJ$15)/MAX(AJ$17-AJ$14,1)*IF(OR(AJ$4<=AJ$17,AJ$18="Linear*"),AJ$4-AJ$14,AJ$17-AJ$14)))*IF(LEFT(AJ$19,7)="Nominal",AJ$8,1) | AK12: =(IF(AK$4<AK$14,0,AK$15+(AK$16-AK$15)/MAX(AK$17-AK$14,1)*IF(OR(AK$4<=AK$17,AK$18="Linear*"),AK$4-AK$14,AK$17-AK$14)))*IF(LEFT(AK$19,7)="Nominal",AK$8,1) | AL12: =(IF(AL$4<AL$14,0,AL$15+(AL$16-AL$15)/MAX(AL$17-AL$14,1)*IF(OR(AL$4<=AL$17,AL$18="Linear*"),AL$4-AL$14,AL$17-AL$14)))*IF(LEFT(AL$19,7)="Nominal",AL$8,1) | AM12: =(IF(AM$4<AM$14,0,AM$15+(AM$16-AM$15)/MAX(AM$17-AM$14,1)*IF(OR(AM$4<=AM$17,AM$18="Linear*"),AM$4-AM$14,AM$17-AM$14)))*IF(LEFT(AM$19,7)="Nominal",AM$8,1) | AN12: =(IF(AN$4<AN$14,0,AN$15+(AN$16-AN$15)/MAX(AN$17-AN$14,1)*IF(OR(AN$4<=AN$17,AN$18="Linear*"),AN$4-AN$14,AN$17-AN$14)))*IF(LEFT(AN$19,7)="Nominal",AN$8,1) | ... AX12: =(IF(AX$4<AX$14,0,AX$15+(AX$16-AX$15)/MAX(AX$17-AX$14,1)*IF(OR(AX$4<=AX$17,AX$18="Linear*"),AX$4-AX$14,AX$17-AX$14)))*IF(LEFT(AX$19,7)="Nominal",AX$8,1) | AY12: =PATH(AY$4,AY$14,AY$17,AY$15,AY$16,AY$18="Linear*")*IF(LEFT(AY$19,7)="Nominal",AY$8,1)
H13: Carbon tax (MTInputs rows 18-21, 265, 266)
A14: CPIntro | D14: 18 | H14: =INDEX(Variables!$B$5:$B$105,MATCH($A14,Variables!$A$5:$A$105,0))&IF($C14="",""," | "&INDEX(Mapping!$B$5:$B$26,MATCH($C14,Mapping!$A$5:$A$26,0))&" | "&INDEX(Mapping!$B$30:$B$41,MATCH($B14,Mapping!$A$30:$A$41,0))) | I14: =INDEX(Variables!$C$5:$C$105,MATCH($A14,Variables!$A$5:$A$105,0)) | J14: =INDEX(Variables!$E$5:$E$105,MATCH($A14,Variables!$A$5:$A$105,0)) | K14: =LOWER(Settings!$C$4)&".mit."&$A14&IF($C14="","","."&$C14&"."&$B14)&IF(INDEX(Variables!$D$5:$D$105,MATCH($A14,Variables!$A$5:$A$105,0))="","","."&INDEX(Variables!$D$5:$D$105,MATCH($A14,Variables!$A$5:$A$105,0)))&"."&K$5 | L14: =INDEX(MTInputs!$J$1:$AZ$415,$D14,MATCH(L$5,MTInputs!$J$5:$AZ$5,0)) | M14: =INDEX(MTInputs!$J$1:$AZ$415,$D14,MATCH(M$5,MTInputs!$J$5:$AZ$5,0)) | N14: =INDEX(MTInputs!$J$1:$AZ$415,$D14,MATCH(N$5,MTInputs!$J$5:$AZ$5,0)) | O14: =INDEX(MTInputs!$J$1:$AZ$415,$D14,MATCH(O$5,MTInputs!$J$5:$AZ$5,0)) | P14: =INDEX(MTInputs!$J$1:$AZ$415,$D14,MATCH(P$5,MTInputs!$J$5:$AZ$5,0)) | Q14: =INDEX(MTInputs!$J$1:$AZ$415,$D14,MATCH(Q$5,MTInputs!$J$5:$AZ$5,0)) | R14: =INDEX(MTInputs!$J$1:$AZ$415,$D14,MATCH(R$5,MTInputs!$J$5:$AZ$5,0)) | S14: =INDEX(MTInputs!$J$1:$AZ$415,$D14,MATCH(S$5,MTInputs!$J$5:$AZ$5,0)) | ... AD14: =INDEX(MTInputs!$J$1:$AZ$415,$D14,MATCH(AD$5,MTInputs!$J$5:$AZ$5,0)) | AF14: =LOWER(Settings!$C$4)&".mit."&$A14&IF($C14="","","."&$C14&"."&$B14)&IF(INDEX(Variables!$D$5:$D$105,MATCH($A14,Variables!$A$5:$A$105,0))="","","."&INDEX(Variables!$D$5:$D$105,MATCH($A14,Variables!$A$5:$A$105,0)))&"."&AF$5 | AG14: =INDEX(MTInputs!$J$1:$AZ$415,$D14,MATCH(AG$5,MTInputs!$J$5:$AZ$5,0)) | AH14: =INDEX(MTInputs!$J$1:$AZ$415,$D14,MATCH(AH$5,MTInputs!$J$5:$AZ$5,0)) | AI14: =INDEX(MTInputs!$J$1:$AZ$415,$D14,MATCH(AI$5,MTInputs!$J$5:$AZ$5,0)) | AJ14: =INDEX(MTInputs!$J$1:$AZ$415,$D14,MATCH(AJ$5,MTInputs!$J$5:$AZ$5,0)) | AK14: =INDEX(MTInputs!$J$1:$AZ$415,$D14,MATCH(AK$5,MTInputs!$J$5:$AZ$5,0)) | AL14: =INDEX(MTInputs!$J$1:$AZ$415,$D14,MATCH(AL$5,MTInputs!$J$5:$AZ$5,0)) | AM14: =INDEX(MTInputs!$J$1:$AZ$415,$D14,MATCH(AM$5,MTInputs!$J$5:$AZ$5,0)) | AN14: =INDEX(MTInputs!$J$1:$AZ$415,$D14,MATCH(AN$5,MTInputs!$J$5:$AZ$5,0)) | ... AY14: =INDEX(MTInputs!$J$1:$AZ$415,$D14,MATCH(AY$5,MTInputs!$J$5:$AZ$5,0))
A15: CPLevelStart | D15: 19 | H15: =INDEX(Variables!$B$5:$B$105,MATCH($A15,Variables!$A$5:$A$105,0))&IF($C15="",""," | "&INDEX(Mapping!$B$5:$B$26,MATCH($C15,Mapping!$A$5:$A$26,0))&" | "&INDEX(Mapping!$B$30:$B$41,MATCH($B15,Mapping!$A$30:$A$41,0))) | I15: =INDEX(Variables!$C$5:$C$105,MATCH($A15,Variables!$A$5:$A$105,0)) | J15: =INDEX(Variables!$E$5:$E$105,MATCH($A15,Variables!$A$5:$A$105,0)) | K15: =LOWER(Settings!$C$4)&".mit."&$A15&IF($C15="","","."&$C15&"."&$B15)&IF(INDEX(Variables!$D$5:$D$105,MATCH($A15,Variables!$A$5:$A$105,0))="","","."&INDEX(Variables!$D$5:$D$105,MATCH($A15,Variables!$A$5:$A$105,0)))&"."&K$5 | L15: =INDEX(MTInputs!$J$1:$AZ$415,$D15,MATCH(L$5,MTInputs!$J$5:$AZ$5,0)) | M15: =INDEX(MTInputs!$J$1:$AZ$415,$D15,MATCH(M$5,MTInputs!$J$5:$AZ$5,0)) | N15: =INDEX(MTInputs!$J$1:$AZ$415,$D15,MATCH(N$5,MTInputs!$J$5:$AZ$5,0)) | O15: =INDEX(MTInputs!$J$1:$AZ$415,$D15,MATCH(O$5,MTInputs!$J$5:$AZ$5,0)) | P15: =INDEX(MTInputs!$J$1:$AZ$415,$D15,MATCH(P$5,MTInputs!$J$5:$AZ$5,0)) | Q15: =INDEX(MTInputs!$J$1:$AZ$415,$D15,MATCH(Q$5,MTInputs!$J$5:$AZ$5,0)) | R15: =INDEX(MTInputs!$J$1:$AZ$415,$D15,MATCH(R$5,MTInputs!$J$5:$AZ$5,0)) | S15: =INDEX(MTInputs!$J$1:$AZ$415,$D15,MATCH(S$5,MTInputs!$J$5:$AZ$5,0)) | ... AD15: =INDEX(MTInputs!$J$1:$AZ$415,$D15,MATCH(AD$5,MTInputs!$J$5:$AZ$5,0)) | AF15: =LOWER(Settings!$C$4)&".mit."&$A15&IF($C15="","","."&$C15&"."&$B15)&IF(INDEX(Variables!$D$5:$D$105,MATCH($A15,Variables!$A$5:$A$105,0))="","","."&INDEX(Variables!$D$5:$D$105,MATCH($A15,Variables!$A$5:$A$105,0)))&"."&AF$5 | AG15: =INDEX(MTInputs!$J$1:$AZ$415,$D15,MATCH(AG$5,MTInputs!$J$5:$AZ$5,0)) | AH15: =INDEX(MTInputs!$J$1:$AZ$415,$D15,MATCH(AH$5,MTInputs!$J$5:$AZ$5,0)) | AI15: =INDEX(MTInputs!$J$1:$AZ$415,$D15,MATCH(AI$5,MTInputs!$J$5:$AZ$5,0)) | AJ15: =INDEX(MTInputs!$J$1:$AZ$415,$D15,MATCH(AJ$5,MTInputs!$J$5:$AZ$5,0)) | AK15: =INDEX(MTInputs!$J$1:$AZ$415,$D15,MATCH(AK$5,MTInputs!$J$5:$AZ$5,0)) | AL15: =INDEX(MTInputs!$J$1:$AZ$415,$D15,MATCH(AL$5,MTInputs!$J$5:$AZ$5,0)) | AM15: =INDEX(MTInputs!$J$1:$AZ$415,$D15,MATCH(AM$5,MTInputs!$J$5:$AZ$5,0)) | AN15: =INDEX(MTInputs!$J$1:$AZ$415,$D15,MATCH(AN$5,MTInputs!$J$5:$AZ$5,0)) | ... AY15: =INDEX(MTInputs!$J$1:$AZ$415,$D15,MATCH(AY$5,MTInputs!$J$5:$AZ$5,0))
A16: CPLevelTarget | D16: 20 | H16: =INDEX(Variables!$B$5:$B$105,MATCH($A16,Variables!$A$5:$A$105,0))&IF($C16="",""," | "&INDEX(Mapping!$B$5:$B$26,MATCH($C16,Mapping!$A$5:$A$26,0))&" | "&INDEX(Mapping!$B$30:$B$41,MATCH($B16,Mapping!$A$30:$A$41,0))) | I16: =INDEX(Variables!$C$5:$C$105,MATCH($A16,Variables!$A$5:$A$105,0)) | J16: =INDEX(Variables!$E$5:$E$105,MATCH($A16,Variables!$A$5:$A$105,0)) | K16: =LOWER(Settings!$C$4)&".mit."&$A16&IF($C16="","","."&$C16&"."&$B16)&IF(INDEX(Variables!$D$5:$D$105,MATCH($A16,Variables!$A$5:$A$105,0))="","","."&INDEX(Variables!$D$5:$D$105,MATCH($A16,Variables!$A$5:$A$105,0)))&"."&K$5 | L16: =INDEX(MTInputs!$J$1:$AZ$415,$D16,MATCH(L$5,MTInputs!$J$5:$AZ$5,0)) | M16: =INDEX(MTInputs!$J$1:$AZ$415,$D16,MATCH(M$5,MTInputs!$J$5:$AZ$5,0)) | N16: =INDEX(MTInputs!$J$1:$AZ$415,$D16,MATCH(N$5,MTInputs!$J$5:$AZ$5,0)) | O16: =INDEX(MTInputs!$J$1:$AZ$415,$D16,MATCH(O$5,MTInputs!$J$5:$AZ$5,0)) | P16: =INDEX(MTInputs!$J$1:$AZ$415,$D16,MATCH(P$5,MTInputs!$J$5:$AZ$5,0)) | Q16: =INDEX(MTInputs!$J$1:$AZ$415,$D16,MATCH(Q$5,MTInputs!$J$5:$AZ$5,0)) | R16: =INDEX(MTInputs!$J$1:$AZ$415,$D16,MATCH(R$5,MTInputs!$J$5:$AZ$5,0)) | S16: =INDEX(MTInputs!$J$1:$AZ$415,$D16,MATCH(S$5,MTInputs!$J$5:$AZ$5,0)) | ... AD16: =INDEX(MTInputs!$J$1:$AZ$415,$D16,MATCH(AD$5,MTInputs!$J$5:$AZ$5,0)) | AF16: =LOWER(Settings!$C$4)&".mit."&$A16&IF($C16="","","."&$C16&"."&$B16)&IF(INDEX(Variables!$D$5:$D$105,MATCH($A16,Variables!$A$5:$A$105,0))="","","."&INDEX(Variables!$D$5:$D$105,MATCH($A16,Variables!$A$5:$A$105,0)))&"."&AF$5 | AG16: =INDEX(MTInputs!$J$1:$AZ$415,$D16,MATCH(AG$5,MTInputs!$J$5:$AZ$5,0)) | AH16: =INDEX(MTInputs!$J$1:$AZ$415,$D16,MATCH(AH$5,MTInputs!$J$5:$AZ$5,0)) | AI16: =INDEX(MTInputs!$J$1:$AZ$415,$D16,MATCH(AI$5,MTInputs!$J$5:$AZ$5,0)) | AJ16: =INDEX(MTInputs!$J$1:$AZ$415,$D16,MATCH(AJ$5,MTInputs!$J$5:$AZ$5,0)) | AK16: =INDEX(MTInputs!$J$1:$AZ$415,$D16,MATCH(AK$5,MTInputs!$J$5:$AZ$5,0)) | AL16: =INDEX(MTInputs!$J$1:$AZ$415,$D16,MATCH(AL$5,MTInputs!$J$5:$AZ$5,0)) | AM16: =INDEX(MTInputs!$J$1:$AZ$415,$D16,MATCH(AM$5,MTInputs!$J$5:$AZ$5,0)) | AN16: =INDEX(MTInputs!$J$1:$AZ$415,$D16,MATCH(AN$5,MTInputs!$J$5:$AZ$5,0)) | ... AY16: =INDEX(MTInputs!$J$1:$AZ$415,$D16,MATCH(AY$5,MTInputs!$J$5:$AZ$5,0))
A17: CPOutro | D17: 21 | H17: =INDEX(Variables!$B$5:$B$105,MATCH($A17,Variables!$A$5:$A$105,0))&IF($C17="",""," | "&INDEX(Mapping!$B$5:$B$26,MATCH($C17,Mapping!$A$5:$A$26,0))&" | "&INDEX(Mapping!$B$30:$B$41,MATCH($B17,Mapping!$A$30:$A$41,0))) | I17: =INDEX(Variables!$C$5:$C$105,MATCH($A17,Variables!$A$5:$A$105,0)) | J17: =INDEX(Variables!$E$5:$E$105,MATCH($A17,Variables!$A$5:$A$105,0)) | K17: =LOWER(Settings!$C$4)&".mit."&$A17&IF($C17="","","."&$C17&"."&$B17)&IF(INDEX(Variables!$D$5:$D$105,MATCH($A17,Variables!$A$5:$A$105,0))="","","."&INDEX(Variables!$D$5:$D$105,MATCH($A17,Variables!$A$5:$A$105,0)))&"."&K$5 | L17: =INDEX(MTInputs!$J$1:$AZ$415,$D17,MATCH(L$5,MTInputs!$J$5:$AZ$5,0)) | M17: =INDEX(MTInputs!$J$1:$AZ$415,$D17,MATCH(M$5,MTInputs!$J$5:$AZ$5,0)) | N17: =INDEX(MTInputs!$J$1:$AZ$415,$D17,MATCH(N$5,MTInputs!$J$5:$AZ$5,0)) | O17: =INDEX(MTInputs!$J$1:$AZ$415,$D17,MATCH(O$5,MTInputs!$J$5:$AZ$5,0)) | P17: =INDEX(MTInputs!$J$1:$AZ$415,$D17,MATCH(P$5,MTInputs!$J$5:$AZ$5,0)) | Q17: =INDEX(MTInputs!$J$1:$AZ$415,$D17,MATCH(Q$5,MTInputs!$J$5:$AZ$5,0)) | R17: =INDEX(MTInputs!$J$1:$AZ$415,$D17,MATCH(R$5,MTInputs!$J$5:$AZ$5,0)) | S17: =INDEX(MTInputs!$J$1:$AZ$415,$D17,MATCH(S$5,MTInputs!$J$5:$AZ$5,0)) | ... AD17: =INDEX(MTInputs!$J$1:$AZ$415,$D17,MATCH(AD$5,MTInputs!$J$5:$AZ$5,0)) | AF17: =LOWER(Settings!$C$4)&".mit."&$A17&IF($C17="","","."&$C17&"."&$B17)&IF(INDEX(Variables!$D$5:$D$105,MATCH($A17,Variables!$A$5:$A$105,0))="","","."&INDEX(Variables!$D$5:$D$105,MATCH($A17,Variables!$A$5:$A$105,0)))&"."&AF$5 | AG17: =INDEX(MTInputs!$J$1:$AZ$415,$D17,MATCH(AG$5,MTInputs!$J$5:$AZ$5,0)) | AH17: =INDEX(MTInputs!$J$1:$AZ$415,$D17,MATCH(AH$5,MTInputs!$J$5:$AZ$5,0)) | AI17: =INDEX(MTInputs!$J$1:$AZ$415,$D17,MATCH(AI$5,MTInputs!$J$5:$AZ$5,0)) | AJ17: =INDEX(MTInputs!$J$1:$AZ$415,$D17,MATCH(AJ$5,MTInputs!$J$5:$AZ$5,0)) | AK17: =INDEX(MTInputs!$J$1:$AZ$415,$D17,MATCH(AK$5,MTInputs!$J$5:$AZ$5,0)) | AL17: =INDEX(MTInputs!$J$1:$AZ$415,$D17,MATCH(AL$5,MTInputs!$J$5:$AZ$5,0)) | AM17: =INDEX(MTInputs!$J$1:$AZ$415,$D17,MATCH(AM$5,MTInputs!$J$5:$AZ$5,0)) | AN17: =INDEX(MTInputs!$J$1:$AZ$415,$D17,MATCH(AN$5,MTInputs!$J$5:$AZ$5,0)) | ... AY17: =INDEX(MTInputs!$J$1:$AZ$415,$D17,MATCH(AY$5,MTInputs!$J$5:$AZ$5,0))
A18: ExtendCarbonPriceBeyondOutro | D18: 265 | H18: =INDEX(Variables!$B$5:$B$105,MATCH($A18,Variables!$A$5:$A$105,0))&IF($C18="",""," | "&INDEX(Mapping!$B$5:$B$26,MATCH($C18,Mapping!$A$5:$A$26,0))&" | "&INDEX(Mapping!$B$30:$B$41,MATCH($B18,Mapping!$A$30:$A$41,0))) | I18: =INDEX(Variables!$C$5:$C$105,MATCH($A18,Variables!$A$5:$A$105,0)) | J18: =INDEX(Variables!$E$5:$E$105,MATCH($A18,Variables!$A$5:$A$105,0)) | K18: =LOWER(Settings!$C$4)&".mit."&$A18&IF($C18="","","."&$C18&"."&$B18)&IF(INDEX(Variables!$D$5:$D$105,MATCH($A18,Variables!$A$5:$A$105,0))="","","."&INDEX(Variables!$D$5:$D$105,MATCH($A18,Variables!$A$5:$A$105,0)))&"."&K$5 | L18: =INDEX(MTInputs!$J$1:$AZ$415,$D18,MATCH(L$5,MTInputs!$J$5:$AZ$5,0)) | M18: =INDEX(MTInputs!$J$1:$AZ$415,$D18,MATCH(M$5,MTInputs!$J$5:$AZ$5,0)) | N18: =INDEX(MTInputs!$J$1:$AZ$415,$D18,MATCH(N$5,MTInputs!$J$5:$AZ$5,0)) | O18: =INDEX(MTInputs!$J$1:$AZ$415,$D18,MATCH(O$5,MTInputs!$J$5:$AZ$5,0)) | P18: =INDEX(MTInputs!$J$1:$AZ$415,$D18,MATCH(P$5,MTInputs!$J$5:$AZ$5,0)) | Q18: =INDEX(MTInputs!$J$1:$AZ$415,$D18,MATCH(Q$5,MTInputs!$J$5:$AZ$5,0)) | R18: =INDEX(MTInputs!$J$1:$AZ$415,$D18,MATCH(R$5,MTInputs!$J$5:$AZ$5,0)) | S18: =INDEX(MTInputs!$J$1:$AZ$415,$D18,MATCH(S$5,MTInputs!$J$5:$AZ$5,0)) | ... AD18: =INDEX(MTInputs!$J$1:$AZ$415,$D18,MATCH(AD$5,MTInputs!$J$5:$AZ$5,0)) | AF18: =LOWER(Settings!$C$4)&".mit."&$A18&IF($C18="","","."&$C18&"."&$B18)&IF(INDEX(Variables!$D$5:$D$105,MATCH($A18,Variables!$A$5:$A$105,0))="","","."&INDEX(Variables!$D$5:$D$105,MATCH($A18,Variables!$A$5:$A$105,0)))&"."&AF$5 | AG18: =INDEX(MTInputs!$J$1:$AZ$415,$D18,MATCH(AG$5,MTInputs!$J$5:$AZ$5,0)) | AH18: =INDEX(MTInputs!$J$1:$AZ$415,$D18,MATCH(AH$5,MTInputs!$J$5:$AZ$5,0)) | AI18: =INDEX(MTInputs!$J$1:$AZ$415,$D18,MATCH(AI$5,MTInputs!$J$5:$AZ$5,0)) | AJ18: =INDEX(MTInputs!$J$1:$AZ$415,$D18,MATCH(AJ$5,MTInputs!$J$5:$AZ$5,0)) | AK18: =INDEX(MTInputs!$J$1:$AZ$415,$D18,MATCH(AK$5,MTInputs!$J$5:$AZ$5,0)) | AL18: =INDEX(MTInputs!$J$1:$AZ$415,$D18,MATCH(AL$5,MTInputs!$J$5:$AZ$5,0)) | AM18: =INDEX(MTInputs!$J$1:$AZ$415,$D18,MATCH(AM$5,MTInputs!$J$5:$AZ$5,0)) | AN18: =INDEX(MTInputs!$J$1:$AZ$415,$D18,MATCH(AN$5,MTInputs!$J$5:$AZ$5,0)) | ... AY18: =INDEX(MTInputs!$J$1:$AZ$415,$D18,MATCH(AY$5,MTInputs!$J$5:$AZ$5,0))
A19: NomorReal | D19: 266 | H19: =INDEX(Variables!$B$5:$B$105,MATCH($A19,Variables!$A$5:$A$105,0))&IF($C19="",""," | "&INDEX(Mapping!$B$5:$B$26,MATCH($C19,Mapping!$A$5:$A$26,0))&" | "&INDEX(Mapping!$B$30:$B$41,MATCH($B19,Mapping!$A$30:$A$41,0))) | I19: =INDEX(Variables!$C$5:$C$105,MATCH($A19,Variables!$A$5:$A$105,0)) | J19: =INDEX(Variables!$E$5:$E$105,MATCH($A19,Variables!$A$5:$A$105,0)) | K19: =LOWER(Settings!$C$4)&".mit."&$A19&IF($C19="","","."&$C19&"."&$B19)&IF(INDEX(Variables!$D$5:$D$105,MATCH($A19,Variables!$A$5:$A$105,0))="","","."&INDEX(Variables!$D$5:$D$105,MATCH($A19,Variables!$A$5:$A$105,0)))&"."&K$5 | L19: =INDEX(MTInputs!$J$1:$AZ$415,$D19,MATCH(L$5,MTInputs!$J$5:$AZ$5,0)) | M19: =INDEX(MTInputs!$J$1:$AZ$415,$D19,MATCH(M$5,MTInputs!$J$5:$AZ$5,0)) | N19: =INDEX(MTInputs!$J$1:$AZ$415,$D19,MATCH(N$5,MTInputs!$J$5:$AZ$5,0)) | O19: =INDEX(MTInputs!$J$1:$AZ$415,$D19,MATCH(O$5,MTInputs!$J$5:$AZ$5,0)) | P19: =INDEX(MTInputs!$J$1:$AZ$415,$D19,MATCH(P$5,MTInputs!$J$5:$AZ$5,0)) | Q19: =INDEX(MTInputs!$J$1:$AZ$415,$D19,MATCH(Q$5,MTInputs!$J$5:$AZ$5,0)) | R19: =INDEX(MTInputs!$J$1:$AZ$415,$D19,MATCH(R$5,MTInputs!$J$5:$AZ$5,0)) | S19: =INDEX(MTInputs!$J$1:$AZ$415,$D19,MATCH(S$5,MTInputs!$J$5:$AZ$5,0)) | ... AD19: =INDEX(MTInputs!$J$1:$AZ$415,$D19,MATCH(AD$5,MTInputs!$J$5:$AZ$5,0)) | AF19: =LOWER(Settings!$C$4)&".mit."&$A19&IF($C19="","","."&$C19&"."&$B19)&IF(INDEX(Variables!$D$5:$D$105,MATCH($A19,Variables!$A$5:$A$105,0))="","","."&INDEX(Variables!$D$5:$D$105,MATCH($A19,Variables!$A$5:$A$105,0)))&"."&AF$5 | AG19: =INDEX(MTInputs!$J$1:$AZ$415,$D19,MATCH(AG$5,MTInputs!$J$5:$AZ$5,0)) | AH19: =INDEX(MTInputs!$J$1:$AZ$415,$D19,MATCH(AH$5,MTInputs!$J$5:$AZ$5,0)) | AI19: =INDEX(MTInputs!$J$1:$AZ$415,$D19,MATCH(AI$5,MTInputs!$J$5:$AZ$5,0)) | AJ19: =INDEX(MTInputs!$J$1:$AZ$415,$D19,MATCH(AJ$5,MTInputs!$J$5:$AZ$5,0)) | AK19: =INDEX(MTInputs!$J$1:$AZ$415,$D19,MATCH(AK$5,MTInputs!$J$5:$AZ$5,0)) | AL19: =INDEX(MTInputs!$J$1:$AZ$415,$D19,MATCH(AL$5,MTInputs!$J$5:$AZ$5,0)) | AM19: =INDEX(MTInputs!$J$1:$AZ$415,$D19,MATCH(AM$5,MTInputs!$J$5:$AZ$5,0)) | AN19: =INDEX(MTInputs!$J$1:$AZ$415,$D19,MATCH(AN$5,MTInputs!$J$5:$AZ$5,0)) | ... AY19: =INDEX(MTInputs!$J$1:$AZ$415,$D19,MATCH(AY$5,MTInputs!$J$5:$AZ$5,0))
H20: Carbon tax coverage: fuels (MTInputs rows 23-29)
A21: ctcov | B21: coa | C21: all | D21: 23 | H21: =INDEX(Variables!$B$5:$B$105,MATCH($A21,Variables!$A$5:$A$105,0))&IF($C21="",""," | "&INDEX(Mapping!$B$5:$B$26,MATCH($C21,Mapping!$A$5:$A$26,0))&" | "&INDEX(Mapping!$B$30:$B$41,MATCH($B21,Mapping!$A$30:$A$41,0))) | I21: =INDEX(Variables!$C$5:$C$105,MATCH($A21,Variables!$A$5:$A$105,0)) | J21: =INDEX(Variables!$E$5:$E$105,MATCH($A21,Variables!$A$5:$A$105,0)) | K21: =LOWER(Settings!$C$4)&".mit."&$A21&IF($C21="","","."&$C21&"."&$B21)&IF(INDEX(Variables!$D$5:$D$105,MATCH($A21,Variables!$A$5:$A$105,0))="","","."&INDEX(Variables!$D$5:$D$105,MATCH($A21,Variables!$A$5:$A$105,0)))&"."&K$5 | L21: =INDEX(MTInputs!$J$1:$AZ$415,$D21,MATCH(L$5,MTInputs!$J$5:$AZ$5,0)) | M21: =INDEX(MTInputs!$J$1:$AZ$415,$D21,MATCH(M$5,MTInputs!$J$5:$AZ$5,0)) | N21: =INDEX(MTInputs!$J$1:$AZ$415,$D21,MATCH(N$5,MTInputs!$J$5:$AZ$5,0)) | O21: =INDEX(MTInputs!$J$1:$AZ$415,$D21,MATCH(O$5,MTInputs!$J$5:$AZ$5,0)) | P21: =INDEX(MTInputs!$J$1:$AZ$415,$D21,MATCH(P$5,MTInputs!$J$5:$AZ$5,0)) | Q21: =INDEX(MTInputs!$J$1:$AZ$415,$D21,MATCH(Q$5,MTInputs!$J$5:$AZ$5,0)) | R21: =INDEX(MTInputs!$J$1:$AZ$415,$D21,MATCH(R$5,MTInputs!$J$5:$AZ$5,0)) | S21: =INDEX(MTInputs!$J$1:$AZ$415,$D21,MATCH(S$5,MTInputs!$J$5:$AZ$5,0)) | ... AD21: =INDEX(MTInputs!$J$1:$AZ$415,$D21,MATCH(AD$5,MTInputs!$J$5:$AZ$5,0)) | AF21: =LOWER(Settings!$C$4)&".mit."&$A21&IF($C21="","","."&$C21&"."&$B21)&IF(INDEX(Variables!$D$5:$D$105,MATCH($A21,Variables!$A$5:$A$105,0))="","","."&INDEX(Variables!$D$5:$D$105,MATCH($A21,Variables!$A$5:$A$105,0)))&"."&AF$5 | AG21: =INDEX(MTInputs!$J$1:$AZ$415,$D21,MATCH(AG$5,MTInputs!$J$5:$AZ$5,0)) | AH21: =INDEX(MTInputs!$J$1:$AZ$415,$D21,MATCH(AH$5,MTInputs!$J$5:$AZ$5,0)) | AI21: =INDEX(MTInputs!$J$1:$AZ$415,$D21,MATCH(AI$5,MTInputs!$J$5:$AZ$5,0)) | AJ21: =INDEX(MTInputs!$J$1:$AZ$415,$D21,MATCH(AJ$5,MTInputs!$J$5:$AZ$5,0)) | AK21: =INDEX(MTInputs!$J$1:$AZ$415,$D21,MATCH(AK$5,MTInputs!$J$5:$AZ$5,0)) | AL21: =INDEX(MTInputs!$J$1:$AZ$415,$D21,MATCH(AL$5,MTInputs!$J$5:$AZ$5,0)) | AM21: =INDEX(MTInputs!$J$1:$AZ$415,$D21,MATCH(AM$5,MTInputs!$J$5:$AZ$5,0)) | AN21: =INDEX(MTInputs!$J$1:$AZ$415,$D21,MATCH(AN$5,MTInputs!$J$5:$AZ$5,0)) | ... AY21: =INDEX(MTInputs!$J$1:$AZ$415,$D21,MATCH(AY$5,MTInputs!$J$5:$AZ$5,0))
A22: ctcov | B22: nga | C22: all | D22: 24 | H22: =INDEX(Variables!$B$5:$B$105,MATCH($A22,Variables!$A$5:$A$105,0))&IF($C22="",""," | "&INDEX(Mapping!$B$5:$B$26,MATCH($C22,Mapping!$A$5:$A$26,0))&" | "&INDEX(Mapping!$B$30:$B$41,MATCH($B22,Mapping!$A$30:$A$41,0))) | I22: =INDEX(Variables!$C$5:$C$105,MATCH($A22,Variables!$A$5:$A$105,0)) | J22: =INDEX(Variables!$E$5:$E$105,MATCH($A22,Variables!$A$5:$A$105,0)) | K22: =LOWER(Settings!$C$4)&".mit."&$A22&IF($C22="","","."&$C22&"."&$B22)&IF(INDEX(Variables!$D$5:$D$105,MATCH($A22,Variables!$A$5:$A$105,0))="","","."&INDEX(Variables!$D$5:$D$105,MATCH($A22,Variables!$A$5:$A$105,0)))&"."&K$5 | L22: =INDEX(MTInputs!$J$1:$AZ$415,$D22,MATCH(L$5,MTInputs!$J$5:$AZ$5,0)) | M22: =INDEX(MTInputs!$J$1:$AZ$415,$D22,MATCH(M$5,MTInputs!$J$5:$AZ$5,0)) | N22: =INDEX(MTInputs!$J$1:$AZ$415,$D22,MATCH(N$5,MTInputs!$J$5:$AZ$5,0)) | O22: =INDEX(MTInputs!$J$1:$AZ$415,$D22,MATCH(O$5,MTInputs!$J$5:$AZ$5,0)) | P22: =INDEX(MTInputs!$J$1:$AZ$415,$D22,MATCH(P$5,MTInputs!$J$5:$AZ$5,0)) | Q22: =INDEX(MTInputs!$J$1:$AZ$415,$D22,MATCH(Q$5,MTInputs!$J$5:$AZ$5,0)) | R22: =INDEX(MTInputs!$J$1:$AZ$415,$D22,MATCH(R$5,MTInputs!$J$5:$AZ$5,0)) | S22: =INDEX(MTInputs!$J$1:$AZ$415,$D22,MATCH(S$5,MTInputs!$J$5:$AZ$5,0)) | ... AD22: =INDEX(MTInputs!$J$1:$AZ$415,$D22,MATCH(AD$5,MTInputs!$J$5:$AZ$5,0)) | AF22: =LOWER(Settings!$C$4)&".mit."&$A22&IF($C22="","","."&$C22&"."&$B22)&IF(INDEX(Variables!$D$5:$D$105,MATCH($A22,Variables!$A$5:$A$105,0))="","","."&INDEX(Variables!$D$5:$D$105,MATCH($A22,Variables!$A$5:$A$105,0)))&"."&AF$5 | AG22: =INDEX(MTInputs!$J$1:$AZ$415,$D22,MATCH(AG$5,MTInputs!$J$5:$AZ$5,0)) | AH22: =INDEX(MTInputs!$J$1:$AZ$415,$D22,MATCH(AH$5,MTInputs!$J$5:$AZ$5,0)) | AI22: =INDEX(MTInputs!$J$1:$AZ$415,$D22,MATCH(AI$5,MTInputs!$J$5:$AZ$5,0)) | AJ22: =INDEX(MTInputs!$J$1:$AZ$415,$D22,MATCH(AJ$5,MTInputs!$J$5:$AZ$5,0)) | AK22: =INDEX(MTInputs!$J$1:$AZ$415,$D22,MATCH(AK$5,MTInputs!$J$5:$AZ$5,0)) | AL22: =INDEX(MTInputs!$J$1:$AZ$415,$D22,MATCH(AL$5,MTInputs!$J$5:$AZ$5,0)) | AM22: =INDEX(MTInputs!$J$1:$AZ$415,$D22,MATCH(AM$5,MTInputs!$J$5:$AZ$5,0)) | AN22: =INDEX(MTInputs!$J$1:$AZ$415,$D22,MATCH(AN$5,MTInputs!$J$5:$AZ$5,0)) | ... AY22: =INDEX(MTInputs!$J$1:$AZ$415,$D22,MATCH(AY$5,MTInputs!$J$5:$AZ$5,0))
A23: ctcov | B23: gso | C23: all | D23: 25 | H23: =INDEX(Variables!$B$5:$B$105,MATCH($A23,Variables!$A$5:$A$105,0))&IF($C23="",""," | "&INDEX(Mapping!$B$5:$B$26,MATCH($C23,Mapping!$A$5:$A$26,0))&" | "&INDEX(Mapping!$B$30:$B$41,MATCH($B23,Mapping!$A$30:$A$41,0))) | I23: =INDEX(Variables!$C$5:$C$105,MATCH($A23,Variables!$A$5:$A$105,0)) | J23: =INDEX(Variables!$E$5:$E$105,MATCH($A23,Variables!$A$5:$A$105,0)) | K23: =LOWER(Settings!$C$4)&".mit."&$A23&IF($C23="","","."&$C23&"."&$B23)&IF(INDEX(Variables!$D$5:$D$105,MATCH($A23,Variables!$A$5:$A$105,0))="","","."&INDEX(Variables!$D$5:$D$105,MATCH($A23,Variables!$A$5:$A$105,0)))&"."&K$5 | L23: =INDEX(MTInputs!$J$1:$AZ$415,$D23,MATCH(L$5,MTInputs!$J$5:$AZ$5,0)) | M23: =INDEX(MTInputs!$J$1:$AZ$415,$D23,MATCH(M$5,MTInputs!$J$5:$AZ$5,0)) | N23: =INDEX(MTInputs!$J$1:$AZ$415,$D23,MATCH(N$5,MTInputs!$J$5:$AZ$5,0)) | O23: =INDEX(MTInputs!$J$1:$AZ$415,$D23,MATCH(O$5,MTInputs!$J$5:$AZ$5,0)) | P23: =INDEX(MTInputs!$J$1:$AZ$415,$D23,MATCH(P$5,MTInputs!$J$5:$AZ$5,0)) | Q23: =INDEX(MTInputs!$J$1:$AZ$415,$D23,MATCH(Q$5,MTInputs!$J$5:$AZ$5,0)) | R23: =INDEX(MTInputs!$J$1:$AZ$415,$D23,MATCH(R$5,MTInputs!$J$5:$AZ$5,0)) | S23: =INDEX(MTInputs!$J$1:$AZ$415,$D23,MATCH(S$5,MTInputs!$J$5:$AZ$5,0)) | ... AD23: =INDEX(MTInputs!$J$1:$AZ$415,$D23,MATCH(AD$5,MTInputs!$J$5:$AZ$5,0)) | AF23: =LOWER(Settings!$C$4)&".mit."&$A23&IF($C23="","","."&$C23&"."&$B23)&IF(INDEX(Variables!$D$5:$D$105,MATCH($A23,Variables!$A$5:$A$105,0))="","","."&INDEX(Variables!$D$5:$D$105,MATCH($A23,Variables!$A$5:$A$105,0)))&"."&AF$5 | AG23: =INDEX(MTInputs!$J$1:$AZ$415,$D23,MATCH(AG$5,MTInputs!$J$5:$AZ$5,0)) | AH23: =INDEX(MTInputs!$J$1:$AZ$415,$D23,MATCH(AH$5,MTInputs!$J$5:$AZ$5,0)) | AI23: =INDEX(MTInputs!$J$1:$AZ$415,$D23,MATCH(AI$5,MTInputs!$J$5:$AZ$5,0)) | AJ23: =INDEX(MTInputs!$J$1:$AZ$415,$D23,MATCH(AJ$5,MTInputs!$J$5:$AZ$5,0)) | AK23: =INDEX(MTInputs!$J$1:$AZ$415,$D23,MATCH(AK$5,MTInputs!$J$5:$AZ$5,0)) | AL23: =INDEX(MTInputs!$J$1:$AZ$415,$D23,MATCH(AL$5,MTInputs!$J$5:$AZ$5,0)) | AM23: =INDEX(MTInputs!$J$1:$AZ$415,$D23,MATCH(AM$5,MTInputs!$J$5:$AZ$5,0)) | AN23: =INDEX(MTInputs!$J$1:$AZ$415,$D23,MATCH(AN$5,MTInputs!$J$5:$AZ$5,0)) | ... AY23: =INDEX(MTInputs!$J$1:$AZ$415,$D23,MATCH(AY$5,MTInputs!$J$5:$AZ$5,0))
A24: ctcov | B24: die | C24: all | D24: 26 | H24: =INDEX(Variables!$B$5:$B$105,MATCH($A24,Variables!$A$5:$A$105,0))&IF($C24="",""," | "&INDEX(Mapping!$B$5:$B$26,MATCH($C24,Mapping!$A$5:$A$26,0))&" | "&INDEX(Mapping!$B$30:$B$41,MATCH($B24,Mapping!$A$30:$A$41,0))) | I24: =INDEX(Variables!$C$5:$C$105,MATCH($A24,Variables!$A$5:$A$105,0)) | J24: =INDEX(Variables!$E$5:$E$105,MATCH($A24,Variables!$A$5:$A$105,0)) | K24: =LOWER(Settings!$C$4)&".mit."&$A24&IF($C24="","","."&$C24&"."&$B24)&IF(INDEX(Variables!$D$5:$D$105,MATCH($A24,Variables!$A$5:$A$105,0))="","","."&INDEX(Variables!$D$5:$D$105,MATCH($A24,Variables!$A$5:$A$105,0)))&"."&K$5 | L24: =INDEX(MTInputs!$J$1:$AZ$415,$D24,MATCH(L$5,MTInputs!$J$5:$AZ$5,0)) | M24: =INDEX(MTInputs!$J$1:$AZ$415,$D24,MATCH(M$5,MTInputs!$J$5:$AZ$5,0)) | N24: =INDEX(MTInputs!$J$1:$AZ$415,$D24,MATCH(N$5,MTInputs!$J$5:$AZ$5,0)) | O24: =INDEX(MTInputs!$J$1:$AZ$415,$D24,MATCH(O$5,MTInputs!$J$5:$AZ$5,0)) | P24: =INDEX(MTInputs!$J$1:$AZ$415,$D24,MATCH(P$5,MTInputs!$J$5:$AZ$5,0)) | Q24: =INDEX(MTInputs!$J$1:$AZ$415,$D24,MATCH(Q$5,MTInputs!$J$5:$AZ$5,0)) | R24: =INDEX(MTInputs!$J$1:$AZ$415,$D24,MATCH(R$5,MTInputs!$J$5:$AZ$5,0)) | S24: =INDEX(MTInputs!$J$1:$AZ$415,$D24,MATCH(S$5,MTInputs!$J$5:$AZ$5,0)) | ... AD24: =INDEX(MTInputs!$J$1:$AZ$415,$D24,MATCH(AD$5,MTInputs!$J$5:$AZ$5,0)) | AF24: =LOWER(Settings!$C$4)&".mit."&$A24&IF($C24="","","."&$C24&"."&$B24)&IF(INDEX(Variables!$D$5:$D$105,MATCH($A24,Variables!$A$5:$A$105,0))="","","."&INDEX(Variables!$D$5:$D$105,MATCH($A24,Variables!$A$5:$A$105,0)))&"."&AF$5 | AG24: =INDEX(MTInputs!$J$1:$AZ$415,$D24,MATCH(AG$5,MTInputs!$J$5:$AZ$5,0)) | AH24: =INDEX(MTInputs!$J$1:$AZ$415,$D24,MATCH(AH$5,MTInputs!$J$5:$AZ$5,0)) | AI24: =INDEX(MTInputs!$J$1:$AZ$415,$D24,MATCH(AI$5,MTInputs!$J$5:$AZ$5,0)) | AJ24: =INDEX(MTInputs!$J$1:$AZ$415,$D24,MATCH(AJ$5,MTInputs!$J$5:$AZ$5,0)) | AK24: =INDEX(MTInputs!$J$1:$AZ$415,$D24,MATCH(AK$5,MTInputs!$J$5:$AZ$5,0)) | AL24: =INDEX(MTInputs!$J$1:$AZ$415,$D24,MATCH(AL$5,MTInputs!$J$5:$AZ$5,0)) | AM24: =INDEX(MTInputs!$J$1:$AZ$415,$D24,MATCH(AM$5,MTInputs!$J$5:$AZ$5,0)) | AN24: =INDEX(MTInputs!$J$1:$AZ$415,$D24,MATCH(AN$5,MTInputs!$J$5:$AZ$5,0)) | ... AY24: =INDEX(MTInputs!$J$1:$AZ$415,$D24,MATCH(AY$5,MTInputs!$J$5:$AZ$5,0))
A25: ctcov | B25: lpg | C25: all | D25: 27 | H25: =INDEX(Variables!$B$5:$B$105,MATCH($A25,Variables!$A$5:$A$105,0))&IF($C25="",""," | "&INDEX(Mapping!$B$5:$B$26,MATCH($C25,Mapping!$A$5:$A$26,0))&" | "&INDEX(Mapping!$B$30:$B$41,MATCH($B25,Mapping!$A$30:$A$41,0))) | I25: =INDEX(Variables!$C$5:$C$105,MATCH($A25,Variables!$A$5:$A$105,0)) | J25: =INDEX(Variables!$E$5:$E$105,MATCH($A25,Variables!$A$5:$A$105,0)) | K25: =LOWER(Settings!$C$4)&".mit."&$A25&IF($C25="","","."&$C25&"."&$B25)&IF(INDEX(Variables!$D$5:$D$105,MATCH($A25,Variables!$A$5:$A$105,0))="","","."&INDEX(Variables!$D$5:$D$105,MATCH($A25,Variables!$A$5:$A$105,0)))&"."&K$5 | L25: =INDEX(MTInputs!$J$1:$AZ$415,$D25,MATCH(L$5,MTInputs!$J$5:$AZ$5,0)) | M25: =INDEX(MTInputs!$J$1:$AZ$415,$D25,MATCH(M$5,MTInputs!$J$5:$AZ$5,0)) | N25: =INDEX(MTInputs!$J$1:$AZ$415,$D25,MATCH(N$5,MTInputs!$J$5:$AZ$5,0)) | O25: =INDEX(MTInputs!$J$1:$AZ$415,$D25,MATCH(O$5,MTInputs!$J$5:$AZ$5,0)) | P25: =INDEX(MTInputs!$J$1:$AZ$415,$D25,MATCH(P$5,MTInputs!$J$5:$AZ$5,0)) | Q25: =INDEX(MTInputs!$J$1:$AZ$415,$D25,MATCH(Q$5,MTInputs!$J$5:$AZ$5,0)) | R25: =INDEX(MTInputs!$J$1:$AZ$415,$D25,MATCH(R$5,MTInputs!$J$5:$AZ$5,0)) | S25: =INDEX(MTInputs!$J$1:$AZ$415,$D25,MATCH(S$5,MTInputs!$J$5:$AZ$5,0)) | ... AD25: =INDEX(MTInputs!$J$1:$AZ$415,$D25,MATCH(AD$5,MTInputs!$J$5:$AZ$5,0)) | AF25: =LOWER(Settings!$C$4)&".mit."&$A25&IF($C25="","","."&$C25&"."&$B25)&IF(INDEX(Variables!$D$5:$D$105,MATCH($A25,Variables!$A$5:$A$105,0))="","","."&INDEX(Variables!$D$5:$D$105,MATCH($A25,Variables!$A$5:$A$105,0)))&"."&AF$5 | AG25: =INDEX(MTInputs!$J$1:$AZ$415,$D25,MATCH(AG$5,MTInputs!$J$5:$AZ$5,0)) | AH25: =INDEX(MTInputs!$J$1:$AZ$415,$D25,MATCH(AH$5,MTInputs!$J$5:$AZ$5,0)) | AI25: =INDEX(MTInputs!$J$1:$AZ$415,$D25,MATCH(AI$5,MTInputs!$J$5:$AZ$5,0)) | AJ25: =INDEX(MTInputs!$J$1:$AZ$415,$D25,MATCH(AJ$5,MTInputs!$J$5:$AZ$5,0)) | AK25: =INDEX(MTInputs!$J$1:$AZ$415,$D25,MATCH(AK$5,MTInputs!$J$5:$AZ$5,0)) | AL25: =INDEX(MTInputs!$J$1:$AZ$415,$D25,MATCH(AL$5,MTInputs!$J$5:$AZ$5,0)) | AM25: =INDEX(MTInputs!$J$1:$AZ$415,$D25,MATCH(AM$5,MTInputs!$J$5:$AZ$5,0)) | AN25: =INDEX(MTInputs!$J$1:$AZ$415,$D25,MATCH(AN$5,MTInputs!$J$5:$AZ$5,0)) | ... AY25: =INDEX(MTInputs!$J$1:$AZ$415,$D25,MATCH(AY$5,MTInputs!$J$5:$AZ$5,0))
A26: ctcov | B26: ker | C26: all | D26: 28 | H26: =INDEX(Variables!$B$5:$B$105,MATCH($A26,Variables!$A$5:$A$105,0))&IF($C26="",""," | "&INDEX(Mapping!$B$5:$B$26,MATCH($C26,Mapping!$A$5:$A$26,0))&" | "&INDEX(Mapping!$B$30:$B$41,MATCH($B26,Mapping!$A$30:$A$41,0))) | I26: =INDEX(Variables!$C$5:$C$105,MATCH($A26,Variables!$A$5:$A$105,0)) | J26: =INDEX(Variables!$E$5:$E$105,MATCH($A26,Variables!$A$5:$A$105,0)) | K26: =LOWER(Settings!$C$4)&".mit."&$A26&IF($C26="","","."&$C26&"."&$B26)&IF(INDEX(Variables!$D$5:$D$105,MATCH($A26,Variables!$A$5:$A$105,0))="","","."&INDEX(Variables!$D$5:$D$105,MATCH($A26,Variables!$A$5:$A$105,0)))&"."&K$5 | L26: =INDEX(MTInputs!$J$1:$AZ$415,$D26,MATCH(L$5,MTInputs!$J$5:$AZ$5,0)) | M26: =INDEX(MTInputs!$J$1:$AZ$415,$D26,MATCH(M$5,MTInputs!$J$5:$AZ$5,0)) | N26: =INDEX(MTInputs!$J$1:$AZ$415,$D26,MATCH(N$5,MTInputs!$J$5:$AZ$5,0)) | O26: =INDEX(MTInputs!$J$1:$AZ$415,$D26,MATCH(O$5,MTInputs!$J$5:$AZ$5,0)) | P26: =INDEX(MTInputs!$J$1:$AZ$415,$D26,MATCH(P$5,MTInputs!$J$5:$AZ$5,0)) | Q26: =INDEX(MTInputs!$J$1:$AZ$415,$D26,MATCH(Q$5,MTInputs!$J$5:$AZ$5,0)) | R26: =INDEX(MTInputs!$J$1:$AZ$415,$D26,MATCH(R$5,MTInputs!$J$5:$AZ$5,0)) | S26: =INDEX(MTInputs!$J$1:$AZ$415,$D26,MATCH(S$5,MTInputs!$J$5:$AZ$5,0)) | ... AD26: =INDEX(MTInputs!$J$1:$AZ$415,$D26,MATCH(AD$5,MTInputs!$J$5:$AZ$5,0)) | AF26: =LOWER(Settings!$C$4)&".mit."&$A26&IF($C26="","","."&$C26&"."&$B26)&IF(INDEX(Variables!$D$5:$D$105,MATCH($A26,Variables!$A$5:$A$105,0))="","","."&INDEX(Variables!$D$5:$D$105,MATCH($A26,Variables!$A$5:$A$105,0)))&"."&AF$5 | AG26: =INDEX(MTInputs!$J$1:$AZ$415,$D26,MATCH(AG$5,MTInputs!$J$5:$AZ$5,0)) | AH26: =INDEX(MTInputs!$J$1:$AZ$415,$D26,MATCH(AH$5,MTInputs!$J$5:$AZ$5,0)) | AI26: =INDEX(MTInputs!$J$1:$AZ$415,$D26,MATCH(AI$5,MTInputs!$J$5:$AZ$5,0)) | AJ26: =INDEX(MTInputs!$J$1:$AZ$415,$D26,MATCH(AJ$5,MTInputs!$J$5:$AZ$5,0)) | AK26: =INDEX(MTInputs!$J$1:$AZ$415,$D26,MATCH(AK$5,MTInputs!$J$5:$AZ$5,0)) | AL26: =INDEX(MTInputs!$J$1:$AZ$415,$D26,MATCH(AL$5,MTInputs!$J$5:$AZ$5,0)) | AM26: =INDEX(MTInputs!$J$1:$AZ$415,$D26,MATCH(AM$5,MTInputs!$J$5:$AZ$5,0)) | AN26: =INDEX(MTInputs!$J$1:$AZ$415,$D26,MATCH(AN$5,MTInputs!$J$5:$AZ$5,0)) | ... AY26: =INDEX(MTInputs!$J$1:$AZ$415,$D26,MATCH(AY$5,MTInputs!$J$5:$AZ$5,0))
A27: ctcov | B27: oop | C27: all | D27: 29 | H27: =INDEX(Variables!$B$5:$B$105,MATCH($A27,Variables!$A$5:$A$105,0))&IF($C27="",""," | "&INDEX(Mapping!$B$5:$B$26,MATCH($C27,Mapping!$A$5:$A$26,0))&" | "&INDEX(Mapping!$B$30:$B$41,MATCH($B27,Mapping!$A$30:$A$41,0))) | I27: =INDEX(Variables!$C$5:$C$105,MATCH($A27,Variables!$A$5:$A$105,0)) | J27: =INDEX(Variables!$E$5:$E$105,MATCH($A27,Variables!$A$5:$A$105,0)) | K27: =LOWER(Settings!$C$4)&".mit."&$A27&IF($C27="","","."&$C27&"."&$B27)&IF(INDEX(Variables!$D$5:$D$105,MATCH($A27,Variables!$A$5:$A$105,0))="","","."&INDEX(Variables!$D$5:$D$105,MATCH($A27,Variables!$A$5:$A$105,0)))&"."&K$5 | L27: =INDEX(MTInputs!$J$1:$AZ$415,$D27,MATCH(L$5,MTInputs!$J$5:$AZ$5,0)) | M27: =INDEX(MTInputs!$J$1:$AZ$415,$D27,MATCH(M$5,MTInputs!$J$5:$AZ$5,0)) | N27: =INDEX(MTInputs!$J$1:$AZ$415,$D27,MATCH(N$5,MTInputs!$J$5:$AZ$5,0)) | O27: =INDEX(MTInputs!$J$1:$AZ$415,$D27,MATCH(O$5,MTInputs!$J$5:$AZ$5,0)) | P27: =INDEX(MTInputs!$J$1:$AZ$415,$D27,MATCH(P$5,MTInputs!$J$5:$AZ$5,0)) | Q27: =INDEX(MTInputs!$J$1:$AZ$415,$D27,MATCH(Q$5,MTInputs!$J$5:$AZ$5,0)) | R27: =INDEX(MTInputs!$J$1:$AZ$415,$D27,MATCH(R$5,MTInputs!$J$5:$AZ$5,0)) | S27: =INDEX(MTInputs!$J$1:$AZ$415,$D27,MATCH(S$5,MTInputs!$J$5:$AZ$5,0)) | ... AD27: =INDEX(MTInputs!$J$1:$AZ$415,$D27,MATCH(AD$5,MTInputs!$J$5:$AZ$5,0)) | AF27: =LOWER(Settings!$C$4)&".mit."&$A27&IF($C27="","","."&$C27&"."&$B27)&IF(INDEX(Variables!$D$5:$D$105,MATCH($A27,Variables!$A$5:$A$105,0))="","","."&INDEX(Variables!$D$5:$D$105,MATCH($A27,Variables!$A$5:$A$105,0)))&"."&AF$5 | AG27: =INDEX(MTInputs!$J$1:$AZ$415,$D27,MATCH(AG$5,MTInputs!$J$5:$AZ$5,0)) | AH27: =INDEX(MTInputs!$J$1:$AZ$415,$D27,MATCH(AH$5,MTInputs!$J$5:$AZ$5,0)) | AI27: =INDEX(MTInputs!$J$1:$AZ$415,$D27,MATCH(AI$5,MTInputs!$J$5:$AZ$5,0)) | AJ27: =INDEX(MTInputs!$J$1:$AZ$415,$D27,MATCH(AJ$5,MTInputs!$J$5:$AZ$5,0)) | AK27: =INDEX(MTInputs!$J$1:$AZ$415,$D27,MATCH(AK$5,MTInputs!$J$5:$AZ$5,0)) | AL27: =INDEX(MTInputs!$J$1:$AZ$415,$D27,MATCH(AL$5,MTInputs!$J$5:$AZ$5,0)) | AM27: =INDEX(MTInputs!$J$1:$AZ$415,$D27,MATCH(AM$5,MTInputs!$J$5:$AZ$5,0)) | AN27: =INDEX(MTInputs!$J$1:$AZ$415,$D27,MATCH(AN$5,MTInputs!$J$5:$AZ$5,0)) | ... AY27: =INDEX(MTInputs!$J$1:$AZ$415,$D27,MATCH(AY$5,MTInputs!$J$5:$AZ$5,0))
A28: ctcov | B28: bio | C28: all | H28: =INDEX(Variables!$B$5:$B$105,MATCH($A28,Variables!$A$5:$A$105,0))&IF($C28="",""," | "&INDEX(Mapping!$B$5:$B$26,MATCH($C28,Mapping!$A$5:$A$26,0))&" | "&INDEX(Mapping!$B$30:$B$41,MATCH($B28,Mapping!$A$30:$A$41,0))) | I28: =INDEX(Variables!$C$5:$C$105,MATCH($A28,Variables!$A$5:$A$105,0)) | J28: =INDEX(Variables!$E$5:$E$105,MATCH($A28,Variables!$A$5:$A$105,0)) | K28: =LOWER(Settings!$C$4)&".mit."&$A28&IF($C28="","","."&$C28&"."&$B28)&IF(INDEX(Variables!$D$5:$D$105,MATCH($A28,Variables!$A$5:$A$105,0))="","","."&INDEX(Variables!$D$5:$D$105,MATCH($A28,Variables!$A$5:$A$105,0)))&"."&K$5 | L28: TRUE | M28: TRUE | N28: TRUE | O28: TRUE | P28: TRUE | Q28: TRUE | R28: TRUE | S28: TRUE | T28: TRUE | U28: TRUE | V28: TRUE | W28: TRUE | X28: TRUE | Y28: TRUE | Z28: TRUE | AA28: TRUE | AB28: TRUE | AC28: TRUE | AD28: TRUE | AF28: =LOWER(Settings!$C$4)&".mit."&$A28&IF($C28="","","."&$C28&"."&$B28)&IF(INDEX(Variables!$D$5:$D$105,MATCH($A28,Variables!$A$5:$A$105,0))="","","."&INDEX(Variables!$D$5:$D$105,MATCH($A28,Variables!$A$5:$A$105,0)))&"."&AF$5 | AG28: TRUE | AH28: TRUE | AI28: TRUE | AJ28: TRUE | AK28: TRUE | AL28: TRUE | AM28: TRUE | AN28: TRUE | AO28: TRUE | AP28: TRUE | AQ28: TRUE | AR28: TRUE | AS28: TRUE | AT28: TRUE | AU28: TRUE | AV28: TRUE | AW28: TRUE | AX28: TRUE | AY28: TRUE
H29: Carbon tax coverage: sectors (MTInputs rows 31-47)
A30: ctcov | B30: all | C30: pow | D30: 31 | H30: =INDEX(Variables!$B$5:$B$105,MATCH($A30,Variables!$A$5:$A$105,0))&IF($C30="",""," | "&INDEX(Mapping!$B$5:$B$26,MATCH($C30,Mapping!$A$5:$A$26,0))&" | "&INDEX(Mapping!$B$30:$B$41,MATCH($B30,Mapping!$A$30:$A$41,0))) | I30: =INDEX(Variables!$C$5:$C$105,MATCH($A30,Variables!$A$5:$A$105,0)) | J30: =INDEX(Variables!$E$5:$E$105,MATCH($A30,Variables!$A$5:$A$105,0)) | K30: =LOWER(Settings!$C$4)&".mit."&$A30&IF($C30="","","."&$C30&"."&$B30)&IF(INDEX(Variables!$D$5:$D$105,MATCH($A30,Variables!$A$5:$A$105,0))="","","."&INDEX(Variables!$D$5:$D$105,MATCH($A30,Variables!$A$5:$A$105,0)))&"."&K$5 | L30: =INDEX(MTInputs!$J$1:$AZ$415,$D30,MATCH(L$5,MTInputs!$J$5:$AZ$5,0)) | M30: =INDEX(MTInputs!$J$1:$AZ$415,$D30,MATCH(M$5,MTInputs!$J$5:$AZ$5,0)) | N30: =INDEX(MTInputs!$J$1:$AZ$415,$D30,MATCH(N$5,MTInputs!$J$5:$AZ$5,0)) | O30: =INDEX(MTInputs!$J$1:$AZ$415,$D30,MATCH(O$5,MTInputs!$J$5:$AZ$5,0)) | P30: =INDEX(MTInputs!$J$1:$AZ$415,$D30,MATCH(P$5,MTInputs!$J$5:$AZ$5,0)) | Q30: =INDEX(MTInputs!$J$1:$AZ$415,$D30,MATCH(Q$5,MTInputs!$J$5:$AZ$5,0)) | R30: =INDEX(MTInputs!$J$1:$AZ$415,$D30,MATCH(R$5,MTInputs!$J$5:$AZ$5,0)) | S30: =INDEX(MTInputs!$J$1:$AZ$415,$D30,MATCH(S$5,MTInputs!$J$5:$AZ$5,0)) | ... AD30: =INDEX(MTInputs!$J$1:$AZ$415,$D30,MATCH(AD$5,MTInputs!$J$5:$AZ$5,0)) | AF30: =LOWER(Settings!$C$4)&".mit."&$A30&IF($C30="","","."&$C30&"."&$B30)&IF(INDEX(Variables!$D$5:$D$105,MATCH($A30,Variables!$A$5:$A$105,0))="","","."&INDEX(Variables!$D$5:$D$105,MATCH($A30,Variables!$A$5:$A$105,0)))&"."&AF$5 | AG30: =INDEX(MTInputs!$J$1:$AZ$415,$D30,MATCH(AG$5,MTInputs!$J$5:$AZ$5,0)) | AH30: =INDEX(MTInputs!$J$1:$AZ$415,$D30,MATCH(AH$5,MTInputs!$J$5:$AZ$5,0)) | AI30: =INDEX(MTInputs!$J$1:$AZ$415,$D30,MATCH(AI$5,MTInputs!$J$5:$AZ$5,0)) | AJ30: =INDEX(MTInputs!$J$1:$AZ$415,$D30,MATCH(AJ$5,MTInputs!$J$5:$AZ$5,0)) | AK30: =INDEX(MTInputs!$J$1:$AZ$415,$D30,MATCH(AK$5,MTInputs!$J$5:$AZ$5,0)) | AL30: =INDEX(MTInputs!$J$1:$AZ$415,$D30,MATCH(AL$5,MTInputs!$J$5:$AZ$5,0)) | AM30: =INDEX(MTInputs!$J$1:$AZ$415,$D30,MATCH(AM$5,MTInputs!$J$5:$AZ$5,0)) | AN30: =INDEX(MTInputs!$J$1:$AZ$415,$D30,MATCH(AN$5,MTInputs!$J$5:$AZ$5,0)) | ... AY30: =INDEX(MTInputs!$J$1:$AZ$415,$D30,MATCH(AY$5,MTInputs!$J$5:$AZ$5,0))
A31: ctcov | B31: all | C31: rod | D31: 32 | H31: =INDEX(Variables!$B$5:$B$105,MATCH($A31,Variables!$A$5:$A$105,0))&IF($C31="",""," | "&INDEX(Mapping!$B$5:$B$26,MATCH($C31,Mapping!$A$5:$A$26,0))&" | "&INDEX(Mapping!$B$30:$B$41,MATCH($B31,Mapping!$A$30:$A$41,0))) | I31: =INDEX(Variables!$C$5:$C$105,MATCH($A31,Variables!$A$5:$A$105,0)) | J31: =INDEX(Variables!$E$5:$E$105,MATCH($A31,Variables!$A$5:$A$105,0)) | K31: =LOWER(Settings!$C$4)&".mit."&$A31&IF($C31="","","."&$C31&"."&$B31)&IF(INDEX(Variables!$D$5:$D$105,MATCH($A31,Variables!$A$5:$A$105,0))="","","."&INDEX(Variables!$D$5:$D$105,MATCH($A31,Variables!$A$5:$A$105,0)))&"."&K$5 | L31: =INDEX(MTInputs!$J$1:$AZ$415,$D31,MATCH(L$5,MTInputs!$J$5:$AZ$5,0)) | M31: =INDEX(MTInputs!$J$1:$AZ$415,$D31,MATCH(M$5,MTInputs!$J$5:$AZ$5,0)) | N31: =INDEX(MTInputs!$J$1:$AZ$415,$D31,MATCH(N$5,MTInputs!$J$5:$AZ$5,0)) | O31: =INDEX(MTInputs!$J$1:$AZ$415,$D31,MATCH(O$5,MTInputs!$J$5:$AZ$5,0)) | P31: =INDEX(MTInputs!$J$1:$AZ$415,$D31,MATCH(P$5,MTInputs!$J$5:$AZ$5,0)) | Q31: =INDEX(MTInputs!$J$1:$AZ$415,$D31,MATCH(Q$5,MTInputs!$J$5:$AZ$5,0)) | R31: =INDEX(MTInputs!$J$1:$AZ$415,$D31,MATCH(R$5,MTInputs!$J$5:$AZ$5,0)) | S31: =INDEX(MTInputs!$J$1:$AZ$415,$D31,MATCH(S$5,MTInputs!$J$5:$AZ$5,0)) | ... AD31: =INDEX(MTInputs!$J$1:$AZ$415,$D31,MATCH(AD$5,MTInputs!$J$5:$AZ$5,0)) | AF31: =LOWER(Settings!$C$4)&".mit."&$A31&IF($C31="","","."&$C31&"."&$B31)&IF(INDEX(Variables!$D$5:$D$105,MATCH($A31,Variables!$A$5:$A$105,0))="","","."&INDEX(Variables!$D$5:$D$105,MATCH($A31,Variables!$A$5:$A$105,0)))&"."&AF$5 | AG31: =INDEX(MTInputs!$J$1:$AZ$415,$D31,MATCH(AG$5,MTInputs!$J$5:$AZ$5,0)) | AH31: =INDEX(MTInputs!$J$1:$AZ$415,$D31,MATCH(AH$5,MTInputs!$J$5:$AZ$5,0)) | AI31: =INDEX(MTInputs!$J$1:$AZ$415,$D31,MATCH(AI$5,MTInputs!$J$5:$AZ$5,0)) | AJ31: =INDEX(MTInputs!$J$1:$AZ$415,$D31,MATCH(AJ$5,MTInputs!$J$5:$AZ$5,0)) | AK31: =INDEX(MTInputs!$J$1:$AZ$415,$D31,MATCH(AK$5,MTInputs!$J$5:$AZ$5,0)) | AL31: =INDEX(MTInputs!$J$1:$AZ$415,$D31,MATCH(AL$5,MTInputs!$J$5:$AZ$5,0)) | AM31: =INDEX(MTInputs!$J$1:$AZ$415,$D31,MATCH(AM$5,MTInputs!$J$5:$AZ$5,0)) | AN31: =INDEX(MTInputs!$J$1:$AZ$415,$D31,MATCH(AN$5,MTInputs!$J$5:$AZ$5,0)) | ... AY31: =INDEX(MTInputs!$J$1:$AZ$415,$D31,MATCH(AY$5,MTInputs!$J$5:$AZ$5,0))
A32: ctcov | B32: all | C32: ral | D32: 33 | H32: =INDEX(Variables!$B$5:$B$105,MATCH($A32,Variables!$A$5:$A$105,0))&IF($C32="",""," | "&INDEX(Mapping!$B$5:$B$26,MATCH($C32,Mapping!$A$5:$A$26,0))&" | "&INDEX(Mapping!$B$30:$B$41,MATCH($B32,Mapping!$A$30:$A$41,0))) | I32: =INDEX(Variables!$C$5:$C$105,MATCH($A32,Variables!$A$5:$A$105,0)) | J32: =INDEX(Variables!$E$5:$E$105,MATCH($A32,Variables!$A$5:$A$105,0)) | K32: =LOWER(Settings!$C$4)&".mit."&$A32&IF($C32="","","."&$C32&"."&$B32)&IF(INDEX(Variables!$D$5:$D$105,MATCH($A32,Variables!$A$5:$A$105,0))="","","."&INDEX(Variables!$D$5:$D$105,MATCH($A32,Variables!$A$5:$A$105,0)))&"."&K$5 | L32: =INDEX(MTInputs!$J$1:$AZ$415,$D32,MATCH(L$5,MTInputs!$J$5:$AZ$5,0)) | M32: =INDEX(MTInputs!$J$1:$AZ$415,$D32,MATCH(M$5,MTInputs!$J$5:$AZ$5,0)) | N32: =INDEX(MTInputs!$J$1:$AZ$415,$D32,MATCH(N$5,MTInputs!$J$5:$AZ$5,0)) | O32: =INDEX(MTInputs!$J$1:$AZ$415,$D32,MATCH(O$5,MTInputs!$J$5:$AZ$5,0)) | P32: =INDEX(MTInputs!$J$1:$AZ$415,$D32,MATCH(P$5,MTInputs!$J$5:$AZ$5,0)) | Q32: =INDEX(MTInputs!$J$1:$AZ$415,$D32,MATCH(Q$5,MTInputs!$J$5:$AZ$5,0)) | R32: =INDEX(MTInputs!$J$1:$AZ$415,$D32,MATCH(R$5,MTInputs!$J$5:$AZ$5,0)) | S32: =INDEX(MTInputs!$J$1:$AZ$415,$D32,MATCH(S$5,MTInputs!$J$5:$AZ$5,0)) | ... AD32: =INDEX(MTInputs!$J$1:$AZ$415,$D32,MATCH(AD$5,MTInputs!$J$5:$AZ$5,0)) | AF32: =LOWER(Settings!$C$4)&".mit."&$A32&IF($C32="","","."&$C32&"."&$B32)&IF(INDEX(Variables!$D$5:$D$105,MATCH($A32,Variables!$A$5:$A$105,0))="","","."&INDEX(Variables!$D$5:$D$105,MATCH($A32,Variables!$A$5:$A$105,0)))&"."&AF$5 | AG32: =INDEX(MTInputs!$J$1:$AZ$415,$D32,MATCH(AG$5,MTInputs!$J$5:$AZ$5,0)) | AH32: =INDEX(MTInputs!$J$1:$AZ$415,$D32,MATCH(AH$5,MTInputs!$J$5:$AZ$5,0)) | AI32: =INDEX(MTInputs!$J$1:$AZ$415,$D32,MATCH(AI$5,MTInputs!$J$5:$AZ$5,0)) | AJ32: =INDEX(MTInputs!$J$1:$AZ$415,$D32,MATCH(AJ$5,MTInputs!$J$5:$AZ$5,0)) | AK32: =INDEX(MTInputs!$J$1:$AZ$415,$D32,MATCH(AK$5,MTInputs!$J$5:$AZ$5,0)) | AL32: =INDEX(MTInputs!$J$1:$AZ$415,$D32,MATCH(AL$5,MTInputs!$J$5:$AZ$5,0)) | AM32: =INDEX(MTInputs!$J$1:$AZ$415,$D32,MATCH(AM$5,MTInputs!$J$5:$AZ$5,0)) | AN32: =INDEX(MTInputs!$J$1:$AZ$415,$D32,MATCH(AN$5,MTInputs!$J$5:$AZ$5,0)) | ... AY32: =INDEX(MTInputs!$J$1:$AZ$415,$D32,MATCH(AY$5,MTInputs!$J$5:$AZ$5,0))
A33: ctcov | B33: all | C33: avi | D33: 34 | H33: =INDEX(Variables!$B$5:$B$105,MATCH($A33,Variables!$A$5:$A$105,0))&IF($C33="",""," | "&INDEX(Mapping!$B$5:$B$26,MATCH($C33,Mapping!$A$5:$A$26,0))&" | "&INDEX(Mapping!$B$30:$B$41,MATCH($B33,Mapping!$A$30:$A$41,0))) | I33: =INDEX(Variables!$C$5:$C$105,MATCH($A33,Variables!$A$5:$A$105,0)) | J33: =INDEX(Variables!$E$5:$E$105,MATCH($A33,Variables!$A$5:$A$105,0)) | K33: =LOWER(Settings!$C$4)&".mit."&$A33&IF($C33="","","."&$C33&"."&$B33)&IF(INDEX(Variables!$D$5:$D$105,MATCH($A33,Variables!$A$5:$A$105,0))="","","."&INDEX(Variables!$D$5:$D$105,MATCH($A33,Variables!$A$5:$A$105,0)))&"."&K$5 | L33: =INDEX(MTInputs!$J$1:$AZ$415,$D33,MATCH(L$5,MTInputs!$J$5:$AZ$5,0)) | M33: =INDEX(MTInputs!$J$1:$AZ$415,$D33,MATCH(M$5,MTInputs!$J$5:$AZ$5,0)) | N33: =INDEX(MTInputs!$J$1:$AZ$415,$D33,MATCH(N$5,MTInputs!$J$5:$AZ$5,0)) | O33: =INDEX(MTInputs!$J$1:$AZ$415,$D33,MATCH(O$5,MTInputs!$J$5:$AZ$5,0)) | P33: =INDEX(MTInputs!$J$1:$AZ$415,$D33,MATCH(P$5,MTInputs!$J$5:$AZ$5,0)) | Q33: =INDEX(MTInputs!$J$1:$AZ$415,$D33,MATCH(Q$5,MTInputs!$J$5:$AZ$5,0)) | R33: =INDEX(MTInputs!$J$1:$AZ$415,$D33,MATCH(R$5,MTInputs!$J$5:$AZ$5,0)) | S33: =INDEX(MTInputs!$J$1:$AZ$415,$D33,MATCH(S$5,MTInputs!$J$5:$AZ$5,0)) | ... AD33: =INDEX(MTInputs!$J$1:$AZ$415,$D33,MATCH(AD$5,MTInputs!$J$5:$AZ$5,0)) | AF33: =LOWER(Settings!$C$4)&".mit."&$A33&IF($C33="","","."&$C33&"."&$B33)&IF(INDEX(Variables!$D$5:$D$105,MATCH($A33,Variables!$A$5:$A$105,0))="","","."&INDEX(Variables!$D$5:$D$105,MATCH($A33,Variables!$A$5:$A$105,0)))&"."&AF$5 | AG33: =INDEX(MTInputs!$J$1:$AZ$415,$D33,MATCH(AG$5,MTInputs!$J$5:$AZ$5,0)) | AH33: =INDEX(MTInputs!$J$1:$AZ$415,$D33,MATCH(AH$5,MTInputs!$J$5:$AZ$5,0)) | AI33: =INDEX(MTInputs!$J$1:$AZ$415,$D33,MATCH(AI$5,MTInputs!$J$5:$AZ$5,0)) | AJ33: =INDEX(MTInputs!$J$1:$AZ$415,$D33,MATCH(AJ$5,MTInputs!$J$5:$AZ$5,0)) | AK33: =INDEX(MTInputs!$J$1:$AZ$415,$D33,MATCH(AK$5,MTInputs!$J$5:$AZ$5,0)) | AL33: =INDEX(MTInputs!$J$1:$AZ$415,$D33,MATCH(AL$5,MTInputs!$J$5:$AZ$5,0)) | AM33: =INDEX(MTInputs!$J$1:$AZ$415,$D33,MATCH(AM$5,MTInputs!$J$5:$AZ$5,0)) | AN33: =INDEX(MTInputs!$J$1:$AZ$415,$D33,MATCH(AN$5,MTInputs!$J$5:$AZ$5,0)) | ... AY33: =INDEX(MTInputs!$J$1:$AZ$415,$D33,MATCH(AY$5,MTInputs!$J$5:$AZ$5,0))
