Workbook

Sheet Settings
A1: CPAT industry kernel - Egypt prototype v0.3
A3: Country code | B3: egy | C3: First component of every code; CPAT convention (egy.mit.<var>.<sector>.<fuel>.<type>.<scenario>)
A4: Price group for industry sectors | B4: ind | C4: C2 retail-price group the four sectors read (pow / res / ind / tra)
A5: Elasticity column | B5: Industries | C5: Column of the master elasticity table (Transport / Residential / Industries / Services)
A6: Base year | B6: 2022 | C6: MTInputs FirstYearCalculations; energy in the base year is read from Data_Energy, later years from the kernel
A7: Additional policy-induced efficiency (alpha+) | B7: =INDEX(MTInputs!$F$8:$F$415,MATCH("AdditionalEfficiencyIndustrial",MTInputs!$H$8:$H$415,0)) -> 0 | C7: Read from the MTInputs column by NameOfParameter; this is the only MTInputs dependency of the kernel rows
A8: Carbon price start year (info) | B8: =INDEX(MTInputs!$F$8:$F$415,MATCH("CPIntro",MTInputs!$H$8:$H$415,0)) -> 2026 | C8: For reference: the policy scenario new-policy wedge (nce) starts here
A9: Carbon price target (info) | B9: =INDEX(MTInputs!$F$8:$F$415,MATCH("CPLevelTarget",MTInputs!$H$8:$H$415,0)) -> 50 | C9: $/tCO2
A12: Kernel (every energy cell, year t >= 2023):
A13: F(t) = F(t-1) * (1+g)^(eY*delta) * (1+psi) * (p(t)/p(t-1))^eU * [ (s(t)/s(t-1))^eF / (1 + a + a+) ]^(1+eU)
A14: p = post-tax price (atp), s = shadow price (shp) = atp + sigma*ssc, g = post-policy GDP growth, delta = income-elasticity discount, psi = exogenous shock
A16: Sheets
A17: Manual inputs | C17: Legacy 'Manual inputs' Process Emissions section (rows 18-47, same positions): CBAM process coverage switches, product emission factors, half-elasticities.
A18: Mitigation_Industry | C18: Kernel sheet in the CPAT Mitigation layout (columns A-AI, years K-AI): 4 CBAM sectors x 2 scenarios, each scenario followed by the 156-row CBAM goods block (legacy Mitigation 5881-6036 / 12198-12353). All formulas; codes built from components.
A19: MTInputs | C19: The 415-row CPAT parameter column, copied unchanged (columns A-I of the MTInputs sheet).
A20: Data_Energy | C20: Base-year energy matrix, fuel x sector, ktoe (Mitigation B4 rows 583-602).
A21: Data_Prices | C21: Pre-tax price before new policies (pbc), new-policy wedge (nce), shadow price (shp), sector coverage (tcf), share of shadow price on efficiency (ssc); both scenarios. Plus carbon price (cptraj) and auctioned ETS price (etstraj) trajectories for the CBAM block.
A22: Data_Macro | C22: GDP growth, income-elasticity discount factor, exogenous shock; both scenarios.
A23: Data_Elast | C23: Master elasticity table (income, usage, efficiency, AEEI) by fuel group x sector group, plus the fuel-group map.
A24: Check | C24: Kernel output against the values stored in CPAT_1_0pre_456 for the same rows; max absolute and relative differences. v0.3: plus CBAM block rows vs legacy (rows from 583).
A26: Version log
A27: v0.1 | C27: Initial kernel (egypt+mitigation).
A28: v0.2 | C28: Conformed to NORMS.md: MTInputs used/unused colouring, hidden MT/Dashboard placeholder columns, CPAT colours, title band. No formula changes.
A29: v0.3 | C29: TASK-1: CBAM goods / process emissions block (legacy Mitigation 12198-12353, 156 rows, cols A-AI) added after each scenario; 'Manual inputs' rows 18-47; cptraj/etstraj in Data_Prices; MTInputs F117:F121 linked to Manual inputs row 22. Carbon Tax/ETS rows now read the scenario trajectories (legacy: hard zeros, broken K refs). Legacy WIP bugs fixed: fuel emissions by sector M..AE hard-coded; aluminium fuel-ER relative ref; missing post-policy process total; product-price year header. Kernel rows unchanged (regression diff 0).

Sheet Manual inputs
B1: CPAT Manual inputs
B2: Replicates the legacy 'Manual inputs' tab at the same row/column positions. Only the Process Emissions section (rows 18-47, used by the CBAM block) is ported; other rows are left blank so legacy references port 1:1.
B3: Change only green cells. Row 22 feeds MTInputs F117:F121 (as in legacy).
A18: . | B18: Process Emissions
B19: Non-Fuel Process Emissions Coverage (CBAM goods only) for ETS and Carbon Tax
H20: mining & chemicals | I20: iron and steel | J20: non-ferrous metals | K20: machinery | L20: cement
D21: Include non-fuel process emissions in ETS/CT? (legacy Dashboard!G20) | E21: =FALSE() -> FALSE | H21: TRUE | I21: TRUE | J21: TRUE | L21: TRUE
H22: =AND($E$21,'Manual inputs'!H21) -> FALSE | I22: =AND($E$21,'Manual inputs'!I21) -> FALSE | J22: =AND($E$21,'Manual inputs'!J21) -> FALSE | K22: FALSE | L22: =AND($E$21,'Manual inputs'!L21) -> FALSE
B28: Emission Factors | H28: SCOPE 1 (tCO₂e/t, NH₃ integrated) | O28: SCOPE 2 + TOTALS | S28: EF INPUTS | W28: LATEST MAY 2026 EU DEFAULTS + BENCHMARKS | AD28: CONFIDENCE
D29: Product | E29: Unit | F29: CN codes | G29: Route | H29: S1.fc | I29: S1.fp | J29: S1.np | K29: S1.no | L29: S1 own | M29: Embed NH₃ | N29: S1 incl NH₃ | O29: S2 | P29: S2 in CBAM scope? | Q29: S1+S2 total | R29: CBAM- equiv | S29: fc GJ/t | T29: fc EF | U29: fp GJ/t | V29: fp EF | W29: EU def base | X29: mark up | Y29: EU def 2026 | Z29: EU bench | AA29: Gap vs def | AB29: Gap vs bench | AC29: Latest EU regulatory note (May 2026) | AD29: S1.fc / S1.fp confidence | AE29: S1.np / S1.no confidence
D30: DRI-EAF steel | E30: t crude steel | F30: 7207 10 (D); 7207 12 (D); 7208/7209 flat (partial); 7214 rebar | G30: Midrex NG shaft furnace + EAF | H30: 0.12903 | I30: 0.561 | J30: 0.04 | K30: 0 | L30: =SUM(H30:K30) -> 0.73003 | M30: 0 | N30: =L30+M30 -> 0.73003 | O30: 0.25 | P30: 0 | Q30: =N30+O30 -> 0.98003 | R30: =N30+O30*P30 -> 0.73003 | S30: 5 | T30: 56.1 | U30: 24 | V30: 56.1 | W30: 1.82 | X30: 0.1 | Y30: =W30*(1+X30) -> 2.002 | Z30: 0.481 | AA30: =R30-Y30 -> -1.27197 | AB30: =R30-Z30 -> 0.24903 | AC30: DRI-EAF. Default base 1.820 ×1.10 markup = 2.002 (2026). Benchmark 0.481 (final IR 2025/2620). CAUTION: CBAM default matrix for HRC CN 7208 may assign only BF-BOF route (4.454) — 'DRI default vacancy' risk for flat products. | AD30: S1.fc: Est: Midrex heat:reductant ratio 5:24 GJ/t NG. Total EF Auth (WSA 2023 / S1.fp: Est: Midrex standard ratio; IPCC 2006 Vol2 2C1; WSA 2023. Total Auth; | AE30: S1.np: Auth: IPCC 2006 2C1 — DRI process CO2 = 0 / S1.no: Auth: IPCC 2006 2C1
D31: Scrap-EAF steel | E31: t crude steel | F31: 7206 10; 7207 10 (E); 7214 rebar; 7208 HRC (E-route); 7216 sections | G31: Scrap-EAF | H31: 0.14025 | I31: 0 | J31: 0.015 | K31: 0 | L31: =SUM(H31:K31) -> 0.15525 | M31: 0 | N31: =L31+M31 -> 0.15525 | O31: 0.25 | P31: 0 | Q31: =N31+O31 -> 0.40525 | R31: =N31+O31*P31 -> 0.15525 | S31: 2.5 | T31: 56.1 | U31: 0 | V31: 0 | W31: 0.72 | X31: 0.1 | Y31: =W31*(1+X31) -> 0.792 | Z31: 0.072 | AA31: =R31-Y31 -> -0.63675 | AB31: =R31-Z31 -> 0.08325 | AC31: Scrap-EAF. Default base 0.720 ×1.10 = 0.792 (2026). Benchmark 0.072 (final, scrap route). | AD31: S1.fc: Est: IEA Egypt sector average; WSA 2023 scrap-EAF range 2-3 GJ/t. Tota / S1.fp: Auth: no reductant in scrap melting process | AE31: S1.np: Est: IPCC 2006 Vol2 2C1 default 0.01-0.02 tCO2/t for scrap-EAF / S1.no: Auth: IPCC 2006 2C1
D32: BF-BOF steel (reference) | E32: t crude steel | F32: 7206 10 (C); 7207 10 (C); 7209 CR (C-route); 7208 HRC (C-route) | G32: BF-BOF coal/coke | H32: 0.3844 | I32: 1.5376 | J32: 0.25 | K32: 0 | L32: =SUM(H32:K32) -> 2.172 | M32: 0 | N32: =L32+M32 -> 2.172 | O32: 0.1875 | P32: 0 | Q32: =N32+O32 -> 2.3595 | R32: =N32+O32*P32 -> 2.172 | S32: 4 | T32: 96.1 | U32: 16 | V32: 96.1 | W32: 2.8 | X32: 0.1 | Y32: =W32*(1+X32) -> 3.08 | Z32: 1.37 | AA32: =R32-Y32 -> -0.908 | AB32: =R32-Z32 -> 0.802 | AC32: BF-BOF reference. Default base 2.800 ×1.10 = 3.080 (2026). Benchmark 1.370 (final IR 2025/2620). | AD32: S1.fc: Prox: WSA 2023 global BF-BOF average. No Egypt-specific data (no produ / S1.fp: Prox: WSA 2023 BF standard; IPCC 2006 Vol2 2C1. Split Est within proxy | AE32: S1.np: Auth: IPCC 2006 Vol2 2C1 default 0.22-0.28 tCO2/t crude steel / S1.no: Auth: IPCC 2006 2C1
D33: Grey clinker (dry-process) | E33: t clinker | F33: 2523 10 (clinker); 2523 21; 2523 29 Portland cement | G33: Dry rotary kiln | H33: 0.2883 | I33: 0 | J33: 0.526 | K33: 0 | L33: =SUM(H33:K33) -> 0.8143 | M33: 0 | N33: =L33+M33 -> 0.8143 | O33: 0.05625 | P33: 1 | Q33: =N33+O33 -> 0.87055 | R33: =N33+O33*P33 -> 0.87055 | S33: 3 | T33: 96.1 | U33: 0 | V33: 0 | W33: 1.58 | X33: 0.1 | Y33: =W33*(1+X33) -> 1.738 | Z33: 0.666 | AA33: =R33-Y33 -> -0.86745 | AB33: =R33-Z33 -> 0.20455 | AC33: Cement clinker. Default base 1.580 ×1.10 = 1.738 (2026). Benchmark 0.666 (col B). S2 IN CBAM scope. | AD33: S1.fc: Est: IEA Egypt cement sector; CSI/GCCA GNR Egypt 2022. Total AukCoa / S1.fp: Auth: cement production has no chemical reductant fuel | AE33: S1.np: Auth: IPCC 2006 2A1 stoichiometric constant (44/100 × fraction CaCO3 i / S1.no: Auth
D34: Ammonia (net merchant) | E34: t NH3 | F34: 2814 10 (anhydrous ammonia) | G34: Steam methane reforming (SMR) + Haber-Bosch synthesis | H34: 0.3927 | I34: 1.4586 | J34: 0 | K34: 0 | L34: =SUM(H34:K34) -> 1.8513 | M34: 0 | N34: =L34+M34 -> 1.8513 | O34: 0.0375 | P34: 1 | Q34: =N34+O34 -> 1.8888 | R34: =N34+O34*P34 -> 1.8888 | S34: 7 | T34: 56.1 | U34: 26 | V34: 56.1 | W34: 2.05 | X34: 0.01 | Y34: =W34*(1+X34) -> 2.0705 | Z34: 1.484 | AA34: =R34-Y34 -> -0.1817 | AB34: =R34-Z34 -> 0.4048 | AC34: Egypt ammonia 2026 default = 2.07 tCO2e/t (incl 1% fertiliser markup; Argus 17 Dec 2025). Benchmark 1.522 → 1.484 after 2.5% reduction in 2026. S2 IN CBAM scope. | AD34: S1.fc: Est: IFA/EFMA BAT Vol.1; combustion ~6-8 GJ/t NH3. Total Auth (IFA sta / S1.fp: Est: IFA/EFMA BAT Vol.1 standard SMR ~24-28 GJ/t NH3. Total Auth; comb | AE34: S1.np: Auth: NH3 synthesis has no carbon process emissions / S1.no: Auth
D35: Urea | E35: t urea | F35: 3102 10 (urea >= 45% N) | G35: Urea synthesis from captured CO2 + NH3 feedstock | H35: 0.1122 | I35: 0 | J35: -0.733 | K35: 0 | L35: =SUM(H35:K35) -> -0.6208 | M35: 1.0709496 | N35: =L35+M35 -> 0.4501496 | O35: 0.0375 | P35: 1 | Q35: =N35+O35 -> 0.4876496 | R35: =N35+O35*P35 -> 0.4876496 | S35: 2 | T35: 56.1 | U35: 0 | V35: 0 | W35: 1.39 | X35: 0.01 | Y35: =W35*(1+X35) -> 1.4039 | Z35: 0.902 | AA35: =R35-Y35 -> -0.9162504 | AB35: =R35-Z35 -> -0.4143504 | AC35: NH₃ INTEGRATED in headline. Egypt urea 2026 default = 1.404 tCO2e/t (incl 1% markup; Sandbag Feb 2026). Benchmark col B 0.902 (col A 0.053 for actual-data pathway). SEFA chain uses ammonia benchmark 1.522. S2 IN CBAM scope. | AD35: S1.fc: Est: IFA/EFMA; small relative to NH3 chain. ~1.5-2.5 GJ/t urea typical / S1.fp: Auth: no additional reductant/feedstock in urea synthesis itself | AE35: S1.np: Auth: IPCC 2006 Vol2 3G stoichiometric constant. 44/60 = 0.733 tCO2 ab / S1.no: Auth
D36: Ammonium nitrate | E36: t AN | F36: 3102 30 (AN >= 28% N); 3102 40 (CAN) | G36: Ostwald process (NH3 → HNO3) + neutralisation (HNO3 + NH3 → NH4NO3) | H36: 0.1122 | I36: 0 | J36: 0 | K36: 0.97 | L36: =SUM(H36:K36) -> 1.0822 | M36: 0.40137 | N36: =L36+M36 -> 1.48357 | O36: 0.04375 | P36: 1 | Q36: =N36+O36 -> 1.52732 | R36: =N36+O36*P36 -> 1.52732 | S36: 2 | T36: 56.1 | U36: 0 | V36: 0 | W36: 2.64 | X36: 0.01 | Y36: =W36*(1+X36) -> 2.6664 | Z36: 0.302 | AA36: =R36-Y36 -> -1.13908 | AB36: =R36-Z36 -> 1.22532 | AC36: NH₃ INTEGRATED in headline. AN/CAN. Default base ~2.64 ×1.01 = 2.666 (2026, N2O-driven). Benchmark 0.302. S2 IN CBAM scope. Default value highly sensitive to assumed N2O abatement. | AD36: S1.fc: Est: IFA/EFMA BAT Vol.3; 1.5-2.5 GJ/t AN typical. Total direct EF less / S1.fp: Auth: HNO3 and neutralisation have no reductant | AE36: S1.np: Auth: AN chemistry (NH4NO3) contains no carbon / S1.no: Est: IPCC 2006 2B2; GWP AR6 AII.1.2. CRITICAL: range 0.21 (with high-e
D37: Primary aluminium | E37: t Al | F37: 7601 10 (unwrought primary); 7601 20 (alloys, semi-finished); 7604 (bars/rods); 7606 (sheet/plate) | G37: Hall-Héroult electrolysis + carbon anode prebaking | H37: 0.156 | I37: 0 | J37: 1.5 | K37: 0.85 | L37: =SUM(H37:K37) -> 2.506 | M37: 0 | N37: =L37+M37 -> 2.506 | O37: 6.75 | P37: 0 | Q37: =N37+O37 -> 9.256 | R37: =N37+O37*P37 -> 2.506 | S37: 2 | T37: 78 | U37: 0 | V37: 0 | W37: 2.06 | X37: 0.1 | Y37: =W37*(1+X37) -> 2.266 | Z37: 1.423 | AA37: =R37-Y37 -> 0.24 | AB37: =R37-Z37 -> 1.083 | AC37: Primary aluminium. Default base 2.060 ×1.10 = 2.266 (2026). Benchmark 1.423. S2 NOT in CBAM scope (direct emissions only). | AD37: S1.fc: Est: IAI 2023 smelter profile; 1.5-2.5 GJ/t range. Weighted EF 78 kgCO / S1.fp: Auth: Hall-Héroult is electrolytic; reduction is electrical not fuel-d | AE37: S1.np: Auth: IPCC 2006 Vol2 2C3 default 1.5 tCO2/t Al for prebaked anodes. Ra / S1.no: Est: IAI 2023 Egypt country profile. Global prebaked average 0.38 tCO2
B38: Process Emissions Half Elasticities
D39: Process | E39: Half Elasticity | F39: ER at $100 (%)
D40: DRI-EAF steel | E40: 0.0010536052 | F40: 0.1
D41: Scrap-EAF steel | E41: 0.00020202707 | F41: 0.02
D42: BF-BOF steel reference | E42: 0.00051293294 | F42: 0.05
D43: Grey clinker dry-process | E43: 0.00083381609 | F43: 0.08
D44: Ammonia net | E44: 0.0019845094 | F44: 0.18
D45: Urea | E45: 0 | F45: 0
D46: AN | E46: 0.010498221 | F46: 0.65
D47: Primary aluminium | E47: 0.00083381609 | F47: 0.08

Sheet Mitigation_Industry
B1: Fuel | C1: Sector | D1: Description | E1: Unit | F1: Source | G1: Input Code | H1: Output Code | I1: Note | J1: Helper | K1: 2021 | L1: 2022 | M1: 2023 | N1: 2024 | O1: 2025 | P1: 2026 | Q1: 2027 | R1: 2028 | S1: 2029 | T1: 2030 | U1: 2031 | V1: 2032 | W1: 2033 | X1: 2034 | Y1: 2035 | Z1: 2036 | AA1: 2037 | AB1: 2038 | AC1: 2039 | AD1: 2040 | AE1: 2041 | AF1: 2042 | AG1: 2043 | AH1: 2044 | AI1: 2045
B2: Mitigation Module - Egypt: Industry kernel
A3: 7 | B3: Industrial sector - Baseline (CBAM sectors: iron and steel, cement, non-ferrous metals, mining & chemicals)
B5: Iron and steel | C5: irn | D5: Fuel Type | E5: Unit | F5: Variable Code | G5: Input Code (data-table key) | H5: Output Code | I5: Scenario | J5: 1 | K5: 2021 | L5: 2022 | M5: 2023 | N5: 2024 | O5: 2025 | P5: 2026 | Q5: 2027 | R5: 2028 | S5: 2029 | T5: 2030 | U5: 2031 | V5: 2032 | W5: 2033 | X5: 2034 | Y5: 2035 | Z5: 2036 | AA5: 2037 | AB5: 2038 | AC5: 2039 | AD5: 2040 | AE5: 2041 | AF5: 2042 | AG5: 2043 | AH5: 2044 | AI5: 2045
B6: Pre-tax price: price before any new policy (supply cost + VAT + existing excise, subsidies and carbon prices)
B7: coa | C7: =$C$5 -> irn | D7: Coal | E7: $/GJ | F7: ptp | G7: =Settings!$B$3&".mit.pbc."&Settings!$B$4&"."&$B7&".a."&$J$5 -> egy.mit.pbc.ind.coa.a.1 | H7: =Settings!$B$3&".mit.ptp."&$C$5&"."&$B7&".e."&$J$5 -> egy.mit.ptp.irn.coa.e.1 | K7: =INDEX(Data_Prices!K:K,MATCH($G7,Data_Prices!$A:$A,0)) -> 11.182902 | L7: =INDEX(Data_Prices!L:L,MATCH($G7,Data_Prices!$A:$A,0)) -> 10.523361 | M7: =INDEX(Data_Prices!M:M,MATCH($G7,Data_Prices!$A:$A,0)) -> 10.299561 | N7: =INDEX(Data_Prices!N:N,MATCH($G7,Data_Prices!$A:$A,0)) -> 9.5775284 | O7: =INDEX(Data_Prices!O:O,MATCH($G7,Data_Prices!$A:$A,0)) -> 8.4854783 | P7: =INDEX(Data_Prices!P:P,MATCH($G7,Data_Prices!$A:$A,0)) -> 9.0871922 | Q7: =INDEX(Data_Prices!Q:Q,MATCH($G7,Data_Prices!$A:$A,0)) -> 9.2229237 | R7: =INDEX(Data_Prices!R:R,MATCH($G7,Data_Prices!$A:$A,0)) -> 9.158565 | S7: =INDEX(Data_Prices!S:S,MATCH($G7,Data_Prices!$A:$A,0)) -> 9.0895479 | T7: =INDEX(Data_Prices!T:T,MATCH($G7,Data_Prices!$A:$A,0)) -> 9.0156817 | U7: =INDEX(Data_Prices!U:U,MATCH($G7,Data_Prices!$A:$A,0)) -> 8.9443978 | V7: =INDEX(Data_Prices!V:V,MATCH($G7,Data_Prices!$A:$A,0)) -> 8.9443978 | W7: =INDEX(Data_Prices!W:W,MATCH($G7,Data_Prices!$A:$A,0)) -> 8.9443978 | X7: =INDEX(Data_Prices!X:X,MATCH($G7,Data_Prices!$A:$A,0)) -> 8.9443978 | Y7: =INDEX(Data_Prices!Y:Y,MATCH($G7,Data_Prices!$A:$A,0)) -> 8.9443978 | Z7: =INDEX(Data_Prices!Z:Z,MATCH($G7,Data_Prices!$A:$A,0)) -> 8.9443978 | AA7: =INDEX(Data_Prices!AA:AA,MATCH($G7,Data_Prices!$A:$A,0)) -> 8.9443978 | AB7: =INDEX(Data_Prices!AB:AB,MATCH($G7,Data_Prices!$A:$A,0)) -> 8.9443978 | AC7: =INDEX(Data_Prices!AC:AC,MATCH($G7,Data_Prices!$A:$A,0)) -> 8.9443978 | AD7: =INDEX(Data_Prices!AD:AD,MATCH($G7,Data_Prices!$A:$A,0)) -> 8.9443978 | AE7: =INDEX(Data_Prices!AE:AE,MATCH($G7,Data_Prices!$A:$A,0)) -> 8.9443978
B8: nga | C8: =$C$5 -> irn | D8: Natural gas | E8: $/GJ | F8: ptp | G8: =Settings!$B$3&".mit.pbc."&Settings!$B$4&"."&$B8&".a."&$J$5 -> egy.mit.pbc.ind.nga.a.1 | H8: =Settings!$B$3&".mit.ptp."&$C$5&"."&$B8&".e."&$J$5 -> egy.mit.ptp.irn.nga.e.1 | K8: =INDEX(Data_Prices!K:K,MATCH($G8,Data_Prices!$A:$A,0)) -> 6.0634636 | L8: =INDEX(Data_Prices!L:L,MATCH($G8,Data_Prices!$A:$A,0)) -> 5.4510151 | M8: =INDEX(Data_Prices!M:M,MATCH($G8,Data_Prices!$A:$A,0)) -> 5.1193563 | N8: =INDEX(Data_Prices!N:N,MATCH($G8,Data_Prices!$A:$A,0)) -> 5.0821846 | O8: =INDEX(Data_Prices!O:O,MATCH($G8,Data_Prices!$A:$A,0)) -> 5.0821846 | P8: =INDEX(Data_Prices!P:P,MATCH($G8,Data_Prices!$A:$A,0)) -> 5.0821846 | Q8: =INDEX(Data_Prices!Q:Q,MATCH($G8,Data_Prices!$A:$A,0)) -> 5.0821846 | R8: =INDEX(Data_Prices!R:R,MATCH($G8,Data_Prices!$A:$A,0)) -> 5.0821846 | S8: =INDEX(Data_Prices!S:S,MATCH($G8,Data_Prices!$A:$A,0)) -> 5.0821846 | T8: =INDEX(Data_Prices!T:T,MATCH($G8,Data_Prices!$A:$A,0)) -> 5.0821846 | U8: =INDEX(Data_Prices!U:U,MATCH($G8,Data_Prices!$A:$A,0)) -> 5.0821846 | V8: =INDEX(Data_Prices!V:V,MATCH($G8,Data_Prices!$A:$A,0)) -> 5.0821846 | W8: =INDEX(Data_Prices!W:W,MATCH($G8,Data_Prices!$A:$A,0)) -> 5.0821846 | X8: =INDEX(Data_Prices!X:X,MATCH($G8,Data_Prices!$A:$A,0)) -> 5.0821846 | Y8: =INDEX(Data_Prices!Y:Y,MATCH($G8,Data_Prices!$A:$A,0)) -> 5.0821846 | Z8: =INDEX(Data_Prices!Z:Z,MATCH($G8,Data_Prices!$A:$A,0)) -> 5.0821846 | AA8: =INDEX(Data_Prices!AA:AA,MATCH($G8,Data_Prices!$A:$A,0)) -> 5.0821846 | AB8: =INDEX(Data_Prices!AB:AB,MATCH($G8,Data_Prices!$A:$A,0)) -> 5.0821846 | AC8: =INDEX(Data_Prices!AC:AC,MATCH($G8,Data_Prices!$A:$A,0)) -> 5.0821846 | AD8: =INDEX(Data_Prices!AD:AD,MATCH($G8,Data_Prices!$A:$A,0)) -> 5.0821846 | AE8: =INDEX(Data_Prices!AE:AE,MATCH($G8,Data_Prices!$A:$A,0)) -> 5.0821846
B9: gso | C9: =$C$5 -> irn | D9: Gasoline | E9: $/liter | F9: ptp | G9: =Settings!$B$3&".mit.pbc."&Settings!$B$4&"."&$B9&".a."&$J$5 -> egy.mit.pbc.ind.gso.a.1 | H9: =Settings!$B$3&".mit.ptp."&$C$5&"."&$B9&".e."&$J$5 -> egy.mit.ptp.irn.gso.e.1 | K9: =INDEX(Data_Prices!K:K,MATCH($G9,Data_Prices!$A:$A,0)) -> 0.67114653 | L9: =INDEX(Data_Prices!L:L,MATCH($G9,Data_Prices!$A:$A,0)) -> 0.61197798 | M9: =INDEX(Data_Prices!M:M,MATCH($G9,Data_Prices!$A:$A,0)) -> 0.61180975 | N9: =INDEX(Data_Prices!N:N,MATCH($G9,Data_Prices!$A:$A,0)) -> 0.6035831 | O9: =INDEX(Data_Prices!O:O,MATCH($G9,Data_Prices!$A:$A,0)) -> 0.6035831 | P9: =INDEX(Data_Prices!P:P,MATCH($G9,Data_Prices!$A:$A,0)) -> 0.6035831 | Q9: =INDEX(Data_Prices!Q:Q,MATCH($G9,Data_Prices!$A:$A,0)) -> 0.6035831 | R9: =INDEX(Data_Prices!R:R,MATCH($G9,Data_Prices!$A:$A,0)) -> 0.6035831 | S9: =INDEX(Data_Prices!S:S,MATCH($G9,Data_Prices!$A:$A,0)) -> 0.6035831 | T9: =INDEX(Data_Prices!T:T,MATCH($G9,Data_Prices!$A:$A,0)) -> 0.6035831 | U9: =INDEX(Data_Prices!U:U,MATCH($G9,Data_Prices!$A:$A,0)) -> 0.6035831 | V9: =INDEX(Data_Prices!V:V,MATCH($G9,Data_Prices!$A:$A,0)) -> 0.6035831 | W9: =INDEX(Data_Prices!W:W,MATCH($G9,Data_Prices!$A:$A,0)) -> 0.6035831 | X9: =INDEX(Data_Prices!X:X,MATCH($G9,Data_Prices!$A:$A,0)) -> 0.6035831 | Y9: =INDEX(Data_Prices!Y:Y,MATCH($G9,Data_Prices!$A:$A,0)) -> 0.6035831 | Z9: =INDEX(Data_Prices!Z:Z,MATCH($G9,Data_Prices!$A:$A,0)) -> 0.6035831 | AA9: =INDEX(Data_Prices!AA:AA,MATCH($G9,Data_Prices!$A:$A,0)) -> 0.6035831 | AB9: =INDEX(Data_Prices!AB:AB,MATCH($G9,Data_Prices!$A:$A,0)) -> 0.6035831 | AC9: =INDEX(Data_Prices!AC:AC,MATCH($G9,Data_Prices!$A:$A,0)) -> 0.6035831 | AD9: =INDEX(Data_Prices!AD:AD,MATCH($G9,Data_Prices!$A:$A,0)) -> 0.6035831 | AE9: =INDEX(Data_Prices!AE:AE,MATCH($G9,Data_Prices!$A:$A,0)) -> 0.6035831
B10: die | C10: =$C$5 -> irn | D10: Diesel | E10: $/liter | F10: ptp | G10: =Settings!$B$3&".mit.pbc."&Settings!$B$4&"."&$B10&".a."&$J$5 -> egy.mit.pbc.ind.die.a.1 | H10: =Settings!$B$3&".mit.ptp."&$C$5&"."&$B10&".e."&$J$5 -> egy.mit.ptp.irn.die.e.1 | K10: =INDEX(Data_Prices!K:K,MATCH($G10,Data_Prices!$A:$A,0)) -> 0.55971121 | L10: =INDEX(Data_Prices!L:L,MATCH($G10,Data_Prices!$A:$A,0)) -> 0.49458873 | M10: =INDEX(Data_Prices!M:M,MATCH($G10,Data_Prices!$A:$A,0)) -> 0.50778655 | N10: =INDEX(Data_Prices!N:N,MATCH($G10,Data_Prices!$A:$A,0)) -> 0.47043643 | O10: =INDEX(Data_Prices!O:O,MATCH($G10,Data_Prices!$A:$A,0)) -> 0.47043643 | P10: =INDEX(Data_Prices!P:P,MATCH($G10,Data_Prices!$A:$A,0)) -> 0.47043643 | Q10: =INDEX(Data_Prices!Q:Q,MATCH($G10,Data_Prices!$A:$A,0)) -> 0.47043643 | R10: =INDEX(Data_Prices!R:R,MATCH($G10,Data_Prices!$A:$A,0)) -> 0.47043643 | S10: =INDEX(Data_Prices!S:S,MATCH($G10,Data_Prices!$A:$A,0)) -> 0.47043643 | T10: =INDEX(Data_Prices!T:T,MATCH($G10,Data_Prices!$A:$A,0)) -> 0.47043643 | U10: =INDEX(Data_Prices!U:U,MATCH($G10,Data_Prices!$A:$A,0)) -> 0.47043643 | V10: =INDEX(Data_Prices!V:V,MATCH($G10,Data_Prices!$A:$A,0)) -> 0.47043643 | W10: =INDEX(Data_Prices!W:W,MATCH($G10,Data_Prices!$A:$A,0)) -> 0.47043643 | X10: =INDEX(Data_Prices!X:X,MATCH($G10,Data_Prices!$A:$A,0)) -> 0.47043643 | Y10: =INDEX(Data_Prices!Y:Y,MATCH($G10,Data_Prices!$A:$A,0)) -> 0.47043643 | Z10: =INDEX(Data_Prices!Z:Z,MATCH($G10,Data_Prices!$A:$A,0)) -> 0.47043643 | AA10: =INDEX(Data_Prices!AA:AA,MATCH($G10,Data_Prices!$A:$A,0)) -> 0.47043643 | AB10: =INDEX(Data_Prices!AB:AB,MATCH($G10,Data_Prices!$A:$A,0)) -> 0.47043643 | AC10: =INDEX(Data_Prices!AC:AC,MATCH($G10,Data_Prices!$A:$A,0)) -> 0.47043643 | AD10: =INDEX(Data_Prices!AD:AD,MATCH($G10,Data_Prices!$A:$A,0)) -> 0.47043643 | AE10: =INDEX(Data_Prices!AE:AE,MATCH($G10,Data_Prices!$A:$A,0)) -> 0.47043643
B11: lpg | C11: =$C$5 -> irn | D11: LPG | E11: $/liter | F11: ptp | G11: =Settings!$B$3&".mit.pbc."&Settings!$B$4&"."&$B11&".a."&$J$5 -> egy.mit.pbc.ind.lpg.a.1 | H11: =Settings!$B$3&".mit.ptp."&$C$5&"."&$B11&".e."&$J$5 -> egy.mit.ptp.irn.lpg.e.1 | K11: =INDEX(Data_Prices!K:K,MATCH($G11,Data_Prices!$A:$A,0)) -> 0.20036669 | L11: =INDEX(Data_Prices!L:L,MATCH($G11,Data_Prices!$A:$A,0)) -> 0.15734474 | M11: =INDEX(Data_Prices!M:M,MATCH($G11,Data_Prices!$A:$A,0)) -> 0.16448404 | N11: =INDEX(Data_Prices!N:N,MATCH($G11,Data_Prices!$A:$A,0)) -> 0.15070908 | O11: =INDEX(Data_Prices!O:O,MATCH($G11,Data_Prices!$A:$A,0)) -> 0.15070908 | P11: =INDEX(Data_Prices!P:P,MATCH($G11,Data_Prices!$A:$A,0)) -> 0.15070908 | Q11: =INDEX(Data_Prices!Q:Q,MATCH($G11,Data_Prices!$A:$A,0)) -> 0.15070908 | R11: =INDEX(Data_Prices!R:R,MATCH($G11,Data_Prices!$A:$A,0)) -> 0.15070908 | S11: =INDEX(Data_Prices!S:S,MATCH($G11,Data_Prices!$A:$A,0)) -> 0.15070908 | T11: =INDEX(Data_Prices!T:T,MATCH($G11,Data_Prices!$A:$A,0)) -> 0.15070908 | U11: =INDEX(Data_Prices!U:U,MATCH($G11,Data_Prices!$A:$A,0)) -> 0.15070908 | V11: =INDEX(Data_Prices!V:V,MATCH($G11,Data_Prices!$A:$A,0)) -> 0.15070908 | W11: =INDEX(Data_Prices!W:W,MATCH($G11,Data_Prices!$A:$A,0)) -> 0.15070908 | X11: =INDEX(Data_Prices!X:X,MATCH($G11,Data_Prices!$A:$A,0)) -> 0.15070908 | Y11: =INDEX(Data_Prices!Y:Y,MATCH($G11,Data_Prices!$A:$A,0)) -> 0.15070908 | Z11: =INDEX(Data_Prices!Z:Z,MATCH($G11,Data_Prices!$A:$A,0)) -> 0.15070908 | AA11: =INDEX(Data_Prices!AA:AA,MATCH($G11,Data_Prices!$A:$A,0)) -> 0.15070908 | AB11: =INDEX(Data_Prices!AB:AB,MATCH($G11,Data_Prices!$A:$A,0)) -> 0.15070908 | AC11: =INDEX(Data_Prices!AC:AC,MATCH($G11,Data_Prices!$A:$A,0)) -> 0.15070908 | AD11: =INDEX(Data_Prices!AD:AD,MATCH($G11,Data_Prices!$A:$A,0)) -> 0.15070908 | AE11: =INDEX(Data_Prices!AE:AE,MATCH($G11,Data_Prices!$A:$A,0)) -> 0.15070908
B12: ker | C12: =$C$5 -> irn | D12: Kerosene | E12: $/liter | F12: ptp | G12: =Settings!$B$3&".mit.pbc."&Settings!$B$4&"."&$B12&".a."&$J$5 -> egy.mit.pbc.ind.ker.a.1 | H12: =Settings!$B$3&".mit.ptp."&$C$5&"."&$B12&".e."&$J$5 -> egy.mit.ptp.irn.ker.e.1 | K12: =INDEX(Data_Prices!K:K,MATCH($G12,Data_Prices!$A:$A,0)) -> 0.48429424 | L12: =INDEX(Data_Prices!L:L,MATCH($G12,Data_Prices!$A:$A,0)) -> 0.45642817 | M12: =INDEX(Data_Prices!M:M,MATCH($G12,Data_Prices!$A:$A,0)) -> 0.4316892 | N12: =INDEX(Data_Prices!N:N,MATCH($G12,Data_Prices!$A:$A,0)) -> 0.42507558 | O12: =INDEX(Data_Prices!O:O,MATCH($G12,Data_Prices!$A:$A,0)) -> 0.42507558 | P12: =INDEX(Data_Prices!P:P,MATCH($G12,Data_Prices!$A:$A,0)) -> 0.42507558 | Q12: =INDEX(Data_Prices!Q:Q,MATCH($G12,Data_Prices!$A:$A,0)) -> 0.42507558 | R12: =INDEX(Data_Prices!R:R,MATCH($G12,Data_Prices!$A:$A,0)) -> 0.42507558 | S12: =INDEX(Data_Prices!S:S,MATCH($G12,Data_Prices!$A:$A,0)) -> 0.42507558 | T12: =INDEX(Data_Prices!T:T,MATCH($G12,Data_Prices!$A:$A,0)) -> 0.42507558 | U12: =INDEX(Data_Prices!U:U,MATCH($G12,Data_Prices!$A:$A,0)) -> 0.42507558 | V12: =INDEX(Data_Prices!V:V,MATCH($G12,Data_Prices!$A:$A,0)) -> 0.42507558 | W12: =INDEX(Data_Prices!W:W,MATCH($G12,Data_Prices!$A:$A,0)) -> 0.42507558 | X12: =INDEX(Data_Prices!X:X,MATCH($G12,Data_Prices!$A:$A,0)) -> 0.42507558 | Y12: =INDEX(Data_Prices!Y:Y,MATCH($G12,Data_Prices!$A:$A,0)) -> 0.42507558 | Z12: =INDEX(Data_Prices!Z:Z,MATCH($G12,Data_Prices!$A:$A,0)) -> 0.42507558 | AA12: =INDEX(Data_Prices!AA:AA,MATCH($G12,Data_Prices!$A:$A,0)) -> 0.42507558 | AB12: =INDEX(Data_Prices!AB:AB,MATCH($G12,Data_Prices!$A:$A,0)) -> 0.42507558 | AC12: =INDEX(Data_Prices!AC:AC,MATCH($G12,Data_Prices!$A:$A,0)) -> 0.42507558 | AD12: =INDEX(Data_Prices!AD:AD,MATCH($G12,Data_Prices!$A:$A,0)) -> 0.42507558 | AE12: =INDEX(Data_Prices!AE:AE,MATCH($G12,Data_Prices!$A:$A,0)) -> 0.42507558
B13: oop | C13: =$C$5 -> irn | D13: Other oil products | E13: $/bbl | F13: ptp | G13: =Settings!$B$3&".mit.pbc."&Settings!$B$4&"."&$B13&".a."&$J$5 -> egy.mit.pbc.ind.oop.a.1 | H13: =Settings!$B$3&".mit.ptp."&$C$5&"."&$B13&".e."&$J$5 -> egy.mit.ptp.irn.oop.e.1 | K13: =INDEX(Data_Prices!K:K,MATCH($G13,Data_Prices!$A:$A,0)) -> 41.500338 | L13: =INDEX(Data_Prices!L:L,MATCH($G13,Data_Prices!$A:$A,0)) -> 34.41537 | M13: =INDEX(Data_Prices!M:M,MATCH($G13,Data_Prices!$A:$A,0)) -> 37.368961 | N13: =INDEX(Data_Prices!N:N,MATCH($G13,Data_Prices!$A:$A,0)) -> 28.982761 | O13: =INDEX(Data_Prices!O:O,MATCH($G13,Data_Prices!$A:$A,0)) -> 15 | P13: =INDEX(Data_Prices!P:P,MATCH($G13,Data_Prices!$A:$A,0)) -> 24.25863 | Q13: =INDEX(Data_Prices!Q:Q,MATCH($G13,Data_Prices!$A:$A,0)) -> 15 | R13: =INDEX(Data_Prices!R:R,MATCH($G13,Data_Prices!$A:$A,0)) -> 15 | S13: =INDEX(Data_Prices!S:S,MATCH($G13,Data_Prices!$A:$A,0)) -> 15 | T13: =INDEX(Data_Prices!T:T,MATCH($G13,Data_Prices!$A:$A,0)) -> 15 | U13: =INDEX(Data_Prices!U:U,MATCH($G13,Data_Prices!$A:$A,0)) -> 15 | V13: =INDEX(Data_Prices!V:V,MATCH($G13,Data_Prices!$A:$A,0)) -> 15 | W13: =INDEX(Data_Prices!W:W,MATCH($G13,Data_Prices!$A:$A,0)) -> 15 | X13: =INDEX(Data_Prices!X:X,MATCH($G13,Data_Prices!$A:$A,0)) -> 15 | Y13: =INDEX(Data_Prices!Y:Y,MATCH($G13,Data_Prices!$A:$A,0)) -> 15 | Z13: =INDEX(Data_Prices!Z:Z,MATCH($G13,Data_Prices!$A:$A,0)) -> 15 | AA13: =INDEX(Data_Prices!AA:AA,MATCH($G13,Data_Prices!$A:$A,0)) -> 15 | AB13: =INDEX(Data_Prices!AB:AB,MATCH($G13,Data_Prices!$A:$A,0)) -> 15 | AC13: =INDEX(Data_Prices!AC:AC,MATCH($G13,Data_Prices!$A:$A,0)) -> 15 | AD13: =INDEX(Data_Prices!AD:AD,MATCH($G13,Data_Prices!$A:$A,0)) -> 15 | AE13: =INDEX(Data_Prices!AE:AE,MATCH($G13,Data_Prices!$A:$A,0)) -> 15
B14: bio | C14: =$C$5 -> irn | D14: Biomass | E14: $/GJ | F14: ptp | G14: =Settings!$B$3&".mit.pbc."&Settings!$B$4&"."&$B14&".a."&$J$5 -> egy.mit.pbc.ind.bio.a.1 | H14: =Settings!$B$3&".mit.ptp."&$C$5&"."&$B14&".e."&$J$5 -> egy.mit.ptp.irn.bio.e.1 | K14: =INDEX(Data_Prices!K:K,MATCH($G14,Data_Prices!$A:$A,0)) -> 15.334551 | L14: =INDEX(Data_Prices!L:L,MATCH($G14,Data_Prices!$A:$A,0)) -> 14.199528 | M14: =INDEX(Data_Prices!M:M,MATCH($G14,Data_Prices!$A:$A,0)) -> 13.840442 | N14: =INDEX(Data_Prices!N:N,MATCH($G14,Data_Prices!$A:$A,0)) -> 13.567727 | O14: =INDEX(Data_Prices!O:O,MATCH($G14,Data_Prices!$A:$A,0)) -> 13.567727 | P14: =INDEX(Data_Prices!P:P,MATCH($G14,Data_Prices!$A:$A,0)) -> 13.567727 | Q14: =INDEX(Data_Prices!Q:Q,MATCH($G14,Data_Prices!$A:$A,0)) -> 13.567727 | R14: =INDEX(Data_Prices!R:R,MATCH($G14,Data_Prices!$A:$A,0)) -> 13.567727 | S14: =INDEX(Data_Prices!S:S,MATCH($G14,Data_Prices!$A:$A,0)) -> 13.567727 | T14: =INDEX(Data_Prices!T:T,MATCH($G14,Data_Prices!$A:$A,0)) -> 13.567727 | U14: =INDEX(Data_Prices!U:U,MATCH($G14,Data_Prices!$A:$A,0)) -> 13.567727 | V14: =INDEX(Data_Prices!V:V,MATCH($G14,Data_Prices!$A:$A,0)) -> 13.567727 | W14: =INDEX(Data_Prices!W:W,MATCH($G14,Data_Prices!$A:$A,0)) -> 13.567727 | X14: =INDEX(Data_Prices!X:X,MATCH($G14,Data_Prices!$A:$A,0)) -> 13.567727 | Y14: =INDEX(Data_Prices!Y:Y,MATCH($G14,Data_Prices!$A:$A,0)) -> 13.567727 | Z14: =INDEX(Data_Prices!Z:Z,MATCH($G14,Data_Prices!$A:$A,0)) -> 13.567727 | AA14: =INDEX(Data_Prices!AA:AA,MATCH($G14,Data_Prices!$A:$A,0)) -> 13.567727 | AB14: =INDEX(Data_Prices!AB:AB,MATCH($G14,Data_Prices!$A:$A,0)) -> 13.567727 | AC14: =INDEX(Data_Prices!AC:AC,MATCH($G14,Data_Prices!$A:$A,0)) -> 13.567727 | AD14: =INDEX(Data_Prices!AD:AD,MATCH($G14,Data_Prices!$A:$A,0)) -> 13.567727 | AE14: =INDEX(Data_Prices!AE:AE,MATCH($G14,Data_Prices!$A:$A,0)) -> 13.567727
B15: ren | C15: =$C$5 -> irn | D15: Self-generated renewables | E15: $/kwh | F15: ptp | G15: =Settings!$B$3&".mit.pbc."&Settings!$B$4&"."&$B15&".a."&$J$5 -> egy.mit.pbc.ind.ren.a.1 | H15: =Settings!$B$3&".mit.ptp."&$C$5&"."&$B15&".e."&$J$5 -> egy.mit.ptp.irn.ren.e.1 | K15: =INDEX(Data_Prices!K:K,MATCH($G15,Data_Prices!$A:$A,0)) -> 0 | L15: =INDEX(Data_Prices!L:L,MATCH($G15,Data_Prices!$A:$A,0)) -> 0.14404499 | M15: =INDEX(Data_Prices!M:M,MATCH($G15,Data_Prices!$A:$A,0)) -> 0.14102041 | N15: =INDEX(Data_Prices!N:N,MATCH($G15,Data_Prices!$A:$A,0)) -> 0.13511636 | O15: =INDEX(Data_Prices!O:O,MATCH($G15,Data_Prices!$A:$A,0)) -> 0.13098826 | P15: =INDEX(Data_Prices!P:P,MATCH($G15,Data_Prices!$A:$A,0)) -> 0.12790842 | Q15: =INDEX(Data_Prices!Q:Q,MATCH($G15,Data_Prices!$A:$A,0)) -> 0.12481431 | R15: =INDEX(Data_Prices!R:R,MATCH($G15,Data_Prices!$A:$A,0)) -> 0.12146026 | S15: =INDEX(Data_Prices!S:S,MATCH($G15,Data_Prices!$A:$A,0)) -> 0.11795074 | T15: =INDEX(Data_Prices!T:T,MATCH($G15,Data_Prices!$A:$A,0)) -> 0.11419916 | U15: =INDEX(Data_Prices!U:U,MATCH($G15,Data_Prices!$A:$A,0)) -> 0.1136651 | V15: =INDEX(Data_Prices!V:V,MATCH($G15,Data_Prices!$A:$A,0)) -> 0.11301693 | W15: =INDEX(Data_Prices!W:W,MATCH($G15,Data_Prices!$A:$A,0)) -> 0.11231407 | X15: =INDEX(Data_Prices!X:X,MATCH($G15,Data_Prices!$A:$A,0)) -> 0.11142204 | Y15: =INDEX(Data_Prices!Y:Y,MATCH($G15,Data_Prices!$A:$A,0)) -> 0.11043412 | Z15: =INDEX(Data_Prices!Z:Z,MATCH($G15,Data_Prices!$A:$A,0)) -> 0.10948397 | AA15: =INDEX(Data_Prices!AA:AA,MATCH($G15,Data_Prices!$A:$A,0)) -> 0.10839192 | AB15: =INDEX(Data_Prices!AB:AB,MATCH($G15,Data_Prices!$A:$A,0)) -> 0.10735443 | AC15: =INDEX(Data_Prices!AC:AC,MATCH($G15,Data_Prices!$A:$A,0)) -> 0.10516868 | AD15: =INDEX(Data_Prices!AD:AD,MATCH($G15,Data_Prices!$A:$A,0)) -> 0.10305798 | AE15: =INDEX(Data_Prices!AE:AE,MATCH($G15,Data_Prices!$A:$A,0)) -> 0.10093184
B16: Post-tax price: pre-tax + new-policy wedge x sector coverage factor (= CPAT atp row)
B17: coa | C17: =$C$5 -> irn | D17: Coal | E17: $/GJ | F17: atp | G17: =Settings!$B$3&".mit.nce."&Settings!$B$4&"."&$B17&".a."&$J$5 -> egy.mit.nce.ind.coa.a.1 | H17: =Settings!$B$3&".mit.atp."&$C$5&"."&$B17&".e."&$J$5 -> egy.mit.atp.irn.coa.e.1 | K17: =K7+INDEX(Data_Prices!K:K,MATCH($G17,Data_Prices!$A:$A,0))*K$37 -> 11.182902 | L17: =L7+INDEX(Data_Prices!L:L,MATCH($G17,Data_Prices!$A:$A,0))*L$37 -> 10.523361 | M17: =M7+INDEX(Data_Prices!M:M,MATCH($G17,Data_Prices!$A:$A,0))*M$37 -> 10.299561 | N17: =N7+INDEX(Data_Prices!N:N,MATCH($G17,Data_Prices!$A:$A,0))*N$37 -> 9.5775284 | O17: =O7+INDEX(Data_Prices!O:O,MATCH($G17,Data_Prices!$A:$A,0))*O$37 -> 8.4854783 | P17: =P7+INDEX(Data_Prices!P:P,MATCH($G17,Data_Prices!$A:$A,0))*P$37 -> 9.0871922 | Q17: =Q7+INDEX(Data_Prices!Q:Q,MATCH($G17,Data_Prices!$A:$A,0))*Q$37 -> 9.2229237 | R17: =R7+INDEX(Data_Prices!R:R,MATCH($G17,Data_Prices!$A:$A,0))*R$37 -> 9.158565 | S17: =S7+INDEX(Data_Prices!S:S,MATCH($G17,Data_Prices!$A:$A,0))*S$37 -> 9.0895479 | T17: =T7+INDEX(Data_Prices!T:T,MATCH($G17,Data_Prices!$A:$A,0))*T$37 -> 9.0156817 | U17: =U7+INDEX(Data_Prices!U:U,MATCH($G17,Data_Prices!$A:$A,0))*U$37 -> 8.9443978 | V17: =V7+INDEX(Data_Prices!V:V,MATCH($G17,Data_Prices!$A:$A,0))*V$37 -> 8.9443978 | W17: =W7+INDEX(Data_Prices!W:W,MATCH($G17,Data_Prices!$A:$A,0))*W$37 -> 8.9443978 | X17: =X7+INDEX(Data_Prices!X:X,MATCH($G17,Data_Prices!$A:$A,0))*X$37 -> 8.9443978 | Y17: =Y7+INDEX(Data_Prices!Y:Y,MATCH($G17,Data_Prices!$A:$A,0))*Y$37 -> 8.9443978 | Z17: =Z7+INDEX(Data_Prices!Z:Z,MATCH($G17,Data_Prices!$A:$A,0))*Z$37 -> 8.9443978 | AA17: =AA7+INDEX(Data_Prices!AA:AA,MATCH($G17,Data_Prices!$A:$A,0))*AA$37 -> 8.9443978 | AB17: =AB7+INDEX(Data_Prices!AB:AB,MATCH($G17,Data_Prices!$A:$A,0))*AB$37 -> 8.9443978 | AC17: =AC7+INDEX(Data_Prices!AC:AC,MATCH($G17,Data_Prices!$A:$A,0))*AC$37 -> 8.9443978 | AD17: =AD7+INDEX(Data_Prices!AD:AD,MATCH($G17,Data_Prices!$A:$A,0))*AD$37 -> 8.9443978 | AE17: =AE7+INDEX(Data_Prices!AE:AE,MATCH($G17,Data_Prices!$A:$A,0))*AE$37 -> 8.9443978
B18: nga | C18: =$C$5 -> irn | D18: Natural gas | E18: $/GJ | F18: atp | G18: =Settings!$B$3&".mit.nce."&Settings!$B$4&"."&$B18&".a."&$J$5 -> egy.mit.nce.ind.nga.a.1 | H18: =Settings!$B$3&".mit.atp."&$C$5&"."&$B18&".e."&$J$5 -> egy.mit.atp.irn.nga.e.1 | K18: =K8+INDEX(Data_Prices!K:K,MATCH($G18,Data_Prices!$A:$A,0))*K$37 -> 6.0634636 | L18: =L8+INDEX(Data_Prices!L:L,MATCH($G18,Data_Prices!$A:$A,0))*L$37 -> 5.4510151 | M18: =M8+INDEX(Data_Prices!M:M,MATCH($G18,Data_Prices!$A:$A,0))*M$37 -> 5.1193563 | N18: =N8+INDEX(Data_Prices!N:N,MATCH($G18,Data_Prices!$A:$A,0))*N$37 -> 5.0821846 | O18: =O8+INDEX(Data_Prices!O:O,MATCH($G18,Data_Prices!$A:$A,0))*O$37 -> 5.0821846 | P18: =P8+INDEX(Data_Prices!P:P,MATCH($G18,Data_Prices!$A:$A,0))*P$37 -> 5.0821846 | Q18: =Q8+INDEX(Data_Prices!Q:Q,MATCH($G18,Data_Prices!$A:$A,0))*Q$37 -> 5.0821846 | R18: =R8+INDEX(Data_Prices!R:R,MATCH($G18,Data_Prices!$A:$A,0))*R$37 -> 5.0821846 | S18: =S8+INDEX(Data_Prices!S:S,MATCH($G18,Data_Prices!$A:$A,0))*S$37 -> 5.0821846 | T18: =T8+INDEX(Data_Prices!T:T,MATCH($G18,Data_Prices!$A:$A,0))*T$37 -> 5.0821846 | U18: =U8+INDEX(Data_Prices!U:U,MATCH($G18,Data_Prices!$A:$A,0))*U$37 -> 5.0821846 | V18: =V8+INDEX(Data_Prices!V:V,MATCH($G18,Data_Prices!$A:$A,0))*V$37 -> 5.0821846 | W18: =W8+INDEX(Data_Prices!W:W,MATCH($G18,Data_Prices!$A:$A,0))*W$37 -> 5.0821846 | X18: =X8+INDEX(Data_Prices!X:X,MATCH($G18,Data_Prices!$A:$A,0))*X$37 -> 5.0821846 | Y18: =Y8+INDEX(Data_Prices!Y:Y,MATCH($G18,Data_Prices!$A:$A,0))*Y$37 -> 5.0821846 | Z18: =Z8+INDEX(Data_Prices!Z:Z,MATCH($G18,Data_Prices!$A:$A,0))*Z$37 -> 5.0821846 | AA18: =AA8+INDEX(Data_Prices!AA:AA,MATCH($G18,Data_Prices!$A:$A,0))*AA$37 -> 5.0821846 | AB18: =AB8+INDEX(Data_Prices!AB:AB,MATCH($G18,Data_Prices!$A:$A,0))*AB$37 -> 5.0821846 | AC18: =AC8+INDEX(Data_Prices!AC:AC,MATCH($G18,Data_Prices!$A:$A,0))*AC$37 -> 5.0821846 | AD18: =AD8+INDEX(Data_Prices!AD:AD,MATCH($G18,Data_Prices!$A:$A,0))*AD$37 -> 5.0821846 | AE18: =AE8+INDEX(Data_Prices!AE:AE,MATCH($G18,Data_Prices!$A:$A,0))*AE$37 -> 5.0821846
B19: gso | C19: =$C$5 -> irn | D19: Gasoline | E19: $/liter | F19: atp | G19: =Settings!$B$3&".mit.nce."&Settings!$B$4&"."&$B19&".a."&$J$5 -> egy.mit.nce.ind.gso.a.1 | H19: =Settings!$B$3&".mit.atp."&$C$5&"."&$B19&".e."&$J$5 -> egy.mit.atp.irn.gso.e.1 | K19: =K9+INDEX(Data_Prices!K:K,MATCH($G19,Data_Prices!$A:$A,0))*K$37 -> 0.67114653 | L19: =L9+INDEX(Data_Prices!L:L,MATCH($G19,Data_Prices!$A:$A,0))*L$37 -> 0.61197798 | M19: =M9+INDEX(Data_Prices!M:M,MATCH($G19,Data_Prices!$A:$A,0))*M$37 -> 0.61180975 | N19: =N9+INDEX(Data_Prices!N:N,MATCH($G19,Data_Prices!$A:$A,0))*N$37 -> 0.6035831 | O19: =O9+INDEX(Data_Prices!O:O,MATCH($G19,Data_Prices!$A:$A,0))*O$37 -> 0.6035831 | P19: =P9+INDEX(Data_Prices!P:P,MATCH($G19,Data_Prices!$A:$A,0))*P$37 -> 0.6035831 | Q19: =Q9+INDEX(Data_Prices!Q:Q,MATCH($G19,Data_Prices!$A:$A,0))*Q$37 -> 0.6035831 | R19: =R9+INDEX(Data_Prices!R:R,MATCH($G19,Data_Prices!$A:$A,0))*R$37 -> 0.6035831 | S19: =S9+INDEX(Data_Prices!S:S,MATCH($G19,Data_Prices!$A:$A,0))*S$37 -> 0.6035831 | T19: =T9+INDEX(Data_Prices!T:T,MATCH($G19,Data_Prices!$A:$A,0))*T$37 -> 0.6035831 | U19: =U9+INDEX(Data_Prices!U:U,MATCH($G19,Data_Prices!$A:$A,0))*U$37 -> 0.6035831 | V19: =V9+INDEX(Data_Prices!V:V,MATCH($G19,Data_Prices!$A:$A,0))*V$37 -> 0.6035831 | W19: =W9+INDEX(Data_Prices!W:W,MATCH($G19,Data_Prices!$A:$A,0))*W$37 -> 0.6035831 | X19: =X9+INDEX(Data_Prices!X:X,MATCH($G19,Data_Prices!$A:$A,0))*X$37 -> 0.6035831 | Y19: =Y9+INDEX(Data_Prices!Y:Y,MATCH($G19,Data_Prices!$A:$A,0))*Y$37 -> 0.6035831 | Z19: =Z9+INDEX(Data_Prices!Z:Z,MATCH($G19,Data_Prices!$A:$A,0))*Z$37 -> 0.6035831 | AA19: =AA9+INDEX(Data_Prices!AA:AA,MATCH($G19,Data_Prices!$A:$A,0))*AA$37 -> 0.6035831 | AB19: =AB9+INDEX(Data_Prices!AB:AB,MATCH($G19,Data_Prices!$A:$A,0))*AB$37 -> 0.6035831 | AC19: =AC9+INDEX(Data_Prices!AC:AC,MATCH($G19,Data_Prices!$A:$A,0))*AC$37 -> 0.6035831 | AD19: =AD9+INDEX(Data_Prices!AD:AD,MATCH($G19,Data_Prices!$A:$A,0))*AD$37 -> 0.6035831 | AE19: =AE9+INDEX(Data_Prices!AE:AE,MATCH($G19,Data_Prices!$A:$A,0))*AE$37 -> 0.6035831
B20: die | C20: =$C$5 -> irn | D20: Diesel | E20: $/liter | F20: atp | G20: =Settings!$B$3&".mit.nce."&Settings!$B$4&"."&$B20&".a."&$J$5 -> egy.mit.nce.ind.die.a.1 | H20: =Settings!$B$3&".mit.atp."&$C$5&"."&$B20&".e."&$J$5 -> egy.mit.atp.irn.die.e.1 | K20: =K10+INDEX(Data_Prices!K:K,MATCH($G20,Data_Prices!$A:$A,0))*K$37 -> 0.55971121 | L20: =L10+INDEX(Data_Prices!L:L,MATCH($G20,Data_Prices!$A:$A,0))*L$37 -> 0.49458873 | M20: =M10+INDEX(Data_Prices!M:M,MATCH($G20,Data_Prices!$A:$A,0))*M$37 -> 0.50778655 | N20: =N10+INDEX(Data_Prices!N:N,MATCH($G20,Data_Prices!$A:$A,0))*N$37 -> 0.47043643 | O20: =O10+INDEX(Data_Prices!O:O,MATCH($G20,Data_Prices!$A:$A,0))*O$37 -> 0.47043643 | P20: =P10+INDEX(Data_Prices!P:P,MATCH($G20,Data_Prices!$A:$A,0))*P$37 -> 0.47043643 | Q20: =Q10+INDEX(Data_Prices!Q:Q,MATCH($G20,Data_Prices!$A:$A,0))*Q$37 -> 0.47043643 | R20: =R10+INDEX(Data_Prices!R:R,MATCH($G20,Data_Prices!$A:$A,0))*R$37 -> 0.47043643 | S20: =S10+INDEX(Data_Prices!S:S,MATCH($G20,Data_Prices!$A:$A,0))*S$37 -> 0.47043643 | T20: =T10+INDEX(Data_Prices!T:T,MATCH($G20,Data_Prices!$A:$A,0))*T$37 -> 0.47043643 | U20: =U10+INDEX(Data_Prices!U:U,MATCH($G20,Data_Prices!$A:$A,0))*U$37 -> 0.47043643 | V20: =V10+INDEX(Data_Prices!V:V,MATCH($G20,Data_Prices!$A:$A,0))*V$37 -> 0.47043643 | W20: =W10+INDEX(Data_Prices!W:W,MATCH($G20,Data_Prices!$A:$A,0))*W$37 -> 0.47043643 | X20: =X10+INDEX(Data_Prices!X:X,MATCH($G20,Data_Prices!$A:$A,0))*X$37 -> 0.47043643 | Y20: =Y10+INDEX(Data_Prices!Y:Y,MATCH($G20,Data_Prices!$A:$A,0))*Y$37 -> 0.47043643 | Z20: =Z10+INDEX(Data_Prices!Z:Z,MATCH($G20,Data_Prices!$A:$A,0))*Z$37 -> 0.47043643 | AA20: =AA10+INDEX(Data_Prices!AA:AA,MATCH($G20,Data_Prices!$A:$A,0))*AA$37 -> 0.47043643 | AB20: =AB10+INDEX(Data_Prices!AB:AB,MATCH($G20,Data_Prices!$A:$A,0))*AB$37 -> 0.47043643 | AC20: =AC10+INDEX(Data_Prices!AC:AC,MATCH($G20,Data_Prices!$A:$A,0))*AC$37 -> 0.47043643 | AD20: =AD10+INDEX(Data_Prices!AD:AD,MATCH($G20,Data_Prices!$A:$A,0))*AD$37 -> 0.47043643 | AE20: =AE10+INDEX(Data_Prices!AE:AE,MATCH($G20,Data_Prices!$A:$A,0))*AE$37 -> 0.47043643
B21: lpg | C21: =$C$5 -> irn | D21: LPG | E21: $/liter | F21: atp | G21: =Settings!$B$3&".mit.nce."&Settings!$B$4&"."&$B21&".a."&$J$5 -> egy.mit.nce.ind.lpg.a.1 | H21: =Settings!$B$3&".mit.atp."&$C$5&"."&$B21&".e."&$J$5 -> egy.mit.atp.irn.lpg.e.1 | K21: =K11+INDEX(Data_Prices!K:K,MATCH($G21,Data_Prices!$A:$A,0))*K$37 -> 0.20036669 | L21: =L11+INDEX(Data_Prices!L:L,MATCH($G21,Data_Prices!$A:$A,0))*L$37 -> 0.15734474 | M21: =M11+INDEX(Data_Prices!M:M,MATCH($G21,Data_Prices!$A:$A,0))*M$37 -> 0.16448404 | N21: =N11+INDEX(Data_Prices!N:N,MATCH($G21,Data_Prices!$A:$A,0))*N$37 -> 0.15070908 | O21: =O11+INDEX(Data_Prices!O:O,MATCH($G21,Data_Prices!$A:$A,0))*O$37 -> 0.15070908 | P21: =P11+INDEX(Data_Prices!P:P,MATCH($G21,Data_Prices!$A:$A,0))*P$37 -> 0.15070908 | Q21: =Q11+INDEX(Data_Prices!Q:Q,MATCH($G21,Data_Prices!$A:$A,0))*Q$37 -> 0.15070908 | R21: =R11+INDEX(Data_Prices!R:R,MATCH($G21,Data_Prices!$A:$A,0))*R$37 -> 0.15070908 | S21: =S11+INDEX(Data_Prices!S:S,MATCH($G21,Data_Prices!$A:$A,0))*S$37 -> 0.15070908 | T21: =T11+INDEX(Data_Prices!T:T,MATCH($G21,Data_Prices!$A:$A,0))*T$37 -> 0.15070908 | U21: =U11+INDEX(Data_Prices!U:U,MATCH($G21,Data_Prices!$A:$A,0))*U$37 -> 0.15070908 | V21: =V11+INDEX(Data_Prices!V:V,MATCH($G21,Data_Prices!$A:$A,0))*V$37 -> 0.15070908 | W21: =W11+INDEX(Data_Prices!W:W,MATCH($G21,Data_Prices!$A:$A,0))*W$37 -> 0.15070908 | X21: =X11+INDEX(Data_Prices!X:X,MATCH($G21,Data_Prices!$A:$A,0))*X$37 -> 0.15070908 | Y21: =Y11+INDEX(Data_Prices!Y:Y,MATCH($G21,Data_Prices!$A:$A,0))*Y$37 -> 0.15070908 | Z21: =Z11+INDEX(Data_Prices!Z:Z,MATCH($G21,Data_Prices!$A:$A,0))*Z$37 -> 0.15070908 | AA21: =AA11+INDEX(Data_Prices!AA:AA,MATCH($G21,Data_Prices!$A:$A,0))*AA$37 -> 0.15070908 | AB21: =AB11+INDEX(Data_Prices!AB:AB,MATCH($G21,Data_Prices!$A:$A,0))*AB$37 -> 0.15070908 | AC21: =AC11+INDEX(Data_Prices!AC:AC,MATCH($G21,Data_Prices!$A:$A,0))*AC$37 -> 0.15070908 | AD21: =AD11+INDEX(Data_Prices!AD:AD,MATCH($G21,Data_Prices!$A:$A,0))*AD$37 -> 0.15070908 | AE21: =AE11+INDEX(Data_Prices!AE:AE,MATCH($G21,Data_Prices!$A:$A,0))*AE$37 -> 0.15070908
B22: ker | C22: =$C$5 -> irn | D22: Kerosene | E22: $/liter | F22: atp | G22: =Settings!$B$3&".mit.nce."&Settings!$B$4&"."&$B22&".a."&$J$5 -> egy.mit.nce.ind.ker.a.1 | H22: =Settings!$B$3&".mit.atp."&$C$5&"."&$B22&".e."&$J$5 -> egy.mit.atp.irn.ker.e.1 | K22: =K12+INDEX(Data_Prices!K:K,MATCH($G22,Data_Prices!$A:$A,0))*K$37 -> 0.48429424 | L22: =L12+INDEX(Data_Prices!L:L,MATCH($G22,Data_Prices!$A:$A,0))*L$37 -> 0.45642817 | M22: =M12+INDEX(Data_Prices!M:M,MATCH($G22,Data_Prices!$A:$A,0))*M$37 -> 0.4316892 | N22: =N12+INDEX(Data_Prices!N:N,MATCH($G22,Data_Prices!$A:$A,0))*N$37 -> 0.42507558 | O22: =O12+INDEX(Data_Prices!O:O,MATCH($G22,Data_Prices!$A:$A,0))*O$37 -> 0.42507558 | P22: =P12+INDEX(Data_Prices!P:P,MATCH($G22,Data_Prices!$A:$A,0))*P$37 -> 0.42507558 | Q22: =Q12+INDEX(Data_Prices!Q:Q,MATCH($G22,Data_Prices!$A:$A,0))*Q$37 -> 0.42507558 | R22: =R12+INDEX(Data_Prices!R:R,MATCH($G22,Data_Prices!$A:$A,0))*R$37 -> 0.42507558 | S22: =S12+INDEX(Data_Prices!S:S,MATCH($G22,Data_Prices!$A:$A,0))*S$37 -> 0.42507558 | T22: =T12+INDEX(Data_Prices!T:T,MATCH($G22,Data_Prices!$A:$A,0))*T$37 -> 0.42507558 | U22: =U12+INDEX(Data_Prices!U:U,MATCH($G22,Data_Prices!$A:$A,0))*U$37 -> 0.42507558 | V22: =V12+INDEX(Data_Prices!V:V,MATCH($G22,Data_Prices!$A:$A,0))*V$37 -> 0.42507558 | W22: =W12+INDEX(Data_Prices!W:W,MATCH($G22,Data_Prices!$A:$A,0))*W$37 -> 0.42507558 | X22: =X12+INDEX(Data_Prices!X:X,MATCH($G22,Data_Prices!$A:$A,0))*X$37 -> 0.42507558 | Y22: =Y12+INDEX(Data_Prices!Y:Y,MATCH($G22,Data_Prices!$A:$A,0))*Y$37 -> 0.42507558 | Z22: =Z12+INDEX(Data_Prices!Z:Z,MATCH($G22,Data_Prices!$A:$A,0))*Z$37 -> 0.42507558 | AA22: =AA12+INDEX(Data_Prices!AA:AA,MATCH($G22,Data_Prices!$A:$A,0))*AA$37 -> 0.42507558 | AB22: =AB12+INDEX(Data_Prices!AB:AB,MATCH($G22,Data_Prices!$A:$A,0))*AB$37 -> 0.42507558 | AC22: =AC12+INDEX(Data_Prices!AC:AC,MATCH($G22,Data_Prices!$A:$A,0))*AC$37 -> 0.42507558 | AD22: =AD12+INDEX(Data_Prices!AD:AD,MATCH($G22,Data_Prices!$A:$A,0))*AD$37 -> 0.42507558 | AE22: =AE12+INDEX(Data_Prices!AE:AE,MATCH($G22,Data_Prices!$A:$A,0))*AE$37 -> 0.42507558
B23: oop | C23: =$C$5 -> irn | D23: Other oil products | E23: $/bbl | F23: atp | G23: =Settings!$B$3&".mit.nce."&Settings!$B$4&"."&$B23&".a."&$J$5 -> egy.mit.nce.ind.oop.a.1 | H23: =Settings!$B$3&".mit.atp."&$C$5&"."&$B23&".e."&$J$5 -> egy.mit.atp.irn.oop.e.1 | K23: =K13+INDEX(Data_Prices!K:K,MATCH($G23,Data_Prices!$A:$A,0))*K$37 -> 41.500338 | L23: =L13+INDEX(Data_Prices!L:L,MATCH($G23,Data_Prices!$A:$A,0))*L$37 -> 34.41537 | M23: =M13+INDEX(Data_Prices!M:M,MATCH($G23,Data_Prices!$A:$A,0))*M$37 -> 37.368961 | N23: =N13+INDEX(Data_Prices!N:N,MATCH($G23,Data_Prices!$A:$A,0))*N$37 -> 28.982761 | O23: =O13+INDEX(Data_Prices!O:O,MATCH($G23,Data_Prices!$A:$A,0))*O$37 -> 15 | P23: =P13+INDEX(Data_Prices!P:P,MATCH($G23,Data_Prices!$A:$A,0))*P$37 -> 24.25863 | Q23: =Q13+INDEX(Data_Prices!Q:Q,MATCH($G23,Data_Prices!$A:$A,0))*Q$37 -> 15 | R23: =R13+INDEX(Data_Prices!R:R,MATCH($G23,Data_Prices!$A:$A,0))*R$37 -> 15 | S23: =S13+INDEX(Data_Prices!S:S,MATCH($G23,Data_Prices!$A:$A,0))*S$37 -> 15 | T23: =T13+INDEX(Data_Prices!T:T,MATCH($G23,Data_Prices!$A:$A,0))*T$37 -> 15 | U23: =U13+INDEX(Data_Prices!U:U,MATCH($G23,Data_Prices!$A:$A,0))*U$37 -> 15 | V23: =V13+INDEX(Data_Prices!V:V,MATCH($G23,Data_Prices!$A:$A,0))*V$37 -> 15 | W23: =W13+INDEX(Data_Prices!W:W,MATCH($G23,Data_Prices!$A:$A,0))*W$37 -> 15 | X23: =X13+INDEX(Data_Prices!X:X,MATCH($G23,Data_Prices!$A:$A,0))*X$37 -> 15 | Y23: =Y13+INDEX(Data_Prices!Y:Y,MATCH($G23,Data_Prices!$A:$A,0))*Y$37 -> 15 | Z23: =Z13+INDEX(Data_Prices!Z:Z,MATCH($G23,Data_Prices!$A:$A,0))*Z$37 -> 15 | AA23: =AA13+INDEX(Data_Prices!AA:AA,MATCH($G23,Data_Prices!$A:$A,0))*AA$37 -> 15 | AB23: =AB13+INDEX(Data_Prices!AB:AB,MATCH($G23,Data_Prices!$A:$A,0))*AB$37 -> 15 | AC23: =AC13+INDEX(Data_Prices!AC:AC,MATCH($G23,Data_Prices!$A:$A,0))*AC$37 -> 15 | AD23: =AD13+INDEX(Data_Prices!AD:AD,MATCH($G23,Data_Prices!$A:$A,0))*AD$37 -> 15 | AE23: =AE13+INDEX(Data_Prices!AE:AE,MATCH($G23,Data_Prices!$A:$A,0))*AE$37 -> 15
B24: bio | C24: =$C$5 -> irn | D24: Biomass | E24: $/GJ | F24: atp | G24: =Settings!$B$3&".mit.nce."&Settings!$B$4&"."&$B24&".a."&$J$5 -> egy.mit.nce.ind.bio.a.1 | H24: =Settings!$B$3&".mit.atp."&$C$5&"."&$B24&".e."&$J$5 -> egy.mit.atp.irn.bio.e.1 | K24: =K14+INDEX(Data_Prices!K:K,MATCH($G24,Data_Prices!$A:$A,0))*K$37 -> 15.334551 | L24: =L14+INDEX(Data_Prices!L:L,MATCH($G24,Data_Prices!$A:$A,0))*L$37 -> 14.199528 | M24: =M14+INDEX(Data_Prices!M:M,MATCH($G24,Data_Prices!$A:$A,0))*M$37 -> 13.840442 | N24: =N14+INDEX(Data_Prices!N:N,MATCH($G24,Data_Prices!$A:$A,0))*N$37 -> 13.567727 | O24: =O14+INDEX(Data_Prices!O:O,MATCH($G24,Data_Prices!$A:$A,0))*O$37 -> 13.567727 | P24: =P14+INDEX(Data_Prices!P:P,MATCH($G24,Data_Prices!$A:$A,0))*P$37 -> 13.567727 | Q24: =Q14+INDEX(Data_Prices!Q:Q,MATCH($G24,Data_Prices!$A:$A,0))*Q$37 -> 13.567727 | R24: =R14+INDEX(Data_Prices!R:R,MATCH($G24,Data_Prices!$A:$A,0))*R$37 -> 13.567727 | S24: =S14+INDEX(Data_Prices!S:S,MATCH($G24,Data_Prices!$A:$A,0))*S$37 -> 13.567727 | T24: =T14+INDEX(Data_Prices!T:T,MATCH($G24,Data_Prices!$A:$A,0))*T$37 -> 13.567727 | U24: =U14+INDEX(Data_Prices!U:U,MATCH($G24,Data_Prices!$A:$A,0))*U$37 -> 13.567727 | V24: =V14+INDEX(Data_Prices!V:V,MATCH($G24,Data_Prices!$A:$A,0))*V$37 -> 13.567727 | W24: =W14+INDEX(Data_Prices!W:W,MATCH($G24,Data_Prices!$A:$A,0))*W$37 -> 13.567727 | X24: =X14+INDEX(Data_Prices!X:X,MATCH($G24,Data_Prices!$A:$A,0))*X$37 -> 13.567727 | Y24: =Y14+INDEX(Data_Prices!Y:Y,MATCH($G24,Data_Prices!$A:$A,0))*Y$37 -> 13.567727 | Z24: =Z14+INDEX(Data_Prices!Z:Z,MATCH($G24,Data_Prices!$A:$A,0))*Z$37 -> 13.567727 | AA24: =AA14+INDEX(Data_Prices!AA:AA,MATCH($G24,Data_Prices!$A:$A,0))*AA$37 -> 13.567727 | AB24: =AB14+INDEX(Data_Prices!AB:AB,MATCH($G24,Data_Prices!$A:$A,0))*AB$37 -> 13.567727 | AC24: =AC14+INDEX(Data_Prices!AC:AC,MATCH($G24,Data_Prices!$A:$A,0))*AC$37 -> 13.567727 | AD24: =AD14+INDEX(Data_Prices!AD:AD,MATCH($G24,Data_Prices!$A:$A,0))*AD$37 -> 13.567727 | AE24: =AE14+INDEX(Data_Prices!AE:AE,MATCH($G24,Data_Prices!$A:$A,0))*AE$37 -> 13.567727
B25: ren | C25: =$C$5 -> irn | D25: Self-generated renewables | E25: $/kwh | F25: atp | G25: =Settings!$B$3&".mit.nce."&Settings!$B$4&"."&$B25&".a."&$J$5 -> egy.mit.nce.ind.ren.a.1 | H25: =Settings!$B$3&".mit.atp."&$C$5&"."&$B25&".e."&$J$5 -> egy.mit.atp.irn.ren.e.1 | K25: =K15+INDEX(Data_Prices!K:K,MATCH($G25,Data_Prices!$A:$A,0))*K$37 -> 0 | L25: =L15+INDEX(Data_Prices!L:L,MATCH($G25,Data_Prices!$A:$A,0))*L$37 -> 0.14404499 | M25: =M15+INDEX(Data_Prices!M:M,MATCH($G25,Data_Prices!$A:$A,0))*M$37 -> 0.14102041 | N25: =N15+INDEX(Data_Prices!N:N,MATCH($G25,Data_Prices!$A:$A,0))*N$37 -> 0.13511636 | O25: =O15+INDEX(Data_Prices!O:O,MATCH($G25,Data_Prices!$A:$A,0))*O$37 -> 0.13098826 | P25: =P15+INDEX(Data_Prices!P:P,MATCH($G25,Data_Prices!$A:$A,0))*P$37 -> 0.12790842 | Q25: =Q15+INDEX(Data_Prices!Q:Q,MATCH($G25,Data_Prices!$A:$A,0))*Q$37 -> 0.12481431 | R25: =R15+INDEX(Data_Prices!R:R,MATCH($G25,Data_Prices!$A:$A,0))*R$37 -> 0.12146026 | S25: =S15+INDEX(Data_Prices!S:S,MATCH($G25,Data_Prices!$A:$A,0))*S$37 -> 0.11795074 | T25: =T15+INDEX(Data_Prices!T:T,MATCH($G25,Data_Prices!$A:$A,0))*T$37 -> 0.11419916 | U25: =U15+INDEX(Data_Prices!U:U,MATCH($G25,Data_Prices!$A:$A,0))*U$37 -> 0.1136651 | V25: =V15+INDEX(Data_Prices!V:V,MATCH($G25,Data_Prices!$A:$A,0))*V$37 -> 0.11301693 | W25: =W15+INDEX(Data_Prices!W:W,MATCH($G25,Data_Prices!$A:$A,0))*W$37 -> 0.11231407 | X25: =X15+INDEX(Data_Prices!X:X,MATCH($G25,Data_Prices!$A:$A,0))*X$37 -> 0.11142204 | Y25: =Y15+INDEX(Data_Prices!Y:Y,MATCH($G25,Data_Prices!$A:$A,0))*Y$37 -> 0.11043412 | Z25: =Z15+INDEX(Data_Prices!Z:Z,MATCH($G25,Data_Prices!$A:$A,0))*Z$37 -> 0.10948397 | AA25: =AA15+INDEX(Data_Prices!AA:AA,MATCH($G25,Data_Prices!$A:$A,0))*AA$37 -> 0.10839192 | AB25: =AB15+INDEX(Data_Prices!AB:AB,MATCH($G25,Data_Prices!$A:$A,0))*AB$37 -> 0.10735443 | AC25: =AC15+INDEX(Data_Prices!AC:AC,MATCH($G25,Data_Prices!$A:$A,0))*AC$37 -> 0.10516868 | AD25: =AD15+INDEX(Data_Prices!AD:AD,MATCH($G25,Data_Prices!$A:$A,0))*AD$37 -> 0.10305798 | AE25: =AE15+INDEX(Data_Prices!AE:AE,MATCH($G25,Data_Prices!$A:$A,0))*AE$37 -> 0.10093184
B26: Shadow price: post-tax + shadow price of non-price policies x share acting on efficiency
B27: coa | C27: =$C$5 -> irn | D27: Coal | E27: $/GJ | F27: shp | G27: =Settings!$B$3&".mit.shp."&$B27&"."&Settings!$B$4&"."&$J$5 -> egy.mit.shp.coa.ind.1 | H27: =Settings!$B$3&".mit.shp."&$C$5&"."&$B27&".e."&$J$5 -> egy.mit.shp.irn.coa.e.1 | K27: =K17+INDEX(Data_Prices!K:K,MATCH($G27,Data_Prices!$A:$A,0))*K$38 -> 11.182902 | L27: =L17+INDEX(Data_Prices!L:L,MATCH($G27,Data_Prices!$A:$A,0))*L$38 -> 10.523361 | M27: =M17+INDEX(Data_Prices!M:M,MATCH($G27,Data_Prices!$A:$A,0))*M$38 -> 10.299561 | N27: =N17+INDEX(Data_Prices!N:N,MATCH($G27,Data_Prices!$A:$A,0))*N$38 -> 9.5775284 | O27: =O17+INDEX(Data_Prices!O:O,MATCH($G27,Data_Prices!$A:$A,0))*O$38 -> 8.4854783 | P27: =P17+INDEX(Data_Prices!P:P,MATCH($G27,Data_Prices!$A:$A,0))*P$38 -> 9.0871922 | Q27: =Q17+INDEX(Data_Prices!Q:Q,MATCH($G27,Data_Prices!$A:$A,0))*Q$38 -> 9.2229237 | R27: =R17+INDEX(Data_Prices!R:R,MATCH($G27,Data_Prices!$A:$A,0))*R$38 -> 9.158565 | S27: =S17+INDEX(Data_Prices!S:S,MATCH($G27,Data_Prices!$A:$A,0))*S$38 -> 9.0895479 | T27: =T17+INDEX(Data_Prices!T:T,MATCH($G27,Data_Prices!$A:$A,0))*T$38 -> 9.0156817 | U27: =U17+INDEX(Data_Prices!U:U,MATCH($G27,Data_Prices!$A:$A,0))*U$38 -> 8.9443978 | V27: =V17+INDEX(Data_Prices!V:V,MATCH($G27,Data_Prices!$A:$A,0))*V$38 -> 8.9443978 | W27: =W17+INDEX(Data_Prices!W:W,MATCH($G27,Data_Prices!$A:$A,0))*W$38 -> 8.9443978 | X27: =X17+INDEX(Data_Prices!X:X,MATCH($G27,Data_Prices!$A:$A,0))*X$38 -> 8.9443978 | Y27: =Y17+INDEX(Data_Prices!Y:Y,MATCH($G27,Data_Prices!$A:$A,0))*Y$38 -> 8.9443978 | Z27: =Z17+INDEX(Data_Prices!Z:Z,MATCH($G27,Data_Prices!$A:$A,0))*Z$38 -> 8.9443978 | AA27: =AA17+INDEX(Data_Prices!AA:AA,MATCH($G27,Data_Prices!$A:$A,0))*AA$38 -> 8.9443978 | AB27: =AB17+INDEX(Data_Prices!AB:AB,MATCH($G27,Data_Prices!$A:$A,0))*AB$38 -> 8.9443978 | AC27: =AC17+INDEX(Data_Prices!AC:AC,MATCH($G27,Data_Prices!$A:$A,0))*AC$38 -> 8.9443978 | AD27: =AD17+INDEX(Data_Prices!AD:AD,MATCH($G27,Data_Prices!$A:$A,0))*AD$38 -> 8.9443978 | AE27: =AE17+INDEX(Data_Prices!AE:AE,MATCH($G27,Data_Prices!$A:$A,0))*AE$38 -> 8.9443978
B28: nga | C28: =$C$5 -> irn | D28: Natural gas | E28: $/GJ | F28: shp | G28: =Settings!$B$3&".mit.shp."&$B28&"."&Settings!$B$4&"."&$J$5 -> egy.mit.shp.nga.ind.1 | H28: =Settings!$B$3&".mit.shp."&$C$5&"."&$B28&".e."&$J$5 -> egy.mit.shp.irn.nga.e.1 | K28: =K18+INDEX(Data_Prices!K:K,MATCH($G28,Data_Prices!$A:$A,0))*K$38 -> 6.0634636 | L28: =L18+INDEX(Data_Prices!L:L,MATCH($G28,Data_Prices!$A:$A,0))*L$38 -> 5.4510151 | M28: =M18+INDEX(Data_Prices!M:M,MATCH($G28,Data_Prices!$A:$A,0))*M$38 -> 5.1193563 | N28: =N18+INDEX(Data_Prices!N:N,MATCH($G28,Data_Prices!$A:$A,0))*N$38 -> 5.0821846 | O28: =O18+INDEX(Data_Prices!O:O,MATCH($G28,Data_Prices!$A:$A,0))*O$38 -> 5.0821846 | P28: =P18+INDEX(Data_Prices!P:P,MATCH($G28,Data_Prices!$A:$A,0))*P$38 -> 5.0821846 | Q28: =Q18+INDEX(Data_Prices!Q:Q,MATCH($G28,Data_Prices!$A:$A,0))*Q$38 -> 5.0821846 | R28: =R18+INDEX(Data_Prices!R:R,MATCH($G28,Data_Prices!$A:$A,0))*R$38 -> 5.0821846 | S28: =S18+INDEX(Data_Prices!S:S,MATCH($G28,Data_Prices!$A:$A,0))*S$38 -> 5.0821846 | T28: =T18+INDEX(Data_Prices!T:T,MATCH($G28,Data_Prices!$A:$A,0))*T$38 -> 5.0821846 | U28: =U18+INDEX(Data_Prices!U:U,MATCH($G28,Data_Prices!$A:$A,0))*U$38 -> 5.0821846 | V28: =V18+INDEX(Data_Prices!V:V,MATCH($G28,Data_Prices!$A:$A,0))*V$38 -> 5.0821846 | W28: =W18+INDEX(Data_Prices!W:W,MATCH($G28,Data_Prices!$A:$A,0))*W$38 -> 5.0821846 | X28: =X18+INDEX(Data_Prices!X:X,MATCH($G28,Data_Prices!$A:$A,0))*X$38 -> 5.0821846 | Y28: =Y18+INDEX(Data_Prices!Y:Y,MATCH($G28,Data_Prices!$A:$A,0))*Y$38 -> 5.0821846 | Z28: =Z18+INDEX(Data_Prices!Z:Z,MATCH($G28,Data_Prices!$A:$A,0))*Z$38 -> 5.0821846 | AA28: =AA18+INDEX(Data_Prices!AA:AA,MATCH($G28,Data_Prices!$A:$A,0))*AA$38 -> 5.0821846 | AB28: =AB18+INDEX(Data_Prices!AB:AB,MATCH($G28,Data_Prices!$A:$A,0))*AB$38 -> 5.0821846 | AC28: =AC18+INDEX(Data_Prices!AC:AC,MATCH($G28,Data_Prices!$A:$A,0))*AC$38 -> 5.0821846 | AD28: =AD18+INDEX(Data_Prices!AD:AD,MATCH($G28,Data_Prices!$A:$A,0))*AD$38 -> 5.0821846 | AE28: =AE18+INDEX(Data_Prices!AE:AE,MATCH($G28,Data_Prices!$A:$A,0))*AE$38 -> 5.0821846
B29: gso | C29: =$C$5 -> irn | D29: Gasoline | E29: $/liter | F29: shp | G29: =Settings!$B$3&".mit.shp."&$B29&"."&Settings!$B$4&"."&$J$5 -> egy.mit.shp.gso.ind.1 | H29: =Settings!$B$3&".mit.shp."&$C$5&"."&$B29&".e."&$J$5 -> egy.mit.shp.irn.gso.e.1 | K29: =K19+INDEX(Data_Prices!K:K,MATCH($G29,Data_Prices!$A:$A,0))*K$38 -> 0.67114653 | L29: =L19+INDEX(Data_Prices!L:L,MATCH($G29,Data_Prices!$A:$A,0))*L$38 -> 0.61197798 | M29: =M19+INDEX(Data_Prices!M:M,MATCH($G29,Data_Prices!$A:$A,0))*M$38 -> 0.61180975 | N29: =N19+INDEX(Data_Prices!N:N,MATCH($G29,Data_Prices!$A:$A,0))*N$38 -> 0.6035831 | O29: =O19+INDEX(Data_Prices!O:O,MATCH($G29,Data_Prices!$A:$A,0))*O$38 -> 0.6035831 | P29: =P19+INDEX(Data_Prices!P:P,MATCH($G29,Data_Prices!$A:$A,0))*P$38 -> 0.6035831 | Q29: =Q19+INDEX(Data_Prices!Q:Q,MATCH($G29,Data_Prices!$A:$A,0))*Q$38 -> 0.6035831 | R29: =R19+INDEX(Data_Prices!R:R,MATCH($G29,Data_Prices!$A:$A,0))*R$38 -> 0.6035831 | S29: =S19+INDEX(Data_Prices!S:S,MATCH($G29,Data_Prices!$A:$A,0))*S$38 -> 0.6035831 | T29: =T19+INDEX(Data_Prices!T:T,MATCH($G29,Data_Prices!$A:$A,0))*T$38 -> 0.6035831 | U29: =U19+INDEX(Data_Prices!U:U,MATCH($G29,Data_Prices!$A:$A,0))*U$38 -> 0.6035831 | V29: =V19+INDEX(Data_Prices!V:V,MATCH($G29,Data_Prices!$A:$A,0))*V$38 -> 0.6035831 | W29: =W19+INDEX(Data_Prices!W:W,MATCH($G29,Data_Prices!$A:$A,0))*W$38 -> 0.6035831 | X29: =X19+INDEX(Data_Prices!X:X,MATCH($G29,Data_Prices!$A:$A,0))*X$38 -> 0.6035831 | Y29: =Y19+INDEX(Data_Prices!Y:Y,MATCH($G29,Data_Prices!$A:$A,0))*Y$38 -> 0.6035831 | Z29: =Z19+INDEX(Data_Prices!Z:Z,MATCH($G29,Data_Prices!$A:$A,0))*Z$38 -> 0.6035831 | AA29: =AA19+INDEX(Data_Prices!AA:AA,MATCH($G29,Data_Prices!$A:$A,0))*AA$38 -> 0.6035831 | AB29: =AB19+INDEX(Data_Prices!AB:AB,MATCH($G29,Data_Prices!$A:$A,0))*AB$38 -> 0.6035831 | AC29: =AC19+INDEX(Data_Prices!AC:AC,MATCH($G29,Data_Prices!$A:$A,0))*AC$38 -> 0.6035831 | AD29: =AD19+INDEX(Data_Prices!AD:AD,MATCH($G29,Data_Prices!$A:$A,0))*AD$38 -> 0.6035831 | AE29: =AE19+INDEX(Data_Prices!AE:AE,MATCH($G29,Data_Prices!$A:$A,0))*AE$38 -> 0.6035831
B30: die | C30: =$C$5 -> irn | D30: Diesel | E30: $/liter | F30: shp | G30: =Settings!$B$3&".mit.shp."&$B30&"."&Settings!$B$4&"."&$J$5 -> egy.mit.shp.die.ind.1 | H30: =Settings!$B$3&".mit.shp."&$C$5&"."&$B30&".e."&$J$5 -> egy.mit.shp.irn.die.e.1 | K30: =K20+INDEX(Data_Prices!K:K,MATCH($G30,Data_Prices!$A:$A,0))*K$38 -> 0.55971121 | L30: =L20+INDEX(Data_Prices!L:L,MATCH($G30,Data_Prices!$A:$A,0))*L$38 -> 0.49458873 | M30: =M20+INDEX(Data_Prices!M:M,MATCH($G30,Data_Prices!$A:$A,0))*M$38 -> 0.50778655 | N30: =N20+INDEX(Data_Prices!N:N,MATCH($G30,Data_Prices!$A:$A,0))*N$38 -> 0.47043643 | O30: =O20+INDEX(Data_Prices!O:O,MATCH($G30,Data_Prices!$A:$A,0))*O$38 -> 0.47043643 | P30: =P20+INDEX(Data_Prices!P:P,MATCH($G30,Data_Prices!$A:$A,0))*P$38 -> 0.47043643 | Q30: =Q20+INDEX(Data_Prices!Q:Q,MATCH($G30,Data_Prices!$A:$A,0))*Q$38 -> 0.47043643 | R30: =R20+INDEX(Data_Prices!R:R,MATCH($G30,Data_Prices!$A:$A,0))*R$38 -> 0.47043643 | S30: =S20+INDEX(Data_Prices!S:S,MATCH($G30,Data_Prices!$A:$A,0))*S$38 -> 0.47043643 | T30: =T20+INDEX(Data_Prices!T:T,MATCH($G30,Data_Prices!$A:$A,0))*T$38 -> 0.47043643 | U30: =U20+INDEX(Data_Prices!U:U,MATCH($G30,Data_Prices!$A:$A,0))*U$38 -> 0.47043643 | V30: =V20+INDEX(Data_Prices!V:V,MATCH($G30,Data_Prices!$A:$A,0))*V$38 -> 0.47043643 | W30: =W20+INDEX(Data_Prices!W:W,MATCH($G30,Data_Prices!$A:$A,0))*W$38 -> 0.47043643 | X30: =X20+INDEX(Data_Prices!X:X,MATCH($G30,Data_Prices!$A:$A,0))*X$38 -> 0.47043643 | Y30: =Y20+INDEX(Data_Prices!Y:Y,MATCH($G30,Data_Prices!$A:$A,0))*Y$38 -> 0.47043643 | Z30: =Z20+INDEX(Data_Prices!Z:Z,MATCH($G30,Data_Prices!$A:$A,0))*Z$38 -> 0.47043643 | AA30: =AA20+INDEX(Data_Prices!AA:AA,MATCH($G30,Data_Prices!$A:$A,0))*AA$38 -> 0.47043643 | AB30: =AB20+INDEX(Data_Prices!AB:AB,MATCH($G30,Data_Prices!$A:$A,0))*AB$38 -> 0.47043643 | AC30: =AC20+INDEX(Data_Prices!AC:AC,MATCH($G30,Data_Prices!$A:$A,0))*AC$38 -> 0.47043643 | AD30: =AD20+INDEX(Data_Prices!AD:AD,MATCH($G30,Data_Prices!$A:$A,0))*AD$38 -> 0.47043643 | AE30: =AE20+INDEX(Data_Prices!AE:AE,MATCH($G30,Data_Prices!$A:$A,0))*AE$38 -> 0.47043643
B31: lpg | C31: =$C$5 -> irn | D31: LPG | E31: $/liter | F31: shp | G31: =Settings!$B$3&".mit.shp."&$B31&"."&Settings!$B$4&"."&$J$5 -> egy.mit.shp.lpg.ind.1 | H31: =Settings!$B$3&".mit.shp."&$C$5&"."&$B31&".e."&$J$5 -> egy.mit.shp.irn.lpg.e.1 | K31: =K21+INDEX(Data_Prices!K:K,MATCH($G31,Data_Prices!$A:$A,0))*K$38 -> 0.20036669 | L31: =L21+INDEX(Data_Prices!L:L,MATCH($G31,Data_Prices!$A:$A,0))*L$38 -> 0.15734474 | M31: =M21+INDEX(Data_Prices!M:M,MATCH($G31,Data_Prices!$A:$A,0))*M$38 -> 0.16448404 | N31: =N21+INDEX(Data_Prices!N:N,MATCH($G31,Data_Prices!$A:$A,0))*N$38 -> 0.15070908 | O31: =O21+INDEX(Data_Prices!O:O,MATCH($G31,Data_Prices!$A:$A,0))*O$38 -> 0.15070908 | P31: =P21+INDEX(Data_Prices!P:P,MATCH($G31,Data_Prices!$A:$A,0))*P$38 -> 0.15070908 | Q31: =Q21+INDEX(Data_Prices!Q:Q,MATCH($G31,Data_Prices!$A:$A,0))*Q$38 -> 0.15070908 | R31: =R21+INDEX(Data_Prices!R:R,MATCH($G31,Data_Prices!$A:$A,0))*R$38 -> 0.15070908 | S31: =S21+INDEX(Data_Prices!S:S,MATCH($G31,Data_Prices!$A:$A,0))*S$38 -> 0.15070908 | T31: =T21+INDEX(Data_Prices!T:T,MATCH($G31,Data_Prices!$A:$A,0))*T$38 -> 0.15070908 | U31: =U21+INDEX(Data_Prices!U:U,MATCH($G31,Data_Prices!$A:$A,0))*U$38 -> 0.15070908 | V31: =V21+INDEX(Data_Prices!V:V,MATCH($G31,Data_Prices!$A:$A,0))*V$38 -> 0.15070908 | W31: =W21+INDEX(Data_Prices!W:W,MATCH($G31,Data_Prices!$A:$A,0))*W$38 -> 0.15070908 | X31: =X21+INDEX(Data_Prices!X:X,MATCH($G31,Data_Prices!$A:$A,0))*X$38 -> 0.15070908 | Y31: =Y21+INDEX(Data_Prices!Y:Y,MATCH($G31,Data_Prices!$A:$A,0))*Y$38 -> 0.15070908 | Z31: =Z21+INDEX(Data_Prices!Z:Z,MATCH($G31,Data_Prices!$A:$A,0))*Z$38 -> 0.15070908 | AA31: =AA21+INDEX(Data_Prices!AA:AA,MATCH($G31,Data_Prices!$A:$A,0))*AA$38 -> 0.15070908 | AB31: =AB21+INDEX(Data_Prices!AB:AB,MATCH($G31,Data_Prices!$A:$A,0))*AB$38 -> 0.15070908 | AC31: =AC21+INDEX(Data_Prices!AC:AC,MATCH($G31,Data_Prices!$A:$A,0))*AC$38 -> 0.15070908 | AD31: =AD21+INDEX(Data_Prices!AD:AD,MATCH($G31,Data_Prices!$A:$A,0))*AD$38 -> 0.15070908 | AE31: =AE21+INDEX(Data_Prices!AE:AE,MATCH($G31,Data_Prices!$A:$A,0))*AE$38 -> 0.15070908
