Workbook
Name POSTTAX: _xlfn.LAMBDA(_xlpm.pre_policy_p,_xlpm.new_policy,_xlpm.vat_rate,MAX(_xlpm.pre_policy_p+_xlpm.new_policy*(1+_xlpm.vat_rate),0.01))
Name SUPPLYCOST: _xlfn.LAMBDA(_xlpm.fix_sp,_xlpm.sp_prev,_xlpm.gp_now,_xlpm.gp_prev,_xlpm.fix_sp+(_xlpm.sp_prev-_xlpm.fix_sp)*_xlpm.gp_now/_xlpm.gp_prev)

Sheet Mitigation
A1: Variable | B1: Fuel | C1: Sector | D1: Param 1 | E1: Param 2 | F1: Param 3 | G1: Param 4 | H1: Description | I1: Unit | J1: Source | L1: Scenario 1: output code | AB1: Scenario 2: output code
A2: Mitigation module - price to fuel use (copy-pasteable, design 2, legacy CPAT sections)
A3: Scenario assumptions (one column group per scenario: code column + years; copy a whole group to add a scenario)
H4: Year | M4: =Settings!$C$7 -> 2022 | N4: =M4+1 -> 2023 | O4: =N4+1 -> 2024 | P4: =O4+1 -> 2025 | Q4: =P4+1 -> 2026 | R4: =Q4+1 -> 2027 | S4: =R4+1 -> 2028 | T4: =S4+1 -> 2029 | U4: =T4+1 -> 2030 | ... Z4: =Y4+1 -> 2035 | AC4: =Settings!$C$7 -> 2022 | AD4: =AC4+1 -> 2023 | AE4: =AD4+1 -> 2024 | AF4: =AE4+1 -> 2025 | AG4: =AF4+1 -> 2026 | AH4: =AG4+1 -> 2027 | AI4: =AH4+1 -> 2028 | AJ4: =AI4+1 -> 2029 | AK4: =AJ4+1 -> 2030 | ... AP4: =AO4+1 -> 2035
H5: Scenario number (MTInputs column) | L5: 1 | M5: =L5 -> 1 | N5: =M5 -> 1 | O5: =N5 -> 1 | P5: =O5 -> 1 | Q5: =P5 -> 1 | R5: =Q5 -> 1 | S5: =R5 -> 1 | T5: =S5 -> 1 | ... Z5: =Y5 -> 1 | AB5: =L5+1 -> 2 | AC5: =AB5 -> 2 | AD5: =AC5 -> 2 | AE5: =AD5 -> 2 | AF5: =AE5 -> 2 | AG5: =AF5 -> 2 | AH5: =AG5 -> 2 | AI5: =AH5 -> 2 | AJ5: =AI5 -> 2 | ... AP5: =AO5 -> 2
H6: Scenario name (from MTInputs) | M6: =INDEX(MTInputs!$J$6:$AZ$6,MATCH(M$5,MTInputs!$J$5:$AZ$5,0)) -> Baseline (no carbon price) | AC6: =INDEX(MTInputs!$J$6:$AZ$6,MATCH(AC$5,MTInputs!$J$5:$AZ$5,0)) -> Carbon price $20/tCO2 from 2027
A7: gdp.pos.pct | H7: =INDEX(Variables!$B$5:$B$65,MATCH($A7,Variables!$A$5:$A$65,0))&IF($C7="",""," | "&INDEX(Mapping!$B$5:$B$26,MATCH($C7,Mapping!$A$5:$A$26,0))&" | "&INDEX(Mapping!$B$30:$B$41,MATCH($B7,Mapping!$A$30:$A$41,0))) -> Real GDP growth | I7: =INDEX(Variables!$C$5:$C$65,MATCH($A7,Variables!$A$5:$A$65,0)) -> % | J7: =INDEX(Variables!$E$5:$E$65,MATCH($A7,Variables!$A$5:$A$65,0)) -> WEO (lookup by country) | L7: =LOWER(Settings!$C$4)&".mit."&$A7&IF($C7="","","."&$C7&"."&$B7)&IF(INDEX(Variables!$D$5:$D$65,MATCH($A7,Variables!$A$5:$A$65,0))="","","."&INDEX(Variables!$D$5:$D$65,MATCH($A7,Variables!$A$5:$A$65,0)))&"."&L$5 -> egy.mit.gdp.pos.pct.1 | M7: =INDEX(WEO!$F$4:$AZ$1000,MATCH(Settings!$C$4&"|gdp_growth",WEO!$A$4:$A$1000,0),MATCH(M$4,WEO!$F$3:$AZ$3,0)) -> 0.06651345 | N7: =INDEX(WEO!$F$4:$AZ$1000,MATCH(Settings!$C$4&"|gdp_growth",WEO!$A$4:$A$1000,0),MATCH(N$4,WEO!$F$3:$AZ$3,0)) -> 0.03760281 | O7: =INDEX(WEO!$F$4:$AZ$1000,MATCH(Settings!$C$4&"|gdp_growth",WEO!$A$4:$A$1000,0),MATCH(O$4,WEO!$F$3:$AZ$3,0)) -> 0.02398801 | P7: =INDEX(WEO!$F$4:$AZ$1000,MATCH(Settings!$C$4&"|gdp_growth",WEO!$A$4:$A$1000,0),MATCH(P$4,WEO!$F$3:$AZ$3,0)) -> 0.04392387 | Q7: =INDEX(WEO!$F$4:$AZ$1000,MATCH(Settings!$C$4&"|gdp_growth",WEO!$A$4:$A$1000,0),MATCH(Q$4,WEO!$F$3:$AZ$3,0)) -> 0.04239706 | R7: =INDEX(WEO!$F$4:$AZ$1000,MATCH(Settings!$C$4&"|gdp_growth",WEO!$A$4:$A$1000,0),MATCH(R$4,WEO!$F$3:$AZ$3,0)) -> 0.04829218 | S7: =INDEX(WEO!$F$4:$AZ$1000,MATCH(Settings!$C$4&"|gdp_growth",WEO!$A$4:$A$1000,0),MATCH(S$4,WEO!$F$3:$AZ$3,0)) -> 0.05535316 | T7: =INDEX(WEO!$F$4:$AZ$1000,MATCH(Settings!$C$4&"|gdp_growth",WEO!$A$4:$A$1000,0),MATCH(T$4,WEO!$F$3:$AZ$3,0)) -> 0.05226606 | ... Z7: =INDEX(WEO!$F$4:$AZ$1000,MATCH(Settings!$C$4&"|gdp_growth",WEO!$A$4:$A$1000,0),MATCH(Z$4,WEO!$F$3:$AZ$3,0)) -> 0.04576172 | AB7: =LOWER(Settings!$C$4)&".mit."&$A7&IF($C7="","","."&$C7&"."&$B7)&IF(INDEX(Variables!$D$5:$D$65,MATCH($A7,Variables!$A$5:$A$65,0))="","","."&INDEX(Variables!$D$5:$D$65,MATCH($A7,Variables!$A$5:$A$65,0)))&"."&AB$5 -> egy.mit.gdp.pos.pct.2 | AC7: =INDEX(WEO!$F$4:$AZ$1000,MATCH(Settings!$C$4&"|gdp_growth",WEO!$A$4:$A$1000,0),MATCH(AC$4,WEO!$F$3:$AZ$3,0)) -> 0.06651345 | AD7: =INDEX(WEO!$F$4:$AZ$1000,MATCH(Settings!$C$4&"|gdp_growth",WEO!$A$4:$A$1000,0),MATCH(AD$4,WEO!$F$3:$AZ$3,0)) -> 0.03760281 | AE7: =INDEX(WEO!$F$4:$AZ$1000,MATCH(Settings!$C$4&"|gdp_growth",WEO!$A$4:$A$1000,0),MATCH(AE$4,WEO!$F$3:$AZ$3,0)) -> 0.02398801 | AF7: =INDEX(WEO!$F$4:$AZ$1000,MATCH(Settings!$C$4&"|gdp_growth",WEO!$A$4:$A$1000,0),MATCH(AF$4,WEO!$F$3:$AZ$3,0)) -> 0.04392387 | AG7: =INDEX(WEO!$F$4:$AZ$1000,MATCH(Settings!$C$4&"|gdp_growth",WEO!$A$4:$A$1000,0),MATCH(AG$4,WEO!$F$3:$AZ$3,0)) -> 0.04239706 | AH7: =INDEX(WEO!$F$4:$AZ$1000,MATCH(Settings!$C$4&"|gdp_growth",WEO!$A$4:$A$1000,0),MATCH(AH$4,WEO!$F$3:$AZ$3,0)) -> 0.04829218 | AI7: =INDEX(WEO!$F$4:$AZ$1000,MATCH(Settings!$C$4&"|gdp_growth",WEO!$A$4:$A$1000,0),MATCH(AI$4,WEO!$F$3:$AZ$3,0)) -> 0.05535316 | AJ7: =INDEX(WEO!$F$4:$AZ$1000,MATCH(Settings!$C$4&"|gdp_growth",WEO!$A$4:$A$1000,0),MATCH(AJ$4,WEO!$F$3:$AZ$3,0)) -> 0.05226606 | ... AP7: =INDEX(WEO!$F$4:$AZ$1000,MATCH(Settings!$C$4&"|gdp_growth",WEO!$A$4:$A$1000,0),MATCH(AP$4,WEO!$F$3:$AZ$3,0)) -> 0.04576172
A8: infl | H8: =INDEX(Variables!$B$5:$B$65,MATCH($A8,Variables!$A$5:$A$65,0))&IF($C8="",""," | "&INDEX(Mapping!$B$5:$B$26,MATCH($C8,Mapping!$A$5:$A$26,0))&" | "&INDEX(Mapping!$B$30:$B$41,MATCH($B8,Mapping!$A$30:$A$41,0))) -> Inflation index: US CPI, ResultsYear = 1 (nominal -> real for domestic prices and nominal policy inputs) | I8: =INDEX(Variables!$C$5:$C$65,MATCH($A8,Variables!$A$5:$A$65,0)) -> index | J8: =INDEX(Variables!$E$5:$E$65,MATCH($A8,Variables!$A$5:$A$65,0)) -> WEO USA|pcpi: CPI(ResultsYear) / CPI(year) | L8: =LOWER(Settings!$C$4)&".mit."&$A8&IF($C8="","","."&$C8&"."&$B8)&IF(INDEX(Variables!$D$5:$D$65,MATCH($A8,Variables!$A$5:$A$65,0))="","","."&INDEX(Variables!$D$5:$D$65,MATCH($A8,Variables!$A$5:$A$65,0)))&"."&L$5 -> egy.mit.infl.1 | M8: =INDEX(WEO!$F$4:$AZ$1000,MATCH("USA|pcpi",WEO!$A$4:$A$1000,0),MATCH(Settings!$C$8,WEO!$F$3:$AZ$3,0))/INDEX(WEO!$F$4:$AZ$1000,MATCH("USA|pcpi",WEO!$A$4:$A$1000,0),MATCH(M$4,WEO!$F$3:$AZ$3,0)) -> 1.1368176 | N8: =INDEX(WEO!$F$4:$AZ$1000,MATCH("USA|pcpi",WEO!$A$4:$A$1000,0),MATCH(Settings!$C$8,WEO!$F$3:$AZ$3,0))/INDEX(WEO!$F$4:$AZ$1000,MATCH("USA|pcpi",WEO!$A$4:$A$1000,0),MATCH(N$4,WEO!$F$3:$AZ$3,0)) -> 1.091761 | O8: =INDEX(WEO!$F$4:$AZ$1000,MATCH("USA|pcpi",WEO!$A$4:$A$1000,0),MATCH(Settings!$C$8,WEO!$F$3:$AZ$3,0))/INDEX(WEO!$F$4:$AZ$1000,MATCH("USA|pcpi",WEO!$A$4:$A$1000,0),MATCH(O$4,WEO!$F$3:$AZ$3,0)) -> 1.0604552 | P8: =INDEX(WEO!$F$4:$AZ$1000,MATCH("USA|pcpi",WEO!$A$4:$A$1000,0),MATCH(Settings!$C$8,WEO!$F$3:$AZ$3,0))/INDEX(WEO!$F$4:$AZ$1000,MATCH("USA|pcpi",WEO!$A$4:$A$1000,0),MATCH(P$4,WEO!$F$3:$AZ$3,0)) -> 1.0322791 | Q8: =INDEX(WEO!$F$4:$AZ$1000,MATCH("USA|pcpi",WEO!$A$4:$A$1000,0),MATCH(Settings!$C$8,WEO!$F$3:$AZ$3,0))/INDEX(WEO!$F$4:$AZ$1000,MATCH("USA|pcpi",WEO!$A$4:$A$1000,0),MATCH(Q$4,WEO!$F$3:$AZ$3,0)) -> 1 | R8: =INDEX(WEO!$F$4:$AZ$1000,MATCH("USA|pcpi",WEO!$A$4:$A$1000,0),MATCH(Settings!$C$8,WEO!$F$3:$AZ$3,0))/INDEX(WEO!$F$4:$AZ$1000,MATCH("USA|pcpi",WEO!$A$4:$A$1000,0),MATCH(R$4,WEO!$F$3:$AZ$3,0)) -> 0.97903568 | S8: =INDEX(WEO!$F$4:$AZ$1000,MATCH("USA|pcpi",WEO!$A$4:$A$1000,0),MATCH(Settings!$C$8,WEO!$F$3:$AZ$3,0))/INDEX(WEO!$F$4:$AZ$1000,MATCH("USA|pcpi",WEO!$A$4:$A$1000,0),MATCH(S$4,WEO!$F$3:$AZ$3,0)) -> 0.95811375 | T8: =INDEX(WEO!$F$4:$AZ$1000,MATCH("USA|pcpi",WEO!$A$4:$A$1000,0),MATCH(Settings!$C$8,WEO!$F$3:$AZ$3,0))/INDEX(WEO!$F$4:$AZ$1000,MATCH("USA|pcpi",WEO!$A$4:$A$1000,0),MATCH(T$4,WEO!$F$3:$AZ$3,0)) -> 0.93759961 | ... Z8: =INDEX(WEO!$F$4:$AZ$1000,MATCH("USA|pcpi",WEO!$A$4:$A$1000,0),MATCH(Settings!$C$8,WEO!$F$3:$AZ$3,0))/INDEX(WEO!$F$4:$AZ$1000,MATCH("USA|pcpi",WEO!$A$4:$A$1000,0),MATCH(Z$4,WEO!$F$3:$AZ$3,0)) -> 0.89789601 | AB8: =LOWER(Settings!$C$4)&".mit."&$A8&IF($C8="","","."&$C8&"."&$B8)&IF(INDEX(Variables!$D$5:$D$65,MATCH($A8,Variables!$A$5:$A$65,0))="","","."&INDEX(Variables!$D$5:$D$65,MATCH($A8,Variables!$A$5:$A$65,0)))&"."&AB$5 -> egy.mit.infl.2 | AC8: =INDEX(WEO!$F$4:$AZ$1000,MATCH("USA|pcpi",WEO!$A$4:$A$1000,0),MATCH(Settings!$C$8,WEO!$F$3:$AZ$3,0))/INDEX(WEO!$F$4:$AZ$1000,MATCH("USA|pcpi",WEO!$A$4:$A$1000,0),MATCH(AC$4,WEO!$F$3:$AZ$3,0)) -> 1.1368176 | AD8: =INDEX(WEO!$F$4:$AZ$1000,MATCH("USA|pcpi",WEO!$A$4:$A$1000,0),MATCH(Settings!$C$8,WEO!$F$3:$AZ$3,0))/INDEX(WEO!$F$4:$AZ$1000,MATCH("USA|pcpi",WEO!$A$4:$A$1000,0),MATCH(AD$4,WEO!$F$3:$AZ$3,0)) -> 1.091761 | AE8: =INDEX(WEO!$F$4:$AZ$1000,MATCH("USA|pcpi",WEO!$A$4:$A$1000,0),MATCH(Settings!$C$8,WEO!$F$3:$AZ$3,0))/INDEX(WEO!$F$4:$AZ$1000,MATCH("USA|pcpi",WEO!$A$4:$A$1000,0),MATCH(AE$4,WEO!$F$3:$AZ$3,0)) -> 1.0604552 | AF8: =INDEX(WEO!$F$4:$AZ$1000,MATCH("USA|pcpi",WEO!$A$4:$A$1000,0),MATCH(Settings!$C$8,WEO!$F$3:$AZ$3,0))/INDEX(WEO!$F$4:$AZ$1000,MATCH("USA|pcpi",WEO!$A$4:$A$1000,0),MATCH(AF$4,WEO!$F$3:$AZ$3,0)) -> 1.0322791 | AG8: =INDEX(WEO!$F$4:$AZ$1000,MATCH("USA|pcpi",WEO!$A$4:$A$1000,0),MATCH(Settings!$C$8,WEO!$F$3:$AZ$3,0))/INDEX(WEO!$F$4:$AZ$1000,MATCH("USA|pcpi",WEO!$A$4:$A$1000,0),MATCH(AG$4,WEO!$F$3:$AZ$3,0)) -> 1 | AH8: =INDEX(WEO!$F$4:$AZ$1000,MATCH("USA|pcpi",WEO!$A$4:$A$1000,0),MATCH(Settings!$C$8,WEO!$F$3:$AZ$3,0))/INDEX(WEO!$F$4:$AZ$1000,MATCH("USA|pcpi",WEO!$A$4:$A$1000,0),MATCH(AH$4,WEO!$F$3:$AZ$3,0)) -> 0.97903568 | AI8: =INDEX(WEO!$F$4:$AZ$1000,MATCH("USA|pcpi",WEO!$A$4:$A$1000,0),MATCH(Settings!$C$8,WEO!$F$3:$AZ$3,0))/INDEX(WEO!$F$4:$AZ$1000,MATCH("USA|pcpi",WEO!$A$4:$A$1000,0),MATCH(AI$4,WEO!$F$3:$AZ$3,0)) -> 0.95811375 | AJ8: =INDEX(WEO!$F$4:$AZ$1000,MATCH("USA|pcpi",WEO!$A$4:$A$1000,0),MATCH(Settings!$C$8,WEO!$F$3:$AZ$3,0))/INDEX(WEO!$F$4:$AZ$1000,MATCH("USA|pcpi",WEO!$A$4:$A$1000,0),MATCH(AJ$4,WEO!$F$3:$AZ$3,0)) -> 0.93759961 | ... AP8: =INDEX(WEO!$F$4:$AZ$1000,MATCH("USA|pcpi",WEO!$A$4:$A$1000,0),MATCH(Settings!$C$8,WEO!$F$3:$AZ$3,0))/INDEX(WEO!$F$4:$AZ$1000,MATCH("USA|pcpi",WEO!$A$4:$A$1000,0),MATCH(AP$4,WEO!$F$3:$AZ$3,0)) -> 0.89789601
A9: defl | H9: =INDEX(Variables!$B$5:$B$65,MATCH($A9,Variables!$A$5:$A$65,0))&IF($C9="",""," | "&INDEX(Mapping!$B$5:$B$26,MATCH($C9,Mapping!$A$5:$A$26,0))&" | "&INDEX(Mapping!$B$30:$B$41,MATCH($B9,Mapping!$A$30:$A$41,0))) -> Deflator index: US GDP deflator, ResultsYear = 1 (nominal -> real for international prices) | I9: =INDEX(Variables!$C$5:$C$65,MATCH($A9,Variables!$A$5:$A$65,0)) -> index | J9: =INDEX(Variables!$E$5:$E$65,MATCH($A9,Variables!$A$5:$A$65,0)) -> WEO USA|ngdp_d: deflator(ResultsYear) / deflator(year) | L9: =LOWER(Settings!$C$4)&".mit."&$A9&IF($C9="","","."&$C9&"."&$B9)&IF(INDEX(Variables!$D$5:$D$65,MATCH($A9,Variables!$A$5:$A$65,0))="","","."&INDEX(Variables!$D$5:$D$65,MATCH($A9,Variables!$A$5:$A$65,0)))&"."&L$5 -> egy.mit.defl.1 | M9: =INDEX(WEO!$F$4:$AZ$1000,MATCH("USA|ngdp_d",WEO!$A$4:$A$1000,0),MATCH(Settings!$C$8,WEO!$F$3:$AZ$3,0))/INDEX(WEO!$F$4:$AZ$1000,MATCH("USA|ngdp_d",WEO!$A$4:$A$1000,0),MATCH(M$4,WEO!$F$3:$AZ$3,0)) -> 1.1242016 | N9: =INDEX(WEO!$F$4:$AZ$1000,MATCH("USA|ngdp_d",WEO!$A$4:$A$1000,0),MATCH(Settings!$C$8,WEO!$F$3:$AZ$3,0))/INDEX(WEO!$F$4:$AZ$1000,MATCH("USA|ngdp_d",WEO!$A$4:$A$1000,0),MATCH(N$4,WEO!$F$3:$AZ$3,0)) -> 1.0840899 | O9: =INDEX(WEO!$F$4:$AZ$1000,MATCH("USA|ngdp_d",WEO!$A$4:$A$1000,0),MATCH(Settings!$C$8,WEO!$F$3:$AZ$3,0))/INDEX(WEO!$F$4:$AZ$1000,MATCH("USA|ngdp_d",WEO!$A$4:$A$1000,0),MATCH(O$4,WEO!$F$3:$AZ$3,0)) -> 1.0578289 | P9: =INDEX(WEO!$F$4:$AZ$1000,MATCH("USA|ngdp_d",WEO!$A$4:$A$1000,0),MATCH(Settings!$C$8,WEO!$F$3:$AZ$3,0))/INDEX(WEO!$F$4:$AZ$1000,MATCH("USA|ngdp_d",WEO!$A$4:$A$1000,0),MATCH(P$4,WEO!$F$3:$AZ$3,0)) -> 1.0286485 | Q9: =INDEX(WEO!$F$4:$AZ$1000,MATCH("USA|ngdp_d",WEO!$A$4:$A$1000,0),MATCH(Settings!$C$8,WEO!$F$3:$AZ$3,0))/INDEX(WEO!$F$4:$AZ$1000,MATCH("USA|ngdp_d",WEO!$A$4:$A$1000,0),MATCH(Q$4,WEO!$F$3:$AZ$3,0)) -> 1 | R9: =INDEX(WEO!$F$4:$AZ$1000,MATCH("USA|ngdp_d",WEO!$A$4:$A$1000,0),MATCH(Settings!$C$8,WEO!$F$3:$AZ$3,0))/INDEX(WEO!$F$4:$AZ$1000,MATCH("USA|ngdp_d",WEO!$A$4:$A$1000,0),MATCH(R$4,WEO!$F$3:$AZ$3,0)) -> 0.97851281 | S9: =INDEX(WEO!$F$4:$AZ$1000,MATCH("USA|ngdp_d",WEO!$A$4:$A$1000,0),MATCH(Settings!$C$8,WEO!$F$3:$AZ$3,0))/INDEX(WEO!$F$4:$AZ$1000,MATCH("USA|ngdp_d",WEO!$A$4:$A$1000,0),MATCH(S$4,WEO!$F$3:$AZ$3,0)) -> 0.96271097 | T9: =INDEX(WEO!$F$4:$AZ$1000,MATCH("USA|ngdp_d",WEO!$A$4:$A$1000,0),MATCH(Settings!$C$8,WEO!$F$3:$AZ$3,0))/INDEX(WEO!$F$4:$AZ$1000,MATCH("USA|ngdp_d",WEO!$A$4:$A$1000,0),MATCH(T$4,WEO!$F$3:$AZ$3,0)) -> 0.94589198 | ... Z9: =INDEX(WEO!$F$4:$AZ$1000,MATCH("USA|ngdp_d",WEO!$A$4:$A$1000,0),MATCH(Settings!$C$8,WEO!$F$3:$AZ$3,0))/INDEX(WEO!$F$4:$AZ$1000,MATCH("USA|ngdp_d",WEO!$A$4:$A$1000,0),MATCH(Z$4,WEO!$F$3:$AZ$3,0)) -> 0.85192546 | AB9: =LOWER(Settings!$C$4)&".mit."&$A9&IF($C9="","","."&$C9&"."&$B9)&IF(INDEX(Variables!$D$5:$D$65,MATCH($A9,Variables!$A$5:$A$65,0))="","","."&INDEX(Variables!$D$5:$D$65,MATCH($A9,Variables!$A$5:$A$65,0)))&"."&AB$5 -> egy.mit.defl.2 | AC9: =INDEX(WEO!$F$4:$AZ$1000,MATCH("USA|ngdp_d",WEO!$A$4:$A$1000,0),MATCH(Settings!$C$8,WEO!$F$3:$AZ$3,0))/INDEX(WEO!$F$4:$AZ$1000,MATCH("USA|ngdp_d",WEO!$A$4:$A$1000,0),MATCH(AC$4,WEO!$F$3:$AZ$3,0)) -> 1.1242016 | AD9: =INDEX(WEO!$F$4:$AZ$1000,MATCH("USA|ngdp_d",WEO!$A$4:$A$1000,0),MATCH(Settings!$C$8,WEO!$F$3:$AZ$3,0))/INDEX(WEO!$F$4:$AZ$1000,MATCH("USA|ngdp_d",WEO!$A$4:$A$1000,0),MATCH(AD$4,WEO!$F$3:$AZ$3,0)) -> 1.0840899 | AE9: =INDEX(WEO!$F$4:$AZ$1000,MATCH("USA|ngdp_d",WEO!$A$4:$A$1000,0),MATCH(Settings!$C$8,WEO!$F$3:$AZ$3,0))/INDEX(WEO!$F$4:$AZ$1000,MATCH("USA|ngdp_d",WEO!$A$4:$A$1000,0),MATCH(AE$4,WEO!$F$3:$AZ$3,0)) -> 1.0578289 | AF9: =INDEX(WEO!$F$4:$AZ$1000,MATCH("USA|ngdp_d",WEO!$A$4:$A$1000,0),MATCH(Settings!$C$8,WEO!$F$3:$AZ$3,0))/INDEX(WEO!$F$4:$AZ$1000,MATCH("USA|ngdp_d",WEO!$A$4:$A$1000,0),MATCH(AF$4,WEO!$F$3:$AZ$3,0)) -> 1.0286485 | AG9: =INDEX(WEO!$F$4:$AZ$1000,MATCH("USA|ngdp_d",WEO!$A$4:$A$1000,0),MATCH(Settings!$C$8,WEO!$F$3:$AZ$3,0))/INDEX(WEO!$F$4:$AZ$1000,MATCH("USA|ngdp_d",WEO!$A$4:$A$1000,0),MATCH(AG$4,WEO!$F$3:$AZ$3,0)) -> 1 | AH9: =INDEX(WEO!$F$4:$AZ$1000,MATCH("USA|ngdp_d",WEO!$A$4:$A$1000,0),MATCH(Settings!$C$8,WEO!$F$3:$AZ$3,0))/INDEX(WEO!$F$4:$AZ$1000,MATCH("USA|ngdp_d",WEO!$A$4:$A$1000,0),MATCH(AH$4,WEO!$F$3:$AZ$3,0)) -> 0.97851281 | AI9: =INDEX(WEO!$F$4:$AZ$1000,MATCH("USA|ngdp_d",WEO!$A$4:$A$1000,0),MATCH(Settings!$C$8,WEO!$F$3:$AZ$3,0))/INDEX(WEO!$F$4:$AZ$1000,MATCH("USA|ngdp_d",WEO!$A$4:$A$1000,0),MATCH(AI$4,WEO!$F$3:$AZ$3,0)) -> 0.96271097 | AJ9: =INDEX(WEO!$F$4:$AZ$1000,MATCH("USA|ngdp_d",WEO!$A$4:$A$1000,0),MATCH(Settings!$C$8,WEO!$F$3:$AZ$3,0))/INDEX(WEO!$F$4:$AZ$1000,MATCH("USA|ngdp_d",WEO!$A$4:$A$1000,0),MATCH(AJ$4,WEO!$F$3:$AZ$3,0)) -> 0.94589198 | ... AP9: =INDEX(WEO!$F$4:$AZ$1000,MATCH("USA|ngdp_d",WEO!$A$4:$A$1000,0),MATCH(Settings!$C$8,WEO!$F$3:$AZ$3,0))/INDEX(WEO!$F$4:$AZ$1000,MATCH("USA|ngdp_d",WEO!$A$4:$A$1000,0),MATCH(AP$4,WEO!$F$3:$AZ$3,0)) -> 0.85192546
A11: 1. Policies (scenario inputs from MTInputs by row and scenario number; policy paths) | D11: MTInputs row
A12: cptraj | H12: =INDEX(Variables!$B$5:$B$65,MATCH($A12,Variables!$A$5:$A$65,0))&IF($C12="",""," | "&INDEX(Mapping!$B$5:$B$26,MATCH($C12,Mapping!$A$5:$A$26,0))&" | "&INDEX(Mapping!$B$30:$B$41,MATCH($B12,Mapping!$A$30:$A$41,0))) -> Carbon price trajectory used | I12: =INDEX(Variables!$C$5:$C$65,MATCH($A12,Variables!$A$5:$A$65,0)) -> $/tCO2 real | J12: =INDEX(Variables!$E$5:$E$65,MATCH($A12,Variables!$A$5:$A$65,0)) -> Calculation (legacy rows 2248, 2251); x infl if NomorReal = Nominal | L12: =LOWER(Settings!$C$4)&".mit."&$A12&IF($C12="","","."&$C12&"."&$B12)&IF(INDEX(Variables!$D$5:$D$65,MATCH($A12,Variables!$A$5:$A$65,0))="","","."&INDEX(Variables!$D$5:$D$65,MATCH($A12,Variables!$A$5:$A$65,0)))&"."&L$5 -> egy.mit.cptraj.1 | M12: =(IF(M$4<M$14,0,M$15+(M$16-M$15)/MAX(M$17-M$14,1)*IF(OR(M$4<=M$17,M$18="Linear*"),M$4-M$14,M$17-M$14)))*IF(LEFT(M$19,7)="Nominal",M$8,1) -> 0 | N12: =(IF(N$4<N$14,0,N$15+(N$16-N$15)/MAX(N$17-N$14,1)*IF(OR(N$4<=N$17,N$18="Linear*"),N$4-N$14,N$17-N$14)))*IF(LEFT(N$19,7)="Nominal",N$8,1) -> 0 | O12: =(IF(O$4<O$14,0,O$15+(O$16-O$15)/MAX(O$17-O$14,1)*IF(OR(O$4<=O$17,O$18="Linear*"),O$4-O$14,O$17-O$14)))*IF(LEFT(O$19,7)="Nominal",O$8,1) -> 0 | P12: =(IF(P$4<P$14,0,P$15+(P$16-P$15)/MAX(P$17-P$14,1)*IF(OR(P$4<=P$17,P$18="Linear*"),P$4-P$14,P$17-P$14)))*IF(LEFT(P$19,7)="Nominal",P$8,1) -> 0 | Q12: =(IF(Q$4<Q$14,0,Q$15+(Q$16-Q$15)/MAX(Q$17-Q$14,1)*IF(OR(Q$4<=Q$17,Q$18="Linear*"),Q$4-Q$14,Q$17-Q$14)))*IF(LEFT(Q$19,7)="Nominal",Q$8,1) -> 0 | R12: =(IF(R$4<R$14,0,R$15+(R$16-R$15)/MAX(R$17-R$14,1)*IF(OR(R$4<=R$17,R$18="Linear*"),R$4-R$14,R$17-R$14)))*IF(LEFT(R$19,7)="Nominal",R$8,1) -> 0 | S12: =(IF(S$4<S$14,0,S$15+(S$16-S$15)/MAX(S$17-S$14,1)*IF(OR(S$4<=S$17,S$18="Linear*"),S$4-S$14,S$17-S$14)))*IF(LEFT(S$19,7)="Nominal",S$8,1) -> 0 | T12: =(IF(T$4<T$14,0,T$15+(T$16-T$15)/MAX(T$17-T$14,1)*IF(OR(T$4<=T$17,T$18="Linear*"),T$4-T$14,T$17-T$14)))*IF(LEFT(T$19,7)="Nominal",T$8,1) -> 0 | ... Z12: =(IF(Z$4<Z$14,0,Z$15+(Z$16-Z$15)/MAX(Z$17-Z$14,1)*IF(OR(Z$4<=Z$17,Z$18="Linear*"),Z$4-Z$14,Z$17-Z$14)))*IF(LEFT(Z$19,7)="Nominal",Z$8,1) -> 0 | AB12: =LOWER(Settings!$C$4)&".mit."&$A12&IF($C12="","","."&$C12&"."&$B12)&IF(INDEX(Variables!$D$5:$D$65,MATCH($A12,Variables!$A$5:$A$65,0))="","","."&INDEX(Variables!$D$5:$D$65,MATCH($A12,Variables!$A$5:$A$65,0)))&"."&AB$5 -> egy.mit.cptraj.2 | AC12: =(IF(AC$4<AC$14,0,AC$15+(AC$16-AC$15)/MAX(AC$17-AC$14,1)*IF(OR(AC$4<=AC$17,AC$18="Linear*"),AC$4-AC$14,AC$17-AC$14)))*IF(LEFT(AC$19,7)="Nominal",AC$8,1) -> 0 | AD12: =(IF(AD$4<AD$14,0,AD$15+(AD$16-AD$15)/MAX(AD$17-AD$14,1)*IF(OR(AD$4<=AD$17,AD$18="Linear*"),AD$4-AD$14,AD$17-AD$14)))*IF(LEFT(AD$19,7)="Nominal",AD$8,1) -> 0 | AE12: =(IF(AE$4<AE$14,0,AE$15+(AE$16-AE$15)/MAX(AE$17-AE$14,1)*IF(OR(AE$4<=AE$17,AE$18="Linear*"),AE$4-AE$14,AE$17-AE$14)))*IF(LEFT(AE$19,7)="Nominal",AE$8,1) -> 0 | AF12: =(IF(AF$4<AF$14,0,AF$15+(AF$16-AF$15)/MAX(AF$17-AF$14,1)*IF(OR(AF$4<=AF$17,AF$18="Linear*"),AF$4-AF$14,AF$17-AF$14)))*IF(LEFT(AF$19,7)="Nominal",AF$8,1) -> 0 | AG12: =(IF(AG$4<AG$14,0,AG$15+(AG$16-AG$15)/MAX(AG$17-AG$14,1)*IF(OR(AG$4<=AG$17,AG$18="Linear*"),AG$4-AG$14,AG$17-AG$14)))*IF(LEFT(AG$19,7)="Nominal",AG$8,1) -> 0 | AH12: =(IF(AH$4<AH$14,0,AH$15+(AH$16-AH$15)/MAX(AH$17-AH$14,1)*IF(OR(AH$4<=AH$17,AH$18="Linear*"),AH$4-AH$14,AH$17-AH$14)))*IF(LEFT(AH$19,7)="Nominal",AH$8,1) -> 20 | AI12: =(IF(AI$4<AI$14,0,AI$15+(AI$16-AI$15)/MAX(AI$17-AI$14,1)*IF(OR(AI$4<=AI$17,AI$18="Linear*"),AI$4-AI$14,AI$17-AI$14)))*IF(LEFT(AI$19,7)="Nominal",AI$8,1) -> 20 | AJ12: =(IF(AJ$4<AJ$14,0,AJ$15+(AJ$16-AJ$15)/MAX(AJ$17-AJ$14,1)*IF(OR(AJ$4<=AJ$17,AJ$18="Linear*"),AJ$4-AJ$14,AJ$17-AJ$14)))*IF(LEFT(AJ$19,7)="Nominal",AJ$8,1) -> 20 | ... AP12: =(IF(AP$4<AP$14,0,AP$15+(AP$16-AP$15)/MAX(AP$17-AP$14,1)*IF(OR(AP$4<=AP$17,AP$18="Linear*"),AP$4-AP$14,AP$17-AP$14)))*IF(LEFT(AP$19,7)="Nominal",AP$8,1) -> 20
H13: Carbon tax (MTInputs rows 18-21, 265, 266)
A14: CPIntro | D14: 18 | H14: =INDEX(Variables!$B$5:$B$65,MATCH($A14,Variables!$A$5:$A$65,0))&IF($C14="",""," | "&INDEX(Mapping!$B$5:$B$26,MATCH($C14,Mapping!$A$5:$A$26,0))&" | "&INDEX(Mapping!$B$30:$B$41,MATCH($B14,Mapping!$A$30:$A$41,0))) -> Carbon pricing start year | I14: =INDEX(Variables!$C$5:$C$65,MATCH($A14,Variables!$A$5:$A$65,0)) -> year | J14: =INDEX(Variables!$E$5:$E$65,MATCH($A14,Variables!$A$5:$A$65,0)) -> MTInputs (scenario column) | L14: =LOWER(Settings!$C$4)&".mit."&$A14&IF($C14="","","."&$C14&"."&$B14)&IF(INDEX(Variables!$D$5:$D$65,MATCH($A14,Variables!$A$5:$A$65,0))="","","."&INDEX(Variables!$D$5:$D$65,MATCH($A14,Variables!$A$5:$A$65,0)))&"."&L$5 -> egy.mit.CPIntro.1 | M14: =INDEX(MTInputs!$J$1:$AZ$415,$D14,MATCH(M$5,MTInputs!$J$5:$AZ$5,0)) -> 2027 | N14: =INDEX(MTInputs!$J$1:$AZ$415,$D14,MATCH(N$5,MTInputs!$J$5:$AZ$5,0)) -> 2027 | O14: =INDEX(MTInputs!$J$1:$AZ$415,$D14,MATCH(O$5,MTInputs!$J$5:$AZ$5,0)) -> 2027 | P14: =INDEX(MTInputs!$J$1:$AZ$415,$D14,MATCH(P$5,MTInputs!$J$5:$AZ$5,0)) -> 2027 | Q14: =INDEX(MTInputs!$J$1:$AZ$415,$D14,MATCH(Q$5,MTInputs!$J$5:$AZ$5,0)) -> 2027 | R14: =INDEX(MTInputs!$J$1:$AZ$415,$D14,MATCH(R$5,MTInputs!$J$5:$AZ$5,0)) -> 2027 | S14: =INDEX(MTInputs!$J$1:$AZ$415,$D14,MATCH(S$5,MTInputs!$J$5:$AZ$5,0)) -> 2027 | T14: =INDEX(MTInputs!$J$1:$AZ$415,$D14,MATCH(T$5,MTInputs!$J$5:$AZ$5,0)) -> 2027 | ... Z14: =INDEX(MTInputs!$J$1:$AZ$415,$D14,MATCH(Z$5,MTInputs!$J$5:$AZ$5,0)) -> 2027 | AB14: =LOWER(Settings!$C$4)&".mit."&$A14&IF($C14="","","."&$C14&"."&$B14)&IF(INDEX(Variables!$D$5:$D$65,MATCH($A14,Variables!$A$5:$A$65,0))="","","."&INDEX(Variables!$D$5:$D$65,MATCH($A14,Variables!$A$5:$A$65,0)))&"."&AB$5 -> egy.mit.CPIntro.2 | AC14: =INDEX(MTInputs!$J$1:$AZ$415,$D14,MATCH(AC$5,MTInputs!$J$5:$AZ$5,0)) -> 2027 | AD14: =INDEX(MTInputs!$J$1:$AZ$415,$D14,MATCH(AD$5,MTInputs!$J$5:$AZ$5,0)) -> 2027 | AE14: =INDEX(MTInputs!$J$1:$AZ$415,$D14,MATCH(AE$5,MTInputs!$J$5:$AZ$5,0)) -> 2027 | AF14: =INDEX(MTInputs!$J$1:$AZ$415,$D14,MATCH(AF$5,MTInputs!$J$5:$AZ$5,0)) -> 2027 | AG14: =INDEX(MTInputs!$J$1:$AZ$415,$D14,MATCH(AG$5,MTInputs!$J$5:$AZ$5,0)) -> 2027 | AH14: =INDEX(MTInputs!$J$1:$AZ$415,$D14,MATCH(AH$5,MTInputs!$J$5:$AZ$5,0)) -> 2027 | AI14: =INDEX(MTInputs!$J$1:$AZ$415,$D14,MATCH(AI$5,MTInputs!$J$5:$AZ$5,0)) -> 2027 | AJ14: =INDEX(MTInputs!$J$1:$AZ$415,$D14,MATCH(AJ$5,MTInputs!$J$5:$AZ$5,0)) -> 2027 | ... AP14: =INDEX(MTInputs!$J$1:$AZ$415,$D14,MATCH(AP$5,MTInputs!$J$5:$AZ$5,0)) -> 2027
A15: CPLevelStart | D15: 19 | H15: =INDEX(Variables!$B$5:$B$65,MATCH($A15,Variables!$A$5:$A$65,0))&IF($C15="",""," | "&INDEX(Mapping!$B$5:$B$26,MATCH($C15,Mapping!$A$5:$A$26,0))&" | "&INDEX(Mapping!$B$30:$B$41,MATCH($B15,Mapping!$A$30:$A$41,0))) -> Starting carbon price | I15: =INDEX(Variables!$C$5:$C$65,MATCH($A15,Variables!$A$5:$A$65,0)) -> nom. USD/tCO2 | J15: =INDEX(Variables!$E$5:$E$65,MATCH($A15,Variables!$A$5:$A$65,0)) -> MTInputs (scenario column) | L15: =LOWER(Settings!$C$4)&".mit."&$A15&IF($C15="","","."&$C15&"."&$B15)&IF(INDEX(Variables!$D$5:$D$65,MATCH($A15,Variables!$A$5:$A$65,0))="","","."&INDEX(Variables!$D$5:$D$65,MATCH($A15,Variables!$A$5:$A$65,0)))&"."&L$5 -> egy.mit.CPLevelStart.1 | M15: =INDEX(MTInputs!$J$1:$AZ$415,$D15,MATCH(M$5,MTInputs!$J$5:$AZ$5,0)) -> 0 | N15: =INDEX(MTInputs!$J$1:$AZ$415,$D15,MATCH(N$5,MTInputs!$J$5:$AZ$5,0)) -> 0 | O15: =INDEX(MTInputs!$J$1:$AZ$415,$D15,MATCH(O$5,MTInputs!$J$5:$AZ$5,0)) -> 0 | P15: =INDEX(MTInputs!$J$1:$AZ$415,$D15,MATCH(P$5,MTInputs!$J$5:$AZ$5,0)) -> 0 | Q15: =INDEX(MTInputs!$J$1:$AZ$415,$D15,MATCH(Q$5,MTInputs!$J$5:$AZ$5,0)) -> 0 | R15: =INDEX(MTInputs!$J$1:$AZ$415,$D15,MATCH(R$5,MTInputs!$J$5:$AZ$5,0)) -> 0 | S15: =INDEX(MTInputs!$J$1:$AZ$415,$D15,MATCH(S$5,MTInputs!$J$5:$AZ$5,0)) -> 0 | T15: =INDEX(MTInputs!$J$1:$AZ$415,$D15,MATCH(T$5,MTInputs!$J$5:$AZ$5,0)) -> 0 | ... Z15: =INDEX(MTInputs!$J$1:$AZ$415,$D15,MATCH(Z$5,MTInputs!$J$5:$AZ$5,0)) -> 0 | AB15: =LOWER(Settings!$C$4)&".mit."&$A15&IF($C15="","","."&$C15&"."&$B15)&IF(INDEX(Variables!$D$5:$D$65,MATCH($A15,Variables!$A$5:$A$65,0))="","","."&INDEX(Variables!$D$5:$D$65,MATCH($A15,Variables!$A$5:$A$65,0)))&"."&AB$5 -> egy.mit.CPLevelStart.2 | AC15: =INDEX(MTInputs!$J$1:$AZ$415,$D15,MATCH(AC$5,MTInputs!$J$5:$AZ$5,0)) -> 20 | AD15: =INDEX(MTInputs!$J$1:$AZ$415,$D15,MATCH(AD$5,MTInputs!$J$5:$AZ$5,0)) -> 20 | AE15: =INDEX(MTInputs!$J$1:$AZ$415,$D15,MATCH(AE$5,MTInputs!$J$5:$AZ$5,0)) -> 20 | AF15: =INDEX(MTInputs!$J$1:$AZ$415,$D15,MATCH(AF$5,MTInputs!$J$5:$AZ$5,0)) -> 20 | AG15: =INDEX(MTInputs!$J$1:$AZ$415,$D15,MATCH(AG$5,MTInputs!$J$5:$AZ$5,0)) -> 20 | AH15: =INDEX(MTInputs!$J$1:$AZ$415,$D15,MATCH(AH$5,MTInputs!$J$5:$AZ$5,0)) -> 20 | AI15: =INDEX(MTInputs!$J$1:$AZ$415,$D15,MATCH(AI$5,MTInputs!$J$5:$AZ$5,0)) -> 20 | AJ15: =INDEX(MTInputs!$J$1:$AZ$415,$D15,MATCH(AJ$5,MTInputs!$J$5:$AZ$5,0)) -> 20 | ... AP15: =INDEX(MTInputs!$J$1:$AZ$415,$D15,MATCH(AP$5,MTInputs!$J$5:$AZ$5,0)) -> 20
A16: CPLevelTarget | D16: 20 | H16: =INDEX(Variables!$B$5:$B$65,MATCH($A16,Variables!$A$5:$A$65,0))&IF($C16="",""," | "&INDEX(Mapping!$B$5:$B$26,MATCH($C16,Mapping!$A$5:$A$26,0))&" | "&INDEX(Mapping!$B$30:$B$41,MATCH($B16,Mapping!$A$30:$A$41,0))) -> Target level of carbon price | I16: =INDEX(Variables!$C$5:$C$65,MATCH($A16,Variables!$A$5:$A$65,0)) -> nom. USD/tCO2 | J16: =INDEX(Variables!$E$5:$E$65,MATCH($A16,Variables!$A$5:$A$65,0)) -> MTInputs (scenario column) | L16: =LOWER(Settings!$C$4)&".mit."&$A16&IF($C16="","","."&$C16&"."&$B16)&IF(INDEX(Variables!$D$5:$D$65,MATCH($A16,Variables!$A$5:$A$65,0))="","","."&INDEX(Variables!$D$5:$D$65,MATCH($A16,Variables!$A$5:$A$65,0)))&"."&L$5 -> egy.mit.CPLevelTarget.1 | M16: =INDEX(MTInputs!$J$1:$AZ$415,$D16,MATCH(M$5,MTInputs!$J$5:$AZ$5,0)) -> 0 | N16: =INDEX(MTInputs!$J$1:$AZ$415,$D16,MATCH(N$5,MTInputs!$J$5:$AZ$5,0)) -> 0 | O16: =INDEX(MTInputs!$J$1:$AZ$415,$D16,MATCH(O$5,MTInputs!$J$5:$AZ$5,0)) -> 0 | P16: =INDEX(MTInputs!$J$1:$AZ$415,$D16,MATCH(P$5,MTInputs!$J$5:$AZ$5,0)) -> 0 | Q16: =INDEX(MTInputs!$J$1:$AZ$415,$D16,MATCH(Q$5,MTInputs!$J$5:$AZ$5,0)) -> 0 | R16: =INDEX(MTInputs!$J$1:$AZ$415,$D16,MATCH(R$5,MTInputs!$J$5:$AZ$5,0)) -> 0 | S16: =INDEX(MTInputs!$J$1:$AZ$415,$D16,MATCH(S$5,MTInputs!$J$5:$AZ$5,0)) -> 0 | T16: =INDEX(MTInputs!$J$1:$AZ$415,$D16,MATCH(T$5,MTInputs!$J$5:$AZ$5,0)) -> 0 | ... Z16: =INDEX(MTInputs!$J$1:$AZ$415,$D16,MATCH(Z$5,MTInputs!$J$5:$AZ$5,0)) -> 0 | AB16: =LOWER(Settings!$C$4)&".mit."&$A16&IF($C16="","","."&$C16&"."&$B16)&IF(INDEX(Variables!$D$5:$D$65,MATCH($A16,Variables!$A$5:$A$65,0))="","","."&INDEX(Variables!$D$5:$D$65,MATCH($A16,Variables!$A$5:$A$65,0)))&"."&AB$5 -> egy.mit.CPLevelTarget.2 | AC16: =INDEX(MTInputs!$J$1:$AZ$415,$D16,MATCH(AC$5,MTInputs!$J$5:$AZ$5,0)) -> 20 | AD16: =INDEX(MTInputs!$J$1:$AZ$415,$D16,MATCH(AD$5,MTInputs!$J$5:$AZ$5,0)) -> 20 | AE16: =INDEX(MTInputs!$J$1:$AZ$415,$D16,MATCH(AE$5,MTInputs!$J$5:$AZ$5,0)) -> 20 | AF16: =INDEX(MTInputs!$J$1:$AZ$415,$D16,MATCH(AF$5,MTInputs!$J$5:$AZ$5,0)) -> 20 | AG16: =INDEX(MTInputs!$J$1:$AZ$415,$D16,MATCH(AG$5,MTInputs!$J$5:$AZ$5,0)) -> 20 | AH16: =INDEX(MTInputs!$J$1:$AZ$415,$D16,MATCH(AH$5,MTInputs!$J$5:$AZ$5,0)) -> 20 | AI16: =INDEX(MTInputs!$J$1:$AZ$415,$D16,MATCH(AI$5,MTInputs!$J$5:$AZ$5,0)) -> 20 | AJ16: =INDEX(MTInputs!$J$1:$AZ$415,$D16,MATCH(AJ$5,MTInputs!$J$5:$AZ$5,0)) -> 20 | ... AP16: =INDEX(MTInputs!$J$1:$AZ$415,$D16,MATCH(AP$5,MTInputs!$J$5:$AZ$5,0)) -> 20
A17: CPOutro | D17: 21 | H17: =INDEX(Variables!$B$5:$B$65,MATCH($A17,Variables!$A$5:$A$65,0))&IF($C17="",""," | "&INDEX(Mapping!$B$5:$B$26,MATCH($C17,Mapping!$A$5:$A$26,0))&" | "&INDEX(Mapping!$B$30:$B$41,MATCH($B17,Mapping!$A$30:$A$41,0))) -> Year to reach target level | I17: =INDEX(Variables!$C$5:$C$65,MATCH($A17,Variables!$A$5:$A$65,0)) -> year | J17: =INDEX(Variables!$E$5:$E$65,MATCH($A17,Variables!$A$5:$A$65,0)) -> MTInputs (scenario column) | L17: =LOWER(Settings!$C$4)&".mit."&$A17&IF($C17="","","."&$C17&"."&$B17)&IF(INDEX(Variables!$D$5:$D$65,MATCH($A17,Variables!$A$5:$A$65,0))="","","."&INDEX(Variables!$D$5:$D$65,MATCH($A17,Variables!$A$5:$A$65,0)))&"."&L$5 -> egy.mit.CPOutro.1 | M17: =INDEX(MTInputs!$J$1:$AZ$415,$D17,MATCH(M$5,MTInputs!$J$5:$AZ$5,0)) -> 2030 | N17: =INDEX(MTInputs!$J$1:$AZ$415,$D17,MATCH(N$5,MTInputs!$J$5:$AZ$5,0)) -> 2030 | O17: =INDEX(MTInputs!$J$1:$AZ$415,$D17,MATCH(O$5,MTInputs!$J$5:$AZ$5,0)) -> 2030 | P17: =INDEX(MTInputs!$J$1:$AZ$415,$D17,MATCH(P$5,MTInputs!$J$5:$AZ$5,0)) -> 2030 | Q17: =INDEX(MTInputs!$J$1:$AZ$415,$D17,MATCH(Q$5,MTInputs!$J$5:$AZ$5,0)) -> 2030 | R17: =INDEX(MTInputs!$J$1:$AZ$415,$D17,MATCH(R$5,MTInputs!$J$5:$AZ$5,0)) -> 2030 | S17: =INDEX(MTInputs!$J$1:$AZ$415,$D17,MATCH(S$5,MTInputs!$J$5:$AZ$5,0)) -> 2030 | T17: =INDEX(MTInputs!$J$1:$AZ$415,$D17,MATCH(T$5,MTInputs!$J$5:$AZ$5,0)) -> 2030 | ... Z17: =INDEX(MTInputs!$J$1:$AZ$415,$D17,MATCH(Z$5,MTInputs!$J$5:$AZ$5,0)) -> 2030 | AB17: =LOWER(Settings!$C$4)&".mit."&$A17&IF($C17="","","."&$C17&"."&$B17)&IF(INDEX(Variables!$D$5:$D$65,MATCH($A17,Variables!$A$5:$A$65,0))="","","."&INDEX(Variables!$D$5:$D$65,MATCH($A17,Variables!$A$5:$A$65,0)))&"."&AB$5 -> egy.mit.CPOutro.2 | AC17: =INDEX(MTInputs!$J$1:$AZ$415,$D17,MATCH(AC$5,MTInputs!$J$5:$AZ$5,0)) -> 2030 | AD17: =INDEX(MTInputs!$J$1:$AZ$415,$D17,MATCH(AD$5,MTInputs!$J$5:$AZ$5,0)) -> 2030 | AE17: =INDEX(MTInputs!$J$1:$AZ$415,$D17,MATCH(AE$5,MTInputs!$J$5:$AZ$5,0)) -> 2030 | AF17: =INDEX(MTInputs!$J$1:$AZ$415,$D17,MATCH(AF$5,MTInputs!$J$5:$AZ$5,0)) -> 2030 | AG17: =INDEX(MTInputs!$J$1:$AZ$415,$D17,MATCH(AG$5,MTInputs!$J$5:$AZ$5,0)) -> 2030 | AH17: =INDEX(MTInputs!$J$1:$AZ$415,$D17,MATCH(AH$5,MTInputs!$J$5:$AZ$5,0)) -> 2030 | AI17: =INDEX(MTInputs!$J$1:$AZ$415,$D17,MATCH(AI$5,MTInputs!$J$5:$AZ$5,0)) -> 2030 | AJ17: =INDEX(MTInputs!$J$1:$AZ$415,$D17,MATCH(AJ$5,MTInputs!$J$5:$AZ$5,0)) -> 2030 | ... AP17: =INDEX(MTInputs!$J$1:$AZ$415,$D17,MATCH(AP$5,MTInputs!$J$5:$AZ$5,0)) -> 2030
A18: ExtendCarbonPriceBeyondOutro | D18: 265 | H18: =INDEX(Variables!$B$5:$B$65,MATCH($A18,Variables!$A$5:$A$65,0))&IF($C18="",""," | "&INDEX(Mapping!$B$5:$B$26,MATCH($C18,Mapping!$A$5:$A$26,0))&" | "&INDEX(Mapping!$B$30:$B$41,MATCH($B18,Mapping!$A$30:$A$41,0))) -> Price pathway continues to rise after target year? | I18: =INDEX(Variables!$C$5:$C$65,MATCH($A18,Variables!$A$5:$A$65,0)) -> switch | J18: =INDEX(Variables!$E$5:$E$65,MATCH($A18,Variables!$A$5:$A$65,0)) -> MTInputs (scenario column) | L18: =LOWER(Settings!$C$4)&".mit."&$A18&IF($C18="","","."&$C18&"."&$B18)&IF(INDEX(Variables!$D$5:$D$65,MATCH($A18,Variables!$A$5:$A$65,0))="","","."&INDEX(Variables!$D$5:$D$65,MATCH($A18,Variables!$A$5:$A$65,0)))&"."&L$5 -> egy.mit.ExtendCarbonPriceBeyondOutro.1 | M18: =INDEX(MTInputs!$J$1:$AZ$415,$D18,MATCH(M$5,MTInputs!$J$5:$AZ$5,0)) -> Linear* | N18: =INDEX(MTInputs!$J$1:$AZ$415,$D18,MATCH(N$5,MTInputs!$J$5:$AZ$5,0)) -> Linear* | O18: =INDEX(MTInputs!$J$1:$AZ$415,$D18,MATCH(O$5,MTInputs!$J$5:$AZ$5,0)) -> Linear* | P18: =INDEX(MTInputs!$J$1:$AZ$415,$D18,MATCH(P$5,MTInputs!$J$5:$AZ$5,0)) -> Linear* | Q18: =INDEX(MTInputs!$J$1:$AZ$415,$D18,MATCH(Q$5,MTInputs!$J$5:$AZ$5,0)) -> Linear* | R18: =INDEX(MTInputs!$J$1:$AZ$415,$D18,MATCH(R$5,MTInputs!$J$5:$AZ$5,0)) -> Linear* | S18: =INDEX(MTInputs!$J$1:$AZ$415,$D18,MATCH(S$5,MTInputs!$J$5:$AZ$5,0)) -> Linear* | T18: =INDEX(MTInputs!$J$1:$AZ$415,$D18,MATCH(T$5,MTInputs!$J$5:$AZ$5,0)) -> Linear* | ... Z18: =INDEX(MTInputs!$J$1:$AZ$415,$D18,MATCH(Z$5,MTInputs!$J$5:$AZ$5,0)) -> Linear* | AB18: =LOWER(Settings!$C$4)&".mit."&$A18&IF($C18="","","."&$C18&"."&$B18)&IF(INDEX(Variables!$D$5:$D$65,MATCH($A18,Variables!$A$5:$A$65,0))="","","."&INDEX(Variables!$D$5:$D$65,MATCH($A18,Variables!$A$5:$A$65,0)))&"."&AB$5 -> egy.mit.ExtendCarbonPriceBeyondOutro.2 | AC18: =INDEX(MTInputs!$J$1:$AZ$415,$D18,MATCH(AC$5,MTInputs!$J$5:$AZ$5,0)) -> Linear* | AD18: =INDEX(MTInputs!$J$1:$AZ$415,$D18,MATCH(AD$5,MTInputs!$J$5:$AZ$5,0)) -> Linear* | AE18: =INDEX(MTInputs!$J$1:$AZ$415,$D18,MATCH(AE$5,MTInputs!$J$5:$AZ$5,0)) -> Linear* | AF18: =INDEX(MTInputs!$J$1:$AZ$415,$D18,MATCH(AF$5,MTInputs!$J$5:$AZ$5,0)) -> Linear* | AG18: =INDEX(MTInputs!$J$1:$AZ$415,$D18,MATCH(AG$5,MTInputs!$J$5:$AZ$5,0)) -> Linear* | AH18: =INDEX(MTInputs!$J$1:$AZ$415,$D18,MATCH(AH$5,MTInputs!$J$5:$AZ$5,0)) -> Linear* | AI18: =INDEX(MTInputs!$J$1:$AZ$415,$D18,MATCH(AI$5,MTInputs!$J$5:$AZ$5,0)) -> Linear* | AJ18: =INDEX(MTInputs!$J$1:$AZ$415,$D18,MATCH(AJ$5,MTInputs!$J$5:$AZ$5,0)) -> Linear* | ... AP18: =INDEX(MTInputs!$J$1:$AZ$415,$D18,MATCH(AP$5,MTInputs!$J$5:$AZ$5,0)) -> Linear*
A19: NomorReal | D19: 266 | H19: =INDEX(Variables!$B$5:$B$65,MATCH($A19,Variables!$A$5:$A$65,0))&IF($C19="",""," | "&INDEX(Mapping!$B$5:$B$26,MATCH($C19,Mapping!$A$5:$A$26,0))&" | "&INDEX(Mapping!$B$30:$B$41,MATCH($B19,Mapping!$A$30:$A$41,0))) -> Tax pathway is in nominal or real terms? | I19: =INDEX(Variables!$C$5:$C$65,MATCH($A19,Variables!$A$5:$A$65,0)) -> switch | J19: =INDEX(Variables!$E$5:$E$65,MATCH($A19,Variables!$A$5:$A$65,0)) -> MTInputs (scenario column) | L19: =LOWER(Settings!$C$4)&".mit."&$A19&IF($C19="","","."&$C19&"."&$B19)&IF(INDEX(Variables!$D$5:$D$65,MATCH($A19,Variables!$A$5:$A$65,0))="","","."&INDEX(Variables!$D$5:$D$65,MATCH($A19,Variables!$A$5:$A$65,0)))&"."&L$5 -> egy.mit.NomorReal.1 | M19: =INDEX(MTInputs!$J$1:$AZ$415,$D19,MATCH(M$5,MTInputs!$J$5:$AZ$5,0)) -> Real* | N19: =INDEX(MTInputs!$J$1:$AZ$415,$D19,MATCH(N$5,MTInputs!$J$5:$AZ$5,0)) -> Real* | O19: =INDEX(MTInputs!$J$1:$AZ$415,$D19,MATCH(O$5,MTInputs!$J$5:$AZ$5,0)) -> Real* | P19: =INDEX(MTInputs!$J$1:$AZ$415,$D19,MATCH(P$5,MTInputs!$J$5:$AZ$5,0)) -> Real* | Q19: =INDEX(MTInputs!$J$1:$AZ$415,$D19,MATCH(Q$5,MTInputs!$J$5:$AZ$5,0)) -> Real* | R19: =INDEX(MTInputs!$J$1:$AZ$415,$D19,MATCH(R$5,MTInputs!$J$5:$AZ$5,0)) -> Real* | S19: =INDEX(MTInputs!$J$1:$AZ$415,$D19,MATCH(S$5,MTInputs!$J$5:$AZ$5,0)) -> Real* | T19: =INDEX(MTInputs!$J$1:$AZ$415,$D19,MATCH(T$5,MTInputs!$J$5:$AZ$5,0)) -> Real* | ... Z19: =INDEX(MTInputs!$J$1:$AZ$415,$D19,MATCH(Z$5,MTInputs!$J$5:$AZ$5,0)) -> Real* | AB19: =LOWER(Settings!$C$4)&".mit."&$A19&IF($C19="","","."&$C19&"."&$B19)&IF(INDEX(Variables!$D$5:$D$65,MATCH($A19,Variables!$A$5:$A$65,0))="","","."&INDEX(Variables!$D$5:$D$65,MATCH($A19,Variables!$A$5:$A$65,0)))&"."&AB$5 -> egy.mit.NomorReal.2 | AC19: =INDEX(MTInputs!$J$1:$AZ$415,$D19,MATCH(AC$5,MTInputs!$J$5:$AZ$5,0)) -> Real* | AD19: =INDEX(MTInputs!$J$1:$AZ$415,$D19,MATCH(AD$5,MTInputs!$J$5:$AZ$5,0)) -> Real* | AE19: =INDEX(MTInputs!$J$1:$AZ$415,$D19,MATCH(AE$5,MTInputs!$J$5:$AZ$5,0)) -> Real* | AF19: =INDEX(MTInputs!$J$1:$AZ$415,$D19,MATCH(AF$5,MTInputs!$J$5:$AZ$5,0)) -> Real* | AG19: =INDEX(MTInputs!$J$1:$AZ$415,$D19,MATCH(AG$5,MTInputs!$J$5:$AZ$5,0)) -> Real* | AH19: =INDEX(MTInputs!$J$1:$AZ$415,$D19,MATCH(AH$5,MTInputs!$J$5:$AZ$5,0)) -> Real* | AI19: =INDEX(MTInputs!$J$1:$AZ$415,$D19,MATCH(AI$5,MTInputs!$J$5:$AZ$5,0)) -> Real* | AJ19: =INDEX(MTInputs!$J$1:$AZ$415,$D19,MATCH(AJ$5,MTInputs!$J$5:$AZ$5,0)) -> Real* | ... AP19: =INDEX(MTInputs!$J$1:$AZ$415,$D19,MATCH(AP$5,MTInputs!$J$5:$AZ$5,0)) -> Real*
H20: Carbon tax coverage: fuels (MTInputs rows 23-29)
A21: ctcov | B21: coa | C21: all | D21: 23 | H21: =INDEX(Variables!$B$5:$B$65,MATCH($A21,Variables!$A$5:$A$65,0))&IF($C21="",""," | "&INDEX(Mapping!$B$5:$B$26,MATCH($C21,Mapping!$A$5:$A$26,0))&" | "&INDEX(Mapping!$B$30:$B$41,MATCH($B21,Mapping!$A$30:$A$41,0))) -> Carbon tax coverage (Apply tax?) | All subsectors | Coal | I21: =INDEX(Variables!$C$5:$C$65,MATCH($A21,Variables!$A$5:$A$65,0)) -> switch | J21: =INDEX(Variables!$E$5:$E$65,MATCH($A21,Variables!$A$5:$A$65,0)) -> MTInputs (scenario column) | L21: =LOWER(Settings!$C$4)&".mit."&$A21&IF($C21="","","."&$C21&"."&$B21)&IF(INDEX(Variables!$D$5:$D$65,MATCH($A21,Variables!$A$5:$A$65,0))="","","."&INDEX(Variables!$D$5:$D$65,MATCH($A21,Variables!$A$5:$A$65,0)))&"."&L$5 -> egy.mit.ctcov.all.coa.1 | M21: =INDEX(MTInputs!$J$1:$AZ$415,$D21,MATCH(M$5,MTInputs!$J$5:$AZ$5,0)) -> TRUE | N21: =INDEX(MTInputs!$J$1:$AZ$415,$D21,MATCH(N$5,MTInputs!$J$5:$AZ$5,0)) -> TRUE | O21: =INDEX(MTInputs!$J$1:$AZ$415,$D21,MATCH(O$5,MTInputs!$J$5:$AZ$5,0)) -> TRUE | P21: =INDEX(MTInputs!$J$1:$AZ$415,$D21,MATCH(P$5,MTInputs!$J$5:$AZ$5,0)) -> TRUE | Q21: =INDEX(MTInputs!$J$1:$AZ$415,$D21,MATCH(Q$5,MTInputs!$J$5:$AZ$5,0)) -> TRUE | R21: =INDEX(MTInputs!$J$1:$AZ$415,$D21,MATCH(R$5,MTInputs!$J$5:$AZ$5,0)) -> TRUE | S21: =INDEX(MTInputs!$J$1:$AZ$415,$D21,MATCH(S$5,MTInputs!$J$5:$AZ$5,0)) -> TRUE | T21: =INDEX(MTInputs!$J$1:$AZ$415,$D21,MATCH(T$5,MTInputs!$J$5:$AZ$5,0)) -> TRUE | ... Z21: =INDEX(MTInputs!$J$1:$AZ$415,$D21,MATCH(Z$5,MTInputs!$J$5:$AZ$5,0)) -> TRUE | AB21: =LOWER(Settings!$C$4)&".mit."&$A21&IF($C21="","","."&$C21&"."&$B21)&IF(INDEX(Variables!$D$5:$D$65,MATCH($A21,Variables!$A$5:$A$65,0))="","","."&INDEX(Variables!$D$5:$D$65,MATCH($A21,Variables!$A$5:$A$65,0)))&"."&AB$5 -> egy.mit.ctcov.all.coa.2 | AC21: =INDEX(MTInputs!$J$1:$AZ$415,$D21,MATCH(AC$5,MTInputs!$J$5:$AZ$5,0)) -> TRUE | AD21: =INDEX(MTInputs!$J$1:$AZ$415,$D21,MATCH(AD$5,MTInputs!$J$5:$AZ$5,0)) -> TRUE | AE21: =INDEX(MTInputs!$J$1:$AZ$415,$D21,MATCH(AE$5,MTInputs!$J$5:$AZ$5,0)) -> TRUE | AF21: =INDEX(MTInputs!$J$1:$AZ$415,$D21,MATCH(AF$5,MTInputs!$J$5:$AZ$5,0)) -> TRUE | AG21: =INDEX(MTInputs!$J$1:$AZ$415,$D21,MATCH(AG$5,MTInputs!$J$5:$AZ$5,0)) -> TRUE | AH21: =INDEX(MTInputs!$J$1:$AZ$415,$D21,MATCH(AH$5,MTInputs!$J$5:$AZ$5,0)) -> TRUE | AI21: =INDEX(MTInputs!$J$1:$AZ$415,$D21,MATCH(AI$5,MTInputs!$J$5:$AZ$5,0)) -> TRUE | AJ21: =INDEX(MTInputs!$J$1:$AZ$415,$D21,MATCH(AJ$5,MTInputs!$J$5:$AZ$5,0)) -> TRUE | ... AP21: =INDEX(MTInputs!$J$1:$AZ$415,$D21,MATCH(AP$5,MTInputs!$J$5:$AZ$5,0)) -> TRUE
A22: ctcov | B22: nga | C22: all | D22: 24 | H22: =INDEX(Variables!$B$5:$B$65,MATCH($A22,Variables!$A$5:$A$65,0))&IF($C22="",""," | "&INDEX(Mapping!$B$5:$B$26,MATCH($C22,Mapping!$A$5:$A$26,0))&" | "&INDEX(Mapping!$B$30:$B$41,MATCH($B22,Mapping!$A$30:$A$41,0))) -> Carbon tax coverage (Apply tax?) | All subsectors | Natural gas | I22: =INDEX(Variables!$C$5:$C$65,MATCH($A22,Variables!$A$5:$A$65,0)) -> switch | J22: =INDEX(Variables!$E$5:$E$65,MATCH($A22,Variables!$A$5:$A$65,0)) -> MTInputs (scenario column) | L22: =LOWER(Settings!$C$4)&".mit."&$A22&IF($C22="","","."&$C22&"."&$B22)&IF(INDEX(Variables!$D$5:$D$65,MATCH($A22,Variables!$A$5:$A$65,0))="","","."&INDEX(Variables!$D$5:$D$65,MATCH($A22,Variables!$A$5:$A$65,0)))&"."&L$5 -> egy.mit.ctcov.all.nga.1 | M22: =INDEX(MTInputs!$J$1:$AZ$415,$D22,MATCH(M$5,MTInputs!$J$5:$AZ$5,0)) -> TRUE | N22: =INDEX(MTInputs!$J$1:$AZ$415,$D22,MATCH(N$5,MTInputs!$J$5:$AZ$5,0)) -> TRUE | O22: =INDEX(MTInputs!$J$1:$AZ$415,$D22,MATCH(O$5,MTInputs!$J$5:$AZ$5,0)) -> TRUE | P22: =INDEX(MTInputs!$J$1:$AZ$415,$D22,MATCH(P$5,MTInputs!$J$5:$AZ$5,0)) -> TRUE | Q22: =INDEX(MTInputs!$J$1:$AZ$415,$D22,MATCH(Q$5,MTInputs!$J$5:$AZ$5,0)) -> TRUE | R22: =INDEX(MTInputs!$J$1:$AZ$415,$D22,MATCH(R$5,MTInputs!$J$5:$AZ$5,0)) -> TRUE | S22: =INDEX(MTInputs!$J$1:$AZ$415,$D22,MATCH(S$5,MTInputs!$J$5:$AZ$5,0)) -> TRUE | T22: =INDEX(MTInputs!$J$1:$AZ$415,$D22,MATCH(T$5,MTInputs!$J$5:$AZ$5,0)) -> TRUE | ... Z22: =INDEX(MTInputs!$J$1:$AZ$415,$D22,MATCH(Z$5,MTInputs!$J$5:$AZ$5,0)) -> TRUE | AB22: =LOWER(Settings!$C$4)&".mit."&$A22&IF($C22="","","."&$C22&"."&$B22)&IF(INDEX(Variables!$D$5:$D$65,MATCH($A22,Variables!$A$5:$A$65,0))="","","."&INDEX(Variables!$D$5:$D$65,MATCH($A22,Variables!$A$5:$A$65,0)))&"."&AB$5 -> egy.mit.ctcov.all.nga.2 | AC22: =INDEX(MTInputs!$J$1:$AZ$415,$D22,MATCH(AC$5,MTInputs!$J$5:$AZ$5,0)) -> TRUE | AD22: =INDEX(MTInputs!$J$1:$AZ$415,$D22,MATCH(AD$5,MTInputs!$J$5:$AZ$5,0)) -> TRUE | AE22: =INDEX(MTInputs!$J$1:$AZ$415,$D22,MATCH(AE$5,MTInputs!$J$5:$AZ$5,0)) -> TRUE | AF22: =INDEX(MTInputs!$J$1:$AZ$415,$D22,MATCH(AF$5,MTInputs!$J$5:$AZ$5,0)) -> TRUE | AG22: =INDEX(MTInputs!$J$1:$AZ$415,$D22,MATCH(AG$5,MTInputs!$J$5:$AZ$5,0)) -> TRUE | AH22: =INDEX(MTInputs!$J$1:$AZ$415,$D22,MATCH(AH$5,MTInputs!$J$5:$AZ$5,0)) -> TRUE | AI22: =INDEX(MTInputs!$J$1:$AZ$415,$D22,MATCH(AI$5,MTInputs!$J$5:$AZ$5,0)) -> TRUE | AJ22: =INDEX(MTInputs!$J$1:$AZ$415,$D22,MATCH(AJ$5,MTInputs!$J$5:$AZ$5,0)) -> TRUE | ... AP22: =INDEX(MTInputs!$J$1:$AZ$415,$D22,MATCH(AP$5,MTInputs!$J$5:$AZ$5,0)) -> TRUE
A23: ctcov | B23: gso | C23: all | D23: 25 | H23: =INDEX(Variables!$B$5:$B$65,MATCH($A23,Variables!$A$5:$A$65,0))&IF($C23="",""," | "&INDEX(Mapping!$B$5:$B$26,MATCH($C23,Mapping!$A$5:$A$26,0))&" | "&INDEX(Mapping!$B$30:$B$41,MATCH($B23,Mapping!$A$30:$A$41,0))) -> Carbon tax coverage (Apply tax?) | All subsectors | Gasoline | I23: =INDEX(Variables!$C$5:$C$65,MATCH($A23,Variables!$A$5:$A$65,0)) -> switch | J23: =INDEX(Variables!$E$5:$E$65,MATCH($A23,Variables!$A$5:$A$65,0)) -> MTInputs (scenario column) | L23: =LOWER(Settings!$C$4)&".mit."&$A23&IF($C23="","","."&$C23&"."&$B23)&IF(INDEX(Variables!$D$5:$D$65,MATCH($A23,Variables!$A$5:$A$65,0))="","","."&INDEX(Variables!$D$5:$D$65,MATCH($A23,Variables!$A$5:$A$65,0)))&"."&L$5 -> egy.mit.ctcov.all.gso.1 | M23: =INDEX(MTInputs!$J$1:$AZ$415,$D23,MATCH(M$5,MTInputs!$J$5:$AZ$5,0)) -> TRUE | N23: =INDEX(MTInputs!$J$1:$AZ$415,$D23,MATCH(N$5,MTInputs!$J$5:$AZ$5,0)) -> TRUE | O23: =INDEX(MTInputs!$J$1:$AZ$415,$D23,MATCH(O$5,MTInputs!$J$5:$AZ$5,0)) -> TRUE | P23: =INDEX(MTInputs!$J$1:$AZ$415,$D23,MATCH(P$5,MTInputs!$J$5:$AZ$5,0)) -> TRUE | Q23: =INDEX(MTInputs!$J$1:$AZ$415,$D23,MATCH(Q$5,MTInputs!$J$5:$AZ$5,0)) -> TRUE | R23: =INDEX(MTInputs!$J$1:$AZ$415,$D23,MATCH(R$5,MTInputs!$J$5:$AZ$5,0)) -> TRUE | S23: =INDEX(MTInputs!$J$1:$AZ$415,$D23,MATCH(S$5,MTInputs!$J$5:$AZ$5,0)) -> TRUE | T23: =INDEX(MTInputs!$J$1:$AZ$415,$D23,MATCH(T$5,MTInputs!$J$5:$AZ$5,0)) -> TRUE | ... Z23: =INDEX(MTInputs!$J$1:$AZ$415,$D23,MATCH(Z$5,MTInputs!$J$5:$AZ$5,0)) -> TRUE | AB23: =LOWER(Settings!$C$4)&".mit."&$A23&IF($C23="","","."&$C23&"."&$B23)&IF(INDEX(Variables!$D$5:$D$65,MATCH($A23,Variables!$A$5:$A$65,0))="","","."&INDEX(Variables!$D$5:$D$65,MATCH($A23,Variables!$A$5:$A$65,0)))&"."&AB$5 -> egy.mit.ctcov.all.gso.2 | AC23: =INDEX(MTInputs!$J$1:$AZ$415,$D23,MATCH(AC$5,MTInputs!$J$5:$AZ$5,0)) -> TRUE | AD23: =INDEX(MTInputs!$J$1:$AZ$415,$D23,MATCH(AD$5,MTInputs!$J$5:$AZ$5,0)) -> TRUE | AE23: =INDEX(MTInputs!$J$1:$AZ$415,$D23,MATCH(AE$5,MTInputs!$J$5:$AZ$5,0)) -> TRUE | AF23: =INDEX(MTInputs!$J$1:$AZ$415,$D23,MATCH(AF$5,MTInputs!$J$5:$AZ$5,0)) -> TRUE | AG23: =INDEX(MTInputs!$J$1:$AZ$415,$D23,MATCH(AG$5,MTInputs!$J$5:$AZ$5,0)) -> TRUE | AH23: =INDEX(MTInputs!$J$1:$AZ$415,$D23,MATCH(AH$5,MTInputs!$J$5:$AZ$5,0)) -> TRUE | AI23: =INDEX(MTInputs!$J$1:$AZ$415,$D23,MATCH(AI$5,MTInputs!$J$5:$AZ$5,0)) -> TRUE | AJ23: =INDEX(MTInputs!$J$1:$AZ$415,$D23,MATCH(AJ$5,MTInputs!$J$5:$AZ$5,0)) -> TRUE | ... AP23: =INDEX(MTInputs!$J$1:$AZ$415,$D23,MATCH(AP$5,MTInputs!$J$5:$AZ$5,0)) -> TRUE
A24: ctcov | B24: die | C24: all | D24: 26 | H24: =INDEX(Variables!$B$5:$B$65,MATCH($A24,Variables!$A$5:$A$65,0))&IF($C24="",""," | "&INDEX(Mapping!$B$5:$B$26,MATCH($C24,Mapping!$A$5:$A$26,0))&" | "&INDEX(Mapping!$B$30:$B$41,MATCH($B24,Mapping!$A$30:$A$41,0))) -> Carbon tax coverage (Apply tax?) | All subsectors | Diesel | I24: =INDEX(Variables!$C$5:$C$65,MATCH($A24,Variables!$A$5:$A$65,0)) -> switch | J24: =INDEX(Variables!$E$5:$E$65,MATCH($A24,Variables!$A$5:$A$65,0)) -> MTInputs (scenario column) | L24: =LOWER(Settings!$C$4)&".mit."&$A24&IF($C24="","","."&$C24&"."&$B24)&IF(INDEX(Variables!$D$5:$D$65,MATCH($A24,Variables!$A$5:$A$65,0))="","","."&INDEX(Variables!$D$5:$D$65,MATCH($A24,Variables!$A$5:$A$65,0)))&"."&L$5 -> egy.mit.ctcov.all.die.1 | M24: =INDEX(MTInputs!$J$1:$AZ$415,$D24,MATCH(M$5,MTInputs!$J$5:$AZ$5,0)) -> TRUE | N24: =INDEX(MTInputs!$J$1:$AZ$415,$D24,MATCH(N$5,MTInputs!$J$5:$AZ$5,0)) -> TRUE | O24: =INDEX(MTInputs!$J$1:$AZ$415,$D24,MATCH(O$5,MTInputs!$J$5:$AZ$5,0)) -> TRUE | P24: =INDEX(MTInputs!$J$1:$AZ$415,$D24,MATCH(P$5,MTInputs!$J$5:$AZ$5,0)) -> TRUE | Q24: =INDEX(MTInputs!$J$1:$AZ$415,$D24,MATCH(Q$5,MTInputs!$J$5:$AZ$5,0)) -> TRUE | R24: =INDEX(MTInputs!$J$1:$AZ$415,$D24,MATCH(R$5,MTInputs!$J$5:$AZ$5,0)) -> TRUE | S24: =INDEX(MTInputs!$J$1:$AZ$415,$D24,MATCH(S$5,MTInputs!$J$5:$AZ$5,0)) -> TRUE | T24: =INDEX(MTInputs!$J$1:$AZ$415,$D24,MATCH(T$5,MTInputs!$J$5:$AZ$5,0)) -> TRUE | ... Z24: =INDEX(MTInputs!$J$1:$AZ$415,$D24,MATCH(Z$5,MTInputs!$J$5:$AZ$5,0)) -> TRUE | AB24: =LOWER(Settings!$C$4)&".mit."&$A24&IF($C24="","","."&$C24&"."&$B24)&IF(INDEX(Variables!$D$5:$D$65,MATCH($A24,Variables!$A$5:$A$65,0))="","","."&INDEX(Variables!$D$5:$D$65,MATCH($A24,Variables!$A$5:$A$65,0)))&"."&AB$5 -> egy.mit.ctcov.all.die.2 | AC24: =INDEX(MTInputs!$J$1:$AZ$415,$D24,MATCH(AC$5,MTInputs!$J$5:$AZ$5,0)) -> TRUE | AD24: =INDEX(MTInputs!$J$1:$AZ$415,$D24,MATCH(AD$5,MTInputs!$J$5:$AZ$5,0)) -> TRUE | AE24: =INDEX(MTInputs!$J$1:$AZ$415,$D24,MATCH(AE$5,MTInputs!$J$5:$AZ$5,0)) -> TRUE | AF24: =INDEX(MTInputs!$J$1:$AZ$415,$D24,MATCH(AF$5,MTInputs!$J$5:$AZ$5,0)) -> TRUE | AG24: =INDEX(MTInputs!$J$1:$AZ$415,$D24,MATCH(AG$5,MTInputs!$J$5:$AZ$5,0)) -> TRUE | AH24: =INDEX(MTInputs!$J$1:$AZ$415,$D24,MATCH(AH$5,MTInputs!$J$5:$AZ$5,0)) -> TRUE | AI24: =INDEX(MTInputs!$J$1:$AZ$415,$D24,MATCH(AI$5,MTInputs!$J$5:$AZ$5,0)) -> TRUE | AJ24: =INDEX(MTInputs!$J$1:$AZ$415,$D24,MATCH(AJ$5,MTInputs!$J$5:$AZ$5,0)) -> TRUE | ... AP24: =INDEX(MTInputs!$J$1:$AZ$415,$D24,MATCH(AP$5,MTInputs!$J$5:$AZ$5,0)) -> TRUE
A25: ctcov | B25: lpg | C25: all | D25: 27 | H25: =INDEX(Variables!$B$5:$B$65,MATCH($A25,Variables!$A$5:$A$65,0))&IF($C25="",""," | "&INDEX(Mapping!$B$5:$B$26,MATCH($C25,Mapping!$A$5:$A$26,0))&" | "&INDEX(Mapping!$B$30:$B$41,MATCH($B25,Mapping!$A$30:$A$41,0))) -> Carbon tax coverage (Apply tax?) | All subsectors | LPG | I25: =INDEX(Variables!$C$5:$C$65,MATCH($A25,Variables!$A$5:$A$65,0)) -> switch | J25: =INDEX(Variables!$E$5:$E$65,MATCH($A25,Variables!$A$5:$A$65,0)) -> MTInputs (scenario column) | L25: =LOWER(Settings!$C$4)&".mit."&$A25&IF($C25="","","."&$C25&"."&$B25)&IF(INDEX(Variables!$D$5:$D$65,MATCH($A25,Variables!$A$5:$A$65,0))="","","."&INDEX(Variables!$D$5:$D$65,MATCH($A25,Variables!$A$5:$A$65,0)))&"."&L$5 -> egy.mit.ctcov.all.lpg.1 | M25: =INDEX(MTInputs!$J$1:$AZ$415,$D25,MATCH(M$5,MTInputs!$J$5:$AZ$5,0)) -> TRUE | N25: =INDEX(MTInputs!$J$1:$AZ$415,$D25,MATCH(N$5,MTInputs!$J$5:$AZ$5,0)) -> TRUE | O25: =INDEX(MTInputs!$J$1:$AZ$415,$D25,MATCH(O$5,MTInputs!$J$5:$AZ$5,0)) -> TRUE | P25: =INDEX(MTInputs!$J$1:$AZ$415,$D25,MATCH(P$5,MTInputs!$J$5:$AZ$5,0)) -> TRUE | Q25: =INDEX(MTInputs!$J$1:$AZ$415,$D25,MATCH(Q$5,MTInputs!$J$5:$AZ$5,0)) -> TRUE | R25: =INDEX(MTInputs!$J$1:$AZ$415,$D25,MATCH(R$5,MTInputs!$J$5:$AZ$5,0)) -> TRUE | S25: =INDEX(MTInputs!$J$1:$AZ$415,$D25,MATCH(S$5,MTInputs!$J$5:$AZ$5,0)) -> TRUE | T25: =INDEX(MTInputs!$J$1:$AZ$415,$D25,MATCH(T$5,MTInputs!$J$5:$AZ$5,0)) -> TRUE | ... Z25: =INDEX(MTInputs!$J$1:$AZ$415,$D25,MATCH(Z$5,MTInputs!$J$5:$AZ$5,0)) -> TRUE | AB25: =LOWER(Settings!$C$4)&".mit."&$A25&IF($C25="","","."&$C25&"."&$B25)&IF(INDEX(Variables!$D$5:$D$65,MATCH($A25,Variables!$A$5:$A$65,0))="","","."&INDEX(Variables!$D$5:$D$65,MATCH($A25,Variables!$A$5:$A$65,0)))&"."&AB$5 -> egy.mit.ctcov.all.lpg.2 | AC25: =INDEX(MTInputs!$J$1:$AZ$415,$D25,MATCH(AC$5,MTInputs!$J$5:$AZ$5,0)) -> TRUE | AD25: =INDEX(MTInputs!$J$1:$AZ$415,$D25,MATCH(AD$5,MTInputs!$J$5:$AZ$5,0)) -> TRUE | AE25: =INDEX(MTInputs!$J$1:$AZ$415,$D25,MATCH(AE$5,MTInputs!$J$5:$AZ$5,0)) -> TRUE | AF25: =INDEX(MTInputs!$J$1:$AZ$415,$D25,MATCH(AF$5,MTInputs!$J$5:$AZ$5,0)) -> TRUE | AG25: =INDEX(MTInputs!$J$1:$AZ$415,$D25,MATCH(AG$5,MTInputs!$J$5:$AZ$5,0)) -> TRUE | AH25: =INDEX(MTInputs!$J$1:$AZ$415,$D25,MATCH(AH$5,MTInputs!$J$5:$AZ$5,0)) -> TRUE | AI25: =INDEX(MTInputs!$J$1:$AZ$415,$D25,MATCH(AI$5,MTInputs!$J$5:$AZ$5,0)) -> TRUE | AJ25: =INDEX(MTInputs!$J$1:$AZ$415,$D25,MATCH(AJ$5,MTInputs!$J$5:$AZ$5,0)) -> TRUE | ... AP25: =INDEX(MTInputs!$J$1:$AZ$415,$D25,MATCH(AP$5,MTInputs!$J$5:$AZ$5,0)) -> TRUE
A26: ctcov | B26: ker | C26: all | D26: 28 | H26: =INDEX(Variables!$B$5:$B$65,MATCH($A26,Variables!$A$5:$A$65,0))&IF($C26="",""," | "&INDEX(Mapping!$B$5:$B$26,MATCH($C26,Mapping!$A$5:$A$26,0))&" | "&INDEX(Mapping!$B$30:$B$41,MATCH($B26,Mapping!$A$30:$A$41,0))) -> Carbon tax coverage (Apply tax?) | All subsectors | Kerosene | I26: =INDEX(Variables!$C$5:$C$65,MATCH($A26,Variables!$A$5:$A$65,0)) -> switch | J26: =INDEX(Variables!$E$5:$E$65,MATCH($A26,Variables!$A$5:$A$65,0)) -> MTInputs (scenario column) | L26: =LOWER(Settings!$C$4)&".mit."&$A26&IF($C26="","","."&$C26&"."&$B26)&IF(INDEX(Variables!$D$5:$D$65,MATCH($A26,Variables!$A$5:$A$65,0))="","","."&INDEX(Variables!$D$5:$D$65,MATCH($A26,Variables!$A$5:$A$65,0)))&"."&L$5 -> egy.mit.ctcov.all.ker.1 | M26: =INDEX(MTInputs!$J$1:$AZ$415,$D26,MATCH(M$5,MTInputs!$J$5:$AZ$5,0)) -> TRUE | N26: =INDEX(MTInputs!$J$1:$AZ$415,$D26,MATCH(N$5,MTInputs!$J$5:$AZ$5,0)) -> TRUE | O26: =INDEX(MTInputs!$J$1:$AZ$415,$D26,MATCH(O$5,MTInputs!$J$5:$AZ$5,0)) -> TRUE | P26: =INDEX(MTInputs!$J$1:$AZ$415,$D26,MATCH(P$5,MTInputs!$J$5:$AZ$5,0)) -> TRUE | Q26: =INDEX(MTInputs!$J$1:$AZ$415,$D26,MATCH(Q$5,MTInputs!$J$5:$AZ$5,0)) -> TRUE | R26: =INDEX(MTInputs!$J$1:$AZ$415,$D26,MATCH(R$5,MTInputs!$J$5:$AZ$5,0)) -> TRUE | S26: =INDEX(MTInputs!$J$1:$AZ$415,$D26,MATCH(S$5,MTInputs!$J$5:$AZ$5,0)) -> TRUE | T26: =INDEX(MTInputs!$J$1:$AZ$415,$D26,MATCH(T$5,MTInputs!$J$5:$AZ$5,0)) -> TRUE | ... Z26: =INDEX(MTInputs!$J$1:$AZ$415,$D26,MATCH(Z$5,MTInputs!$J$5:$AZ$5,0)) -> TRUE | AB26: =LOWER(Settings!$C$4)&".mit."&$A26&IF($C26="","","."&$C26&"."&$B26)&IF(INDEX(Variables!$D$5:$D$65,MATCH($A26,Variables!$A$5:$A$65,0))="","","."&INDEX(Variables!$D$5:$D$65,MATCH($A26,Variables!$A$5:$A$65,0)))&"."&AB$5 -> egy.mit.ctcov.all.ker.2 | AC26: =INDEX(MTInputs!$J$1:$AZ$415,$D26,MATCH(AC$5,MTInputs!$J$5:$AZ$5,0)) -> TRUE | AD26: =INDEX(MTInputs!$J$1:$AZ$415,$D26,MATCH(AD$5,MTInputs!$J$5:$AZ$5,0)) -> TRUE | AE26: =INDEX(MTInputs!$J$1:$AZ$415,$D26,MATCH(AE$5,MTInputs!$J$5:$AZ$5,0)) -> TRUE | AF26: =INDEX(MTInputs!$J$1:$AZ$415,$D26,MATCH(AF$5,MTInputs!$J$5:$AZ$5,0)) -> TRUE | AG26: =INDEX(MTInputs!$J$1:$AZ$415,$D26,MATCH(AG$5,MTInputs!$J$5:$AZ$5,0)) -> TRUE | AH26: =INDEX(MTInputs!$J$1:$AZ$415,$D26,MATCH(AH$5,MTInputs!$J$5:$AZ$5,0)) -> TRUE | AI26: =INDEX(MTInputs!$J$1:$AZ$415,$D26,MATCH(AI$5,MTInputs!$J$5:$AZ$5,0)) -> TRUE | AJ26: =INDEX(MTInputs!$J$1:$AZ$415,$D26,MATCH(AJ$5,MTInputs!$J$5:$AZ$5,0)) -> TRUE | ... AP26: =INDEX(MTInputs!$J$1:$AZ$415,$D26,MATCH(AP$5,MTInputs!$J$5:$AZ$5,0)) -> TRUE
A27: ctcov | B27: oop | C27: all | D27: 29 | H27: =INDEX(Variables!$B$5:$B$65,MATCH($A27,Variables!$A$5:$A$65,0))&IF($C27="",""," | "&INDEX(Mapping!$B$5:$B$26,MATCH($C27,Mapping!$A$5:$A$26,0))&" | "&INDEX(Mapping!$B$30:$B$41,MATCH($B27,Mapping!$A$30:$A$41,0))) -> Carbon tax coverage (Apply tax?) | All subsectors | Other oil products | I27: =INDEX(Variables!$C$5:$C$65,MATCH($A27,Variables!$A$5:$A$65,0)) -> switch | J27: =INDEX(Variables!$E$5:$E$65,MATCH($A27,Variables!$A$5:$A$65,0)) -> MTInputs (scenario column) | L27: =LOWER(Settings!$C$4)&".mit."&$A27&IF($C27="","","."&$C27&"."&$B27)&IF(INDEX(Variables!$D$5:$D$65,MATCH($A27,Variables!$A$5:$A$65,0))="","","."&INDEX(Variables!$D$5:$D$65,MATCH($A27,Variables!$A$5:$A$65,0)))&"."&L$5 -> egy.mit.ctcov.all.oop.1 | M27: =INDEX(MTInputs!$J$1:$AZ$415,$D27,MATCH(M$5,MTInputs!$J$5:$AZ$5,0)) -> TRUE | N27: =INDEX(MTInputs!$J$1:$AZ$415,$D27,MATCH(N$5,MTInputs!$J$5:$AZ$5,0)) -> TRUE | O27: =INDEX(MTInputs!$J$1:$AZ$415,$D27,MATCH(O$5,MTInputs!$J$5:$AZ$5,0)) -> TRUE | P27: =INDEX(MTInputs!$J$1:$AZ$415,$D27,MATCH(P$5,MTInputs!$J$5:$AZ$5,0)) -> TRUE | Q27: =INDEX(MTInputs!$J$1:$AZ$415,$D27,MATCH(Q$5,MTInputs!$J$5:$AZ$5,0)) -> TRUE | R27: =INDEX(MTInputs!$J$1:$AZ$415,$D27,MATCH(R$5,MTInputs!$J$5:$AZ$5,0)) -> TRUE | S27: =INDEX(MTInputs!$J$1:$AZ$415,$D27,MATCH(S$5,MTInputs!$J$5:$AZ$5,0)) -> TRUE | T27: =INDEX(MTInputs!$J$1:$AZ$415,$D27,MATCH(T$5,MTInputs!$J$5:$AZ$5,0)) -> TRUE | ... Z27: =INDEX(MTInputs!$J$1:$AZ$415,$D27,MATCH(Z$5,MTInputs!$J$5:$AZ$5,0)) -> TRUE | AB27: =LOWER(Settings!$C$4)&".mit."&$A27&IF($C27="","","."&$C27&"."&$B27)&IF(INDEX(Variables!$D$5:$D$65,MATCH($A27,Variables!$A$5:$A$65,0))="","","."&INDEX(Variables!$D$5:$D$65,MATCH($A27,Variables!$A$5:$A$65,0)))&"."&AB$5 -> egy.mit.ctcov.all.oop.2 | AC27: =INDEX(MTInputs!$J$1:$AZ$415,$D27,MATCH(AC$5,MTInputs!$J$5:$AZ$5,0)) -> TRUE | AD27: =INDEX(MTInputs!$J$1:$AZ$415,$D27,MATCH(AD$5,MTInputs!$J$5:$AZ$5,0)) -> TRUE | AE27: =INDEX(MTInputs!$J$1:$AZ$415,$D27,MATCH(AE$5,MTInputs!$J$5:$AZ$5,0)) -> TRUE | AF27: =INDEX(MTInputs!$J$1:$AZ$415,$D27,MATCH(AF$5,MTInputs!$J$5:$AZ$5,0)) -> TRUE | AG27: =INDEX(MTInputs!$J$1:$AZ$415,$D27,MATCH(AG$5,MTInputs!$J$5:$AZ$5,0)) -> TRUE | AH27: =INDEX(MTInputs!$J$1:$AZ$415,$D27,MATCH(AH$5,MTInputs!$J$5:$AZ$5,0)) -> TRUE | AI27: =INDEX(MTInputs!$J$1:$AZ$415,$D27,MATCH(AI$5,MTInputs!$J$5:$AZ$5,0)) -> TRUE | AJ27: =INDEX(MTInputs!$J$1:$AZ$415,$D27,MATCH(AJ$5,MTInputs!$J$5:$AZ$5,0)) -> TRUE | ... AP27: =INDEX(MTInputs!$J$1:$AZ$415,$D27,MATCH(AP$5,MTInputs!$J$5:$AZ$5,0)) -> TRUE
A28: ctcov | B28: bio | C28: all | H28: =INDEX(Variables!$B$5:$B$65,MATCH($A28,Variables!$A$5:$A$65,0))&IF($C28="",""," | "&INDEX(Mapping!$B$5:$B$26,MATCH($C28,Mapping!$A$5:$A$26,0))&" | "&INDEX(Mapping!$B$30:$B$41,MATCH($B28,Mapping!$A$30:$A$41,0))) -> Carbon tax coverage (Apply tax?) | All subsectors | Biomass | I28: =INDEX(Variables!$C$5:$C$65,MATCH($A28,Variables!$A$5:$A$65,0)) -> switch | J28: =INDEX(Variables!$E$5:$E$65,MATCH($A28,Variables!$A$5:$A$65,0)) -> MTInputs (scenario column) | L28: =LOWER(Settings!$C$4)&".mit."&$A28&IF($C28="","","."&$C28&"."&$B28)&IF(INDEX(Variables!$D$5:$D$65,MATCH($A28,Variables!$A$5:$A$65,0))="","","."&INDEX(Variables!$D$5:$D$65,MATCH($A28,Variables!$A$5:$A$65,0)))&"."&L$5 -> egy.mit.ctcov.all.bio.1 | M28: TRUE | N28: TRUE | O28: TRUE | P28: TRUE | Q28: TRUE | R28: TRUE | S28: TRUE | T28: TRUE | U28: TRUE | V28: TRUE | W28: TRUE | X28: TRUE | Y28: TRUE | Z28: TRUE | AB28: =LOWER(Settings!$C$4)&".mit."&$A28&IF($C28="","","."&$C28&"."&$B28)&IF(INDEX(Variables!$D$5:$D$65,MATCH($A28,Variables!$A$5:$A$65,0))="","","."&INDEX(Variables!$D$5:$D$65,MATCH($A28,Variables!$A$5:$A$65,0)))&"."&AB$5 -> egy.mit.ctcov.all.bio.2 | AC28: TRUE | AD28: TRUE | AE28: TRUE | AF28: TRUE | AG28: TRUE | AH28: TRUE | AI28: TRUE | AJ28: TRUE | AK28: TRUE | AL28: TRUE | AM28: TRUE | AN28: TRUE | AO28: TRUE | AP28: TRUE
H29: Carbon tax coverage: sectors (MTInputs rows 31-47)
A30: ctcov | B30: all | C30: pow | D30: 31 | H30: =INDEX(Variables!$B$5:$B$65,MATCH($A30,Variables!$A$5:$A$65,0))&IF($C30="",""," | "&INDEX(Mapping!$B$5:$B$26,MATCH($C30,Mapping!$A$5:$A$26,0))&" | "&INDEX(Mapping!$B$30:$B$41,MATCH($B30,Mapping!$A$30:$A$41,0))) -> Carbon tax coverage (Apply tax?) | Power | All fuels | I30: =INDEX(Variables!$C$5:$C$65,MATCH($A30,Variables!$A$5:$A$65,0)) -> switch | J30: =INDEX(Variables!$E$5:$E$65,MATCH($A30,Variables!$A$5:$A$65,0)) -> MTInputs (scenario column) | L30: =LOWER(Settings!$C$4)&".mit."&$A30&IF($C30="","","."&$C30&"."&$B30)&IF(INDEX(Variables!$D$5:$D$65,MATCH($A30,Variables!$A$5:$A$65,0))="","","."&INDEX(Variables!$D$5:$D$65,MATCH($A30,Variables!$A$5:$A$65,0)))&"."&L$5 -> egy.mit.ctcov.pow.all.1 | M30: =INDEX(MTInputs!$J$1:$AZ$415,$D30,MATCH(M$5,MTInputs!$J$5:$AZ$5,0)) -> TRUE | N30: =INDEX(MTInputs!$J$1:$AZ$415,$D30,MATCH(N$5,MTInputs!$J$5:$AZ$5,0)) -> TRUE | O30: =INDEX(MTInputs!$J$1:$AZ$415,$D30,MATCH(O$5,MTInputs!$J$5:$AZ$5,0)) -> TRUE | P30: =INDEX(MTInputs!$J$1:$AZ$415,$D30,MATCH(P$5,MTInputs!$J$5:$AZ$5,0)) -> TRUE | Q30: =INDEX(MTInputs!$J$1:$AZ$415,$D30,MATCH(Q$5,MTInputs!$J$5:$AZ$5,0)) -> TRUE | R30: =INDEX(MTInputs!$J$1:$AZ$415,$D30,MATCH(R$5,MTInputs!$J$5:$AZ$5,0)) -> TRUE | S30: =INDEX(MTInputs!$J$1:$AZ$415,$D30,MATCH(S$5,MTInputs!$J$5:$AZ$5,0)) -> TRUE | T30: =INDEX(MTInputs!$J$1:$AZ$415,$D30,MATCH(T$5,MTInputs!$J$5:$AZ$5,0)) -> TRUE | ... Z30: =INDEX(MTInputs!$J$1:$AZ$415,$D30,MATCH(Z$5,MTInputs!$J$5:$AZ$5,0)) -> TRUE | AB30: =LOWER(Settings!$C$4)&".mit."&$A30&IF($C30="","","."&$C30&"."&$B30)&IF(INDEX(Variables!$D$5:$D$65,MATCH($A30,Variables!$A$5:$A$65,0))="","","."&INDEX(Variables!$D$5:$D$65,MATCH($A30,Variables!$A$5:$A$65,0)))&"."&AB$5 -> egy.mit.ctcov.pow.all.2 | AC30: =INDEX(MTInputs!$J$1:$AZ$415,$D30,MATCH(AC$5,MTInputs!$J$5:$AZ$5,0)) -> TRUE | AD30: =INDEX(MTInputs!$J$1:$AZ$415,$D30,MATCH(AD$5,MTInputs!$J$5:$AZ$5,0)) -> TRUE | AE30: =INDEX(MTInputs!$J$1:$AZ$415,$D30,MATCH(AE$5,MTInputs!$J$5:$AZ$5,0)) -> TRUE | AF30: =INDEX(MTInputs!$J$1:$AZ$415,$D30,MATCH(AF$5,MTInputs!$J$5:$AZ$5,0)) -> TRUE | AG30: =INDEX(MTInputs!$J$1:$AZ$415,$D30,MATCH(AG$5,MTInputs!$J$5:$AZ$5,0)) -> TRUE | AH30: =INDEX(MTInputs!$J$1:$AZ$415,$D30,MATCH(AH$5,MTInputs!$J$5:$AZ$5,0)) -> TRUE | AI30: =INDEX(MTInputs!$J$1:$AZ$415,$D30,MATCH(AI$5,MTInputs!$J$5:$AZ$5,0)) -> TRUE | AJ30: =INDEX(MTInputs!$J$1:$AZ$415,$D30,MATCH(AJ$5,MTInputs!$J$5:$AZ$5,0)) -> TRUE | ... AP30: =INDEX(MTInputs!$J$1:$AZ$415,$D30,MATCH(AP$5,MTInputs!$J$5:$AZ$5,0)) -> TRUE
A31: ctcov | B31: all | C31: rod | D31: 32 | H31: =INDEX(Variables!$B$5:$B$65,MATCH($A31,Variables!$A$5:$A$65,0))&IF($C31="",""," | "&INDEX(Mapping!$B$5:$B$26,MATCH($C31,Mapping!$A$5:$A$26,0))&" | "&INDEX(Mapping!$B$30:$B$41,MATCH($B31,Mapping!$A$30:$A$41,0))) -> Carbon tax coverage (Apply tax?) | Road | All fuels | I31: =INDEX(Variables!$C$5:$C$65,MATCH($A31,Variables!$A$5:$A$65,0)) -> switch | J31: =INDEX(Variables!$E$5:$E$65,MATCH($A31,Variables!$A$5:$A$65,0)) -> MTInputs (scenario column) | L31: =LOWER(Settings!$C$4)&".mit."&$A31&IF($C31="","","."&$C31&"."&$B31)&IF(INDEX(Variables!$D$5:$D$65,MATCH($A31,Variables!$A$5:$A$65,0))="","","."&INDEX(Variables!$D$5:$D$65,MATCH($A31,Variables!$A$5:$A$65,0)))&"."&L$5 -> egy.mit.ctcov.rod.all.1 | M31: =INDEX(MTInputs!$J$1:$AZ$415,$D31,MATCH(M$5,MTInputs!$J$5:$AZ$5,0)) -> TRUE | N31: =INDEX(MTInputs!$J$1:$AZ$415,$D31,MATCH(N$5,MTInputs!$J$5:$AZ$5,0)) -> TRUE | O31: =INDEX(MTInputs!$J$1:$AZ$415,$D31,MATCH(O$5,MTInputs!$J$5:$AZ$5,0)) -> TRUE | P31: =INDEX(MTInputs!$J$1:$AZ$415,$D31,MATCH(P$5,MTInputs!$J$5:$AZ$5,0)) -> TRUE | Q31: =INDEX(MTInputs!$J$1:$AZ$415,$D31,MATCH(Q$5,MTInputs!$J$5:$AZ$5,0)) -> TRUE | R31: =INDEX(MTInputs!$J$1:$AZ$415,$D31,MATCH(R$5,MTInputs!$J$5:$AZ$5,0)) -> TRUE | S31: =INDEX(MTInputs!$J$1:$AZ$415,$D31,MATCH(S$5,MTInputs!$J$5:$AZ$5,0)) -> TRUE | T31: =INDEX(MTInputs!$J$1:$AZ$415,$D31,MATCH(T$5,MTInputs!$J$5:$AZ$5,0)) -> TRUE | ... Z31: =INDEX(MTInputs!$J$1:$AZ$415,$D31,MATCH(Z$5,MTInputs!$J$5:$AZ$5,0)) -> TRUE | AB31: =LOWER(Settings!$C$4)&".mit."&$A31&IF($C31="","","."&$C31&"."&$B31)&IF(INDEX(Variables!$D$5:$D$65,MATCH($A31,Variables!$A$5:$A$65,0))="","","."&INDEX(Variables!$D$5:$D$65,MATCH($A31,Variables!$A$5:$A$65,0)))&"."&AB$5 -> egy.mit.ctcov.rod.all.2 | AC31: =INDEX(MTInputs!$J$1:$AZ$415,$D31,MATCH(AC$5,MTInputs!$J$5:$AZ$5,0)) -> TRUE | AD31: =INDEX(MTInputs!$J$1:$AZ$415,$D31,MATCH(AD$5,MTInputs!$J$5:$AZ$5,0)) -> TRUE | AE31: =INDEX(MTInputs!$J$1:$AZ$415,$D31,MATCH(AE$5,MTInputs!$J$5:$AZ$5,0)) -> TRUE | AF31: =INDEX(MTInputs!$J$1:$AZ$415,$D31,MATCH(AF$5,MTInputs!$J$5:$AZ$5,0)) -> TRUE | AG31: =INDEX(MTInputs!$J$1:$AZ$415,$D31,MATCH(AG$5,MTInputs!$J$5:$AZ$5,0)) -> TRUE | AH31: =INDEX(MTInputs!$J$1:$AZ$415,$D31,MATCH(AH$5,MTInputs!$J$5:$AZ$5,0)) -> TRUE | AI31: =INDEX(MTInputs!$J$1:$AZ$415,$D31,MATCH(AI$5,MTInputs!$J$5:$AZ$5,0)) -> TRUE | AJ31: =INDEX(MTInputs!$J$1:$AZ$415,$D31,MATCH(AJ$5,MTInputs!$J$5:$AZ$5,0)) -> TRUE | ... AP31: =INDEX(MTInputs!$J$1:$AZ$415,$D31,MATCH(AP$5,MTInputs!$J$5:$AZ$5,0)) -> TRUE
