Workbook

Sheet README
B2: Integrated MF-C tool — macro-fiscal and climate
B3: Version 0.1. 217 countries, 91 indicators, built from the Global Fiscal Indicators dashboard (v1.2 panel) and the mitigation investment needs models (v1.1 workbook, NMIM v0.2).
B5: What this is | C5: The integrated macro-fiscal climate (MF-C) tool. It puts the Global Fiscal Indicators dashboard and the mitigation investment needs models on one country page: what a country's net zero programme needs and costs, beside whether it can pay for it, build it, and finance it. More modules will be added. The is_ccdr column flags the 98 economies with a published Country Climate and Development Report.
B7: How it is organised | C7: Thirteen blocks, in reading order. Four ASSESSMENT blocks carry the diagnosis: fiscal space, delivery, cost of capital, and financing. Three CONTEXT blocks explain it: fossil revenue in the budget, fossil trade and extraction, and power generation. Two INVESTMENT blocks give the need: Investment 1 (2030 snapshot, by sector and cost-of-capital lens) and Investment 2 (who pays, and the path to 2050). They read High / Medium / Low, like the Context blocks. Four APPENDIX blocks - fuel pricing, power market regulation, macro-model inputs and the integrated scenario - are reference detail in grey and carry no block verdict.
B9: How to use it | C9: Dashboard: pick a country in the yellow cell. Everything resolves - evaluation, score, value, observation year, coverage - grouped and coloured by block. Data_wide is the cross-section, Data_long names the source file for every value, Scores holds the 1-10 rescaling, Spec is the indicator list, Sources lists the datasets.
B11: Reading the rows | C11: Indented italic rows are components of the line above: subsidies split into explicit and implicit, net fuel trade into exports and imports, fossil rents into oil, gas and coal, and the headline WACC into its cross-check sources. They are scored individually but they are not independent of their parent.
B13: Evaluation and score | C13: Every indicator carries a plain-word Evaluation beside a 1-10 Score. Good / Medium / Bad where a direction exists. High / Medium / Low where the number is a magnitude rather than a verdict. High or Low Exporter / Importer for net fuel trade, read off the value. Thresholds: 7 and above, 4 to 7, below 4.
B15: Context blocks are magnitudes | C15: The three Context blocks use High / Medium / Low, not Good / Bad. A country reading High on Context 2 has a large extraction and export position - read as opportunity that is revenue it could expand, read as exposure it is revenue the transition puts at risk. The file does not pick one.
B17: Do not build an index | C17: Block averages are given, but do not average across blocks into a single country score. There are no defensible weights between them, and it would erase the triage: a country weak on Fiscal needs different instruments from one weak on PIMA.
B19: Non-negotiables | C19: Nothing is imputed; missing stays missing. Every value carries its observation year, because vintages span five years - fiscal core 2024, capex execution mostly 2022, rents and WACC 2021. Scores are relative to the 217-country sample and move if the sample changes.
B21: Appendix blocks | C21: Appendix A gives retail prices by fuel and sector, all from CPAT and all 2024. Appendix B describes how the power sector is organised. Note the vintages: the PSRT market-structure and regulator flags are 2013 and non-OECD only, so read them as structural context, not current state; RISE scores are 2023 and cover 140 countries.
B23: Appendix C and D | C23: Appendix C holds the WEO ratios the macro-fiscal models start from (revenue, primary balance, investment, current account, average growth). Appendix D is MODEL OUTPUT, not data: the integrated scenario from MacroFiscalModels (investment needs from NMIM, feasible power-sector carbon pricing from PriceFeasibility, a macro model, LIC-DSF-lite), with illustrative calibrations. Read it as a scenario, never as an observation; its year is the scenario year.
B25: A caveat on electricity prices | C25: The two electricity price rows come from the same CPAT series behind the cost-recovery indicators that were dropped from this tool on data-quality grounds. Retail prices are closer to observed than the modelled supply costs were, and they are the input CPAT uses to compute subsidies - but treat them as reference values rather than evidence.
B27: Not included | C27: IMF PIMA and C-PIMA scores. Publication is consent-based and the published subsample self-selects toward better performers, so a scored column would understate weakness. PEFA PI-11 is the substitute. Electricity cost recovery was also dropped: the CPAT retail-price basis is not reliable enough to carry a scored column.
... B33: Overlap with Appendix D | C33: Appendix D's budget need is the incremental budget need from NMIM, as passed through MacroFiscalModels; Investment 2's is the budget need of the whole net zero programme. Use Investment 2 for size and composition, Appendix D for what it does to the budget and debt.

Sheet Dashboard
B2: Country profile
B4: Country | C4: Kenya | D4: =INDEX(Data_wide!$A$2:$A$218,MATCH($C$4,Data_wide!$B$2:$B$218,0)) | F4: =INDEX(Data_wide!$C$2:$C$218,MATCH($C$4,Data_wide!$B$2:$B$218,0))
B6: ="CCDR economy: "&IF(INDEX(Data_wide!$E$2:$E$218,MATCH($C$4,Data_wide!$B$2:$B$218,0))=TRUE,"yes","no")&" | indicators with data: "&COUNT(F9:F115)&" of 91"
B7: Pick a country above. ● marks the headline indicator for each block.
C8: Indicator | D8: Evaluation | E8: Score | F8: Value | G8: Year | H8: Direction | I8: Area | J8: Data source | K8: Cov. | L8: Data?
C9: Fiscal — Can they pay for it? | D9: =IFERROR(IF(E9>=7,"Good",IF(E9>=4,"Medium","Bad")),"") | E9: =IFERROR(ROUND(AVERAGE(E10:E13),1),"") | H9: Fiscal space | I9: Debt service and revenue capacity | L9: =COUNT(F10:F13)&"/4"
B10: ● | C10: Interest-to-revenue, general govt (%) | D10: =IF(E10="","",IF(E10>=7,"Good",IF(E10>=4,"Medium","Bad"))) | E10: =IFERROR(INDEX(Scores!$C$6:$C$222,MATCH($C$4,Scores!$B$6:$B$222,0)),"") | F10: =IFERROR(IF(INDEX(Data_wide!$F$2:$F$218,MATCH($C$4,Data_wide!$B$2:$B$218,0))="","",INDEX(Data_wide!$F$2:$F$218,MATCH($C$4,Data_wide!$B$2:$B$218,0))),"") | G10: =IFERROR(IF(INDEX(Data_wide!$CS$2:$CS$218,MATCH($C$4,Data_wide!$B$2:$B$218,0))="","",INDEX(Data_wide!$CS$2:$CS$218,MATCH($C$4,Data_wide!$B$2:$B$218,0))),"") | H10: High = worse | I10: Debt service burden | J10: IMF WEO (derived) | K10: 184 | L10: =IF(F10="","-","Yes")
C11: Interest payments (net), general govt (% GDP) | D11: =IF(E11="","",IF(E11>=7,"Good",IF(E11>=4,"Medium","Bad"))) | E11: =IFERROR(INDEX(Scores!$D$6:$D$222,MATCH($C$4,Scores!$B$6:$B$222,0)),"") | F11: =IFERROR(IF(INDEX(Data_wide!$G$2:$G$218,MATCH($C$4,Data_wide!$B$2:$B$218,0))="","",INDEX(Data_wide!$G$2:$G$218,MATCH($C$4,Data_wide!$B$2:$B$218,0))),"") | G11: =IFERROR(IF(INDEX(Data_wide!$CT$2:$CT$218,MATCH($C$4,Data_wide!$B$2:$B$218,0))="","",INDEX(Data_wide!$CT$2:$CT$218,MATCH($C$4,Data_wide!$B$2:$B$218,0))),"") | H11: High = worse | I11: Debt service burden | J11: IMF WEO (derived) | K11: 189 | L11: =IF(F11="","-","Yes")
C12: Gross debt, general govt (% GDP) | D12: =IF(E12="","",IF(E12>=7,"Good",IF(E12>=4,"Medium","Bad"))) | E12: =IFERROR(INDEX(Scores!$E$6:$E$222,MATCH($C$4,Scores!$B$6:$B$222,0)),"") | F12: =IFERROR(IF(INDEX(Data_wide!$H$2:$H$218,MATCH($C$4,Data_wide!$B$2:$B$218,0))="","",INDEX(Data_wide!$H$2:$H$218,MATCH($C$4,Data_wide!$B$2:$B$218,0))),"") | G12: =IFERROR(IF(INDEX(Data_wide!$CU$2:$CU$218,MATCH($C$4,Data_wide!$B$2:$B$218,0))="","",INDEX(Data_wide!$CU$2:$CU$218,MATCH($C$4,Data_wide!$B$2:$B$218,0))),"") | H12: High = worse | I12: Fiscal space | J12: IMF WEO | K12: 191 | L12: =IF(F12="","-","Yes")
C13: Tax revenue (% GDP) | D13: =IF(E13="","",IF(E13>=7,"Good",IF(E13>=4,"Medium","Bad"))) | E13: =IFERROR(INDEX(Scores!$F$6:$F$222,MATCH($C$4,Scores!$B$6:$B$222,0)),"") | F13: =IFERROR(IF(INDEX(Data_wide!$I$2:$I$218,MATCH($C$4,Data_wide!$B$2:$B$218,0))="","",INDEX(Data_wide!$I$2:$I$218,MATCH($C$4,Data_wide!$B$2:$B$218,0))),"") | G13: =IFERROR(IF(INDEX(Data_wide!$CV$2:$CV$218,MATCH($C$4,Data_wide!$B$2:$B$218,0))="","",INDEX(Data_wide!$CV$2:$CV$218,MATCH($C$4,Data_wide!$B$2:$B$218,0))),"") | H13: High = better | I13: Revenue capacity | J13: IMF WoRLD 2026 | K13: 193 | L13: =IF(F13="","-","Yes")
C14: PIMA — Can they build it? | D14: =IFERROR(IF(E14>=7,"Good",IF(E14>=4,"Medium","Bad")),"") | E14: =IFERROR(ROUND(AVERAGE(E15:E18),1),"") | H14: Delivery | I14: Execution capacity and institutions | L14: =COUNT(F15:F18)&"/4"
B15: ● | C15: Capital budget execution rate (%) | D15: =IF(E15="","",IF(E15>=7,"Good",IF(E15>=4,"Medium","Bad"))) | E15: =IFERROR(INDEX(Scores!$G$6:$G$222,MATCH($C$4,Scores!$B$6:$B$222,0)),"") | F15: =IFERROR(IF(INDEX(Data_wide!$J$2:$J$218,MATCH($C$4,Data_wide!$B$2:$B$218,0))="","",INDEX(Data_wide!$J$2:$J$218,MATCH($C$4,Data_wide!$B$2:$B$218,0))),"") | G15: =IFERROR(IF(INDEX(Data_wide!$CW$2:$CW$218,MATCH($C$4,Data_wide!$B$2:$B$218,0))="","",INDEX(Data_wide!$CW$2:$CW$218,MATCH($C$4,Data_wide!$B$2:$B$218,0))),"") | H15: High = better (>100 worse) | I15: Delivery capacity | J15: World Bank BOOST | K15: 104 | L15: =IF(F15="","-","Yes")
C16: PEFA PI-11, public investment management (1-4) | D16: =IF(E16="","",IF(E16>=7,"Good",IF(E16>=4,"Medium","Bad"))) | E16: =IFERROR(INDEX(Scores!$H$6:$H$222,MATCH($C$4,Scores!$B$6:$B$222,0)),"") | F16: =IFERROR(IF(INDEX(Data_wide!$K$2:$K$218,MATCH($C$4,Data_wide!$B$2:$B$218,0))="","",INDEX(Data_wide!$K$2:$K$218,MATCH($C$4,Data_wide!$B$2:$B$218,0))),"") | G16: =IFERROR(IF(INDEX(Data_wide!$CX$2:$CX$218,MATCH($C$4,Data_wide!$B$2:$B$218,0))="","",INDEX(Data_wide!$CX$2:$CX$218,MATCH($C$4,Data_wide!$B$2:$B$218,0))),"") | H16: High = better | I16: PIM quality | J16: PEFA 2016 framework | K16: 82 | L16: =IF(F16="","-","Yes")
C17: PEFA PI-12.2, asset monitoring (1-4) | D17: =IF(E17="","",IF(E17>=7,"Good",IF(E17>=4,"Medium","Bad"))) | E17: =IFERROR(INDEX(Scores!$I$6:$I$222,MATCH($C$4,Scores!$B$6:$B$222,0)),"") | F17: =IFERROR(IF(INDEX(Data_wide!$L$2:$L$218,MATCH($C$4,Data_wide!$B$2:$B$218,0))="","",INDEX(Data_wide!$L$2:$L$218,MATCH($C$4,Data_wide!$B$2:$B$218,0))),"") | G17: =IFERROR(IF(INDEX(Data_wide!$CY$2:$CY$218,MATCH($C$4,Data_wide!$B$2:$B$218,0))="","",INDEX(Data_wide!$CY$2:$CY$218,MATCH($C$4,Data_wide!$B$2:$B$218,0))),"") | H17: High = better | I17: Asset management | J17: PEFA 2016 framework | K17: 83 | L17: =IF(F17="","-","Yes")
C18: Climate-PFM diagnostic on record (0/1) | D18: =IF(E18="","",IF(E18>=7,"Good",IF(E18>=4,"Medium","Bad"))) | E18: =IFERROR(INDEX(Scores!$J$6:$J$222,MATCH($C$4,Scores!$B$6:$B$222,0)),"") | F18: =IFERROR(IF(INDEX(Data_wide!$M$2:$M$218,MATCH($C$4,Data_wide!$B$2:$B$218,0))="","",INDEX(Data_wide!$M$2:$M$218,MATCH($C$4,Data_wide!$B$2:$B$218,0))),"") | G18: =IFERROR(IF(INDEX(Data_wide!$CZ$2:$CZ$218,MATCH($C$4,Data_wide!$B$2:$B$218,0))="","",INDEX(Data_wide!$CZ$2:$CZ$218,MATCH($C$4,Data_wide!$B$2:$B$218,0))),"") | H18: High = better | I18: Institutional history | J18: UNDP Global Climate PFR 2022 | K18: 217 | L18: =IF(F18="","-","Yes")
C19: Finance 1 — What does capital cost them? | D19: =IFERROR(IF(E19>=7,"Good",IF(E19>=4,"Medium","Bad")),"") | E19: =IFERROR(ROUND(AVERAGE(E20:E26),1),"") | H19: Cost of capital | I19: Project WACC and borrowing terms | L19: =COUNT(F20:F26)&"/7"
B20: ● | C20: WACC, solar PV, real after-tax (%) | D20: =IF(E20="","",IF(E20>=7,"Good",IF(E20>=4,"Medium","Bad"))) | E20: =IFERROR(INDEX(Scores!$K$6:$K$222,MATCH($C$4,Scores!$B$6:$B$222,0)),"") | F20: =IFERROR(IF(INDEX(Data_wide!$N$2:$N$218,MATCH($C$4,Data_wide!$B$2:$B$218,0))="","",INDEX(Data_wide!$N$2:$N$218,MATCH($C$4,Data_wide!$B$2:$B$218,0))),"") | G20: =IFERROR(IF(INDEX(Data_wide!$DA$2:$DA$218,MATCH($C$4,Data_wide!$B$2:$B$218,0))="","",INDEX(Data_wide!$DA$2:$DA$218,MATCH($C$4,Data_wide!$B$2:$B$218,0))),"") | H20: High = worse | I20: RE cost of capital | J20: IRENA (2022), ref. yr 2021 | K20: 43 | L20: =IF(F20="","-","Yes")
C21: cross-check: WACC nominal after-tax (%) | D21: =IF(E21="","",IF(E21>=7,"Good",IF(E21>=4,"Medium","Bad"))) | E21: =IFERROR(INDEX(Scores!$L$6:$L$222,MATCH($C$4,Scores!$B$6:$B$222,0)),"") | F21: =IFERROR(IF(INDEX(Data_wide!$O$2:$O$218,MATCH($C$4,Data_wide!$B$2:$B$218,0))="","",INDEX(Data_wide!$O$2:$O$218,MATCH($C$4,Data_wide!$B$2:$B$218,0))),"") | G21: =IFERROR(IF(INDEX(Data_wide!$DB$2:$DB$218,MATCH($C$4,Data_wide!$B$2:$B$218,0))="","",INDEX(Data_wide!$DB$2:$DB$218,MATCH($C$4,Data_wide!$B$2:$B$218,0))),"") | H21: High = worse | I21: RE cost of capital | J21: Steffen et al. (2025) | K21: 64 | L21: =IF(F21="","-","Yes")
C22: cross-check: WACC evidence strength (0-3) | E22: =IFERROR(INDEX(Scores!$M$6:$M$222,MATCH($C$4,Scores!$B$6:$B$222,0)),"") | F22: =IFERROR(IF(INDEX(Data_wide!$P$2:$P$218,MATCH($C$4,Data_wide!$B$2:$B$218,0))="","",INDEX(Data_wide!$P$2:$P$218,MATCH($C$4,Data_wide!$B$2:$B$218,0))),"") | G22: =IFERROR(IF(INDEX(Data_wide!$DC$2:$DC$218,MATCH($C$4,Data_wide!$B$2:$B$218,0))="","",INDEX(Data_wide!$DC$2:$DC$218,MATCH($C$4,Data_wide!$B$2:$B$218,0))),"") | H22: Not evaluated | I22: Data quality, not performance | J22: IRENA / Steffen / IEA | K22: 84 | L22: =IF(F22="","-","Yes")
C23: cross-check: IEA Observatory available (0/1) | E23: =IFERROR(INDEX(Scores!$N$6:$N$222,MATCH($C$4,Scores!$B$6:$B$222,0)),"") | F23: =IFERROR(IF(INDEX(Data_wide!$Q$2:$Q$218,MATCH($C$4,Data_wide!$B$2:$B$218,0))="","",INDEX(Data_wide!$Q$2:$Q$218,MATCH($C$4,Data_wide!$B$2:$B$218,0))),"") | G23: =IFERROR(IF(INDEX(Data_wide!$DD$2:$DD$218,MATCH($C$4,Data_wide!$B$2:$B$218,0))="","",INDEX(Data_wide!$DD$2:$DD$218,MATCH($C$4,Data_wide!$B$2:$B$218,0))),"") | H23: Not evaluated | I23: Data quality, not performance | J23: IEA CofC Observatory | K23: 9 | L23: =IF(F23="","-","Yes")
C24: Official-private rate spread (pp) | D24: =IF(E24="","",IF(E24>=7,"Good",IF(E24>=4,"Medium","Bad"))) | E24: =IFERROR(INDEX(Scores!$O$6:$O$222,MATCH($C$4,Scores!$B$6:$B$222,0)),"") | F24: =IFERROR(IF(INDEX(Data_wide!$R$2:$R$218,MATCH($C$4,Data_wide!$B$2:$B$218,0))="","",INDEX(Data_wide!$R$2:$R$218,MATCH($C$4,Data_wide!$B$2:$B$218,0))),"") | G24: =IFERROR(IF(INDEX(Data_wide!$DE$2:$DE$218,MATCH($C$4,Data_wide!$B$2:$B$218,0))="","",INDEX(Data_wide!$DE$2:$DE$218,MATCH($C$4,Data_wide!$B$2:$B$218,0))),"") | H24: High = worse | I24: Value of a guarantee | J24: IDS DT.INR.PRVT less OFFT | K24: 88 | L24: =IF(F24="","-","Yes")
C25: Private creditor interest rate (%) | D25: =IF(E25="","",IF(E25>=7,"Good",IF(E25>=4,"Medium","Bad"))) | E25: =IFERROR(INDEX(Scores!$P$6:$P$222,MATCH($C$4,Scores!$B$6:$B$222,0)),"") | F25: =IFERROR(IF(INDEX(Data_wide!$S$2:$S$218,MATCH($C$4,Data_wide!$B$2:$B$218,0))="","",INDEX(Data_wide!$S$2:$S$218,MATCH($C$4,Data_wide!$B$2:$B$218,0))),"") | G25: =IFERROR(IF(INDEX(Data_wide!$DF$2:$DF$218,MATCH($C$4,Data_wide!$B$2:$B$218,0))="","",INDEX(Data_wide!$DF$2:$DF$218,MATCH($C$4,Data_wide!$B$2:$B$218,0))),"") | H25: High = worse | I25: Market cost of borrowing | J25: IDS DT.INR.PRVT | K25: 88 | L25: =IF(F25="","-","Yes")
C26: Avg maturity, new commitments (yrs) | D26: =IF(E26="","",IF(E26>=7,"Good",IF(E26>=4,"Medium","Bad"))) | E26: =IFERROR(INDEX(Scores!$Q$6:$Q$222,MATCH($C$4,Scores!$B$6:$B$222,0)),"") | F26: =IFERROR(IF(INDEX(Data_wide!$T$2:$T$218,MATCH($C$4,Data_wide!$B$2:$B$218,0))="","",INDEX(Data_wide!$T$2:$T$218,MATCH($C$4,Data_wide!$B$2:$B$218,0))),"") | G26: =IFERROR(IF(INDEX(Data_wide!$DG$2:$DG$218,MATCH($C$4,Data_wide!$B$2:$B$218,0))="","",INDEX(Data_wide!$DG$2:$DG$218,MATCH($C$4,Data_wide!$B$2:$B$218,0))),"") | H26: High = better | I26: Borrowing terms | J26: IDS DT.MAT.DPPG | K26: 118 | L26: =IF(F26="","-","Yes")
C27: Finance 2 — Who finances it, and what risk does the budget carry? | D27: =IFERROR(IF(E27>=7,"Good",IF(E27>=4,"Medium","Bad")),"") | E27: =IFERROR(ROUND(AVERAGE(E28:E33),1),"") | H27: Financing and risk | I27: Creditors, exposure and mobilisation | L27: =COUNT(F28:F33)&"/6"
B28: ● | C28: Mitigation finance received (% GDP) | D28: =IF(E28="","",IF(E28>=7,"High",IF(E28>=4,"Medium","Low"))) | E28: =IFERROR(INDEX(Scores!$R$6:$R$222,MATCH($C$4,Scores!$B$6:$B$222,0)),"") | F28: =IFERROR(IF(INDEX(Data_wide!$U$2:$U$218,MATCH($C$4,Data_wide!$B$2:$B$218,0))="","",INDEX(Data_wide!$U$2:$U$218,MATCH($C$4,Data_wide!$B$2:$B$218,0))),"") | G28: =IFERROR(IF(INDEX(Data_wide!$DH$2:$DH$218,MATCH($C$4,Data_wide!$B$2:$B$218,0))="","",INDEX(Data_wide!$DH$2:$DH$218,MATCH($C$4,Data_wide!$B$2:$B$218,0))),"") | H28: High = more inflows | I28: Climate finance inflows | J28: OECD CRDF (recipient) + WEO | K28: 133 | L28: =IF(F28="","-","Yes")
C29: Multilateral share of PPG debt (%) | D29: =IF(E29="","",IF(E29>=7,"High",IF(E29>=4,"Medium","Low"))) | E29: =IFERROR(INDEX(Scores!$S$6:$S$222,MATCH($C$4,Scores!$B$6:$B$222,0)),"") | F29: =IFERROR(IF(INDEX(Data_wide!$V$2:$V$218,MATCH($C$4,Data_wide!$B$2:$B$218,0))="","",INDEX(Data_wide!$V$2:$V$218,MATCH($C$4,Data_wide!$B$2:$B$218,0))),"") | G29: =IFERROR(IF(INDEX(Data_wide!$DI$2:$DI$218,MATCH($C$4,Data_wide!$B$2:$B$218,0))="","",INDEX(Data_wide!$DI$2:$DI$218,MATCH($C$4,Data_wide!$B$2:$B$218,0))),"") | H29: High = more concessional | I29: Creditor mix - triage | J29: IDS DT.DOD.MLAT/DPPG | K29: 120 | L29: =IF(F29="","-","Yes")
C30: Private creditor share of PPG debt (%) | D30: =IF(E30="","",IF(E30>=7,"High",IF(E30>=4,"Medium","Low"))) | E30: =IFERROR(INDEX(Scores!$T$6:$T$222,MATCH($C$4,Scores!$B$6:$B$222,0)),"") | F30: =IFERROR(IF(INDEX(Data_wide!$W$2:$W$218,MATCH($C$4,Data_wide!$B$2:$B$218,0))="","",INDEX(Data_wide!$W$2:$W$218,MATCH($C$4,Data_wide!$B$2:$B$218,0))),"") | G30: =IFERROR(IF(INDEX(Data_wide!$DJ$2:$DJ$218,MATCH($C$4,Data_wide!$B$2:$B$218,0))="","",INDEX(Data_wide!$DJ$2:$DJ$218,MATCH($C$4,Data_wide!$B$2:$B$218,0))),"") | H30: High = more market-financed | I30: Creditor mix - triage | J30: IDS DT.DOD.PRVT/DPPG | K30: 107 | L30: =IF(F30="","-","Yes")
C31: USD share of PPG debt (%) | D31: =IF(E31="","",IF(E31>=7,"Good",IF(E31>=4,"Medium","Bad"))) | E31: =IFERROR(INDEX(Scores!$U$6:$U$222,MATCH($C$4,Scores!$B$6:$B$222,0)),"") | F31: =IFERROR(IF(INDEX(Data_wide!$X$2:$X$218,MATCH($C$4,Data_wide!$B$2:$B$218,0))="","",INDEX(Data_wide!$X$2:$X$218,MATCH($C$4,Data_wide!$B$2:$B$218,0))),"") | G31: =IFERROR(IF(INDEX(Data_wide!$DK$2:$DK$218,MATCH($C$4,Data_wide!$B$2:$B$218,0))="","",INDEX(Data_wide!$DK$2:$DK$218,MATCH($C$4,Data_wide!$B$2:$B$218,0))),"") | H31: High = worse | I31: FX exposure | J31: IDS DT.CUR.USDL.ZS | K31: 120 | L31: =IF(F31="","-","Yes")
C32: PEFA PI-10.3, contingent liabilities (1-4) | D32: =IF(E32="","",IF(E32>=7,"Good",IF(E32>=4,"Medium","Bad"))) | E32: =IFERROR(INDEX(Scores!$V$6:$V$222,MATCH($C$4,Scores!$B$6:$B$222,0)),"") | F32: =IFERROR(IF(INDEX(Data_wide!$Y$2:$Y$218,MATCH($C$4,Data_wide!$B$2:$B$218,0))="","",INDEX(Data_wide!$Y$2:$Y$218,MATCH($C$4,Data_wide!$B$2:$B$218,0))),"") | G32: =IFERROR(IF(INDEX(Data_wide!$DL$2:$DL$218,MATCH($C$4,Data_wide!$B$2:$B$218,0))="","",INDEX(Data_wide!$DL$2:$DL$218,MATCH($C$4,Data_wide!$B$2:$B$218,0))),"") | H32: High = better | I32: Fiscal risk disclosure | J32: PEFA 2016 framework | K32: 82 | L32: =IF(F32="","-","Yes")
C33: PPI investment commitments (% GDP) | D33: =IF(E33="","",IF(E33>=7,"Good",IF(E33>=4,"Medium","Bad"))) | E33: =IFERROR(INDEX(Scores!$W$6:$W$222,MATCH($C$4,Scores!$B$6:$B$222,0)),"") | F33: =IFERROR(IF(INDEX(Data_wide!$Z$2:$Z$218,MATCH($C$4,Data_wide!$B$2:$B$218,0))="","",INDEX(Data_wide!$Z$2:$Z$218,MATCH($C$4,Data_wide!$B$2:$B$218,0))),"") | G33: =IFERROR(IF(INDEX(Data_wide!$DM$2:$DM$218,MATCH($C$4,Data_wide!$B$2:$B$218,0))="","",INDEX(Data_wide!$DM$2:$DM$218,MATCH($C$4,Data_wide!$B$2:$B$218,0))),"") | H33: High = better | I33: Private mobilisation | J33: World Bank PPI + WEO | K33: 93 | L33: =IF(F33="","-","Yes")
C34: Context 1 — How much fossil and climate money runs through the budget? | D34: =IFERROR(IF(E34>=7,"High",IF(E34>=4,"Medium","Low")),"") | E34: =IFERROR(ROUND(AVERAGE(E35:E39),1),"") | H34: Fossil and climate fiscal | I34: Energy taxes levied, subsidies paid, environment spending | L34: =COUNT(F35:F39)&"/5"
B35: ● | C35: Excise revenue (% of total revenue) | D35: =IF(E35="","",IF(E35>=7,"High",IF(E35>=4,"Medium","Low"))) | E35: =IFERROR(INDEX(Scores!$X$6:$X$222,MATCH($C$4,Scores!$B$6:$B$222,0)),"") | F35: =IFERROR(IF(INDEX(Data_wide!$AA$2:$AA$218,MATCH($C$4,Data_wide!$B$2:$B$218,0))="","",INDEX(Data_wide!$AA$2:$AA$218,MATCH($C$4,Data_wide!$B$2:$B$218,0))),"") | G35: =IFERROR(IF(INDEX(Data_wide!$DN$2:$DN$218,MATCH($C$4,Data_wide!$B$2:$B$218,0))="","",INDEX(Data_wide!$DN$2:$DN$218,MATCH($C$4,Data_wide!$B$2:$B$218,0))),"") | H35: High = more already taxed | I35: Energy tax already levied | J35: IMF WoRLD 2026 | K35: 163 | L35: =IF(F35="","-","Yes")
C36: Fossil fuel subsidies, total (% GDP) | D36: =IF(E36="","",IF(E36>=7,"High",IF(E36>=4,"Medium","Low"))) | E36: =IFERROR(INDEX(Scores!$Y$6:$Y$222,MATCH($C$4,Scores!$B$6:$B$222,0)),"") | F36: =IFERROR(IF(INDEX(Data_wide!$AB$2:$AB$218,MATCH($C$4,Data_wide!$B$2:$B$218,0))="","",INDEX(Data_wide!$AB$2:$AB$218,MATCH($C$4,Data_wide!$B$2:$B$218,0))),"") | G36: =IFERROR(IF(INDEX(Data_wide!$DO$2:$DO$218,MATCH($C$4,Data_wide!$B$2:$B$218,0))="","",INDEX(Data_wide!$DO$2:$DO$218,MATCH($C$4,Data_wide!$B$2:$B$218,0))),"") | H36: High = more forgone | I36: Revenue forgone at home | J36: IMF FFS (CPAT) + WEO | K36: 185 | L36: =IF(F36="","-","Yes")
C37: of which: explicit (% GDP) | D37: =IF(E37="","",IF(E37>=7,"High",IF(E37>=4,"Medium","Low"))) | E37: =IFERROR(INDEX(Scores!$Z$6:$Z$222,MATCH($C$4,Scores!$B$6:$B$222,0)),"") | F37: =IFERROR(IF(INDEX(Data_wide!$AC$2:$AC$218,MATCH($C$4,Data_wide!$B$2:$B$218,0))="","",INDEX(Data_wide!$AC$2:$AC$218,MATCH($C$4,Data_wide!$B$2:$B$218,0))),"") | G37: =IFERROR(IF(INDEX(Data_wide!$DP$2:$DP$218,MATCH($C$4,Data_wide!$B$2:$B$218,0))="","",INDEX(Data_wide!$DP$2:$DP$218,MATCH($C$4,Data_wide!$B$2:$B$218,0))),"") | H37: High = more forgone | I37: Revenue forgone at home | J37: IMF FFS (CPAT) + WEO | K37: 185 | L37: =IF(F37="","-","Yes")
C38: of which: implicit (% GDP) | D38: =IF(E38="","",IF(E38>=7,"High",IF(E38>=4,"Medium","Low"))) | E38: =IFERROR(INDEX(Scores!$AA$6:$AA$222,MATCH($C$4,Scores!$B$6:$B$222,0)),"") | F38: =IFERROR(IF(INDEX(Data_wide!$AD$2:$AD$218,MATCH($C$4,Data_wide!$B$2:$B$218,0))="","",INDEX(Data_wide!$AD$2:$AD$218,MATCH($C$4,Data_wide!$B$2:$B$218,0))),"") | G38: =IFERROR(IF(INDEX(Data_wide!$DQ$2:$DQ$218,MATCH($C$4,Data_wide!$B$2:$B$218,0))="","",INDEX(Data_wide!$DQ$2:$DQ$218,MATCH($C$4,Data_wide!$B$2:$B$218,0))),"") | H38: High = more forgone | I38: Revenue forgone at home | J38: IMF FFS (CPAT) + WEO | K38: 185 | L38: =IF(F38="","-","Yes")
C39: Environment protection (% of expenditure) | D39: =IF(E39="","",IF(E39>=7,"High",IF(E39>=4,"Medium","Low"))) | E39: =IFERROR(INDEX(Scores!$AB$6:$AB$222,MATCH($C$4,Scores!$B$6:$B$222,0)),"") | F39: =IFERROR(IF(INDEX(Data_wide!$AE$2:$AE$218,MATCH($C$4,Data_wide!$B$2:$B$218,0))="","",INDEX(Data_wide!$AE$2:$AE$218,MATCH($C$4,Data_wide!$B$2:$B$218,0))),"") | G39: =IFERROR(IF(INDEX(Data_wide!$DR$2:$DR$218,MATCH($C$4,Data_wide!$B$2:$B$218,0))="","",INDEX(Data_wide!$DR$2:$DR$218,MATCH($C$4,Data_wide!$B$2:$B$218,0))),"") | H39: High = more climate spending | I39: Climate-relevant spending | J39: World Bank BOOST COFOG 705 | K39: 150 | L39: =IF(F39="","-","Yes")
C40: Context 2 — Does the country sell fossil fuels, or buy them? | D40: =IFERROR(IF(E40>=7,"High",IF(E40>=4,"Medium","Low")),"") | E40: =IFERROR(ROUND(AVERAGE(E41:E48),1),"") | H40: Fossil trade and extraction | I40: Rents, exports, imports and dependency | L40: =COUNT(F41:F48)&"/8"
B41: ● | C41: Net fuel trade (% merch. trade) | D41: =IF(F41="","",IF(F41>20,"High Exporter",IF(F41>0,"Low Exporter",IF(F41>=-20,"Low Importer","High Importer")))) | E41: =IFERROR(INDEX(Scores!$AC$6:$AC$222,MATCH($C$4,Scores!$B$6:$B$222,0)),"") | F41: =IFERROR(IF(INDEX(Data_wide!$AF$2:$AF$218,MATCH($C$4,Data_wide!$B$2:$B$218,0))="","",INDEX(Data_wide!$AF$2:$AF$218,MATCH($C$4,Data_wide!$B$2:$B$218,0))),"") | G41: =IFERROR(IF(INDEX(Data_wide!$DS$2:$DS$218,MATCH($C$4,Data_wide!$B$2:$B$218,0))="","",INDEX(Data_wide!$DS$2:$DS$218,MATCH($C$4,Data_wide!$B$2:$B$218,0))),"") | H41: + = exporter, - = importer | I41: Importer / exporter position | J41: WDI TX less TM.VAL.FUEL | K41: 197 | L41: =IF(F41="","-","Yes")
C42: of which: fuel exports (% merch. exports) | D42: =IF(E42="","",IF(E42>=7,"High",IF(E42>=4,"Medium","Low"))) | E42: =IFERROR(INDEX(Scores!$AD$6:$AD$222,MATCH($C$4,Scores!$B$6:$B$222,0)),"") | F42: =IFERROR(IF(INDEX(Data_wide!$AG$2:$AG$218,MATCH($C$4,Data_wide!$B$2:$B$218,0))="","",INDEX(Data_wide!$AG$2:$AG$218,MATCH($C$4,Data_wide!$B$2:$B$218,0))),"") | G42: =IFERROR(IF(INDEX(Data_wide!$DT$2:$DT$218,MATCH($C$4,Data_wide!$B$2:$B$218,0))="","",INDEX(Data_wide!$DT$2:$DT$218,MATCH($C$4,Data_wide!$B$2:$B$218,0))),"") | H42: High = more export-dependent | I42: Export dependence | J42: WDI TX.VAL.FUEL.ZS.UN | K42: 197 | L42: =IF(F42="","-","Yes")
C43: of which: fuel imports (% merch. imports) | D43: =IF(E43="","",IF(E43>=7,"High",IF(E43>=4,"Medium","Low"))) | E43: =IFERROR(INDEX(Scores!$AE$6:$AE$222,MATCH($C$4,Scores!$B$6:$B$222,0)),"") | F43: =IFERROR(IF(INDEX(Data_wide!$AH$2:$AH$218,MATCH($C$4,Data_wide!$B$2:$B$218,0))="","",INDEX(Data_wide!$AH$2:$AH$218,MATCH($C$4,Data_wide!$B$2:$B$218,0))),"") | G43: =IFERROR(IF(INDEX(Data_wide!$DU$2:$DU$218,MATCH($C$4,Data_wide!$B$2:$B$218,0))="","",INDEX(Data_wide!$DU$2:$DU$218,MATCH($C$4,Data_wide!$B$2:$B$218,0))),"") | H43: High = more relief available | I43: Import bill relief available | J43: WDI TM.VAL.FUEL.ZS.UN | K43: 198 | L43: =IF(F43="","-","Yes")
...

Sheet Data_wide
A1: iso3 | B1: country | C1: region | D1: income | E1: is_ccdr | F1: interest_to_revenue_pct | G1: interest_pct_gdp | H1: gross_debt_pct_gdp | I1: tax_revenue_pct_gdp | J1: capex_execution_rate_pct | K1: pefa_pi11_pim_score | L1: pefa_pi122_asset_monitoring | M1: climate_pfm_diagnostic_on_record | N1: wacc_solar_real_aftertax_pct | O1: wacc_steffen_nominal_aftertax_pct | P1: wacc_n_sources | Q1: wacc_iea_observatory_available | R1: ids_official_private_rate_spread_pp | S1: ids_private_creditor_rate_pct | T1: ids_avg_maturity_years | U1: mitigation_finance_received_pct_gdp | V1: ids_multilateral_share_pct | W1: ids_private_creditor_share_pct | X1: ids_usd_share_ppg_debt_pct | Y1: pefa_pi103_contingent_liabilities | Z1: ppi_commitments_pct_gdp | AA1: excise_revenue_pct_of_revenue | AB1: ff_subsidy_total_pct_gdp | AC1: ff_subsidy_explicit_pct_gdp | AD1: ff_subsidy_implicit_pct_gdp | AE1: env_protection_pct_of_expenditure | AF1: net_fuel_trade_pct_merch | AG1: fuel_exports_pct_merch | AH1: fuel_imports_pct_merch | AI1: energy_import_dep_pct | AJ1: fossil_rents_total_pct_gdp | AK1: oil_rents_pct_gdp | AL1: gas_rents_pct_gdp | AM1: coal_rents_pct_gdp | AN1: other_fossil_gen_share_pct | AO1: renewable_share_electricity_pct | AP1: re_share_change_pp | AQ1: re_capacity_growth_pct | AR1: inn_total_inv_2030_pct_gdp | AS1: inn_incr_inv_2030_pct_gdp | AT1: inn_incr_inv_gen_2030_pct_gdp | AU1: inn_incr_inv_grid_2030_pct_gdp | AV1: inn_incr_inv_trn_2030_pct_gdp | AW1: inn_incr_inv_bld_2030_pct_gdp | AX1: inn_incr_inv_ind_2030_pct_gdp | AY1: inn_incr_inv_fuel_2030_pct_gdp | AZ1: inn_incr_inv_afolu_2030_pct_gdp | BA1: inn_incr_cost_a_2030_pct_gdp | BB1: inn_incr_cost_b_2030_pct_gdp | BC1: inn_incr_cost_c_2030_pct_gdp | BD1: inn_cost_per_t_b_2030_usd | BE1: inn_coc_penalty_2030_pct_gdp | BF1: inn_pima_adj_inv_2030_pct_gdp | BG1: nmim_nz_inv_2030_pct_gdp | BH1: nmim_typ1_2030_pct_gdp | BI1: nmim_typ2_2030_pct_gdp | BJ1: nmim_typ3_2030_pct_gdp | BK1: nmim_typ4_2030_pct_gdp | BL1: nmim_typ5_2030_pct_gdp | BM1: nmim_budget_need_2030_pct_gdp | BN1: nmim_private_share_2030_pct | BO1: nmim_incr_inv_2030_pct_gdp | BP1: nmim_incr_inv_2050_pct_gdp | BQ1: nmim_pv_incr_cost_b_pct_gdp | BR1: price_diesel_usd_litre | BS1: price_gasoline_usd_litre | BT1: price_electricity_residential_usd_kwh | BU1: price_electricity_industry_usd_kwh | BV1: price_gas_residential_usd_gj | BW1: price_gas_industry_usd_gj | BX1: price_gas_power_usd_gj | BY1: price_coal_residential_usd_gj | BZ1: price_coal_industry_usd_gj | CA1: price_coal_power_usd_gj | CB1: power_market_structure | CC1: independent_regulator | CD1: generation_unbundled | CE1: rise_renewable_energy_score | CF1: rise_level_playing_field_score | CG1: rise_ee_financing_mechanisms_score | CH1: revenue_pct_gdp | CI1: primary_balance_pct_gdp | CJ1: current_account_pct_gdp | CK1: gross_capital_formation_pct_gdp | CL1: real_gdp_growth_5y_avg_pct | CM1: int_budget_need_2030_pct_gdp | CN1: int_pricing_revenue_2030_pct_gdp | CO1: int_financing_gap_2030_pct_gdp | CP1: int_gdp_dev_2050_pct | CQ1: int_debt_2050_pct_gdp | CR1: int_dsf_risk_code | CS1: interest_to_revenue_pct__year | CT1: interest_pct_gdp__year | CU1: gross_debt_pct_gdp__year | CV1: tax_revenue_pct_gdp__year | CW1: capex_execution_rate_pct__year | CX1: pefa_pi11_pim_score__year | CY1: pefa_pi122_asset_monitoring__year | CZ1: climate_pfm_diagnostic_on_record__year | DA1: wacc_solar_real_aftertax_pct__year | DB1: wacc_steffen_nominal_aftertax_pct__year | DC1: wacc_n_sources__year | DD1: wacc_iea_observatory_available__year | DE1: ids_official_private_rate_spread_pp__year | DF1: ids_private_creditor_rate_pct__year | DG1: ids_avg_maturity_years__year | DH1: mitigation_finance_received_pct_gdp__year | DI1: ids_multilateral_share_pct__year | DJ1: ids_private_creditor_share_pct__year | DK1: ids_usd_share_ppg_debt_pct__year | DL1: pefa_pi103_contingent_liabilities__year | DM1: ppi_commitments_pct_gdp__year | DN1: excise_revenue_pct_of_revenue__year | DO1: ff_subsidy_total_pct_gdp__year | DP1: ff_subsidy_explicit_pct_gdp__year | DQ1: ff_subsidy_implicit_pct_gdp__year | DR1: env_protection_pct_of_expenditure__year | DS1: net_fuel_trade_pct_merch__year | DT1: fuel_exports_pct_merch__year | DU1: fuel_imports_pct_merch__year | DV1: energy_import_dep_pct__year | DW1: fossil_rents_total_pct_gdp__year | DX1: oil_rents_pct_gdp__year | DY1: gas_rents_pct_gdp__year | DZ1: coal_rents_pct_gdp__year | EA1: other_fossil_gen_share_pct__year | EB1: renewable_share_electricity_pct__year | EC1: re_share_change_pp__year | ED1: re_capacity_growth_pct__year | EE1: inn_total_inv_2030_pct_gdp__year | EF1: inn_incr_inv_2030_pct_gdp__year | EG1: inn_incr_inv_gen_2030_pct_gdp__year | EH1: inn_incr_inv_grid_2030_pct_gdp__year | EI1: inn_incr_inv_trn_2030_pct_gdp__year | EJ1: inn_incr_inv_bld_2030_pct_gdp__year | EK1: inn_incr_inv_ind_2030_pct_gdp__year | EL1: inn_incr_inv_fuel_2030_pct_gdp__year | EM1: inn_incr_inv_afolu_2030_pct_gdp__year | EN1: inn_incr_cost_a_2030_pct_gdp__year | EO1: inn_incr_cost_b_2030_pct_gdp__year | EP1: inn_incr_cost_c_2030_pct_gdp__year | EQ1: inn_cost_per_t_b_2030_usd__year | ER1: inn_coc_penalty_2030_pct_gdp__year | ES1: inn_pima_adj_inv_2030_pct_gdp__year | ET1: nmim_nz_inv_2030_pct_gdp__year | EU1: nmim_typ1_2030_pct_gdp__year | EV1: nmim_typ2_2030_pct_gdp__year | EW1: nmim_typ3_2030_pct_gdp__year | EX1: nmim_typ4_2030_pct_gdp__year | EY1: nmim_typ5_2030_pct_gdp__year | EZ1: nmim_budget_need_2030_pct_gdp__year | FA1: nmim_private_share_2030_pct__year | FB1: nmim_incr_inv_2030_pct_gdp__year | FC1: nmim_incr_inv_2050_pct_gdp__year | FD1: nmim_pv_incr_cost_b_pct_gdp__year | FE1: price_diesel_usd_litre__year | FF1: price_gasoline_usd_litre__year | FG1: price_electricity_residential_usd_kwh__year | FH1: price_electricity_industry_usd_kwh__year | FI1: price_gas_residential_usd_gj__year | FJ1: price_gas_industry_usd_gj__year | FK1: price_gas_power_usd_gj__year | FL1: price_coal_residential_usd_gj__year | FM1: price_coal_industry_usd_gj__year | FN1: price_coal_power_usd_gj__year | FO1: power_market_structure__year | FP1: independent_regulator__year | FQ1: generation_unbundled__year | FR1: rise_renewable_energy_score__year | FS1: rise_level_playing_field_score__year | FT1: rise_ee_financing_mechanisms_score__year | FU1: revenue_pct_gdp__year | FV1: primary_balance_pct_gdp__year | FW1: current_account_pct_gdp__year | FX1: gross_capital_formation_pct_gdp__year | FY1: real_gdp_growth_5y_avg_pct__year | FZ1: int_budget_need_2030_pct_gdp__year | GA1: int_pricing_revenue_2030_pct_gdp__year | GB1: int_financing_gap_2030_pct_gdp__year | GC1: int_gdp_dev_2050_pct__year | GD1: int_debt_2050_pct_gdp__year | GE1: int_dsf_risk_code__year
A2: AFG | B2: Afghanistan | C2: Middle East & North Africa | D2: Low income | E2: FALSE | F2: 0.241 | G2: 0.046 | H2: 8.912 | I2: 10.867 | J2: 94.541 | K2: 1.5 | L2: 1 | M2: 0 | T2: 39.833 | U2: 0.056 | V2: 45.043 | X2: 72.025 | Y2: 1 | AA2: 0 | AB2: 9.3 | AC2: 1.383 | AD2: 7.917 | AE2: 0.436 | AF2: -14.644 | AG2: 8.051 | AH2: 22.695 | AJ2: 0.039 | AK2: 0.018 | AL2: 0.002 | AM2: 0.019 | AN2: 10.101 | AO2: 93.86 | AP2: 0.271 | AQ2: 1.923 | AR2: 8.8928901 | AS2: 2.1342936 | AT2: 0.4956232 | AU2: 0.33985591 | AV2: 0.31154014 | AW2: 0.23198169 | AX2: 0.096766924 | AY2: 0.12266699 | AZ2: 0.53585877 | BA2: 0.091178249 | BB2: 0.013370869 | BC2: -0.067820175 | BD2: 10.491672 | BE2: 0.32419742 | BF2: 10.850705 | BG2: 4.3584008 | BH2: 1.2832666 | BI2: 0.16395742 | BJ2: 0.28310723 | BK2: 2.0059837 | BL2: 0.62208593 | BM2: 1.8850616 | BN2: 52.986906 | BO2: 3.5820085 | BP2: 2.9387382 | BQ2: -13.376709 | BT2: 0.059 | BU2: 0.029 | BV2: 15.829 | BW2: 6.449 | BX2: 5.125 | BY2: 23.086 | BZ2: 7.124 | CA2: 4.833 | CB2: 3 | CC2: 0 | CD2: 0 | CE2: 12.116 | CF2: 0 | CG2: 33.333 | CH2: 19.121 | CI2: -0.502 | CJ2: -39.612 | CK2: 10.895 | CL2: -3.799 | CM2: 1.577 | CN2: 0.176 | CO2: 1.4 | CP2: 1.957 | CQ2: 27.67 | CR2: 1 | CS2: 2024 | CT2: 2024 | CU2: 2024 | CV2: 2024 | CW2: 2019 | CX2: 2018 | CY2: 2018 | CZ2: 2022 | DG2: 2019 | DH2: 2024 | DI2: 2024 | DK2: 2024 | DL2: 2018 | DN2: 2024 | DO2: 2024 | DP2: 2024 | DQ2: 2024 | DR2: 2020 | DS2: 2019 | DT2: 2019 | DU2: 2019 | DW2: 2021 | DX2: 2021 | DY2: 2021 | DZ2: 2021 | EA2: 2024 | EB2: 2024 | EC2: 2024 | ED2: 2024 | EE2: 2030 | EF2: 2030 | EG2: 2030 | EH2: 2030 | EI2: 2030 | EJ2: 2030 | EK2: 2030 | EL2: 2030 | EM2: 2030 | EN2: 2030 | EO2: 2030 | EP2: 2030 | EQ2: 2030 | ER2: 2030 | ES2: 2030 | ET2: 2030 | EU2: 2030 | EV2: 2030 | EW2: 2030 | EX2: 2030 | EY2: 2030 | EZ2: 2030 | FA2: 2030 | FB2: 2030 | FC2: 2050 | FD2: 2025-2050 | FG2: 2024 | FH2: 2024 | FI2: 2024 | FJ2: 2024 | FK2: 2024 | FL2: 2024 | FM2: 2024 | FN2: 2024 | FO2: 2013 | FP2: 2013 | FQ2: 2013 | FR2: 2023 | FS2: 2023 | FT2: 2023 | FU2: 2024 | FV2: 2024 | FW2: 2024 | FX2: 2024 | FY2: 2020-2024 avg | FZ2: 2030 | GA2: 2030 | GB2: 2030 | GC2: 2050 | GD2: 2050 | GE2: 2034
A3: ALB | B3: Albania | C3: Europe & Central Asia | D3: Upper middle income | E3: TRUE | F3: 7.667 | G3: 2.163 | H3: 54.505 | I3: 19.751 | J3: 100.792 | K3: 3 | L3: 2 | M3: 0 | R3: 1.982 | S3: 5.9 | T3: 18.669 | U3: 1.349 | V3: 46.852 | W3: 35.24 | X3: 34.055 | Y3: 2 | Z3: 0.23 | AA3: 9.063 | AB3: 1.686 | AC3: 0 | AD3: 1.686 | AE3: 1.095 | AF3: -5.325 | AG3: 3.258 | AH3: 8.583 | AI3: 22.702 | AJ3: 1.123 | AK3: 1.042 | AL3: 0.049 | AM3: 0.032 | AN3: 0 | AO3: 100 | AP3: -0.004 | AQ3: 20.147 | AR3: 4.7694382 | AS3: 1.1446652 | AT3: 0.37399992 | AU3: 0.25645709 | AV3: 0.13935624 | AW3: 0.11575342 | AX3: 0.051332012 | AY3: 0.056244476 | AZ3: 0.15152201 | BA3: 0.01498067 | BB3: -0.027000274 | BC3: -0.11103268 | BD3: -53.218321 | BE3: 0.1749206 | BF3: 5.3075286 | BG3: 1.6889921 | BH3: 0.14420362 | BI3: 0.24595084 | BJ3: 0.34637119 | BK3: 0.35033389 | BL3: 0.60213252 | BM3: 0.24930378 | BN3: 70.677504 | BO3: 0.97040461 | BP3: 0.91643395 | BQ3: -0.91440094 | BR3: 1.714 | BS3: 1.889 | BT3: 0.123 | BU3: 0.138 | BV3: 13.93 | BW3: 6.853 | BX3: 6.975 | BY3: 11.7 | BZ3: 5.333 | CA3: 4.713 | CB3: 3 | CC3: 1 | CD3: 1 | CE3: 51.011 | CF3: 40 | CG3: 16.667 | CH3: 28.212 | CI3: 1.438 | CJ3: -2.425 | CK3: 25.51 | CL3: 3.709 | CM3: 0.161 | CN3: 0 | CO3: 0.161 | CP3: 4.369 | CQ3: 54.43 | CS3: 2024 | CT3: 2024 | CU3: 2024 | CV3: 2024 | CW3: 2022 | CX3: 2025 | CY3: 2025 | CZ3: 2022 | DE3: 2024 | DF3: 2023 | DG3: 2024 | DH3: 2024 | DI3: 2024 | DJ3: 2024 | DK3: 2024 | DL3: 2025 | DM3: 2020-2024 avg | DN3: 2024 | DO3: 2024 | DP3: 2024 | DQ3: 2024 | DR3: 2022 | DS3: 2024 | DT3: 2024 | DU3: 2024 | DV3: 2023 | DW3: 2021 | DX3: 2021 | DY3: 2021 | DZ3: 2021 | EA3: 2025 | EB3: 2024 | EC3: 2025 | ED3: 2024 | EE3: 2030 | EF3: 2030 | EG3: 2030 | EH3: 2030 | EI3: 2030 | EJ3: 2030 | EK3: 2030 | EL3: 2030 | EM3: 2030 | EN3: 2030 | EO3: 2030 | EP3: 2030 | EQ3: 2030 | ER3: 2030 | ES3: 2030 | ET3: 2030 | EU3: 2030 | EV3: 2030 | EW3: 2030 | EX3: 2030 | EY3: 2030 | EZ3: 2030 | FA3: 2030 | FB3: 2030 | FC3: 2050 | FD3: 2025-2050 | FE3: 2024 | FF3: 2024 | FG3: 2024 | FH3: 2024 | FI3: 2024 | FJ3: 2024 | FK3: 2024 | FL3: 2024 | FM3: 2024 | FN3: 2024 | FO3: 2013 | FP3: 2013 | FQ3: 2013 | FR3: 2023 | FS3: 2023 | FT3: 2023 | FU3: 2024 | FV3: 2024 | FW3: 2024 | FX3: 2024 | FY3: 2020-2024 avg | FZ3: 2030 | GA3: 2030 | GB3: 2030 | GC3: 2050 | GD3: 2050
A4: DZA | B4: Algeria | C4: Middle East & North Africa | D4: Upper middle income | E4: FALSE | F4: 4.884 | G4: 1.123 | H4: 48.069 | I4: 9.35 | M4: 0 | N4: 11 | P4: 1 | T4: 19.583 | U4: 0.014 | V4: 84.213 | W4: 0 | X4: 0 | Z4: 0.005 | AA4: 1.195 | AB4: 19.195 | AC4: 9.347 | AD4: 9.848 | AF4: 91.904 | AG4: 96.112 | AH4: 4.208 | AI4: -129.337 | AJ4: 22.458 | AK4: 14.462 | AL4: 7.996 | AM4: 0 | AN4: 0.342 | AO4: 2.422 | AP4: 0.12 | AQ4: 0 | AR4: 5.7794066 | AS4: 1.3870576 | AT4: 0.34751635 | AU4: 0.23829692 | AV4: 0.19273818 | AW4: 0.19837275 | AX4: 0.066861937 | AY4: 0.10448006 | AZ4: 0.23879139 | BA4: 0.11251862 | BB4: 0.028888981 | BC4: -0.027798306 | BD4: 31.259575 | BE4: 0.34845683 | BF4: 6.6344421 | BG4: 4.0442591 | BH4: 0.9160609 | BI4: 0.39948238 | BJ4: 0.40722623 | BK4: 1.6451074 | BL4: 0.67638209 | BM4: 1.4095931 | BN4: 55.26806 | BO4: 2.9572435 | BP4: 2.8240353 | BQ4: 1.7147137 | BR4: 0.182 | BS4: 0.288 | BT4: 0.036 | BU4: 0.013 | BV4: 0.796 | BW4: 0.99 | BX4: 1.262 | BY4: 14.762 | BZ4: 7.281 | CA4: 5.787 | CB4: 2 | CC4: 1 | CD4: 1 | CE4: 19.339 | CF4: 0 | CG4: 50 | CH4: 22.995 | CI4: -12.668 | CJ4: -1.073 | CK4: 41.124 | CL4: 2.04 | CM4: 1.026 | CN4: 0.134 | CO4: 0.892 | CP4: -14.69 | CQ4: 85.27 | CS4: 2024 | CT4: 2024 | CU4: 2024 | CV4: 2024 | CZ4: 2022 | DA4: 2021 | DC4: 2021-2024 | DG4: 2016 | DH4: 2024 | DI4: 2024 | DJ4: 2023 | DK4: 2024 | DM4: 2020-2024 avg | DN4: 2024 | DO4: 2024 | DP4: 2024 | DQ4: 2024 | DS4: 2017 | DT4: 2017 | DU4: 2017 | DV4: 2023 | DW4: 2021 | DX4: 2021 | DY4: 2021 | DZ4: 2021 | EA4: 2024 | EB4: 2024 | EC4: 2024 | ED4: 2024 | EE4: 2030 | EF4: 2030 | EG4: 2030 | EH4: 2030 | EI4: 2030 | EJ4: 2030 | EK4: 2030 | EL4: 2030 | EM4: 2030 | EN4: 2030 | EO4: 2030 | EP4: 2030 | EQ4: 2030 | ER4: 2030 | ES4: 2030 | ET4: 2030 | EU4: 2030 | EV4: 2030 | EW4: 2030 | EX4: 2030 | EY4: 2030 | EZ4: 2030 | FA4: 2030 | FB4: 2030 | FC4: 2050 | FD4: 2025-2050 | FE4: 2024 | FF4: 2024 | FG4: 2024 | FH4: 2024 | FI4: 2024 | FJ4: 2024 | FK4: 2024 | FL4: 2024 | FM4: 2024 | FN4: 2024 | FO4: 2013 | FP4: 2013 | FQ4: 2013 | FR4: 2023 | FS4: 2023 | FT4: 2023 | FU4: 2024 | FV4: 2024 | FW4: 2024 | FX4: 2024 | FY4: 2020-2024 avg | FZ4: 2030 | GA4: 2030 | GB4: 2030 | GC4: 2050 | GD4: 2050
A5: ASM | B5: American Samoa | C5: East Asia & Pacific | D5: High income | E5: FALSE | M5: 0 | AJ5: 0 | AK5: 0 | AL5: 0 | AM5: 0 | AN5: 94.444 | AP5: 5.556 | AQ5: 0 | CZ5: 2022 | DW5: 2021 | DX5: 2021 | DY5: 2021 | DZ5: 2021 | EA5: 2024 | EC5: 2024 | ED5: 2024
A6: AND | B6: Andorra | C6: Europe & Central Asia | D6: High income | E6: FALSE | F6: 1.325 | G6: 0.529 | H6: 32.889 | I6: 15.812 | M6: 0 | AF6: -8.638 | AG6: 0.01 | AH6: 8.648 | AR6: 3.5281571 | AS6: 1.3406997 | AT6: 0.46338539 | AU6: 0.31774998 | AV6: 0.19469002 | AW6: 0.15186413 | AX6: 0.087731103 | AY6: 0.10526126 | AZ6: 0.020017811 | BA6: -0.014405898 | BB6: -0.0094267006 | BC6: -0.12780851 | BD6: -21.668497 | BE6: -0.013103152 | BF6: 3.6863159 | CB6: 1 | CC6: 0 | CD6: 0 | CH6: 39.91 | CI6: 3.312 | CJ6: 15.941 | CL6: 2.62 | CS6: 2024 | CT6: 2024 | CU6: 2024 | CV6: 2024 | CZ6: 2022 | DS6: 2023 | DT6: 2023 | DU6: 2023 | EE6: 2030 | EF6: 2030 | EG6: 2030 | EH6: 2030 | EI6: 2030 | EJ6: 2030 | EK6: 2030 | EL6: 2030 | EM6: 2030 | EN6: 2030 | EO6: 2030 | EP6: 2030 | EQ6: 2030 | ER6: 2030 | ES6: 2030 | FO6: 2013 | FP6: 2013 | FQ6: 2013 | FU6: 2024 | FV6: 2024 | FW6: 2024 | FY6: 2020-2024 avg
A7: AGO | B7: Angola | C7: Sub-Saharan Africa | D7: Lower middle income | E7: TRUE | F7: 25.816 | G7: 4.593 | H7: 57.107 | I7: 5.608 | J7: 113.01 | M7: 0 | R7: -1.088 | S7: 4.681 | T7: 11.087 | U7: 0.333 | V7: 13.443 | W7: 77.629 | X7: 86.499 | Z7: 0.438 | AB7: 5.948 | AC7: 3.212 | AD7: 2.737 | AE7: 0.077 | AF7: 73.589 | AG7: 94.135 | AH7: 20.546 | AI7: -353.972 | AJ7: 29.286 | AK7: 28.274 | AL7: 1.012 | AM7: 0 | AN7: 17.319 | AO7: 72.85 | AP7: -0.331 | AQ7: 1.222 | AR7: 5.3038794 | AS7: 1.272931 | AT7: 0.30159661 | AU7: 0.2068091 | AV7: 0.1507162 | AW7: 0.13412771 | AX7: 0.048323464 | AY7: 0.067789568 | AZ7: 0.36356838 | BA7: 0.072825439 | BB7: 0.026139022 | BC7: -0.028290735 | BD7: 31.081943 | BE7: 0.19452674 | BF7: 6.0885629 | BG7: 3.4866256 | BH7: 1.6148338 | BI7: 0.13878981 | BJ7: 0.17937386 | BK7: 1.228093 | BL7: 0.32553508 | BM7: 1.9832617 | BN7: 39.137385 | BO7: 2.8726504 | BP7: 2.0180929 | BQ7: 14.62693 | BR7: 0.185 | BS7: 0.303 | BT7: 0.012 | BU7: 0.01 | BV7: 12.161 | BW7: 6.696 | BX7: 6.034 | BY7: 13.997 | BZ7: 7.187 | CA7: 5.66 | CB7: 1 | CC7: 1 | CD7: 0 | CE7: 28.259 | CF7: 0 | CG7: 0 | CH7: 17.791 | CI7: 3.401 | CJ7: 5.277 | CK7: 10.638 | CL7: 1.711 | CM7: 1.751 | CN7: 0.006 | CO7: 1.745 | CP7: -20.53 | CQ7: 82.13 | CR7: 3 | CS7: 2024 | CT7: 2024 | CU7: 2024 | CV7: 2024 | CW7: 2022 | CZ7: 2022 | DE7: 2024 | DF7: 2024 | DG7: 2024 | DH7: 2024 | DI7: 2024 | DJ7: 2024 | DK7: 2024 | DM7: 2020-2024 avg | DO7: 2024 | DP7: 2024 | DQ7: 2024 | DR7: 2022 | DS7: 2024 | DT7: 2024 | DU7: 2024 | DV7: 2022 | DW7: 2021 | DX7: 2021 | DY7: 2021 | DZ7: 2021 | EA7: 2024 | EB7: 2024 | EC7: 2024 | ED7: 2024 | EE7: 2030 | EF7: 2030 | EG7: 2030 | EH7: 2030 | EI7: 2030 | EJ7: 2030 | EK7: 2030 | EL7: 2030 | EM7: 2030 | EN7: 2030 | EO7: 2030 | EP7: 2030 | EQ7: 2030 | ER7: 2030 | ES7: 2030 | ET7: 2030 | EU7: 2030 | EV7: 2030 | EW7: 2030 | EX7: 2030 | EY7: 2030 | EZ7: 2030 | FA7: 2030 | FB7: 2030 | FC7: 2050 | FD7: 2025-2050 | FE7: 2024 | FF7: 2024 | FG7: 2024 | FH7: 2024 | FI7: 2024 | FJ7: 2024 | FK7: 2024 | FL7: 2024 | FM7: 2024 | FN7: 2024 | FO7: 2013 | FP7: 2013 | FQ7: 2013 | FR7: 2023 | FS7: 2023 | FT7: 2023 | FU7: 2024 | FV7: 2024 | FW7: 2024 | FX7: 2024 | FY7: 2020-2024 avg | FZ7: 2030 | GA7: 2030 | GB7: 2030 | GC7: 2050 | GD7: 2050 | GE7: 2034
A8: ATG | B8: Antigua and Barbuda | C8: Latin America & Caribbean | D8: High income | E8: FALSE | F8: 10.827 | G8: 2.368 | H8: 71.773 | I8: 15.581 | M8: 0 | AB8: 2.169 | AC8: 0.35 | AD8: 1.818 | AF8: -0.678 | AG8: 0 | AH8: 0.678 | AJ8: 0 | AK8: 0 | AL8: 0 | AM8: 0 | AN8: 91.892 | AO8: 21.024 | AP8: 2.552 | AQ8: 0 | AR8: 4.6231267 | AS8: 1.1095504 | AT8: 0.29273368 | AU8: 0.20073167 | AV8: 0.22294024 | AW8: 0.072253597 | AX8: 0.11787678 | AY8: 0.094842268 | AZ8: 0.10817217 | BA8: -0.041850375 | BB8: -0.081747733 | BC8: -0.10183365 | BD8: -97.494993 | BE8: 0.16623899 | BF8: 5.3070961 | BG8: 4.1327783 | BH8: 0.099574618 | BI8: 1.0787503 | BJ8: 0.7289363 | BK8: 0.93707767 | BL8: 1.2884395 | BM8: 0.38069792 | BN8: 64.686028 | BO8: 3.289848 | BP8: 3.3102898 | BQ8: 0.17714738 | BR8: 1.206 | BS8: 1.56 | BT8: 0.449 | BU8: 0.822 | BV8: 24.233 | BW8: 12.771 | BX8: 11.447 | BY8: 14.266 | BZ8: 7.124 | CA8: 5.575 | CB8: 2 | CC8: 0 | CD8: 0 | CH8: 21.872 | CI8: 4.014 | CJ8: -7.457 | CK8: 33.398 | CL8: 0.842 | CM8: 0.299 | CN8: 1.837 | CO8: -1.538 | CP8: 18.43 | CQ8: 54.07 | CS8: 2024 | CT8: 2024 | CU8: 2024 | CV8: 2024 | CZ8: 2022 | DO8: 2024 | DP8: 2024 | DQ8: 2024 | DS8: 2024 | DT8: 2024 | DU8: 2024 | DW8: 2021 | DX8: 2021 | DY8: 2021 | DZ8: 2021 | EA8: 2024 | EB8: 2024 | EC8: 2024 | ED8: 2024 | EE8: 2030 | EF8: 2030 | EG8: 2030 | EH8: 2030 | EI8: 2030 | EJ8: 2030 | EK8: 2030 | EL8: 2030 | EM8: 2030 | EN8: 2030 | EO8: 2030 | EP8: 2030 | EQ8: 2030 | ER8: 2030 | ES8: 2030 | ET8: 2030 | EU8: 2030 | EV8: 2030 | EW8: 2030 | EX8: 2030 | EY8: 2030 | EZ8: 2030 | FA8: 2030 | FB8: 2030 | FC8: 2050 | FD8: 2025-2050 | FE8: 2024 | FF8: 2024 | FG8: 2024 | FH8: 2024 | FI8: 2024 | FJ8: 2024 | FK8: 2024 | FL8: 2024 | FM8: 2024 | FN8: 2024 | FO8: 2013 | FP8: 2013 | FQ8: 2013 | FU8: 2024 | FV8: 2024 | FW8: 2024 | FX8: 2024 | FY8: 2020-2024 avg | FZ8: 2030 | GA8: 2030 | GB8: 2030 | GC8: 2050 | GD8: 2050
A9: ARG | B9: Argentina | C9: Latin America & Caribbean | D9: Upper middle income | E9: TRUE | F9: 5.445 | G9: 1.714 | H9: 84.653 | I9: 22.823 | J9: 97.306 | K9: 1.5 | L9: 2 | M9: 0 | N9: 13.8 | O9: 9.3 | P9: 2 | R9: -2.971 | S9: 3.721 | T9: 12.617 | U9: 0.336 | V9: 31.558 | W9: 62.387 | X9: 92.809 | Y9: 3 | Z9: 0.076 | AA9: 3.4 | AB9: 6.221 | AC9: 2.164 | AD9: 4.058 | AE9: 0.274 | AF9: 2.551 | AG9: 8.77 | AH9: 6.219 | AI9: 0.416 | AJ9: 1.933 | AK9: 1.544 | AL9: 0.389 | AM9: 0 | AN9: 3.866 | AO9: 37.229 | AP9: 0.2 | AQ9: 6.841 | AR9: 4.7471991 | AS9: 1.1393278 | AT9: 0.31180059 | AU9: 0.21380612 | AV9: 0.1367259 | AW9: 0.12584165 | AX9: 0.055652711 | AY9: 0.069348591 | AZ9: 0.22615223 | BA9: 0.078604395 | BB9: 0.014930971 | BC9: -0.037927559 | BD9: 21.442011 | BE9: 0.26530593 | BF9: 5.7923189 | BG9: 2.6957288 | BH9: 0.42720891 | BI9: 0.28082479 | BJ9: 0.37133381 | BK9: 1.0490511 | BL9: 0.56731018 | BM9: 0.74192425 | BN9: 62.060388 | BO9: 1.9132613 | BP9: 1.7162013 | BQ9: 6.6670093 | BR9: 0.961 | BS9: 1.071 | BT9: 0.081 | BU9: 0.114 | BV9: 9.735 | BW9: 7.576 | BY9: 14.944 | BZ9: 7.328 | CA9: 5.767 | CB9: 3 | CC9: 1 | CD9: 1 | CE9: 49.622 | CF9: 40 | CG9: 66.667 | CH9: 31.477 | CI9: 2.172 | CJ9: 0.894 | CK9: 15.829 | CL9: 0.673 | CM9: 0.595 | CN9: 0.117 | CO9: 0.478 | CP9: 6.661 | CQ9: 86.56 | CS9: 2024 | CT9: 2024 | CU9: 2024 | CV9: 2024 | CW9: 2022 | CX9: 2019 | CY9: 2019 | CZ9: 2022 | DA9: 2021 | DB9: 2020 | DC9: 2021-2024 | DE9: 2024 | DF9: 2024 | DG9: 2024 | DH9: 2024 | DI9: 2024 | DJ9: 2024 | DK9: 2024 | DL9: 2019 | DM9: 2020-2024 avg | DN9: 2024 | DO9: 2024 | DP9: 2024 | DQ9: 2024 | DR9: 2022 | DS9: 2024 | DT9: 2024 | DU9: 2024 | DV9: 2023 | DW9: 2021 | DX9: 2021 | DY9: 2021 | DZ9: 2021 | EA9: 2025 | EB9: 2024 | EC9: 2025 | ED9: 2025 | EE9: 2030 | EF9: 2030 | EG9: 2030 | EH9: 2030 | EI9: 2030 | EJ9: 2030 | EK9: 2030 | EL9: 2030 | EM9: 2030 | EN9: 2030 | EO9: 2030 | EP9: 2030 | EQ9: 2030 | ER9: 2030 | ES9: 2030 | ET9: 2030 | EU9: 2030 | EV9: 2030 | EW9: 2030 | EX9: 2030 | EY9: 2030 | EZ9: 2030 | FA9: 2030 | FB9: 2030 | FC9: 2050 | FD9: 2025-2050 | FE9: 2024 | FF9: 2024 | FG9: 2024 | FH9: 2024 | FI9: 2024 | FJ9: 2024 | FL9: 2024 | FM9: 2024 | FN9: 2024 | FO9: 2013 | FP9: 2013 | FQ9: 2013 | FR9: 2023 | FS9: 2023 | FT9: 2023 | FU9: 2024 | FV9: 2024 | FW9: 2024 | FX9: 2024 | FY9: 2020-2024 avg | FZ9: 2030 | GA9: 2030 | GB9: 2030 | GC9: 2050 | GD9: 2050
A10: ARM | B10: Armenia | C10: Europe & Central Asia | D10: Upper middle income | E10: TRUE | F10: 12.158 | G10: 3.076 | H10: 49.961 | I10: 22.441 | J10: 107.426 | K10: 1 | L10: 2 | M10: 1 | R10: -0.421 | S10: 3.6 | T10: 21.977 | U10: 1.203 | V10: 56.811 | W10: 25.356 | X10: 72.468 | Y10: 3 | Z10: 0.089 | AA10: 6.304 | AB10: 4.261 | AC10: 0 | AD10: 4.261 | AE10: 1.407 | AF10: -5.718 | AG10: 0.679 | AH10: 6.397 | AI10: 76.872 | AJ10: 0 | AK10: 0 | AL10: 0 | AM10: 0 | AN10: 0 | AO10: 34.939 | AP10: -1.384 | AQ10: 11.413 | AR10: 4.2378666 | AS10: 1.017088 | AT10: 0.30666802 | AU10: 0.21028664 | AV10: 0.10258892 | AW10: 0.14261642 | AX10: 0.050758188 | AY10: 0.06550504 | AZ10: 0.13866477 | BA10: 0.070461711 | BB10: 0.03314974 | BC10: -0.018825165 | BD10: 68.202919 | BE10: 0.15546654 | BF10: 5.3679644 | BG10: 3.2463078 | BH10: 0.25631292 | BI10: 0.77198062 | BJ10: 0.79046401 | BK10: 0.46417243 | BL10: 0.96337784 | BM10: 0.39556465 | BN10: 64.034672 | BO10: 1.9322344 | BP10: 1.5564725 | BQ10: 7.5612426 | BT10: 0.111 | BU10: 0.123 | BY10: 13.161 | BZ10: 7.123 | CA10: 4.35 | CB10: 3 | CC10: 1 | CD10: 1 | CE10: 36.267 | CF10: 0 | CG10: 83.333 | CH10: 25.301 | CI10: -0.597 | CJ10: -4.602 | CK10: 23.833 | CL10: 5.088 | CM10: 0.3 | CN10: 0.227 | CO10: 0.073 | CP10: 4.999 | CQ10: 49.76 | CS10: 2024 | CT10: 2024 | CU10: 2024 | CV10: 2024 | CW10: 2022 | CX10: 2024 | CY10: 2024 | CZ10: 2022 | DE10: 2024 | DF10: 2021 | DG10: 2024 | DH10: 2024 | DI10: 2024 | DJ10: 2024 | DK10: 2024 | DL10: 2024 | DM10: 2020-2024 avg | DN10: 2024 | DO10: 2024 | DP10: 2024 | DQ10: 2024 | DR10: 2022 | DS10: 2024 | DT10: 2024 | DU10: 2024 | DV10: 2022 | DW10: 2021 | DX10: 2021 | DY10: 2021 | DZ10: 2021 | EA10: 2025 | EB10: 2024 | EC10: 2025 | ED10: 2025 | EE10: 2030 | EF10: 2030 | EG10: 2030 | EH10: 2030 | EI10: 2030 | EJ10: 2030 | EK10: 2030 | EL10: 2030 | EM10: 2030 | EN10: 2030 | EO10: 2030 | EP10: 2030 | EQ10: 2030 | ER10: 2030 | ES10: 2030 | ET10: 2030 | EU10: 2030 | EV10: 2030 | EW10: 2030 | EX10: 2030 | EY10: 2030 | EZ10: 2030 | FA10: 2030 | FB10: 2030 | FC10: 2050 | FD10: 2025-2050 | FG10: 2024 | FH10: 2024 | FL10: 2024 | FM10: 2024 | FN10: 2024 | FO10: 2013 | FP10: 2013 | FQ10: 2013 | FR10: 2023 | FS10: 2023 | FT10: 2023 | FU10: 2024 | FV10: 2024 | FW10: 2024 | FX10: 2024 | FY10: 2020-2024 avg | FZ10: 2030 | GA10: 2030 | GB10: 2030 | GC10: 2050 | GD10: 2050
A11: ABW | B11: Aruba | C11: Latin America & Caribbean | D11: High income | E11: FALSE | F11: 16.586 | G11: 4.056 | H11: 68.646 | I11: 20.958 | M11: 0 | AA11: 8.393 | AB11: 0 | AC11: 0 | AD11: 0 | AF11: -5.855 | AG11: 0.06 | AH11: 5.915 | AJ11: 0 | AK11: 0 | AL11: 0 | AM11: 0 | AN11: 83 | AO11: 29.227 | AP11: 0 | AQ11: 0 | AR11: 4.3704137 | AS11: 1.0488993 | AT11: 0.33710484 | AU11: 0.23115761 | AV11: 0.14169749 | AW11: 0.083945238 | AX11: 0.093086034 | AY11: 0.071079887 | AZ11: 0.090828192 | BA11: -0.056703435 | BB11: -0.094966609 | BC11: -0.1123927 | BD11: -118.24358 | BE11: 0.15942989 | BF11: 5.0169955 | BG11: 3.3255038 | BH11: 0.087498006 | BI11: 1.4676455 | BJ11: 0.2985025 | BK11: 0.57843004 | BL11: 0.8934278 | BM11: 0.26102702 | BN11: 48.017726 | BO11: 2.3451367 | BP11: 2.2152324 | BQ11: -6.1045555 | BR11: 1.328 | BS11: 1.462 | BT11: 0.275 | BU11: 0.318 | BV11: 10.375 | BW11: 2.458 | BX11: 2.458 | BY11: 12.376 | BZ11: 7.124 | CA11: 5.575 | CB11: 1 | CC11: 0 | CD11: 0 | CH11: 24.454 | CI11: 7.743 | CJ11: 9.639 | CL11: 3.593 | CM11: 0.187 | CN11: 0.82 | CO11: -0.632 | CP11: 14.33 | CQ11: 57.95 | CS11: 2024 | CT11: 2024 | CU11: 2024 | CV11: 2024 | CZ11: 2022 | DN11: 2024 | DO11: 2024 | DP11: 2024 | DQ11: 2024 | DS11: 2023 | DT11: 2023 | DU11: 2023 | DW11: 2021 | DX11: 2021 | DY11: 2021 | DZ11: 2021 | EA11: 2024 | EB11: 2024 | EC11: 2024 | ED11: 2024 | EE11: 2030 | EF11: 2030 | EG11: 2030 | EH11: 2030 | EI11: 2030 | EJ11: 2030 | EK11: 2030 | EL11: 2030 | EM11: 2030 | EN11: 2030 | EO11: 2030 | EP11: 2030 | EQ11: 2030 | ER11: 2030 | ES11: 2030 | ET11: 2030 | EU11: 2030 | EV11: 2030 | EW11: 2030 | EX11: 2030 | EY11: 2030 | EZ11: 2030 | FA11: 2030 | FB11: 2030 | FC11: 2050 | FD11: 2025-2050 | FE11: 2024 | FF11: 2024 | FG11: 2024 | FH11: 2024 | FI11: 2024 | FJ11: 2024 | FK11: 2024 | FL11: 2024 | FM11: 2024 | FN11: 2024 | FO11: 2013 | FP11: 2013 | FQ11: 2013 | FU11: 2024 | FV11: 2024 | FW11: 2024 | FY11: 2020-2024 avg | FZ11: 2030 | GA11: 2030 | GB11: 2030 | GC11: 2050 | GD11: 2050
A12: AUS | B12: Australia | C12: East Asia & Pacific | D12: High income | E12: FALSE | F12: 2.416 | G12: 0.881 | H12: 50.611 | I12: 29.408 | M12: 0 | O12: 5.02 | P12: 1 | AA12: 3.229 | AB12: 2.2 | AC12: 0.115 | AD12: 2.086 | AE12: 2.124 | AF12: 15.237 | AG12: 26.894 | AH12: 11.657 | AI12: -214.472 | AJ12: 2.768 | AK12: 0.264 | AL12: 1.718 | AM12: 0.786 | AN12: 2.219 | AO12: 39.611 | AP12: 3.628 | AQ12: 9.616 | AR12: 3.3797869 | AS12: 1.284319 | AT12: 0.42454479 | AU12: 0.29111643 | AV12: 0.22134023 | AW12: 0.1120502 | AX12: 0.096674217 | AY12: 0.11249355 | AZ12: 0.026099604 | BA12: 0.02246574 | BB12: 0.031677882 | BC12: 0.014829091 | BD12: 42.359262 | BE12: -0.024242477 | BF12: 3.5312946 | BG12: 4.0276262 | BH12: 0.2007776 | BI12: 1.0142759 | BJ12: 0.96285218 | BK12: 0.23884172 | BL12: 1.6108788 | BM12: 0.27243012 | BN12: 68.052994 | BO12: 2.3753812 | BP12: 1.2610067 | BQ12: 7.8045855 | BR12: 1.121 | BS12: 1.189 | BT12: 0.257 | BU12: 0.235 | BV12: 19.703 | BW12: 11.238 | BX12: 9.914 | BY12: 6.096 | BZ12: 5.777 | CA12: 4.461 | CE12: 67.981 | CF12: 60 | CG12: 50 | CH12: 36.463 | CI12: -1.37 | CJ12: -2.245 | CK12: 24.506 | CL12: 2.132 | CM12: 0.135 | CN12: 0.194 | CO12: -0.059 | CP12: 4.851 | CQ12: 49.32 | CS12: 2024 | CT12: 2024 | CU12: 2024 | CV12: 2024 | CZ12: 2022 | DB12: 2020 | DC12: 2021-2024 | DN12: 2024 | DO12: 2024 | DP12: 2024 | DQ12: 2024 | DR12: 2022 | DS12: 2025 | DT12: 2025 | DU12: 2025 | DV12: 2023 | DW12: 2021 | DX12: 2021 | DY12: 2021 | DZ12: 2021 | EA12: 2025 | EB12: 2024 | EC12: 2025 | ED12: 2025 | EE12: 2030 | EF12: 2030 | EG12: 2030 | EH12: 2030 | EI12: 2030 | EJ12: 2030 | EK12: 2030 | EL12: 2030 | EM12: 2030 | EN12: 2030 | EO12: 2030 | EP12: 2030 | EQ12: 2030 | ER12: 2030 | ES12: 2030 | ET12: 2030 | EU12: 2030 | EV12: 2030 | EW12: 2030 | EX12: 2030 | EY12: 2030 | EZ12: 2030 | FA12: 2030 | FB12: 2030 | FC12: 2050 | FD12: 2025-2050 | FE12: 2024 | FF12: 2024 | FG12: 2024 | FH12: 2024 | FI12: 2024 | FJ12: 2024 | FK12: 2024 | FL12: 2024 | FM12: 2024 | FN12: 2024 | FR12: 2023 | FS12: 2023 | FT12: 2023 | FU12: 2024 | FV12: 2024 | FW12: 2024 | FX12: 2024 | FY12: 2020-2024 avg | FZ12: 2030 | GA12: 2030 | GB12: 2030 | GC12: 2050 | GD12: 2050
A13: AUT | B13: Austria | C13: Europe & Central Asia | D13: High income | E13: FALSE | F13: 1.964 | G13: 0.992 | H13: 79.176 | I13: 28.33 | M13: 0 | O13: 6.11 | P13: 1 | AA13: 3.409 | AB13: 0.21 | AC13: 0.041 | AD13: 0.17 | AE13: 0.939 | AF13: -4.681 | AG13: 2.771 | AH13: 7.452 | AI13: 63.966 | AJ13: 0.062 | AK13: 0.038 | AL13: 0.024 | AM13: 0 | AN13: 4.464 | AO13: 88.811 | AP13: -2.7 | AQ13: 7.467 | AR13: 3.0715332 | AS13: 1.1671826 | AT13: 0.40753227 | AU13: 0.2794507 | AV13: 0.18386029 | AW13: 0.12037145 | AX13: 0.075662649 | AY13: 0.08489596 | AZ13: 0.015409305 | BA13: 0.034339155 | BB13: 0.033374552 | BC13: 0.021722757 | BD13: 99.36919 | BE13: 0.0025384294 | BF13: 3.2092226 | BG13: 2.5737515 | BH13: 0.25062596 | BI13: 0.44641495 | BJ13: 0.59399297 | BK13: 0.17998711 | BL13: 1.1027305 | BM13: 0.30462209 | BN13: 70.819365 | BO13: 1.0957333 | BP13: 0.85497882 | BQ13: 1.2170908 | BR13: 1.639 | BS13: 1.696 | BT13: 0.28 | BU13: 0.167 | BV13: 39.334 | BW13: 20.896 | BX13: 20.896 | BY13: 21.913 | BZ13: 26.879 | CA13: 18.327 | CE13: 82.426 | CF13: 40 | CG13: 50 | CH13: 50.51 | CI13: -3.685 | CJ13: 1.527 | CK13: 23.577 | CL13: 0.498 | CM13: 0.131 | CN13: 0.084 | CO13: 0.047 | CP13: 3.947 | CQ13: 77.71 | CS13: 2024 | CT13: 2024 | CU13: 2024 | CV13: 2024 | CZ13: 2022 | DB13: 2020 | DC13: 2021-2024 | DN13: 2023 | DO13: 2024 | DP13: 2024 | DQ13: 2024 | DR13: 2022 | DS13: 2024 | DT13: 2024 | DU13: 2024 | DV13: 2023 | DW13: 2021 | DX13: 2021 | DY13: 2021 | DZ13: 2021 | EA13: 2025 | EB13: 2024 | EC13: 2025 | ED13: 2025 | EE13: 2030 | EF13: 2030 | EG13: 2030 | EH13: 2030 | EI13: 2030 | EJ13: 2030 | EK13: 2030 | EL13: 2030 | EM13: 2030 | EN13: 2030 | EO13: 2030 | EP13: 2030 | EQ13: 2030 | ER13: 2030 | ES13: 2030 | ET13: 2030 | EU13: 2030 | EV13: 2030 | EW13: 2030 | EX13: 2030 | EY13: 2030 | EZ13: 2030 | FA13: 2030 | FB13: 2030 | FC13: 2050 | FD13: 2025-2050 | FE13: 2024 | FF13: 2024 | FG13: 2024 | FH13: 2024 | FI13: 2024 | FJ13: 2024 | FK13: 2024 | FL13: 2024 | FM13: 2024 | FN13: 2024 | FR13: 2023 | FS13: 2023 | FT13: 2023 | FU13: 2024 | FV13: 2024 | FW13: 2024 | FX13: 2024 | FY13: 2020-2024 avg | FZ13: 2030 | GA13: 2030 | GB13: 2030 | GC13: 2050 | GD13: 2050
A14: AZE | B14: Azerbaijan | C14: Europe & Central Asia | D14: Upper middle income | E14: TRUE | F14: 1.134 | G14: 0.43 | H14: 21.64 | I14: 17.785 | J14: 99.354 | M14: 1 | N14: 7 | P14: 1 | R14: 2.041 | S14: 7.23 | T14: 21.499 | U14: 0.611 | V14: 50.922 | W14: 40.628 | X14: 78.594 | Z14: 0.49 | AA14: 3.536 | AB14: 13.299 | AC14: 5.538 | AD14: 7.76 | AE14: 0.863 | AF14: 80.472 | AG14: 85.924 | AH14: 5.452 | AI14: -255.959 | AJ14: 29.57 | AK14: 20.983 | AL14: 8.587 | AM14: 0 | AN14: 0.366 | AO14: 7.837 | AP14: -2.236 | AQ14: 1.111 | AR14: 6.4972007 | AS14: 1.5593282 | AT14: 0.41607704 | AU14: 0.28530997 | AV14: 0.18074683 | AW14: 0.22811903 | AX14: 0.066928693 | AY14: 0.10762843 | AZ14: 0.27451818 | BA14: 0.070603439 | BB14: 0.031589222 | BC14: -0.039095356 | BD14: 30.939819 | BE14: 0.16255924 | BF14: 7.4584304 | BG14: 4.4050998 | BH14: 1.2030709 | BI14: 0.57929177 | BJ14: 0.54470819 | BK14: 1.187545 | BL14: 0.89048392 | BM14: 1.5593344 | BN14: 51.451131 | BO14: 3.2916333 | BP14: 3.0872531 | BQ14: 12.841008 | BR14: 0.447 | BS14: 0.537 | BT14: 0.046 | BU14: 0.063 | BV14: 3.758 | BW14: 3.758 | BX14: 3.758 | BY14: 12.967 | BZ14: 7.151 | CA14: 4.371 | CB14: 1 | CC14: 0 | CD14: 0 | CE14: 11.283 | CF14: 0 | CG14: 0 | CH14: 37.913 | CI14: 4.484 | CJ14: 6.276 | CK14: 16.772 | CL14: 2.328 | CM14: 1.175 | CN14: 0.152 | CO14: 1.023 | CP14: -19.79 | CQ14: 52.15 | CS14: 2024 | CT14: 2024 | CU14: 2024 | CV14: 2024 | CW14: 2022 | CZ14: 2022 | DA14: 2021 | DC14: 2021-2024 | DE14: 2024 | DF14: 2022 | DG14: 2024 | DH14: 2024 | DI14: 2024 | DJ14: 2024 | DK14: 2024 | DM14: 2020-2024 avg | DN14: 2024 | DO14: 2024 | DP14: 2024 | DQ14: 2024 | DR14: 2022 | DS14: 2025 | DT14: 2025 | DU14: 2025 | DV14: 2023 | DW14: 2021 | DX14: 2021 | DY14: 2021 | DZ14: 2021 | EA14: 2025 | EB14: 2024 | EC14: 2025 | ED14: 2025 | EE14: 2030 | EF14: 2030 | EG14: 2030 | EH14: 2030 | EI14: 2030 | EJ14: 2030 | EK14: 2030 | EL14: 2030 | EM14: 2030 | EN14: 2030 | EO14: 2030 | EP14: 2030 | EQ14: 2030 | ER14: 2030 | ES14: 2030 | ET14: 2030 | EU14: 2030 | EV14: 2030 | EW14: 2030 | EX14: 2030 | EY14: 2030 | EZ14: 2030 | FA14: 2030 | FB14: 2030 | FC14: 2050 | FD14: 2025-2050 | FE14: 2024 | FF14: 2024 | FG14: 2024 | FH14: 2024 | FI14: 2024 | FJ14: 2024 | FK14: 2024 | FL14: 2024 | FM14: 2024 | FN14: 2024 | FO14: 2013 | FP14: 2013 | FQ14: 2013 | FR14: 2023 | FS14: 2023 | FT14: 2023 | FU14: 2024 | FV14: 2024 | FW14: 2024 | FX14: 2024 | FY14: 2020-2024 avg | FZ14: 2030 | GA14: 2030 | GB14: 2030 | GC14: 2050 | GD14: 2050
